Workbook
Name _25_de_agosto: 'RESUMEN TOTAL'!$A$4:$D$365
Name _25_de_agosto_3: 'RESUMEN TOTAL'!$A$4:$D$377
Name BONOMOcam: Hoja1!$B$2
Name CANTIDAD_DE_CAMARAS: 'RESUMEN TOTAL'!$B$1
Name COSEIDIcam: Hoja1!$B$4

Sheet RESUMEN TOTAL
A1: CANTIDAD DE CAMARAS | B1: =COUNTA(B5:B533) -> 435 | D1: PORCIENTO DE CAIDAS | K1: =(K3)/(K2+K3) -> 0 | L1: =(L3)/(L2+L3) -> 0 | M1: =(M3)/(M2+M3) -> 0 | N1: =(N3)/(N2+N3) -> 0 | O1: =(O3)/(O2+O3) -> 0 | P1: =(P3)/(P2+P3) -> 0 | Q1: =(Q3)/(Q2+Q3) -> 0 | R1: =(R3)/(R2+R3) -> 0 | ... AN1: =(AN3)/(AN2+AN3) -> 0
D2: FUNCIONAN | K2: =B1-K3 -> 435 | L2: =CANTIDAD_DE_CAMARAS-L3 -> 435 | M2: =CANTIDAD_DE_CAMARAS-M3 -> 435 | N2: =CANTIDAD_DE_CAMARAS-N3 -> 435 | O2: =CANTIDAD_DE_CAMARAS-O3 -> 435 | P2: =CANTIDAD_DE_CAMARAS-P3 -> 435 | Q2: =CANTIDAD_DE_CAMARAS-Q3 -> 435 | R2: =CANTIDAD_DE_CAMARAS-R3 -> 435 | S2: =CANTIDAD_DE_CAMARAS-S3 -> 435 | ... AN2: =CANTIDAD_DE_CAMARAS-AN3 -> 435
D3: CAIDAS | K3: =COUNTIF(K4:K453, "apagado") -> 0 | L3: =COUNTIF(L4:L453, "apagado") -> 0 | M3: =COUNTIF(M4:M453, "apagado") -> 0 | N3: =COUNTIF(N4:N453, "apagado") -> 0 | O3: =COUNTIF(O4:O453, "apagado") -> 0 | P3: =COUNTIF(P4:P453, "apagado") -> 0 | Q3: =COUNTIF(Q4:Q453, "apagado") -> 0 | R3: =COUNTIF(R4:R453, "apagado") -> 0 | ... AN3: =COUNTIF(AN4:AN453, "apagado") -> 0
A4: Barrio | B4: [Denominacion] | C4: [Empresa Mantenimiento] | D4: [Ubicacion] | E4: [Tipo de Camara] | F4: [Tipo de Conexion] | H4: DIAS FUNCIONANDO | I4: DIAS CAIDA | J4: EFECTIVIDAD | K4: 44927 | L4: 44928 | M4: 44929 | N4: 44930 | O4: 44931 | P4: 44932 | Q4: 44933 | R4: 44934 | S4: 44935 | T4: 44936 | U4: 44937 | V4: 44938 | W4: 44939 | X4: 44940 | Y4: 44941 | Z4: 44942 | AA4: 44943 | AB4: 44944 | AC4: 44945 | AD4: 44946 | AE4: 44947 | AF4: 44948 | AG4: 44949 | AH4: 44950 | AI4: 44951 | AJ4: 44952 | AK4: 44953 | AL4: 44954 | AM4: 44955 | AN4: 44956 | AO4: 44957
A5: ALTAMIRA | B5: ALT01 | C5: BONOMO | D5: Calchaqui y Sgto. Cabral | E5: Domo | F5: Fibra Optica | G5: 172.20.10.6 | H5: =COUNTIF(K5:AO5,"") -> 31 | I5: =COUNTIF(K5:AL5,"APAGADO") -> 0 | J5: =(H5)/(I5+H5) -> 1
A6: ALTAMIRA | B6: ALT02 | C6: BONOMO | D6: Calchaqui y Lope de Vega | E6: Domo | F6: PTO A FO | G6: 172.20.12.218 | H6: =COUNTIF(K6:AO6,"") -> 31 | I6: =COUNTIF(K6:AL6,"APAGADO") -> 0 | J6: =(H6)/(I6+H6) -> 1
A7: ALTAMIRA | B7: ALT 03 | C7: BONOMO | D7: Bombero Galarza y Necochea | E7: Domo | F7: FIBRA OPTICA | G7: 172.20.12.54 | H7: =COUNTIF(K7:AO7,"") -> 31 | I7: =COUNTIF(K7:AL7,"APAGADO") -> 0 | J7: =(H7)/(I7+H7) -> 1
A8: ALTAMIRA | B8: ALT 04 | C8: BONOMO | D8: Francia y Necochea | E8: Domo | F8: FIBRA OPTICA | G8: 172.20.12.55 | H8: =COUNTIF(K8:AO8,"") -> 31 | I8: =COUNTIF(K8:AL8,"APAGADO") -> 0 | J8: =(H8)/(I8+H8) -> 1
A9: ALTAMIRA | B9: ALT05 | C9: BONOMO | D9: Av. Calchaqui y Bombero Galarza | E9: Domo | F9: PTO A FO | G9: 172.20.12.216 | H9: =COUNTIF(K9:AO9,"") -> 31 | I9: =COUNTIF(K9:AL9,"APAGADO") -> 0 | J9: =(H9)/(I9+H9) -> 1
A10: ALTAMIRA | B10: ALT 06 | C10: BONOMO | D10: LOPE DE VEGA Y NECOCHEA | E10: Domo | F10: PTO A FO | G10: 172.20.12.12 | H10: =COUNTIF(K10:AO10,"") -> 31 | I10: =COUNTIF(K10:AL10,"APAGADO") -> 0 | J10: =(H10)/(I10+H10) -> 1
A11: ALTAMIRA | B11: ALT07 | C11: BONOMO | D11: AV. CALCHAQUI Y AV. DEL TRABAJO | E11: DOMO | F11: PTO A FO | G11: 172.20.10.57 | H11: =COUNTIF(K11:AO11,"") -> 31 | I11: =COUNTIF(K11:AL11,"APAGADO") -> 0 | J11: =(H11)/(I11+H11) -> 1
A12: ALTAMIRA | B12: ALT 08 | C12: BONOMO | D12: HUMAITA Y NECOCHEA | E12: DOMO | F12: Fibra Optica | G12: 172.20.11.215 | H12: =COUNTIF(K12:AO12,"") -> 31 | I12: =COUNTIF(K12:AL12,"APAGADO") -> 0 | J12: =(H12)/(I12+H12) -> 1
A13: ALTAMIRA | B13: ALT 09 | C13: BONOMO | D13: NECOCHEA Y CURUPAITY | E13: DOMO | F13: Fibra Optica | G13: 172.20.11.216 | H13: =COUNTIF(K13:AO13,"") -> 31 | I13: =COUNTIF(K13:AL13,"APAGADO") -> 0 | J13: =(H13)/(I13+H13) -> 1
A14: ALTAMIRA | B14: ALT 10 | C14: BONOMO | D14: Calchaqui y Francia | E14: Domo | F14: Radio | H14: =COUNTIF(K14:AO14,"") -> 31 | I14: =COUNTIF(K14:AL14,"APAGADO") -> 0 | J14: =(H14)/(I14+H14) -> 1
A15: AGUSTIN RAMIREZ | B15: ARA 01 | C15: COSEIDI | D15: Malambo y Tranquera | E15: Domo | F15: FIBRA OPTICA | G15: 172.20.12.110 | H15: =COUNTIF(K15:AO15,"") -> 31 | I15: =COUNTIF(K15:AL15,"APAGADO") -> 0 | J15: =(H15)/(I15+H15) -> 1
A16: BELGRANO | B16: BEL 01 | C16: BONOMO | D16: San Martin y Dardo Rocha | E16: DOMO | F16: FIBRA OPTICA | G16: 172.20.12.64 | H16: =COUNTIF(K16:AO16,"") -> 31 | I16: =COUNTIF(K16:AL16,"APAGADO") -> 0 | J16: =(H16)/(I16+H16) -> 1
A17: BOSQUES CENTRO | B17: BOSQC 01 | C17: COSEIDI | D17: LUIS AGOTE E/DANUNCIO Y CAMPOAMOR | E17: Fija | F17: Radio | G17: 172.20.11.15 | H17: =COUNTIF(K17:AO17,"") -> 31 | I17: =COUNTIF(K17:AL17,"APAGADO") -> 0 | J17: =(H17)/(I17+H17) -> 1
A18: BOSQUES CENTRO | B18: BOSQC 02 | C18: COSEIDI | D18: LUIS AGOTE E/DANUNCIO Y CAMPOAMOR | E18: Fija | F18: Radio | G18: 172.20.11.16 | H18: =COUNTIF(K18:AO18,"") -> 31 | I18: =COUNTIF(K18:AL18,"APAGADO") -> 0 | J18: =(H18)/(I18+H18) -> 1
A19: BOSQUES CENTRO | B19: BOSQC 03 | C19: COSEIDI | D19: BENAVENTE Y LUIS AGOTE | E19: Fija | F19: Radio | G19: 172.20.11.13 | H19: =COUNTIF(K19:AO19,"") -> 31 | I19: =COUNTIF(K19:AL19,"APAGADO") -> 0 | J19: =(H19)/(I19+H19) -> 1
A20: BOSQUES CENTRO | B20: BOSQC 04 | C20: COSEIDI | D20: BENAVENTE Y LUIS AGOTE | E20: Fija | F20: Radio | G20: 172.20.11.113 | H20: =COUNTIF(K20:AO20,"") -> 31 | I20: =COUNTIF(K20:AL20,"APAGADO") -> 0 | J20: =(H20)/(I20+H20) -> 1
A21: BOSQUES CENTRO | B21: BOSQC 05 | C21: COSEIDI | D21: LUIS AGOTE Y RUTA 36 | E21: Fija | F21: Radio | G21: 172.20.11.17 | H21: =COUNTIF(K21:AO21,"") -> 31 | I21: =COUNTIF(K21:AL21,"APAGADO") -> 0 | J21: =(H21)/(I21+H21) -> 1
A22: BOSQUES CENTRO | B22: BOSQC 06 | C22: COSEIDI | D22: LUIS AGOTE Y RUTA 36 | E22: Fija | F22: Radio | G22: 172.20.11.18 | H22: =COUNTIF(K22:AO22,"") -> 31 | I22: =COUNTIF(K22:AL22,"APAGADO") -> 0 | J22: =(H22)/(I22+H22) -> 1
A23: CENTRO | B23: CEN01 | C23: BONOMO | D23: San Martin y 9 de Julio | E23: Fija | F23: Fibra Optica | G23: 172.20.11.10 | H23: =COUNTIF(K23:AO23,"") -> 31 | I23: =COUNTIF(K23:AL23,"APAGADO") -> 0 | J23: =(H23)/(I23+H23) -> 1
A24: CENTRO | B24: CEN02 | C24: BONOMO | D24: San Martin y Almafuerte | E24: Fija | F24: Fibra Optica | G24: 172.20.11.11 | H24: =COUNTIF(K24:AO24,"") -> 31 | I24: =COUNTIF(K24:AL24,"APAGADO") -> 0 | J24: =(H24)/(I24+H24) -> 1
A25: CENTRO | B25: CEN03 | C25: BONOMO | D25: San Martin y Sallares | E25: Domo | F25: Fibra Optica | G25: 172.20.12.30 | H25: =COUNTIF(K25:AO25,"") -> 31 | I25: =COUNTIF(K25:AL25,"APAGADO") -> 0 | J25: =(H25)/(I25+H25) -> 1
A26: CENTRO | B26: CEN04 | C26: BONOMO | D26: San Martin y Contreras | E26: Domo | F26: Fibra Optica | G26: 172.20.12.29 | H26: =COUNTIF(K26:AO26,"") -> 31 | I26: =COUNTIF(K26:AL26,"APAGADO") -> 0 | J26: =(H26)/(I26+H26) -> 1
... A96: CENTRO | B96: CEN74 | C96: BONOMO | D96: Las Heras y Maipu | E96: Domo | F96: FIBRA OPTICA | G96: 172.20.11.53 | H96: =COUNTIF(K96:AO96,"") -> 31 | I96: =COUNTIF(K96:AL96,"APAGADO") -> 0 | J96: =(H96)/(I96+H96) -> 1
A97: CENTRO | B97: CEN 75 | C97: BONOMO | D97: 25 DE MAYO Y CASTELLI | E97: Domo | F97: Fibra Optica | H97: =COUNTIF(K97:AO97,"") -> 31 | I97: =COUNTIF(K97:AL97,"APAGADO") -> 0 | J97: =(H97)/(I97+H97) -> 1
A98: CENTRO | B98: CEN 76 | C98: BONOMO | D98: ESPAÑA E/MITRE Y BOCUZZI | E98: Fija | F98: Fibra Optica | H98: =COUNTIF(K98:AO98,"") -> 31 | I98: =COUNTIF(K98:AL98,"APAGADO") -> 0 | J98: =(H98)/(I98+H98) -> 1
A99: CENTRO | B99: CEN 77 | C99: BONOMO | D99: Monteagudo e/ Mitre y Boccuzzi | E99: Fija | F99: Fibra Optica | G99: 172.20.11.241 | H99: =COUNTIF(K99:AO99,"") -> 31 | I99: =COUNTIF(K99:AL99,"APAGADO") -> 0 | J99: =(H99)/(I99+H99) -> 1
A100: CENTRO | B100: CEN 78 | C100: BONOMO | D100: Mitre e/Monteagudo y Alberdi | E100: Fija | F100: Fibra Optica | G100: 172.20.11.240 | H100: =COUNTIF(K100:AO100,"") -> 31 | I100: =COUNTIF(K100:AL100,"APAGADO") -> 0 | J100: =(H100)/(I100+H100) -> 1
A101: CENTRO | B101: CEN 79 | C101: BONOMO | D101: Diag. Constituyente y Brown | E101: Fija | F101: Fibra Optica | G101: 172.20.11.243 | H101: =COUNTIF(K101:AO101,"") -> 31 | I101: =COUNTIF(K101:AL101,"APAGADO") -> 0 | J101: =(H101)/(I101+H101) -> 1
A102: CENTRO | B102: CEN 80 | C102: BONOMO | D102: Diag. Constituyente y Brown | E102: Fija | F102: Fibra Optica | G102: 172.20.11.244 | H102: =COUNTIF(K102:AO102,"") -> 31 | I102: =COUNTIF(K102:AL102,"APAGADO") -> 0 | J102: =(H102)/(I102+H102) -> 1
A103: CENTRO | B103: CEN 81 | C103: BONOMO | D103: Alberdi y A.del Valle | E103: Fija | F103: Fibra Optica | G103: 172.20.11.242 | H103: =COUNTIF(K103:AO103,"") -> 31 | I103: =COUNTIF(K103:AL103,"APAGADO") -> 0 | J103: =(H103)/(I103+H103) -> 1
A104: CENTRO | B104: CEN 82 | C104: BONOMO | D104: DORREGO Y BOUREL | E104: Domo | F104: Fibra Optica | G104: 172.20.11.198 | H104: =COUNTIF(K104:AO104,"") -> 31 | I104: =COUNTIF(K104:AL104,"APAGADO") -> 0 | J104: =(H104)/(I104+H104) -> 1
A105: CENTRO | B105: CEN83 | C105: BONOMO | D105: RECONQUISTA Y 25 DE MAYO | E105: Domo | F105: Radio | G105: 172.20.11.123 | H105: =COUNTIF(K105:AO105,"") -> 31 | I105: =COUNTIF(K105:AL105,"APAGADO") -> 0 | J105: =(H105)/(I105+H105) -> 1
A106: SAN NICOLAS | B106: CHA01 | C106: BONOMO | D106: Novak y Pte Illia | E106: Domo | F106: Radio | G106: 172.20.200.126 | H106: =COUNTIF(K106:AO106,"") -> 31 | I106: =COUNTIF(K106:AL106,"APAGADO") -> 0 | J106: =(H106)/(I106+H106) -> 1
A107: CHACABUCO | B107: CHA02 | C107: BONOMO | D107: Pte. Illia y Posadas | E107: Domo | F107: Radio | G107: 172.20.200.186 | H107: =COUNTIF(K107:AO107,"") -> 31 | I107: =COUNTIF(K107:AL107,"APAGADO") -> 0 | J107: =(H107)/(I107+H107) -> 1
A108: CHACABUCO | B108: CHA03 | C108: BONOMO | D108: MAIPU Y ALVAREZ THOMAS | E108: DOMO | F108: Fibra Optica | G108: 172.20.11.71 | H108: =COUNTIF(K108:AO108,"") -> 31 | I108: =COUNTIF(K108:AL108,"APAGADO") -> 0 | J108: =(H108)/(I108+H108) -> 1
A109: CHACABUCO | B109: CHA04 | C109: BONOMO | D109: ESTADOS UNIDOS DE A. E ILLIA | E109: DOMO | F109: Fibra Optica | G109: 172.20.11.191 | H109: =COUNTIF(K109:AO109,"") -> 31 | I109: =COUNTIF(K109:AL109,"APAGADO") -> 0 | J109: =(H109)/(I109+H109) -> 1
...

Sheet Hoja4
A10: Barrio | B10: [Denominacion] | C10: [Empresa Mantenimiento] | D10: [Ubicacion] | E10: [Tipo de Camara] | F10: [Tipo de Conexion]
A11: BELGRANO | B11: BEL 01 | C11: BONOMO | D11: San Martin y Dardo Rocha | E11: DOMO | F11: FIBRA OPTICA | G11: 172.20.12.64
A12: CENTRO | B12: CEN18 | C12: BONOMO | D12: Monteagudo e/Mitre y Sallares | E12: Fija | F12: Fibra Optica | G12: 172.20.10.26
A13: CENTRO | B13: CEN26 | C13: BONOMO | D13: Mitre y España | E13: Domo | F13: Fibra Optica | G13: 172.20.12.06
A14: CENTRO | B14: CEN44 | C14: BONOMO | D14: Mitre y Brown | E14: Domo | F14: Fibra Optica | G14: 172.20.12.62
A15: CENTRO | B15: CEN47 | C15: BONOMO | D15: Sallares y Brown | E15: Domo | F15: Fibra Optica | G15: 172.20.12.65
A16: CENTRO | B16: CEN 53 | C16: BONOMO | D16: GUTIERREZ Y BROWN | E16: Domo | F16: Radio | G16: 172.20.200.166
A17: CENTRO | B17: CEN 72 | C17: BONOMO | D17: MORENO Y 25 DE MAYO | E17: Domo | F17: Fibra Optica | G17: 172.20.11.219
A18: CENTRO | B18: CEN 82 | C18: BONOMO | D18: DORREGO Y BOUREL | E18: Domo | F18: Fibra Optica | G18: 172.20.11.198
A19: CENTRO | B19: CEN83 | C19: BONOMO | D19: RECONQUISTA Y 25 DE MAYO | E19: Domo | F19: Radio | G19: 172.20.11.123
A20: CHACABUCO | B20: CHA02 | C20: BONOMO | D20: Pte. Illia y Posadas | E20: Domo | F20: Radio | G20: 172.20.200.186
A21: LOPEZ ROMERO | B21: LRO01 | C21: BONOMO | D21: H. IRIGOYEN Y BRAILE | E21: FIJA | F21: FIBRA OPTICA | G21: 172.20.10.36
A22: PRESIDENTE SARMIENTO | B22: LRO02 | C22: BONOMO | D22: H. Irigoyen e Islas Orcadas | E22: Domo | F22: FIBRA OPTICA | G22: 172.20.10.40
A23: LOPEZ ROMERO | B23: LRO03 | C23: BONOMO | D23: H. Irigoyen y Parravicini | E23: Fija | F23: Fibra Optica | G23: 172.20.10.38
A24: LOPEZ ROMERO | B24: LRO11 | C24: BONOMO | D24: Av. Yrigoyen y Braile | F24: FIBRA OPTICA | G24: 172.20.11.27
A25: SAN EMILIO | B25: MFI 05 | C25: BONOMO | D25: Cno. Gral. Belgrano y Guayaquil | E25: Domo | F25: FIBRA OPTICA | G25: 172.20.10.41
A26: GOBERNADOR MONTEVERDE | B26: MON03 | C26: BONOMO | D26: Senzabello y Guemes | E26: Domo | F26: Radio | G26: 172.20.200.134
A27: 9 DE JULIO | B27: NJU 01 | C27: BONOMO | D27: Sallares y Parrillo | E27: Domo | F27: Fibra Optica | G27: 172.20.10.22
A28: 9 DE JULIO | B28: NJU03 | C28: BONOMO | D28: San Juan y Parrillo | E28: Domo | F28: PTO A FO | G28: 172.20.10.45
A29: ZEBALLOS CENTRO | B29: NJU05 | C29: BONOMO | D29: Ituzaingo y Alem | E29: Domo | F29: Radio | G29: 172.200.141
A30: 9 DE JULIO | B30: NJU09 | C30: BONOMO | D30: PARRILLO Y CONTRERAS | E30: DOMO | F30: Fibra Optica | G30: 172.20.11.190
A31: DON JOSE | B31: PUNTO SEGURO AGUSTIN RAMIREZ INTERCOMUNICADOR | C31: BONOMO | D31: MALAMBO Y LA TRANQUERA | E31: Fija | F31: Fibra Optica
A32: PRESIDENTE SARMIENTO | B32: SAR 02 (fija 1) | C32: BONOMO | D32: DARDO ROCHA Y GABRIELA MISTRAL | E32: Fija | F32: Fibra Optica | G32: 172.20.11.184
A33: PRESIDENTE SARMIENTO | B33: SAR 03 (fija 2) | C33: BONOMO | D33: DARDO ROCHA Y GABRIELA MISTRAL | E33: Fija | F33: Fibra Optica | G33: 172.20.11.185
A35: CAMARAS SIN FUNCIONAMIENTO DEL DIA 28 DE DICIEMBRE DE 2022
A37: RECIBIDO:
A39: EMPRESA: BONOMO SISTEMAS | D39: FIRMA:
D41: ACALARCION:

Sheet ESTADISTICA
A1: ='RESUMEN TOTAL'!A4 -> Barrio | B1: ='RESUMEN TOTAL'!B4 -> [Denominacion] | C1: ='RESUMEN TOTAL'!D4 -> [Ubicacion] | D1: ='RESUMEN TOTAL'!E4 -> [Tipo de Camara] | E1: ='RESUMEN TOTAL'!F4 -> [Tipo de Conexion] | F1: ='RESUMEN TOTAL'!K4 -> 44927 | G1: ='RESUMEN TOTAL'!L4 -> 44928 | H1: ='RESUMEN TOTAL'!M4 -> 44929 | I1: ='RESUMEN TOTAL'!N4 -> 44930 | J1: ='RESUMEN TOTAL'!O4 -> 44931 | K1: ='RESUMEN TOTAL'!P4 -> 44932 | L1: ='RESUMEN TOTAL'!Q4 -> 44933 | M1: ='RESUMEN TOTAL'!R4 -> 44934 | ... AI1: ='RESUMEN TOTAL'!AN4 -> 44956
A2: ='RESUMEN TOTAL'!A5 -> ALTAMIRA | B2: ='RESUMEN TOTAL'!B5 -> ALT01 | C2: ='RESUMEN TOTAL'!D5 -> Calchaqui y Sgto. Cabral | D2: ='RESUMEN TOTAL'!E5 -> Domo | E2: ='RESUMEN TOTAL'!F5 -> Fibra Optica | F2: ='RESUMEN TOTAL'!K5 -> 0 | G2: ='RESUMEN TOTAL'!L5 -> 0 | H2: ='RESUMEN TOTAL'!M5 -> 0 | I2: ='RESUMEN TOTAL'!N5 -> 0 | J2: ='RESUMEN TOTAL'!O5 -> 0 | K2: ='RESUMEN TOTAL'!P5 -> 0 | L2: ='RESUMEN TOTAL'!Q5 -> 0 | M2: ='RESUMEN TOTAL'!R5 -> 0 | ... AI2: ='RESUMEN TOTAL'!AN5 -> 0
A3: ='RESUMEN TOTAL'!A6 -> ALTAMIRA | B3: ='RESUMEN TOTAL'!B6 -> ALT02 | C3: ='RESUMEN TOTAL'!D6 -> Calchaqui y Lope de Vega | D3: ='RESUMEN TOTAL'!E6 -> Domo | E3: ='RESUMEN TOTAL'!F6 -> PTO A FO | F3: ='RESUMEN TOTAL'!K6 -> 0 | G3: ='RESUMEN TOTAL'!L6 -> 0 | H3: ='RESUMEN TOTAL'!M6 -> 0 | I3: ='RESUMEN TOTAL'!N6 -> 0 | J3: ='RESUMEN TOTAL'!O6 -> 0 | K3: ='RESUMEN TOTAL'!P6 -> 0 | L3: ='RESUMEN TOTAL'!Q6 -> 0 | M3: ='RESUMEN TOTAL'!R6 -> 0 | ... AI3: ='RESUMEN TOTAL'!AN6 -> 0
A4: ='RESUMEN TOTAL'!A7 -> ALTAMIRA | B4: ='RESUMEN TOTAL'!B7 -> ALT 03 | C4: ='RESUMEN TOTAL'!D7 -> Bombero Galarza y Necochea | D4: ='RESUMEN TOTAL'!E7 -> Domo | E4: ='RESUMEN TOTAL'!F7 -> FIBRA OPTICA | F4: ='RESUMEN TOTAL'!K7 -> 0 | G4: ='RESUMEN TOTAL'!L7 -> 0 | H4: ='RESUMEN TOTAL'!M7 -> 0 | I4: ='RESUMEN TOTAL'!N7 -> 0 | J4: ='RESUMEN TOTAL'!O7 -> 0 | K4: ='RESUMEN TOTAL'!P7 -> 0 | L4: ='RESUMEN TOTAL'!Q7 -> 0 | M4: ='RESUMEN TOTAL'!R7 -> 0 | ... AI4: ='RESUMEN TOTAL'!AN7 -> 0
A5: ='RESUMEN TOTAL'!A8 -> ALTAMIRA | B5: ='RESUMEN TOTAL'!B8 -> ALT 04 | C5: ='RESUMEN TOTAL'!D8 -> Francia y Necochea | D5: ='RESUMEN TOTAL'!E8 -> Domo | E5: ='RESUMEN TOTAL'!F8 -> FIBRA OPTICA | F5: ='RESUMEN TOTAL'!K8 -> 0 | G5: ='RESUMEN TOTAL'!L8 -> 0 | H5: ='RESUMEN TOTAL'!M8 -> 0 | I5: ='RESUMEN TOTAL'!N8 -> 0 | J5: ='RESUMEN TOTAL'!O8 -> 0 | K5: ='RESUMEN TOTAL'!P8 -> 0 | L5: ='RESUMEN TOTAL'!Q8 -> 0 | M5: ='RESUMEN TOTAL'!R8 -> 0 | ... AI5: ='RESUMEN TOTAL'!AN8 -> 0
A6: ='RESUMEN TOTAL'!A9 -> ALTAMIRA | B6: ='RESUMEN TOTAL'!B9 -> ALT05 | C6: ='RESUMEN TOTAL'!D9 -> Av. Calchaqui y Bombero Galarza | D6: ='RESUMEN TOTAL'!E9 -> Domo | E6: ='RESUMEN TOTAL'!F9 -> PTO A FO | F6: ='RESUMEN TOTAL'!K9 -> 0 | G6: ='RESUMEN TOTAL'!L9 -> 0 | H6: ='RESUMEN TOTAL'!M9 -> 0 | I6: ='RESUMEN TOTAL'!N9 -> 0 | J6: ='RESUMEN TOTAL'!O9 -> 0 | K6: ='RESUMEN TOTAL'!P9 -> 0 | L6: ='RESUMEN TOTAL'!Q9 -> 0 | M6: ='RESUMEN TOTAL'!R9 -> 0 | ... AI6: ='RESUMEN TOTAL'!AN9 -> 0
A7: ='RESUMEN TOTAL'!A10 -> ALTAMIRA | B7: ='RESUMEN TOTAL'!B10 -> ALT 06 | C7: ='RESUMEN TOTAL'!D10 -> LOPE DE VEGA Y NECOCHEA | D7: ='RESUMEN TOTAL'!E10 -> Domo | E7: ='RESUMEN TOTAL'!F10 -> PTO A FO | F7: ='RESUMEN TOTAL'!K10 -> 0 | G7: ='RESUMEN TOTAL'!L10 -> 0 | H7: ='RESUMEN TOTAL'!M10 -> 0 | I7: ='RESUMEN TOTAL'!N10 -> 0 | J7: ='RESUMEN TOTAL'!O10 -> 0 | K7: ='RESUMEN TOTAL'!P10 -> 0 | L7: ='RESUMEN TOTAL'!Q10 -> 0 | M7: ='RESUMEN TOTAL'!R10 -> 0 | ... AI7: ='RESUMEN TOTAL'!AN10 -> 0
A8: ='RESUMEN TOTAL'!A11 -> ALTAMIRA | B8: ='RESUMEN TOTAL'!B11 -> ALT07 | C8: ='RESUMEN TOTAL'!D11 -> AV. CALCHAQUI Y AV. DEL TRABAJO | D8: ='RESUMEN TOTAL'!E11 -> DOMO | E8: ='RESUMEN TOTAL'!F11 -> PTO A FO | F8: ='RESUMEN TOTAL'!K11 -> 0 | G8: ='RESUMEN TOTAL'!L11 -> 0 | H8: ='RESUMEN TOTAL'!M11 -> 0 | I8: ='RESUMEN TOTAL'!N11 -> 0 | J8: ='RESUMEN TOTAL'!O11 -> 0 | K8: ='RESUMEN TOTAL'!P11 -> 0 | L8: ='RESUMEN TOTAL'!Q11 -> 0 | M8: ='RESUMEN TOTAL'!R11 -> 0 | ... AI8: ='RESUMEN TOTAL'!AN11 -> 0
A9: ='RESUMEN TOTAL'!A12 -> ALTAMIRA | B9: ='RESUMEN TOTAL'!B12 -> ALT 08 | C9: ='RESUMEN TOTAL'!D12 -> HUMAITA Y NECOCHEA | D9: ='RESUMEN TOTAL'!E12 -> DOMO | E9: ='RESUMEN TOTAL'!F12 -> Fibra Optica | F9: ='RESUMEN TOTAL'!K12 -> 0 | G9: ='RESUMEN TOTAL'!L12 -> 0 | H9: ='RESUMEN TOTAL'!M12 -> 0 | I9: ='RESUMEN TOTAL'!N12 -> 0 | J9: ='RESUMEN TOTAL'!O12 -> 0 | K9: ='RESUMEN TOTAL'!P12 -> 0 | L9: ='RESUMEN TOTAL'!Q12 -> 0 | M9: ='RESUMEN TOTAL'!R12 -> 0 | ... AI9: ='RESUMEN TOTAL'!AN12 -> 0
A10: ='RESUMEN TOTAL'!A13 -> ALTAMIRA | B10: ='RESUMEN TOTAL'!B13 -> ALT 09 | C10: ='RESUMEN TOTAL'!D13 -> NECOCHEA Y CURUPAITY | D10: ='RESUMEN TOTAL'!E13 -> DOMO | E10: ='RESUMEN TOTAL'!F13 -> Fibra Optica | F10: ='RESUMEN TOTAL'!K13 -> 0 | G10: ='RESUMEN TOTAL'!L13 -> 0 | H10: ='RESUMEN TOTAL'!M13 -> 0 | I10: ='RESUMEN TOTAL'!N13 -> 0 | J10: ='RESUMEN TOTAL'!O13 -> 0 | K10: ='RESUMEN TOTAL'!P13 -> 0 | L10: ='RESUMEN TOTAL'!Q13 -> 0 | M10: ='RESUMEN TOTAL'!R13 -> 0 | ... AI10: ='RESUMEN TOTAL'!AN13 -> 0
A11: ='RESUMEN TOTAL'!A14 -> ALTAMIRA | B11: ='RESUMEN TOTAL'!B14 -> ALT 10 | C11: ='RESUMEN TOTAL'!D14 -> Calchaqui y Francia | D11: ='RESUMEN TOTAL'!E14 -> Domo | E11: ='RESUMEN TOTAL'!F14 -> Radio | F11: ='RESUMEN TOTAL'!K14 -> 0 | G11: ='RESUMEN TOTAL'!L14 -> 0 | H11: ='RESUMEN TOTAL'!M14 -> 0 | I11: ='RESUMEN TOTAL'!N14 -> 0 | J11: ='RESUMEN TOTAL'!O14 -> 0 | K11: ='RESUMEN TOTAL'!P14 -> 0 | L11: ='RESUMEN TOTAL'!Q14 -> 0 | M11: ='RESUMEN TOTAL'!R14 -> 0 | ... AI11: ='RESUMEN TOTAL'!AN14 -> 0
A12: ='RESUMEN TOTAL'!A15 -> AGUSTIN RAMIREZ | B12: ='RESUMEN TOTAL'!B15 -> ARA 01 | C12: ='RESUMEN TOTAL'!D15 -> Malambo y Tranquera | D12: ='RESUMEN TOTAL'!E15 -> Domo | E12: ='RESUMEN TOTAL'!F15 -> FIBRA OPTICA | F12: ='RESUMEN TOTAL'!K15 -> 0 | G12: ='RESUMEN TOTAL'!L15 -> 0 | H12: ='RESUMEN TOTAL'!M15 -> 0 | I12: ='RESUMEN TOTAL'!N15 -> 0 | J12: ='RESUMEN TOTAL'!O15 -> 0 | K12: ='RESUMEN TOTAL'!P15 -> 0 | L12: ='RESUMEN TOTAL'!Q15 -> 0 | M12: ='RESUMEN TOTAL'!R15 -> 0 | ... AI12: ='RESUMEN TOTAL'!AN15 -> 0
... A19: ='RESUMEN TOTAL'!A22 -> BOSQUES CENTRO | B19: ='RESUMEN TOTAL'!B22 -> BOSQC 06 | C19: ='RESUMEN TOTAL'!D22 -> LUIS AGOTE Y RUTA 36 | D19: ='RESUMEN TOTAL'!E22 -> Fija | E19: ='RESUMEN TOTAL'!F22 -> Radio | F19: ='RESUMEN TOTAL'!K22 -> 0 | G19: ='RESUMEN TOTAL'!L22 -> 0 | H19: ='RESUMEN TOTAL'!M22 -> 0 | I19: ='RESUMEN TOTAL'!N22 -> 0 | J19: ='RESUMEN TOTAL'!O22 -> 0 | K19: ='RESUMEN TOTAL'!P22 -> 0 | L19: ='RESUMEN TOTAL'!Q22 -> 0 | M19: ='RESUMEN TOTAL'!R22 -> 0 | ... AI19: ='RESUMEN TOTAL'!AN22 -> 0
A20: ='RESUMEN TOTAL'!A265 -> RICARDO ROJAS | B20: ='RESUMEN TOTAL'!B265 -> RRJ 12 | C20: ='RESUMEN TOTAL'!D265 -> FADER Y DIAGONAL LOS POETAS | D20: ='RESUMEN TOTAL'!E265 -> Fija | E20: ='RESUMEN TOTAL'!F265 -> Fibra Optica | F20: ='RESUMEN TOTAL'!K265 -> 0 | G20: ='RESUMEN TOTAL'!L265 -> 0 | H20: ='RESUMEN TOTAL'!M265 -> 0 | I20: ='RESUMEN TOTAL'!N265 -> 0 | J20: ='RESUMEN TOTAL'!O265 -> 0 | K20: ='RESUMEN TOTAL'!P265 -> 0 | L20: ='RESUMEN TOTAL'!Q265 -> 0 | M20: ='RESUMEN TOTAL'!R265 -> 0 | ... AI20: ='RESUMEN TOTAL'!AN265 -> 0
A21: ='RESUMEN TOTAL'!A23 -> CENTRO | B21: ='RESUMEN TOTAL'!B23 -> CEN01 | C21: ='RESUMEN TOTAL'!D23 -> San Martin y 9 de Julio | D21: ='RESUMEN TOTAL'!E23 -> Fija | E21: ='RESUMEN TOTAL'!F23 -> Fibra Optica | F21: ='RESUMEN TOTAL'!K23 -> 0 | G21: ='RESUMEN TOTAL'!L23 -> 0 | H21: ='RESUMEN TOTAL'!M23 -> 0 | I21: ='RESUMEN TOTAL'!N23 -> 0 | J21: ='RESUMEN TOTAL'!O23 -> 0 | K21: ='RESUMEN TOTAL'!P23 -> 0 | L21: ='RESUMEN TOTAL'!Q23 -> 0 | M21: ='RESUMEN TOTAL'!R23 -> 0 | ... AI21: ='RESUMEN TOTAL'!AN23 -> 0
A22: ='RESUMEN TOTAL'!A24 -> CENTRO | B22: ='RESUMEN TOTAL'!B24 -> CEN02 | C22: ='RESUMEN TOTAL'!D24 -> San Martin y Almafuerte | D22: ='RESUMEN TOTAL'!E24 -> Fija | E22: ='RESUMEN TOTAL'!F24 -> Fibra Optica | F22: ='RESUMEN TOTAL'!K24 -> 0 | G22: ='RESUMEN TOTAL'!L24 -> 0 | H22: ='RESUMEN TOTAL'!M24 -> 0 | I22: ='RESUMEN TOTAL'!N24 -> 0 | J22: ='RESUMEN TOTAL'!O24 -> 0 | K22: ='RESUMEN TOTAL'!P24 -> 0 | L22: ='RESUMEN TOTAL'!Q24 -> 0 | M22: ='RESUMEN TOTAL'!R24 -> 0 | ... AI22: ='RESUMEN TOTAL'!AN24 -> 0
A23: ='RESUMEN TOTAL'!A25 -> CENTRO | B23: ='RESUMEN TOTAL'!B25 -> CEN03 | C23: ='RESUMEN TOTAL'!D25 -> San Martin y Sallares | D23: ='RESUMEN TOTAL'!E25 -> Domo | E23: ='RESUMEN TOTAL'!F25 -> Fibra Optica | F23: ='RESUMEN TOTAL'!K25 -> 0 | G23: ='RESUMEN TOTAL'!L25 -> 0 | H23: ='RESUMEN TOTAL'!M25 -> 0 | I23: ='RESUMEN TOTAL'!N25 -> 0 | J23: ='RESUMEN TOTAL'!O25 -> 0 | K23: ='RESUMEN TOTAL'!P25 -> 0 | L23: ='RESUMEN TOTAL'!Q25 -> 0 | M23: ='RESUMEN TOTAL'!R25 -> 0 | ... AI23: ='RESUMEN TOTAL'!AN25 -> 0
A24: ='RESUMEN TOTAL'!A26 -> CENTRO | B24: ='RESUMEN TOTAL'!B26 -> CEN04 | C24: ='RESUMEN TOTAL'!D26 -> San Martin y Contreras | D24: ='RESUMEN TOTAL'!E26 -> Domo | E24: ='RESUMEN TOTAL'!F26 -> Fibra Optica | F24: ='RESUMEN TOTAL'!K26 -> 0 | G24: ='RESUMEN TOTAL'!L26 -> 0 | H24: ='RESUMEN TOTAL'!M26 -> 0 | I24: ='RESUMEN TOTAL'!N26 -> 0 | J24: ='RESUMEN TOTAL'!O26 -> 0 | K24: ='RESUMEN TOTAL'!P26 -> 0 | L24: ='RESUMEN TOTAL'!Q26 -> 0 | M24: ='RESUMEN TOTAL'!R26 -> 0 | ... AI24: ='RESUMEN TOTAL'!AN26 -> 0
A25: ='RESUMEN TOTAL'!A27 -> CENTRO | B25: ='RESUMEN TOTAL'!B27 -> CEN 05 | C25: ='RESUMEN TOTAL'!D27 -> Bocuzzi e/España y San Martin | D25: ='RESUMEN TOTAL'!E27 -> DOMO | E25: ='RESUMEN TOTAL'!F27 -> Fibra Optica | F25: ='RESUMEN TOTAL'!K27 -> 0 | G25: ='RESUMEN TOTAL'!L27 -> 0 | H25: ='RESUMEN TOTAL'!M27 -> 0 | I25: ='RESUMEN TOTAL'!N27 -> 0 | J25: ='RESUMEN TOTAL'!O27 -> 0 | K25: ='RESUMEN TOTAL'!P27 -> 0 | L25: ='RESUMEN TOTAL'!Q27 -> 0 | M25: ='RESUMEN TOTAL'!R27 -> 0 | ... AI25: ='RESUMEN TOTAL'!AN27 -> 0
A26: ='RESUMEN TOTAL'!A28 -> CENTRO | B26: ='RESUMEN TOTAL'!B28 -> CEN06 | C26: ='RESUMEN TOTAL'!D28 -> Monteagudo y A.del Valle | D26: ='RESUMEN TOTAL'!E28 -> Fija | E26: ='RESUMEN TOTAL'!F28 -> Fibra Optica | F26: ='RESUMEN TOTAL'!K28 -> 0 | G26: ='RESUMEN TOTAL'!L28 -> 0 | H26: ='RESUMEN TOTAL'!M28 -> 0 | I26: ='RESUMEN TOTAL'!N28 -> 0 | J26: ='RESUMEN TOTAL'!O28 -> 0 | K26: ='RESUMEN TOTAL'!P28 -> 0 | L26: ='RESUMEN TOTAL'!Q28 -> 0 | M26: ='RESUMEN TOTAL'!R28 -> 0 | ... AI26: ='RESUMEN TOTAL'!AN28 -> 0
A27: ='RESUMEN TOTAL'!A29 -> CENTRO | B27: ='RESUMEN TOTAL'!B29 -> CEN07 | C27: ='RESUMEN TOTAL'!D29 -> San Martin y Guemes | D27: ='RESUMEN TOTAL'!E29 -> DOMO | E27: ='RESUMEN TOTAL'!F29 -> Fibra Optica | F27: ='RESUMEN TOTAL'!K29 -> 0 | G27: ='RESUMEN TOTAL'!L29 -> 0 | H27: ='RESUMEN TOTAL'!M29 -> 0 | I27: ='RESUMEN TOTAL'!N29 -> 0 | J27: ='RESUMEN TOTAL'!O29 -> 0 | K27: ='RESUMEN TOTAL'!P29 -> 0 | L27: ='RESUMEN TOTAL'!Q29 -> 0 | M27: ='RESUMEN TOTAL'!R29 -> 0 | ... AI27: ='RESUMEN TOTAL'!AN29 -> 0
A28: ='RESUMEN TOTAL'!A30 -> CENTRO | B28: ='RESUMEN TOTAL'!B30 -> CEN08 | C28: ='RESUMEN TOTAL'!D30 -> San Martin y Pte.Peron | D28: ='RESUMEN TOTAL'!E30 -> Domo | E28: ='RESUMEN TOTAL'!F30 -> Fibra Optica | F28: ='RESUMEN TOTAL'!K30 -> 0 | G28: ='RESUMEN TOTAL'!L30 -> 0 | H28: ='RESUMEN TOTAL'!M30 -> 0 | I28: ='RESUMEN TOTAL'!N30 -> 0 | J28: ='RESUMEN TOTAL'!O30 -> 0 | K28: ='RESUMEN TOTAL'!P30 -> 0 | L28: ='RESUMEN TOTAL'!Q30 -> 0 | M28: ='RESUMEN TOTAL'!R30 -> 0 | ... AI28: ='RESUMEN TOTAL'!AN30 -> 0
A29: ='RESUMEN TOTAL'!A31 -> CENTRO | B29: ='RESUMEN TOTAL'!B31 -> CEN09 | C29: ='RESUMEN TOTAL'!D31 -> Chacabuco y 25 de Mayo | D29: ='RESUMEN TOTAL'!E31 -> Domo | E29: ='RESUMEN TOTAL'!F31 -> Fibra Optica | F29: ='RESUMEN TOTAL'!K31 -> 0 | G29: ='RESUMEN TOTAL'!L31 -> 0 | H29: ='RESUMEN TOTAL'!M31 -> 0 | I29: ='RESUMEN TOTAL'!N31 -> 0 | J29: ='RESUMEN TOTAL'!O31 -> 0 | K29: ='RESUMEN TOTAL'!P31 -> 0 | L29: ='RESUMEN TOTAL'!Q31 -> 0 | M29: ='RESUMEN TOTAL'!R31 -> 0 | ... AI29: ='RESUMEN TOTAL'!AN31 -> 0
A30: ='RESUMEN TOTAL'!A32 -> CENTRO | B30: ='RESUMEN TOTAL'!B32 -> CEN10 | C30: ='RESUMEN TOTAL'!D32 -> Monteagudo y Pte. Peron | D30: ='RESUMEN TOTAL'!E32 -> Domo | E30: ='RESUMEN TOTAL'!F32 -> Fibra Optica | F30: ='RESUMEN TOTAL'!K32 -> 0 | G30: ='RESUMEN TOTAL'!L32 -> 0 | H30: ='RESUMEN TOTAL'!M32 -> 0 | I30: ='RESUMEN TOTAL'!N32 -> 0 | J30: ='RESUMEN TOTAL'!O32 -> 0 | K30: ='RESUMEN TOTAL'!P32 -> 0 | L30: ='RESUMEN TOTAL'!Q32 -> 0 | M30: ='RESUMEN TOTAL'!R32 -> 0 | ... AI30: ='RESUMEN TOTAL'!AN32 -> 0
A31: ='RESUMEN TOTAL'!A33 -> CENTRO | B31: ='RESUMEN TOTAL'!B33 -> CEN11 | C31: ='RESUMEN TOTAL'!D33 -> Monteagudo y Bocuzzi | D31: ='RESUMEN TOTAL'!E33 -> Domo | E31: ='RESUMEN TOTAL'!F33 -> Fibra Optica | F31: ='RESUMEN TOTAL'!K33 -> 0 | G31: ='RESUMEN TOTAL'!L33 -> 0 | H31: ='RESUMEN TOTAL'!M33 -> 0 | I31: ='RESUMEN TOTAL'!N33 -> 0 | J31: ='RESUMEN TOTAL'!O33 -> 0 | K31: ='RESUMEN TOTAL'!P33 -> 0 | L31: ='RESUMEN TOTAL'!Q33 -> 0 | M31: ='RESUMEN TOTAL'!R33 -> 0 | ... AI31: ='RESUMEN TOTAL'!AN33 -> 0
A32: ='RESUMEN TOTAL'!A34 -> CENTRO | B32: ='RESUMEN TOTAL'!B34 -> CEN 12 | C32: ='RESUMEN TOTAL'!D34 -> Monteagudo y Mitre | D32: ='RESUMEN TOTAL'!E34 -> Domo | E32: ='RESUMEN TOTAL'!F34 -> Fibra Optica | F32: ='RESUMEN TOTAL'!K34 -> 0 | G32: ='RESUMEN TOTAL'!L34 -> 0 | H32: ='RESUMEN TOTAL'!M34 -> 0 | I32: ='RESUMEN TOTAL'!N34 -> 0 | J32: ='RESUMEN TOTAL'!O34 -> 0 | K32: ='RESUMEN TOTAL'!P34 -> 0 | L32: ='RESUMEN TOTAL'!Q34 -> 0 | M32: ='RESUMEN TOTAL'!R34 -> 0 | ... AI32: ='RESUMEN TOTAL'!AN34 -> 0
... A121: ='RESUMEN TOTAL'!A123 -> EL PARQUE | B121: ='RESUMEN TOTAL'!B123 -> EPQ 04 | C121: ='RESUMEN TOTAL'!D123 -> 1282 Y MORENO | D121: ='RESUMEN TOTAL'!E123 -> DOMO | E121: ='RESUMEN TOTAL'!F123 -> Fibra Optica | F121: ='RESUMEN TOTAL'!K123 -> 0 | G121: ='RESUMEN TOTAL'!L123 -> 0 | H121: ='RESUMEN TOTAL'!M123 -> 0 | I121: ='RESUMEN TOTAL'!N123 -> 0 | J121: ='RESUMEN TOTAL'!O123 -> 0 | K121: ='RESUMEN TOTAL'!P123 -> 0 | L121: ='RESUMEN TOTAL'!Q123 -> 0 | M121: ='RESUMEN TOTAL'!R123 -> 0 | ... AI121: ='RESUMEN TOTAL'!AN123 -> 0
A122: ='RESUMEN TOTAL'!A131 -> LA ESMERALDA | B122: ='RESUMEN TOTAL'!B131 -> ESM 08 | C122: ='RESUMEN TOTAL'!D131 -> DAVINSON Y MORANCHEL | D122: ='RESUMEN TOTAL'!E131 -> FIJA | E122: ='RESUMEN TOTAL'!F131 -> Radio | F122: ='RESUMEN TOTAL'!K131 -> 0 | G122: ='RESUMEN TOTAL'!L131 -> 0 | H122: ='RESUMEN TOTAL'!M131 -> 0 | I122: ='RESUMEN TOTAL'!N131 -> 0 | J122: ='RESUMEN TOTAL'!O131 -> 0 | K122: ='RESUMEN TOTAL'!P131 -> 0 | L122: ='RESUMEN TOTAL'!Q131 -> 0 | M122: ='RESUMEN TOTAL'!R131 -> 0 | ... AI122: ='RESUMEN TOTAL'!AN131 -> 0
A123: ='RESUMEN TOTAL'!A124 -> LA ESMERALDA | B123: ='RESUMEN TOTAL'!B124 -> ESM01 | C123: ='RESUMEN TOTAL'!D124 -> Cabello y Brasil | D123: ='RESUMEN TOTAL'!E124 -> Domo | E123: ='RESUMEN TOTAL'!F124 -> Radio | F123: ='RESUMEN TOTAL'!K124 -> 0 | G123: ='RESUMEN TOTAL'!L124 -> 0 | H123: ='RESUMEN TOTAL'!M124 -> 0 | I123: ='RESUMEN TOTAL'!N124 -> 0 | J123: ='RESUMEN TOTAL'!O124 -> 0 | K123: ='RESUMEN TOTAL'!P124 -> 0 | L123: ='RESUMEN TOTAL'!Q124 -> 0 | M123: ='RESUMEN TOTAL'!R124 -> 0 | ... AI123: ='RESUMEN TOTAL'!AN124 -> 0
A124: ='RESUMEN TOTAL'!A125 -> SAN JORGE | B124: ='RESUMEN TOTAL'!B125 -> ESM02 | C124: ='RESUMEN TOTAL'!D125 -> Novak y Cabello | D124: ='RESUMEN TOTAL'!E125 -> Domo | E124: ='RESUMEN TOTAL'!F125 -> PTO A FO | F124: ='RESUMEN TOTAL'!K125 -> 0 | G124: ='RESUMEN TOTAL'!L125 -> 0 | H124: ='RESUMEN TOTAL'!M125 -> 0 | I124: ='RESUMEN TOTAL'!N125 -> 0 | J124: ='RESUMEN TOTAL'!O125 -> 0 | K124: ='RESUMEN TOTAL'!P125 -> 0 | L124: ='RESUMEN TOTAL'!Q125 -> 0 | M124: ='RESUMEN TOTAL'!R125 -> 0 | ... AI124: ='RESUMEN TOTAL'!AN125 -> 0
A125: ='RESUMEN TOTAL'!A126 -> LIBERTAD | B125: ='RESUMEN TOTAL'!B126 -> ESM03 | C125: ='RESUMEN TOTAL'!D126 -> Novak y Humahuaca | D125: ='RESUMEN TOTAL'!E126 -> DOMO | E125: ='RESUMEN TOTAL'!F126 -> PTO A FO | F125: ='RESUMEN TOTAL'!K126 -> 0 | G125: ='RESUMEN TOTAL'!L126 -> 0 | H125: ='RESUMEN TOTAL'!M126 -> 0 | I125: ='RESUMEN TOTAL'!N126 -> 0 | J125: ='RESUMEN TOTAL'!O126 -> 0 | K125: ='RESUMEN TOTAL'!P126 -> 0 | L125: ='RESUMEN TOTAL'!Q126 -> 0 | M125: ='RESUMEN TOTAL'!R126 -> 0 | ... AI125: ='RESUMEN TOTAL'!AN126 -> 0
A126: ='RESUMEN TOTAL'!A127 -> LA ESMERALDA | B126: ='RESUMEN TOTAL'!B127 -> ESM04 | C126: ='RESUMEN TOTAL'!D127 -> Basualdo y Bengochea | D126: ='RESUMEN TOTAL'!E127 -> Domo | E126: ='RESUMEN TOTAL'!F127 -> FIBRA OPTICA | F126: ='RESUMEN TOTAL'!K127 -> 0 | G126: ='RESUMEN TOTAL'!L127 -> 0 | H126: ='RESUMEN TOTAL'!M127 -> 0 | I126: ='RESUMEN TOTAL'!N127 -> 0 | J126: ='RESUMEN TOTAL'!O127 -> 0 | K126: ='RESUMEN TOTAL'!P127 -> 0 | L126: ='RESUMEN TOTAL'!Q127 -> 0 | M126: ='RESUMEN TOTAL'!R127 -> 0 | ... AI126: ='RESUMEN TOTAL'!AN127 -> 0
A127: ='RESUMEN TOTAL'!A128 -> LA ESMERALDA | B127: ='RESUMEN TOTAL'!B128 -> ESM05 | C127: ='RESUMEN TOTAL'!D128 -> Aniceto Diaz y Villar | D127: ='RESUMEN TOTAL'!E128 -> Domo | E127: ='RESUMEN TOTAL'!F128 -> FIBRA OPTICA | F127: ='RESUMEN TOTAL'!K128 -> 0 | G127: ='RESUMEN TOTAL'!L128 -> 0 | H127: ='RESUMEN TOTAL'!M128 -> 0 | I127: ='RESUMEN TOTAL'!N128 -> 0 | J127: ='RESUMEN TOTAL'!O128 -> 0 | K127: ='RESUMEN TOTAL'!P128 -> 0 | L127: ='RESUMEN TOTAL'!Q128 -> 0 | M127: ='RESUMEN TOTAL'!R128 -> 0 | ... AI127: ='RESUMEN TOTAL'!AN128 -> 0
A128: ='RESUMEN TOTAL'!A129 -> LA ESMERALDA | B128: ='RESUMEN TOTAL'!B129 -> ESM06 | C128: ='RESUMEN TOTAL'!D129 -> Roselli y Cabello | D128: ='RESUMEN TOTAL'!E129 -> Domo | E128: ='RESUMEN TOTAL'!F129 -> Radio | F128: ='RESUMEN TOTAL'!K129 -> 0 | G128: ='RESUMEN TOTAL'!L129 -> 0 | H128: ='RESUMEN TOTAL'!M129 -> 0 | I128: ='RESUMEN TOTAL'!N129 -> 0 | J128: ='RESUMEN TOTAL'!O129 -> 0 | K128: ='RESUMEN TOTAL'!P129 -> 0 | L128: ='RESUMEN TOTAL'!Q129 -> 0 | M128: ='RESUMEN TOTAL'!R129 -> 0 | ... AI128: ='RESUMEN TOTAL'!AN129 -> 0
A129: ='RESUMEN TOTAL'!A130 -> LA ESMERALDA | B129: ='RESUMEN TOTAL'!B130 -> ESM07 | C129: ='RESUMEN TOTAL'!D130 -> AV. NOVAK Y SERRANO | D129: ='RESUMEN TOTAL'!E130 -> DOMO | E129: ='RESUMEN TOTAL'!F130 -> PTO A FO | F129: ='RESUMEN TOTAL'!K130 -> 0 | G129: ='RESUMEN TOTAL'!L130 -> 0 | H129: ='RESUMEN TOTAL'!M130 -> 0 | I129: ='RESUMEN TOTAL'!N130 -> 0 | J129: ='RESUMEN TOTAL'!O130 -> 0 | K129: ='RESUMEN TOTAL'!P130 -> 0 | L129: ='RESUMEN TOTAL'!Q130 -> 0 | M129: ='RESUMEN TOTAL'!R130 -> 0 | ... AI129: ='RESUMEN TOTAL'!AN130 -> 0
A130: ='RESUMEN TOTAL'!A132 -> LA ESMERALDA | B130: ='RESUMEN TOTAL'!B132 -> ESM09 (fija 1) | C130: ='RESUMEN TOTAL'!D132 -> EEUU Y CABELLO | D130: ='RESUMEN TOTAL'!E132 -> Fija | E130: ='RESUMEN TOTAL'!F132 -> Fibra Optica | F130: ='RESUMEN TOTAL'!K132 -> 0 | G130: ='RESUMEN TOTAL'!L132 -> 0 | H130: ='RESUMEN TOTAL'!M132 -> 0 | I130: ='RESUMEN TOTAL'!N132 -> 0 | J130: ='RESUMEN TOTAL'!O132 -> 0 | K130: ='RESUMEN TOTAL'!P132 -> 0 | L130: ='RESUMEN TOTAL'!Q132 -> 0 | M130: ='RESUMEN TOTAL'!R132 -> 0 | ... AI130: ='RESUMEN TOTAL'!AN132 -> 0
A131: ='RESUMEN TOTAL'!A133 -> LA ESMERALDA | B131: ='RESUMEN TOTAL'!B133 -> ESM10 (fija 2) | C131: ='RESUMEN TOTAL'!D133 -> EEUU Y CABELLO | D131: ='RESUMEN TOTAL'!E133 -> Fija | E131: ='RESUMEN TOTAL'!F133 -> Fibra Optica | F131: ='RESUMEN TOTAL'!K133 -> 0 | G131: ='RESUMEN TOTAL'!L133 -> 0 | H131: ='RESUMEN TOTAL'!M133 -> 0 | I131: ='RESUMEN TOTAL'!N133 -> 0 | J131: ='RESUMEN TOTAL'!O133 -> 0 | K131: ='RESUMEN TOTAL'!P133 -> 0 | L131: ='RESUMEN TOTAL'!Q133 -> 0 | M131: ='RESUMEN TOTAL'!R133 -> 0 | ... AI131: ='RESUMEN TOTAL'!AN133 -> 0
A132: ='RESUMEN TOTAL'!A134 -> LA ESMERALDA | B132: ='RESUMEN TOTAL'!B134 -> ESM11 (fija 1) | C132: ='RESUMEN TOTAL'!D134 -> NOVAK Y LAMBARDI | D132: ='RESUMEN TOTAL'!E134 -> Fija | E132: ='RESUMEN TOTAL'!F134 -> Fibra Optica | F132: ='RESUMEN TOTAL'!K134 -> 0 | G132: ='RESUMEN TOTAL'!L134 -> 0 | H132: ='RESUMEN TOTAL'!M134 -> 0 | I132: ='RESUMEN TOTAL'!N134 -> 0 | J132: ='RESUMEN TOTAL'!O134 -> 0 | K132: ='RESUMEN TOTAL'!P134 -> 0 | L132: ='RESUMEN TOTAL'!Q134 -> 0 | M132: ='RESUMEN TOTAL'!R134 -> 0 | ... AI132: ='RESUMEN TOTAL'!AN134 -> 0
A133: ='RESUMEN TOTAL'!A135 -> LA ESMERALDA | B133: ='RESUMEN TOTAL'!B135 -> ESM12 (fija 2) | C133: ='RESUMEN TOTAL'!D135 -> NOVAK Y LAMBARDI | D133: ='RESUMEN TOTAL'!E135 -> Fija | E133: ='RESUMEN TOTAL'!F135 -> Fibra Optica | F133: ='RESUMEN TOTAL'!K135 -> 0 | G133: ='RESUMEN TOTAL'!L135 -> 0 | H133: ='RESUMEN TOTAL'!M135 -> 0 | I133: ='RESUMEN TOTAL'!N135 -> 0 | J133: ='RESUMEN TOTAL'!O135 -> 0 | K133: ='RESUMEN TOTAL'!P135 -> 0 | L133: ='RESUMEN TOTAL'!Q135 -> 0 | M133: ='RESUMEN TOTAL'!R135 -> 0 | ... AI133: ='RESUMEN TOTAL'!AN135 -> 0
A134: ='RESUMEN TOTAL'!A136 -> LA ESMERALDA | B134: ='RESUMEN TOTAL'!B136 -> ESM 13 | C134: ='RESUMEN TOTAL'!D136 -> Barzi y Serrano | D134: ='RESUMEN TOTAL'!E136 -> fija | E134: ='RESUMEN TOTAL'!F136 -> Fibra Optica | F134: ='RESUMEN TOTAL'!K136 -> 0 | G134: ='RESUMEN TOTAL'!L136 -> 0 | H134: ='RESUMEN TOTAL'!M136 -> 0 | I134: ='RESUMEN TOTAL'!N136 -> 0 | J134: ='RESUMEN TOTAL'!O136 -> 0 | K134: ='RESUMEN TOTAL'!P136 -> 0 | L134: ='RESUMEN TOTAL'!Q136 -> 0 | M134: ='RESUMEN TOTAL'!R136 -> 0 | ... AI134: ='RESUMEN TOTAL'!AN136 -> 0
...

Sheet APAGADOS
E1: APAGADOS | F1: =COUNTIF(F3:F400, "APAGADO") -> 0 | G1: =COUNTIF(G3:G400, "APAGADO") -> 0 | H1: =COUNTIF(H3:H500, "APAGADO") -> 0 | I1: =COUNTIF(I3:I400, "APAGADO") -> 0 | J1: =COUNTIF(J3:J400, "APAGADO") -> 0 | K1: =COUNTIF(K3:K400, "APAGADO") -> 0 | L1: =COUNTIF(L3:L400, "APAGADO") -> 0 | M1: =COUNTIF(M3:M400, "APAGADO") -> 0 | N1: =COUNTIF(N3:N400, "APAGADO") -> 0 | O1: =COUNTIF(O3:O400, "APAGADO") -> 0 | P1: =COUNTIF(P3:P400, "APAGADO") -> 0 | ... AD1: =COUNTIF(AD3:AD400, "APAGADO") -> 0 | AE1: =COUNTIF(AE3:AE500, "APAGADO") -> 0 | AF1: =COUNTIF(AF3:AF400, "APAGADO") -> 0 | AG1: =COUNTIF(AG3:AG400, "APAGADO") -> 0 | AH1: =COUNTIF(AH3:AH400, "APAGADO") -> 0 | AI1: =COUNTIF(AI3:AI400, "APAGADO") -> 0
A2: =ESTADISTICA!A1 -> Barrio | B2: =ESTADISTICA!B1 -> [Denominacion] | C2: =ESTADISTICA!C1 -> [Ubicacion] | D2: =ESTADISTICA!D1 -> [Tipo de Camara] | E2: =ESTADISTICA!E1 -> [Tipo de Conexion] | F2: =ESTADISTICA!F1 -> 44927 | G2: =ESTADISTICA!G1 -> 44928 | H2: =ESTADISTICA!H1 -> 44929 | ... AI2: =ESTADISTICA!AI1 -> 44956
A3: =ESTADISTICA!A2 -> ALTAMIRA | B3: =ESTADISTICA!B2 -> ALT01 | C3: =ESTADISTICA!C2 -> Calchaqui y Sgto. Cabral | D3: =ESTADISTICA!D2 -> Domo | E3: =ESTADISTICA!E2 -> Fibra Optica | F3: =ESTADISTICA!F2 -> 0 | G3: =ESTADISTICA!G2 -> 0 | H3: =ESTADISTICA!H2 -> 0 | ... AI3: =ESTADISTICA!AI2 -> 0
A4: =ESTADISTICA!A3 -> ALTAMIRA | B4: =ESTADISTICA!B3 -> ALT02 | C4: =ESTADISTICA!C3 -> Calchaqui y Lope de Vega | D4: =ESTADISTICA!D3 -> Domo | E4: =ESTADISTICA!E3 -> PTO A FO | F4: =ESTADISTICA!F3 -> 0 | G4: =ESTADISTICA!G3 -> 0 | H4: =ESTADISTICA!H3 -> 0 | ... AI4: =ESTADISTICA!AI3 -> 0
A5: =ESTADISTICA!A4 -> ALTAMIRA | B5: =ESTADISTICA!B4 -> ALT 03 | C5: =ESTADISTICA!C4 -> Bombero Galarza y Necochea | D5: =ESTADISTICA!D4 -> Domo | E5: =ESTADISTICA!E4 -> FIBRA OPTICA | F5: =ESTADISTICA!F4 -> 0 | G5: =ESTADISTICA!G4 -> 0 | H5: =ESTADISTICA!H4 -> 0 | ... AI5: =ESTADISTICA!AI4 -> 0
A6: =ESTADISTICA!A5 -> ALTAMIRA | B6: =ESTADISTICA!B5 -> ALT 04 | C6: =ESTADISTICA!C5 -> Francia y Necochea | D6: =ESTADISTICA!D5 -> Domo | E6: =ESTADISTICA!E5 -> FIBRA OPTICA | F6: =ESTADISTICA!F5 -> 0 | G6: =ESTADISTICA!G5 -> 0 | H6: =ESTADISTICA!H5 -> 0 | ... AI6: =ESTADISTICA!AI5 -> 0
A7: =ESTADISTICA!A6 -> ALTAMIRA | B7: =ESTADISTICA!B6 -> ALT05 | C7: =ESTADISTICA!C6 -> Av. Calchaqui y Bombero Galarza | D7: =ESTADISTICA!D6 -> Domo | E7: =ESTADISTICA!E6 -> PTO A FO | F7: =ESTADISTICA!F6 -> 0 | G7: =ESTADISTICA!G6 -> 0 | H7: =ESTADISTICA!H6 -> 0 | ... AI7: =ESTADISTICA!AI6 -> 0
A8: =ESTADISTICA!A7 -> ALTAMIRA | B8: =ESTADISTICA!B7 -> ALT 06 | C8: =ESTADISTICA!C7 -> LOPE DE VEGA Y NECOCHEA | D8: =ESTADISTICA!D7 -> Domo | E8: =ESTADISTICA!E7 -> PTO A FO | F8: =ESTADISTICA!F7 -> 0 | G8: =ESTADISTICA!G7 -> 0 | H8: =ESTADISTICA!H7 -> 0 | ... AI8: =ESTADISTICA!AI7 -> 0
A9: =ESTADISTICA!A8 -> ALTAMIRA | B9: =ESTADISTICA!B8 -> ALT07 | C9: =ESTADISTICA!C8 -> AV. CALCHAQUI Y AV. DEL TRABAJO | D9: =ESTADISTICA!D8 -> DOMO | E9: =ESTADISTICA!E8 -> PTO A FO | F9: =ESTADISTICA!F8 -> 0 | G9: =ESTADISTICA!G8 -> 0 | H9: =ESTADISTICA!H8 -> 0 | ... AI9: =ESTADISTICA!AI8 -> 0
A10: =ESTADISTICA!A9 -> ALTAMIRA | B10: =ESTADISTICA!B9 -> ALT 08 | C10: =ESTADISTICA!C9 -> HUMAITA Y NECOCHEA | D10: =ESTADISTICA!D9 -> DOMO | E10: =ESTADISTICA!E9 -> Fibra Optica | F10: =ESTADISTICA!F9 -> 0 | G10: =ESTADISTICA!G9 -> 0 | H10: =ESTADISTICA!H9 -> 0 | ... AI10: =ESTADISTICA!AI9 -> 0
A11: =ESTADISTICA!A10 -> ALTAMIRA | B11: =ESTADISTICA!B10 -> ALT 09 | C11: =ESTADISTICA!C10 -> NECOCHEA Y CURUPAITY | D11: =ESTADISTICA!D10 -> DOMO | E11: =ESTADISTICA!E10 -> Fibra Optica | F11: =ESTADISTICA!F10 -> 0 | G11: =ESTADISTICA!G10 -> 0 | H11: =ESTADISTICA!H10 -> 0 | ... AI11: =ESTADISTICA!AI10 -> 0
A12: =ESTADISTICA!A11 -> ALTAMIRA | B12: =ESTADISTICA!B11 -> ALT 10 | C12: =ESTADISTICA!C11 -> Calchaqui y Francia | D12: =ESTADISTICA!D11 -> Domo | E12: =ESTADISTICA!E11 -> Radio | F12: =ESTADISTICA!F11 -> 0 | G12: =ESTADISTICA!G11 -> 0 | H12: =ESTADISTICA!H11 -> 0 | ... AI12: =ESTADISTICA!AI11 -> 0
A13: =ESTADISTICA!A12 -> AGUSTIN RAMIREZ | B13: =ESTADISTICA!B12 -> ARA 01 | C13: =ESTADISTICA!C12 -> Malambo y Tranquera | D13: =ESTADISTICA!D12 -> Domo | E13: =ESTADISTICA!E12 -> FIBRA OPTICA | F13: =ESTADISTICA!F12 -> 0 | G13: =ESTADISTICA!G12 -> 0 | H13: =ESTADISTICA!H12 -> 0 | ... AI13: =ESTADISTICA!AI12 -> 0
... A513: =ESTADISTICA!A512 -> 0 | B513: =ESTADISTICA!B512 -> 0 | C513: =ESTADISTICA!C512 -> 0 | D513: =ESTADISTICA!D512 -> 0 | E513: =ESTADISTICA!E512 -> 0 | F513: =ESTADISTICA!F512 -> 0 | G513: =ESTADISTICA!G512 -> 0 | H513: =ESTADISTICA!H512 -> 0 | ... AI513: =ESTADISTICA!AI512 -> 0

Sheet APAGADOS FIBRA
C1: TOTAL FIBRA | D1: =COUNTIFS(E4:E400,"=Fibra Optica") -> 267
E2: APAGADOS | F2: =COUNTIFS(F4:F500, "=APAGADO",E4:E500,"=Fibra Optica") -> 0 | G2: =COUNTIFS(G4:G500, "=APAGADO",E4:E500,"=Fibra Optica") -> 0 | H2: =COUNTIFS(H4:H500, "=APAGADO",E4:E500,"=Fibra Optica") -> 0 | I2: =COUNTIFS(I4:I500, "=APAGADO",E4:E500,"=Fibra Optica") -> 0 | J2: =COUNTIFS(J4:J500, "=APAGADO",E4:E500,"=Fibra Optica") -> 0 | K2: =COUNTIFS(K4:K500, "=APAGADO",E4:E500,"=Fibra Optica") -> 0 | L2: =COUNTIFS(L4:L500, "=APAGADO",E4:E500,"=Fibra Optica") -> 0 | M2: =COUNTIFS(M4:M500, "=APAGADO",E4:E500,"=Fibra Optica") -> 0 | N2: =COUNTIFS(N4:N500, "=APAGADO",E4:E500,"=Fibra Optica") -> 0 | O2: =COUNTIFS(O4:O500, "=APAGADO",E4:E500,"=Fibra Optica") -> 0 | P2: =COUNTIFS(P4:P500, "=APAGADO",E4:E500,"=Fibra Optica") -> 0 | Q2: =COUNTIFS(Q4:Q500, "=APAGADO",E4:E500,"=Fibra Optica") -> 2 | R2: =COUNTIFS(R4:R500, "=APAGADO",E4:E500,"=Fibra Optica") -> 0 | S2: =COUNTIFS(S4:S500, "=APAGADO",E4:E500,"=Fibra Optica") -> 0 | T2: =COUNTIFS(T4:T500, "=APAGADO",E4:E500,"=Fibra Optica") -> 7 | U2: =COUNTIFS(U4:U500, "=APAGADO",E4:E500,"=Fibra Optica") -> 0 | V2: =COUNTIFS(V4:V500, "=APAGADO",E4:E500,"=Fibra Optica") -> 0 | W2: =COUNTIFS(W4:W500, "=APAGADO",E4:E500,"=Fibra Optica") -> 0 | X2: =COUNTIFS(X4:X500, "=APAGADO",E4:E500,"=Fibra Optica") -> 0 | Y2: =COUNTIFS(Y4:Y500, "=APAGADO",E4:E500,"=Fibra Optica") -> 0 | Z2: =COUNTIFS(Z4:Z500, "=APAGADO",E4:E500,"=Fibra Optica") -> 0 | AA2: =COUNTIFS(AA4:AA500, "=APAGADO",E4:E500,"=Fibra Optica") -> 0 | AB2: =COUNTIFS(AB4:AB500, "=APAGADO",E4:E500,"=Fibra Optica") -> 0 | AC2: =COUNTIFS(AC4:AC500, "=APAGADO",E4:E500,"=Fibra Optica") -> 0 | AD2: =COUNTIFS(AD4:AD500, "=APAGADO",E4:E500,"=Fibra Optica") -> 0 | AE2: =COUNTIFS(AE4:AE500, "=APAGADO",E4:E500,"=Fibra Optica") -> 0 | AF2: =COUNTIFS(AF4:AF500, "=APAGADO",E4:E500,"=Fibra Optica") -> 0 | AG2: =COUNTIFS(AG4:AG500, "=APAGADO",E4:E500,"=Fibra Optica") -> 0 | AH2: =COUNTIFS(AH4:AH500, "=APAGADO",E4:E500,"=Fibra Optica") -> 0 | AI2: =COUNTIFS(AI4:AI400, "=APAGADO",E4:E400,"=Fibra Optica") -> 0
A3: =ESTADISTICA!A1 -> Barrio | B3: =ESTADISTICA!B1 -> [Denominacion] | C3: =ESTADISTICA!C1 -> [Ubicacion] | D3: =ESTADISTICA!D1 -> [Tipo de Camara] | E3: =ESTADISTICA!E1 -> [Tipo de Conexion] | F3: =ESTADISTICA!F1 -> 44927 | G3: =ESTADISTICA!G1 -> 44928 | H3: =ESTADISTICA!H1 -> 44929 | ... AI3: =ESTADISTICA!AI1 -> 44956
A4: =ESTADISTICA!A2 -> ALTAMIRA | B4: =ESTADISTICA!B2 -> ALT01 | C4: =ESTADISTICA!C2 -> Calchaqui y Sgto. Cabral | D4: =ESTADISTICA!D2 -> Domo | E4: =ESTADISTICA!E2 -> Fibra Optica | F4: =ESTADISTICA!F2 -> 0 | G4: =ESTADISTICA!G2 -> 0 | H4: =ESTADISTICA!H2 -> 0 | ... AI4: =ESTADISTICA!AI2 -> 0
A5: =ESTADISTICA!A3 -> ALTAMIRA | B5: =ESTADISTICA!B3 -> ALT02 | C5: =ESTADISTICA!C3 -> Calchaqui y Lope de Vega | D5: =ESTADISTICA!D3 -> Domo | E5: =ESTADISTICA!E3 -> PTO A FO | F5: =ESTADISTICA!F3 -> 0 | G5: =ESTADISTICA!G3 -> 0 | H5: =ESTADISTICA!H3 -> 0 | ... AI5: =ESTADISTICA!AI3 -> 0
A6: =ESTADISTICA!A4 -> ALTAMIRA | B6: =ESTADISTICA!B4 -> ALT 03 | C6: =ESTADISTICA!C4 -> Bombero Galarza y Necochea | D6: =ESTADISTICA!D4 -> Domo | E6: =ESTADISTICA!E4 -> FIBRA OPTICA | F6: =ESTADISTICA!F4 -> 0 | G6: =ESTADISTICA!G4 -> 0 | H6: =ESTADISTICA!H4 -> 0 | ... AI6: =ESTADISTICA!AI4 -> 0
A7: =ESTADISTICA!A5 -> ALTAMIRA | B7: =ESTADISTICA!B5 -> ALT 04 | C7: =ESTADISTICA!C5 -> Francia y Necochea | D7: =ESTADISTICA!D5 -> Domo | E7: =ESTADISTICA!E5 -> FIBRA OPTICA | F7: =ESTADISTICA!F5 -> 0 | G7: =ESTADISTICA!G5 -> 0 | H7: =ESTADISTICA!H5 -> 0 | ... AI7: =ESTADISTICA!AI5 -> 0
A8: =ESTADISTICA!A6 -> ALTAMIRA | B8: =ESTADISTICA!B6 -> ALT05 | C8: =ESTADISTICA!C6 -> Av. Calchaqui y Bombero Galarza | D8: =ESTADISTICA!D6 -> Domo | E8: =ESTADISTICA!E6 -> PTO A FO | F8: =ESTADISTICA!F6 -> 0 | G8: =ESTADISTICA!G6 -> 0 | H8: =ESTADISTICA!H6 -> 0 | ... AI8: =ESTADISTICA!AI6 -> 0
A9: =ESTADISTICA!A7 -> ALTAMIRA | B9: =ESTADISTICA!B7 -> ALT 06 | C9: =ESTADISTICA!C7 -> LOPE DE VEGA Y NECOCHEA | D9: =ESTADISTICA!D7 -> Domo | E9: =ESTADISTICA!E7 -> PTO A FO | F9: =ESTADISTICA!F7 -> 0 | G9: =ESTADISTICA!G7 -> 0 | H9: =ESTADISTICA!H7 -> 0 | ... AI9: =ESTADISTICA!AI7 -> 0
A10: =ESTADISTICA!A8 -> ALTAMIRA | B10: =ESTADISTICA!B8 -> ALT07 | C10: =ESTADISTICA!C8 -> AV. CALCHAQUI Y AV. DEL TRABAJO | D10: =ESTADISTICA!D8 -> DOMO | E10: =ESTADISTICA!E8 -> PTO A FO | F10: =ESTADISTICA!F8 -> 0 | G10: =ESTADISTICA!G8 -> 0 | H10: =ESTADISTICA!H8 -> 0 | ... AI10: =ESTADISTICA!AI8 -> 0
A11: =ESTADISTICA!A9 -> ALTAMIRA | B11: =ESTADISTICA!B9 -> ALT 08 | C11: =ESTADISTICA!C9 -> HUMAITA Y NECOCHEA | D11: =ESTADISTICA!D9 -> DOMO | E11: =ESTADISTICA!E9 -> Fibra Optica | F11: =ESTADISTICA!F9 -> 0 | G11: =ESTADISTICA!G9 -> 0 | H11: =ESTADISTICA!H9 -> 0 | ... AI11: =ESTADISTICA!AI9 -> 0
A12: =ESTADISTICA!A10 -> ALTAMIRA | B12: =ESTADISTICA!B10 -> ALT 09 | C12: =ESTADISTICA!C10 -> NECOCHEA Y CURUPAITY | D12: =ESTADISTICA!D10 -> DOMO | E12: =ESTADISTICA!E10 -> Fibra Optica | F12: =ESTADISTICA!F10 -> 0 | G12: =ESTADISTICA!G10 -> 0 | H12: =ESTADISTICA!H10 -> 0 | ... AI12: =ESTADISTICA!AI10 -> 0
A13: =ESTADISTICA!A11 -> ALTAMIRA | B13: =ESTADISTICA!B11 -> ALT 10 | C13: =ESTADISTICA!C11 -> Calchaqui y Francia | D13: =ESTADISTICA!D11 -> Domo | E13: =ESTADISTICA!E11 -> Radio | F13: =ESTADISTICA!F11 -> 0 | G13: =ESTADISTICA!G11 -> 0 | H13: =ESTADISTICA!H11 -> 0 | ... AI13: =ESTADISTICA!AI11 -> 0
A14: =ESTADISTICA!A12 -> AGUSTIN RAMIREZ | B14: =ESTADISTICA!B12 -> ARA 01 | C14: =ESTADISTICA!C12 -> Malambo y Tranquera | D14: =ESTADISTICA!D12 -> Domo | E14: =ESTADISTICA!E12 -> FIBRA OPTICA | F14: =ESTADISTICA!F12 -> 0 | G14: =ESTADISTICA!G12 -> 0 | H14: =ESTADISTICA!H12 -> 0 | ... AI14: =ESTADISTICA!AI12 -> 0
... A601: =ESTADISTICA!A599 -> 0 | B601: =ESTADISTICA!B599 -> 0 | C601: =ESTADISTICA!C599 -> 0 | D601: =ESTADISTICA!D599 -> 0 | E601: =ESTADISTICA!E599 -> 0 | F601: =ESTADISTICA!F599 -> 0 | G601: =ESTADISTICA!G599 -> 0 | H601: =ESTADISTICA!H599 -> 0 | ... AI601: =ESTADISTICA!AI599 -> 0

Sheet APAGADOS ANTENA
C1: TOTAL PTO A FO
E2: APAGADOS | F2: =COUNTIFS(F4:F500, "=APAGADO",E4:E500,"=PTO A FO") -> 0 | G2: =COUNTIFS(G4:G500, "=APAGADO",E4:E500,"=PTO A FO") -> 0 | H2: =COUNTIFS(H4:H500, "=APAGADO",E4:E500,"=PTO A FO") -> 0 | I2: =COUNTIFS(I4:I500, "=APAGADO",E4:E500,"=PTO A FO") -> 0 | J2: =COUNTIFS(J4:J500, "=APAGADO",E4:E500,"=PTO A FO") -> 0 | K2: =COUNTIFS(K4:K500, "=APAGADO",E4:E500,"=PTO A FO") -> 0 | L2: =COUNTIFS(L4:L500, "=APAGADO",E4:E500,"=PTO A FO") -> 0 | M2: =COUNTIFS(M4:M500, "=APAGADO",E4:E500,"=PTO A FO") -> 0 | N2: =COUNTIFS(N4:N500, "=APAGADO",E4:E500,"=PTO A FO") -> 0 | O2: =COUNTIFS(O4:O500, "=APAGADO",E4:E500,"=PTO A FO") -> 0 | P2: =COUNTIFS(P4:P500, "=APAGADO",E4:E500,"=PTO A FO") -> 0 | Q2: =COUNTIFS(Q4:Q500, "=APAGADO",E4:E500,"=PTO A FO") -> 1 | R2: =COUNTIFS(R4:R500, "=APAGADO",E4:E500,"=PTO A FO") -> 0 | S2: =COUNTIFS(S4:S500, "=APAGADO",E4:E500,"=PTO A FO") -> 0 | T2: =COUNTIFS(T4:T500, "=APAGADO",E4:E500,"=PTO A FO") -> 2 | U2: =COUNTIFS(U4:U500, "=APAGADO",E4:E500,"=PTO A FO") -> 0 | V2: =COUNTIFS(V4:V500, "=APAGADO",E4:E500,"=PTO A FO") -> 0 | W2: =COUNTIFS(W4:W500, "=APAGADO",E4:E500,"=PTO A FO") -> 0 | X2: =COUNTIFS(X4:X500, "=APAGADO",E4:E500,"=PTO A FO") -> 0 | Y2: =COUNTIFS(Y4:Y500, "=APAGADO",E4:E500,"=PTO A FO") -> 0 | Z2: =COUNTIFS(Z4:Z500, "=APAGADO",E4:E500,"=PTO A FO") -> 0 | AA2: =COUNTIFS(AA4:AA500, "=APAGADO",E4:E500,"=PTO A FO") -> 0 | AB2: =COUNTIFS(AB4:AB500, "=APAGADO",E4:E500,"=PTO A FO") -> 0 | AC2: =COUNTIFS(AC4:AC500, "=APAGADO",E4:E500,"=PTO A FO") -> 0 | AD2: =COUNTIFS(AD4:AD500, "=APAGADO",E4:E500,"=PTO A FO") -> 0 | AE2: =COUNTIFS(AE4:AE500, "=APAGADO",E4:E500,"=PTO A FO") -> 0 | AF2: =COUNTIFS(AF4:AF500, "=APAGADO",E4:E500,"=PTO A FO") -> 0 | AG2: =COUNTIFS(AG4:AG500, "=APAGADO",E4:E500,"=PTO A FO") -> 0 | AH2: =COUNTIFS(AH4:AH500, "=APAGADO",E4:E500,"=PTO A FO") -> 0 | AI2: =COUNTIFS(AI4:AI500, "=APAGADO",E4:E500,"=PTO A FO") -> 0
A3: =ESTADISTICA!A1 -> Barrio | B3: =ESTADISTICA!B1 -> [Denominacion] | C3: =ESTADISTICA!C1 -> [Ubicacion] | D3: =ESTADISTICA!D1 -> [Tipo de Camara] | E3: =ESTADISTICA!E1 -> [Tipo de Conexion] | F3: =ESTADISTICA!F1 -> 44927 | G3: =ESTADISTICA!G1 -> 44928 | H3: =ESTADISTICA!H1 -> 44929 | ... AI3: =ESTADISTICA!AI1 -> 44956
A4: =ESTADISTICA!A2 -> ALTAMIRA | B4: =ESTADISTICA!B2 -> ALT01 | C4: =ESTADISTICA!C2 -> Calchaqui y Sgto. Cabral | D4: =ESTADISTICA!D2 -> Domo | E4: =ESTADISTICA!E2 -> Fibra Optica | F4: =ESTADISTICA!F2 -> 0 | G4: =ESTADISTICA!G2 -> 0 | H4: =ESTADISTICA!H2 -> 0 | ... AI4: =ESTADISTICA!AI2 -> 0
A5: =ESTADISTICA!A3 -> ALTAMIRA | B5: =ESTADISTICA!B3 -> ALT02 | C5: =ESTADISTICA!C3 -> Calchaqui y Lope de Vega | D5: =ESTADISTICA!D3 -> Domo | E5: =ESTADISTICA!E3 -> PTO A FO | F5: =ESTADISTICA!F3 -> 0 | G5: =ESTADISTICA!G3 -> 0 | H5: =ESTADISTICA!H3 -> 0 | ... AI5: =ESTADISTICA!AI3 -> 0
A6: =ESTADISTICA!A4 -> ALTAMIRA | B6: =ESTADISTICA!B4 -> ALT 03 | C6: =ESTADISTICA!C4 -> Bombero Galarza y Necochea | D6: =ESTADISTICA!D4 -> Domo | E6: =ESTADISTICA!E4 -> FIBRA OPTICA | F6: =ESTADISTICA!F4 -> 0 | G6: =ESTADISTICA!G4 -> 0 | H6: =ESTADISTICA!H4 -> 0 | ... AI6: =ESTADISTICA!AI4 -> 0
A7: =ESTADISTICA!A5 -> ALTAMIRA | B7: =ESTADISTICA!B5 -> ALT 04 | C7: =ESTADISTICA!C5 -> Francia y Necochea | D7: =ESTADISTICA!D5 -> Domo | E7: =ESTADISTICA!E5 -> FIBRA OPTICA | F7: =ESTADISTICA!F5 -> 0 | G7: =ESTADISTICA!G5 -> 0 | H7: =ESTADISTICA!H5 -> 0 | ... AI7: =ESTADISTICA!AI5 -> 0
A8: =ESTADISTICA!A6 -> ALTAMIRA | B8: =ESTADISTICA!B6 -> ALT05 | C8: =ESTADISTICA!C6 -> Av. Calchaqui y Bombero Galarza | D8: =ESTADISTICA!D6 -> Domo | E8: =ESTADISTICA!E6 -> PTO A FO | F8: =ESTADISTICA!F6 -> 0 | G8: =ESTADISTICA!G6 -> 0 | H8: =ESTADISTICA!H6 -> 0 | ... AI8: =ESTADISTICA!AI6 -> 0
A9: =ESTADISTICA!A7 -> ALTAMIRA | B9: =ESTADISTICA!B7 -> ALT 06 | C9: =ESTADISTICA!C7 -> LOPE DE VEGA Y NECOCHEA | D9: =ESTADISTICA!D7 -> Domo | E9: =ESTADISTICA!E7 -> PTO A FO | F9: =ESTADISTICA!F7 -> 0 | G9: =ESTADISTICA!G7 -> 0 | H9: =ESTADISTICA!H7 -> 0 | ... AI9: =ESTADISTICA!AI7 -> 0
A10: =ESTADISTICA!A8 -> ALTAMIRA | B10: =ESTADISTICA!B8 -> ALT07 | C10: =ESTADISTICA!C8 -> AV. CALCHAQUI Y AV. DEL TRABAJO | D10: =ESTADISTICA!D8 -> DOMO | E10: =ESTADISTICA!E8 -> PTO A FO | F10: =ESTADISTICA!F8 -> 0 | G10: =ESTADISTICA!G8 -> 0 | H10: =ESTADISTICA!H8 -> 0 | ... AI10: =ESTADISTICA!AI8 -> 0
A11: =ESTADISTICA!A9 -> ALTAMIRA | B11: =ESTADISTICA!B9 -> ALT 08 | C11: =ESTADISTICA!C9 -> HUMAITA Y NECOCHEA | D11: =ESTADISTICA!D9 -> DOMO | E11: =ESTADISTICA!E9 -> Fibra Optica | F11: =ESTADISTICA!F9 -> 0 | G11: =ESTADISTICA!G9 -> 0 | H11: =ESTADISTICA!H9 -> 0 | ... AI11: =ESTADISTICA!AI9 -> 0
A12: =ESTADISTICA!A10 -> ALTAMIRA | B12: =ESTADISTICA!B10 -> ALT 09 | C12: =ESTADISTICA!C10 -> NECOCHEA Y CURUPAITY | D12: =ESTADISTICA!D10 -> DOMO | E12: =ESTADISTICA!E10 -> Fibra Optica | F12: =ESTADISTICA!F10 -> 0 | G12: =ESTADISTICA!G10 -> 0 | H12: =ESTADISTICA!H10 -> 0 | ... AI12: =ESTADISTICA!AI10 -> 0
A13: =ESTADISTICA!A11 -> ALTAMIRA | B13: =ESTADISTICA!B11 -> ALT 10 | C13: =ESTADISTICA!C11 -> Calchaqui y Francia | D13: =ESTADISTICA!D11 -> Domo | E13: =ESTADISTICA!E11 -> Radio | F13: =ESTADISTICA!F11 -> 0 | G13: =ESTADISTICA!G11 -> 0 | H13: =ESTADISTICA!H11 -> 0 | ... AI13: =ESTADISTICA!AI11 -> 0
A14: =ESTADISTICA!A12 -> AGUSTIN RAMIREZ | B14: =ESTADISTICA!B12 -> ARA 01 | C14: =ESTADISTICA!C12 -> Malambo y Tranquera | D14: =ESTADISTICA!D12 -> Domo | E14: =ESTADISTICA!E12 -> FIBRA OPTICA | F14: =ESTADISTICA!F12 -> 0 | G14: =ESTADISTICA!G12 -> 0 | H14: =ESTADISTICA!H12 -> 0 | ... AI14: =ESTADISTICA!AI12 -> 0
... A539: =ESTADISTICA!A537 -> 0 | B539: =ESTADISTICA!B537 -> 0 | C539: =ESTADISTICA!C537 -> 0 | D539: =ESTADISTICA!D537 -> 0 | E539: =ESTADISTICA!E537 -> 0 | F539: =ESTADISTICA!F537 -> 0 | G539: =ESTADISTICA!G537 -> 0 | H539: =ESTADISTICA!H537 -> 0 | ... AI539: =ESTADISTICA!AI537 -> 0

Sheet APAGADOS RADIO
C1: TOTAL RADIO | D1: =COUNTIFS(E4:E400,"=radio") -> 94
E2: APAGADOS | F2: =COUNTIFS(F4:F500, "=APAGADO",E4:E500,"=radio") -> 0 | G2: =COUNTIFS(G4:G500, "=APAGADO",E4:E500,"=radio") -> 0 | H2: =COUNTIFS(H4:H500, "=APAGADO",E4:E500,"=radio") -> 0 | I2: =COUNTIFS(I4:I500, "=APAGADO",E4:E500,"=radio") -> 0 | J2: =COUNTIFS(J4:J500, "=APAGADO",E4:E500,"=radio") -> 0 | K2: =COUNTIFS(K4:K500, "=APAGADO",E4:E500,"=radio") -> 0 | L2: =COUNTIFS(L4:L500, "=APAGADO",E4:E500,"=radio") -> 0 | M2: =COUNTIFS(M4:M500, "=APAGADO",E4:E500,"=radio") -> 0 | N2: =COUNTIFS(N4:N500, "=APAGADO",E4:E500,"=radio") -> 0 | O2: =COUNTIFS(O4:O500, "=APAGADO",E4:E500,"=radio") -> 0 | P2: =COUNTIFS(P4:P500, "=APAGADO",E4:E500,"=radio") -> 0 | Q2: =COUNTIFS(Q4:Q367, "=APAGADO",E4:E367,"=radio") -> 0 | R2: =COUNTIFS(R4:R500, "=APAGADO",E4:E500,"=radio") -> 0 | S2: =COUNTIFS(S4:S500, "=APAGADO",E4:E500,"=radio") -> 0 | T2: =COUNTIFS(T4:T500, "=APAGADO",E4:E500,"=radio") -> 0 | U2: =COUNTIFS(U4:U500, "=APAGADO",E4:E500,"=radio") -> 0 | V2: =COUNTIFS(V4:V500, "=APAGADO",E4:E500,"=radio") -> 0 | W2: =COUNTIFS(W4:W500, "=APAGADO",E4:E500,"=radio") -> 0 | X2: =COUNTIFS(X4:X500, "=APAGADO",E4:E500,"=radio") -> 0 | Y2: =COUNTIFS(Y4:Y500, "=APAGADO",E4:E500,"=radio") -> 0 | Z2: =COUNTIFS(Z4:Z500, "=APAGADO",E4:E500,"=radio") -> 0 | AA2: =COUNTIFS(AA4:AA500, "=APAGADO",E4:E500,"=radio") -> 0 | AB2: =COUNTIFS(AB4:AB500, "=APAGADO",E4:E500,"=radio") -> 0 | AC2: =COUNTIFS(AC4:AC500, "=APAGADO",E4:E500,"=radio") -> 0 | AD2: =COUNTIFS(AD4:AD500, "=APAGADO",E4:E500,"=radio") -> 0 | AE2: =COUNTIFS(AE4:AE500, "=APAGADO",E4:E500,"=radio") -> 0 | AF2: =COUNTIFS(AF4:AF500, "=APAGADO",E4:E500,"=radio") -> 0 | AG2: =COUNTIFS(AG4:AG500, "=APAGADO",E4:E500,"=radio") -> 0 | AH2: =COUNTIFS(AH4:AH500, "=APAGADO",E4:E500,"=radio") -> 0 | AI2: =COUNTIFS(AI4:AI500, "=APAGADO",E4:E500,"=radio") -> 0
A3: =ESTADISTICA!A1 -> Barrio | B3: =ESTADISTICA!B1 -> [Denominacion] | C3: =ESTADISTICA!C1 -> [Ubicacion] | D3: =ESTADISTICA!D1 -> [Tipo de Camara] | E3: =ESTADISTICA!E1 -> [Tipo de Conexion] | F3: =ESTADISTICA!F1 -> 44927 | G3: =ESTADISTICA!G1 -> 44928 | H3: =ESTADISTICA!H1 -> 44929 | ... AI3: =ESTADISTICA!AI1 -> 44956
A4: =ESTADISTICA!A2 -> ALTAMIRA | B4: =ESTADISTICA!B2 -> ALT01 | C4: =ESTADISTICA!C2 -> Calchaqui y Sgto. Cabral | D4: =ESTADISTICA!D2 -> Domo | E4: =ESTADISTICA!E2 -> Fibra Optica | F4: =ESTADISTICA!F2 -> 0 | G4: =ESTADISTICA!G2 -> 0 | H4: =ESTADISTICA!H2 -> 0 | ... AI4: =ESTADISTICA!AI2 -> 0
A5: =ESTADISTICA!A3 -> ALTAMIRA | B5: =ESTADISTICA!B3 -> ALT02 | C5: =ESTADISTICA!C3 -> Calchaqui y Lope de Vega | D5: =ESTADISTICA!D3 -> Domo | E5: =ESTADISTICA!E3 -> PTO A FO | F5: =ESTADISTICA!F3 -> 0 | G5: =ESTADISTICA!G3 -> 0 | H5: =ESTADISTICA!H3 -> 0 | ... AI5: =ESTADISTICA!AI3 -> 0
A6: =ESTADISTICA!A4 -> ALTAMIRA | B6: =ESTADISTICA!B4 -> ALT 03 | C6: =ESTADISTICA!C4 -> Bombero Galarza y Necochea | D6: =ESTADISTICA!D4 -> Domo | E6: =ESTADISTICA!E4 -> FIBRA OPTICA | F6: =ESTADISTICA!F4 -> 0 | G6: =ESTADISTICA!G4 -> 0 | H6: =ESTADISTICA!H4 -> 0 | ... AI6: =ESTADISTICA!AI4 -> 0
A7: =ESTADISTICA!A5 -> ALTAMIRA | B7: =ESTADISTICA!B5 -> ALT 04 | C7: =ESTADISTICA!C5 -> Francia y Necochea | D7: =ESTADISTICA!D5 -> Domo | E7: =ESTADISTICA!E5 -> FIBRA OPTICA | F7: =ESTADISTICA!F5 -> 0 | G7: =ESTADISTICA!G5 -> 0 | H7: =ESTADISTICA!H5 -> 0 | ... AI7: =ESTADISTICA!AI5 -> 0
A8: =ESTADISTICA!A6 -> ALTAMIRA | B8: =ESTADISTICA!B6 -> ALT05 | C8: =ESTADISTICA!C6 -> Av. Calchaqui y Bombero Galarza | D8: =ESTADISTICA!D6 -> Domo | E8: =ESTADISTICA!E6 -> PTO A FO | F8: =ESTADISTICA!F6 -> 0 | G8: =ESTADISTICA!G6 -> 0 | H8: =ESTADISTICA!H6 -> 0 | ... AI8: =ESTADISTICA!AI6 -> 0
A9: =ESTADISTICA!A7 -> ALTAMIRA | B9: =ESTADISTICA!B7 -> ALT 06 | C9: =ESTADISTICA!C7 -> LOPE DE VEGA Y NECOCHEA | D9: =ESTADISTICA!D7 -> Domo | E9: =ESTADISTICA!E7 -> PTO A FO | F9: =ESTADISTICA!F7 -> 0 | G9: =ESTADISTICA!G7 -> 0 | H9: =ESTADISTICA!H7 -> 0 | ... AI9: =ESTADISTICA!AI7 -> 0
A10: =ESTADISTICA!A8 -> ALTAMIRA | B10: =ESTADISTICA!B8 -> ALT07 | C10: =ESTADISTICA!C8 -> AV. CALCHAQUI Y AV. DEL TRABAJO | D10: =ESTADISTICA!D8 -> DOMO | E10: =ESTADISTICA!E8 -> PTO A FO | F10: =ESTADISTICA!F8 -> 0 | G10: =ESTADISTICA!G8 -> 0 | H10: =ESTADISTICA!H8 -> 0 | ... AI10: =ESTADISTICA!AI8 -> 0
A11: =ESTADISTICA!A9 -> ALTAMIRA | B11: =ESTADISTICA!B9 -> ALT 08 | C11: =ESTADISTICA!C9 -> HUMAITA Y NECOCHEA | D11: =ESTADISTICA!D9 -> DOMO | E11: =ESTADISTICA!E9 -> Fibra Optica | F11: =ESTADISTICA!F9 -> 0 | G11: =ESTADISTICA!G9 -> 0 | H11: =ESTADISTICA!H9 -> 0 | ... AI11: =ESTADISTICA!AI9 -> 0
A12: =ESTADISTICA!A10 -> ALTAMIRA | B12: =ESTADISTICA!B10 -> ALT 09 | C12: =ESTADISTICA!C10 -> NECOCHEA Y CURUPAITY | D12: =ESTADISTICA!D10 -> DOMO | E12: =ESTADISTICA!E10 -> Fibra Optica | F12: =ESTADISTICA!F10 -> 0 | G12: =ESTADISTICA!G10 -> 0 | H12: =ESTADISTICA!H10 -> 0 | ... AI12: =ESTADISTICA!AI10 -> 0
A13: =ESTADISTICA!A11 -> ALTAMIRA | B13: =ESTADISTICA!B11 -> ALT 10 | C13: =ESTADISTICA!C11 -> Calchaqui y Francia | D13: =ESTADISTICA!D11 -> Domo | E13: =ESTADISTICA!E11 -> Radio | F13: =ESTADISTICA!F11 -> 0 | G13: =ESTADISTICA!G11 -> 0 | H13: =ESTADISTICA!H11 -> 0 | ... AI13: =ESTADISTICA!AI11 -> 0
A14: =ESTADISTICA!A12 -> AGUSTIN RAMIREZ | B14: =ESTADISTICA!B12 -> ARA 01 | C14: =ESTADISTICA!C12 -> Malambo y Tranquera | D14: =ESTADISTICA!D12 -> Domo | E14: =ESTADISTICA!E12 -> FIBRA OPTICA | F14: =ESTADISTICA!F12 -> 0 | G14: =ESTADISTICA!G12 -> 0 | H14: =ESTADISTICA!H12 -> 0 | ... AI14: =ESTADISTICA!AI12 -> 0
... A686: =ESTADISTICA!A684 -> 0 | B686: =ESTADISTICA!B684 -> 0 | C686: =ESTADISTICA!C684 -> 0 | D686: =ESTADISTICA!D684 -> 0 | E686: =ESTADISTICA!E684 -> 0 | F686: =ESTADISTICA!F684 -> 0 | G686: =ESTADISTICA!G684 -> 0 | H686: =ESTADISTICA!H684 -> 0 | ... AI686: =ESTADISTICA!AI684 -> 0

Sheet BARRAS

Sheet PORCENTAJE

Sheet informe
B1: CANTIDAD | D1: %
A2: TOTAL | B2: 435 | E2: 44896 | F2: tormenta con granizo el 30-11, hoy lluvioso
A3: CAIDAS | B3: 135 | C3: 135 | D3: =C3/B2 -> 0.31034483
A4: LLEGAMOS NOSOTROS | B4: 5 | C4: =C3-B4 -> 130 | D4: =C4/B2 -> 0.29885057
A5: NO ESTA LA CAMARA | B5: 3 | C5: =C4-B5 -> 127 | D5: =C5/B2 -> 0.29195402
A6: RADIO | B6: 24 | C6: =C5-B6 -> 103 | D6: =C6/B2 -> 0.23678161
A7: TOTAL | B7: 435 | E7: 44897
A8: CAIDAS | B8: 113 | C8: 113 | D8: =C8/B7 -> 0.25977011
A9: LLEGAMOS NOSOTROS | B9: 4 | C9: =C8-B9 -> 109 | D9: =C9/B7 -> 0.25057471
A10: NO ESTA LA CAMARA | B10: 3 | C10: =C9-B10 -> 106 | D10: =C10/B7 -> 0.24367816
A11: RADIO | B11: 21 | C11: =C10-B11 -> 85 | D11: =C11/B7 -> 0.1954023
A12: TOTAL | B12: 435 | E12: 44900
A13: CAIDAS | B13: 98 | C13: 98 | D13: =C13/B12 -> 0.22528736
A14: LLEGAMOS NOSOTROS | B14: 2 | C14: =C13-B14 -> 96 | D14: =C14/B12 -> 0.22068966
A15: NO ESTA LA CAMARA | B15: 3 | C15: =C14-B15 -> 93 | D15: =C15/B12 -> 0.2137931
A16: RADIO | B16: 16 | C16: =C15-B16 -> 77 | D16: =C16/B12 -> 0.17701149
A17: TOTAL | B17: 435 | E17: 44901
A18: CAIDAS | B18: 82 | C18: 82 | D18: =C18/B17 -> 0.18850575
A19: LLEGAMOS NOSOTROS | B19: 3 | C19: =C18-B19 -> 79 | D19: =C19/B17 -> 0.1816092
A20: NO ESTA LA CAMARA | B20: 3 | C20: =C19-B20 -> 76 | D20: =C20/B17 -> 0.17471264
A21: RADIO | B21: 15 | C21: =C20-B21 -> 61 | D21: =C21/B17 -> 0.14022989
A22: TOTAL | B22: 435 | E22: 44908
A23: CAIDAS | B23: 78 | C23: 78 | D23: =C23/B22 -> 0.17931034
A24: LLEGAMOS NOSOTROS | B24: 0 | C24: =C23-B24 -> 78 | D24: =C24/B22 -> 0.17931034
A25: NO ESTA LA CAMARA | B25: 3 | C25: =C24-B25 -> 75 | D25: =C25/B22 -> 0.17241379
A26: RADIO | B26: 10 | C26: =C25-B26 -> 65 | D26: =C26/B22 -> 0.14942529
A27: TOTAL | B27: 436 | E27: 44914
A28: CAIDAS | B28: 38 | C28: 38 | D28: =C28/B27 -> 0.087155963
A29: LLEGAMOS NOSOTROS | B29: 1 | C29: =C28-B29 -> 37 | D29: =C29/B27 -> 0.084862385
A30: NO ESTA LA CAMARA | B30: 3 | C30: =C29-B30 -> 34 | D30: =C30/B27 -> 0.077981651
A31: RADIO | B31: 9 | C31: =C30-B31 -> 25 | D31: =C31/B27 -> 0.05733945
A32: TOTAL | B32: 436 | E32: 44916
A33: CAIDAS | B33: 36 | C33: 36 | D33: =C33/B32 -> 0.082568807
A34: LLEGAMOS NOSOTROS | B34: 0 | C34: =C33-B34 -> 36 | D34: =C34/B32 -> 0.082568807
A35: NO ESTA LA CAMARA | B35: 3 | C35: =C34-B35 -> 33 | D35: =C35/B32 -> 0.075688073
A36: RADIO | B36: 3 | C36: =C35-B36 -> 30 | D36: =C36/B32 -> 0.068807339
A37: TOTAL | B37: 436 | E37: 44921
A38: CAIDAS | B38: 32 | C38: 32 | D38: =C38/B37 -> 0.073394495
A39: LLEGAMOS NOSOTROS | B39: 0 | C39: =C38-B39 -> 32 | D39: =C39/B37 -> 0.073394495
A40: NO ESTA LA CAMARA | B40: 3 | C40: =C39-B40 -> 29 | D40: =C40/B37 -> 0.066513761
...

Sheet Hoja2
C3: CAMARAS | D3: 44922 | I3: CAMARAS | J3: 44922
B4: BONOMO | C4: =COUNTIFS('RESUMEN TOTAL'!C5:C504,"=BONOMO") -> 228 | D4: 29 | E4: 3 no esta la camara | F4: 6 de radio | H4: BONOMO | I4: 228 | J4: 20
D5: 0.12719298 | J5: 0.088
B6: COSEIDI | C6: =COUNTIFS('RESUMEN TOTAL'!C5:C504,"=COSEIDI") -> 207 | D6: 11 | E6: 1 no esta la camara | F6: 1 de radio | H6: COSEIDI | I6: 207 | J6: 11
D7: 0.053140097 | J7: 0.053140097

Sheet GRAFICO2

Sheet AUXILIAR
A1: FECHA | B1: RADIO | C1: FIBRA | D1: ANTENA | E1: TOTAL APAGADOS | F1: INSTALADAS | G1: % APAGADOS
A2: ='APAGADOS RADIO'!F3 -> 44927 | B2: ='APAGADOS RADIO'!F2+D2 -> 0 | C2: ='APAGADOS FIBRA'!F2 -> 0 | D2: ='APAGADOS ANTENA'!F2 -> 0 | E2: =B2+C2 -> 0 | F2: ='RESUMEN TOTAL'!B1 -> 435 | G2: =E2/F2 -> 0
