Workbook
Name _25_de_agosto: 'RESUMEN TOTAL'!$A$4:$D$375
Name _25_de_agosto_3: 'RESUMEN TOTAL'!$A$4:$D$387
Name BONOMOcam: Hoja1!$B$2
Name CANTIDAD_DE_CAMARAS: 'RESUMEN TOTAL'!$B$1
Name COSEIDIcam: Hoja1!$B$4

Sheet RESUMEN TOTAL
A1: CANTIDAD DE CAMARAS | B1: =COUNTA(B5:B542) -> 444 | D1: PORCIENTO DE CAIDAS | K1: =(K3)/(K2+K3) -> 0.12612613 | L1: =(L3)/(L2+L3) -> 0 | M1: =(M3)/(M2+M3) -> 0 | N1: =(N3)/(N2+N3) -> 0 | O1: =(O3)/(O2+O3) -> 0 | P1: =(P3)/(P2+P3) -> 0 | Q1: =(Q3)/(Q2+Q3) -> 0 | R1: =(R3)/(R2+R3) -> 0 | ... AN1: =(AN3)/(AN2+AN3) -> 0
D2: FUNCIONAN | K2: =B1-K3 -> 388 | L2: =CANTIDAD_DE_CAMARAS-L3 -> 444 | M2: =CANTIDAD_DE_CAMARAS-M3 -> 444 | N2: =CANTIDAD_DE_CAMARAS-N3 -> 444 | O2: =CANTIDAD_DE_CAMARAS-O3 -> 444 | P2: =CANTIDAD_DE_CAMARAS-P3 -> 444 | Q2: =CANTIDAD_DE_CAMARAS-Q3 -> 444 | R2: =CANTIDAD_DE_CAMARAS-R3 -> 444 | S2: =CANTIDAD_DE_CAMARAS-S3 -> 444 | ... AN2: =CANTIDAD_DE_CAMARAS-AN3 -> 444
D3: CAIDAS | K3: =COUNTIF(K4:K462, "apagado") -> 56 | L3: =COUNTIF(L4:L462, "apagado") -> 0 | M3: =COUNTIF(M4:M462, "apagado") -> 0 | N3: =COUNTIF(N4:N462, "apagado") -> 0 | O3: =COUNTIF(O4:O462, "apagado") -> 0 | P3: =COUNTIF(P4:P462, "apagado") -> 0 | Q3: =COUNTIF(Q4:Q462, "apagado") -> 0 | R3: =COUNTIF(R4:R462, "apagado") -> 0 | ... AN3: =COUNTIF(AN4:AN462, "apagado") -> 0
A4: Barrio | B4: [Denominacion] | C4: [Empresa Mantenimiento] | D4: [Ubicacion] | E4: [Tipo de Camara] | F4: [Tipo de Conexion] | H4: DIAS FUNCIONANDO | I4: DIAS CAIDA | J4: EFECTIVIDAD | K4: 45078 | L4: 45079 | M4: 45080 | N4: 45081 | O4: 45082 | P4: 45083 | Q4: 45084 | R4: 45085 | S4: 45086 | T4: 45087 | U4: 45088 | V4: 45089 | W4: 45090 | X4: 45091 | Y4: 45092 | Z4: 45093 | AA4: 45094 | AB4: 45095 | AC4: 45096 | AD4: 45097 | AE4: 45098 | AF4: 45099 | AG4: 45100 | AH4: 45101 | AI4: 45102 | AJ4: 45103 | AK4: 45104 | AL4: 45105 | AM4: 45106 | AN4: 45107
A5: ALTAMIRA | B5: ALT01 | C5: BONOMO | D5: Calchaqui y Sgto. Cabral | E5: Domo | F5: Fibra Optica | G5: 172.20.10.6 | H5: =COUNTIF(K5:AL5,"") -> 28 | I5: =COUNTIF(K5:AL5,"APAGADO") -> 0 | J5: =(H5)/(I5+H5) -> 1
A6: ALTAMIRA | B6: ALT02 | C6: BONOMO | D6: Calchaqui y Lope de Vega | E6: Domo | F6: PTO A FO | G6: 172.20.12.218 | H6: =COUNTIF(K6:AL6,"") -> 28 | I6: =COUNTIF(K6:AL6,"APAGADO") -> 0 | J6: =(H6)/(I6+H6) -> 1
A7: ALTAMIRA | B7: ALT 03 | C7: BONOMO | D7: Bombero Galarza y Necochea | E7: Domo | F7: FIBRA OPTICA | G7: 172.20.12.54 | H7: =COUNTIF(K7:AL7,"") -> 28 | I7: =COUNTIF(K7:AL7,"APAGADO") -> 0 | J7: =(H7)/(I7+H7) -> 1
A8: ALTAMIRA | B8: ALT 04 | C8: BONOMO | D8: Francia y Necochea | E8: Domo | F8: FIBRA OPTICA | G8: 172.20.12.55 | H8: =COUNTIF(K8:AL8,"") -> 28 | I8: =COUNTIF(K8:AL8,"APAGADO") -> 0 | J8: =(H8)/(I8+H8) -> 1
A9: ALTAMIRA | B9: ALT05 | C9: BONOMO | D9: Av. Calchaqui y Bombero Galarza | E9: Domo | F9: PTO A FO | G9: 172.20.12.216 | H9: =COUNTIF(K9:AL9,"") -> 28 | I9: =COUNTIF(K9:AL9,"APAGADO") -> 0 | J9: =(H9)/(I9+H9) -> 1
A10: ALTAMIRA | B10: ALT 06 | C10: BONOMO | D10: LOPE DE VEGA Y NECOCHEA | E10: Domo | F10: PTO A FO | G10: 172.20.12.12 | H10: =COUNTIF(K10:AL10,"") -> 28 | I10: =COUNTIF(K10:AL10,"APAGADO") -> 0 | J10: =(H10)/(I10+H10) -> 1
A11: ALTAMIRA | B11: ALT07 | C11: BONOMO | D11: AV. CALCHAQUI Y AV. DEL TRABAJO | E11: DOMO | F11: PTO A FO | G11: 172.20.10.57 | H11: =COUNTIF(K11:AL11,"") -> 28 | I11: =COUNTIF(K11:AL11,"APAGADO") -> 0 | J11: =(H11)/(I11+H11) -> 1
A12: ALTAMIRA | B12: ALT 08 | C12: BONOMO | D12: HUMAITA Y NECOCHEA | E12: DOMO | F12: Fibra Optica | G12: 172.20.11.215 | H12: =COUNTIF(K12:AL12,"") -> 28 | I12: =COUNTIF(K12:AL12,"APAGADO") -> 0 | J12: =(H12)/(I12+H12) -> 1
A13: ALTAMIRA | B13: ALT 09 | C13: BONOMO | D13: NECOCHEA Y CURUPAITY | E13: DOMO | F13: Fibra Optica | G13: 172.20.11.216 | H13: =COUNTIF(K13:AL13,"") -> 28 | I13: =COUNTIF(K13:AL13,"APAGADO") -> 0 | J13: =(H13)/(I13+H13) -> 1
A14: ALTAMIRA | B14: ALT 10 | C14: BONOMO | D14: Calchaqui y Francia | E14: Domo | F14: Radio | G14: 172.20.12.156 | H14: =COUNTIF(K14:AL14,"") -> 28 | I14: =COUNTIF(K14:AL14,"APAGADO") -> 0 | J14: =(H14)/(I14+H14) -> 1
A15: AGUSTIN RAMIREZ | B15: ARA 01 | C15: COSEIDI | D15: Malambo y Tranquera | E15: Domo | F15: FIBRA OPTICA | G15: 172.20.12.110 | H15: =COUNTIF(K15:AL15,"") -> 28 | I15: =COUNTIF(K15:AL15,"APAGADO") -> 0 | J15: =(H15)/(I15+H15) -> 1
A16: BELGRANO | B16: BEL 01 | C16: BONOMO | D16: San Martin y Dardo Rocha | E16: DOMO | F16: FIBRA OPTICA | G16: 172.20.12.64 | H16: =COUNTIF(K16:AL16,"") -> 28 | I16: =COUNTIF(K16:AL16,"APAGADO") -> 0 | J16: =(H16)/(I16+H16) -> 1
... A86: CENTRO | B86: CEN64 | C86: BONOMO | D86: SAN MARTIN Y BOCCUZZI | E86: FIJA | F86: Fibra Optica | G86: 172.20.11.134 | H86: =COUNTIF(K86:AL86,"") -> 28 | I86: =COUNTIF(K86:AL86,"APAGADO") -> 0 | J86: =(H86)/(I86+H86) -> 1
A87: º | B87: CEN 65 | C87: BONOMO | D87: SAN MARTIN Y JUAN PERON | E87: FIJA | F87: Fibra Optica | G87: 172.20.11.135 | H87: =COUNTIF(K87:AL87,"") -> 27 | I87: =COUNTIF(K87:AL87,"APAGADO") -> 1 | J87: =(H87)/(I87+H87) -> 0.96428571 | K87: APAGADO
A88: CENTRO | B88: CEN66 | C88: BONOMO | D88: SAN MARTIN Y JUAN PERON | E88: FIJA | F88: Fibra Optica | G88: 172.20.11.136 | H88: =COUNTIF(K88:AL88,"") -> 27 | I88: =COUNTIF(K88:AL88,"APAGADO") -> 1 | J88: =(H88)/(I88+H88) -> 0.96428571 | K88: APAGADO
A89: CENTRO | B89: CEN67 (fija 1) | C89: BONOMO | D89: 9 DE JULIO Y BROWN | E89: Fija | F89: Fibra Optica | G89: 172.20.11.188 | H89: =COUNTIF(K89:AL89,"") -> 28 | I89: =COUNTIF(K89:AL89,"APAGADO") -> 0 | J89: =(H89)/(I89+H89) -> 1
A90: CENTRO | B90: CEN68 (fija 2) | C90: BONOMO | D90: 9 DE JULIO Y BROWN | E90: Fija | F90: Fibra Optica | G90: 172.20.11.189 | H90: =COUNTIF(K90:AL90,"") -> 28 | I90: =COUNTIF(K90:AL90,"APAGADO") -> 0 | J90: =(H90)/(I90+H90) -> 1
A91: CENTRO | B91: CEN69 | C91: BONOMO | D91: RIVADAVIA Y BOUREL | E91: DOMO | F91: Fibra Optica | G91: 172.20.11.222 | H91: =COUNTIF(K91:AL91,"") -> 28 | I91: =COUNTIF(K91:AL91,"APAGADO") -> 0 | J91: =(H91)/(I91+H91) -> 1
A92: CENTRO | B92: CEN 70 | C92: BONOMO | D92: RIVADAVIA Y 25 MAYO | E92: Domo | F92: Fibra Optica | G92: 172.20.11.221 | H92: =COUNTIF(K92:AL92,"") -> 28 | I92: =COUNTIF(K92:AL92,"APAGADO") -> 0 | J92: =(H92)/(I92+H92) -> 1
A93: CENTRO | B93: CEN 71 | C93: BONOMO | D93: MORENO Y BOUREL | E93: Domo | F93: Fibra Optica | G93: 172.20.11.220 | H93: =COUNTIF(K93:AL93,"") -> 28 | I93: =COUNTIF(K93:AL93,"APAGADO") -> 0 | J93: =(H93)/(I93+H93) -> 1
A94: CENTRO | B94: CEN 72 | C94: BONOMO | D94: MORENO Y 25 DE MAYO | E94: Domo | F94: Fibra Optica | G94: 172.20.11.219 | H94: =COUNTIF(K94:AL94,"") -> 27 | I94: =COUNTIF(K94:AL94,"APAGADO") -> 1 | J94: =(H94)/(I94+H94) -> 0.96428571 | K94: APAGADO
A95: CENTRO | B95: CEN73 | C95: BONOMO | D95: BOUREL Y DEFENSA | E95: DOMO | F95: Fibra Optica | G95: 172.20.11.223 | H95: =COUNTIF(K95:AL95,"") -> 28 | I95: =COUNTIF(K95:AL95,"APAGADO") -> 0 | J95: =(H95)/(I95+H95) -> 1
A96: CENTRO | B96: CEN74 | C96: BONOMO | D96: Las Heras y Maipu | E96: Domo | F96: FIBRA OPTICA | G96: 172.20.11.53 | H96: =COUNTIF(K96:AL96,"") -> 28 | I96: =COUNTIF(K96:AL96,"APAGADO") -> 0 | J96: =(H96)/(I96+H96) -> 1
A97: CENTRO | B97: CEN 75 | C97: BONOMO | D97: 25 DE MAYO Y CASTELLI | E97: Domo | F97: Fibra Optica | G97: 172.20.11.114 | H97: =COUNTIF(K97:AL97,"") -> 28 | I97: =COUNTIF(K97:AL97,"APAGADO") -> 0 | J97: =(H97)/(I97+H97) -> 1
A98: CENTRO | B98: CEN 76 | C98: BONOMO | D98: ESPAÑA E/MITRE Y BOCUZZI | E98: Fija | F98: Fibra Optica | G98: 172-20.11.110 | H98: =COUNTIF(K98:AL98,"") -> 28 | I98: =COUNTIF(K98:AL98,"APAGADO") -> 0 | J98: =(H98)/(I98+H98) -> 1
A99: CENTRO | B99: CEN 77 | C99: BONOMO | D99: Monteagudo e/ Mitre y Boccuzzi | E99: Fija | F99: Fibra Optica | G99: 172.20.11.241 | H99: =COUNTIF(K99:AL99,"") -> 28 | I99: =COUNTIF(K99:AL99,"APAGADO") -> 0 | J99: =(H99)/(I99+H99) -> 1
A100: CENTRO | B100: CEN 78 | C100: BONOMO | D100: Mitre e/Monteagudo y Alberdi | E100: Fija | F100: Fibra Optica | G100: 172.20.11.240 | H100: =COUNTIF(K100:AL100,"") -> 28 | I100: =COUNTIF(K100:AL100,"APAGADO") -> 0 | J100: =(H100)/(I100+H100) -> 1
A101: CENTRO | B101: CEN 79 | C101: BONOMO | D101: Diag. Constituyente y Brown | E101: Fija | F101: Fibra Optica | G101: 172.20.11.243 | H101: =COUNTIF(K101:AL101,"") -> 28 | I101: =COUNTIF(K101:AL101,"APAGADO") -> 0 | J101: =(H101)/(I101+H101) -> 1
A102: CENTRO | B102: CEN 80 | C102: BONOMO | D102: Diag. Constituyente y Brown | E102: Fija | F102: Fibra Optica | G102: 172.20.11.244 | H102: =COUNTIF(K102:AL102,"") -> 28 | I102: =COUNTIF(K102:AL102,"APAGADO") -> 0 | J102: =(H102)/(I102+H102) -> 1
A103: CENTRO | B103: CEN 81 | C103: BONOMO | D103: Alberdi y A.del Valle | E103: Fija | F103: Fibra Optica | G103: 172.20.11.242 | H103: =COUNTIF(K103:AL103,"") -> 28 | I103: =COUNTIF(K103:AL103,"APAGADO") -> 0 | J103: =(H103)/(I103+H103) -> 1
A104: CENTRO | B104: CEN 82 | C104: BONOMO | D104: DORREGO Y BOUREL | E104: Domo | F104: Fibra Optica | G104: 172.20.11.198 | H104: =COUNTIF(K104:AL104,"") -> 28 | I104: =COUNTIF(K104:AL104,"APAGADO") -> 0 | J104: =(H104)/(I104+H104) -> 1
A105: CENTRO | B105: CEN83 | C105: BONOMO | D105: RECONQUISTA Y 25 DE MAYO | E105: Domo | F105: Radio | G105: 172.20.11.123 | H105: =COUNTIF(K105:AL105,"") -> 28 | I105: =COUNTIF(K105:AL105,"APAGADO") -> 0 | J105: =(H105)/(I105+H105) -> 1
A106: CENTRO | B106: CEN 84 | C106: BONOMO | D106: 25 DE MAYO Y MAIPU | E106: Fija | F106: Fibra Optica | H106: =COUNTIF(K106:AL106,"") -> 28 | I106: =COUNTIF(K106:AL106,"APAGADO") -> 0 | J106: =(H106)/(I106+H106) -> 1
A107: CENTRO | B107: CEN 85 | C107: BONOMO | D107: PTE PERON E/ PRINGLES Y BROWN | E107: Fija | F107: Fibra Optica | G107: 172.20.10.21 | H107: =COUNTIF(K107:AL107,"") -> 28 | I107: =COUNTIF(K107:AL107,"APAGADO") -> 0 | J107: =(H107)/(I107+H107) -> 1
A108: SAN NICOLAS | B108: CHA01 | C108: BONOMO | D108: Novak y Pte Illia | E108: Domo | F108: Radio | G108: 172.20.200.126 | H108: =COUNTIF(K108:AL108,"") -> 28 | I108: =COUNTIF(K108:AL108,"APAGADO") -> 0 | J108: =(H108)/(I108+H108) -> 1
A109: CHACABUCO | B109: CHA02 | C109: BONOMO | D109: Pte. Illia y Posadas | E109: Domo | F109: Radio | G109: 172.20.200.186 | H109: =COUNTIF(K109:AL109,"") -> 28 | I109: =COUNTIF(K109:AL109,"APAGADO") -> 0 | J109: =(H109)/(I109+H109) -> 1
...

Sheet Hoja4
A10: Barrio | B10: [Denominacion] | C10: [Empresa Mantenimiento] | D10: [Ubicacion] | E10: [Tipo de Camara] | F10: [Tipo de Conexion]
A11: CENTRO | B11: CEN 65 | C11: BONOMO | D11: SAN MARTIN Y JUAN PERON | E11: FIJA | F11: Fibra Optica | G11: 172.20.11.135
A12: CENTRO | B12: CEN66 | C12: BONOMO | D12: SAN MARTIN Y JUAN PERON | E12: FIJA | F12: Fibra Optica | G12: 172.20.11.136
A13: CENTRO | B13: CEN 72 | C13: BONOMO | D13: MORENO Y 25 DE MAYO | E13: Domo | F13: Fibra Optica | G13: 172.20.11.219
A14: DON JOSE | B14: DJO 02 (fija 1) | C14: BONOMO | D14: DONATO ALVAREZ Y EL APERO | E14: Fija | F14: PTO A FO | G14: 172.20.12.97
A15: DON JOSE | B15: DJO 03 (fija 2) | C15: BONOMO | D15: DONATO ALVAREZ Y EL APERO | E15: Fija | F15: PTO A FO | G15: 172.20.12.98
A16: DON JOSE | B16: DJO 04 (Fija 1) | C16: BONOMO | D16: MONTEVERDE Y EL INDIO | E16: Fija | F16: Radio | G16: 172.20.12.91
A17: DON JOSE | B17: DJO 05 (Fija 2) | C17: BONOMO | D17: MONTEVERDE Y EL INDIO | E17: Fija | F17: Radio | G17: 172.20.12.92
A18: DON JOSE | B18: DJ O6 | C18: BONOMO | D18: Calle 414 y El Indio | E18: Fija | F18: Radio | G18: 172.20.12.121
A19: DON JOSE | B19: DJ 07 | C19: BONOMO | D19: Calle 414 y El Indio | E19: Fija | F19: Radio | G19: 172.20.12.122
A20: KM 26700 (JULIO A. COSTA) | B20: KM 12 FIJA 1 | C20: BONOMO | D20: BLANDENGUES Y LA ZAMBA | E20: Fija | F20: PTO A FO | G20: 172.20.12.85
A21: KM 26700 (JULIO A. COSTA) | B21: KM 13 FIJA 2 | C21: BONOMO | D21: BLANDENGUES Y LA ZAMBA | E21: Fija | F21: PTO A FO | G21: 172.20.12.86
A22: KM 26700 (JULIO A. COSTA) | B22: KM 14 (fija 1) | C22: BONOMO | D22: EL GAUCHO Y EL ZONDA | E22: Fija | F22: PTO A FO | G22: 172.20.12.94
... A27: 9 DE JULIO | B27: NJU09 | C27: BONOMO | D27: PARRILLO Y CONTRERAS | E27: DOMO | F27: Fibra Optica | G27: 172.20.11.190
A28: DON JOSE | B28: PUNTO SEGURO AGUSTIN RAMIREZ INTERCOMUNICADOR | C28: BONOMO | D28: MALAMBO Y LA TRANQUERA | E28: Fija | F28: Fibra Optica
A29: SAN EDUARDO | B29: SEDU01 | C29: BONOMO | D29: San Martin y Sperandio | E29: Domo | F29: Fibra Optica | G29: 172.20.10.10
A30: VILLA CIRIO | B30: SEDU03 | C30: BONOMO | D30: Av. San Martin y Las Americas | E30: Domo | F30: Radio | G30: 172.20.200.183
A31: LA SIRENA | B31: SIR01 | C31: BONOMO | D31: Moran y Calle 14 | E31: DOMO | F31: Radio | G31: 172.20.200.124
A32: LA SIRENA | B32: SIR09 (fija 1) | C32: BONOMO | D32: GUIDO SPANO Y MORAN | E32: Fija | F32: Fibra Optica | G32: 172.20.11.96
A33: LA SIRENA | B33: SIR10 (fija 2) | C33: BONOMO | D33: GUIDO SPANO Y MORAN | E33: Fija | F33: Fibra Optica | G33: 172.20.11.97
A34: LA SIRENA | B34: SIR 15 | C34: BONOMO | D34: Monteverde y Azara | E34: Domo | F34: Fibra Optica | G34: 172.20.11.93
A35: VILLA VATTEONE CENTRO | B35: VAT23 (fija 1) | C35: BONOMO | D35: EVA PERON Y "EL TUNEL" (BAJO NIVEL) | E35: Fija | F35: Fibra Optica | G35: 172.20.11.139
A36: VILLA VATTEONE CENTRO | B36: VAT24 (fija 2) | C36: BONOMO | D36: EVA PERON Y "EL TUNEL" (BAJO NIVEL) | E36: Fija | F36: Fibra Optica | G36: 172.20.11.140
A37: VILLA DEL PLATA | B37: VDPL05 | C37: BONOMO | D37: Ruta 36 y Abraham | E37: Domo | F37: PTO A FO | G37: 172.20.12.219
A38: VILLA ANGELICA | B38: VDPL06 | C38: BONOMO | D38: Thevenet e/ Islas Orcadas y Gardel | E38: Domo | F38: Radio | G38: 172.20.200.196
A43: CAMARAS SIN FUNCIONAMIENTO DEL DIA 01 DE JUNIO DE 2023
A46: RECIBIDO: | D46: FIRMA:
A49: EMPRESA: BONOMO SISTEMAS
D51: ACALARCION:

Sheet ESTADISTICA
A1: ='RESUMEN TOTAL'!A4 -> Barrio | B1: ='RESUMEN TOTAL'!B4 -> [Denominacion] | C1: ='RESUMEN TOTAL'!D4 -> [Ubicacion] | D1: ='RESUMEN TOTAL'!E4 -> [Tipo de Camara] | E1: ='RESUMEN TOTAL'!F4 -> [Tipo de Conexion] | F1: ='RESUMEN TOTAL'!K4 -> 45078 | G1: ='RESUMEN TOTAL'!L4 -> 45079 | H1: ='RESUMEN TOTAL'!M4 -> 45080 | I1: ='RESUMEN TOTAL'!N4 -> 45081 | J1: ='RESUMEN TOTAL'!O4 -> 45082 | K1: ='RESUMEN TOTAL'!P4 -> 45083 | L1: ='RESUMEN TOTAL'!Q4 -> 45084 | M1: ='RESUMEN TOTAL'!R4 -> 45085 | ... AI1: ='RESUMEN TOTAL'!AN4 -> 45107 | AJ1: ='RESUMEN TOTAL'!#REF! -> #REF!
A2: ='RESUMEN TOTAL'!A5 -> ALTAMIRA | B2: ='RESUMEN TOTAL'!B5 -> ALT01 | C2: ='RESUMEN TOTAL'!D5 -> Calchaqui y Sgto. Cabral | D2: ='RESUMEN TOTAL'!E5 -> Domo | E2: ='RESUMEN TOTAL'!F5 -> Fibra Optica | F2: ='RESUMEN TOTAL'!K5 -> 0 | G2: ='RESUMEN TOTAL'!L5 -> 0 | H2: ='RESUMEN TOTAL'!M5 -> 0 | I2: ='RESUMEN TOTAL'!N5 -> 0 | J2: ='RESUMEN TOTAL'!O5 -> 0 | K2: ='RESUMEN TOTAL'!P5 -> 0 | L2: ='RESUMEN TOTAL'!Q5 -> 0 | M2: ='RESUMEN TOTAL'!R5 -> 0 | ... AI2: ='RESUMEN TOTAL'!AN5 -> 0 | AJ2: ='RESUMEN TOTAL'!#REF! -> #REF!
A3: ='RESUMEN TOTAL'!A6 -> ALTAMIRA | B3: ='RESUMEN TOTAL'!B6 -> ALT02 | C3: ='RESUMEN TOTAL'!D6 -> Calchaqui y Lope de Vega | D3: ='RESUMEN TOTAL'!E6 -> Domo | E3: ='RESUMEN TOTAL'!F6 -> PTO A FO | F3: ='RESUMEN TOTAL'!K6 -> 0 | G3: ='RESUMEN TOTAL'!L6 -> 0 | H3: ='RESUMEN TOTAL'!M6 -> 0 | I3: ='RESUMEN TOTAL'!N6 -> 0 | J3: ='RESUMEN TOTAL'!O6 -> 0 | K3: ='RESUMEN TOTAL'!P6 -> 0 | L3: ='RESUMEN TOTAL'!Q6 -> 0 | M3: ='RESUMEN TOTAL'!R6 -> 0 | ... AI3: ='RESUMEN TOTAL'!AN6 -> 0 | AJ3: ='RESUMEN TOTAL'!#REF! -> #REF!
A4: ='RESUMEN TOTAL'!A7 -> ALTAMIRA | B4: ='RESUMEN TOTAL'!B7 -> ALT 03 | C4: ='RESUMEN TOTAL'!D7 -> Bombero Galarza y Necochea | D4: ='RESUMEN TOTAL'!E7 -> Domo | E4: ='RESUMEN TOTAL'!F7 -> FIBRA OPTICA | F4: ='RESUMEN TOTAL'!K7 -> 0 | G4: ='RESUMEN TOTAL'!L7 -> 0 | H4: ='RESUMEN TOTAL'!M7 -> 0 | I4: ='RESUMEN TOTAL'!N7 -> 0 | J4: ='RESUMEN TOTAL'!O7 -> 0 | K4: ='RESUMEN TOTAL'!P7 -> 0 | L4: ='RESUMEN TOTAL'!Q7 -> 0 | M4: ='RESUMEN TOTAL'!R7 -> 0 | ... AI4: ='RESUMEN TOTAL'!AN7 -> 0 | AJ4: ='RESUMEN TOTAL'!#REF! -> #REF!
A5: ='RESUMEN TOTAL'!A8 -> ALTAMIRA | B5: ='RESUMEN TOTAL'!B8 -> ALT 04 | C5: ='RESUMEN TOTAL'!D8 -> Francia y Necochea | D5: ='RESUMEN TOTAL'!E8 -> Domo | E5: ='RESUMEN TOTAL'!F8 -> FIBRA OPTICA | F5: ='RESUMEN TOTAL'!K8 -> 0 | G5: ='RESUMEN TOTAL'!L8 -> 0 | H5: ='RESUMEN TOTAL'!M8 -> 0 | I5: ='RESUMEN TOTAL'!N8 -> 0 | J5: ='RESUMEN TOTAL'!O8 -> 0 | K5: ='RESUMEN TOTAL'!P8 -> 0 | L5: ='RESUMEN TOTAL'!Q8 -> 0 | M5: ='RESUMEN TOTAL'!R8 -> 0 | ... AI5: ='RESUMEN TOTAL'!AN8 -> 0 | AJ5: ='RESUMEN TOTAL'!#REF! -> #REF!
A6: ='RESUMEN TOTAL'!A9 -> ALTAMIRA | B6: ='RESUMEN TOTAL'!B9 -> ALT05 | C6: ='RESUMEN TOTAL'!D9 -> Av. Calchaqui y Bombero Galarza | D6: ='RESUMEN TOTAL'!E9 -> Domo | E6: ='RESUMEN TOTAL'!F9 -> PTO A FO | F6: ='RESUMEN TOTAL'!K9 -> 0 | G6: ='RESUMEN TOTAL'!L9 -> 0 | H6: ='RESUMEN TOTAL'!M9 -> 0 | I6: ='RESUMEN TOTAL'!N9 -> 0 | J6: ='RESUMEN TOTAL'!O9 -> 0 | K6: ='RESUMEN TOTAL'!P9 -> 0 | L6: ='RESUMEN TOTAL'!Q9 -> 0 | M6: ='RESUMEN TOTAL'!R9 -> 0 | ... AI6: ='RESUMEN TOTAL'!AN9 -> 0 | AJ6: ='RESUMEN TOTAL'!#REF! -> #REF!
A7: ='RESUMEN TOTAL'!A10 -> ALTAMIRA | B7: ='RESUMEN TOTAL'!B10 -> ALT 06 | C7: ='RESUMEN TOTAL'!D10 -> LOPE DE VEGA Y NECOCHEA | D7: ='RESUMEN TOTAL'!E10 -> Domo | E7: ='RESUMEN TOTAL'!F10 -> PTO A FO | F7: ='RESUMEN TOTAL'!K10 -> 0 | G7: ='RESUMEN TOTAL'!L10 -> 0 | H7: ='RESUMEN TOTAL'!M10 -> 0 | I7: ='RESUMEN TOTAL'!N10 -> 0 | J7: ='RESUMEN TOTAL'!O10 -> 0 | K7: ='RESUMEN TOTAL'!P10 -> 0 | L7: ='RESUMEN TOTAL'!Q10 -> 0 | M7: ='RESUMEN TOTAL'!R10 -> 0 | ... AI7: ='RESUMEN TOTAL'!AN10 -> 0 | AJ7: ='RESUMEN TOTAL'!#REF! -> #REF!
A8: ='RESUMEN TOTAL'!A11 -> ALTAMIRA | B8: ='RESUMEN TOTAL'!B11 -> ALT07 | C8: ='RESUMEN TOTAL'!D11 -> AV. CALCHAQUI Y AV. DEL TRABAJO | D8: ='RESUMEN TOTAL'!E11 -> DOMO | E8: ='RESUMEN TOTAL'!F11 -> PTO A FO | F8: ='RESUMEN TOTAL'!K11 -> 0 | G8: ='RESUMEN TOTAL'!L11 -> 0 | H8: ='RESUMEN TOTAL'!M11 -> 0 | I8: ='RESUMEN TOTAL'!N11 -> 0 | J8: ='RESUMEN TOTAL'!O11 -> 0 | K8: ='RESUMEN TOTAL'!P11 -> 0 | L8: ='RESUMEN TOTAL'!Q11 -> 0 | M8: ='RESUMEN TOTAL'!R11 -> 0 | ... AI8: ='RESUMEN TOTAL'!AN11 -> 0 | AJ8: ='RESUMEN TOTAL'!#REF! -> #REF!
A9: ='RESUMEN TOTAL'!A12 -> ALTAMIRA | B9: ='RESUMEN TOTAL'!B12 -> ALT 08 | C9: ='RESUMEN TOTAL'!D12 -> HUMAITA Y NECOCHEA | D9: ='RESUMEN TOTAL'!E12 -> DOMO | E9: ='RESUMEN TOTAL'!F12 -> Fibra Optica | F9: ='RESUMEN TOTAL'!K12 -> 0 | G9: ='RESUMEN TOTAL'!L12 -> 0 | H9: ='RESUMEN TOTAL'!M12 -> 0 | I9: ='RESUMEN TOTAL'!N12 -> 0 | J9: ='RESUMEN TOTAL'!O12 -> 0 | K9: ='RESUMEN TOTAL'!P12 -> 0 | L9: ='RESUMEN TOTAL'!Q12 -> 0 | M9: ='RESUMEN TOTAL'!R12 -> 0 | ... AI9: ='RESUMEN TOTAL'!AN12 -> 0 | AJ9: ='RESUMEN TOTAL'!#REF! -> #REF!
A10: ='RESUMEN TOTAL'!A13 -> ALTAMIRA | B10: ='RESUMEN TOTAL'!B13 -> ALT 09 | C10: ='RESUMEN TOTAL'!D13 -> NECOCHEA Y CURUPAITY | D10: ='RESUMEN TOTAL'!E13 -> DOMO | E10: ='RESUMEN TOTAL'!F13 -> Fibra Optica | F10: ='RESUMEN TOTAL'!K13 -> 0 | G10: ='RESUMEN TOTAL'!L13 -> 0 | H10: ='RESUMEN TOTAL'!M13 -> 0 | I10: ='RESUMEN TOTAL'!N13 -> 0 | J10: ='RESUMEN TOTAL'!O13 -> 0 | K10: ='RESUMEN TOTAL'!P13 -> 0 | L10: ='RESUMEN TOTAL'!Q13 -> 0 | M10: ='RESUMEN TOTAL'!R13 -> 0 | ... AI10: ='RESUMEN TOTAL'!AN13 -> 0 | AJ10: ='RESUMEN TOTAL'!#REF! -> #REF!
A11: ='RESUMEN TOTAL'!A14 -> ALTAMIRA | B11: ='RESUMEN TOTAL'!B14 -> ALT 10 | C11: ='RESUMEN TOTAL'!D14 -> Calchaqui y Francia | D11: ='RESUMEN TOTAL'!E14 -> Domo | E11: ='RESUMEN TOTAL'!F14 -> Radio | F11: ='RESUMEN TOTAL'!K14 -> 0 | G11: ='RESUMEN TOTAL'!L14 -> 0 | H11: ='RESUMEN TOTAL'!M14 -> 0 | I11: ='RESUMEN TOTAL'!N14 -> 0 | J11: ='RESUMEN TOTAL'!O14 -> 0 | K11: ='RESUMEN TOTAL'!P14 -> 0 | L11: ='RESUMEN TOTAL'!Q14 -> 0 | M11: ='RESUMEN TOTAL'!R14 -> 0 | ... AI11: ='RESUMEN TOTAL'!AN14 -> 0 | AJ11: ='RESUMEN TOTAL'!#REF! -> #REF!
A12: ='RESUMEN TOTAL'!A15 -> AGUSTIN RAMIREZ | B12: ='RESUMEN TOTAL'!B15 -> ARA 01 | C12: ='RESUMEN TOTAL'!D15 -> Malambo y Tranquera | D12: ='RESUMEN TOTAL'!E15 -> Domo | E12: ='RESUMEN TOTAL'!F15 -> FIBRA OPTICA | F12: ='RESUMEN TOTAL'!K15 -> 0 | G12: ='RESUMEN TOTAL'!L15 -> 0 | H12: ='RESUMEN TOTAL'!M15 -> 0 | I12: ='RESUMEN TOTAL'!N15 -> 0 | J12: ='RESUMEN TOTAL'!O15 -> 0 | K12: ='RESUMEN TOTAL'!P15 -> 0 | L12: ='RESUMEN TOTAL'!Q15 -> 0 | M12: ='RESUMEN TOTAL'!R15 -> 0 | ... AI12: ='RESUMEN TOTAL'!AN15 -> 0 | AJ12: ='RESUMEN TOTAL'!#REF! -> #REF!
... A634: ='RESUMEN TOTAL'!A637 -> 0 | B634: ='RESUMEN TOTAL'!B637 -> 0 | C634: ='RESUMEN TOTAL'!D637 -> 0 | D634: ='RESUMEN TOTAL'!E637 -> 0 | E634: ='RESUMEN TOTAL'!F637 -> 0 | F634: ='RESUMEN TOTAL'!K637 -> 0 | G634: ='RESUMEN TOTAL'!L637 -> 0 | H634: ='RESUMEN TOTAL'!M637 -> 0 | I634: ='RESUMEN TOTAL'!N637 -> 0 | J634: ='RESUMEN TOTAL'!O637 -> 0 | K634: ='RESUMEN TOTAL'!P637 -> 0 | L634: ='RESUMEN TOTAL'!Q637 -> 0 | M634: ='RESUMEN TOTAL'!R637 -> 0 | ... AI634: ='RESUMEN TOTAL'!AN637 -> 0 | AJ634: ='RESUMEN TOTAL'!#REF! -> #REF!

Sheet APAGADOS
E1: APAGADOS | F1: =COUNTIF(F3:F400, "APAGADO") -> 47 | G1: =COUNTIF(G3:G400, "APAGADO") -> 0 | H1: =COUNTIF(H3:H500, "APAGADO") -> 0 | I1: =COUNTIF(I3:I400, "APAGADO") -> 0 | J1: =COUNTIF(J3:J400, "APAGADO") -> 0 | K1: =COUNTIF(K3:K400, "APAGADO") -> 0 | L1: =COUNTIF(L3:L400, "APAGADO") -> 0 | M1: =COUNTIF(M3:M400, "APAGADO") -> 0 | N1: =COUNTIF(N3:N400, "APAGADO") -> 0 | O1: =COUNTIF(O3:O400, "APAGADO") -> 0 | P1: =COUNTIF(P3:P400, "APAGADO") -> 0 | ... AD1: =COUNTIF(AD3:AD400, "APAGADO") -> 0 | AE1: =COUNTIF(AE3:AE500, "APAGADO") -> 0 | AF1: =COUNTIF(AF3:AF400, "APAGADO") -> 0 | AG1: =COUNTIF(AG3:AG400, "APAGADO") -> 0 | AH1: =COUNTIF(AH3:AH400, "APAGADO") -> 0 | AI1: =COUNTIF(AI3:AI400, "APAGADO") -> 0 | AJ1: =COUNTIF(AJ3:AJ400, "APAGADO") -> 0
A2: =ESTADISTICA!A1 -> Barrio | B2: =ESTADISTICA!B1 -> [Denominacion] | C2: =ESTADISTICA!C1 -> [Ubicacion] | D2: =ESTADISTICA!D1 -> [Tipo de Camara] | E2: =ESTADISTICA!E1 -> [Tipo de Conexion] | F2: =ESTADISTICA!F1 -> 45078 | G2: =ESTADISTICA!G1 -> 45079 | H2: =ESTADISTICA!H1 -> 45080 | ... AJ2: =ESTADISTICA!AJ1 -> #REF!
A3: =ESTADISTICA!A2 -> ALTAMIRA | B3: =ESTADISTICA!B2 -> ALT01 | C3: =ESTADISTICA!C2 -> Calchaqui y Sgto. Cabral | D3: =ESTADISTICA!D2 -> Domo | E3: =ESTADISTICA!E2 -> Fibra Optica | F3: =ESTADISTICA!F2 -> 0 | G3: =ESTADISTICA!G2 -> 0 | H3: =ESTADISTICA!H2 -> 0 | ... AJ3: =ESTADISTICA!AJ2 -> #REF!
A4: =ESTADISTICA!A3 -> ALTAMIRA | B4: =ESTADISTICA!B3 -> ALT02 | C4: =ESTADISTICA!C3 -> Calchaqui y Lope de Vega | D4: =ESTADISTICA!D3 -> Domo | E4: =ESTADISTICA!E3 -> PTO A FO | F4: =ESTADISTICA!F3 -> 0 | G4: =ESTADISTICA!G3 -> 0 | H4: =ESTADISTICA!H3 -> 0 | ... AJ4: =ESTADISTICA!AJ3 -> #REF!
A5: =ESTADISTICA!A4 -> ALTAMIRA | B5: =ESTADISTICA!B4 -> ALT 03 | C5: =ESTADISTICA!C4 -> Bombero Galarza y Necochea | D5: =ESTADISTICA!D4 -> Domo | E5: =ESTADISTICA!E4 -> FIBRA OPTICA | F5: =ESTADISTICA!F4 -> 0 | G5: =ESTADISTICA!G4 -> 0 | H5: =ESTADISTICA!H4 -> 0 | ... AJ5: =ESTADISTICA!AJ4 -> #REF!
A6: =ESTADISTICA!A5 -> ALTAMIRA | B6: =ESTADISTICA!B5 -> ALT 04 | C6: =ESTADISTICA!C5 -> Francia y Necochea | D6: =ESTADISTICA!D5 -> Domo | E6: =ESTADISTICA!E5 -> FIBRA OPTICA | F6: =ESTADISTICA!F5 -> 0 | G6: =ESTADISTICA!G5 -> 0 | H6: =ESTADISTICA!H5 -> 0 | ... AJ6: =ESTADISTICA!AJ5 -> #REF!
A7: =ESTADISTICA!A6 -> ALTAMIRA | B7: =ESTADISTICA!B6 -> ALT05 | C7: =ESTADISTICA!C6 -> Av. Calchaqui y Bombero Galarza | D7: =ESTADISTICA!D6 -> Domo | E7: =ESTADISTICA!E6 -> PTO A FO | F7: =ESTADISTICA!F6 -> 0 | G7: =ESTADISTICA!G6 -> 0 | H7: =ESTADISTICA!H6 -> 0 | ... AJ7: =ESTADISTICA!AJ6 -> #REF!
A8: =ESTADISTICA!A7 -> ALTAMIRA | B8: =ESTADISTICA!B7 -> ALT 06 | C8: =ESTADISTICA!C7 -> LOPE DE VEGA Y NECOCHEA | D8: =ESTADISTICA!D7 -> Domo | E8: =ESTADISTICA!E7 -> PTO A FO | F8: =ESTADISTICA!F7 -> 0 | G8: =ESTADISTICA!G7 -> 0 | H8: =ESTADISTICA!H7 -> 0 | ... AJ8: =ESTADISTICA!AJ7 -> #REF!
A9: =ESTADISTICA!A8 -> ALTAMIRA | B9: =ESTADISTICA!B8 -> ALT07 | C9: =ESTADISTICA!C8 -> AV. CALCHAQUI Y AV. DEL TRABAJO | D9: =ESTADISTICA!D8 -> DOMO | E9: =ESTADISTICA!E8 -> PTO A FO | F9: =ESTADISTICA!F8 -> 0 | G9: =ESTADISTICA!G8 -> 0 | H9: =ESTADISTICA!H8 -> 0 | ... AJ9: =ESTADISTICA!AJ8 -> #REF!
A10: =ESTADISTICA!A9 -> ALTAMIRA | B10: =ESTADISTICA!B9 -> ALT 08 | C10: =ESTADISTICA!C9 -> HUMAITA Y NECOCHEA | D10: =ESTADISTICA!D9 -> DOMO | E10: =ESTADISTICA!E9 -> Fibra Optica | F10: =ESTADISTICA!F9 -> 0 | G10: =ESTADISTICA!G9 -> 0 | H10: =ESTADISTICA!H9 -> 0 | ... AJ10: =ESTADISTICA!AJ9 -> #REF!
A11: =ESTADISTICA!A10 -> ALTAMIRA | B11: =ESTADISTICA!B10 -> ALT 09 | C11: =ESTADISTICA!C10 -> NECOCHEA Y CURUPAITY | D11: =ESTADISTICA!D10 -> DOMO | E11: =ESTADISTICA!E10 -> Fibra Optica | F11: =ESTADISTICA!F10 -> 0 | G11: =ESTADISTICA!G10 -> 0 | H11: =ESTADISTICA!H10 -> 0 | ... AJ11: =ESTADISTICA!AJ10 -> #REF!
A12: =ESTADISTICA!A11 -> ALTAMIRA | B12: =ESTADISTICA!B11 -> ALT 10 | C12: =ESTADISTICA!C11 -> Calchaqui y Francia | D12: =ESTADISTICA!D11 -> Domo | E12: =ESTADISTICA!E11 -> Radio | F12: =ESTADISTICA!F11 -> 0 | G12: =ESTADISTICA!G11 -> 0 | H12: =ESTADISTICA!H11 -> 0 | ... AJ12: =ESTADISTICA!AJ11 -> #REF!
A13: =ESTADISTICA!A12 -> AGUSTIN RAMIREZ | B13: =ESTADISTICA!B12 -> ARA 01 | C13: =ESTADISTICA!C12 -> Malambo y Tranquera | D13: =ESTADISTICA!D12 -> Domo | E13: =ESTADISTICA!E12 -> FIBRA OPTICA | F13: =ESTADISTICA!F12 -> 0 | G13: =ESTADISTICA!G12 -> 0 | H13: =ESTADISTICA!H12 -> 0 | ... AJ13: =ESTADISTICA!AJ12 -> #REF!
... A513: =ESTADISTICA!A512 -> 0 | B513: =ESTADISTICA!B512 -> 0 | C513: =ESTADISTICA!C512 -> 0 | D513: =ESTADISTICA!D512 -> 0 | E513: =ESTADISTICA!E512 -> 0 | F513: =ESTADISTICA!F512 -> 0 | G513: =ESTADISTICA!G512 -> 0 | H513: =ESTADISTICA!H512 -> 0 | ... AJ513: =ESTADISTICA!AJ512 -> #REF!

Sheet APAGADOS FIBRA
C1: TOTAL FIBRA | D1: =COUNTIFS(E4:E400,"=Fibra Optica") -> 266
E2: APAGADOS | F2: =COUNTIFS(F4:F500, "=APAGADO",E4:E500,"=Fibra Optica") -> 35 | G2: =COUNTIFS(G4:G500, "=APAGADO",E4:E500,"=Fibra Optica") -> 0 | H2: =COUNTIFS(H4:H500, "=APAGADO",E4:E500,"=Fibra Optica") -> 0 | I2: =COUNTIFS(I4:I500, "=APAGADO",E4:E500,"=Fibra Optica") -> 0 | J2: =COUNTIFS(J4:J500, "=APAGADO",E4:E500,"=Fibra Optica") -> 0 | K2: =COUNTIFS(K4:K500, "=APAGADO",E4:E500,"=Fibra Optica") -> 0 | L2: =COUNTIFS(L4:L500, "=APAGADO",E4:E500,"=Fibra Optica") -> 0 | M2: =COUNTIFS(M4:M500, "=APAGADO",E4:E500,"=Fibra Optica") -> 0 | N2: =COUNTIFS(N4:N500, "=APAGADO",E4:E500,"=Fibra Optica") -> 0 | O2: =COUNTIFS(O4:O500, "=APAGADO",E4:E500,"=Fibra Optica") -> 0 | P2: =COUNTIFS(P4:P500, "=APAGADO",E4:E500,"=Fibra Optica") -> 0 | Q2: =COUNTIFS(Q4:Q500, "=APAGADO",E4:E500,"=Fibra Optica") -> 0 | R2: =COUNTIFS(R4:R500, "=APAGADO",E4:E500,"=Fibra Optica") -> 0 | S2: =COUNTIFS(S4:S500, "=APAGADO",E4:E500,"=Fibra Optica") -> 0 | T2: =COUNTIFS(T4:T500, "=APAGADO",E4:E500,"=Fibra Optica") -> 0 | U2: =COUNTIFS(U4:U500, "=APAGADO",E4:E500,"=Fibra Optica") -> 0 | V2: =COUNTIFS(V4:V500, "=APAGADO",E4:E500,"=Fibra Optica") -> 0 | W2: =COUNTIFS(W4:W500, "=APAGADO",E4:E500,"=Fibra Optica") -> 0 | X2: =COUNTIFS(X4:X500, "=APAGADO",E4:E500,"=Fibra Optica") -> 0 | Y2: =COUNTIFS(Y4:Y500, "=APAGADO",E4:E500,"=Fibra Optica") -> 0 | Z2: =COUNTIFS(Z4:Z500, "=APAGADO",E4:E500,"=Fibra Optica") -> 0 | AA2: =COUNTIFS(AA4:AA500, "=APAGADO",E4:E500,"=Fibra Optica") -> 0 | AB2: =COUNTIFS(AB4:AB500, "=APAGADO",E4:E500,"=Fibra Optica") -> 0 | AC2: =COUNTIFS(AC4:AC500, "=APAGADO",E4:E500,"=Fibra Optica") -> 0 | AD2: =COUNTIFS(AD4:AD500, "=APAGADO",E4:E500,"=Fibra Optica") -> 0 | AE2: =COUNTIFS(AE4:AE500, "=APAGADO",E4:E500,"=Fibra Optica") -> 0 | AF2: =COUNTIFS(AF4:AF500, "=APAGADO",E4:E500,"=Fibra Optica") -> 0 | AG2: =COUNTIFS(AG4:AG500, "=APAGADO",E4:E500,"=Fibra Optica") -> 0 | AH2: =COUNTIFS(AH4:AH500, "=APAGADO",E4:E500,"=Fibra Optica") -> 0 | AI2: =COUNTIFS(AI4:AI400, "=APAGADO",E4:E400,"=Fibra Optica") -> 0 | AJ2: =COUNTIFS(AJ4:AJ400, "=APAGADO",F4:F400,"=Fibra Optica") -> 0
A3: =ESTADISTICA!A1 -> Barrio | B3: =ESTADISTICA!B1 -> [Denominacion] | C3: =ESTADISTICA!C1 -> [Ubicacion] | D3: =ESTADISTICA!D1 -> [Tipo de Camara] | E3: =ESTADISTICA!E1 -> [Tipo de Conexion] | F3: =ESTADISTICA!F1 -> 45078 | G3: =ESTADISTICA!G1 -> 45079 | H3: =ESTADISTICA!H1 -> 45080 | ... AJ3: =ESTADISTICA!AJ1 -> #REF!
A4: =ESTADISTICA!A2 -> ALTAMIRA | B4: =ESTADISTICA!B2 -> ALT01 | C4: =ESTADISTICA!C2 -> Calchaqui y Sgto. Cabral | D4: =ESTADISTICA!D2 -> Domo | E4: =ESTADISTICA!E2 -> Fibra Optica | F4: =ESTADISTICA!F2 -> 0 | G4: =ESTADISTICA!G2 -> 0 | H4: =ESTADISTICA!H2 -> 0 | ... AJ4: =ESTADISTICA!AJ2 -> #REF!
A5: =ESTADISTICA!A3 -> ALTAMIRA | B5: =ESTADISTICA!B3 -> ALT02 | C5: =ESTADISTICA!C3 -> Calchaqui y Lope de Vega | D5: =ESTADISTICA!D3 -> Domo | E5: =ESTADISTICA!E3 -> PTO A FO | F5: =ESTADISTICA!F3 -> 0 | G5: =ESTADISTICA!G3 -> 0 | H5: =ESTADISTICA!H3 -> 0 | ... AJ5: =ESTADISTICA!AJ3 -> #REF!
A6: =ESTADISTICA!A4 -> ALTAMIRA | B6: =ESTADISTICA!B4 -> ALT 03 | C6: =ESTADISTICA!C4 -> Bombero Galarza y Necochea | D6: =ESTADISTICA!D4 -> Domo | E6: =ESTADISTICA!E4 -> FIBRA OPTICA | F6: =ESTADISTICA!F4 -> 0 | G6: =ESTADISTICA!G4 -> 0 | H6: =ESTADISTICA!H4 -> 0 | ... AJ6: =ESTADISTICA!AJ4 -> #REF!
A7: =ESTADISTICA!A5 -> ALTAMIRA | B7: =ESTADISTICA!B5 -> ALT 04 | C7: =ESTADISTICA!C5 -> Francia y Necochea | D7: =ESTADISTICA!D5 -> Domo | E7: =ESTADISTICA!E5 -> FIBRA OPTICA | F7: =ESTADISTICA!F5 -> 0 | G7: =ESTADISTICA!G5 -> 0 | H7: =ESTADISTICA!H5 -> 0 | ... AJ7: =ESTADISTICA!AJ5 -> #REF!
A8: =ESTADISTICA!A6 -> ALTAMIRA | B8: =ESTADISTICA!B6 -> ALT05 | C8: =ESTADISTICA!C6 -> Av. Calchaqui y Bombero Galarza | D8: =ESTADISTICA!D6 -> Domo | E8: =ESTADISTICA!E6 -> PTO A FO | F8: =ESTADISTICA!F6 -> 0 | G8: =ESTADISTICA!G6 -> 0 | H8: =ESTADISTICA!H6 -> 0 | ... AJ8: =ESTADISTICA!AJ6 -> #REF!
A9: =ESTADISTICA!A7 -> ALTAMIRA | B9: =ESTADISTICA!B7 -> ALT 06 | C9: =ESTADISTICA!C7 -> LOPE DE VEGA Y NECOCHEA | D9: =ESTADISTICA!D7 -> Domo | E9: =ESTADISTICA!E7 -> PTO A FO | F9: =ESTADISTICA!F7 -> 0 | G9: =ESTADISTICA!G7 -> 0 | H9: =ESTADISTICA!H7 -> 0 | ... AJ9: =ESTADISTICA!AJ7 -> #REF!
A10: =ESTADISTICA!A8 -> ALTAMIRA | B10: =ESTADISTICA!B8 -> ALT07 | C10: =ESTADISTICA!C8 -> AV. CALCHAQUI Y AV. DEL TRABAJO | D10: =ESTADISTICA!D8 -> DOMO | E10: =ESTADISTICA!E8 -> PTO A FO | F10: =ESTADISTICA!F8 -> 0 | G10: =ESTADISTICA!G8 -> 0 | H10: =ESTADISTICA!H8 -> 0 | ... AJ10: =ESTADISTICA!AJ8 -> #REF!
A11: =ESTADISTICA!A9 -> ALTAMIRA | B11: =ESTADISTICA!B9 -> ALT 08 | C11: =ESTADISTICA!C9 -> HUMAITA Y NECOCHEA | D11: =ESTADISTICA!D9 -> DOMO | E11: =ESTADISTICA!E9 -> Fibra Optica | F11: =ESTADISTICA!F9 -> 0 | G11: =ESTADISTICA!G9 -> 0 | H11: =ESTADISTICA!H9 -> 0 | ... AJ11: =ESTADISTICA!AJ9 -> #REF!
A12: =ESTADISTICA!A10 -> ALTAMIRA | B12: =ESTADISTICA!B10 -> ALT 09 | C12: =ESTADISTICA!C10 -> NECOCHEA Y CURUPAITY | D12: =ESTADISTICA!D10 -> DOMO | E12: =ESTADISTICA!E10 -> Fibra Optica | F12: =ESTADISTICA!F10 -> 0 | G12: =ESTADISTICA!G10 -> 0 | H12: =ESTADISTICA!H10 -> 0 | ... AJ12: =ESTADISTICA!AJ10 -> #REF!
A13: =ESTADISTICA!A11 -> ALTAMIRA | B13: =ESTADISTICA!B11 -> ALT 10 | C13: =ESTADISTICA!C11 -> Calchaqui y Francia | D13: =ESTADISTICA!D11 -> Domo | E13: =ESTADISTICA!E11 -> Radio | F13: =ESTADISTICA!F11 -> 0 | G13: =ESTADISTICA!G11 -> 0 | H13: =ESTADISTICA!H11 -> 0 | ... AJ13: =ESTADISTICA!AJ11 -> #REF!
A14: =ESTADISTICA!A12 -> AGUSTIN RAMIREZ | B14: =ESTADISTICA!B12 -> ARA 01 | C14: =ESTADISTICA!C12 -> Malambo y Tranquera | D14: =ESTADISTICA!D12 -> Domo | E14: =ESTADISTICA!E12 -> FIBRA OPTICA | F14: =ESTADISTICA!F12 -> 0 | G14: =ESTADISTICA!G12 -> 0 | H14: =ESTADISTICA!H12 -> 0 | ... AJ14: =ESTADISTICA!AJ12 -> #REF!
... A571: =ESTADISTICA!A569 -> 0 | B571: =ESTADISTICA!B569 -> 0 | C571: =ESTADISTICA!C569 -> 0 | D571: =ESTADISTICA!D569 -> 0 | E571: =ESTADISTICA!E569 -> 0 | F571: =ESTADISTICA!F569 -> 0 | G571: =ESTADISTICA!G569 -> 0 | H571: =ESTADISTICA!H569 -> 0 | ... AJ571: =ESTADISTICA!AJ569 -> #REF!
A572: =ESTADISTICA!A570 -> 0 | B572: =ESTADISTICA!B570 -> 0 | C572: =ESTADISTICA!C570 -> 0 | D572: =ESTADISTICA!D570 -> 0 | E572: =ESTADISTICA!E570 -> 0 | F572: =ESTADISTICA!F570 -> 0 | G572: =ESTADISTICA!G570 -> 0 | H572: =ESTADISTICA!H570 -> 0 | ... AI572: =ESTADISTICA!AI570 -> 0
A573: =ESTADISTICA!A571 -> 0 | B573: =ESTADISTICA!B571 -> 0 | C573: =ESTADISTICA!C571 -> 0 | D573: =ESTADISTICA!D571 -> 0 | E573: =ESTADISTICA!E571 -> 0 | F573: =ESTADISTICA!F571 -> 0 | G573: =ESTADISTICA!G571 -> 0 | H573: =ESTADISTICA!H571 -> 0 | ... AI573: =ESTADISTICA!AI571 -> 0
A574: =ESTADISTICA!A572 -> 0 | B574: =ESTADISTICA!B572 -> 0 | C574: =ESTADISTICA!C572 -> 0 | D574: =ESTADISTICA!D572 -> 0 | E574: =ESTADISTICA!E572 -> 0 | F574: =ESTADISTICA!F572 -> 0 | G574: =ESTADISTICA!G572 -> 0 | H574: =ESTADISTICA!H572 -> 0 | ... AI574: =ESTADISTICA!AI572 -> 0
A575: =ESTADISTICA!A573 -> 0 | B575: =ESTADISTICA!B573 -> 0 | C575: =ESTADISTICA!C573 -> 0 | D575: =ESTADISTICA!D573 -> 0 | E575: =ESTADISTICA!E573 -> 0 | F575: =ESTADISTICA!F573 -> 0 | G575: =ESTADISTICA!G573 -> 0 | H575: =ESTADISTICA!H573 -> 0 | ... AI575: =ESTADISTICA!AI573 -> 0
A576: =ESTADISTICA!A574 -> 0 | B576: =ESTADISTICA!B574 -> 0 | C576: =ESTADISTICA!C574 -> 0 | D576: =ESTADISTICA!D574 -> 0 | E576: =ESTADISTICA!E574 -> 0 | F576: =ESTADISTICA!F574 -> 0 | G576: =ESTADISTICA!G574 -> 0 | H576: =ESTADISTICA!H574 -> 0 | ... AI576: =ESTADISTICA!AI574 -> 0
A577: =ESTADISTICA!A575 -> 0 | B577: =ESTADISTICA!B575 -> 0 | C577: =ESTADISTICA!C575 -> 0 | D577: =ESTADISTICA!D575 -> 0 | E577: =ESTADISTICA!E575 -> 0 | F577: =ESTADISTICA!F575 -> 0 | G577: =ESTADISTICA!G575 -> 0 | H577: =ESTADISTICA!H575 -> 0 | ... AI577: =ESTADISTICA!AI575 -> 0
A578: =ESTADISTICA!A576 -> 0 | B578: =ESTADISTICA!B576 -> 0 | C578: =ESTADISTICA!C576 -> 0 | D578: =ESTADISTICA!D576 -> 0 | E578: =ESTADISTICA!E576 -> 0 | F578: =ESTADISTICA!F576 -> 0 | G578: =ESTADISTICA!G576 -> 0 | H578: =ESTADISTICA!H576 -> 0 | ... AI578: =ESTADISTICA!AI576 -> 0
A579: =ESTADISTICA!A577 -> 0 | B579: =ESTADISTICA!B577 -> 0 | C579: =ESTADISTICA!C577 -> 0 | D579: =ESTADISTICA!D577 -> 0 | E579: =ESTADISTICA!E577 -> 0 | F579: =ESTADISTICA!F577 -> 0 | G579: =ESTADISTICA!G577 -> 0 | H579: =ESTADISTICA!H577 -> 0 | ... AI579: =ESTADISTICA!AI577 -> 0
A580: =ESTADISTICA!A578 -> 0 | B580: =ESTADISTICA!B578 -> 0 | C580: =ESTADISTICA!C578 -> 0 | D580: =ESTADISTICA!D578 -> 0 | E580: =ESTADISTICA!E578 -> 0 | F580: =ESTADISTICA!F578 -> 0 | G580: =ESTADISTICA!G578 -> 0 | H580: =ESTADISTICA!H578 -> 0 | ... AI580: =ESTADISTICA!AI578 -> 0
A581: =ESTADISTICA!A579 -> 0 | B581: =ESTADISTICA!B579 -> 0 | C581: =ESTADISTICA!C579 -> 0 | D581: =ESTADISTICA!D579 -> 0 | E581: =ESTADISTICA!E579 -> 0 | F581: =ESTADISTICA!F579 -> 0 | G581: =ESTADISTICA!G579 -> 0 | H581: =ESTADISTICA!H579 -> 0 | ... AI581: =ESTADISTICA!AI579 -> 0
A582: =ESTADISTICA!A580 -> 0 | B582: =ESTADISTICA!B580 -> 0 | C582: =ESTADISTICA!C580 -> 0 | D582: =ESTADISTICA!D580 -> 0 | E582: =ESTADISTICA!E580 -> 0 | F582: =ESTADISTICA!F580 -> 0 | G582: =ESTADISTICA!G580 -> 0 | H582: =ESTADISTICA!H580 -> 0 | ... AI582: =ESTADISTICA!AI580 -> 0
A583: =ESTADISTICA!A581 -> 0 | B583: =ESTADISTICA!B581 -> 0 | C583: =ESTADISTICA!C581 -> 0 | D583: =ESTADISTICA!D581 -> 0 | E583: =ESTADISTICA!E581 -> 0 | F583: =ESTADISTICA!F581 -> 0 | G583: =ESTADISTICA!G581 -> 0 | H583: =ESTADISTICA!H581 -> 0 | ... AI583: =ESTADISTICA!AI581 -> 0
... A601: =ESTADISTICA!A599 -> 0 | B601: =ESTADISTICA!B599 -> 0 | C601: =ESTADISTICA!C599 -> 0 | D601: =ESTADISTICA!D599 -> 0 | E601: =ESTADISTICA!E599 -> 0 | F601: =ESTADISTICA!F599 -> 0 | G601: =ESTADISTICA!G599 -> 0 | H601: =ESTADISTICA!H599 -> 0 | ... AI601: =ESTADISTICA!AI599 -> 0

Sheet APAGADOS ANTENA
C1: TOTAL PTO A FO
E2: APAGADOS | F2: =COUNTIFS(F4:F500, "=APAGADO",E4:E500,"=PTO A FO") -> 10 | G2: =COUNTIFS(G4:G500, "=APAGADO",E4:E500,"=PTO A FO") -> 0 | H2: =COUNTIFS(H4:H500, "=APAGADO",E4:E500,"=PTO A FO") -> 0 | I2: =COUNTIFS(I4:I500, "=APAGADO",E4:E500,"=PTO A FO") -> 0 | J2: =COUNTIFS(J4:J500, "=APAGADO",E4:E500,"=PTO A FO") -> 0 | K2: =COUNTIFS(K4:K500, "=APAGADO",E4:E500,"=PTO A FO") -> 0 | L2: =COUNTIFS(L4:L500, "=APAGADO",E4:E500,"=PTO A FO") -> 0 | M2: =COUNTIFS(M4:M500, "=APAGADO",E4:E500,"=PTO A FO") -> 0 | N2: =COUNTIFS(N4:N500, "=APAGADO",E4:E500,"=PTO A FO") -> 0 | O2: =COUNTIFS(O4:O500, "=APAGADO",E4:E500,"=PTO A FO") -> 0 | P2: =COUNTIFS(P4:P500, "=APAGADO",E4:E500,"=PTO A FO") -> 0 | Q2: =COUNTIFS(Q4:Q500, "=APAGADO",E4:E500,"=PTO A FO") -> 0 | R2: =COUNTIFS(R4:R500, "=APAGADO",E4:E500,"=PTO A FO") -> 0 | S2: =COUNTIFS(S4:S500, "=APAGADO",E4:E500,"=PTO A FO") -> 0 | T2: =COUNTIFS(T4:T500, "=APAGADO",E4:E500,"=PTO A FO") -> 0 | U2: =COUNTIFS(U4:U500, "=APAGADO",E4:E500,"=PTO A FO") -> 0 | V2: =COUNTIFS(V4:V500, "=APAGADO",E4:E500,"=PTO A FO") -> 0 | W2: =COUNTIFS(W4:W500, "=APAGADO",E4:E500,"=PTO A FO") -> 0 | X2: =COUNTIFS(X4:X500, "=APAGADO",E4:E500,"=PTO A FO") -> 0 | Y2: =COUNTIFS(Y4:Y500, "=APAGADO",E4:E500,"=PTO A FO") -> 0 | Z2: =COUNTIFS(Z4:Z500, "=APAGADO",E4:E500,"=PTO A FO") -> 0 | AA2: =COUNTIFS(AA4:AA500, "=APAGADO",E4:E500,"=PTO A FO") -> 0 | AB2: =COUNTIFS(AB4:AB500, "=APAGADO",E4:E500,"=PTO A FO") -> 0 | AC2: =COUNTIFS(AC4:AC500, "=APAGADO",E4:E500,"=PTO A FO") -> 0 | AD2: =COUNTIFS(AD4:AD500, "=APAGADO",E4:E500,"=PTO A FO") -> 0 | AE2: =COUNTIFS(AE4:AE500, "=APAGADO",E4:E500,"=PTO A FO") -> 0 | AF2: =COUNTIFS(AF4:AF500, "=APAGADO",E4:E500,"=PTO A FO") -> 0 | AG2: =COUNTIFS(AG4:AG500, "=APAGADO",E4:E500,"=PTO A FO") -> 0 | AH2: =COUNTIFS(AH4:AH500, "=APAGADO",E4:E500,"=PTO A FO") -> 0 | AI2: =COUNTIFS(AI4:AI500, "=APAGADO",E4:E500,"=PTO A FO") -> 0
A3: =ESTADISTICA!A1 -> Barrio | B3: =ESTADISTICA!B1 -> [Denominacion] | C3: =ESTADISTICA!C1 -> [Ubicacion] | D3: =ESTADISTICA!D1 -> [Tipo de Camara] | E3: =ESTADISTICA!E1 -> [Tipo de Conexion] | F3: =ESTADISTICA!F1 -> 45078 | G3: =ESTADISTICA!G1 -> 45079 | H3: =ESTADISTICA!H1 -> 45080 | ... AI3: =ESTADISTICA!AI1 -> 45107
A4: =ESTADISTICA!A2 -> ALTAMIRA | B4: =ESTADISTICA!B2 -> ALT01 | C4: =ESTADISTICA!C2 -> Calchaqui y Sgto. Cabral | D4: =ESTADISTICA!D2 -> Domo | E4: =ESTADISTICA!E2 -> Fibra Optica | F4: =ESTADISTICA!F2 -> 0 | G4: =ESTADISTICA!G2 -> 0 | H4: =ESTADISTICA!H2 -> 0 | ... AI4: =ESTADISTICA!AI2 -> 0
A5: =ESTADISTICA!A3 -> ALTAMIRA | B5: =ESTADISTICA!B3 -> ALT02 | C5: =ESTADISTICA!C3 -> Calchaqui y Lope de Vega | D5: =ESTADISTICA!D3 -> Domo | E5: =ESTADISTICA!E3 -> PTO A FO | F5: =ESTADISTICA!F3 -> 0 | G5: =ESTADISTICA!G3 -> 0 | H5: =ESTADISTICA!H3 -> 0 | ... AI5: =ESTADISTICA!AI3 -> 0
A6: =ESTADISTICA!A4 -> ALTAMIRA | B6: =ESTADISTICA!B4 -> ALT 03 | C6: =ESTADISTICA!C4 -> Bombero Galarza y Necochea | D6: =ESTADISTICA!D4 -> Domo | E6: =ESTADISTICA!E4 -> FIBRA OPTICA | F6: =ESTADISTICA!F4 -> 0 | G6: =ESTADISTICA!G4 -> 0 | H6: =ESTADISTICA!H4 -> 0 | ... AI6: =ESTADISTICA!AI4 -> 0
A7: =ESTADISTICA!A5 -> ALTAMIRA | B7: =ESTADISTICA!B5 -> ALT 04 | C7: =ESTADISTICA!C5 -> Francia y Necochea | D7: =ESTADISTICA!D5 -> Domo | E7: =ESTADISTICA!E5 -> FIBRA OPTICA | F7: =ESTADISTICA!F5 -> 0 | G7: =ESTADISTICA!G5 -> 0 | H7: =ESTADISTICA!H5 -> 0 | ... AI7: =ESTADISTICA!AI5 -> 0
A8: =ESTADISTICA!A6 -> ALTAMIRA | B8: =ESTADISTICA!B6 -> ALT05 | C8: =ESTADISTICA!C6 -> Av. Calchaqui y Bombero Galarza | D8: =ESTADISTICA!D6 -> Domo | E8: =ESTADISTICA!E6 -> PTO A FO | F8: =ESTADISTICA!F6 -> 0 | G8: =ESTADISTICA!G6 -> 0 | H8: =ESTADISTICA!H6 -> 0 | ... AI8: =ESTADISTICA!AI6 -> 0
A9: =ESTADISTICA!A7 -> ALTAMIRA | B9: =ESTADISTICA!B7 -> ALT 06 | C9: =ESTADISTICA!C7 -> LOPE DE VEGA Y NECOCHEA | D9: =ESTADISTICA!D7 -> Domo | E9: =ESTADISTICA!E7 -> PTO A FO | F9: =ESTADISTICA!F7 -> 0 | G9: =ESTADISTICA!G7 -> 0 | H9: =ESTADISTICA!H7 -> 0 | ... AI9: =ESTADISTICA!AI7 -> 0
A10: =ESTADISTICA!A8 -> ALTAMIRA | B10: =ESTADISTICA!B8 -> ALT07 | C10: =ESTADISTICA!C8 -> AV. CALCHAQUI Y AV. DEL TRABAJO | D10: =ESTADISTICA!D8 -> DOMO | E10: =ESTADISTICA!E8 -> PTO A FO | F10: =ESTADISTICA!F8 -> 0 | G10: =ESTADISTICA!G8 -> 0 | H10: =ESTADISTICA!H8 -> 0 | ... AI10: =ESTADISTICA!AI8 -> 0
A11: =ESTADISTICA!A9 -> ALTAMIRA | B11: =ESTADISTICA!B9 -> ALT 08 | C11: =ESTADISTICA!C9 -> HUMAITA Y NECOCHEA | D11: =ESTADISTICA!D9 -> DOMO | E11: =ESTADISTICA!E9 -> Fibra Optica | F11: =ESTADISTICA!F9 -> 0 | G11: =ESTADISTICA!G9 -> 0 | H11: =ESTADISTICA!H9 -> 0 | ... AI11: =ESTADISTICA!AI9 -> 0
A12: =ESTADISTICA!A10 -> ALTAMIRA | B12: =ESTADISTICA!B10 -> ALT 09 | C12: =ESTADISTICA!C10 -> NECOCHEA Y CURUPAITY | D12: =ESTADISTICA!D10 -> DOMO | E12: =ESTADISTICA!E10 -> Fibra Optica | F12: =ESTADISTICA!F10 -> 0 | G12: =ESTADISTICA!G10 -> 0 | H12: =ESTADISTICA!H10 -> 0 | ... AI12: =ESTADISTICA!AI10 -> 0
A13: =ESTADISTICA!A11 -> ALTAMIRA | B13: =ESTADISTICA!B11 -> ALT 10 | C13: =ESTADISTICA!C11 -> Calchaqui y Francia | D13: =ESTADISTICA!D11 -> Domo | E13: =ESTADISTICA!E11 -> Radio | F13: =ESTADISTICA!F11 -> 0 | G13: =ESTADISTICA!G11 -> 0 | H13: =ESTADISTICA!H11 -> 0 | ... AI13: =ESTADISTICA!AI11 -> 0
A14: =ESTADISTICA!A12 -> AGUSTIN RAMIREZ | B14: =ESTADISTICA!B12 -> ARA 01 | C14: =ESTADISTICA!C12 -> Malambo y Tranquera | D14: =ESTADISTICA!D12 -> Domo | E14: =ESTADISTICA!E12 -> FIBRA OPTICA | F14: =ESTADISTICA!F12 -> 0 | G14: =ESTADISTICA!G12 -> 0 | H14: =ESTADISTICA!H12 -> 0 | ... AI14: =ESTADISTICA!AI12 -> 0
... A539: =ESTADISTICA!A537 -> 0 | B539: =ESTADISTICA!B537 -> 0 | C539: =ESTADISTICA!C537 -> 0 | D539: =ESTADISTICA!D537 -> 0 | E539: =ESTADISTICA!E537 -> 0 | F539: =ESTADISTICA!F537 -> 0 | G539: =ESTADISTICA!G537 -> 0 | H539: =ESTADISTICA!H537 -> 0 | ... AI539: =ESTADISTICA!AI537 -> 0

Sheet APAGADOS RADIO
C1: TOTAL RADIO | D1: =COUNTIFS(E4:E400,"=radio") -> 95
E2: APAGADOS | F2: =COUNTIFS(F4:F500, "=APAGADO",E4:E500,"=radio") -> 11 | G2: =COUNTIFS(G4:G500, "=APAGADO",E4:E500,"=radio") -> 0 | H2: =COUNTIFS(H4:H500, "=APAGADO",E4:E500,"=radio") -> 0 | I2: =COUNTIFS(I4:I500, "=APAGADO",E4:E500,"=radio") -> 0 | J2: =COUNTIFS(J4:J500, "=APAGADO",E4:E500,"=radio") -> 0 | K2: =COUNTIFS(K4:K500, "=APAGADO",E4:E500,"=radio") -> 0 | L2: =COUNTIFS(L4:L500, "=APAGADO",E4:E500,"=radio") -> 0 | M2: =COUNTIFS(M4:M500, "=APAGADO",E4:E500,"=radio") -> 0 | N2: =COUNTIFS(N4:N500, "=APAGADO",E4:E500,"=radio") -> 0 | O2: =COUNTIFS(O4:O500, "=APAGADO",E4:E500,"=radio") -> 0 | P2: =COUNTIFS(P4:P500, "=APAGADO",E4:E500,"=radio") -> 0 | Q2: =COUNTIFS(Q4:Q367, "=APAGADO",E4:E367,"=radio") -> 0 | R2: =COUNTIFS(R4:R500, "=APAGADO",E4:E500,"=radio") -> 0 | S2: =COUNTIFS(S4:S500, "=APAGADO",E4:E500,"=radio") -> 0 | T2: =COUNTIFS(T4:T500, "=APAGADO",E4:E500,"=radio") -> 0 | U2: =COUNTIFS(U4:U500, "=APAGADO",E4:E500,"=radio") -> 0 | V2: =COUNTIFS(V4:V500, "=APAGADO",E4:E500,"=radio") -> 0 | W2: =COUNTIFS(W4:W500, "=APAGADO",E4:E500,"=radio") -> 0 | X2: =COUNTIFS(X4:X500, "=APAGADO",E4:E500,"=radio") -> 0 | Y2: =COUNTIFS(Y4:Y500, "=APAGADO",E4:E500,"=radio") -> 0 | Z2: =COUNTIFS(Z4:Z500, "=APAGADO",E4:E500,"=radio") -> 0 | AA2: =COUNTIFS(AA4:AA500, "=APAGADO",E4:E500,"=radio") -> 0 | AB2: =COUNTIFS(AB4:AB500, "=APAGADO",E4:E500,"=radio") -> 0 | AC2: =COUNTIFS(AC4:AC500, "=APAGADO",E4:E500,"=radio") -> 0 | AD2: =COUNTIFS(AD4:AD500, "=APAGADO",E4:E500,"=radio") -> 0 | AE2: =COUNTIFS(AE4:AE500, "=APAGADO",E4:E500,"=radio") -> 0 | AF2: =COUNTIFS(AF4:AF500, "=APAGADO",E4:E500,"=radio") -> 0 | AG2: =COUNTIFS(AG4:AG500, "=APAGADO",E4:E500,"=radio") -> 0 | AH2: =COUNTIFS(AH4:AH500, "=APAGADO",F4:F500,"=radio") -> 0 | AI2: =COUNTIFS(AI4:AI500, "=APAGADO",G4:G500,"=radio") -> 0 | AJ2: =COUNTIFS(AJ4:AJ500, "=APAGADO",H4:H500,"=radio") -> 0
A3: =ESTADISTICA!A1 -> Barrio | B3: =ESTADISTICA!B1 -> [Denominacion] | C3: =ESTADISTICA!C1 -> [Ubicacion] | D3: =ESTADISTICA!D1 -> [Tipo de Camara] | E3: =ESTADISTICA!E1 -> [Tipo de Conexion] | F3: =ESTADISTICA!F1 -> 45078 | G3: =ESTADISTICA!G1 -> 45079 | H3: =ESTADISTICA!H1 -> 45080 | ... AJ3: =ESTADISTICA!AJ1 -> #REF!
A4: =ESTADISTICA!A2 -> ALTAMIRA | B4: =ESTADISTICA!B2 -> ALT01 | C4: =ESTADISTICA!C2 -> Calchaqui y Sgto. Cabral | D4: =ESTADISTICA!D2 -> Domo | E4: =ESTADISTICA!E2 -> Fibra Optica | F4: =ESTADISTICA!F2 -> 0 | G4: =ESTADISTICA!G2 -> 0 | H4: =ESTADISTICA!H2 -> 0 | ... AI4: =ESTADISTICA!AI2 -> 0
A5: =ESTADISTICA!A3 -> ALTAMIRA | B5: =ESTADISTICA!B3 -> ALT02 | C5: =ESTADISTICA!C3 -> Calchaqui y Lope de Vega | D5: =ESTADISTICA!D3 -> Domo | E5: =ESTADISTICA!E3 -> PTO A FO | F5: =ESTADISTICA!F3 -> 0 | G5: =ESTADISTICA!G3 -> 0 | H5: =ESTADISTICA!H3 -> 0 | ... AI5: =ESTADISTICA!AI3 -> 0
A6: =ESTADISTICA!A4 -> ALTAMIRA | B6: =ESTADISTICA!B4 -> ALT 03 | C6: =ESTADISTICA!C4 -> Bombero Galarza y Necochea | D6: =ESTADISTICA!D4 -> Domo | E6: =ESTADISTICA!E4 -> FIBRA OPTICA | F6: =ESTADISTICA!F4 -> 0 | G6: =ESTADISTICA!G4 -> 0 | H6: =ESTADISTICA!H4 -> 0 | ... AI6: =ESTADISTICA!AI4 -> 0
A7: =ESTADISTICA!A5 -> ALTAMIRA | B7: =ESTADISTICA!B5 -> ALT 04 | C7: =ESTADISTICA!C5 -> Francia y Necochea | D7: =ESTADISTICA!D5 -> Domo | E7: =ESTADISTICA!E5 -> FIBRA OPTICA | F7: =ESTADISTICA!F5 -> 0 | G7: =ESTADISTICA!G5 -> 0 | H7: =ESTADISTICA!H5 -> 0 | ... AI7: =ESTADISTICA!AI5 -> 0
A8: =ESTADISTICA!A6 -> ALTAMIRA | B8: =ESTADISTICA!B6 -> ALT05 | C8: =ESTADISTICA!C6 -> Av. Calchaqui y Bombero Galarza | D8: =ESTADISTICA!D6 -> Domo | E8: =ESTADISTICA!E6 -> PTO A FO | F8: =ESTADISTICA!F6 -> 0 | G8: =ESTADISTICA!G6 -> 0 | H8: =ESTADISTICA!H6 -> 0 | ... AI8: =ESTADISTICA!AI6 -> 0
A9: =ESTADISTICA!A7 -> ALTAMIRA | B9: =ESTADISTICA!B7 -> ALT 06 | C9: =ESTADISTICA!C7 -> LOPE DE VEGA Y NECOCHEA | D9: =ESTADISTICA!D7 -> Domo | E9: =ESTADISTICA!E7 -> PTO A FO | F9: =ESTADISTICA!F7 -> 0 | G9: =ESTADISTICA!G7 -> 0 | H9: =ESTADISTICA!H7 -> 0 | ... AI9: =ESTADISTICA!AI7 -> 0
A10: =ESTADISTICA!A8 -> ALTAMIRA | B10: =ESTADISTICA!B8 -> ALT07 | C10: =ESTADISTICA!C8 -> AV. CALCHAQUI Y AV. DEL TRABAJO | D10: =ESTADISTICA!D8 -> DOMO | E10: =ESTADISTICA!E8 -> PTO A FO | F10: =ESTADISTICA!F8 -> 0 | G10: =ESTADISTICA!G8 -> 0 | H10: =ESTADISTICA!H8 -> 0 | ... AI10: =ESTADISTICA!AI8 -> 0
A11: =ESTADISTICA!A9 -> ALTAMIRA | B11: =ESTADISTICA!B9 -> ALT 08 | C11: =ESTADISTICA!C9 -> HUMAITA Y NECOCHEA | D11: =ESTADISTICA!D9 -> DOMO | E11: =ESTADISTICA!E9 -> Fibra Optica | F11: =ESTADISTICA!F9 -> 0 | G11: =ESTADISTICA!G9 -> 0 | H11: =ESTADISTICA!H9 -> 0 | ... AI11: =ESTADISTICA!AI9 -> 0
A12: =ESTADISTICA!A10 -> ALTAMIRA | B12: =ESTADISTICA!B10 -> ALT 09 | C12: =ESTADISTICA!C10 -> NECOCHEA Y CURUPAITY | D12: =ESTADISTICA!D10 -> DOMO | E12: =ESTADISTICA!E10 -> Fibra Optica | F12: =ESTADISTICA!F10 -> 0 | G12: =ESTADISTICA!G10 -> 0 | H12: =ESTADISTICA!H10 -> 0 | ... AI12: =ESTADISTICA!AI10 -> 0
A13: =ESTADISTICA!A11 -> ALTAMIRA | B13: =ESTADISTICA!B11 -> ALT 10 | C13: =ESTADISTICA!C11 -> Calchaqui y Francia | D13: =ESTADISTICA!D11 -> Domo | E13: =ESTADISTICA!E11 -> Radio | F13: =ESTADISTICA!F11 -> 0 | G13: =ESTADISTICA!G11 -> 0 | H13: =ESTADISTICA!H11 -> 0 | ... AI13: =ESTADISTICA!AI11 -> 0
A14: =ESTADISTICA!A12 -> AGUSTIN RAMIREZ | B14: =ESTADISTICA!B12 -> ARA 01 | C14: =ESTADISTICA!C12 -> Malambo y Tranquera | D14: =ESTADISTICA!D12 -> Domo | E14: =ESTADISTICA!E12 -> FIBRA OPTICA | F14: =ESTADISTICA!F12 -> 0 | G14: =ESTADISTICA!G12 -> 0 | H14: =ESTADISTICA!H12 -> 0 | ... AI14: =ESTADISTICA!AI12 -> 0
A15: =ESTADISTICA!A13 -> BELGRANO | B15: =ESTADISTICA!B13 -> BEL 01 | C15: =ESTADISTICA!C13 -> San Martin y Dardo Rocha | D15: =ESTADISTICA!D13 -> DOMO | E15: =ESTADISTICA!E13 -> FIBRA OPTICA | F15: =ESTADISTICA!F13 -> 0 | G15: =ESTADISTICA!G13 -> 0 | H15: =ESTADISTICA!H13 -> 0 | ... AJ15: =ESTADISTICA!AJ13 -> #REF!
A16: =ESTADISTICA!A14 -> BOSQUES CENTRO | B16: =ESTADISTICA!B14 -> BOSQC 01 | C16: =ESTADISTICA!C14 -> LUIS AGOTE E/DANUNCIO Y CAMPOAMOR | D16: =ESTADISTICA!D14 -> Fija | E16: =ESTADISTICA!E14 -> Radio | F16: =ESTADISTICA!F14 -> 0 | G16: =ESTADISTICA!G14 -> 0 | H16: =ESTADISTICA!H14 -> 0 | ... AI16: =ESTADISTICA!AI14 -> 0
A17: =ESTADISTICA!A15 -> BOSQUES CENTRO | B17: =ESTADISTICA!B15 -> BOSQC 02 | C17: =ESTADISTICA!C15 -> LUIS AGOTE E/DANUNCIO Y CAMPOAMOR | D17: =ESTADISTICA!D15 -> Fija | E17: =ESTADISTICA!E15 -> Radio | F17: =ESTADISTICA!F15 -> 0 | G17: =ESTADISTICA!G15 -> 0 | H17: =ESTADISTICA!H15 -> 0 | ... AI17: =ESTADISTICA!AI15 -> 0
A18: =ESTADISTICA!A16 -> BOSQUES CENTRO | B18: =ESTADISTICA!B16 -> BOSQC 03 | C18: =ESTADISTICA!C16 -> BENAVENTE Y LUIS AGOTE | D18: =ESTADISTICA!D16 -> Fija | E18: =ESTADISTICA!E16 -> Radio | F18: =ESTADISTICA!F16 -> 0 | G18: =ESTADISTICA!G16 -> 0 | H18: =ESTADISTICA!H16 -> 0 | ... AI18: =ESTADISTICA!AI16 -> 0
A19: =ESTADISTICA!A17 -> BOSQUES CENTRO | B19: =ESTADISTICA!B17 -> BOSQC 04 | C19: =ESTADISTICA!C17 -> BENAVENTE Y LUIS AGOTE | D19: =ESTADISTICA!D17 -> Fija | E19: =ESTADISTICA!E17 -> Radio | F19: =ESTADISTICA!F17 -> 0 | G19: =ESTADISTICA!G17 -> 0 | H19: =ESTADISTICA!H17 -> 0 | ... AI19: =ESTADISTICA!AI17 -> 0
A20: =ESTADISTICA!A18 -> BOSQUES CENTRO | B20: =ESTADISTICA!B18 -> BOSQC 05 | C20: =ESTADISTICA!C18 -> LUIS AGOTE Y RUTA 36 | D20: =ESTADISTICA!D18 -> Fija | E20: =ESTADISTICA!E18 -> Radio | F20: =ESTADISTICA!F18 -> 0 | G20: =ESTADISTICA!G18 -> 0 | H20: =ESTADISTICA!H18 -> 0 | ... AI20: =ESTADISTICA!AI18 -> 0
A21: =ESTADISTICA!A19 -> BOSQUES CENTRO | B21: =ESTADISTICA!B19 -> BOSQC 06 | C21: =ESTADISTICA!C19 -> LUIS AGOTE Y RUTA 36 | D21: =ESTADISTICA!D19 -> Fija | E21: =ESTADISTICA!E19 -> Radio | F21: =ESTADISTICA!F19 -> 0 | G21: =ESTADISTICA!G19 -> 0 | H21: =ESTADISTICA!H19 -> 0 | ... AI21: =ESTADISTICA!AI19 -> 0
A22: =ESTADISTICA!A20 -> CENTRO | B22: =ESTADISTICA!B20 -> CEN01 | C22: =ESTADISTICA!C20 -> San Martin y 9 de Julio | D22: =ESTADISTICA!D20 -> Fija | E22: =ESTADISTICA!E20 -> Fibra Optica | F22: =ESTADISTICA!F20 -> 0 | G22: =ESTADISTICA!G20 -> 0 | H22: =ESTADISTICA!H20 -> 0 | ... AI22: =ESTADISTICA!AI20 -> 0
A23: =ESTADISTICA!A21 -> CENTRO | B23: =ESTADISTICA!B21 -> CEN02 | C23: =ESTADISTICA!C21 -> San Martin y Almafuerte | D23: =ESTADISTICA!D21 -> Fija | E23: =ESTADISTICA!E21 -> Fibra Optica | F23: =ESTADISTICA!F21 -> 0 | G23: =ESTADISTICA!G21 -> 0 | H23: =ESTADISTICA!H21 -> 0 | ... AI23: =ESTADISTICA!AI21 -> 0
A24: =ESTADISTICA!A22 -> CENTRO | B24: =ESTADISTICA!B22 -> CEN03 | C24: =ESTADISTICA!C22 -> San Martin y Sallares | D24: =ESTADISTICA!D22 -> Domo | E24: =ESTADISTICA!E22 -> Fibra Optica | F24: =ESTADISTICA!F22 -> 0 | G24: =ESTADISTICA!G22 -> 0 | H24: =ESTADISTICA!H22 -> 0 | ... AI24: =ESTADISTICA!AI22 -> 0
A25: =ESTADISTICA!A23 -> CENTRO | B25: =ESTADISTICA!B23 -> CEN04 | C25: =ESTADISTICA!C23 -> San Martin y Contreras | D25: =ESTADISTICA!D23 -> Domo | E25: =ESTADISTICA!E23 -> Fibra Optica | F25: =ESTADISTICA!F23 -> 0 | G25: =ESTADISTICA!G23 -> 0 | H25: =ESTADISTICA!H23 -> 0 | ... AI25: =ESTADISTICA!AI23 -> 0
A26: =ESTADISTICA!A24 -> CENTRO | B26: =ESTADISTICA!B24 -> CEN 05 | C26: =ESTADISTICA!C24 -> Bocuzzi e/España y San Martin | D26: =ESTADISTICA!D24 -> DOMO | E26: =ESTADISTICA!E24 -> Fibra Optica | F26: =ESTADISTICA!F24 -> 0 | G26: =ESTADISTICA!G24 -> 0 | H26: =ESTADISTICA!H24 -> 0 | ... AI26: =ESTADISTICA!AI24 -> 0
A27: =ESTADISTICA!A25 -> CENTRO | B27: =ESTADISTICA!B25 -> CEN06 | C27: =ESTADISTICA!C25 -> Monteagudo y A.del Valle | D27: =ESTADISTICA!D25 -> Fija | E27: =ESTADISTICA!E25 -> Fibra Optica | F27: =ESTADISTICA!F25 -> 0 | G27: =ESTADISTICA!G25 -> 0 | H27: =ESTADISTICA!H25 -> 0 | ... AI27: =ESTADISTICA!AI25 -> 0
... A39: =ESTADISTICA!A37 -> CENTRO | B39: =ESTADISTICA!B37 -> CEN18 | C39: =ESTADISTICA!C37 -> Monteagudo e/Mitre y Sallares | D39: =ESTADISTICA!D37 -> Fija | E39: =ESTADISTICA!E37 -> Fibra Optica | F39: =ESTADISTICA!F37 -> 0 | G39: =ESTADISTICA!G37 -> 0 | H39: =ESTADISTICA!H37 -> 0 | ... AI39: =ESTADISTICA!AI37 -> 0
A40: =ESTADISTICA!A38 -> CENTRO | B40: =ESTADISTICA!B38 -> CEN19 | C40: =ESTADISTICA!C38 -> Chacabuco y 25 de Mayo | D40: =ESTADISTICA!D38 -> Fija | E40: =ESTADISTICA!E38 -> Fibra Optica | F40: =ESTADISTICA!F38 -> 0 | G40: =ESTADISTICA!G38 -> 0 | H40: =ESTADISTICA!H38 -> 0 | ... AJ40: =ESTADISTICA!AJ38 -> #REF!
A41: =ESTADISTICA!A39 -> LOMAS DE MONTEVERDE | B41: =ESTADISTICA!B39 -> CEN20 | C41: =ESTADISTICA!C39 -> Pte. Illia y Las Heras | D41: =ESTADISTICA!D39 -> Domo | E41: =ESTADISTICA!E39 -> Fibra Optica | F41: =ESTADISTICA!F39 -> 0 | G41: =ESTADISTICA!G39 -> 0 | H41: =ESTADISTICA!H39 -> 0 | ... AI41: =ESTADISTICA!AI39 -> 0
A42: =ESTADISTICA!A40 -> CENTRO | B42: =ESTADISTICA!B40 -> CEN21 | C42: =ESTADISTICA!C40 -> Misiones y Urquiza | D42: =ESTADISTICA!D40 -> Fija | E42: =ESTADISTICA!E40 -> Radio | F42: =ESTADISTICA!F40 -> 0 | G42: =ESTADISTICA!G40 -> 0 | H42: =ESTADISTICA!H40 -> 0 | ... AI42: =ESTADISTICA!AI40 -> 0
A43: =ESTADISTICA!A41 -> CENTRO | B43: =ESTADISTICA!B41 -> CEN22 | C43: =ESTADISTICA!C41 -> Las Heras y Chacabuco | D43: =ESTADISTICA!D41 -> Domo | E43: =ESTADISTICA!E41 -> Radio | F43: =ESTADISTICA!F41 -> 0 | G43: =ESTADISTICA!G41 -> 0 | H43: =ESTADISTICA!H41 -> 0 | ... AI43: =ESTADISTICA!AI41 -> 0
A44: =ESTADISTICA!A42 -> CENTRO | B44: =ESTADISTICA!B42 -> CEN23 | C44: =ESTADISTICA!C42 -> Sallares y Monteagudo | D44: =ESTADISTICA!D42 -> Domo | E44: =ESTADISTICA!E42 -> Fibra Optica | F44: =ESTADISTICA!F42 -> 0 | G44: =ESTADISTICA!G42 -> 0 | H44: =ESTADISTICA!H42 -> 0 | ... AI44: =ESTADISTICA!AI42 -> 0
A45: =ESTADISTICA!A43 -> CENTRO | B45: =ESTADISTICA!B43 -> CEN24 | C45: =ESTADISTICA!C43 -> Sallares y España | D45: =ESTADISTICA!D43 -> Domo | E45: =ESTADISTICA!E43 -> Fibra Optica | F45: =ESTADISTICA!F43 -> 0 | G45: =ESTADISTICA!G43 -> 0 | H45: =ESTADISTICA!H43 -> 0 | ... AI45: =ESTADISTICA!AI43 -> 0
A46: =ESTADISTICA!A44 -> CENTRO | B46: =ESTADISTICA!B44 -> CEN25 | C46: =ESTADISTICA!C44 -> SAN MARTIN Y 9 DE JULIO | D46: =ESTADISTICA!D44 -> Domo | E46: =ESTADISTICA!E44 -> Fibra Optica | F46: =ESTADISTICA!F44 -> 0 | G46: =ESTADISTICA!G44 -> 0 | H46: =ESTADISTICA!H44 -> 0 | ... AI46: =ESTADISTICA!AI44 -> 0
A47: =ESTADISTICA!A45 -> CENTRO | B47: =ESTADISTICA!B45 -> CEN26 | C47: =ESTADISTICA!C45 -> Mitre y España | D47: =ESTADISTICA!D45 -> Domo | E47: =ESTADISTICA!E45 -> Fibra Optica | F47: =ESTADISTICA!F45 -> 0 | G47: =ESTADISTICA!G45 -> 0 | H47: =ESTADISTICA!H45 -> 0 | ... AI47: =ESTADISTICA!AI45 -> 0
A48: =ESTADISTICA!A46 -> CENTRO | B48: =ESTADISTICA!B46 -> CEN27 | C48: =ESTADISTICA!C46 -> San Juan y España | D48: =ESTADISTICA!D46 -> Domo | E48: =ESTADISTICA!E46 -> Fibra Optica | F48: =ESTADISTICA!F46 -> 0 | G48: =ESTADISTICA!G46 -> 0 | H48: =ESTADISTICA!H46 -> 0 | ... AJ48: =ESTADISTICA!AJ46 -> #REF!
A49: =ESTADISTICA!A47 -> CENTRO | B49: =ESTADISTICA!B47 -> CEN28 | C49: =ESTADISTICA!C47 -> Mitre y Alberdi | D49: =ESTADISTICA!D47 -> Domo | E49: =ESTADISTICA!E47 -> Fibra Optica | F49: =ESTADISTICA!F47 -> 0 | G49: =ESTADISTICA!G47 -> 0 | H49: =ESTADISTICA!H47 -> 0 | ... AI49: =ESTADISTICA!AI47 -> 0
A50: =ESTADISTICA!A48 -> CENTRO | B50: =ESTADISTICA!B48 -> CEN29 | C50: =ESTADISTICA!C48 -> Alberdi y San Juan | D50: =ESTADISTICA!D48 -> Domo | E50: =ESTADISTICA!E48 -> Fibra Optica | F50: =ESTADISTICA!F48 -> 0 | G50: =ESTADISTICA!G48 -> 0 | H50: =ESTADISTICA!H48 -> 0 | ... AI50: =ESTADISTICA!AI48 -> 0
A51: =ESTADISTICA!A49 -> CENTRO | B51: =ESTADISTICA!B49 -> CEN30 | C51: =ESTADISTICA!C49 -> Mitre y Pringles | D51: =ESTADISTICA!D49 -> Domo | E51: =ESTADISTICA!E49 -> Fibra Optica | F51: =ESTADISTICA!F49 -> 0 | G51: =ESTADISTICA!G49 -> 0 | H51: =ESTADISTICA!H49 -> 0 | ... AI51: =ESTADISTICA!AI49 -> 0
...

Sheet BARRAS

Sheet PORCENTAJE

Sheet informe
B1: CANTIDAD | D1: %
A2: TOTAL | B2: 444 | E2: 45078
A3: CAIDAS | B3: 57 | C3: =B3 -> 57 | D3: =C3/B2 -> 0.12837838
A4: LLEGAMOS NOSOTROS | B4: 12 | C4: =C3-B4 -> 45 | D4: =C4/B2 -> 0.10135135
A5: NO ESTA LA CAMARA | B5: 1 | C5: =C4-B5 -> 44 | D5: =C5/B2 -> 0.099099099
A6: RADIO | B6: 11 | C6: =C5-B6 -> 33 | D6: =C6/B2 -> 0.074324324

Sheet Hoja2
C3: CAMARAS | D3: 153
B4: BONOMO | C4: 236 | D4: 29
D5: =D4/BONOMOcam -> 0.12288136
B6: COSEIDI | C6: 208 | D6: 28
D7: =D6/COSEIDIcam -> 0.13461538

Sheet AUXILIAR
A1: FECHA | B1: RADIO | C1: FIBRA | D1: ANTENA | E1: TOTAL APAGADOS | F1: INSTALADAS | G1: % APAGADOS
A2: ='APAGADOS RADIO'!F3 -> 45078 | B2: ='APAGADOS RADIO'!F2+D2 -> 21 | C2: ='APAGADOS FIBRA'!F2 -> 35 | D2: ='APAGADOS ANTENA'!F2 -> 10 | E2: =B2+C2 -> 56 | F2: ='RESUMEN TOTAL'!B1 -> 444 | G2: =E2/F2 -> 0.12612613
A3: ='APAGADOS RADIO'!G3 -> 45079 | B3: ='APAGADOS RADIO'!G2+D3 -> 0 | C3: ='APAGADOS FIBRA'!G2 -> 0 | D3: ='APAGADOS ANTENA'!G2 -> 0 | E3: =B3+C3 -> 0 | F3: ='RESUMEN TOTAL'!B1 -> 444 | G3: =E3/F3 -> 0
A4: ='APAGADOS RADIO'!H3 -> 45080 | B4: ='APAGADOS RADIO'!H2+D4 -> 0 | C4: ='APAGADOS FIBRA'!H2 -> 0 | D4: ='APAGADOS ANTENA'!H2 -> 0 | E4: =B4+C4 -> 0 | F4: ='RESUMEN TOTAL'!B1 -> 444 | G4: =E4/F4 -> 0
A5: ='APAGADOS RADIO'!I3 -> 45081 | B5: ='APAGADOS RADIO'!I2+D5 -> 0 | C5: ='APAGADOS FIBRA'!I2 -> 0 | D5: ='APAGADOS ANTENA'!I2 -> 0 | E5: =B5+C5 -> 0 | F5: ='RESUMEN TOTAL'!B1 -> 444 | G5: =E5/F5 -> 0
A6: ='APAGADOS RADIO'!J3 -> 45082 | B6: ='APAGADOS RADIO'!J2+D6 -> 0 | C6: ='APAGADOS FIBRA'!J2 -> 0 | D6: ='APAGADOS ANTENA'!J2 -> 0 | E6: =B6+C6 -> 0 | F6: ='RESUMEN TOTAL'!B1 -> 444 | G6: =E6/F6 -> 0
A7: ='APAGADOS RADIO'!K3 -> 45083 | B7: ='APAGADOS RADIO'!K2+D7 -> 0 | C7: ='APAGADOS FIBRA'!K2 -> 0 | D7: ='APAGADOS ANTENA'!K2 -> 0 | E7: =B7+C7 -> 0 | F7: ='RESUMEN TOTAL'!B1 -> 444 | G7: =E7/F7 -> 0
A8: ='APAGADOS RADIO'!L3 -> 45084 | B8: ='APAGADOS RADIO'!L2+D8 -> 0 | C8: ='APAGADOS FIBRA'!L2 -> 0 | D8: ='APAGADOS ANTENA'!L2 -> 0 | E8: =B8+C8 -> 0 | F8: ='RESUMEN TOTAL'!B1 -> 444 | G8: =E8/F8 -> 0
A9: ='APAGADOS RADIO'!M3 -> 45085 | B9: ='APAGADOS RADIO'!M2+D9 -> 0 | C9: ='APAGADOS FIBRA'!M2 -> 0 | D9: ='APAGADOS ANTENA'!M2 -> 0 | E9: =B9+C9 -> 0 | F9: ='RESUMEN TOTAL'!B1 -> 444 | G9: =E9/F9 -> 0
A10: ='APAGADOS RADIO'!N3 -> 45086 | B10: ='APAGADOS RADIO'!N2+D10 -> 0 | C10: ='APAGADOS FIBRA'!N2 -> 0 | D10: ='APAGADOS ANTENA'!N2 -> 0 | E10: =B10+C10 -> 0 | F10: ='RESUMEN TOTAL'!B1 -> 444 | G10: =E10/F10 -> 0
A11: ='APAGADOS RADIO'!O3 -> 45087 | B11: ='APAGADOS RADIO'!O2+D11 -> 0 | C11: ='APAGADOS FIBRA'!O2 -> 0 | D11: ='APAGADOS ANTENA'!O2 -> 0 | E11: =B11+C11 -> 0 | F11: ='RESUMEN TOTAL'!B1 -> 444 | G11: =E11/F11 -> 0
A12: ='APAGADOS RADIO'!P3 -> 45088 | B12: ='APAGADOS RADIO'!P2+D12 -> 0 | C12: ='APAGADOS FIBRA'!P2 -> 0 | D12: ='APAGADOS ANTENA'!P2 -> 0 | E12: =B12+C12 -> 0 | F12: ='RESUMEN TOTAL'!B1 -> 444 | G12: =E12/F12 -> 0
A13: ='APAGADOS RADIO'!Q3 -> 45089 | B13: ='APAGADOS RADIO'!Q2+D13 -> 0 | C13: ='APAGADOS FIBRA'!Q2 -> 0 | D13: ='APAGADOS ANTENA'!Q2 -> 0 | E13: =B13+C13 -> 0 | F13: ='RESUMEN TOTAL'!B1 -> 444 | G13: =E13/F13 -> 0
A14: ='APAGADOS RADIO'!R3 -> 45090 | B14: ='APAGADOS RADIO'!R2+D14 -> 0 | C14: ='APAGADOS FIBRA'!R2 -> 0 | D14: ='APAGADOS ANTENA'!R2 -> 0 | E14: =B14+C14 -> 0 | F14: ='RESUMEN TOTAL'!B1 -> 444 | G14: =E14/F14 -> 0
A15: ='APAGADOS RADIO'!S3 -> 45091 | B15: ='APAGADOS RADIO'!S2+D15 -> 0 | C15: ='APAGADOS FIBRA'!S2 -> 0 | D15: ='APAGADOS ANTENA'!S2 -> 0 | E15: =B15+C15 -> 0 | F15: ='RESUMEN TOTAL'!B1 -> 444 | G15: =E15/F15 -> 0
A16: ='APAGADOS RADIO'!T3 -> 45092 | B16: ='APAGADOS RADIO'!T2+D16 -> 0 | C16: ='APAGADOS FIBRA'!T2 -> 0 | D16: ='APAGADOS ANTENA'!T2 -> 0 | E16: =B16+C16 -> 0 | F16: ='RESUMEN TOTAL'!B1 -> 444 | G16: =E16/F16 -> 0
A17: ='APAGADOS RADIO'!U3 -> 45093 | B17: ='APAGADOS RADIO'!U2+D17 -> 0 | C17: ='APAGADOS FIBRA'!U2 -> 0 | D17: ='APAGADOS ANTENA'!U2 -> 0 | E17: =B17+C17 -> 0 | F17: ='RESUMEN TOTAL'!B1 -> 444 | G17: =E17/F17 -> 0
A18: ='APAGADOS RADIO'!V3 -> 45094 | B18: ='APAGADOS RADIO'!V2+D18 -> 0 | C18: ='APAGADOS FIBRA'!V2 -> 0 | D18: ='APAGADOS ANTENA'!V2 -> 0 | E18: =B18+C18 -> 0 | F18: ='RESUMEN TOTAL'!B1 -> 444 | G18: =E18/F18 -> 0
A19: ='APAGADOS RADIO'!W3 -> 45095
A20: ='APAGADOS RADIO'!X3 -> 45096
A21: ='APAGADOS RADIO'!Y3 -> 45097
A22: ='APAGADOS RADIO'!Z3 -> 45098
A23: ='APAGADOS RADIO'!AA3 -> 45099
A24: ='APAGADOS RADIO'!AB3 -> 45100
A25: ='APAGADOS RADIO'!AC3 -> 45101
A26: ='APAGADOS RADIO'!AD3 -> 45102
A27: ='APAGADOS RADIO'!AE3 -> 45103
A28: ='APAGADOS RADIO'!AF3 -> 45104
A29: ='APAGADOS RADIO'!AG3 -> 45105
A30: ='APAGADOS RADIO'!AH3 -> 45106
A31: ='APAGADOS RADIO'!AI3 -> 45107
A32: ='APAGADOS RADIO'!AJ3 -> #REF!

Sheet GRAFICO2

Sheet Hoja1
B1: CAMARAS
A2: BONOMO | B2: =COUNTIFS('RESUMEN TOTAL'!C5:C512,"=BONOMO") -> 236 | F2: 45078 | G2: 45079 | H2: 45080 | I2: 45081 | J2: 45082 | K2: 45083 | L2: 45084 | M2: 45085 | N2: 45086 | O2: 45087 | P2: 45088 | Q2: 45089 | R2: 45090 | S2: 45091 | T2: 45092 | U2: 45093 | V2: 45094 | W2: 45095 | X2: 45096 | Y2: 45097 | Z2: 45098 | AA2: 45099 | AB2: 45100 | AC2: 45101 | AD2: 45102 | AE2: 45103 | AF2: 45104 | AG2: 45105 | AH2: 45106 | AI2: 45107
