Workbook
Name _25_de_agosto: 'RESUMEN TOTAL'!$A$4:$D$379
Name _25_de_agosto_3: 'RESUMEN TOTAL'!$A$4:$D$391
Name BONOMOcam: Hoja1!$B$2
Name CANTIDAD_DE_CAMARAS: 'RESUMEN TOTAL'!$B$1
Name COSEIDIcam: Hoja1!$B$4

Sheet RESUMEN TOTAL
A1: CANTIDAD DE CAMARAS | B1: =COUNTA(B5:B546) -> 448 | D1: PORCIENTO DE CAIDAS | L1: =(L3)/(L2+L3) -> 0 | M1: =(M3)/(M2+M3) -> 0 | N1: =(N3)/(N2+N3) -> 0.040178571 | O1: =(O3)/(O2+O3) -> 0 | P1: =(P3)/(P2+P3) -> 0 | Q1: =(Q3)/(Q2+Q3) -> 0 | R1: =(R3)/(R2+R3) -> 0 | S1: =(S3)/(S2+S3) -> 0 | ... X1: =(X3)/(X2+X3) -> 0 | Z1: =(Z3)/(Z2+Z3) -> 0 | AA1: =(AA3)/(AA2+AA3) -> 0 | AB1: =(AB3)/(AB2+AB3) -> 0 | AC1: =(AC3)/(AC2+AC3) -> 0 | AD1: =(AD3)/(AD2+AD3) -> 0 | AE1: =(AE3)/(AE2+AE3) -> 0 | AF1: =(AF3)/(AF2+AF3) -> 0 | AG1: =(AG3)/(AG2+AG3) -> 0 | ... AO1: =(AO3)/(AO2+AO3) -> 0
D2: FUNCIONAN | L2: =B1-L3 -> 448 | M2: =CANTIDAD_DE_CAMARAS-M3 -> 448 | N2: =CANTIDAD_DE_CAMARAS-N3 -> 430 | O2: =CANTIDAD_DE_CAMARAS-O3 -> 448 | P2: =CANTIDAD_DE_CAMARAS-P3 -> 448 | Q2: =CANTIDAD_DE_CAMARAS-Q3 -> 448 | R2: =CANTIDAD_DE_CAMARAS-R3 -> 448 | S2: =CANTIDAD_DE_CAMARAS-S3 -> 448 | T2: =CANTIDAD_DE_CAMARAS-T3 -> 448 | ... AO2: =CANTIDAD_DE_CAMARAS-AO3 -> 448
D3: CAIDAS | L3: =COUNTIF(L4:L466, "apagado") -> 0 | M3: =COUNTIF(M4:M466, "apagado") -> 0 | N3: =COUNTIF(N4:N466, "apagado") -> 18 | O3: =COUNTIF(O4:O466, "apagado") -> 0 | P3: =COUNTIF(P4:P466, "apagado") -> 0 | Q3: =COUNTIF(Q4:Q466, "apagado") -> 0 | R3: =COUNTIF(R4:R466, "apagado") -> 0 | S3: =COUNTIF(S4:S466, "apagado") -> 0 | ... AO3: =COUNTIF(AO4:AO466, "apagado") -> 0
A4: Barrio | B4: [Denominacion] | C4: [Empresa Mantenimiento] | D4: [Ubicacion] | E4: [Tipo de Camara] | F4: [Tipo de Conexion] | G4: Destino | I4: DIAS FUNCIONANDO | J4: DIAS CAIDA | K4: EFECTIVIDAD | L4: 45108 | M4: 45109 | N4: 45110 | O4: 45111 | P4: 45112 | Q4: 45113 | R4: 45114 | S4: 45115 | T4: 45116 | U4: 45117 | V4: 45118 | W4: 45119 | X4: 45120 | Y4: 45121 | Z4: 45122 | AA4: 45123 | AB4: 45124 | AC4: 45125 | AD4: 45126 | AE4: 45127 | AF4: 45128 | AG4: 45129 | AH4: 45130 | AI4: 45131 | AJ4: 45132 | AK4: 45133 | AL4: 45134 | AM4: 45135 | AN4: 45136 | AO4: 45137 | AP4: 45138
A5: ALTAMIRA | B5: ALT01 | C5: BONOMO | D5: Calchaqui y Sgto. Cabral | E5: Domo | F5: Fibra Optica | H5: 172.20.10.6 | I5: =COUNTIF(L5:AM5,"") -> 28 | J5: =COUNTIF(L5:AM5,"APAGADO") -> 0 | K5: =(I5)/(J5+I5) -> 1
A6: ALTAMIRA | B6: ALT02 | C6: BONOMO | D6: Calchaqui y Lope de Vega | E6: Domo | F6: PTO A FO | G6: CABRAL Y CALCHAQUI | H6: 172.20.12.218 | I6: =COUNTIF(L6:AM6,"") -> 28 | J6: =COUNTIF(L6:AM6,"APAGADO") -> 0 | K6: =(I6)/(J6+I6) -> 1
A7: ALTAMIRA | B7: ALT 03 | C7: BONOMO | D7: Bombero Galarza y Necochea | E7: Domo | F7: Fibra Optica | H7: 172.20.12.54 | I7: =COUNTIF(L7:AM7,"") -> 28 | J7: =COUNTIF(L7:AM7,"APAGADO") -> 0 | K7: =(I7)/(J7+I7) -> 1
A8: ALTAMIRA | B8: ALT 04 | C8: BONOMO | D8: Francia y Necochea | E8: Domo | F8: Fibra Optica | H8: 172.20.12.55 | I8: =COUNTIF(L8:AM8,"") -> 28 | J8: =COUNTIF(L8:AM8,"APAGADO") -> 0 | K8: =(I8)/(J8+I8) -> 1
A9: ALTAMIRA | B9: ALT05 | C9: BONOMO | D9: Av. Calchaqui y Bombero Galarza | E9: Domo | F9: PTO A FO | G9: NECOCHEA Y GALARZA | H9: 172.20.12.216 | I9: =COUNTIF(L9:AM9,"") -> 28 | J9: =COUNTIF(L9:AM9,"APAGADO") -> 0 | K9: =(I9)/(J9+I9) -> 1
A10: ALTAMIRA | B10: ALT 06 | C10: BONOMO | D10: LOPE DE VEGA Y NECOCHEA | E10: Domo | F10: PTO A FO | G10: NECOCHEA Y GALARZA | H10: 172.20.12.12 | I10: =COUNTIF(L10:AM10,"") -> 28 | J10: =COUNTIF(L10:AM10,"APAGADO") -> 0 | K10: =(I10)/(J10+I10) -> 1
A11: ALTAMIRA | B11: ALT07 | C11: BONOMO | D11: AV. CALCHAQUI Y AV. DEL TRABAJO | E11: DOMO | F11: PTO A FO | G11: CABRAL Y CALCHAQUI | H11: 172.20.10.57 | I11: =COUNTIF(L11:AM11,"") -> 28 | J11: =COUNTIF(L11:AM11,"APAGADO") -> 0 | K11: =(I11)/(J11+I11) -> 1
A12: ALTAMIRA | B12: ALT 08 | C12: BONOMO | D12: HUMAITA Y NECOCHEA | E12: DOMO | F12: Fibra Optica | H12: 172.20.11.215 | I12: =COUNTIF(L12:AM12,"") -> 28 | J12: =COUNTIF(L12:AM12,"APAGADO") -> 0 | K12: =(I12)/(J12+I12) -> 1
A13: ALTAMIRA | B13: ALT 09 | C13: BONOMO | D13: NECOCHEA Y CURUPAITY | E13: DOMO | F13: Fibra Optica | H13: 172.20.11.216 | I13: =COUNTIF(L13:AM13,"") -> 28 | J13: =COUNTIF(L13:AM13,"APAGADO") -> 0 | K13: =(I13)/(J13+I13) -> 1
A14: ALTAMIRA | B14: ALT 10 | C14: BONOMO | D14: Calchaqui y Francia | E14: Domo | F14: Radio | H14: 172.20.12.156 | I14: =COUNTIF(L14:AM14,"") -> 28 | J14: =COUNTIF(L14:AM14,"APAGADO") -> 0 | K14: =(I14)/(J14+I14) -> 1
A15: AGUSTIN RAMIREZ | B15: ARA 01 | C15: COSEIDI | D15: Malambo y Tranquera | E15: Domo | F15: Fibra Optica | H15: 172.20.12.110 | I15: =COUNTIF(L15:AM15,"") -> 28 | J15: =COUNTIF(L15:AM15,"APAGADO") -> 0 | K15: =(I15)/(J15+I15) -> 1
A16: BELGRANO | B16: BEL 01 | C16: BONOMO | D16: San Martin y Dardo Rocha | E16: DOMO | F16: Fibra Optica | H16: 172.20.12.64 | I16: =COUNTIF(L16:AM16,"") -> 28 | J16: =COUNTIF(L16:AM16,"APAGADO") -> 0 | K16: =(I16)/(J16+I16) -> 1
A17: BELGRANO | B17: BEL 02 | C17: BONOMO | D17: Guardia vieja y Fronteriz | E17: DOMO | F17: Fibra Optica | I17: =COUNTIF(L17:AM17,"") -> 28 | J17: =COUNTIF(L17:AM17,"APAGADO") -> 0 | K17: =(I17)/(J17+I17) -> 1
A18: BOSQUES CENTRO | B18: BOSQC 01 | C18: COSEIDI | D18: LUIS AGOTE E/DANUNCIO Y CAMPOAMOR | E18: Fija | F18: Radio | H18: 172.20.11.15 | I18: =COUNTIF(L18:AM18,"") -> 28 | J18: =COUNTIF(L18:AM18,"APAGADO") -> 0 | K18: =(I18)/(J18+I18) -> 1
A19: BOSQUES CENTRO | B19: BOSQC 02 | C19: COSEIDI | D19: LUIS AGOTE E/DANUNCIO Y CAMPOAMOR | E19: Fija | F19: Radio | H19: 172.20.11.16 | I19: =COUNTIF(L19:AM19,"") -> 28 | J19: =COUNTIF(L19:AM19,"APAGADO") -> 0 | K19: =(I19)/(J19+I19) -> 1
A20: BOSQUES CENTRO | B20: BOSQC 03 | C20: COSEIDI | D20: BENAVENTE Y LUIS AGOTE | E20: Fija | F20: Radio | H20: 172.20.11.13 | I20: =COUNTIF(L20:AM20,"") -> 28 | J20: =COUNTIF(L20:AM20,"APAGADO") -> 0 | K20: =(I20)/(J20+I20) -> 1
A21: BOSQUES CENTRO | B21: BOSQC 04 | C21: COSEIDI | D21: BENAVENTE Y LUIS AGOTE | E21: Fija | F21: Radio | H21: 172.20.11.113 | I21: =COUNTIF(L21:AM21,"") -> 28 | J21: =COUNTIF(L21:AM21,"APAGADO") -> 0 | K21: =(I21)/(J21+I21) -> 1
A22: BOSQUES CENTRO | B22: BOSQC 05 | C22: COSEIDI | D22: LUIS AGOTE Y RUTA 36 | E22: Fija | F22: Radio | H22: 172.20.11.17 | I22: =COUNTIF(L22:AM22,"") -> 28 | J22: =COUNTIF(L22:AM22,"APAGADO") -> 0 | K22: =(I22)/(J22+I22) -> 1
A23: BOSQUES CENTRO | B23: BOSQC 06 | C23: COSEIDI | D23: LUIS AGOTE Y RUTA 36 | E23: Fija | F23: Radio | H23: 172.20.11.18 | I23: =COUNTIF(L23:AM23,"") -> 28 | J23: =COUNTIF(L23:AM23,"APAGADO") -> 0 | K23: =(I23)/(J23+I23) -> 1
A24: CENTRO | B24: CEN01 | C24: BONOMO | D24: San Martin y 9 de Julio | E24: Fija | F24: Fibra Optica | H24: 172.20.11.10 | I24: =COUNTIF(L24:AM24,"") -> 28 | J24: =COUNTIF(L24:AM24,"APAGADO") -> 0 | K24: =(I24)/(J24+I24) -> 1
A25: CENTRO | B25: CEN02 | C25: BONOMO | D25: San Martin y Almafuerte | E25: Fija | F25: Fibra Optica | H25: 172.20.11.11 | I25: =COUNTIF(L25:AM25,"") -> 28 | J25: =COUNTIF(L25:AM25,"APAGADO") -> 0 | K25: =(I25)/(J25+I25) -> 1
A26: CENTRO | B26: CEN03 | C26: BONOMO | D26: San Martin y Sallares | E26: Domo | F26: Fibra Optica | H26: 172.20.12.30 | I26: =COUNTIF(L26:AM26,"") -> 28 | J26: =COUNTIF(L26:AM26,"APAGADO") -> 0 | K26: =(I26)/(J26+I26) -> 1
A27: CENTRO | B27: CEN04 | C27: BONOMO | D27: San Martin y Contreras | E27: Domo | F27: Fibra Optica | H27: 172.20.12.29 | I27: =COUNTIF(L27:AM27,"") -> 28 | J27: =COUNTIF(L27:AM27,"APAGADO") -> 0 | K27: =(I27)/(J27+I27) -> 1
A28: CENTRO | B28: CEN 05 | C28: BONOMO | D28: Bocuzzi e/España y San Martin | E28: DOMO | F28: Fibra Optica | H28: 172.20.10.200 | I28: =COUNTIF(L28:AM28,"") -> 28 | J28: =COUNTIF(L28:AM28,"APAGADO") -> 0 | K28: =(I28)/(J28+I28) -> 1
A29: CENTRO | B29: CEN06 | C29: BONOMO | D29: Monteagudo y A.del Valle | E29: Fija | F29: Fibra Optica | H29: 172.20.10.02 | I29: =COUNTIF(L29:AM29,"") -> 28 | J29: =COUNTIF(L29:AM29,"APAGADO") -> 0 | K29: =(I29)/(J29+I29) -> 1
... A39: CENTRO | B39: CEN16 | C39: BONOMO | D39: San Martin y Pte. Peron | E39: Fija | F39: Fibra Optica | H39: 172.20.12.36 | I39: =COUNTIF(L39:AM39,"") -> 28 | J39: =COUNTIF(L39:AM39,"APAGADO") -> 0 | K39: =(I39)/(J39+I39) -> 1
A40: CENTRO | B40: CEN17 | C40: BONOMO | D40: San Martin y Mitre | E40: Domo | F40: PTO A FO | G40: SAN MARTIN Y SALLARES | H40: 172.20.12.200 | I40: =COUNTIF(L40:AM40,"") -> 28 | J40: =COUNTIF(L40:AM40,"APAGADO") -> 0 | K40: =(I40)/(J40+I40) -> 1
A41: CENTRO | B41: CEN18 | C41: BONOMO | D41: Monteagudo e/Mitre y Sallares | E41: Fija | F41: Fibra Optica | H41: 172.20.10.26 | I41: =COUNTIF(L41:AM41,"") -> 28 | J41: =COUNTIF(L41:AM41,"APAGADO") -> 0 | K41: =(I41)/(J41+I41) -> 1
A42: CENTRO | B42: CEN19 | C42: BONOMO | D42: Chacabuco y 25 de Mayo | E42: Fija | F42: Fibra Optica | H42: 172.20.10.27 | I42: =COUNTIF(L42:AM42,"") -> 28 | J42: =COUNTIF(L42:AM42,"APAGADO") -> 0 | K42: =(I42)/(J42+I42) -> 1
A43: LOMAS DE MONTEVERDE | B43: CEN20 | C43: BONOMO | D43: Pte. Illia y Las Heras | E43: Domo | F43: Fibra Optica | H43: 172.20.10.33 | I43: =COUNTIF(L43:AM43,"") -> 28 | J43: =COUNTIF(L43:AM43,"APAGADO") -> 0 | K43: =(I43)/(J43+I43) -> 1
A44: CENTRO | B44: CEN21 | C44: BONOMO | D44: Misiones y Urquiza | E44: Fija | F44: Radio | H44: 172.20.200.132 | I44: =COUNTIF(L44:AM44,"") -> 28 | J44: =COUNTIF(L44:AM44,"APAGADO") -> 0 | K44: =(I44)/(J44+I44) -> 1
A45: CENTRO | B45: CEN22 | C45: BONOMO | D45: Las Heras y Chacabuco | E45: Domo | F45: Radio | H45: 172.20.200.125 | I45: =COUNTIF(L45:AM45,"") -> 28 | J45: =COUNTIF(L45:AM45,"APAGADO") -> 0 | K45: =(I45)/(J45+I45) -> 1
A46: CENTRO | B46: CEN23 | C46: BONOMO | D46: Sallares y Monteagudo | E46: Domo | F46: Fibra Optica | H46: 172.20.12.05 | I46: =COUNTIF(L46:AM46,"") -> 28 | J46: =COUNTIF(L46:AM46,"APAGADO") -> 0 | K46: =(I46)/(J46+I46) -> 1
A47: CENTRO | B47: CEN24 | C47: BONOMO | D47: Sallares y España | E47: Domo | F47: Fibra Optica | H47: 172.20.12.04 | I47: =COUNTIF(L47:AM47,"") -> 28 | J47: =COUNTIF(L47:AM47,"APAGADO") -> 0 | K47: =(I47)/(J47+I47) -> 1
A48: CENTRO | B48: CEN25 | C48: BONOMO | D48: SAN MARTIN Y 9 DE JULIO | E48: Domo | F48: Fibra Optica | H48: 172.20.12.02 | I48: =COUNTIF(L48:AM48,"") -> 28 | J48: =COUNTIF(L48:AM48,"APAGADO") -> 0 | K48: =(I48)/(J48+I48) -> 1
A49: CENTRO | B49: CEN26 | C49: BONOMO | D49: Mitre y España | E49: Domo | F49: Fibra Optica | H49: 172.20.12.06 | I49: =COUNTIF(L49:AM49,"") -> 28 | J49: =COUNTIF(L49:AM49,"APAGADO") -> 0 | K49: =(I49)/(J49+I49) -> 1
...

Sheet ESTADISTICA
A1: ='RESUMEN TOTAL'!A4 -> Barrio | B1: ='RESUMEN TOTAL'!B4 -> [Denominacion] | C1: ='RESUMEN TOTAL'!D4 -> [Ubicacion] | D1: ='RESUMEN TOTAL'!E4 -> [Tipo de Camara] | E1: ='RESUMEN TOTAL'!F4 -> [Tipo de Conexion] | F1: ='RESUMEN TOTAL'!L4 -> 45108 | G1: ='RESUMEN TOTAL'!M4 -> 45109 | H1: ='RESUMEN TOTAL'!N4 -> 45110 | I1: ='RESUMEN TOTAL'!O4 -> 45111 | J1: ='RESUMEN TOTAL'!P4 -> 45112 | K1: ='RESUMEN TOTAL'!Q4 -> 45113 | L1: ='RESUMEN TOTAL'!R4 -> 45114 | M1: ='RESUMEN TOTAL'!S4 -> 45115 | ... AI1: ='RESUMEN TOTAL'!AO4 -> 45137 | AJ1: ='RESUMEN TOTAL'!#REF! -> #REF!
A2: ='RESUMEN TOTAL'!A5 -> ALTAMIRA | B2: ='RESUMEN TOTAL'!B5 -> ALT01 | C2: ='RESUMEN TOTAL'!D5 -> Calchaqui y Sgto. Cabral | D2: ='RESUMEN TOTAL'!E5 -> Domo | E2: ='RESUMEN TOTAL'!F5 -> Fibra Optica | F2: ='RESUMEN TOTAL'!L5 -> 0 | G2: ='RESUMEN TOTAL'!M5 -> 0 | H2: ='RESUMEN TOTAL'!N5 -> 0 | I2: ='RESUMEN TOTAL'!O5 -> 0 | J2: ='RESUMEN TOTAL'!P5 -> 0 | K2: ='RESUMEN TOTAL'!Q5 -> 0 | L2: ='RESUMEN TOTAL'!R5 -> 0 | M2: ='RESUMEN TOTAL'!S5 -> 0 | ... AI2: ='RESUMEN TOTAL'!AO5 -> 0 | AJ2: ='RESUMEN TOTAL'!#REF! -> #REF!
A3: ='RESUMEN TOTAL'!A6 -> ALTAMIRA | B3: ='RESUMEN TOTAL'!B6 -> ALT02 | C3: ='RESUMEN TOTAL'!D6 -> Calchaqui y Lope de Vega | D3: ='RESUMEN TOTAL'!E6 -> Domo | E3: ='RESUMEN TOTAL'!F6 -> PTO A FO | F3: ='RESUMEN TOTAL'!L6 -> 0 | G3: ='RESUMEN TOTAL'!M6 -> 0 | H3: ='RESUMEN TOTAL'!N6 -> 0 | I3: ='RESUMEN TOTAL'!O6 -> 0 | J3: ='RESUMEN TOTAL'!P6 -> 0 | K3: ='RESUMEN TOTAL'!Q6 -> 0 | L3: ='RESUMEN TOTAL'!R6 -> 0 | M3: ='RESUMEN TOTAL'!S6 -> 0 | ... AI3: ='RESUMEN TOTAL'!AO6 -> 0 | AJ3: ='RESUMEN TOTAL'!#REF! -> #REF!
A4: ='RESUMEN TOTAL'!A7 -> ALTAMIRA | B4: ='RESUMEN TOTAL'!B7 -> ALT 03 | C4: ='RESUMEN TOTAL'!D7 -> Bombero Galarza y Necochea | D4: ='RESUMEN TOTAL'!E7 -> Domo | E4: ='RESUMEN TOTAL'!F7 -> Fibra Optica | F4: ='RESUMEN TOTAL'!L7 -> 0 | G4: ='RESUMEN TOTAL'!M7 -> 0 | H4: ='RESUMEN TOTAL'!N7 -> 0 | I4: ='RESUMEN TOTAL'!O7 -> 0 | J4: ='RESUMEN TOTAL'!P7 -> 0 | K4: ='RESUMEN TOTAL'!Q7 -> 0 | L4: ='RESUMEN TOTAL'!R7 -> 0 | M4: ='RESUMEN TOTAL'!S7 -> 0 | ... AI4: ='RESUMEN TOTAL'!AO7 -> 0 | AJ4: ='RESUMEN TOTAL'!#REF! -> #REF!
A5: ='RESUMEN TOTAL'!A8 -> ALTAMIRA | B5: ='RESUMEN TOTAL'!B8 -> ALT 04 | C5: ='RESUMEN TOTAL'!D8 -> Francia y Necochea | D5: ='RESUMEN TOTAL'!E8 -> Domo | E5: ='RESUMEN TOTAL'!F8 -> Fibra Optica | F5: ='RESUMEN TOTAL'!L8 -> 0 | G5: ='RESUMEN TOTAL'!M8 -> 0 | H5: ='RESUMEN TOTAL'!N8 -> 0 | I5: ='RESUMEN TOTAL'!O8 -> 0 | J5: ='RESUMEN TOTAL'!P8 -> 0 | K5: ='RESUMEN TOTAL'!Q8 -> 0 | L5: ='RESUMEN TOTAL'!R8 -> 0 | M5: ='RESUMEN TOTAL'!S8 -> 0 | ... AI5: ='RESUMEN TOTAL'!AO8 -> 0 | AJ5: ='RESUMEN TOTAL'!#REF! -> #REF!
A6: ='RESUMEN TOTAL'!A9 -> ALTAMIRA | B6: ='RESUMEN TOTAL'!B9 -> ALT05 | C6: ='RESUMEN TOTAL'!D9 -> Av. Calchaqui y Bombero Galarza | D6: ='RESUMEN TOTAL'!E9 -> Domo | E6: ='RESUMEN TOTAL'!F9 -> PTO A FO | F6: ='RESUMEN TOTAL'!L9 -> 0 | G6: ='RESUMEN TOTAL'!M9 -> 0 | H6: ='RESUMEN TOTAL'!N9 -> 0 | I6: ='RESUMEN TOTAL'!O9 -> 0 | J6: ='RESUMEN TOTAL'!P9 -> 0 | K6: ='RESUMEN TOTAL'!Q9 -> 0 | L6: ='RESUMEN TOTAL'!R9 -> 0 | M6: ='RESUMEN TOTAL'!S9 -> 0 | ... AI6: ='RESUMEN TOTAL'!AO9 -> 0 | AJ6: ='RESUMEN TOTAL'!#REF! -> #REF!
A7: ='RESUMEN TOTAL'!A10 -> ALTAMIRA | B7: ='RESUMEN TOTAL'!B10 -> ALT 06 | C7: ='RESUMEN TOTAL'!D10 -> LOPE DE VEGA Y NECOCHEA | D7: ='RESUMEN TOTAL'!E10 -> Domo | E7: ='RESUMEN TOTAL'!F10 -> PTO A FO | F7: ='RESUMEN TOTAL'!L10 -> 0 | G7: ='RESUMEN TOTAL'!M10 -> 0 | H7: ='RESUMEN TOTAL'!N10 -> 0 | I7: ='RESUMEN TOTAL'!O10 -> 0 | J7: ='RESUMEN TOTAL'!P10 -> 0 | K7: ='RESUMEN TOTAL'!Q10 -> 0 | L7: ='RESUMEN TOTAL'!R10 -> 0 | M7: ='RESUMEN TOTAL'!S10 -> 0 | ... AI7: ='RESUMEN TOTAL'!AO10 -> 0 | AJ7: ='RESUMEN TOTAL'!#REF! -> #REF!
A8: ='RESUMEN TOTAL'!A11 -> ALTAMIRA | B8: ='RESUMEN TOTAL'!B11 -> ALT07 | C8: ='RESUMEN TOTAL'!D11 -> AV. CALCHAQUI Y AV. DEL TRABAJO | D8: ='RESUMEN TOTAL'!E11 -> DOMO | E8: ='RESUMEN TOTAL'!F11 -> PTO A FO | F8: ='RESUMEN TOTAL'!L11 -> 0 | G8: ='RESUMEN TOTAL'!M11 -> 0 | H8: ='RESUMEN TOTAL'!N11 -> 0 | I8: ='RESUMEN TOTAL'!O11 -> 0 | J8: ='RESUMEN TOTAL'!P11 -> 0 | K8: ='RESUMEN TOTAL'!Q11 -> 0 | L8: ='RESUMEN TOTAL'!R11 -> 0 | M8: ='RESUMEN TOTAL'!S11 -> 0 | ... AI8: ='RESUMEN TOTAL'!AO11 -> 0 | AJ8: ='RESUMEN TOTAL'!#REF! -> #REF!
A9: ='RESUMEN TOTAL'!A12 -> ALTAMIRA | B9: ='RESUMEN TOTAL'!B12 -> ALT 08 | C9: ='RESUMEN TOTAL'!D12 -> HUMAITA Y NECOCHEA | D9: ='RESUMEN TOTAL'!E12 -> DOMO | E9: ='RESUMEN TOTAL'!F12 -> Fibra Optica | F9: ='RESUMEN TOTAL'!L12 -> 0 | G9: ='RESUMEN TOTAL'!M12 -> 0 | H9: ='RESUMEN TOTAL'!N12 -> 0 | I9: ='RESUMEN TOTAL'!O12 -> 0 | J9: ='RESUMEN TOTAL'!P12 -> 0 | K9: ='RESUMEN TOTAL'!Q12 -> 0 | L9: ='RESUMEN TOTAL'!R12 -> 0 | M9: ='RESUMEN TOTAL'!S12 -> 0 | ... AI9: ='RESUMEN TOTAL'!AO12 -> 0 | AJ9: ='RESUMEN TOTAL'!#REF! -> #REF!
A10: ='RESUMEN TOTAL'!A13 -> ALTAMIRA | B10: ='RESUMEN TOTAL'!B13 -> ALT 09 | C10: ='RESUMEN TOTAL'!D13 -> NECOCHEA Y CURUPAITY | D10: ='RESUMEN TOTAL'!E13 -> DOMO | E10: ='RESUMEN TOTAL'!F13 -> Fibra Optica | F10: ='RESUMEN TOTAL'!L13 -> 0 | G10: ='RESUMEN TOTAL'!M13 -> 0 | H10: ='RESUMEN TOTAL'!N13 -> 0 | I10: ='RESUMEN TOTAL'!O13 -> 0 | J10: ='RESUMEN TOTAL'!P13 -> 0 | K10: ='RESUMEN TOTAL'!Q13 -> 0 | L10: ='RESUMEN TOTAL'!R13 -> 0 | M10: ='RESUMEN TOTAL'!S13 -> 0 | ... AI10: ='RESUMEN TOTAL'!AO13 -> 0 | AJ10: ='RESUMEN TOTAL'!#REF! -> #REF!
A11: ='RESUMEN TOTAL'!A14 -> ALTAMIRA | B11: ='RESUMEN TOTAL'!B14 -> ALT 10 | C11: ='RESUMEN TOTAL'!D14 -> Calchaqui y Francia | D11: ='RESUMEN TOTAL'!E14 -> Domo | E11: ='RESUMEN TOTAL'!F14 -> Radio | F11: ='RESUMEN TOTAL'!L14 -> 0 | G11: ='RESUMEN TOTAL'!M14 -> 0 | H11: ='RESUMEN TOTAL'!N14 -> 0 | I11: ='RESUMEN TOTAL'!O14 -> 0 | J11: ='RESUMEN TOTAL'!P14 -> 0 | K11: ='RESUMEN TOTAL'!Q14 -> 0 | L11: ='RESUMEN TOTAL'!R14 -> 0 | M11: ='RESUMEN TOTAL'!S14 -> 0 | ... AI11: ='RESUMEN TOTAL'!AO14 -> 0 | AJ11: ='RESUMEN TOTAL'!#REF! -> #REF!
A12: ='RESUMEN TOTAL'!A15 -> AGUSTIN RAMIREZ | B12: ='RESUMEN TOTAL'!B15 -> ARA 01 | C12: ='RESUMEN TOTAL'!D15 -> Malambo y Tranquera | D12: ='RESUMEN TOTAL'!E15 -> Domo | E12: ='RESUMEN TOTAL'!F15 -> Fibra Optica | F12: ='RESUMEN TOTAL'!L15 -> 0 | G12: ='RESUMEN TOTAL'!M15 -> 0 | H12: ='RESUMEN TOTAL'!N15 -> 0 | I12: ='RESUMEN TOTAL'!O15 -> 0 | J12: ='RESUMEN TOTAL'!P15 -> 0 | K12: ='RESUMEN TOTAL'!Q15 -> 0 | L12: ='RESUMEN TOTAL'!R15 -> 0 | M12: ='RESUMEN TOTAL'!S15 -> 0 | ... R12: ='RESUMEN TOTAL'!X15 -> 0 | S12: ='RESUMEN TOTAL'!Y21 -> 0 | T12: ='RESUMEN TOTAL'!Z15 -> 0 | U12: ='RESUMEN TOTAL'!AA15 -> 0 | V12: ='RESUMEN TOTAL'!AB15 -> 0 | W12: ='RESUMEN TOTAL'!AC15 -> 0 | X12: ='RESUMEN TOTAL'!AD15 -> 0 | Y12: ='RESUMEN TOTAL'!AE15 -> 0 | Z12: ='RESUMEN TOTAL'!AF15 -> 0 | AA12: ='RESUMEN TOTAL'!AG15 -> 0 | ... AI12: ='RESUMEN TOTAL'!AO15 -> 0 | AJ12: ='RESUMEN TOTAL'!#REF! -> #REF!
A13: ='RESUMEN TOTAL'!A16 -> BELGRANO | B13: ='RESUMEN TOTAL'!B16 -> BEL 01 | C13: ='RESUMEN TOTAL'!D16 -> San Martin y Dardo Rocha | D13: ='RESUMEN TOTAL'!E16 -> DOMO | E13: ='RESUMEN TOTAL'!F16 -> Fibra Optica | F13: ='RESUMEN TOTAL'!L16 -> 0 | G13: ='RESUMEN TOTAL'!M16 -> 0 | H13: ='RESUMEN TOTAL'!N16 -> 0 | I13: ='RESUMEN TOTAL'!O16 -> 0 | J13: ='RESUMEN TOTAL'!P16 -> 0 | K13: ='RESUMEN TOTAL'!Q16 -> 0 | L13: ='RESUMEN TOTAL'!R16 -> 0 | M13: ='RESUMEN TOTAL'!S16 -> 0 | ... AI13: ='RESUMEN TOTAL'!AO16 -> 0 | AJ13: ='RESUMEN TOTAL'!#REF! -> #REF!
A14: ='RESUMEN TOTAL'!A17 -> BELGRANO | B14: ='RESUMEN TOTAL'!B17 -> BEL 02 | C14: ='RESUMEN TOTAL'!D17 -> Guardia vieja y Fronteriz | D14: ='RESUMEN TOTAL'!E17 -> DOMO | E14: ='RESUMEN TOTAL'!F17 -> Fibra Optica | F14: ='RESUMEN TOTAL'!L17 -> 0 | G14: ='RESUMEN TOTAL'!M17 -> 0 | H14: ='RESUMEN TOTAL'!N17 -> 0 | I14: ='RESUMEN TOTAL'!O17 -> 0 | J14: ='RESUMEN TOTAL'!P17 -> 0 | K14: ='RESUMEN TOTAL'!Q17 -> 0 | L14: ='RESUMEN TOTAL'!R17 -> 0 | M14: ='RESUMEN TOTAL'!S17 -> 0 | ... AI14: ='RESUMEN TOTAL'!AO17 -> 0 | AJ14: ='RESUMEN TOTAL'!#REF! -> #REF!
A15: ='RESUMEN TOTAL'!A18 -> BOSQUES CENTRO | B15: ='RESUMEN TOTAL'!B18 -> BOSQC 01 | C15: ='RESUMEN TOTAL'!D18 -> LUIS AGOTE E/DANUNCIO Y CAMPOAMOR | D15: ='RESUMEN TOTAL'!E18 -> Fija | E15: ='RESUMEN TOTAL'!F18 -> Radio | F15: ='RESUMEN TOTAL'!L18 -> 0 | G15: ='RESUMEN TOTAL'!M18 -> 0 | H15: ='RESUMEN TOTAL'!N18 -> 0 | I15: ='RESUMEN TOTAL'!O18 -> 0 | J15: ='RESUMEN TOTAL'!P18 -> 0 | K15: ='RESUMEN TOTAL'!Q18 -> 0 | L15: ='RESUMEN TOTAL'!R18 -> 0 | M15: ='RESUMEN TOTAL'!S18 -> 0 | ... AI15: ='RESUMEN TOTAL'!AO18 -> 0 | AJ15: ='RESUMEN TOTAL'!#REF! -> #REF!
A16: ='RESUMEN TOTAL'!A19 -> BOSQUES CENTRO | B16: ='RESUMEN TOTAL'!B19 -> BOSQC 02 | C16: ='RESUMEN TOTAL'!D19 -> LUIS AGOTE E/DANUNCIO Y CAMPOAMOR | D16: ='RESUMEN TOTAL'!E19 -> Fija | E16: ='RESUMEN TOTAL'!F19 -> Radio | F16: ='RESUMEN TOTAL'!L19 -> 0 | G16: ='RESUMEN TOTAL'!M19 -> 0 | H16: ='RESUMEN TOTAL'!N19 -> 0 | I16: ='RESUMEN TOTAL'!O19 -> 0 | J16: ='RESUMEN TOTAL'!P19 -> 0 | K16: ='RESUMEN TOTAL'!Q19 -> 0 | L16: ='RESUMEN TOTAL'!R19 -> 0 | M16: ='RESUMEN TOTAL'!S19 -> 0 | ... AI16: ='RESUMEN TOTAL'!AO19 -> 0 | AJ16: ='RESUMEN TOTAL'!#REF! -> #REF!
A17: ='RESUMEN TOTAL'!A20 -> BOSQUES CENTRO | B17: ='RESUMEN TOTAL'!B20 -> BOSQC 03 | C17: ='RESUMEN TOTAL'!D20 -> BENAVENTE Y LUIS AGOTE | D17: ='RESUMEN TOTAL'!E20 -> Fija | E17: ='RESUMEN TOTAL'!F20 -> Radio | F17: ='RESUMEN TOTAL'!L20 -> 0 | G17: ='RESUMEN TOTAL'!M20 -> 0 | H17: ='RESUMEN TOTAL'!N20 -> 0 | I17: ='RESUMEN TOTAL'!O20 -> 0 | J17: ='RESUMEN TOTAL'!P20 -> 0 | K17: ='RESUMEN TOTAL'!Q20 -> 0 | L17: ='RESUMEN TOTAL'!R20 -> 0 | M17: ='RESUMEN TOTAL'!S20 -> 0 | ... AI17: ='RESUMEN TOTAL'!AO20 -> 0 | AJ17: ='RESUMEN TOTAL'!#REF! -> #REF!
A18: ='RESUMEN TOTAL'!A21 -> BOSQUES CENTRO | B18: ='RESUMEN TOTAL'!B21 -> BOSQC 04 | C18: ='RESUMEN TOTAL'!D21 -> BENAVENTE Y LUIS AGOTE | D18: ='RESUMEN TOTAL'!E21 -> Fija | E18: ='RESUMEN TOTAL'!F21 -> Radio | F18: ='RESUMEN TOTAL'!L21 -> 0 | G18: ='RESUMEN TOTAL'!M21 -> 0 | H18: ='RESUMEN TOTAL'!N21 -> 0 | I18: ='RESUMEN TOTAL'!O21 -> 0 | J18: ='RESUMEN TOTAL'!P21 -> 0 | K18: ='RESUMEN TOTAL'!Q21 -> 0 | L18: ='RESUMEN TOTAL'!R21 -> 0 | M18: ='RESUMEN TOTAL'!S21 -> 0 | ... AI18: ='RESUMEN TOTAL'!AO21 -> 0 | AJ18: ='RESUMEN TOTAL'!#REF! -> #REF!
A19: ='RESUMEN TOTAL'!A22 -> BOSQUES CENTRO | B19: ='RESUMEN TOTAL'!B22 -> BOSQC 05 | C19: ='RESUMEN TOTAL'!D22 -> LUIS AGOTE Y RUTA 36 | D19: ='RESUMEN TOTAL'!E22 -> Fija | E19: ='RESUMEN TOTAL'!F22 -> Radio | F19: ='RESUMEN TOTAL'!L22 -> 0 | G19: ='RESUMEN TOTAL'!M22 -> 0 | H19: ='RESUMEN TOTAL'!N22 -> 0 | I19: ='RESUMEN TOTAL'!O22 -> 0 | J19: ='RESUMEN TOTAL'!P22 -> 0 | K19: ='RESUMEN TOTAL'!Q22 -> 0 | L19: ='RESUMEN TOTAL'!R22 -> 0 | M19: ='RESUMEN TOTAL'!S22 -> 0 | ... AI19: ='RESUMEN TOTAL'!AO22 -> 0 | AJ19: ='RESUMEN TOTAL'!#REF! -> #REF!
A20: ='RESUMEN TOTAL'!A23 -> BOSQUES CENTRO | B20: ='RESUMEN TOTAL'!B23 -> BOSQC 06 | C20: ='RESUMEN TOTAL'!D23 -> LUIS AGOTE Y RUTA 36 | D20: ='RESUMEN TOTAL'!E23 -> Fija | E20: ='RESUMEN TOTAL'!F23 -> Radio | F20: ='RESUMEN TOTAL'!L23 -> 0 | G20: ='RESUMEN TOTAL'!M23 -> 0 | H20: ='RESUMEN TOTAL'!N23 -> 0 | I20: ='RESUMEN TOTAL'!O23 -> 0 | J20: ='RESUMEN TOTAL'!P23 -> 0 | K20: ='RESUMEN TOTAL'!Q23 -> 0 | L20: ='RESUMEN TOTAL'!R23 -> 0 | M20: ='RESUMEN TOTAL'!S23 -> 0 | ... AI20: ='RESUMEN TOTAL'!AO23 -> 0 | AJ20: ='RESUMEN TOTAL'!#REF! -> #REF!
A21: ='RESUMEN TOTAL'!A24 -> CENTRO | B21: ='RESUMEN TOTAL'!B24 -> CEN01 | C21: ='RESUMEN TOTAL'!D24 -> San Martin y 9 de Julio | D21: ='RESUMEN TOTAL'!E24 -> Fija | E21: ='RESUMEN TOTAL'!F24 -> Fibra Optica | F21: ='RESUMEN TOTAL'!L24 -> 0 | G21: ='RESUMEN TOTAL'!M24 -> 0 | H21: ='RESUMEN TOTAL'!N24 -> 0 | I21: ='RESUMEN TOTAL'!O24 -> 0 | J21: ='RESUMEN TOTAL'!P24 -> 0 | K21: ='RESUMEN TOTAL'!Q24 -> 0 | L21: ='RESUMEN TOTAL'!R24 -> 0 | M21: ='RESUMEN TOTAL'!S24 -> 0 | ... AI21: ='RESUMEN TOTAL'!AO24 -> 0 | AJ21: ='RESUMEN TOTAL'!#REF! -> #REF!
A22: ='RESUMEN TOTAL'!A25 -> CENTRO | B22: ='RESUMEN TOTAL'!B25 -> CEN02 | C22: ='RESUMEN TOTAL'!D25 -> San Martin y Almafuerte | D22: ='RESUMEN TOTAL'!E25 -> Fija | E22: ='RESUMEN TOTAL'!F25 -> Fibra Optica | F22: ='RESUMEN TOTAL'!L25 -> 0 | G22: ='RESUMEN TOTAL'!M25 -> 0 | H22: ='RESUMEN TOTAL'!N25 -> 0 | I22: ='RESUMEN TOTAL'!O25 -> 0 | J22: ='RESUMEN TOTAL'!P25 -> 0 | K22: ='RESUMEN TOTAL'!Q25 -> 0 | L22: ='RESUMEN TOTAL'!R25 -> 0 | M22: ='RESUMEN TOTAL'!S25 -> 0 | ... AI22: ='RESUMEN TOTAL'!AO25 -> 0 | AJ22: ='RESUMEN TOTAL'!#REF! -> #REF!
A23: ='RESUMEN TOTAL'!A26 -> CENTRO | B23: ='RESUMEN TOTAL'!B26 -> CEN03 | C23: ='RESUMEN TOTAL'!D26 -> San Martin y Sallares | D23: ='RESUMEN TOTAL'!E26 -> Domo | E23: ='RESUMEN TOTAL'!F26 -> Fibra Optica | F23: ='RESUMEN TOTAL'!L26 -> 0 | G23: ='RESUMEN TOTAL'!M26 -> 0 | H23: ='RESUMEN TOTAL'!N26 -> 0 | I23: ='RESUMEN TOTAL'!O26 -> 0 | J23: ='RESUMEN TOTAL'!P26 -> 0 | K23: ='RESUMEN TOTAL'!Q26 -> 0 | L23: ='RESUMEN TOTAL'!R26 -> 0 | M23: ='RESUMEN TOTAL'!S26 -> 0 | ... AI23: ='RESUMEN TOTAL'!AO26 -> 0 | AJ23: ='RESUMEN TOTAL'!#REF! -> #REF!
A24: ='RESUMEN TOTAL'!A27 -> CENTRO | B24: ='RESUMEN TOTAL'!B27 -> CEN04 | C24: ='RESUMEN TOTAL'!D27 -> San Martin y Contreras | D24: ='RESUMEN TOTAL'!E27 -> Domo | E24: ='RESUMEN TOTAL'!F27 -> Fibra Optica | F24: ='RESUMEN TOTAL'!L27 -> 0 | G24: ='RESUMEN TOTAL'!M27 -> 0 | H24: ='RESUMEN TOTAL'!N27 -> 0 | I24: ='RESUMEN TOTAL'!O27 -> 0 | J24: ='RESUMEN TOTAL'!P27 -> 0 | K24: ='RESUMEN TOTAL'!Q27 -> 0 | L24: ='RESUMEN TOTAL'!R27 -> 0 | M24: ='RESUMEN TOTAL'!S27 -> 0 | ... AI24: ='RESUMEN TOTAL'!AO27 -> 0 | AJ24: ='RESUMEN TOTAL'!#REF! -> #REF!
... A452: ='RESUMEN TOTAL'!A455 -> 0 | B452: ='RESUMEN TOTAL'!B455 -> 0 | C452: ='RESUMEN TOTAL'!D455 -> 0 | D452: ='RESUMEN TOTAL'!E455 -> 0 | E452: ='RESUMEN TOTAL'!F455 -> 0 | F452: ='RESUMEN TOTAL'!L455 -> 0 | G452: ='RESUMEN TOTAL'!M455 -> 0 | H452: ='RESUMEN TOTAL'!N455 -> 0 | I452: ='RESUMEN TOTAL'!O455 -> 0 | J452: ='RESUMEN TOTAL'!P455 -> 0 | K452: ='RESUMEN TOTAL'!Q455 -> 0 | L452: ='RESUMEN TOTAL'!R455 -> 0 | M452: ='RESUMEN TOTAL'!S455 -> 0 | ... AI452: ='RESUMEN TOTAL'!AO455 -> 0 | AJ452: ='RESUMEN TOTAL'!#REF! -> #REF!
A453: ='RESUMEN TOTAL'!A456 -> 0 | B453: ='RESUMEN TOTAL'!B456 -> 0 | C453: ='RESUMEN TOTAL'!C456 -> 0 | D453: ='RESUMEN TOTAL'!E456 -> 0 | E453: ='RESUMEN TOTAL'!F456 -> 0 | F453: ='RESUMEN TOTAL'!L456 -> 0 | G453: ='RESUMEN TOTAL'!M456 -> 0 | H453: ='RESUMEN TOTAL'!N456 -> 0 | I453: ='RESUMEN TOTAL'!O456 -> 0 | J453: ='RESUMEN TOTAL'!P456 -> 0 | K453: ='RESUMEN TOTAL'!Q456 -> 0 | L453: ='RESUMEN TOTAL'!R456 -> 0 | M453: ='RESUMEN TOTAL'!S456 -> 0 | ... AI453: ='RESUMEN TOTAL'!AO456 -> 0 | AJ453: ='RESUMEN TOTAL'!#REF! -> #REF!
A454: ='RESUMEN TOTAL'!A457 -> 0 | B454: ='RESUMEN TOTAL'!B457 -> 0 | C454: ='RESUMEN TOTAL'!D457 -> 0 | D454: ='RESUMEN TOTAL'!E457 -> 0 | E454: ='RESUMEN TOTAL'!F457 -> 0 | F454: ='RESUMEN TOTAL'!L457 -> 0 | G454: ='RESUMEN TOTAL'!M457 -> 0 | H454: ='RESUMEN TOTAL'!N457 -> 0 | I454: ='RESUMEN TOTAL'!O457 -> 0 | J454: ='RESUMEN TOTAL'!P457 -> 0 | K454: ='RESUMEN TOTAL'!Q457 -> 0 | L454: ='RESUMEN TOTAL'!R457 -> 0 | M454: ='RESUMEN TOTAL'!S457 -> 0 | ... AI454: ='RESUMEN TOTAL'!AO457 -> 0 | AJ454: ='RESUMEN TOTAL'!#REF! -> #REF!
A455: ='RESUMEN TOTAL'!A458 -> 0 | B455: ='RESUMEN TOTAL'!B458 -> 0 | C455: ='RESUMEN TOTAL'!D458 -> 0 | D455: ='RESUMEN TOTAL'!E458 -> 0 | E455: ='RESUMEN TOTAL'!F458 -> 0 | F455: ='RESUMEN TOTAL'!L458 -> 0 | G455: ='RESUMEN TOTAL'!M458 -> 0 | H455: ='RESUMEN TOTAL'!N458 -> 0 | I455: ='RESUMEN TOTAL'!O458 -> 0 | J455: ='RESUMEN TOTAL'!P458 -> 0 | K455: ='RESUMEN TOTAL'!Q458 -> 0 | L455: ='RESUMEN TOTAL'!R458 -> 0 | M455: ='RESUMEN TOTAL'!S458 -> 0 | ... AI455: ='RESUMEN TOTAL'!AO458 -> 0 | AJ455: ='RESUMEN TOTAL'!#REF! -> #REF!
A456: ='RESUMEN TOTAL'!A459 -> 0 | B456: ='RESUMEN TOTAL'!B459 -> 0 | C456: ='RESUMEN TOTAL'!D459 -> 0 | D456: ='RESUMEN TOTAL'!E459 -> 0 | E456: ='RESUMEN TOTAL'!F459 -> 0 | F456: ='RESUMEN TOTAL'!L459 -> 0 | G456: ='RESUMEN TOTAL'!M459 -> 0 | H456: ='RESUMEN TOTAL'!N459 -> 0 | I456: ='RESUMEN TOTAL'!O459 -> 0 | J456: ='RESUMEN TOTAL'!P459 -> 0 | K456: ='RESUMEN TOTAL'!Q459 -> 0 | L456: ='RESUMEN TOTAL'!R459 -> 0 | M456: ='RESUMEN TOTAL'!S459 -> 0 | ... AI456: ='RESUMEN TOTAL'!AO459 -> 0 | AJ456: ='RESUMEN TOTAL'!#REF! -> #REF!
A457: ='RESUMEN TOTAL'!A460 -> 0 | B457: ='RESUMEN TOTAL'!B460 -> 0 | C457: ='RESUMEN TOTAL'!D460 -> 0 | D457: ='RESUMEN TOTAL'!E460 -> 0 | E457: ='RESUMEN TOTAL'!F460 -> 0 | F457: ='RESUMEN TOTAL'!L460 -> 0 | G457: ='RESUMEN TOTAL'!M460 -> 0 | H457: ='RESUMEN TOTAL'!N460 -> 0 | I457: ='RESUMEN TOTAL'!O460 -> 0 | J457: ='RESUMEN TOTAL'!P460 -> 0 | K457: ='RESUMEN TOTAL'!Q460 -> 0 | L457: ='RESUMEN TOTAL'!R460 -> 0 | M457: ='RESUMEN TOTAL'!S460 -> 0 | ... AI457: ='RESUMEN TOTAL'!AO460 -> 0 | AJ457: ='RESUMEN TOTAL'!#REF! -> #REF!
A458: ='RESUMEN TOTAL'!A461 -> 0 | B458: ='RESUMEN TOTAL'!B461 -> 0 | C458: ='RESUMEN TOTAL'!D461 -> 0 | D458: ='RESUMEN TOTAL'!E461 -> 0 | E458: ='RESUMEN TOTAL'!F461 -> 0 | F458: ='RESUMEN TOTAL'!L461 -> 0 | G458: ='RESUMEN TOTAL'!M461 -> 0 | H458: ='RESUMEN TOTAL'!N461 -> 0 | I458: ='RESUMEN TOTAL'!O461 -> 0 | J458: ='RESUMEN TOTAL'!P461 -> 0 | K458: ='RESUMEN TOTAL'!Q461 -> 0 | L458: ='RESUMEN TOTAL'!R461 -> 0 | M458: ='RESUMEN TOTAL'!S461 -> 0 | ... AI458: ='RESUMEN TOTAL'!AO461 -> 0 | AJ458: ='RESUMEN TOTAL'!#REF! -> #REF!
A459: ='RESUMEN TOTAL'!A462 -> 0 | B459: ='RESUMEN TOTAL'!B462 -> 0 | C459: ='RESUMEN TOTAL'!D462 -> 0 | D459: ='RESUMEN TOTAL'!E462 -> 0 | E459: ='RESUMEN TOTAL'!F462 -> 0 | F459: ='RESUMEN TOTAL'!L462 -> 0 | G459: ='RESUMEN TOTAL'!M462 -> 0 | H459: ='RESUMEN TOTAL'!N462 -> 0 | I459: ='RESUMEN TOTAL'!O462 -> 0 | J459: ='RESUMEN TOTAL'!P462 -> 0 | K459: ='RESUMEN TOTAL'!Q462 -> 0 | L459: ='RESUMEN TOTAL'!R462 -> 0 | M459: ='RESUMEN TOTAL'!S462 -> 0 | ... AI459: ='RESUMEN TOTAL'!AO462 -> 0 | AJ459: ='RESUMEN TOTAL'!#REF! -> #REF!
A460: ='RESUMEN TOTAL'!A463 -> 0 | B460: ='RESUMEN TOTAL'!B463 -> 0 | C460: ='RESUMEN TOTAL'!D463 -> 0 | D460: ='RESUMEN TOTAL'!E463 -> 0 | E460: ='RESUMEN TOTAL'!F463 -> 0 | F460: ='RESUMEN TOTAL'!L463 -> 0 | G460: ='RESUMEN TOTAL'!M463 -> 0 | H460: ='RESUMEN TOTAL'!N463 -> 0 | I460: ='RESUMEN TOTAL'!O463 -> 0 | J460: ='RESUMEN TOTAL'!P463 -> 0 | K460: ='RESUMEN TOTAL'!Q463 -> 0 | L460: ='RESUMEN TOTAL'!R463 -> 0 | M460: ='RESUMEN TOTAL'!S463 -> 0 | ... AI460: ='RESUMEN TOTAL'!AO463 -> 0 | AJ460: ='RESUMEN TOTAL'!#REF! -> #REF!
A461: ='RESUMEN TOTAL'!A464 -> 0 | B461: ='RESUMEN TOTAL'!B464 -> 0 | C461: ='RESUMEN TOTAL'!D464 -> 0 | D461: ='RESUMEN TOTAL'!E464 -> 0 | E461: ='RESUMEN TOTAL'!F464 -> 0 | F461: ='RESUMEN TOTAL'!L464 -> 0 | G461: ='RESUMEN TOTAL'!M464 -> 0 | H461: ='RESUMEN TOTAL'!N464 -> 0 | I461: ='RESUMEN TOTAL'!O464 -> 0 | J461: ='RESUMEN TOTAL'!P464 -> 0 | K461: ='RESUMEN TOTAL'!Q464 -> 0 | L461: ='RESUMEN TOTAL'!R464 -> 0 | M461: ='RESUMEN TOTAL'!S464 -> 0 | ... AI461: ='RESUMEN TOTAL'!AO464 -> 0 | AJ461: ='RESUMEN TOTAL'!#REF! -> #REF!
A462: ='RESUMEN TOTAL'!A465 -> 0 | B462: ='RESUMEN TOTAL'!B465 -> 0 | C462: ='RESUMEN TOTAL'!D465 -> 0 | D462: ='RESUMEN TOTAL'!E465 -> 0 | E462: ='RESUMEN TOTAL'!F465 -> 0 | F462: ='RESUMEN TOTAL'!L465 -> 0 | G462: ='RESUMEN TOTAL'!M465 -> 0 | H462: ='RESUMEN TOTAL'!N465 -> 0 | I462: ='RESUMEN TOTAL'!O465 -> 0 | J462: ='RESUMEN TOTAL'!P465 -> 0 | K462: ='RESUMEN TOTAL'!Q465 -> 0 | L462: ='RESUMEN TOTAL'!R465 -> 0 | M462: ='RESUMEN TOTAL'!S465 -> 0 | ... AI462: ='RESUMEN TOTAL'!AO465 -> 0 | AJ462: ='RESUMEN TOTAL'!#REF! -> #REF!
A463: ='RESUMEN TOTAL'!A466 -> 0 | B463: ='RESUMEN TOTAL'!B466 -> 0 | C463: ='RESUMEN TOTAL'!D466 -> 0 | D463: ='RESUMEN TOTAL'!E466 -> 0 | E463: ='RESUMEN TOTAL'!F466 -> 0 | F463: ='RESUMEN TOTAL'!L466 -> 0 | G463: ='RESUMEN TOTAL'!M466 -> 0 | H463: ='RESUMEN TOTAL'!N466 -> 0 | I463: ='RESUMEN TOTAL'!O466 -> 0 | J463: ='RESUMEN TOTAL'!P466 -> 0 | K463: ='RESUMEN TOTAL'!Q466 -> 0 | L463: ='RESUMEN TOTAL'!R466 -> 0 | M463: ='RESUMEN TOTAL'!S466 -> 0 | ... AI463: ='RESUMEN TOTAL'!AO466 -> 0 | AJ463: ='RESUMEN TOTAL'!#REF! -> #REF!
A464: ='RESUMEN TOTAL'!A467 -> 0 | B464: ='RESUMEN TOTAL'!B467 -> 0 | C464: ='RESUMEN TOTAL'!D467 -> 0 | D464: ='RESUMEN TOTAL'!E467 -> 0 | E464: ='RESUMEN TOTAL'!F467 -> 0 | F464: ='RESUMEN TOTAL'!L467 -> 0 | G464: ='RESUMEN TOTAL'!M467 -> 0 | H464: ='RESUMEN TOTAL'!N467 -> 0 | I464: ='RESUMEN TOTAL'!O467 -> 0 | J464: ='RESUMEN TOTAL'!P467 -> 0 | K464: ='RESUMEN TOTAL'!Q467 -> 0 | L464: ='RESUMEN TOTAL'!R467 -> 0 | M464: ='RESUMEN TOTAL'!S467 -> 0 | ... AI464: ='RESUMEN TOTAL'!AO467 -> 0 | AJ464: ='RESUMEN TOTAL'!#REF! -> #REF!
A465: ='RESUMEN TOTAL'!A468 -> 0 | B465: ='RESUMEN TOTAL'!B468 -> 0 | C465: ='RESUMEN TOTAL'!D468 -> 0 | D465: ='RESUMEN TOTAL'!E468 -> 0 | E465: ='RESUMEN TOTAL'!F468 -> 0 | F465: ='RESUMEN TOTAL'!L468 -> 0 | G465: ='RESUMEN TOTAL'!M468 -> 0 | H465: ='RESUMEN TOTAL'!N468 -> 0 | I465: ='RESUMEN TOTAL'!O468 -> 0 | J465: ='RESUMEN TOTAL'!P468 -> 0 | K465: ='RESUMEN TOTAL'!Q468 -> 0 | L465: ='RESUMEN TOTAL'!R468 -> 0 | M465: ='RESUMEN TOTAL'!S468 -> 0 | ... AI465: ='RESUMEN TOTAL'!AO468 -> 0 | AJ465: ='RESUMEN TOTAL'!#REF! -> #REF!
... A638: ='RESUMEN TOTAL'!A641 -> 0 | B638: ='RESUMEN TOTAL'!B641 -> 0 | C638: ='RESUMEN TOTAL'!D641 -> 0 | D638: ='RESUMEN TOTAL'!E641 -> 0 | E638: ='RESUMEN TOTAL'!F641 -> 0 | F638: ='RESUMEN TOTAL'!L641 -> 0 | G638: ='RESUMEN TOTAL'!M641 -> 0 | H638: ='RESUMEN TOTAL'!N641 -> 0 | I638: ='RESUMEN TOTAL'!O641 -> 0 | J638: ='RESUMEN TOTAL'!P641 -> 0 | K638: ='RESUMEN TOTAL'!Q641 -> 0 | L638: ='RESUMEN TOTAL'!R641 -> 0 | M638: ='RESUMEN TOTAL'!S641 -> 0 | ... AI638: ='RESUMEN TOTAL'!AO641 -> 0 | AJ638: ='RESUMEN TOTAL'!#REF! -> #REF!

Sheet APAGADOS
E1: APAGADOS | F1: =COUNTIF(F3:F403, "APAGADO") -> 0 | G1: =COUNTIF(G3:G403, "APAGADO") -> 0 | H1: =COUNTIF(H3:H503, "APAGADO") -> 18 | I1: =COUNTIF(I3:I403, "APAGADO") -> 0 | J1: =COUNTIF(J3:J403, "APAGADO") -> 0 | K1: =COUNTIF(K3:K403, "APAGADO") -> 0 | L1: =COUNTIF(L3:L403, "APAGADO") -> 0 | M1: =COUNTIF(M3:M403, "APAGADO") -> 0 | N1: =COUNTIF(N3:N403, "APAGADO") -> 0 | O1: =COUNTIF(O3:O403, "APAGADO") -> 0 | P1: =COUNTIF(P3:P403, "APAGADO") -> 0 | ... AD1: =COUNTIF(AD3:AD403, "APAGADO") -> 0 | AE1: =COUNTIF(AE3:AE503, "APAGADO") -> 0 | AF1: =COUNTIF(AF3:AF403, "APAGADO") -> 0 | AG1: =COUNTIF(AG3:AG403, "APAGADO") -> 0 | AH1: =COUNTIF(AH3:AH403, "APAGADO") -> 0 | AI1: =COUNTIF(AI3:AI403, "APAGADO") -> 0 | AJ1: =COUNTIF(AJ3:AJ403, "APAGADO") -> 0
A2: =ESTADISTICA!A1 -> Barrio | B2: =ESTADISTICA!B1 -> [Denominacion] | C2: =ESTADISTICA!C1 -> [Ubicacion] | D2: =ESTADISTICA!D1 -> [Tipo de Camara] | E2: =ESTADISTICA!E1 -> [Tipo de Conexion] | F2: =ESTADISTICA!F1 -> 45108 | G2: =ESTADISTICA!G1 -> 45109 | H2: =ESTADISTICA!H1 -> 45110 | ... AJ2: =ESTADISTICA!AJ1 -> #REF!
A3: =ESTADISTICA!A2 -> ALTAMIRA | B3: =ESTADISTICA!B2 -> ALT01 | C3: =ESTADISTICA!C2 -> Calchaqui y Sgto. Cabral | D3: =ESTADISTICA!D2 -> Domo | E3: =ESTADISTICA!E2 -> Fibra Optica | F3: =ESTADISTICA!F2 -> 0 | G3: =ESTADISTICA!G2 -> 0 | H3: =ESTADISTICA!H2 -> 0 | ... AJ3: =ESTADISTICA!AJ2 -> #REF!
A4: =ESTADISTICA!A3 -> ALTAMIRA | B4: =ESTADISTICA!B3 -> ALT02 | C4: =ESTADISTICA!C3 -> Calchaqui y Lope de Vega | D4: =ESTADISTICA!D3 -> Domo | E4: =ESTADISTICA!E3 -> PTO A FO | F4: =ESTADISTICA!F3 -> 0 | G4: =ESTADISTICA!G3 -> 0 | H4: =ESTADISTICA!H3 -> 0 | ... AJ4: =ESTADISTICA!AJ3 -> #REF!
A5: =ESTADISTICA!A4 -> ALTAMIRA | B5: =ESTADISTICA!B4 -> ALT 03 | C5: =ESTADISTICA!C4 -> Bombero Galarza y Necochea | D5: =ESTADISTICA!D4 -> Domo | E5: =ESTADISTICA!E4 -> Fibra Optica | F5: =ESTADISTICA!F4 -> 0 | G5: =ESTADISTICA!G4 -> 0 | H5: =ESTADISTICA!H4 -> 0 | ... AJ5: =ESTADISTICA!AJ4 -> #REF!
A6: =ESTADISTICA!A5 -> ALTAMIRA | B6: =ESTADISTICA!B5 -> ALT 04 | C6: =ESTADISTICA!C5 -> Francia y Necochea | D6: =ESTADISTICA!D5 -> Domo | E6: =ESTADISTICA!E5 -> Fibra Optica | F6: =ESTADISTICA!F5 -> 0 | G6: =ESTADISTICA!G5 -> 0 | H6: =ESTADISTICA!H5 -> 0 | ... AJ6: =ESTADISTICA!AJ5 -> #REF!
A7: =ESTADISTICA!A6 -> ALTAMIRA | B7: =ESTADISTICA!B6 -> ALT05 | C7: =ESTADISTICA!C6 -> Av. Calchaqui y Bombero Galarza | D7: =ESTADISTICA!D6 -> Domo | E7: =ESTADISTICA!E6 -> PTO A FO | F7: =ESTADISTICA!F6 -> 0 | G7: =ESTADISTICA!G6 -> 0 | H7: =ESTADISTICA!H6 -> 0 | ... AJ7: =ESTADISTICA!AJ6 -> #REF!
A8: =ESTADISTICA!A7 -> ALTAMIRA | B8: =ESTADISTICA!B7 -> ALT 06 | C8: =ESTADISTICA!C7 -> LOPE DE VEGA Y NECOCHEA | D8: =ESTADISTICA!D7 -> Domo | E8: =ESTADISTICA!E7 -> PTO A FO | F8: =ESTADISTICA!F7 -> 0 | G8: =ESTADISTICA!G7 -> 0 | H8: =ESTADISTICA!H7 -> 0 | ... AJ8: =ESTADISTICA!AJ7 -> #REF!
A9: =ESTADISTICA!A8 -> ALTAMIRA | B9: =ESTADISTICA!B8 -> ALT07 | C9: =ESTADISTICA!C8 -> AV. CALCHAQUI Y AV. DEL TRABAJO | D9: =ESTADISTICA!D8 -> DOMO | E9: =ESTADISTICA!E8 -> PTO A FO | F9: =ESTADISTICA!F8 -> 0 | G9: =ESTADISTICA!G8 -> 0 | H9: =ESTADISTICA!H8 -> 0 | ... AJ9: =ESTADISTICA!AJ8 -> #REF!
A10: =ESTADISTICA!A9 -> ALTAMIRA | B10: =ESTADISTICA!B9 -> ALT 08 | C10: =ESTADISTICA!C9 -> HUMAITA Y NECOCHEA | D10: =ESTADISTICA!D9 -> DOMO | E10: =ESTADISTICA!E9 -> Fibra Optica | F10: =ESTADISTICA!F9 -> 0 | G10: =ESTADISTICA!G9 -> 0 | H10: =ESTADISTICA!H9 -> 0 | ... AJ10: =ESTADISTICA!AJ9 -> #REF!
A11: =ESTADISTICA!A10 -> ALTAMIRA | B11: =ESTADISTICA!B10 -> ALT 09 | C11: =ESTADISTICA!C10 -> NECOCHEA Y CURUPAITY | D11: =ESTADISTICA!D10 -> DOMO | E11: =ESTADISTICA!E10 -> Fibra Optica | F11: =ESTADISTICA!F10 -> 0 | G11: =ESTADISTICA!G10 -> 0 | H11: =ESTADISTICA!H10 -> 0 | ... AJ11: =ESTADISTICA!AJ10 -> #REF!
A12: =ESTADISTICA!A11 -> ALTAMIRA | B12: =ESTADISTICA!B11 -> ALT 10 | C12: =ESTADISTICA!C11 -> Calchaqui y Francia | D12: =ESTADISTICA!D11 -> Domo | E12: =ESTADISTICA!E11 -> Radio | F12: =ESTADISTICA!F11 -> 0 | G12: =ESTADISTICA!G11 -> 0 | H12: =ESTADISTICA!H11 -> 0 | ... AJ12: =ESTADISTICA!AJ11 -> #REF!
A13: =ESTADISTICA!A12 -> AGUSTIN RAMIREZ | B13: =ESTADISTICA!B12 -> ARA 01 | C13: =ESTADISTICA!C12 -> Malambo y Tranquera | D13: =ESTADISTICA!D12 -> Domo | E13: =ESTADISTICA!E12 -> Fibra Optica | F13: =ESTADISTICA!F12 -> 0 | G13: =ESTADISTICA!G12 -> 0 | H13: =ESTADISTICA!H12 -> 0 | ... AJ13: =ESTADISTICA!AJ12 -> #REF!
... A207: =ESTADISTICA!A206 -> MARTIN FIERRO | B207: =ESTADISTICA!B206 -> MFI 07 | C207: =ESTADISTICA!C206 -> Sargento Cabral y Carlos Gardel | D207: =ESTADISTICA!D206 -> Domo | E207: =ESTADISTICA!E206 -> PTO A FO | F207: =ESTADISTICA!F206 -> 0 | G207: =ESTADISTICA!G206 -> 0 | H207: =ESTADISTICA!H206 -> 0 | ... AJ207: =ESTADISTICA!AJ206 -> #REF!
A208: =ESTADISTICA!A208 -> GOBERNADOR MONTEVERDE | B208: =ESTADISTICA!B208 -> MON01 | C208: =ESTADISTICA!C208 -> San Martin y Patricias Argentinas | D208: =ESTADISTICA!D208 -> Fija | E208: =ESTADISTICA!E208 -> Fibra Optica | F208: =ESTADISTICA!F208 -> 0 | G208: =ESTADISTICA!G208 -> 0 | H208: =ESTADISTICA!H208 -> 0 | ... AJ208: =ESTADISTICA!AJ208 -> #REF!
A209: =ESTADISTICA!A209 -> GOBERNADOR MONTEVERDE | B209: =ESTADISTICA!B209 -> MON02 | C209: =ESTADISTICA!C209 -> Senzabello y Famatina | D209: =ESTADISTICA!D209 -> Domo | E209: =ESTADISTICA!E209 -> Radio | F209: =ESTADISTICA!F209 -> 0 | G209: =ESTADISTICA!G209 -> 0 | H209: =ESTADISTICA!H209 -> 0 | ... AJ209: =ESTADISTICA!AJ209 -> #REF!
A210: =ESTADISTICA!A210 -> GOBERNADOR MONTEVERDE | B210: =ESTADISTICA!B210 -> MON03 | C210: =ESTADISTICA!C210 -> Senzabello y Guemes | D210: =ESTADISTICA!D210 -> Domo | E210: =ESTADISTICA!E210 -> Radio | F210: =ESTADISTICA!F210 -> 0 | G210: =ESTADISTICA!G210 -> 0 | H210: =ESTADISTICA!H210 -> 0 | ... AJ210: =ESTADISTICA!AJ210 -> #REF!
A211: =ESTADISTICA!A211 -> GOBERNADOR MONTEVERDE | B211: =ESTADISTICA!B211 -> MON04 | C211: =ESTADISTICA!C211 -> Av. Yrigoyen y San Lorenzo | D211: =ESTADISTICA!D211 -> Domo | E211: =ESTADISTICA!E211 -> Radio | F211: =ESTADISTICA!F211 -> 0 | G211: =ESTADISTICA!G211 -> 0 | H211: =ESTADISTICA!H211 -> 0 | ... AJ211: =ESTADISTICA!AJ211 -> #REF!
A212: =ESTADISTICA!A212 -> 9 DE JULIO | B212: =ESTADISTICA!B212 -> NJU 01 | C212: =ESTADISTICA!C212 -> Sallares y Parrillo | D212: =ESTADISTICA!D212 -> Domo | E212: =ESTADISTICA!E212 -> Fibra Optica | F212: =ESTADISTICA!F212 -> 0 | G212: =ESTADISTICA!G212 -> 0 | H212: =ESTADISTICA!H212 -> 0 | ... AJ212: =ESTADISTICA!AJ212 -> #REF!
A213: =ESTADISTICA!A213 -> 9 DE JULIO | B213: =ESTADISTICA!B213 -> NJU02 | C213: =ESTADISTICA!C213 -> Ituzaingo y Boccuzzi | D213: =ESTADISTICA!D213 -> Domo | E213: =ESTADISTICA!E213 -> Radio | F213: =ESTADISTICA!F213 -> 0 | G213: =ESTADISTICA!G213 -> 0 | H213: =ESTADISTICA!H213 -> 0 | ... AJ213: =ESTADISTICA!AJ213 -> #REF!
A214: =ESTADISTICA!A214 -> 9 DE JULIO | B214: =ESTADISTICA!B214 -> NJU03 | C214: =ESTADISTICA!C214 -> San Juan y Parrillo | D214: =ESTADISTICA!D214 -> Domo | E214: =ESTADISTICA!E214 -> PTO A FO | F214: =ESTADISTICA!F214 -> 0 | G214: =ESTADISTICA!G214 -> 0 | H214: =ESTADISTICA!H214 -> 0 | ... AJ214: =ESTADISTICA!AJ214 -> #REF!
A215: =ESTADISTICA!A215 -> 9 DE JULIO | B215: =ESTADISTICA!B215 -> NJU04 | C215: =ESTADISTICA!C215 -> Ituzaingo y 214 A | D215: =ESTADISTICA!D215 -> Domo | E215: =ESTADISTICA!E215 -> Radio | F215: =ESTADISTICA!F215 -> 0 | G215: =ESTADISTICA!G215 -> 0 | H215: =ESTADISTICA!H215 -> 0 | ... AJ215: =ESTADISTICA!AJ215 -> #REF!
A216: =ESTADISTICA!A216 -> ZEBALLOS CENTRO | B216: =ESTADISTICA!B216 -> NJU05 | C216: =ESTADISTICA!C216 -> Ituzaingo y Alem | D216: =ESTADISTICA!D216 -> Domo | E216: =ESTADISTICA!E216 -> Radio | F216: =ESTADISTICA!F216 -> 0 | G216: =ESTADISTICA!G216 -> 0 | H216: =ESTADISTICA!H216 -> APAGADO | ... AJ216: =ESTADISTICA!AJ216 -> #REF!
A217: =ESTADISTICA!A217 -> CENTRO | B217: =ESTADISTICA!B217 -> NJU06 | C217: =ESTADISTICA!C217 -> Sallares y Rodo | D217: =ESTADISTICA!D217 -> Domo | E217: =ESTADISTICA!E217 -> Fibra Optica | F217: =ESTADISTICA!F217 -> 0 | G217: =ESTADISTICA!G217 -> 0 | H217: =ESTADISTICA!H217 -> 0 | ... AJ217: =ESTADISTICA!AJ217 -> #REF!
A218: =ESTADISTICA!A218 -> 9 DE JULIO | B218: =ESTADISTICA!B218 -> NJU07 | C218: =ESTADISTICA!C218 -> Gral. Juan Domingo Peron y Parrillo | D218: =ESTADISTICA!D218 -> Domo | E218: =ESTADISTICA!E218 -> Fibra Optica | F218: =ESTADISTICA!F218 -> 0 | G218: =ESTADISTICA!G218 -> 0 | H218: =ESTADISTICA!H218 -> 0 | ... AJ218: =ESTADISTICA!AJ218 -> #REF!
A219: =ESTADISTICA!A219 -> 9 DE JULIO | B219: =ESTADISTICA!B219 -> NJU 08 | C219: =ESTADISTICA!C219 -> BOCCUZZI Y O HIGGINS | D219: =ESTADISTICA!D219 -> DOMO | E219: =ESTADISTICA!E219 -> Radio | F219: =ESTADISTICA!F219 -> 0 | G219: =ESTADISTICA!G219 -> 0 | H219: =ESTADISTICA!H219 -> 0 | ... AJ219: =ESTADISTICA!AJ219 -> #REF!
... A516: =ESTADISTICA!A516 -> 0 | B516: =ESTADISTICA!B516 -> 0 | C516: =ESTADISTICA!C516 -> 0 | D516: =ESTADISTICA!D516 -> 0 | E516: =ESTADISTICA!E516 -> 0 | F516: =ESTADISTICA!F516 -> 0 | G516: =ESTADISTICA!G516 -> 0 | H516: =ESTADISTICA!H516 -> 0 | ... AJ516: =ESTADISTICA!AJ516 -> #REF!

Sheet APAGADOS FIBRA
C1: TOTAL FIBRA | D1: =COUNTIFS(E4:E400,"=Fibra Optica") -> 268
E2: APAGADOS | F2: =COUNTIFS(F4:F500, "=APAGADO",E4:E500,"=Fibra Optica") -> 0 | G2: =COUNTIFS(G4:G500, "=APAGADO",E4:E500,"=Fibra Optica") -> 0 | H2: =COUNTIFS(H4:H500, "=APAGADO",E4:E500,"=Fibra Optica") -> 10 | I2: =COUNTIFS(I4:I500, "=APAGADO",E4:E500,"=Fibra Optica") -> 0 | J2: =COUNTIFS(J4:J500, "=APAGADO",E4:E500,"=Fibra Optica") -> 0 | K2: =COUNTIFS(K4:K500, "=APAGADO",E4:E500,"=Fibra Optica") -> 0 | L2: =COUNTIFS(L4:L500, "=APAGADO",E4:E500,"=Fibra Optica") -> 0 | M2: =COUNTIFS(M4:M500, "=APAGADO",E4:E500,"=Fibra Optica") -> 0 | N2: =COUNTIFS(N4:N500, "=APAGADO",E4:E500,"=Fibra Optica") -> 0 | O2: =COUNTIFS(O4:O500, "=APAGADO",E4:E500,"=Fibra Optica") -> 0 | P2: =COUNTIFS(P4:P500, "=APAGADO",E4:E500,"=Fibra Optica") -> 0 | Q2: =COUNTIFS(Q4:Q500, "=APAGADO",E4:E500,"=Fibra Optica") -> 0 | R2: =COUNTIFS(R4:R500, "=APAGADO",E4:E500,"=Fibra Optica") -> 0 | S2: =COUNTIFS(S4:S500, "=APAGADO",E4:E500,"=Fibra Optica") -> 0 | T2: =COUNTIFS(T4:T500, "=APAGADO",E4:E500,"=Fibra Optica") -> 0 | U2: =COUNTIFS(U4:U500, "=APAGADO",E4:E500,"=Fibra Optica") -> 0 | V2: =COUNTIFS(V4:V500, "=APAGADO",E4:E500,"=Fibra Optica") -> 0 | W2: =COUNTIFS(W4:W500, "=APAGADO",E4:E500,"=Fibra Optica") -> 0 | X2: =COUNTIFS(X4:X500, "=APAGADO",E4:E500,"=Fibra Optica") -> 0 | Y2: =COUNTIFS(Y4:Y500, "=APAGADO",E4:E500,"=Fibra Optica") -> 0 | Z2: =COUNTIFS(Z4:Z500, "=APAGADO",E4:E500,"=Fibra Optica") -> 0 | AA2: =COUNTIFS(AA4:AA500, "=APAGADO",E4:E500,"=Fibra Optica") -> 0 | AB2: =COUNTIFS(AB4:AB500, "=APAGADO",E4:E500,"=Fibra Optica") -> 0 | AC2: =COUNTIFS(AC4:AC500, "=APAGADO",E4:E500,"=Fibra Optica") -> 0 | AD2: =COUNTIFS(AD4:AD500, "=APAGADO",E4:E500,"=Fibra Optica") -> 0 | AE2: =COUNTIFS(AE4:AE500, "=APAGADO",E4:E500,"=Fibra Optica") -> 0 | AF2: =COUNTIFS(AF4:AF500, "=APAGADO",E4:E500,"=Fibra Optica") -> 0 | AG2: =COUNTIFS(AG4:AG500, "=APAGADO",E4:E500,"=Fibra Optica") -> 0 | AH2: =COUNTIFS(AH4:AH500, "=APAGADO",E4:E500,"=Fibra Optica") -> 0 | AI2: =COUNTIFS(AI4:AI400, "=APAGADO",E4:E400,"=Fibra Optica") -> 0 | AJ2: =COUNTIFS(AJ4:AJ400, "=APAGADO",F4:F400,"=Fibra Optica") -> 0
A3: =ESTADISTICA!A1 -> Barrio | B3: =ESTADISTICA!B1 -> [Denominacion] | C3: =ESTADISTICA!C1 -> [Ubicacion] | D3: =ESTADISTICA!D1 -> [Tipo de Camara] | E3: =ESTADISTICA!E1 -> [Tipo de Conexion] | F3: =ESTADISTICA!F1 -> 45108 | G3: =ESTADISTICA!G1 -> 45109 | H3: =ESTADISTICA!H1 -> 45110 | ... AJ3: =ESTADISTICA!AJ1 -> #REF!
A4: ='RESUMEN TOTAL'!A7 -> ALTAMIRA | B4: ='RESUMEN TOTAL'!B7 -> ALT 03 | C4: ='RESUMEN TOTAL'!D7 -> Bombero Galarza y Necochea | D4: ='RESUMEN TOTAL'!E7 -> Domo | E4: ='RESUMEN TOTAL'!F7 -> Fibra Optica | F4: ='RESUMEN TOTAL'!L7 -> 0 | G4: ='RESUMEN TOTAL'!M7 -> 0 | H4: ='RESUMEN TOTAL'!N7 -> 0 | I4: ='RESUMEN TOTAL'!O7 -> 0 | J4: ='RESUMEN TOTAL'!P7 -> 0 | K4: ='RESUMEN TOTAL'!Q7 -> 0 | L4: ='RESUMEN TOTAL'!R7 -> 0 | M4: ='RESUMEN TOTAL'!S7 -> 0 | ... AI4: ='RESUMEN TOTAL'!AO7 -> 0 | AJ4: ='RESUMEN TOTAL'!#REF! -> #REF!
A5: ='RESUMEN TOTAL'!A8 -> ALTAMIRA | B5: ='RESUMEN TOTAL'!B8 -> ALT 04 | C5: ='RESUMEN TOTAL'!D8 -> Francia y Necochea | D5: ='RESUMEN TOTAL'!E8 -> Domo | E5: ='RESUMEN TOTAL'!F8 -> Fibra Optica | F5: ='RESUMEN TOTAL'!L8 -> 0 | G5: ='RESUMEN TOTAL'!M8 -> 0 | H5: ='RESUMEN TOTAL'!N8 -> 0 | I5: ='RESUMEN TOTAL'!O8 -> 0 | J5: ='RESUMEN TOTAL'!P8 -> 0 | K5: ='RESUMEN TOTAL'!Q8 -> 0 | L5: ='RESUMEN TOTAL'!R8 -> 0 | M5: ='RESUMEN TOTAL'!S8 -> 0 | ... AI5: ='RESUMEN TOTAL'!AO8 -> 0 | AJ5: ='RESUMEN TOTAL'!#REF! -> #REF!
A6: ='RESUMEN TOTAL'!A9 -> ALTAMIRA | B6: ='RESUMEN TOTAL'!B9 -> ALT05 | C6: ='RESUMEN TOTAL'!D9 -> Av. Calchaqui y Bombero Galarza | D6: ='RESUMEN TOTAL'!E9 -> Domo | E6: ='RESUMEN TOTAL'!F9 -> PTO A FO | F6: ='RESUMEN TOTAL'!L9 -> 0 | G6: ='RESUMEN TOTAL'!M9 -> 0 | H6: ='RESUMEN TOTAL'!N9 -> 0 | I6: ='RESUMEN TOTAL'!O9 -> 0 | J6: ='RESUMEN TOTAL'!P9 -> 0 | K6: ='RESUMEN TOTAL'!Q9 -> 0 | L6: ='RESUMEN TOTAL'!R9 -> 0 | M6: ='RESUMEN TOTAL'!S9 -> 0 | ... AI6: ='RESUMEN TOTAL'!AO9 -> 0 | AJ6: ='RESUMEN TOTAL'!#REF! -> #REF!
A7: ='RESUMEN TOTAL'!A10 -> ALTAMIRA | B7: ='RESUMEN TOTAL'!B10 -> ALT 06 | C7: ='RESUMEN TOTAL'!D10 -> LOPE DE VEGA Y NECOCHEA | D7: ='RESUMEN TOTAL'!E10 -> Domo | E7: ='RESUMEN TOTAL'!F10 -> PTO A FO | F7: ='RESUMEN TOTAL'!L10 -> 0 | G7: ='RESUMEN TOTAL'!M10 -> 0 | H7: ='RESUMEN TOTAL'!N10 -> 0 | I7: ='RESUMEN TOTAL'!O10 -> 0 | J7: ='RESUMEN TOTAL'!P10 -> 0 | K7: ='RESUMEN TOTAL'!Q10 -> 0 | L7: ='RESUMEN TOTAL'!R10 -> 0 | M7: ='RESUMEN TOTAL'!S10 -> 0 | ... AI7: ='RESUMEN TOTAL'!AO10 -> 0 | AJ7: ='RESUMEN TOTAL'!#REF! -> #REF!
A8: ='RESUMEN TOTAL'!A11 -> ALTAMIRA | B8: ='RESUMEN TOTAL'!B11 -> ALT07 | C8: ='RESUMEN TOTAL'!D11 -> AV. CALCHAQUI Y AV. DEL TRABAJO | D8: ='RESUMEN TOTAL'!E11 -> DOMO | E8: ='RESUMEN TOTAL'!F11 -> PTO A FO | F8: ='RESUMEN TOTAL'!L11 -> 0 | G8: ='RESUMEN TOTAL'!M11 -> 0 | H8: ='RESUMEN TOTAL'!N11 -> 0 | I8: ='RESUMEN TOTAL'!O11 -> 0 | J8: ='RESUMEN TOTAL'!P11 -> 0 | K8: ='RESUMEN TOTAL'!Q11 -> 0 | L8: ='RESUMEN TOTAL'!R11 -> 0 | M8: ='RESUMEN TOTAL'!S11 -> 0 | ... AI8: ='RESUMEN TOTAL'!AO11 -> 0 | AJ8: ='RESUMEN TOTAL'!#REF! -> #REF!
A9: ='RESUMEN TOTAL'!A12 -> ALTAMIRA | B9: ='RESUMEN TOTAL'!B12 -> ALT 08 | C9: ='RESUMEN TOTAL'!D12 -> HUMAITA Y NECOCHEA | D9: ='RESUMEN TOTAL'!E12 -> DOMO | E9: ='RESUMEN TOTAL'!F12 -> Fibra Optica | F9: ='RESUMEN TOTAL'!L12 -> 0 | G9: ='RESUMEN TOTAL'!M12 -> 0 | H9: ='RESUMEN TOTAL'!N12 -> 0 | I9: ='RESUMEN TOTAL'!O12 -> 0 | J9: ='RESUMEN TOTAL'!P12 -> 0 | K9: ='RESUMEN TOTAL'!Q12 -> 0 | L9: ='RESUMEN TOTAL'!R12 -> 0 | M9: ='RESUMEN TOTAL'!S12 -> 0 | ... AI9: ='RESUMEN TOTAL'!AO12 -> 0 | AJ9: ='RESUMEN TOTAL'!#REF! -> #REF!
A10: ='RESUMEN TOTAL'!A13 -> ALTAMIRA | B10: ='RESUMEN TOTAL'!B13 -> ALT 09 | C10: ='RESUMEN TOTAL'!D13 -> NECOCHEA Y CURUPAITY | D10: ='RESUMEN TOTAL'!E13 -> DOMO | E10: ='RESUMEN TOTAL'!F13 -> Fibra Optica | F10: ='RESUMEN TOTAL'!L13 -> 0 | G10: ='RESUMEN TOTAL'!M13 -> 0 | H10: ='RESUMEN TOTAL'!N13 -> 0 | I10: ='RESUMEN TOTAL'!O13 -> 0 | J10: ='RESUMEN TOTAL'!P13 -> 0 | K10: ='RESUMEN TOTAL'!Q13 -> 0 | L10: ='RESUMEN TOTAL'!R13 -> 0 | M10: ='RESUMEN TOTAL'!S13 -> 0 | ... AI10: ='RESUMEN TOTAL'!AO13 -> 0 | AJ10: ='RESUMEN TOTAL'!#REF! -> #REF!
A11: ='RESUMEN TOTAL'!A14 -> ALTAMIRA | B11: ='RESUMEN TOTAL'!B14 -> ALT 10 | C11: ='RESUMEN TOTAL'!D14 -> Calchaqui y Francia | D11: ='RESUMEN TOTAL'!E14 -> Domo | E11: ='RESUMEN TOTAL'!F14 -> Radio | F11: ='RESUMEN TOTAL'!L14 -> 0 | G11: ='RESUMEN TOTAL'!M14 -> 0 | H11: ='RESUMEN TOTAL'!N14 -> 0 | I11: ='RESUMEN TOTAL'!O14 -> 0 | J11: ='RESUMEN TOTAL'!P14 -> 0 | K11: ='RESUMEN TOTAL'!Q14 -> 0 | L11: ='RESUMEN TOTAL'!R14 -> 0 | M11: ='RESUMEN TOTAL'!S14 -> 0 | ... AI11: ='RESUMEN TOTAL'!AO14 -> 0 | AJ11: ='RESUMEN TOTAL'!#REF! -> #REF!
A12: ='RESUMEN TOTAL'!A15 -> AGUSTIN RAMIREZ | B12: ='RESUMEN TOTAL'!B15 -> ARA 01 | C12: ='RESUMEN TOTAL'!D15 -> Malambo y Tranquera | D12: ='RESUMEN TOTAL'!E15 -> Domo | E12: ='RESUMEN TOTAL'!F15 -> Fibra Optica | F12: ='RESUMEN TOTAL'!L15 -> 0 | G12: ='RESUMEN TOTAL'!M15 -> 0 | H12: ='RESUMEN TOTAL'!N15 -> 0 | I12: ='RESUMEN TOTAL'!O15 -> 0 | J12: ='RESUMEN TOTAL'!P15 -> 0 | K12: ='RESUMEN TOTAL'!Q15 -> 0 | L12: ='RESUMEN TOTAL'!R15 -> 0 | M12: ='RESUMEN TOTAL'!S15 -> 0 | ... AI12: ='RESUMEN TOTAL'!AO15 -> 0 | AJ12: ='RESUMEN TOTAL'!#REF! -> #REF!
A13: ='RESUMEN TOTAL'!A16 -> BELGRANO | B13: ='RESUMEN TOTAL'!B16 -> BEL 01 | C13: ='RESUMEN TOTAL'!D16 -> San Martin y Dardo Rocha | D13: ='RESUMEN TOTAL'!E16 -> DOMO | E13: ='RESUMEN TOTAL'!F16 -> Fibra Optica | F13: ='RESUMEN TOTAL'!L16 -> 0 | G13: ='RESUMEN TOTAL'!M16 -> 0 | H13: ='RESUMEN TOTAL'!N16 -> 0 | I13: ='RESUMEN TOTAL'!O16 -> 0 | J13: ='RESUMEN TOTAL'!P16 -> 0 | K13: ='RESUMEN TOTAL'!Q16 -> 0 | L13: ='RESUMEN TOTAL'!R16 -> 0 | M13: ='RESUMEN TOTAL'!S16 -> 0 | ... AI13: ='RESUMEN TOTAL'!AO16 -> 0 | AJ13: ='RESUMEN TOTAL'!#REF! -> #REF!
A14: ='RESUMEN TOTAL'!A17 -> BELGRANO | B14: ='RESUMEN TOTAL'!B17 -> BEL 02 | C14: ='RESUMEN TOTAL'!D17 -> Guardia vieja y Fronteriz | D14: ='RESUMEN TOTAL'!E17 -> DOMO | E14: ='RESUMEN TOTAL'!F17 -> Fibra Optica | F14: ='RESUMEN TOTAL'!L17 -> 0 | G14: ='RESUMEN TOTAL'!M17 -> 0 | H14: ='RESUMEN TOTAL'!N17 -> 0 | I14: ='RESUMEN TOTAL'!O17 -> 0 | J14: ='RESUMEN TOTAL'!P17 -> 0 | K14: ='RESUMEN TOTAL'!Q17 -> 0 | L14: ='RESUMEN TOTAL'!R17 -> 0 | M14: ='RESUMEN TOTAL'!S17 -> 0 | ... R14: ='RESUMEN TOTAL'!X17 -> 0 | S14: ='RESUMEN TOTAL'!Y23 -> 0 | T14: ='RESUMEN TOTAL'!Z17 -> 0 | U14: ='RESUMEN TOTAL'!AA17 -> 0 | V14: ='RESUMEN TOTAL'!AB17 -> 0 | W14: ='RESUMEN TOTAL'!AC17 -> 0 | X14: ='RESUMEN TOTAL'!AD17 -> 0 | Y14: ='RESUMEN TOTAL'!AE17 -> 0 | Z14: ='RESUMEN TOTAL'!AF17 -> 0 | AA14: ='RESUMEN TOTAL'!AG17 -> 0 | ... AI14: ='RESUMEN TOTAL'!AO17 -> 0 | AJ14: ='RESUMEN TOTAL'!#REF! -> #REF!
A15: ='RESUMEN TOTAL'!A18 -> BOSQUES CENTRO | B15: ='RESUMEN TOTAL'!B18 -> BOSQC 01 | C15: ='RESUMEN TOTAL'!D18 -> LUIS AGOTE E/DANUNCIO Y CAMPOAMOR | D15: ='RESUMEN TOTAL'!E18 -> Fija | E15: ='RESUMEN TOTAL'!F18 -> Radio | F15: ='RESUMEN TOTAL'!L18 -> 0 | G15: ='RESUMEN TOTAL'!M18 -> 0 | H15: ='RESUMEN TOTAL'!N18 -> 0 | I15: ='RESUMEN TOTAL'!O18 -> 0 | J15: ='RESUMEN TOTAL'!P18 -> 0 | K15: ='RESUMEN TOTAL'!Q18 -> 0 | L15: ='RESUMEN TOTAL'!R18 -> 0 | M15: ='RESUMEN TOTAL'!S18 -> 0 | ... AI15: ='RESUMEN TOTAL'!AO18 -> 0 | AJ15: ='RESUMEN TOTAL'!#REF! -> #REF!
A16: ='RESUMEN TOTAL'!A19 -> BOSQUES CENTRO | B16: ='RESUMEN TOTAL'!B19 -> BOSQC 02 | C16: ='RESUMEN TOTAL'!D19 -> LUIS AGOTE E/DANUNCIO Y CAMPOAMOR | D16: ='RESUMEN TOTAL'!E19 -> Fija | E16: ='RESUMEN TOTAL'!F19 -> Radio | F16: ='RESUMEN TOTAL'!L19 -> 0 | G16: ='RESUMEN TOTAL'!M19 -> 0 | H16: ='RESUMEN TOTAL'!N19 -> 0 | I16: ='RESUMEN TOTAL'!O19 -> 0 | J16: ='RESUMEN TOTAL'!P19 -> 0 | K16: ='RESUMEN TOTAL'!Q19 -> 0 | L16: ='RESUMEN TOTAL'!R19 -> 0 | M16: ='RESUMEN TOTAL'!S19 -> 0 | ... AI16: ='RESUMEN TOTAL'!AO19 -> 0 | AJ16: ='RESUMEN TOTAL'!#REF! -> #REF!
A17: ='RESUMEN TOTAL'!A20 -> BOSQUES CENTRO | B17: ='RESUMEN TOTAL'!B20 -> BOSQC 03 | C17: ='RESUMEN TOTAL'!D20 -> BENAVENTE Y LUIS AGOTE | D17: ='RESUMEN TOTAL'!E20 -> Fija | E17: ='RESUMEN TOTAL'!F20 -> Radio | F17: ='RESUMEN TOTAL'!L20 -> 0 | G17: ='RESUMEN TOTAL'!M20 -> 0 | H17: ='RESUMEN TOTAL'!N20 -> 0 | I17: ='RESUMEN TOTAL'!O20 -> 0 | J17: ='RESUMEN TOTAL'!P20 -> 0 | K17: ='RESUMEN TOTAL'!Q20 -> 0 | L17: ='RESUMEN TOTAL'!R20 -> 0 | M17: ='RESUMEN TOTAL'!S20 -> 0 | ... AI17: ='RESUMEN TOTAL'!AO20 -> 0 | AJ17: ='RESUMEN TOTAL'!#REF! -> #REF!
A18: ='RESUMEN TOTAL'!A21 -> BOSQUES CENTRO | B18: ='RESUMEN TOTAL'!B21 -> BOSQC 04 | C18: ='RESUMEN TOTAL'!D21 -> BENAVENTE Y LUIS AGOTE | D18: ='RESUMEN TOTAL'!E21 -> Fija | E18: ='RESUMEN TOTAL'!F21 -> Radio | F18: ='RESUMEN TOTAL'!L21 -> 0 | G18: ='RESUMEN TOTAL'!M21 -> 0 | H18: ='RESUMEN TOTAL'!N21 -> 0 | I18: ='RESUMEN TOTAL'!O21 -> 0 | J18: ='RESUMEN TOTAL'!P21 -> 0 | K18: ='RESUMEN TOTAL'!Q21 -> 0 | L18: ='RESUMEN TOTAL'!R21 -> 0 | M18: ='RESUMEN TOTAL'!S21 -> 0 | ... AI18: ='RESUMEN TOTAL'!AO21 -> 0 | AJ18: ='RESUMEN TOTAL'!#REF! -> #REF!
A19: ='RESUMEN TOTAL'!A22 -> BOSQUES CENTRO | B19: ='RESUMEN TOTAL'!B22 -> BOSQC 05 | C19: ='RESUMEN TOTAL'!D22 -> LUIS AGOTE Y RUTA 36 | D19: ='RESUMEN TOTAL'!E22 -> Fija | E19: ='RESUMEN TOTAL'!F22 -> Radio | F19: ='RESUMEN TOTAL'!L22 -> 0 | G19: ='RESUMEN TOTAL'!M22 -> 0 | H19: ='RESUMEN TOTAL'!N22 -> 0 | I19: ='RESUMEN TOTAL'!O22 -> 0 | J19: ='RESUMEN TOTAL'!P22 -> 0 | K19: ='RESUMEN TOTAL'!Q22 -> 0 | L19: ='RESUMEN TOTAL'!R22 -> 0 | M19: ='RESUMEN TOTAL'!S22 -> 0 | ... AI19: ='RESUMEN TOTAL'!AO22 -> 0 | AJ19: ='RESUMEN TOTAL'!#REF! -> #REF!
A20: ='RESUMEN TOTAL'!A23 -> BOSQUES CENTRO | B20: ='RESUMEN TOTAL'!B23 -> BOSQC 06 | C20: ='RESUMEN TOTAL'!D23 -> LUIS AGOTE Y RUTA 36 | D20: ='RESUMEN TOTAL'!E23 -> Fija | E20: ='RESUMEN TOTAL'!F23 -> Radio | F20: ='RESUMEN TOTAL'!L23 -> 0 | G20: ='RESUMEN TOTAL'!M23 -> 0 | H20: ='RESUMEN TOTAL'!N23 -> 0 | I20: ='RESUMEN TOTAL'!O23 -> 0 | J20: ='RESUMEN TOTAL'!P23 -> 0 | K20: ='RESUMEN TOTAL'!Q23 -> 0 | L20: ='RESUMEN TOTAL'!R23 -> 0 | M20: ='RESUMEN TOTAL'!S23 -> 0 | ... AI20: ='RESUMEN TOTAL'!AO23 -> 0 | AJ20: ='RESUMEN TOTAL'!#REF! -> #REF!
A21: ='RESUMEN TOTAL'!A24 -> CENTRO | B21: ='RESUMEN TOTAL'!B24 -> CEN01 | C21: ='RESUMEN TOTAL'!D24 -> San Martin y 9 de Julio | D21: ='RESUMEN TOTAL'!E24 -> Fija | E21: ='RESUMEN TOTAL'!F24 -> Fibra Optica | F21: ='RESUMEN TOTAL'!L24 -> 0 | G21: ='RESUMEN TOTAL'!M24 -> 0 | H21: ='RESUMEN TOTAL'!N24 -> 0 | I21: ='RESUMEN TOTAL'!O24 -> 0 | J21: ='RESUMEN TOTAL'!P24 -> 0 | K21: ='RESUMEN TOTAL'!Q24 -> 0 | L21: ='RESUMEN TOTAL'!R24 -> 0 | M21: ='RESUMEN TOTAL'!S24 -> 0 | ... AI21: ='RESUMEN TOTAL'!AO24 -> 0 | AJ21: ='RESUMEN TOTAL'!#REF! -> #REF!
A22: ='RESUMEN TOTAL'!A25 -> CENTRO | B22: ='RESUMEN TOTAL'!B25 -> CEN02 | C22: ='RESUMEN TOTAL'!D25 -> San Martin y Almafuerte | D22: ='RESUMEN TOTAL'!E25 -> Fija | E22: ='RESUMEN TOTAL'!F25 -> Fibra Optica | F22: ='RESUMEN TOTAL'!L25 -> 0 | G22: ='RESUMEN TOTAL'!M25 -> 0 | H22: ='RESUMEN TOTAL'!N25 -> 0 | I22: ='RESUMEN TOTAL'!O25 -> 0 | J22: ='RESUMEN TOTAL'!P25 -> 0 | K22: ='RESUMEN TOTAL'!Q25 -> 0 | L22: ='RESUMEN TOTAL'!R25 -> 0 | M22: ='RESUMEN TOTAL'!S25 -> 0 | ... AI22: ='RESUMEN TOTAL'!AO25 -> 0 | AJ22: ='RESUMEN TOTAL'!#REF! -> #REF!
A23: ='RESUMEN TOTAL'!A26 -> CENTRO | B23: ='RESUMEN TOTAL'!B26 -> CEN03 | C23: ='RESUMEN TOTAL'!D26 -> San Martin y Sallares | D23: ='RESUMEN TOTAL'!E26 -> Domo | E23: ='RESUMEN TOTAL'!F26 -> Fibra Optica | F23: ='RESUMEN TOTAL'!L26 -> 0 | G23: ='RESUMEN TOTAL'!M26 -> 0 | H23: ='RESUMEN TOTAL'!N26 -> 0 | I23: ='RESUMEN TOTAL'!O26 -> 0 | J23: ='RESUMEN TOTAL'!P26 -> 0 | K23: ='RESUMEN TOTAL'!Q26 -> 0 | L23: ='RESUMEN TOTAL'!R26 -> 0 | M23: ='RESUMEN TOTAL'!S26 -> 0 | ... AI23: ='RESUMEN TOTAL'!AO26 -> 0 | AJ23: ='RESUMEN TOTAL'!#REF! -> #REF!
A24: ='RESUMEN TOTAL'!A27 -> CENTRO | B24: ='RESUMEN TOTAL'!B27 -> CEN04 | C24: ='RESUMEN TOTAL'!D27 -> San Martin y Contreras | D24: ='RESUMEN TOTAL'!E27 -> Domo | E24: ='RESUMEN TOTAL'!F27 -> Fibra Optica | F24: ='RESUMEN TOTAL'!L27 -> 0 | G24: ='RESUMEN TOTAL'!M27 -> 0 | H24: ='RESUMEN TOTAL'!N27 -> 0 | I24: ='RESUMEN TOTAL'!O27 -> 0 | J24: ='RESUMEN TOTAL'!P27 -> 0 | K24: ='RESUMEN TOTAL'!Q27 -> 0 | L24: ='RESUMEN TOTAL'!R27 -> 0 | M24: ='RESUMEN TOTAL'!S27 -> 0 | ... AI24: ='RESUMEN TOTAL'!AO27 -> 0 | AJ24: ='RESUMEN TOTAL'!#REF! -> #REF!
A25: ='RESUMEN TOTAL'!A28 -> CENTRO | B25: ='RESUMEN TOTAL'!B28 -> CEN 05 | C25: ='RESUMEN TOTAL'!D28 -> Bocuzzi e/España y San Martin | D25: ='RESUMEN TOTAL'!E28 -> DOMO | E25: ='RESUMEN TOTAL'!F28 -> Fibra Optica | F25: ='RESUMEN TOTAL'!L28 -> 0 | G25: ='RESUMEN TOTAL'!M28 -> 0 | H25: ='RESUMEN TOTAL'!N28 -> 0 | I25: ='RESUMEN TOTAL'!O28 -> 0 | J25: ='RESUMEN TOTAL'!P28 -> 0 | K25: ='RESUMEN TOTAL'!Q28 -> 0 | L25: ='RESUMEN TOTAL'!R28 -> 0 | M25: ='RESUMEN TOTAL'!S28 -> 0 | ... AI25: ='RESUMEN TOTAL'!AO28 -> 0 | AJ25: ='RESUMEN TOTAL'!#REF! -> #REF!
A26: ='RESUMEN TOTAL'!A29 -> CENTRO | B26: ='RESUMEN TOTAL'!B29 -> CEN06 | C26: ='RESUMEN TOTAL'!D29 -> Monteagudo y A.del Valle | D26: ='RESUMEN TOTAL'!E29 -> Fija | E26: ='RESUMEN TOTAL'!F29 -> Fibra Optica | F26: ='RESUMEN TOTAL'!L29 -> 0 | G26: ='RESUMEN TOTAL'!M29 -> 0 | H26: ='RESUMEN TOTAL'!N29 -> 0 | I26: ='RESUMEN TOTAL'!O29 -> 0 | J26: ='RESUMEN TOTAL'!P29 -> 0 | K26: ='RESUMEN TOTAL'!Q29 -> 0 | L26: ='RESUMEN TOTAL'!R29 -> 0 | M26: ='RESUMEN TOTAL'!S29 -> 0 | ... AI26: ='RESUMEN TOTAL'!AO29 -> 0 | AJ26: ='RESUMEN TOTAL'!#REF! -> #REF!
... A206: ='RESUMEN TOTAL'!A209 -> MARTIN FIERRO | B206: ='RESUMEN TOTAL'!B209 -> MFI 07 | C206: ='RESUMEN TOTAL'!D209 -> Sargento Cabral y Carlos Gardel | D206: ='RESUMEN TOTAL'!E209 -> Domo | E206: ='RESUMEN TOTAL'!F209 -> PTO A FO | F206: ='RESUMEN TOTAL'!L209 -> 0 | G206: ='RESUMEN TOTAL'!M209 -> 0 | H206: ='RESUMEN TOTAL'!N209 -> 0 | I206: ='RESUMEN TOTAL'!O209 -> 0 | J206: ='RESUMEN TOTAL'!P209 -> 0 | K206: ='RESUMEN TOTAL'!Q209 -> 0 | L206: ='RESUMEN TOTAL'!R209 -> 0 | M206: ='RESUMEN TOTAL'!S209 -> 0 | ... AI206: ='RESUMEN TOTAL'!AO209 -> 0 | AJ206: ='RESUMEN TOTAL'!#REF! -> #REF!
A207: ='RESUMEN TOTAL'!A211 -> GOBERNADOR MONTEVERDE | B207: ='RESUMEN TOTAL'!B211 -> MON01 | C207: ='RESUMEN TOTAL'!D211 -> San Martin y Patricias Argentinas | D207: ='RESUMEN TOTAL'!E211 -> Fija | E207: ='RESUMEN TOTAL'!F211 -> Fibra Optica | F207: ='RESUMEN TOTAL'!L211 -> 0 | G207: ='RESUMEN TOTAL'!M211 -> 0 | H207: ='RESUMEN TOTAL'!N211 -> 0 | I207: ='RESUMEN TOTAL'!O211 -> 0 | J207: ='RESUMEN TOTAL'!P211 -> 0 | K207: ='RESUMEN TOTAL'!Q211 -> 0 | L207: ='RESUMEN TOTAL'!R211 -> 0 | M207: ='RESUMEN TOTAL'!S211 -> 0 | ... AI207: ='RESUMEN TOTAL'!AO211 -> 0 | AJ207: ='RESUMEN TOTAL'!#REF! -> #REF!
A208: ='RESUMEN TOTAL'!A212 -> GOBERNADOR MONTEVERDE | B208: ='RESUMEN TOTAL'!B212 -> MON02 | C208: ='RESUMEN TOTAL'!D212 -> Senzabello y Famatina | D208: ='RESUMEN TOTAL'!E212 -> Domo | E208: ='RESUMEN TOTAL'!F212 -> Radio | F208: ='RESUMEN TOTAL'!L212 -> 0 | G208: ='RESUMEN TOTAL'!M212 -> 0 | H208: ='RESUMEN TOTAL'!N212 -> 0 | I208: ='RESUMEN TOTAL'!O212 -> 0 | J208: ='RESUMEN TOTAL'!P212 -> 0 | K208: ='RESUMEN TOTAL'!Q212 -> 0 | L208: ='RESUMEN TOTAL'!R212 -> 0 | M208: ='RESUMEN TOTAL'!S212 -> 0 | ... AI208: ='RESUMEN TOTAL'!AO212 -> 0 | AJ208: ='RESUMEN TOTAL'!#REF! -> #REF!
A209: ='RESUMEN TOTAL'!A213 -> GOBERNADOR MONTEVERDE | B209: ='RESUMEN TOTAL'!B213 -> MON03 | C209: ='RESUMEN TOTAL'!D213 -> Senzabello y Guemes | D209: ='RESUMEN TOTAL'!E213 -> Domo | E209: ='RESUMEN TOTAL'!F213 -> Radio | F209: ='RESUMEN TOTAL'!L213 -> 0 | G209: ='RESUMEN TOTAL'!M213 -> 0 | H209: ='RESUMEN TOTAL'!N213 -> 0 | I209: ='RESUMEN TOTAL'!O213 -> 0 | J209: ='RESUMEN TOTAL'!P213 -> 0 | K209: ='RESUMEN TOTAL'!Q213 -> 0 | L209: ='RESUMEN TOTAL'!R213 -> 0 | M209: ='RESUMEN TOTAL'!S213 -> 0 | ... AI209: ='RESUMEN TOTAL'!AO213 -> 0 | AJ209: ='RESUMEN TOTAL'!#REF! -> #REF!
A210: ='RESUMEN TOTAL'!A214 -> GOBERNADOR MONTEVERDE | B210: ='RESUMEN TOTAL'!B214 -> MON04 | C210: ='RESUMEN TOTAL'!D214 -> Av. Yrigoyen y San Lorenzo | D210: ='RESUMEN TOTAL'!E214 -> Domo | E210: ='RESUMEN TOTAL'!F214 -> Radio | F210: ='RESUMEN TOTAL'!L214 -> 0 | G210: ='RESUMEN TOTAL'!M214 -> 0 | H210: ='RESUMEN TOTAL'!N214 -> 0 | I210: ='RESUMEN TOTAL'!O214 -> 0 | J210: ='RESUMEN TOTAL'!P214 -> 0 | K210: ='RESUMEN TOTAL'!Q214 -> 0 | L210: ='RESUMEN TOTAL'!R214 -> 0 | M210: ='RESUMEN TOTAL'!S214 -> 0 | ... AI210: ='RESUMEN TOTAL'!AO214 -> 0 | AJ210: ='RESUMEN TOTAL'!#REF! -> #REF!
A211: ='RESUMEN TOTAL'!A215 -> 9 DE JULIO | B211: ='RESUMEN TOTAL'!B215 -> NJU 01 | C211: ='RESUMEN TOTAL'!D215 -> Sallares y Parrillo | D211: ='RESUMEN TOTAL'!E215 -> Domo | E211: ='RESUMEN TOTAL'!F215 -> Fibra Optica | F211: ='RESUMEN TOTAL'!L215 -> 0 | G211: ='RESUMEN TOTAL'!M215 -> 0 | H211: ='RESUMEN TOTAL'!N215 -> 0 | I211: ='RESUMEN TOTAL'!O215 -> 0 | J211: ='RESUMEN TOTAL'!P215 -> 0 | K211: ='RESUMEN TOTAL'!Q215 -> 0 | L211: ='RESUMEN TOTAL'!R215 -> 0 | M211: ='RESUMEN TOTAL'!S215 -> 0 | ... AI211: ='RESUMEN TOTAL'!AO215 -> 0 | AJ211: ='RESUMEN TOTAL'!#REF! -> #REF!
