Workbook
Name _25_de_agosto: 'RESUMEN TOTAL'!$A$4:$D$388
Name _25_de_agosto_3: 'RESUMEN TOTAL'!$A$4:$D$400
Name _30_mar: 'APAGADOS ANTENA'!$AI$3
Name BONOMOcam: Hoja1!$B$2
Name CANTIDAD_DE_CAMARAS: 'RESUMEN TOTAL'!$B$1
Name COSEIDIcam: Hoja1!$B$4

Sheet RESUMEN TOTAL
A1: CANTIDAD DE CAMARAS | B1: =COUNTA(B5:B624) -> 536 | D1: PORCIENTO DE CAIDAS | L1: =(L3)/(L2+L3) -> 0.22655123 | N1: =(N3)/(N2+N3) -> 0.22318841 | P1: =(P3)/(P2+P3) -> 0.22093023 | R1: =(R3)/(R2+R3) -> 0.21176471 | T1: =(T3)/(T2+T3) -> 0 | V1: =(V3)/(V2+V3) -> 0 | X1: =(X3)/(X2+X3) -> 0 | Z1: =(Z3)/(Z2+Z3) -> 0 | AB1: =(AB3)/(AB2+AB3) -> 0 | AD1: =(AD3)/(AD2+AD3) -> 0 | AF1: =(AF3)/(AF2+AF3) -> 0 | AH1: =(AH3)/(AH2+AH3) -> 0 | AJ1: =(AJ3)/(AJ2+AJ3) -> 0 | AN1: =(AN3)/(AN2+AN3) -> 0 | AP1: =(AP3)/(AP2+AP3) -> 0 | AR1: =(AR3)/(AR2+AR3) -> 0 | AT1: =(AT3)/(AT2+AT3) -> 0 | AV1: =(AV3)/(AV2+AV3) -> 0 | AX1: =(AX3)/(AX2+AX3) -> 0 | AZ1: =(AZ3)/(AZ2+AZ3) -> 0 | BB1: =(BB3)/(BB2+BB3) -> 0 | BD1: =(BD3)/(BD2+BD3) -> 0 | BF1: =(BF3)/(BF2+BF3) -> 0 | BH1: =(BH3)/(BH2+BH3) -> 0 | BJ1: =(BJ3)/(BJ2+BJ3) -> 0 | BL1: =(BL3)/(BL2+BL3) -> 0 | BN1: =(BN3)/(BN2+BN3) -> 0 | BP1: =(BP3)/(BP2+BP3) -> 0 | BR1: =(BR3)/(BR2+BR3) -> 0
D2: FUNCIONAN | L2: 536 | N2: 536 | P2: 536 | R2: 536 | T2: 536 | V2: 536 | X2: 536 | Z2: 536 | AB2: 536 | AD2: 536 | AF2: 536 | AH2: 536 | AJ2: 536 | AL2: 536 | AN2: 536 | AP2: 536 | AR2: 536 | AT2: 536 | AV2: 536 | AX2: 536 | AZ2: 536 | BB2: 536 | BD2: 536 | BF2: 536 | BH2: 536 | BJ2: 536 | BL2: 536 | BN2: 536 | BP2: 536 | BR2: 536
D3: CAIDAS | L3: =COUNTIF(L4:L624, "apagado") -> 157 | N3: =COUNTIF(N4:N624, "apagado") -> 154 | P3: =COUNTIF(P4:P624, "apagado") -> 152 | R3: =COUNTIF(R4:R624, "apagado") -> 144 | T3: =COUNTIF(T4:T624, "apagado") -> 0 | V3: =COUNTIF(V4:V624, "apagado") -> 0 | X3: =COUNTIF(X4:X624, "apagado") -> 0 | Z3: =COUNTIF(Z4:Z624, "apagado") -> 0 | AB3: =COUNTIF(AB4:AB624, "apagado") -> 0 | AD3: =COUNTIF(AD4:AD624, "apagado") -> 0 | AF3: =COUNTIF(AF4:AF624, "apagado") -> 0 | AH3: =COUNTIF(AH4:AH624, "apagado") -> 0 | AJ3: =COUNTIF(AJ4:AJ524, "apagado") -> 0 | AL3: =COUNTIF(AL4:AL524, "apagado") -> 0 | AN3: =COUNTIF(AN4:AN624, "apagado") -> 0 | AP3: =COUNTIF(AP4:AP624, "apagado") -> 0 | AR3: =COUNTIF(AR4:AR624, "apagado") -> 0 | AT3: =COUNTIF(AT4:AT624, "apagado") -> 0 | AV3: =COUNTIF(AV4:AV624, "apagado") -> 0 | AX3: =COUNTIF(AX4:AX624, "apagado") -> 0 | AZ3: =COUNTIF(AZ4:AZ624, "apagado") -> 0 | BB3: =COUNTIF(BB4:BB624, "apagado") -> 0 | BD3: =COUNTIF(BD4:BD624, "apagado") -> 0 | BF3: =COUNTIF(BF4:BF624, "apagado") -> 0 | BH3: =COUNTIF(BH4:BH624, "apagado") -> 0 | BJ3: =COUNTIF(BJ4:BJ624, "apagado") -> 0 | BL3: =COUNTIF(BL4:BL624, "apagado") -> 0 | BN3: =COUNTIF(BN4:BN624, "apagado") -> 0 | BP3: =COUNTIF(BP4:BP624, "apagado") -> 0 | BR3: =COUNTIF(BR4:BR624, "apagado") -> 0
A4: Barrio | B4: [Denominacion] | C4: [Empresa Mantenimiento] | D4: [Ubicacion] | E4: [Tipo de Camara] | F4: [Tipo de Conexion] | G4: Destino | I4: DIAS FUNCIONANDO | J4: DIAS CAIDA | K4: EFECTIVIDAD | L4: 45383 | M4: 45383 | N4: 45384 | O4: 45384 | P4: 45385 | Q4: 45385 | R4: 45386 | S4: 45386 | T4: 45387 | V4: 45388 | X4: 45389 | Z4: 45390 | AB4: 45391 | AD4: 45392 | AF4: 45393 | AH4: 45394 | AJ4: 45395 | AL4: 45396 | AN4: 45397 | AP4: 45398 | AR4: 45399 | AT4: 45400 | AV4: 45401 | AX4: 45402 | AZ4: 45403 | BB4: 45404 | BD4: 45405 | BF4: 45406 | BH4: 45407 | BJ4: 45408 | BL4: 45409 | BN4: 45410 | BP4: 45411 | BR4: 45412
A5: ALTAMIRA | B5: ALT01 | C5: BONOMO | D5: Calchaqui y Sgto. Cabral | E5: Domo | F5: Fibra Optica | H5: 172.20.10.6 | I5: =COUNTIF(L5:BN5,"") -> 55 | J5: =COUNTIF(L5:BN5,"APAGADO") -> 0 | K5: =(I5)/(J5+I5) -> 1
A6: ALTAMIRA | B6: ALT02 | C6: BONOMO | D6: Calchaqui y Lope de Vega | E6: Domo | F6: PTO A FO | G6: CABRAL Y CALCHAQUI | H6: 172.20.12.218 | I6: =COUNTIF(L6:BN6,"") -> 55 | J6: =COUNTIF(L6:BN6,"APAGADO") -> 0 | K6: =(I6)/(J6+I6) -> 1
A7: ALTAMIRA | B7: ALT 03 | C7: BONOMO | D7: Bombero Galarza y Necochea | E7: Domo | F7: Fibra Optica | H7: 172.20.12.54 | I7: =COUNTIF(L7:BN7,"") -> 55 | J7: =COUNTIF(L7:BN7,"APAGADO") -> 0 | K7: =(I7)/(J7+I7) -> 1
A8: ALTAMIRA | B8: ALT 04 | C8: BONOMO | D8: Francia y Necochea | E8: Domo | F8: Fibra Optica | H8: 172.20.12.55 | I8: =COUNTIF(L8:BN8,"") -> 55 | J8: =COUNTIF(L8:BN8,"APAGADO") -> 0 | K8: =(I8)/(J8+I8) -> 1
A9: ALTAMIRA | B9: ALT05 | C9: BONOMO | D9: Av. Calchaqui y Bombero Galarza | E9: Domo | F9: PTO A FO | G9: NECOCHEA Y GALARZA | H9: 172.20.12.216 | I9: =COUNTIF(L9:BN9,"") -> 55 | J9: =COUNTIF(L9:BN9,"APAGADO") -> 0 | K9: =(I9)/(J9+I9) -> 1
A10: ALTAMIRA | B10: ALT 06 | C10: BONOMO | D10: LOPE DE VEGA Y NECOCHEA | E10: Domo | F10: PTO A FO | G10: NECOCHEA Y GALARZA | H10: 172.20.12.12 | I10: =COUNTIF(L10:BN10,"") -> 55 | J10: =COUNTIF(L10:BN10,"APAGADO") -> 0 | K10: =(I10)/(J10+I10) -> 1
A11: ALTAMIRA | B11: ALT07 | C11: BONOMO | D11: AV. CALCHAQUI Y AV. DEL TRABAJO | E11: DOMO | F11: PTO A FO | G11: CABRAL Y CALCHAQUI | H11: 172.20.10.57 | I11: =COUNTIF(L11:BN11,"") -> 55 | J11: =COUNTIF(L11:BN11,"APAGADO") -> 0 | K11: =(I11)/(J11+I11) -> 1
A12: ALTAMIRA | B12: ALT 08 | C12: BONOMO | D12: HUMAITA Y NECOCHEA | E12: DOMO | F12: Fibra Optica | H12: 172.20.11.215 | I12: =COUNTIF(L12:BN12,"") -> 55 | J12: =COUNTIF(L12:BN12,"APAGADO") -> 0 | K12: =(I12)/(J12+I12) -> 1
A13: ALTAMIRA | B13: ALT 09 | C13: BONOMO | D13: NECOCHEA Y CURUPAITY | E13: DOMO | F13: Fibra Optica | H13: 172.20.11.216 | I13: =COUNTIF(L13:BN13,"") -> 51 | J13: =COUNTIF(L13:BN13,"APAGADO") -> 4 | K13: =(I13)/(J13+I13) -> 0.92727273 | L13: APAGADO | N13: APAGADO | P13: APAGADO | R13: APAGADO
A14: ALTAMIRA | B14: ALT 10 | C14: BONOMO | D14: Calchaqui y Francia | E14: Domo | F14: Radio | H14: 172.20.12.156 | I14: =COUNTIF(L14:BN14,"") -> 55 | J14: =COUNTIF(L14:BN14,"APAGADO") -> 0 | K14: =(I14)/(J14+I14) -> 1
A15: AGUSTIN RAMIREZ | B15: ARA 01 | C15: BONOMO | D15: Malambo y Tranquera | E15: Domo | F15: Fibra Optica | H15: 172.20.12.110 | I15: =COUNTIF(L15:BN15,"") -> 51 | J15: =COUNTIF(L15:BN15,"APAGADO") -> 4 | K15: =(I15)/(J15+I15) -> 0.92727273 | L15: APAGADO | N15: APAGADO | P15: APAGADO | R15: APAGADO
A16: BELGRANO | B16: BEL 01 | C16: BONOMO | D16: San Martin y Dardo Rocha | E16: DOMO | F16: Fibra Optica | H16: 172.20.12.64 | I16: =COUNTIF(L16:BN16,"") -> 55 | J16: =COUNTIF(L16:BN16,"APAGADO") -> 0 | K16: =(I16)/(J16+I16) -> 1
A17: BELGRANO | B17: BEL 02 | C17: BONOMO | D17: Guardia vieja y Fronteriz | E17: DOMO | F17: Fibra Optica | I17: =COUNTIF(L17:BN17,"") -> 55 | J17: =COUNTIF(L17:BN17,"APAGADO") -> 0 | K17: =(I17)/(J17+I17) -> 1
A18: BOSQUES CENTRO | B18: BOSQC 01 | C18: COSEIDI | D18: LUIS AGOTE E/DANUNCIO Y CAMPOAMOR | E18: Fija | F18: Radio | H18: 172.20.11.15 | I18: =COUNTIF(L18:BN18,"") -> 55 | J18: =COUNTIF(L18:BN18,"APAGADO") -> 0 | K18: =(I18)/(J18+I18) -> 1
A19: BOSQUES CENTRO | B19: BOSQC 02 | C19: COSEIDI | D19: LUIS AGOTE E/DANUNCIO Y CAMPOAMOR | E19: Fija | F19: Radio | H19: 172.20.11.16 | I19: =COUNTIF(L19:BN19,"") -> 55 | J19: =COUNTIF(L19:BN19,"APAGADO") -> 0 | K19: =(I19)/(J19+I19) -> 1
A20: BOSQUES CENTRO | B20: BOSQC 03 | C20: COSEIDI | D20: BENAVENTE Y LUIS AGOTE | E20: Fija | F20: Radio | H20: 172.20.11.13 | I20: =COUNTIF(L20:BN20,"") -> 55 | J20: =COUNTIF(L20:BN20,"APAGADO") -> 0 | K20: =(I20)/(J20+I20) -> 1
A21: BOSQUES CENTRO | B21: BOSQC 04 | C21: COSEIDI | D21: BENAVENTE Y LUIS AGOTE | E21: Fija | F21: Radio | H21: 172.20.11.113 | I21: =COUNTIF(L21:BN21,"") -> 55 | J21: =COUNTIF(L21:BN21,"APAGADO") -> 0 | K21: =(I21)/(J21+I21) -> 1
A22: BOSQUES CENTRO | B22: BOSQC 05 | C22: COSEIDI | D22: LUIS AGOTE Y RUTA 36 | E22: Fija | F22: Radio | H22: 172.20.11.17 | I22: =COUNTIF(L22:BN22,"") -> 55 | J22: =COUNTIF(L22:BN22,"APAGADO") -> 0 | K22: =(I22)/(J22+I22) -> 1
A23: BOSQUES CENTRO | B23: BOSQC 06 | C23: COSEIDI | D23: LUIS AGOTE Y RUTA 36 | E23: Fija | F23: Radio | H23: 172.20.11.18 | I23: =COUNTIF(L23:BN23,"") -> 55 | J23: =COUNTIF(L23:BN23,"APAGADO") -> 0 | K23: =(I23)/(J23+I23) -> 1
A24: CENTRO | B24: CEN01 | C24: BONOMO | D24: San Martin y 9 de Julio | E24: Fija | F24: Fibra Optica | H24: 172.20.11.10 | I24: =COUNTIF(L24:BN24,"") -> 51 | J24: =COUNTIF(L24:BN24,"APAGADO") -> 4 | K24: =(I24)/(J24+I24) -> 0.92727273 | L24: APAGADO | N24: APAGADO | P24: APAGADO | R24: APAGADO
A25: CENTRO | B25: CEN02 | C25: BONOMO | D25: San Martin y Almafuerte | E25: Fija | F25: Fibra Optica | H25: 172.20.11.11 | I25: =COUNTIF(L25:BN25,"") -> 51 | J25: =COUNTIF(L25:BN25,"APAGADO") -> 4 | K25: =(I25)/(J25+I25) -> 0.92727273 | L25: APAGADO | N25: APAGADO | P25: APAGADO | R25: APAGADO
A26: CENTRO | B26: CEN03 | C26: BONOMO | D26: San Martin y Sallares | E26: Domo | F26: Fibra Optica | H26: 172.20.12.30 | I26: =COUNTIF(L26:BN26,"") -> 55 | J26: =COUNTIF(L26:BN26,"APAGADO") -> 0 | K26: =(I26)/(J26+I26) -> 1
A27: CENTRO | B27: CEN04 | C27: BONOMO | D27: San Martin y Contreras | E27: Domo | F27: Fibra Optica | H27: 172.20.12.29 | I27: =COUNTIF(L27:BN27,"") -> 55 | J27: =COUNTIF(L27:BN27,"APAGADO") -> 0 | K27: =(I27)/(J27+I27) -> 1
A28: CENTRO | B28: CEN 05 | C28: BONOMO | D28: Bocuzzi e/España y San Martin | E28: DOMO | F28: Fibra Optica | H28: 172.20.10.200 | I28: =COUNTIF(L28:BN28,"") -> 47 | J28: =COUNTIF(L28:BN28,"APAGADO") -> 4 | K28: =(I28)/(J28+I28) -> 0.92156863 | L28: APAGADO | M28: problemas en el dispositivo - tiene vinculo de red | N28: APAGADO | O28: problemas en el dispositivo - tiene vinculo de red | P28: APAGADO | Q28: problemas en el dispositivo - tiene vinculo de red | R28: APAGADO | S28: problemas en el dispositivo - tiene vinculo de red
A29: CENTRO | B29: CEN06 | C29: BONOMO | D29: Monteagudo y A.del Valle | E29: Fija | F29: Fibra Optica | H29: 172.20.10.02 | I29: =COUNTIF(L29:BN29,"") -> 47 | J29: =COUNTIF(L29:BN29,"APAGADO") -> 4 | K29: =(I29)/(J29+I29) -> 0.92156863 | L29: APAGADO | M29: problemas en el dispositivo - tiene vinculo de red | N29: APAGADO | O29: problemas en el dispositivo - tiene vinculo de red | P29: APAGADO | Q29: problemas en el dispositivo - tiene vinculo de red | R29: APAGADO | S29: problemas en el dispositivo - tiene vinculo de red
A30: CENTRO | B30: CEN07 | C30: BONOMO | D30: San Martin y Guemes | E30: DOMO | F30: Fibra Optica | H30: 172.20.11.20 | I30: =COUNTIF(L30:BN30,"") -> 55 | J30: =COUNTIF(L30:BN30,"APAGADO") -> 0 | K30: =(I30)/(J30+I30) -> 1
A31: CENTRO | B31: CEN08 | C31: BONOMO | D31: San Martin y Pte.Peron | E31: Domo | F31: Fibra Optica | H31: 172.20.11.21 | I31: =COUNTIF(L31:BN31,"") -> 55 | J31: =COUNTIF(L31:BN31,"APAGADO") -> 0 | K31: =(I31)/(J31+I31) -> 1
A32: CENTRO | B32: CEN09 | C32: BONOMO | D32: Chacabuco y 25 de Mayo | E32: Domo | F32: Fibra Optica | H32: 172.20.11.22 | I32: =COUNTIF(L32:BN32,"") -> 55 | J32: =COUNTIF(L32:BN32,"APAGADO") -> 0 | K32: =(I32)/(J32+I32) -> 1
A33: CENTRO | B33: CEN10 | C33: BONOMO | D33: Monteagudo y Pte. Peron | E33: Domo | F33: Fibra Optica | H33: 172.20.11.23 | I33: =COUNTIF(L33:BN33,"") -> 55 | J33: =COUNTIF(L33:BN33,"APAGADO") -> 0 | K33: =(I33)/(J33+I33) -> 1
A34: CENTRO | B34: CEN11 | C34: BONOMO | D34: Monteagudo y Bocuzzi | E34: Domo | F34: Fibra Optica | H34: 172.20.10.24 | I34: =COUNTIF(L34:BN34,"") -> 55 | J34: =COUNTIF(L34:BN34,"APAGADO") -> 0 | K34: =(I34)/(J34+I34) -> 1
A35: CENTRO | B35: CEN 12 | C35: BONOMO | D35: Monteagudo y Mitre | E35: Domo | F35: Fibra Optica | H35: 172.20.10.23 | I35: =COUNTIF(L35:BN35,"") -> 55 | J35: =COUNTIF(L35:BN35,"APAGADO") -> 0 | K35: =(I35)/(J35+I35) -> 1
A36: CENTRO | B36: CEN 13 | C36: BONOMO | D36: 25 de Mayo y Maipu | E36: DOMO | F36: Fibra Optica | H36: 172.20.10.20 | I36: =COUNTIF(L36:BN36,"") -> 55 | J36: =COUNTIF(L36:BN36,"APAGADO") -> 0 | K36: =(I36)/(J36+I36) -> 1
A37: CENTRO | B37: CEN14 | C37: BONOMO | D37: Pte.Peron e/Pringles y Brown | E37: Domo | F37: Fibra Optica | H37: 172.20.10.94 | I37: =COUNTIF(L37:BN37,"") -> 55 | J37: =COUNTIF(L37:BN37,"APAGADO") -> 0 | K37: =(I37)/(J37+I37) -> 1
A38: CENTRO | B38: CEN15 | C38: BONOMO | D38: Alberdi y A.del Valle | E38: Domo | F38: Fibra Optica | H38: 172.20.10.35 | I38: =COUNTIF(L38:BN38,"") -> 55 | J38: =COUNTIF(L38:BN38,"APAGADO") -> 0 | K38: =(I38)/(J38+I38) -> 1
A39: CENTRO | B39: CEN16 | C39: BONOMO | D39: San Martin y Pte. Peron | E39: Fija | F39: Fibra Optica | H39: 172.20.12.36 | I39: =COUNTIF(L39:BN39,"") -> 55 | J39: =COUNTIF(L39:BN39,"APAGADO") -> 0 | K39: =(I39)/(J39+I39) -> 1
A40: CENTRO | B40: CEN17 | C40: BONOMO | D40: San Martin y Mitre | E40: Domo | F40: PTO A FO | G40: SAN MARTIN Y SALLARES | H40: 172.20.12.200 | I40: =COUNTIF(L40:BN40,"") -> 55 | J40: =COUNTIF(L40:BN40,"APAGADO") -> 0 | K40: =(I40)/(J40+I40) -> 1
...

Sheet Hoja3

Sheet ESTADISTICA
A1: ='RESUMEN TOTAL'!A4 -> Barrio | B1: ='RESUMEN TOTAL'!B4 -> [Denominacion] | C1: ='RESUMEN TOTAL'!D4 -> [Ubicacion] | D1: ='RESUMEN TOTAL'!E4 -> [Tipo de Camara] | E1: ='RESUMEN TOTAL'!F4 -> [Tipo de Conexion] | F1: ='RESUMEN TOTAL'!L4 -> 45383 | G1: ='RESUMEN TOTAL'!N4 -> 45384 | H1: ='RESUMEN TOTAL'!P4 -> 45385 | I1: ='RESUMEN TOTAL'!R4 -> 45386 | J1: ='RESUMEN TOTAL'!T4 -> 45387 | K1: ='RESUMEN TOTAL'!V4 -> 45388 | L1: ='RESUMEN TOTAL'!X4 -> 45389 | M1: ='RESUMEN TOTAL'!Z4 -> 45390 | N1: ='RESUMEN TOTAL'!AB4 -> 45391 | O1: ='RESUMEN TOTAL'!AD4 -> 45392 | P1: ='RESUMEN TOTAL'!AF4 -> 45393 | Q1: ='RESUMEN TOTAL'!AH4 -> 45394 | R1: ='RESUMEN TOTAL'!AJ4 -> 45395 | S1: ='RESUMEN TOTAL'!AL4 -> 45396 | T1: ='RESUMEN TOTAL'!AN4 -> 45397 | U1: ='RESUMEN TOTAL'!AP4 -> 45398 | V1: ='RESUMEN TOTAL'!AR4 -> 45399 | W1: ='RESUMEN TOTAL'!AT4 -> 45400 | X1: ='RESUMEN TOTAL'!AV4 -> 45401 | Y1: ='RESUMEN TOTAL'!AX4 -> 45402 | Z1: ='RESUMEN TOTAL'!AZ4 -> 45403 | AA1: ='RESUMEN TOTAL'!BB4 -> 45404 | AB1: ='RESUMEN TOTAL'!BD4 -> 45405 | AC1: ='RESUMEN TOTAL'!BF4 -> 45406 | AD1: ='RESUMEN TOTAL'!BH4 -> 45407 | AE1: ='RESUMEN TOTAL'!BJ4 -> 45408 | AF1: ='RESUMEN TOTAL'!BL4 -> 45409 | AG1: ='RESUMEN TOTAL'!BN4 -> 45410 | AH1: ='RESUMEN TOTAL'!BP4 -> 45411
A2: ='RESUMEN TOTAL'!A5 -> ALTAMIRA | B2: ='RESUMEN TOTAL'!B5 -> ALT01 | C2: ='RESUMEN TOTAL'!D5 -> Calchaqui y Sgto. Cabral | D2: ='RESUMEN TOTAL'!E5 -> Domo | E2: ='RESUMEN TOTAL'!F5 -> Fibra Optica | F2: ='RESUMEN TOTAL'!L5 -> 0 | G2: ='RESUMEN TOTAL'!N5 -> 0 | H2: ='RESUMEN TOTAL'!P5 -> 0 | I2: ='RESUMEN TOTAL'!R5 -> 0 | J2: ='RESUMEN TOTAL'!T5 -> 0 | K2: ='RESUMEN TOTAL'!V5 -> 0 | L2: ='RESUMEN TOTAL'!X5 -> 0 | M2: ='RESUMEN TOTAL'!Z5 -> 0 | N2: ='RESUMEN TOTAL'!AB5 -> 0 | O2: ='RESUMEN TOTAL'!AD5 -> 0 | P2: ='RESUMEN TOTAL'!AF5 -> 0 | Q2: ='RESUMEN TOTAL'!AH5 -> 0 | R2: ='RESUMEN TOTAL'!AJ5 -> 0 | S2: ='RESUMEN TOTAL'!AL5 -> 0 | T2: ='RESUMEN TOTAL'!AN5 -> 0 | U2: ='RESUMEN TOTAL'!AP5 -> 0 | V2: ='RESUMEN TOTAL'!AR5 -> 0 | W2: ='RESUMEN TOTAL'!AT5 -> 0 | X2: ='RESUMEN TOTAL'!AV5 -> 0 | Y2: ='RESUMEN TOTAL'!AX5 -> 0 | Z2: ='RESUMEN TOTAL'!AZ5 -> 0 | AA2: ='RESUMEN TOTAL'!BB5 -> 0 | AB2: ='RESUMEN TOTAL'!BD5 -> 0 | AC2: ='RESUMEN TOTAL'!BF5 -> 0 | AD2: ='RESUMEN TOTAL'!BH5 -> 0 | AE2: ='RESUMEN TOTAL'!BJ5 -> 0 | AF2: ='RESUMEN TOTAL'!BL5 -> 0 | AG2: ='RESUMEN TOTAL'!BN5 -> 0 | AH2: ='RESUMEN TOTAL'!BP5 -> 0
A3: ='RESUMEN TOTAL'!A6 -> ALTAMIRA | B3: ='RESUMEN TOTAL'!B6 -> ALT02 | C3: ='RESUMEN TOTAL'!D6 -> Calchaqui y Lope de Vega | D3: ='RESUMEN TOTAL'!E6 -> Domo | E3: ='RESUMEN TOTAL'!F6 -> PTO A FO | F3: ='RESUMEN TOTAL'!L6 -> 0 | G3: ='RESUMEN TOTAL'!N6 -> 0 | H3: ='RESUMEN TOTAL'!P6 -> 0 | I3: ='RESUMEN TOTAL'!R6 -> 0 | J3: ='RESUMEN TOTAL'!T6 -> 0 | K3: ='RESUMEN TOTAL'!V6 -> 0 | L3: ='RESUMEN TOTAL'!X6 -> 0 | M3: ='RESUMEN TOTAL'!Z6 -> 0 | N3: ='RESUMEN TOTAL'!AB6 -> 0 | O3: ='RESUMEN TOTAL'!AD6 -> 0 | P3: ='RESUMEN TOTAL'!AF6 -> 0 | Q3: ='RESUMEN TOTAL'!AH6 -> 0 | R3: ='RESUMEN TOTAL'!AJ6 -> 0 | S3: ='RESUMEN TOTAL'!AL6 -> 0 | T3: ='RESUMEN TOTAL'!AN6 -> 0 | U3: ='RESUMEN TOTAL'!AP6 -> 0 | V3: ='RESUMEN TOTAL'!AR6 -> 0 | W3: ='RESUMEN TOTAL'!AT6 -> 0 | X3: ='RESUMEN TOTAL'!AV6 -> 0 | Y3: ='RESUMEN TOTAL'!AX6 -> 0 | Z3: ='RESUMEN TOTAL'!AZ6 -> 0 | AA3: ='RESUMEN TOTAL'!BB6 -> 0 | AB3: ='RESUMEN TOTAL'!BD6 -> 0 | AC3: ='RESUMEN TOTAL'!BF6 -> 0 | AD3: ='RESUMEN TOTAL'!BH6 -> 0 | AE3: ='RESUMEN TOTAL'!BJ6 -> 0 | AF3: ='RESUMEN TOTAL'!BL6 -> 0 | AG3: ='RESUMEN TOTAL'!BN6 -> 0 | AH3: ='RESUMEN TOTAL'!BP6 -> 0
A4: ='RESUMEN TOTAL'!A7 -> ALTAMIRA | B4: ='RESUMEN TOTAL'!B7 -> ALT 03 | C4: ='RESUMEN TOTAL'!D7 -> Bombero Galarza y Necochea | D4: ='RESUMEN TOTAL'!E7 -> Domo | E4: ='RESUMEN TOTAL'!F7 -> Fibra Optica | F4: ='RESUMEN TOTAL'!L7 -> 0 | G4: ='RESUMEN TOTAL'!N7 -> 0 | H4: ='RESUMEN TOTAL'!P7 -> 0 | I4: ='RESUMEN TOTAL'!R7 -> 0 | J4: ='RESUMEN TOTAL'!T7 -> 0 | K4: ='RESUMEN TOTAL'!V7 -> 0 | L4: ='RESUMEN TOTAL'!X7 -> 0 | M4: ='RESUMEN TOTAL'!Z7 -> 0 | N4: ='RESUMEN TOTAL'!AB7 -> 0 | O4: ='RESUMEN TOTAL'!AD7 -> 0 | P4: ='RESUMEN TOTAL'!AF7 -> 0 | Q4: ='RESUMEN TOTAL'!AH7 -> 0 | R4: ='RESUMEN TOTAL'!AJ7 -> 0 | S4: ='RESUMEN TOTAL'!AL7 -> 0 | T4: ='RESUMEN TOTAL'!AN7 -> 0 | U4: ='RESUMEN TOTAL'!AP7 -> 0 | V4: ='RESUMEN TOTAL'!AR7 -> 0 | W4: ='RESUMEN TOTAL'!AT7 -> 0 | X4: ='RESUMEN TOTAL'!AV7 -> 0 | Y4: ='RESUMEN TOTAL'!AX7 -> 0 | Z4: ='RESUMEN TOTAL'!AZ7 -> 0 | AA4: ='RESUMEN TOTAL'!BB7 -> 0 | AB4: ='RESUMEN TOTAL'!BD7 -> 0 | AC4: ='RESUMEN TOTAL'!BF7 -> 0 | AD4: ='RESUMEN TOTAL'!BH7 -> 0 | AE4: ='RESUMEN TOTAL'!BJ7 -> 0 | AF4: ='RESUMEN TOTAL'!BL7 -> 0 | AG4: ='RESUMEN TOTAL'!BN7 -> 0 | AH4: ='RESUMEN TOTAL'!BP7 -> 0
A5: ='RESUMEN TOTAL'!A8 -> ALTAMIRA | B5: ='RESUMEN TOTAL'!B8 -> ALT 04 | C5: ='RESUMEN TOTAL'!D8 -> Francia y Necochea | D5: ='RESUMEN TOTAL'!E8 -> Domo | E5: ='RESUMEN TOTAL'!F8 -> Fibra Optica | F5: ='RESUMEN TOTAL'!L8 -> 0 | G5: ='RESUMEN TOTAL'!N8 -> 0 | H5: ='RESUMEN TOTAL'!P8 -> 0 | I5: ='RESUMEN TOTAL'!R8 -> 0 | J5: ='RESUMEN TOTAL'!T8 -> 0 | K5: ='RESUMEN TOTAL'!V8 -> 0 | L5: ='RESUMEN TOTAL'!X8 -> 0 | M5: ='RESUMEN TOTAL'!Z8 -> 0 | N5: ='RESUMEN TOTAL'!AB8 -> 0 | O5: ='RESUMEN TOTAL'!AD8 -> 0 | P5: ='RESUMEN TOTAL'!AF8 -> 0 | Q5: ='RESUMEN TOTAL'!AH8 -> 0 | R5: ='RESUMEN TOTAL'!AJ8 -> 0 | S5: ='RESUMEN TOTAL'!AL8 -> 0 | T5: ='RESUMEN TOTAL'!AN8 -> 0 | U5: ='RESUMEN TOTAL'!AP8 -> 0 | V5: ='RESUMEN TOTAL'!AR8 -> 0 | W5: ='RESUMEN TOTAL'!AT8 -> 0 | X5: ='RESUMEN TOTAL'!AV8 -> 0 | Y5: ='RESUMEN TOTAL'!AX8 -> 0 | Z5: ='RESUMEN TOTAL'!AZ8 -> 0 | AA5: ='RESUMEN TOTAL'!BB8 -> 0 | AB5: ='RESUMEN TOTAL'!BD8 -> 0 | AC5: ='RESUMEN TOTAL'!BF8 -> 0 | AD5: ='RESUMEN TOTAL'!BH8 -> 0 | AE5: ='RESUMEN TOTAL'!BJ8 -> 0 | AF5: ='RESUMEN TOTAL'!BL8 -> 0 | AG5: ='RESUMEN TOTAL'!BN8 -> 0 | AH5: ='RESUMEN TOTAL'!BP8 -> 0
A6: ='RESUMEN TOTAL'!A9 -> ALTAMIRA | B6: ='RESUMEN TOTAL'!B9 -> ALT05 | C6: ='RESUMEN TOTAL'!D9 -> Av. Calchaqui y Bombero Galarza | D6: ='RESUMEN TOTAL'!E9 -> Domo | E6: ='RESUMEN TOTAL'!F9 -> PTO A FO | F6: ='RESUMEN TOTAL'!L9 -> 0 | G6: ='RESUMEN TOTAL'!N9 -> 0 | H6: ='RESUMEN TOTAL'!P9 -> 0 | I6: ='RESUMEN TOTAL'!R9 -> 0 | J6: ='RESUMEN TOTAL'!T9 -> 0 | K6: ='RESUMEN TOTAL'!V9 -> 0 | L6: ='RESUMEN TOTAL'!X9 -> 0 | M6: ='RESUMEN TOTAL'!Z9 -> 0 | N6: ='RESUMEN TOTAL'!AB9 -> 0 | O6: ='RESUMEN TOTAL'!AD9 -> 0 | P6: ='RESUMEN TOTAL'!AF9 -> 0 | Q6: ='RESUMEN TOTAL'!AH9 -> 0 | R6: ='RESUMEN TOTAL'!AJ9 -> 0 | S6: ='RESUMEN TOTAL'!AL9 -> 0 | T6: ='RESUMEN TOTAL'!AN9 -> 0 | U6: ='RESUMEN TOTAL'!AP9 -> 0 | V6: ='RESUMEN TOTAL'!AR9 -> 0 | W6: ='RESUMEN TOTAL'!AT9 -> 0 | X6: ='RESUMEN TOTAL'!AV9 -> 0 | Y6: ='RESUMEN TOTAL'!AX9 -> 0 | Z6: ='RESUMEN TOTAL'!AZ9 -> 0 | AA6: ='RESUMEN TOTAL'!BB9 -> 0 | AB6: ='RESUMEN TOTAL'!BD9 -> 0 | AC6: ='RESUMEN TOTAL'!BF9 -> 0 | AD6: ='RESUMEN TOTAL'!BH9 -> 0 | AE6: ='RESUMEN TOTAL'!BJ9 -> 0 | AF6: ='RESUMEN TOTAL'!BL9 -> 0 | AG6: ='RESUMEN TOTAL'!BN9 -> 0 | AH6: ='RESUMEN TOTAL'!BP9 -> 0
A7: ='RESUMEN TOTAL'!A10 -> ALTAMIRA | B7: ='RESUMEN TOTAL'!B10 -> ALT 06 | C7: ='RESUMEN TOTAL'!D10 -> LOPE DE VEGA Y NECOCHEA | D7: ='RESUMEN TOTAL'!E10 -> Domo | E7: ='RESUMEN TOTAL'!F10 -> PTO A FO | F7: ='RESUMEN TOTAL'!L10 -> 0 | G7: ='RESUMEN TOTAL'!N10 -> 0 | H7: ='RESUMEN TOTAL'!P10 -> 0 | I7: ='RESUMEN TOTAL'!R10 -> 0 | J7: ='RESUMEN TOTAL'!T10 -> 0 | K7: ='RESUMEN TOTAL'!V10 -> 0 | L7: ='RESUMEN TOTAL'!X10 -> 0 | M7: ='RESUMEN TOTAL'!Z10 -> 0 | N7: ='RESUMEN TOTAL'!AB10 -> 0 | O7: ='RESUMEN TOTAL'!AD10 -> 0 | P7: ='RESUMEN TOTAL'!AF10 -> 0 | Q7: ='RESUMEN TOTAL'!AH10 -> 0 | R7: ='RESUMEN TOTAL'!AJ10 -> 0 | S7: ='RESUMEN TOTAL'!AL10 -> 0 | T7: ='RESUMEN TOTAL'!AN10 -> 0 | U7: ='RESUMEN TOTAL'!AP10 -> 0 | V7: ='RESUMEN TOTAL'!AR10 -> 0 | W7: ='RESUMEN TOTAL'!AT10 -> 0 | X7: ='RESUMEN TOTAL'!AV10 -> 0 | Y7: ='RESUMEN TOTAL'!AX10 -> 0 | Z7: ='RESUMEN TOTAL'!AZ10 -> 0 | AA7: ='RESUMEN TOTAL'!BB10 -> 0 | AB7: ='RESUMEN TOTAL'!BD10 -> 0 | AC7: ='RESUMEN TOTAL'!BF10 -> 0 | AD7: ='RESUMEN TOTAL'!BH10 -> 0 | AE7: ='RESUMEN TOTAL'!BJ10 -> 0 | AF7: ='RESUMEN TOTAL'!BL10 -> 0 | AG7: ='RESUMEN TOTAL'!BN10 -> 0 | AH7: ='RESUMEN TOTAL'!BP10 -> 0
A8: ='RESUMEN TOTAL'!A11 -> ALTAMIRA | B8: ='RESUMEN TOTAL'!B11 -> ALT07 | C8: ='RESUMEN TOTAL'!D11 -> AV. CALCHAQUI Y AV. DEL TRABAJO | D8: ='RESUMEN TOTAL'!E11 -> DOMO | E8: ='RESUMEN TOTAL'!F11 -> PTO A FO | F8: ='RESUMEN TOTAL'!L11 -> 0 | G8: ='RESUMEN TOTAL'!N11 -> 0 | H8: ='RESUMEN TOTAL'!P11 -> 0 | I8: ='RESUMEN TOTAL'!R11 -> 0 | J8: ='RESUMEN TOTAL'!T11 -> 0 | K8: ='RESUMEN TOTAL'!V11 -> 0 | L8: ='RESUMEN TOTAL'!X11 -> 0 | M8: ='RESUMEN TOTAL'!Z11 -> 0 | N8: ='RESUMEN TOTAL'!AB11 -> 0 | O8: ='RESUMEN TOTAL'!AD11 -> 0 | P8: ='RESUMEN TOTAL'!AF11 -> 0 | Q8: ='RESUMEN TOTAL'!AH11 -> 0 | R8: ='RESUMEN TOTAL'!AJ11 -> 0 | S8: ='RESUMEN TOTAL'!AL11 -> 0 | T8: ='RESUMEN TOTAL'!AN11 -> 0 | U8: ='RESUMEN TOTAL'!AP11 -> 0 | V8: ='RESUMEN TOTAL'!AR11 -> 0 | W8: ='RESUMEN TOTAL'!AT11 -> 0 | X8: ='RESUMEN TOTAL'!AV11 -> 0 | Y8: ='RESUMEN TOTAL'!AX11 -> 0 | Z8: ='RESUMEN TOTAL'!AZ11 -> 0 | AA8: ='RESUMEN TOTAL'!BB11 -> 0 | AB8: ='RESUMEN TOTAL'!BD11 -> 0 | AC8: ='RESUMEN TOTAL'!BF11 -> 0 | AD8: ='RESUMEN TOTAL'!BH11 -> 0 | AE8: ='RESUMEN TOTAL'!BJ11 -> 0 | AF8: ='RESUMEN TOTAL'!BL11 -> 0 | AG8: ='RESUMEN TOTAL'!BN11 -> 0 | AH8: ='RESUMEN TOTAL'!BP11 -> 0
A9: ='RESUMEN TOTAL'!A12 -> ALTAMIRA | B9: ='RESUMEN TOTAL'!B12 -> ALT 08 | C9: ='RESUMEN TOTAL'!D12 -> HUMAITA Y NECOCHEA | D9: ='RESUMEN TOTAL'!E12 -> DOMO | E9: ='RESUMEN TOTAL'!F12 -> Fibra Optica | F9: ='RESUMEN TOTAL'!L12 -> 0 | G9: ='RESUMEN TOTAL'!N12 -> 0 | H9: ='RESUMEN TOTAL'!P12 -> 0 | I9: ='RESUMEN TOTAL'!R12 -> 0 | J9: ='RESUMEN TOTAL'!T12 -> 0 | K9: ='RESUMEN TOTAL'!V12 -> 0 | L9: ='RESUMEN TOTAL'!X12 -> 0 | M9: ='RESUMEN TOTAL'!Z12 -> 0 | N9: ='RESUMEN TOTAL'!AB12 -> 0 | O9: ='RESUMEN TOTAL'!AD12 -> 0 | P9: ='RESUMEN TOTAL'!AF12 -> 0 | Q9: ='RESUMEN TOTAL'!AH12 -> 0 | R9: ='RESUMEN TOTAL'!AJ12 -> 0 | S9: ='RESUMEN TOTAL'!AL12 -> 0 | T9: ='RESUMEN TOTAL'!AN12 -> 0 | U9: ='RESUMEN TOTAL'!AP12 -> 0 | V9: ='RESUMEN TOTAL'!AR12 -> 0 | W9: ='RESUMEN TOTAL'!AT12 -> 0 | X9: ='RESUMEN TOTAL'!AV12 -> 0 | Y9: ='RESUMEN TOTAL'!AX12 -> 0 | Z9: ='RESUMEN TOTAL'!AZ12 -> 0 | AA9: ='RESUMEN TOTAL'!BB12 -> 0 | AB9: ='RESUMEN TOTAL'!BD12 -> 0 | AC9: ='RESUMEN TOTAL'!BF12 -> 0 | AD9: ='RESUMEN TOTAL'!BH12 -> 0 | AE9: ='RESUMEN TOTAL'!BJ12 -> 0 | AF9: ='RESUMEN TOTAL'!BL12 -> 0 | AG9: ='RESUMEN TOTAL'!BN12 -> 0 | AH9: ='RESUMEN TOTAL'!BP12 -> 0
A10: ='RESUMEN TOTAL'!A13 -> ALTAMIRA | B10: ='RESUMEN TOTAL'!B13 -> ALT 09 | C10: ='RESUMEN TOTAL'!D13 -> NECOCHEA Y CURUPAITY | D10: ='RESUMEN TOTAL'!E13 -> DOMO | E10: ='RESUMEN TOTAL'!F13 -> Fibra Optica | F10: ='RESUMEN TOTAL'!L13 -> APAGADO | G10: ='RESUMEN TOTAL'!N13 -> APAGADO | H10: ='RESUMEN TOTAL'!P13 -> APAGADO | I10: ='RESUMEN TOTAL'!R13 -> APAGADO | J10: ='RESUMEN TOTAL'!T13 -> 0 | K10: ='RESUMEN TOTAL'!V13 -> 0 | L10: ='RESUMEN TOTAL'!X13 -> 0 | M10: ='RESUMEN TOTAL'!Z13 -> 0 | N10: ='RESUMEN TOTAL'!AB13 -> 0 | O10: ='RESUMEN TOTAL'!AD13 -> 0 | P10: ='RESUMEN TOTAL'!AF13 -> 0 | Q10: ='RESUMEN TOTAL'!AH13 -> 0 | R10: ='RESUMEN TOTAL'!AJ13 -> 0 | S10: ='RESUMEN TOTAL'!AL13 -> 0 | T10: ='RESUMEN TOTAL'!AN13 -> 0 | U10: ='RESUMEN TOTAL'!AP13 -> 0 | V10: ='RESUMEN TOTAL'!AR13 -> 0 | W10: ='RESUMEN TOTAL'!AT13 -> 0 | X10: ='RESUMEN TOTAL'!AV13 -> 0 | Y10: ='RESUMEN TOTAL'!AX13 -> 0 | Z10: ='RESUMEN TOTAL'!AZ13 -> 0 | AA10: ='RESUMEN TOTAL'!BB13 -> 0 | AB10: ='RESUMEN TOTAL'!BD13 -> 0 | AC10: ='RESUMEN TOTAL'!BF13 -> 0 | AD10: ='RESUMEN TOTAL'!BH13 -> 0 | AE10: ='RESUMEN TOTAL'!BJ13 -> 0 | AF10: ='RESUMEN TOTAL'!BL13 -> 0 | AG10: ='RESUMEN TOTAL'!BN13 -> 0 | AH10: ='RESUMEN TOTAL'!BP13 -> 0
A11: ='RESUMEN TOTAL'!A14 -> ALTAMIRA | B11: ='RESUMEN TOTAL'!B14 -> ALT 10 | C11: ='RESUMEN TOTAL'!D14 -> Calchaqui y Francia | D11: ='RESUMEN TOTAL'!E14 -> Domo | E11: ='RESUMEN TOTAL'!F14 -> Radio | F11: ='RESUMEN TOTAL'!L14 -> 0 | G11: ='RESUMEN TOTAL'!N14 -> 0 | H11: ='RESUMEN TOTAL'!P14 -> 0 | I11: ='RESUMEN TOTAL'!R14 -> 0 | J11: ='RESUMEN TOTAL'!T14 -> 0 | K11: ='RESUMEN TOTAL'!V14 -> 0 | L11: ='RESUMEN TOTAL'!X14 -> 0 | M11: ='RESUMEN TOTAL'!Z14 -> 0 | N11: ='RESUMEN TOTAL'!AB14 -> 0 | O11: ='RESUMEN TOTAL'!AD14 -> 0 | P11: ='RESUMEN TOTAL'!AF14 -> 0 | Q11: ='RESUMEN TOTAL'!AH14 -> 0 | R11: ='RESUMEN TOTAL'!AJ14 -> 0 | S11: ='RESUMEN TOTAL'!AL14 -> 0 | T11: ='RESUMEN TOTAL'!AN14 -> 0 | U11: ='RESUMEN TOTAL'!AP14 -> 0 | V11: ='RESUMEN TOTAL'!AR14 -> 0 | W11: ='RESUMEN TOTAL'!AT14 -> 0 | X11: ='RESUMEN TOTAL'!AV14 -> 0 | Y11: ='RESUMEN TOTAL'!AX14 -> 0 | Z11: ='RESUMEN TOTAL'!AZ14 -> 0 | AA11: ='RESUMEN TOTAL'!BB14 -> 0 | AB11: ='RESUMEN TOTAL'!BD14 -> 0 | AC11: ='RESUMEN TOTAL'!BF14 -> 0 | AD11: ='RESUMEN TOTAL'!BH14 -> 0 | AE11: ='RESUMEN TOTAL'!BJ14 -> 0 | AF11: ='RESUMEN TOTAL'!BL14 -> 0 | AG11: ='RESUMEN TOTAL'!BN14 -> 0 | AH11: ='RESUMEN TOTAL'!BP14 -> 0
A12: ='RESUMEN TOTAL'!A15 -> AGUSTIN RAMIREZ | B12: ='RESUMEN TOTAL'!B15 -> ARA 01 | C12: ='RESUMEN TOTAL'!D15 -> Malambo y Tranquera | D12: ='RESUMEN TOTAL'!E15 -> Domo | E12: ='RESUMEN TOTAL'!F15 -> Fibra Optica | F12: ='RESUMEN TOTAL'!L15 -> APAGADO | G12: ='RESUMEN TOTAL'!N15 -> APAGADO | H12: ='RESUMEN TOTAL'!P15 -> APAGADO | I12: ='RESUMEN TOTAL'!R15 -> APAGADO | J12: ='RESUMEN TOTAL'!T15 -> 0 | K12: ='RESUMEN TOTAL'!V15 -> 0 | L12: ='RESUMEN TOTAL'!X15 -> 0 | M12: ='RESUMEN TOTAL'!Z15 -> 0 | N12: ='RESUMEN TOTAL'!AB15 -> 0 | O12: ='RESUMEN TOTAL'!AD15 -> 0 | P12: ='RESUMEN TOTAL'!AF15 -> 0 | Q12: ='RESUMEN TOTAL'!AH15 -> 0 | R12: ='RESUMEN TOTAL'!AJ15 -> 0 | S12: ='RESUMEN TOTAL'!AL15 -> 0 | T12: ='RESUMEN TOTAL'!AN15 -> 0 | U12: ='RESUMEN TOTAL'!AP15 -> 0 | V12: ='RESUMEN TOTAL'!AR15 -> 0 | W12: ='RESUMEN TOTAL'!AT15 -> 0 | X12: ='RESUMEN TOTAL'!AV15 -> 0 | Y12: ='RESUMEN TOTAL'!AX15 -> 0 | Z12: ='RESUMEN TOTAL'!AZ15 -> 0 | AA12: ='RESUMEN TOTAL'!BB15 -> 0 | AB12: ='RESUMEN TOTAL'!BD15 -> 0 | AC12: ='RESUMEN TOTAL'!BF15 -> 0 | AD12: ='RESUMEN TOTAL'!BH15 -> 0 | AE12: ='RESUMEN TOTAL'!BJ15 -> 0 | AF12: ='RESUMEN TOTAL'!BL15 -> 0 | AG12: ='RESUMEN TOTAL'!BN15 -> 0 | AH12: ='RESUMEN TOTAL'!BP15 -> 0
... A315: ='RESUMEN TOTAL'!A318 -> SAN JORGE | B315: ='RESUMEN TOTAL'!B318 -> SJO 03 | C315: ='RESUMEN TOTAL'!D318 -> 517 Y 580 | D315: ='RESUMEN TOTAL'!E318 -> DOMO | E315: ='RESUMEN TOTAL'!F318 -> Radio | F315: ='RESUMEN TOTAL'!L318 -> 0 | G315: ='RESUMEN TOTAL'!N318 -> 0 | H315: ='RESUMEN TOTAL'!P318 -> 0 | I315: ='RESUMEN TOTAL'!R318 -> 0 | J315: ='RESUMEN TOTAL'!T318 -> 0 | K315: ='RESUMEN TOTAL'!V318 -> 0 | L315: ='RESUMEN TOTAL'!X318 -> 0 | M315: ='RESUMEN TOTAL'!Z318 -> 0 | N315: ='RESUMEN TOTAL'!AB318 -> 0 | O315: ='RESUMEN TOTAL'!AD318 -> 0 | P315: ='RESUMEN TOTAL'!AF318 -> 0 | Q315: ='RESUMEN TOTAL'!AH318 -> 0 | R315: ='RESUMEN TOTAL'!AJ318 -> 0 | S315: ='RESUMEN TOTAL'!AL318 -> 0 | T315: ='RESUMEN TOTAL'!AN318 -> 0 | U315: ='RESUMEN TOTAL'!AP318 -> 0 | V315: ='RESUMEN TOTAL'!AR318 -> 0 | W315: ='RESUMEN TOTAL'!AT318 -> 0 | X315: ='RESUMEN TOTAL'!AV318 -> 0 | Y315: ='RESUMEN TOTAL'!AX318 -> 0 | Z315: ='RESUMEN TOTAL'!AZ318 -> 0 | AA315: ='RESUMEN TOTAL'!BB318 -> 0 | AB315: ='RESUMEN TOTAL'!BD318 -> 0 | AC315: ='RESUMEN TOTAL'!BF318 -> 0 | AD315: ='RESUMEN TOTAL'!BH318 -> 0 | AE315: ='RESUMEN TOTAL'!BJ318 -> 0 | AF315: ='RESUMEN TOTAL'!BL318 -> 0 | AG315: ='RESUMEN TOTAL'!BN318 -> 0 | AH315: ='RESUMEN TOTAL'!BP318 -> 0
A316: ='RESUMEN TOTAL'!A319 -> SAN JORGE | B316: ='RESUMEN TOTAL'!B319 -> SJO 04 | C316: ='RESUMEN TOTAL'!D319 -> 552 Y 519 | D316: ='RESUMEN TOTAL'!E319 -> DOMO | E316: ='RESUMEN TOTAL'!F319 -> Radio | F316: ='RESUMEN TOTAL'!L319 -> 0 | G316: ='RESUMEN TOTAL'!N319 -> 0 | H316: ='RESUMEN TOTAL'!R319 -> 0 | I316: ='RESUMEN TOTAL'!#REF! -> #REF! | J316: ='RESUMEN TOTAL'!T319 -> 0 | K316: ='RESUMEN TOTAL'!V319 -> 0 | L316: ='RESUMEN TOTAL'!X319 -> 0 | M316: ='RESUMEN TOTAL'!Z319 -> 0 | N316: ='RESUMEN TOTAL'!AB319 -> 0 | O316: ='RESUMEN TOTAL'!AD319 -> 0 | P316: ='RESUMEN TOTAL'!AF319 -> 0 | Q316: ='RESUMEN TOTAL'!AH319 -> 0 | R316: ='RESUMEN TOTAL'!AJ319 -> 0 | S316: ='RESUMEN TOTAL'!AL319 -> 0 | T316: ='RESUMEN TOTAL'!AN319 -> 0 | U316: ='RESUMEN TOTAL'!AP319 -> 0 | V316: ='RESUMEN TOTAL'!AR319 -> 0 | W316: ='RESUMEN TOTAL'!AT319 -> 0 | X316: ='RESUMEN TOTAL'!AV319 -> 0 | Y316: ='RESUMEN TOTAL'!AX319 -> 0 | Z316: ='RESUMEN TOTAL'!AZ319 -> 0 | AA316: ='RESUMEN TOTAL'!BB319 -> 0 | AB316: ='RESUMEN TOTAL'!BD319 -> 0 | AC316: ='RESUMEN TOTAL'!BF319 -> 0 | AD316: ='RESUMEN TOTAL'!BH319 -> 0 | AE316: ='RESUMEN TOTAL'!BJ319 -> 0 | AF316: ='RESUMEN TOTAL'!BL319 -> 0 | AG316: ='RESUMEN TOTAL'!BN319 -> 0 | AH316: ='RESUMEN TOTAL'!BP319 -> 0
A317: ='RESUMEN TOTAL'!A320 -> SAN JORGE | B317: ='RESUMEN TOTAL'!B320 -> SJO 09 (FIJA 1) | C317: ='RESUMEN TOTAL'!D320 -> 515 Y 566 | D317: ='RESUMEN TOTAL'!E320 -> Fija | E317: ='RESUMEN TOTAL'!F320 -> Radio | F317: ='RESUMEN TOTAL'!L320 -> 0 | G317: ='RESUMEN TOTAL'!N320 -> 0 | H317: ='RESUMEN TOTAL'!P320 -> 0 | I317: ='RESUMEN TOTAL'!R320 -> 0 | J317: ='RESUMEN TOTAL'!T320 -> 0 | K317: ='RESUMEN TOTAL'!V320 -> 0 | L317: ='RESUMEN TOTAL'!X320 -> 0 | M317: ='RESUMEN TOTAL'!Z320 -> 0 | N317: ='RESUMEN TOTAL'!AB320 -> 0 | O317: ='RESUMEN TOTAL'!AD320 -> 0 | P317: ='RESUMEN TOTAL'!AF320 -> 0 | Q317: ='RESUMEN TOTAL'!AH320 -> 0 | R317: ='RESUMEN TOTAL'!AJ320 -> 0 | S317: ='RESUMEN TOTAL'!AL320 -> 0 | T317: ='RESUMEN TOTAL'!AN320 -> 0 | U317: ='RESUMEN TOTAL'!AP320 -> 0 | V317: ='RESUMEN TOTAL'!AR320 -> 0 | W317: ='RESUMEN TOTAL'!AT320 -> 0 | X317: ='RESUMEN TOTAL'!AV320 -> 0 | Y317: ='RESUMEN TOTAL'!AX320 -> 0 | Z317: ='RESUMEN TOTAL'!AZ320 -> 0 | AA317: ='RESUMEN TOTAL'!BB320 -> 0 | AB317: ='RESUMEN TOTAL'!BD320 -> 0 | AC317: ='RESUMEN TOTAL'!BF320 -> 0 | AD317: ='RESUMEN TOTAL'!BH320 -> 0 | AE317: ='RESUMEN TOTAL'!BJ320 -> 0 | AF317: ='RESUMEN TOTAL'!BL320 -> 0 | AG317: ='RESUMEN TOTAL'!BN320 -> 0 | AH317: ='RESUMEN TOTAL'!BP320 -> 0
A318: ='RESUMEN TOTAL'!A321 -> SAN JORGE | B318: ='RESUMEN TOTAL'!B321 -> SJO 10 (FIJA 2) | C318: ='RESUMEN TOTAL'!D321 -> 515 Y 566 | D318: ='RESUMEN TOTAL'!E321 -> Fija | E318: ='RESUMEN TOTAL'!F321 -> Radio | F318: ='RESUMEN TOTAL'!L321 -> 0 | G318: ='RESUMEN TOTAL'!N321 -> 0 | H318: ='RESUMEN TOTAL'!P321 -> 0 | I318: ='RESUMEN TOTAL'!R321 -> 0 | J318: ='RESUMEN TOTAL'!T321 -> 0 | K318: ='RESUMEN TOTAL'!V321 -> 0 | L318: ='RESUMEN TOTAL'!X321 -> 0 | M318: ='RESUMEN TOTAL'!Z321 -> 0 | N318: ='RESUMEN TOTAL'!AB321 -> 0 | O318: ='RESUMEN TOTAL'!AD321 -> 0 | P318: ='RESUMEN TOTAL'!AF321 -> 0 | Q318: ='RESUMEN TOTAL'!AH321 -> 0 | R318: ='RESUMEN TOTAL'!AJ321 -> 0 | S318: ='RESUMEN TOTAL'!AL321 -> 0 | T318: ='RESUMEN TOTAL'!AN321 -> 0 | U318: ='RESUMEN TOTAL'!AP321 -> 0 | V318: ='RESUMEN TOTAL'!AR321 -> 0 | W318: ='RESUMEN TOTAL'!AT321 -> 0 | X318: ='RESUMEN TOTAL'!AV321 -> 0 | Y318: ='RESUMEN TOTAL'!AX321 -> 0 | Z318: ='RESUMEN TOTAL'!AZ321 -> 0 | AA318: ='RESUMEN TOTAL'!BB321 -> 0 | AB318: ='RESUMEN TOTAL'!BD321 -> 0 | AC318: ='RESUMEN TOTAL'!BF321 -> 0 | AD318: ='RESUMEN TOTAL'!BH321 -> 0 | AE318: ='RESUMEN TOTAL'!BJ321 -> 0 | AF318: ='RESUMEN TOTAL'!BL321 -> 0 | AG318: ='RESUMEN TOTAL'!BN321 -> 0 | AH318: ='RESUMEN TOTAL'!BP321 -> 0
A319: ='RESUMEN TOTAL'!A322 -> SAN JORGE | B319: ='RESUMEN TOTAL'!B322 -> SJO01 | C319: ='RESUMEN TOTAL'!D322 -> Calle 554 y 527 | D319: ='RESUMEN TOTAL'!E322 -> Domo | E319: ='RESUMEN TOTAL'!F322 -> Radio | F319: ='RESUMEN TOTAL'!L322 -> 0 | G319: ='RESUMEN TOTAL'!N322 -> 0 | H319: ='RESUMEN TOTAL'!P322 -> 0 | I319: ='RESUMEN TOTAL'!R322 -> 0 | J319: ='RESUMEN TOTAL'!T322 -> 0 | K319: ='RESUMEN TOTAL'!V322 -> 0 | L319: ='RESUMEN TOTAL'!X322 -> 0 | M319: ='RESUMEN TOTAL'!Z322 -> 0 | N319: ='RESUMEN TOTAL'!AB322 -> 0 | O319: ='RESUMEN TOTAL'!AD322 -> 0 | P319: ='RESUMEN TOTAL'!AF322 -> 0 | Q319: ='RESUMEN TOTAL'!AH322 -> 0 | R319: ='RESUMEN TOTAL'!AJ322 -> 0 | S319: ='RESUMEN TOTAL'!AL322 -> 0 | T319: ='RESUMEN TOTAL'!AN322 -> 0 | U319: ='RESUMEN TOTAL'!AP322 -> 0 | V319: ='RESUMEN TOTAL'!AR322 -> 0 | W319: ='RESUMEN TOTAL'!AT322 -> 0 | X319: ='RESUMEN TOTAL'!AV322 -> 0 | Y319: ='RESUMEN TOTAL'!AX322 -> 0 | Z319: ='RESUMEN TOTAL'!AZ322 -> 0 | AA319: ='RESUMEN TOTAL'!BB322 -> 0 | AB319: ='RESUMEN TOTAL'!BD322 -> 0 | AC319: ='RESUMEN TOTAL'!BF322 -> 0 | AD319: ='RESUMEN TOTAL'!BH322 -> 0 | AE319: ='RESUMEN TOTAL'!BJ322 -> 0 | AF319: ='RESUMEN TOTAL'!BL322 -> 0 | AG319: ='RESUMEN TOTAL'!BN322 -> 0 | AH319: ='RESUMEN TOTAL'!BP322 -> 0
A320: ='RESUMEN TOTAL'!A323 -> SAN JORGE | B320: ='RESUMEN TOTAL'!B323 -> SJO02 | C320: ='RESUMEN TOTAL'!D323 -> Calle 554 y 511 | D320: ='RESUMEN TOTAL'!E323 -> Domo | E320: ='RESUMEN TOTAL'!F323 -> Radio | F320: ='RESUMEN TOTAL'!L323 -> 0 | G320: ='RESUMEN TOTAL'!N323 -> 0 | H320: ='RESUMEN TOTAL'!R323 -> 0 | I320: ='RESUMEN TOTAL'!#REF! -> #REF! | J320: ='RESUMEN TOTAL'!T323 -> 0 | K320: ='RESUMEN TOTAL'!V323 -> 0 | L320: ='RESUMEN TOTAL'!X323 -> 0 | M320: ='RESUMEN TOTAL'!Z323 -> 0 | N320: ='RESUMEN TOTAL'!AB323 -> 0 | O320: ='RESUMEN TOTAL'!AD323 -> 0 | P320: ='RESUMEN TOTAL'!AF323 -> 0 | Q320: ='RESUMEN TOTAL'!AH323 -> 0 | R320: ='RESUMEN TOTAL'!AJ323 -> 0 | S320: ='RESUMEN TOTAL'!AL323 -> 0 | T320: ='RESUMEN TOTAL'!AN323 -> 0 | U320: ='RESUMEN TOTAL'!AP323 -> 0 | V320: ='RESUMEN TOTAL'!AR323 -> 0 | W320: ='RESUMEN TOTAL'!AT323 -> 0 | X320: ='RESUMEN TOTAL'!AV323 -> 0 | Y320: ='RESUMEN TOTAL'!AX323 -> 0 | Z320: ='RESUMEN TOTAL'!AZ323 -> 0 | AA320: ='RESUMEN TOTAL'!BB323 -> 0 | AB320: ='RESUMEN TOTAL'!BD323 -> 0 | AC320: ='RESUMEN TOTAL'!BF323 -> 0 | AD320: ='RESUMEN TOTAL'!BH323 -> 0 | AE320: ='RESUMEN TOTAL'!BJ323 -> 0 | AF320: ='RESUMEN TOTAL'!BL323 -> 0 | AG320: ='RESUMEN TOTAL'!BN323 -> 0 | AH320: ='RESUMEN TOTAL'!BP323 -> 0
A321: ='RESUMEN TOTAL'!A324 -> SAN JORGE | B321: ='RESUMEN TOTAL'!B324 -> SJO05 (fija 1) | C321: ='RESUMEN TOTAL'!D324 -> 511 Y 560 | D321: ='RESUMEN TOTAL'!E324 -> Fija | E321: ='RESUMEN TOTAL'!F324 -> Fibra Optica | F321: ='RESUMEN TOTAL'!L324 -> APAGADO | G321: ='RESUMEN TOTAL'!N324 -> APAGADO | H321: ='RESUMEN TOTAL'!R324 -> APAGADO | I321: ='RESUMEN TOTAL'!#REF! -> #REF! | J321: ='RESUMEN TOTAL'!T324 -> 0 | K321: ='RESUMEN TOTAL'!V324 -> 0 | L321: ='RESUMEN TOTAL'!X324 -> 0 | M321: ='RESUMEN TOTAL'!Z324 -> 0 | N321: ='RESUMEN TOTAL'!AB324 -> 0 | O321: ='RESUMEN TOTAL'!AD324 -> 0 | P321: ='RESUMEN TOTAL'!AF324 -> 0 | Q321: ='RESUMEN TOTAL'!AH324 -> 0 | R321: ='RESUMEN TOTAL'!AJ324 -> 0 | S321: ='RESUMEN TOTAL'!AL324 -> 0 | T321: ='RESUMEN TOTAL'!AN324 -> 0 | U321: ='RESUMEN TOTAL'!AP324 -> 0 | V321: ='RESUMEN TOTAL'!AR324 -> 0 | W321: ='RESUMEN TOTAL'!AT324 -> 0 | X321: ='RESUMEN TOTAL'!AV324 -> 0 | Y321: ='RESUMEN TOTAL'!AX324 -> 0 | Z321: ='RESUMEN TOTAL'!AZ324 -> 0 | AA321: ='RESUMEN TOTAL'!BB324 -> 0 | AB321: ='RESUMEN TOTAL'!BD324 -> 0 | AC321: ='RESUMEN TOTAL'!BF324 -> 0 | AD321: ='RESUMEN TOTAL'!BH324 -> 0 | AE321: ='RESUMEN TOTAL'!BJ324 -> 0 | AF321: ='RESUMEN TOTAL'!BL324 -> 0 | AG321: ='RESUMEN TOTAL'!BN324 -> 0 | AH321: ='RESUMEN TOTAL'!BP324 -> 0
A322: ='RESUMEN TOTAL'!A325 -> SAN JORGE | B322: ='RESUMEN TOTAL'!B325 -> SJO06 (fija 2) | C322: ='RESUMEN TOTAL'!D325 -> 511 Y 560 | D322: ='RESUMEN TOTAL'!E325 -> Fija | E322: ='RESUMEN TOTAL'!F325 -> Fibra Optica | F322: ='RESUMEN TOTAL'!L325 -> APAGADO | G322: ='RESUMEN TOTAL'!N325 -> APAGADO | H322: ='RESUMEN TOTAL'!R325 -> APAGADO | I322: ='RESUMEN TOTAL'!#REF! -> #REF! | J322: ='RESUMEN TOTAL'!T325 -> 0 | K322: ='RESUMEN TOTAL'!V325 -> 0 | L322: ='RESUMEN TOTAL'!X325 -> 0 | M322: ='RESUMEN TOTAL'!Z325 -> 0 | N322: ='RESUMEN TOTAL'!AB325 -> 0 | O322: ='RESUMEN TOTAL'!AD325 -> 0 | P322: ='RESUMEN TOTAL'!AF325 -> 0 | Q322: ='RESUMEN TOTAL'!AH325 -> 0 | R322: ='RESUMEN TOTAL'!AJ325 -> 0 | S322: ='RESUMEN TOTAL'!AL325 -> 0 | T322: ='RESUMEN TOTAL'!AN325 -> 0 | U322: ='RESUMEN TOTAL'!AP325 -> 0 | V322: ='RESUMEN TOTAL'!AR325 -> 0 | W322: ='RESUMEN TOTAL'!AT325 -> 0 | X322: ='RESUMEN TOTAL'!AV325 -> 0 | Y322: ='RESUMEN TOTAL'!AX325 -> 0 | Z322: ='RESUMEN TOTAL'!AZ325 -> 0 | AA322: ='RESUMEN TOTAL'!BB325 -> 0 | AB322: ='RESUMEN TOTAL'!BD325 -> 0 | AC322: ='RESUMEN TOTAL'!BF325 -> 0 | AD322: ='RESUMEN TOTAL'!BH325 -> 0 | AE322: ='RESUMEN TOTAL'!BJ325 -> 0 | AF322: ='RESUMEN TOTAL'!BL325 -> 0 | AG322: ='RESUMEN TOTAL'!BN325 -> 0 | AH322: ='RESUMEN TOTAL'!BP325 -> 0
A323: ='RESUMEN TOTAL'!A326 -> SAN JORGE | B323: ='RESUMEN TOTAL'!B326 -> SJO07 (fija 1) | C323: ='RESUMEN TOTAL'!D326 -> 503 Y 556 | D323: ='RESUMEN TOTAL'!E326 -> Fija | E323: ='RESUMEN TOTAL'!F326 -> Fibra Optica | F323: ='RESUMEN TOTAL'!L326 -> APAGADO | G323: ='RESUMEN TOTAL'!N326 -> APAGADO | H323: ='RESUMEN TOTAL'!R326 -> APAGADO | I323: ='RESUMEN TOTAL'!#REF! -> #REF! | J323: ='RESUMEN TOTAL'!T326 -> 0 | K323: ='RESUMEN TOTAL'!V326 -> 0 | L323: ='RESUMEN TOTAL'!X326 -> 0 | M323: ='RESUMEN TOTAL'!Z326 -> 0 | N323: ='RESUMEN TOTAL'!AB326 -> 0 | O323: ='RESUMEN TOTAL'!AD326 -> 0 | P323: ='RESUMEN TOTAL'!AF326 -> 0 | Q323: ='RESUMEN TOTAL'!AH326 -> 0 | R323: ='RESUMEN TOTAL'!AJ326 -> 0 | S323: ='RESUMEN TOTAL'!AL326 -> 0 | T323: ='RESUMEN TOTAL'!AN326 -> 0 | U323: ='RESUMEN TOTAL'!AP326 -> 0 | V323: ='RESUMEN TOTAL'!AR326 -> 0 | W323: ='RESUMEN TOTAL'!AT326 -> 0 | X323: ='RESUMEN TOTAL'!AV326 -> 0 | Y323: ='RESUMEN TOTAL'!AX326 -> 0 | Z323: ='RESUMEN TOTAL'!AZ326 -> 0 | AA323: ='RESUMEN TOTAL'!BB326 -> 0 | AB323: ='RESUMEN TOTAL'!BD326 -> 0 | AC323: ='RESUMEN TOTAL'!BF326 -> 0 | AD323: ='RESUMEN TOTAL'!BH326 -> 0 | AE323: ='RESUMEN TOTAL'!BJ326 -> 0 | AF323: ='RESUMEN TOTAL'!BL326 -> 0 | AG323: ='RESUMEN TOTAL'!BN326 -> 0 | AH323: ='RESUMEN TOTAL'!BP326 -> 0
A324: ='RESUMEN TOTAL'!A327 -> SAN JORGE | B324: ='RESUMEN TOTAL'!B327 -> SJO08 (fija 2) | C324: ='RESUMEN TOTAL'!D327 -> 503 Y 556 | D324: ='RESUMEN TOTAL'!E327 -> Fija | E324: ='RESUMEN TOTAL'!F327 -> Fibra Optica | F324: ='RESUMEN TOTAL'!L327 -> APAGADO | G324: ='RESUMEN TOTAL'!N327 -> APAGADO | H324: ='RESUMEN TOTAL'!R327 -> APAGADO | I324: ='RESUMEN TOTAL'!#REF! -> #REF! | J324: ='RESUMEN TOTAL'!T327 -> 0 | K324: ='RESUMEN TOTAL'!V327 -> 0 | L324: ='RESUMEN TOTAL'!X327 -> 0 | M324: ='RESUMEN TOTAL'!Z327 -> 0 | N324: ='RESUMEN TOTAL'!AB327 -> 0 | O324: ='RESUMEN TOTAL'!AD327 -> 0 | P324: ='RESUMEN TOTAL'!AF327 -> 0 | Q324: ='RESUMEN TOTAL'!AH327 -> 0 | R324: ='RESUMEN TOTAL'!AJ327 -> 0 | S324: ='RESUMEN TOTAL'!AL327 -> 0 | T324: ='RESUMEN TOTAL'!AN327 -> 0 | U324: ='RESUMEN TOTAL'!AP327 -> 0 | V324: ='RESUMEN TOTAL'!AR327 -> 0 | W324: ='RESUMEN TOTAL'!AT327 -> 0 | X324: ='RESUMEN TOTAL'!AV327 -> 0 | Y324: ='RESUMEN TOTAL'!AX327 -> 0 | Z324: ='RESUMEN TOTAL'!AZ327 -> 0 | AA324: ='RESUMEN TOTAL'!BB327 -> 0 | AB324: ='RESUMEN TOTAL'!BD327 -> 0 | AC324: ='RESUMEN TOTAL'!BF327 -> 0 | AD324: ='RESUMEN TOTAL'!BH327 -> 0 | AE324: ='RESUMEN TOTAL'!BJ327 -> 0 | AF324: ='RESUMEN TOTAL'!BL327 -> 0 | AG324: ='RESUMEN TOTAL'!BN327 -> 0 | AH324: ='RESUMEN TOTAL'!BP327 -> 0
A325: ='RESUMEN TOTAL'!A328 -> SANTO TOMAS | B325: ='RESUMEN TOTAL'!B328 -> SJU01 | C325: ='RESUMEN TOTAL'!D328 -> Ruta 36 y Pte.Peron | D325: ='RESUMEN TOTAL'!E328 -> Domo | E325: ='RESUMEN TOTAL'!F328 -> Radio | F325: ='RESUMEN TOTAL'!L328 -> 0 | G325: ='RESUMEN TOTAL'!N328 -> 0 | H325: ='RESUMEN TOTAL'!P328 -> 0 | I325: ='RESUMEN TOTAL'!R328 -> 0 | J325: ='RESUMEN TOTAL'!T328 -> 0 | K325: ='RESUMEN TOTAL'!V328 -> 0 | L325: ='RESUMEN TOTAL'!X328 -> 0 | M325: ='RESUMEN TOTAL'!Z328 -> 0 | N325: ='RESUMEN TOTAL'!AB328 -> 0 | O325: ='RESUMEN TOTAL'!AD328 -> 0 | P325: ='RESUMEN TOTAL'!AF328 -> 0 | Q325: ='RESUMEN TOTAL'!AH328 -> 0 | R325: ='RESUMEN TOTAL'!AJ328 -> 0 | S325: ='RESUMEN TOTAL'!AL328 -> 0 | T325: ='RESUMEN TOTAL'!AN328 -> 0 | U325: ='RESUMEN TOTAL'!AP328 -> 0 | V325: ='RESUMEN TOTAL'!AR328 -> 0 | W325: ='RESUMEN TOTAL'!AT328 -> 0 | X325: ='RESUMEN TOTAL'!AV328 -> 0 | Y325: ='RESUMEN TOTAL'!AX328 -> 0 | Z325: ='RESUMEN TOTAL'!AZ328 -> 0 | AA325: ='RESUMEN TOTAL'!BB328 -> 0 | AB325: ='RESUMEN TOTAL'!BD328 -> 0 | AC325: ='RESUMEN TOTAL'!BF328 -> 0 | AD325: ='RESUMEN TOTAL'!BH328 -> 0 | AE325: ='RESUMEN TOTAL'!BJ328 -> 0 | AF325: ='RESUMEN TOTAL'!BL328 -> 0 | AG325: ='RESUMEN TOTAL'!BN328 -> 0 | AH325: ='RESUMEN TOTAL'!BP328 -> 0
A326: ='RESUMEN TOTAL'!A329 -> VILLA GENERAL SAN MARTIN | B326: ='RESUMEN TOTAL'!B329 -> SMA01 | C326: ='RESUMEN TOTAL'!D329 -> Hudson y Montevideo | D326: ='RESUMEN TOTAL'!E329 -> DOMO | E326: ='RESUMEN TOTAL'!F329 -> Radio | F326: ='RESUMEN TOTAL'!L329 -> 0 | G326: ='RESUMEN TOTAL'!N329 -> 0 | H326: ='RESUMEN TOTAL'!P329 -> 0 | I326: ='RESUMEN TOTAL'!R329 -> 0 | J326: ='RESUMEN TOTAL'!T329 -> 0 | K326: ='RESUMEN TOTAL'!V329 -> 0 | L326: ='RESUMEN TOTAL'!X329 -> 0 | M326: ='RESUMEN TOTAL'!Z329 -> 0 | N326: ='RESUMEN TOTAL'!AB329 -> 0 | O326: ='RESUMEN TOTAL'!AD329 -> 0 | P326: ='RESUMEN TOTAL'!AF329 -> 0 | Q326: ='RESUMEN TOTAL'!AH329 -> 0 | R326: ='RESUMEN TOTAL'!AJ329 -> 0 | S326: ='RESUMEN TOTAL'!AL329 -> 0 | T326: ='RESUMEN TOTAL'!AN329 -> 0 | U326: ='RESUMEN TOTAL'!AP329 -> 0 | V326: ='RESUMEN TOTAL'!AR329 -> 0 | W326: ='RESUMEN TOTAL'!AT329 -> 0 | X326: ='RESUMEN TOTAL'!AV329 -> 0 | Y326: ='RESUMEN TOTAL'!AX329 -> 0 | Z326: ='RESUMEN TOTAL'!AZ329 -> 0 | AA326: ='RESUMEN TOTAL'!BB329 -> 0 | AB326: ='RESUMEN TOTAL'!BD329 -> 0 | AC326: ='RESUMEN TOTAL'!BF329 -> 0 | AD326: ='RESUMEN TOTAL'!BH329 -> 0 | AE326: ='RESUMEN TOTAL'!BJ329 -> 0 | AF326: ='RESUMEN TOTAL'!BL329 -> 0 | AG326: ='RESUMEN TOTAL'!BN329 -> 0 | AH326: ='RESUMEN TOTAL'!BP329 -> 0
A327: ='RESUMEN TOTAL'!A330 -> VILLA GENERAL SAN MARTIN | B327: ='RESUMEN TOTAL'!B330 -> SMA02 | C327: ='RESUMEN TOTAL'!D330 -> Hudson y San Nicolas | D327: ='RESUMEN TOTAL'!E330 -> Domo | E327: ='RESUMEN TOTAL'!F330 -> Radio | F327: ='RESUMEN TOTAL'!L330 -> APAGADO | G327: ='RESUMEN TOTAL'!N330 -> APAGADO | H327: ='RESUMEN TOTAL'!P330 -> APAGADO | I327: ='RESUMEN TOTAL'!R330 -> APAGADO | J327: ='RESUMEN TOTAL'!T330 -> 0 | K327: ='RESUMEN TOTAL'!V330 -> 0 | L327: ='RESUMEN TOTAL'!X330 -> 0 | M327: ='RESUMEN TOTAL'!Z330 -> 0 | N327: ='RESUMEN TOTAL'!AB330 -> 0 | O327: ='RESUMEN TOTAL'!AD330 -> 0 | P327: ='RESUMEN TOTAL'!AF330 -> 0 | Q327: ='RESUMEN TOTAL'!AH330 -> 0 | R327: ='RESUMEN TOTAL'!AJ330 -> 0 | S327: ='RESUMEN TOTAL'!AL330 -> 0 | T327: ='RESUMEN TOTAL'!AN330 -> 0 | U327: ='RESUMEN TOTAL'!AP330 -> 0 | V327: ='RESUMEN TOTAL'!AR330 -> 0 | W327: ='RESUMEN TOTAL'!AT330 -> 0 | X327: ='RESUMEN TOTAL'!AV330 -> 0 | Y327: ='RESUMEN TOTAL'!AX330 -> 0 | Z327: ='RESUMEN TOTAL'!AZ330 -> 0 | AA327: ='RESUMEN TOTAL'!BB330 -> 0 | AB327: ='RESUMEN TOTAL'!BD330 -> 0 | AC327: ='RESUMEN TOTAL'!BF330 -> 0 | AD327: ='RESUMEN TOTAL'!BH330 -> 0 | AE327: ='RESUMEN TOTAL'!BJ330 -> 0 | AF327: ='RESUMEN TOTAL'!BL330 -> 0 | AG327: ='RESUMEN TOTAL'!BN330 -> 0 | AH327: ='RESUMEN TOTAL'!BP330 -> 0
A328: ='RESUMEN TOTAL'!A331 -> VILLA GENERAL SAN MARTIN | B328: ='RESUMEN TOTAL'!B331 -> SMA 03 | C328: ='RESUMEN TOTAL'!D331 -> ROSARIO Y SAN NICOLAS | D328: ='RESUMEN TOTAL'!E331 -> Domo | E328: ='RESUMEN TOTAL'!F331 -> Radio | F328: ='RESUMEN TOTAL'!L331 -> 0 | G328: ='RESUMEN TOTAL'!N331 -> 0 | H328: ='RESUMEN TOTAL'!P331 -> 0 | I328: ='RESUMEN TOTAL'!R331 -> 0 | J328: ='RESUMEN TOTAL'!T331 -> 0 | K328: ='RESUMEN TOTAL'!V331 -> 0 | L328: ='RESUMEN TOTAL'!X331 -> 0 | M328: ='RESUMEN TOTAL'!Z331 -> 0 | N328: ='RESUMEN TOTAL'!AB331 -> 0 | O328: ='RESUMEN TOTAL'!AD331 -> 0 | P328: ='RESUMEN TOTAL'!AF331 -> 0 | Q328: ='RESUMEN TOTAL'!AH331 -> 0 | R328: ='RESUMEN TOTAL'!AJ331 -> 0 | S328: ='RESUMEN TOTAL'!AL331 -> 0 | T328: ='RESUMEN TOTAL'!AN331 -> 0 | U328: ='RESUMEN TOTAL'!AP331 -> 0 | V328: ='RESUMEN TOTAL'!AR331 -> 0 | W328: ='RESUMEN TOTAL'!AT331 -> 0 | X328: ='RESUMEN TOTAL'!AV331 -> 0 | Y328: ='RESUMEN TOTAL'!AX331 -> 0 | Z328: ='RESUMEN TOTAL'!AZ331 -> 0 | AA328: ='RESUMEN TOTAL'!BB331 -> 0 | AB328: ='RESUMEN TOTAL'!BD331 -> 0 | AC328: ='RESUMEN TOTAL'!BF331 -> 0 | AD328: ='RESUMEN TOTAL'!BH331 -> 0 | AE328: ='RESUMEN TOTAL'!BJ331 -> 0 | AF328: ='RESUMEN TOTAL'!BL331 -> 0 | AG328: ='RESUMEN TOTAL'!BN331 -> 0 | AH328: ='RESUMEN TOTAL'!BP331 -> 0
A329: ='RESUMEN TOTAL'!A332 -> VILLA GENERAL SAN MARTIN | B329: ='RESUMEN TOTAL'!B332 -> SMA 04 | C329: ='RESUMEN TOTAL'!D332 -> HUDSON Y MONTEVIDEO | D329: ='RESUMEN TOTAL'!E332 -> FIJA | E329: ='RESUMEN TOTAL'!F332 -> Radio | F329: ='RESUMEN TOTAL'!L332 -> 0 | G329: ='RESUMEN TOTAL'!N332 -> 0 | H329: ='RESUMEN TOTAL'!P332 -> 0 | I329: ='RESUMEN TOTAL'!R332 -> 0 | J329: ='RESUMEN TOTAL'!T332 -> 0 | K329: ='RESUMEN TOTAL'!V332 -> 0 | L329: ='RESUMEN TOTAL'!X332 -> 0 | M329: ='RESUMEN TOTAL'!Z332 -> 0 | N329: ='RESUMEN TOTAL'!AB332 -> 0 | O329: ='RESUMEN TOTAL'!AD332 -> 0 | P329: ='RESUMEN TOTAL'!AF332 -> 0 | Q329: ='RESUMEN TOTAL'!AH332 -> 0 | R329: ='RESUMEN TOTAL'!AJ332 -> 0 | S329: ='RESUMEN TOTAL'!AL332 -> 0 | T329: ='RESUMEN TOTAL'!AN332 -> 0 | U329: ='RESUMEN TOTAL'!AP332 -> 0 | V329: ='RESUMEN TOTAL'!AR332 -> 0 | W329: ='RESUMEN TOTAL'!AT332 -> 0 | X329: ='RESUMEN TOTAL'!AV332 -> 0 | Y329: ='RESUMEN TOTAL'!AX332 -> 0 | Z329: ='RESUMEN TOTAL'!AZ332 -> 0 | AA329: ='RESUMEN TOTAL'!BB332 -> 0 | AB329: ='RESUMEN TOTAL'!BD332 -> 0 | AC329: ='RESUMEN TOTAL'!BF332 -> 0 | AD329: ='RESUMEN TOTAL'!BH332 -> 0 | AE329: ='RESUMEN TOTAL'!BJ332 -> 0 | AF329: ='RESUMEN TOTAL'!BL332 -> 0 | AG329: ='RESUMEN TOTAL'!BN332 -> 0 | AH329: ='RESUMEN TOTAL'!BP332 -> 0
A330: ='RESUMEN TOTAL'!A333 -> VILLA GENERAL SAN MARTIN | B330: ='RESUMEN TOTAL'!B333 -> SMA05 | C330: ='RESUMEN TOTAL'!D333 -> MONTEVIDEO Y VILLEGAS | D330: ='RESUMEN TOTAL'!E333 -> DOMO | E330: ='RESUMEN TOTAL'!F333 -> PTO A FO | F330: ='RESUMEN TOTAL'!L333 -> 0 | G330: ='RESUMEN TOTAL'!N333 -> 0 | H330: ='RESUMEN TOTAL'!P333 -> 0 | I330: ='RESUMEN TOTAL'!R333 -> 0 | J330: ='RESUMEN TOTAL'!T333 -> 0 | K330: ='RESUMEN TOTAL'!V333 -> 0 | L330: ='RESUMEN TOTAL'!X333 -> 0 | M330: ='RESUMEN TOTAL'!Z333 -> 0 | N330: ='RESUMEN TOTAL'!AB333 -> 0 | O330: ='RESUMEN TOTAL'!AD333 -> 0 | P330: ='RESUMEN TOTAL'!AF333 -> 0 | Q330: ='RESUMEN TOTAL'!AH333 -> 0 | R330: ='RESUMEN TOTAL'!AJ333 -> 0 | S330: ='RESUMEN TOTAL'!AL333 -> 0 | T330: ='RESUMEN TOTAL'!AN333 -> 0 | U330: ='RESUMEN TOTAL'!AP333 -> 0 | V330: ='RESUMEN TOTAL'!AR333 -> 0 | W330: ='RESUMEN TOTAL'!AT333 -> 0 | X330: ='RESUMEN TOTAL'!AV333 -> 0 | Y330: ='RESUMEN TOTAL'!AX333 -> 0 | Z330: ='RESUMEN TOTAL'!AZ333 -> 0 | AA330: ='RESUMEN TOTAL'!BB333 -> 0 | AB330: ='RESUMEN TOTAL'!BD333 -> 0 | AC330: ='RESUMEN TOTAL'!BF333 -> 0 | AD330: ='RESUMEN TOTAL'!BH333 -> 0 | AE330: ='RESUMEN TOTAL'!BJ333 -> 0 | AF330: ='RESUMEN TOTAL'!BL333 -> 0 | AG330: ='RESUMEN TOTAL'!BN333 -> 0 | AH330: ='RESUMEN TOTAL'!BP333 -> 0
A331: ='RESUMEN TOTAL'!A334 -> VILLA GENERAL SAN MARTIN | B331: ='RESUMEN TOTAL'!B334 -> SMA 06 | C331: ='RESUMEN TOTAL'!D334 -> AV. HUDSON Y RIO IGUAZU | D331: ='RESUMEN TOTAL'!E334 -> DOMO | E331: ='RESUMEN TOTAL'!F334 -> Fibra Optica | F331: ='RESUMEN TOTAL'!L334 -> 0 | G331: ='RESUMEN TOTAL'!N334 -> 0 | H331: ='RESUMEN TOTAL'!P334 -> 0 | I331: ='RESUMEN TOTAL'!R334 -> 0 | J331: ='RESUMEN TOTAL'!T334 -> 0 | K331: ='RESUMEN TOTAL'!V334 -> 0 | L331: ='RESUMEN TOTAL'!X334 -> 0 | M331: ='RESUMEN TOTAL'!Z334 -> 0 | N331: ='RESUMEN TOTAL'!AB334 -> 0 | O331: ='RESUMEN TOTAL'!AD334 -> 0 | P331: ='RESUMEN TOTAL'!AF334 -> 0 | Q331: ='RESUMEN TOTAL'!AH334 -> 0 | R331: ='RESUMEN TOTAL'!AJ334 -> 0 | S331: ='RESUMEN TOTAL'!AL334 -> 0 | T331: ='RESUMEN TOTAL'!AN334 -> 0 | U331: ='RESUMEN TOTAL'!AP334 -> 0 | V331: ='RESUMEN TOTAL'!AR334 -> 0 | W331: ='RESUMEN TOTAL'!AT334 -> 0 | X331: ='RESUMEN TOTAL'!AV334 -> 0 | Y331: ='RESUMEN TOTAL'!AX334 -> 0 | Z331: ='RESUMEN TOTAL'!AZ334 -> 0 | AA331: ='RESUMEN TOTAL'!BB334 -> 0 | AB331: ='RESUMEN TOTAL'!BD334 -> 0 | AC331: ='RESUMEN TOTAL'!BF334 -> 0 | AD331: ='RESUMEN TOTAL'!BH334 -> 0 | AE331: ='RESUMEN TOTAL'!BJ334 -> 0 | AF331: ='RESUMEN TOTAL'!BL334 -> 0 | AG331: ='RESUMEN TOTAL'!BN334 -> 0 | AH331: ='RESUMEN TOTAL'!BP334 -> 0
A332: ='RESUMEN TOTAL'!A335 -> VILLA GENERAL SAN MARTIN | B332: ='RESUMEN TOTAL'!B335 -> SMA 07 | C332: ='RESUMEN TOTAL'!D335 -> AV. HUDSON Y RIO TURBIO | D332: ='RESUMEN TOTAL'!E335 -> DOMO | E332: ='RESUMEN TOTAL'!F335 -> Fibra Optica | F332: ='RESUMEN TOTAL'!L335 -> 0 | G332: ='RESUMEN TOTAL'!N335 -> 0 | H332: ='RESUMEN TOTAL'!P335 -> 0 | I332: ='RESUMEN TOTAL'!R335 -> 0 | J332: ='RESUMEN TOTAL'!T335 -> 0 | K332: ='RESUMEN TOTAL'!V335 -> 0 | L332: ='RESUMEN TOTAL'!X335 -> 0 | M332: ='RESUMEN TOTAL'!Z335 -> 0 | N332: ='RESUMEN TOTAL'!AB335 -> 0 | O332: ='RESUMEN TOTAL'!AD335 -> 0 | P332: ='RESUMEN TOTAL'!AF335 -> 0 | Q332: ='RESUMEN TOTAL'!AH335 -> 0 | R332: ='RESUMEN TOTAL'!AJ335 -> 0 | S332: ='RESUMEN TOTAL'!AL335 -> 0 | T332: ='RESUMEN TOTAL'!AN335 -> 0 | U332: ='RESUMEN TOTAL'!AP335 -> 0 | V332: ='RESUMEN TOTAL'!AR335 -> 0 | W332: ='RESUMEN TOTAL'!AT335 -> 0 | X332: ='RESUMEN TOTAL'!AV335 -> 0 | Y332: ='RESUMEN TOTAL'!AX335 -> 0 | Z332: ='RESUMEN TOTAL'!AZ335 -> 0 | AA332: ='RESUMEN TOTAL'!BB335 -> 0 | AB332: ='RESUMEN TOTAL'!BD335 -> 0 | AC332: ='RESUMEN TOTAL'!BF335 -> 0 | AD332: ='RESUMEN TOTAL'!BH335 -> 0 | AE332: ='RESUMEN TOTAL'!BJ335 -> 0 | AF332: ='RESUMEN TOTAL'!BL335 -> 0 | AG332: ='RESUMEN TOTAL'!BN335 -> 0 | AH332: ='RESUMEN TOTAL'!BP335 -> 0
A333: ='RESUMEN TOTAL'!A336 -> SAN MARTIN | B333: ='RESUMEN TOTAL'!B336 -> SMA 08 | C333: ='RESUMEN TOTAL'!D336 -> 12 De Octubre y H. Lagos | D333: ='RESUMEN TOTAL'!E336 -> fija | E333: ='RESUMEN TOTAL'!F336 -> Fibra Optica | F333: ='RESUMEN TOTAL'!L336 -> APAGADO | G333: ='RESUMEN TOTAL'!N336 -> APAGADO | H333: ='RESUMEN TOTAL'!R336 -> APAGADO | I333: ='RESUMEN TOTAL'!#REF! -> #REF! | J333: ='RESUMEN TOTAL'!T336 -> 0 | K333: ='RESUMEN TOTAL'!V336 -> 0 | L333: ='RESUMEN TOTAL'!X336 -> 0 | M333: ='RESUMEN TOTAL'!Z336 -> 0 | N333: ='RESUMEN TOTAL'!AB336 -> 0 | O333: ='RESUMEN TOTAL'!AD336 -> 0 | P333: ='RESUMEN TOTAL'!AF336 -> 0 | Q333: ='RESUMEN TOTAL'!AH336 -> 0 | R333: ='RESUMEN TOTAL'!AJ336 -> 0 | S333: ='RESUMEN TOTAL'!AL336 -> 0 | T333: ='RESUMEN TOTAL'!AN336 -> 0 | U333: ='RESUMEN TOTAL'!AP336 -> 0 | V333: ='RESUMEN TOTAL'!AR336 -> 0 | W333: ='RESUMEN TOTAL'!AT336 -> 0 | X333: ='RESUMEN TOTAL'!AV336 -> 0 | Y333: ='RESUMEN TOTAL'!AX336 -> 0 | Z333: ='RESUMEN TOTAL'!AZ336 -> 0 | AA333: ='RESUMEN TOTAL'!BB336 -> 0 | AB333: ='RESUMEN TOTAL'!BD336 -> 0 | AC333: ='RESUMEN TOTAL'!BF336 -> 0 | AD333: ='RESUMEN TOTAL'!BH336 -> 0 | AE333: ='RESUMEN TOTAL'!BJ336 -> 0 | AF333: ='RESUMEN TOTAL'!BL336 -> 0 | AG333: ='RESUMEN TOTAL'!BN336 -> 0 | AH333: ='RESUMEN TOTAL'!BP336 -> 0
A334: ='RESUMEN TOTAL'!A337 -> SAN MARTIN | B334: ='RESUMEN TOTAL'!B337 -> SMA 09 | C334: ='RESUMEN TOTAL'!D337 -> 12 De Octubre y H. Lagos | D334: ='RESUMEN TOTAL'!E337 -> fija | E334: ='RESUMEN TOTAL'!F337 -> Fibra Optica | F334: ='RESUMEN TOTAL'!L337 -> APAGADO | G334: ='RESUMEN TOTAL'!N337 -> APAGADO | H334: ='RESUMEN TOTAL'!R337 -> APAGADO | I334: ='RESUMEN TOTAL'!#REF! -> #REF! | J334: ='RESUMEN TOTAL'!T337 -> 0 | K334: ='RESUMEN TOTAL'!V337 -> 0 | L334: ='RESUMEN TOTAL'!X337 -> 0 | M334: ='RESUMEN TOTAL'!Z337 -> 0 | N334: ='RESUMEN TOTAL'!AB337 -> 0 | O334: ='RESUMEN TOTAL'!AD337 -> 0 | P334: ='RESUMEN TOTAL'!AF337 -> 0 | Q334: ='RESUMEN TOTAL'!AH337 -> 0 | R334: ='RESUMEN TOTAL'!AJ337 -> 0 | S334: ='RESUMEN TOTAL'!AL337 -> 0 | T334: ='RESUMEN TOTAL'!AN337 -> 0 | U334: ='RESUMEN TOTAL'!AP337 -> 0 | V334: ='RESUMEN TOTAL'!AR337 -> 0 | W334: ='RESUMEN TOTAL'!AT337 -> 0 | X334: ='RESUMEN TOTAL'!AV337 -> 0 | Y334: ='RESUMEN TOTAL'!AX337 -> 0 | Z334: ='RESUMEN TOTAL'!AZ337 -> 0 | AA334: ='RESUMEN TOTAL'!BB337 -> 0 | AB334: ='RESUMEN TOTAL'!BD337 -> 0 | AC334: ='RESUMEN TOTAL'!BF337 -> 0 | AD334: ='RESUMEN TOTAL'!BH337 -> 0 | AE334: ='RESUMEN TOTAL'!BJ337 -> 0 | AF334: ='RESUMEN TOTAL'!BL337 -> 0 | AG334: ='RESUMEN TOTAL'!BN337 -> 0 | AH334: ='RESUMEN TOTAL'!BP337 -> 0
A335: ='RESUMEN TOTAL'!A338 -> SAN NICOLAS | B335: ='RESUMEN TOTAL'!B338 -> SNI01 (fija 1) | C335: ='RESUMEN TOTAL'!D338 -> SARRATEA E/ EEUU DE A. Y AGRELO | D335: ='RESUMEN TOTAL'!E338 -> Fija | E335: ='RESUMEN TOTAL'!F338 -> Fibra Optica | F335: ='RESUMEN TOTAL'!L338 -> APAGADO | G335: ='RESUMEN TOTAL'!N338 -> APAGADO | H335: ='RESUMEN TOTAL'!P338 -> APAGADO | I335: ='RESUMEN TOTAL'!R338 -> APAGADO | J335: ='RESUMEN TOTAL'!T338 -> 0 | K335: ='RESUMEN TOTAL'!V338 -> 0 | L335: ='RESUMEN TOTAL'!X338 -> 0 | M335: ='RESUMEN TOTAL'!Z338 -> 0 | N335: ='RESUMEN TOTAL'!AB338 -> 0 | O335: ='RESUMEN TOTAL'!AD338 -> 0 | P335: ='RESUMEN TOTAL'!AF338 -> 0 | Q335: ='RESUMEN TOTAL'!AH338 -> 0 | R335: ='RESUMEN TOTAL'!AJ338 -> 0 | S335: ='RESUMEN TOTAL'!AL338 -> 0 | T335: ='RESUMEN TOTAL'!AN338 -> 0 | U335: ='RESUMEN TOTAL'!AP338 -> 0 | V335: ='RESUMEN TOTAL'!AR338 -> 0 | W335: ='RESUMEN TOTAL'!AT338 -> 0 | X335: ='RESUMEN TOTAL'!AV338 -> 0 | Y335: ='RESUMEN TOTAL'!AX338 -> 0 | Z335: ='RESUMEN TOTAL'!AZ338 -> 0 | AA335: ='RESUMEN TOTAL'!BB338 -> 0 | AB335: ='RESUMEN TOTAL'!BD338 -> 0 | AC335: ='RESUMEN TOTAL'!BF338 -> 0 | AD335: ='RESUMEN TOTAL'!BH338 -> 0 | AE335: ='RESUMEN TOTAL'!BJ338 -> 0 | AF335: ='RESUMEN TOTAL'!BL338 -> 0 | AG335: ='RESUMEN TOTAL'!BN338 -> 0 | AH335: ='RESUMEN TOTAL'!BP338 -> 0
A336: ='RESUMEN TOTAL'!A339 -> SAN NICOLAS | B336: ='RESUMEN TOTAL'!B339 -> SNI02 (fija 2) | C336: ='RESUMEN TOTAL'!D339 -> SARRATEA E/ EEUU DE A. Y AGRELO | D336: ='RESUMEN TOTAL'!E339 -> Fija | E336: ='RESUMEN TOTAL'!F339 -> Fibra Optica | F336: ='RESUMEN TOTAL'!L339 -> APAGADO | G336: ='RESUMEN TOTAL'!N339 -> APAGADO | H336: ='RESUMEN TOTAL'!P339 -> APAGADO | I336: ='RESUMEN TOTAL'!R339 -> APAGADO | J336: ='RESUMEN TOTAL'!T339 -> 0 | K336: ='RESUMEN TOTAL'!V339 -> 0 | L336: ='RESUMEN TOTAL'!X339 -> 0 | M336: ='RESUMEN TOTAL'!Z339 -> 0 | N336: ='RESUMEN TOTAL'!AB339 -> 0 | O336: ='RESUMEN TOTAL'!AD339 -> 0 | P336: ='RESUMEN TOTAL'!AF339 -> 0 | Q336: ='RESUMEN TOTAL'!AH339 -> 0 | R336: ='RESUMEN TOTAL'!AJ339 -> 0 | S336: ='RESUMEN TOTAL'!AL339 -> 0 | T336: ='RESUMEN TOTAL'!AN339 -> 0 | U336: ='RESUMEN TOTAL'!AP339 -> 0 | V336: ='RESUMEN TOTAL'!AR339 -> 0 | W336: ='RESUMEN TOTAL'!AT339 -> 0 | X336: ='RESUMEN TOTAL'!AV339 -> 0 | Y336: ='RESUMEN TOTAL'!AX339 -> 0 | Z336: ='RESUMEN TOTAL'!AZ339 -> 0 | AA336: ='RESUMEN TOTAL'!BB339 -> 0 | AB336: ='RESUMEN TOTAL'!BD339 -> 0 | AC336: ='RESUMEN TOTAL'!BF339 -> 0 | AD336: ='RESUMEN TOTAL'!BH339 -> 0 | AE336: ='RESUMEN TOTAL'!BJ339 -> 0 | AF336: ='RESUMEN TOTAL'!BL339 -> 0 | AG336: ='RESUMEN TOTAL'!BN339 -> 0 | AH336: ='RESUMEN TOTAL'!BP339 -> 0
A337: ='RESUMEN TOTAL'!A340 -> SAN NICOLAS | B337: ='RESUMEN TOTAL'!B340 -> SNI 03 (fija 1) | C337: ='RESUMEN TOTAL'!D340 -> SARRATEA Y LOS TREBOLES | D337: ='RESUMEN TOTAL'!E340 -> Fija | E337: ='RESUMEN TOTAL'!F340 -> Fibra Optica | F337: ='RESUMEN TOTAL'!L340 -> APAGADO | G337: ='RESUMEN TOTAL'!N340 -> APAGADO | H337: ='RESUMEN TOTAL'!P340 -> APAGADO | I337: ='RESUMEN TOTAL'!R340 -> APAGADO | J337: ='RESUMEN TOTAL'!T340 -> 0 | K337: ='RESUMEN TOTAL'!V340 -> 0 | L337: ='RESUMEN TOTAL'!X340 -> 0 | M337: ='RESUMEN TOTAL'!Z340 -> 0 | N337: ='RESUMEN TOTAL'!AB340 -> 0 | O337: ='RESUMEN TOTAL'!AD340 -> 0 | P337: ='RESUMEN TOTAL'!AF340 -> 0 | Q337: ='RESUMEN TOTAL'!AH340 -> 0 | R337: ='RESUMEN TOTAL'!AJ340 -> 0 | S337: ='RESUMEN TOTAL'!AL340 -> 0 | T337: ='RESUMEN TOTAL'!AN340 -> 0 | U337: ='RESUMEN TOTAL'!AP340 -> 0 | V337: ='RESUMEN TOTAL'!AR340 -> 0 | W337: ='RESUMEN TOTAL'!AT340 -> 0 | X337: ='RESUMEN TOTAL'!AV340 -> 0 | Y337: ='RESUMEN TOTAL'!AX340 -> 0 | Z337: ='RESUMEN TOTAL'!AZ340 -> 0 | AA337: ='RESUMEN TOTAL'!BB340 -> 0 | AB337: ='RESUMEN TOTAL'!BD340 -> 0 | AC337: ='RESUMEN TOTAL'!BF340 -> 0 | AD337: ='RESUMEN TOTAL'!BH340 -> 0 | AE337: ='RESUMEN TOTAL'!BJ340 -> 0 | AF337: ='RESUMEN TOTAL'!BL340 -> 0 | AG337: ='RESUMEN TOTAL'!BN340 -> 0 | AH337: ='RESUMEN TOTAL'!BP340 -> 0
A338: ='RESUMEN TOTAL'!A341 -> SAN NICOLAS | B338: ='RESUMEN TOTAL'!B341 -> SNI 04 (fija 2) | C338: ='RESUMEN TOTAL'!D341 -> SARRATEA Y LOS TREBOLES | D338: ='RESUMEN TOTAL'!E341 -> Fija | E338: ='RESUMEN TOTAL'!F341 -> Fibra Optica | F338: ='RESUMEN TOTAL'!L341 -> APAGADO | G338: ='RESUMEN TOTAL'!N341 -> APAGADO | H338: ='RESUMEN TOTAL'!P341 -> APAGADO | I338: ='RESUMEN TOTAL'!R341 -> APAGADO | J338: ='RESUMEN TOTAL'!T341 -> 0 | K338: ='RESUMEN TOTAL'!V341 -> 0 | L338: ='RESUMEN TOTAL'!X341 -> 0 | M338: ='RESUMEN TOTAL'!Z341 -> 0 | N338: ='RESUMEN TOTAL'!AB341 -> 0 | O338: ='RESUMEN TOTAL'!AD341 -> 0 | P338: ='RESUMEN TOTAL'!AF341 -> 0 | Q338: ='RESUMEN TOTAL'!AH341 -> 0 | R338: ='RESUMEN TOTAL'!AJ341 -> 0 | S338: ='RESUMEN TOTAL'!AL341 -> 0 | T338: ='RESUMEN TOTAL'!AN341 -> 0 | U338: ='RESUMEN TOTAL'!AP341 -> 0 | V338: ='RESUMEN TOTAL'!AR341 -> 0 | W338: ='RESUMEN TOTAL'!AT341 -> 0 | X338: ='RESUMEN TOTAL'!AV341 -> 0 | Y338: ='RESUMEN TOTAL'!AX341 -> 0 | Z338: ='RESUMEN TOTAL'!AZ341 -> 0 | AA338: ='RESUMEN TOTAL'!BB341 -> 0 | AB338: ='RESUMEN TOTAL'!BD341 -> 0 | AC338: ='RESUMEN TOTAL'!BF341 -> 0 | AD338: ='RESUMEN TOTAL'!BH341 -> 0 | AE338: ='RESUMEN TOTAL'!BJ341 -> 0 | AF338: ='RESUMEN TOTAL'!BL341 -> 0 | AG338: ='RESUMEN TOTAL'!BN341 -> 0 | AH338: ='RESUMEN TOTAL'!BP341 -> 0
A339: ='RESUMEN TOTAL'!A342 -> SANTA ROSA | B339: ='RESUMEN TOTAL'!B342 -> SRO01 | C339: ='RESUMEN TOTAL'!D342 -> Yugoslavia y MilÃ¡n | D339: ='RESUMEN TOTAL'!E342 -> Domo | E339: ='RESUMEN TOTAL'!F342 -> Radio | F339: ='RESUMEN TOTAL'!L342 -> APAGADO | G339: ='RESUMEN TOTAL'!N342 -> APAGADO | H339: ='RESUMEN TOTAL'!P342 -> APAGADO | I339: ='RESUMEN TOTAL'!R342 -> APAGADO | J339: ='RESUMEN TOTAL'!T342 -> 0 | K339: ='RESUMEN TOTAL'!V342 -> 0 | L339: ='RESUMEN TOTAL'!X342 -> 0 | M339: ='RESUMEN TOTAL'!Z342 -> 0 | N339: ='RESUMEN TOTAL'!AB342 -> 0 | O339: ='RESUMEN TOTAL'!AD342 -> 0 | P339: ='RESUMEN TOTAL'!AF342 -> 0 | Q339: ='RESUMEN TOTAL'!AH342 -> 0 | R339: ='RESUMEN TOTAL'!AJ342 -> 0 | S339: ='RESUMEN TOTAL'!AL342 -> 0 | T339: ='RESUMEN TOTAL'!AN342 -> 0 | U339: ='RESUMEN TOTAL'!AP342 -> 0 | V339: ='RESUMEN TOTAL'!AR342 -> 0 | W339: ='RESUMEN TOTAL'!AT342 -> 0 | X339: ='RESUMEN TOTAL'!AV342 -> 0 | Y339: ='RESUMEN TOTAL'!AX342 -> 0 | Z339: ='RESUMEN TOTAL'!AZ342 -> 0 | AA339: ='RESUMEN TOTAL'!BB342 -> 0 | AB339: ='RESUMEN TOTAL'!BD342 -> 0 | AC339: ='RESUMEN TOTAL'!BF342 -> 0 | AD339: ='RESUMEN TOTAL'!BH342 -> 0 | AE339: ='RESUMEN TOTAL'!BJ342 -> 0 | AF339: ='RESUMEN TOTAL'!BL342 -> 0 | AG339: ='RESUMEN TOTAL'!BN342 -> 0 | AH339: ='RESUMEN TOTAL'!BP342 -> 0
A340: ='RESUMEN TOTAL'!A343 -> ZONA RURAL SANTA ROSA | B340: ='RESUMEN TOTAL'!B343 -> SRO02 | C340: ='RESUMEN TOTAL'!D343 -> Bruselas y Calle 647 | D340: ='RESUMEN TOTAL'!E343 -> Domo | E340: ='RESUMEN TOTAL'!F343 -> Radio | F340: ='RESUMEN TOTAL'!L343 -> APAGADO | G340: ='RESUMEN TOTAL'!N343 -> APAGADO | H340: ='RESUMEN TOTAL'!P343 -> APAGADO | I340: ='RESUMEN TOTAL'!R343 -> APAGADO | J340: ='RESUMEN TOTAL'!T343 -> 0 | K340: ='RESUMEN TOTAL'!V343 -> 0 | L340: ='RESUMEN TOTAL'!X343 -> 0 | M340: ='RESUMEN TOTAL'!Z343 -> 0 | N340: ='RESUMEN TOTAL'!AB343 -> 0 | O340: ='RESUMEN TOTAL'!AD343 -> 0 | P340: ='RESUMEN TOTAL'!AF343 -> 0 | Q340: ='RESUMEN TOTAL'!AH343 -> 0 | R340: ='RESUMEN TOTAL'!AJ343 -> 0 | S340: ='RESUMEN TOTAL'!AL343 -> 0 | T340: ='RESUMEN TOTAL'!AN343 -> 0 | U340: ='RESUMEN TOTAL'!AP343 -> 0 | V340: ='RESUMEN TOTAL'!AR343 -> 0 | W340: ='RESUMEN TOTAL'!AT343 -> 0 | X340: ='RESUMEN TOTAL'!AV343 -> 0 | Y340: ='RESUMEN TOTAL'!AX343 -> 0 | Z340: ='RESUMEN TOTAL'!AZ343 -> 0 | AA340: ='RESUMEN TOTAL'!BB343 -> 0 | AB340: ='RESUMEN TOTAL'!BD343 -> 0 | AC340: ='RESUMEN TOTAL'!BF343 -> 0 | AD340: ='RESUMEN TOTAL'!BH343 -> 0 | AE340: ='RESUMEN TOTAL'!BJ343 -> 0 | AF340: ='RESUMEN TOTAL'!BL343 -> 0 | AG340: ='RESUMEN TOTAL'!BN343 -> 0 | AH340: ='RESUMEN TOTAL'!BP343 -> 0
