Workbook
Name _25_de_agosto: 'RESUMEN TOTAL'!$A$4:$D$376
Name _25_de_agosto_3: 'RESUMEN TOTAL'!$A$4:$D$388
Name BONOMOcam: Hoja1!$B$2
Name CANTIDAD_DE_CAMARAS: 'RESUMEN TOTAL'!$B$1
Name COSEIDIcam: Hoja1!$B$4

Sheet RESUMEN TOTAL
A1: CANTIDAD DE CAMARAS | B1: =COUNTA(B5:B543) -> 445 | D1: PORCIENTO DE CAIDAS | L1: =(L3)/(L2+L3) -> 0.1258427 | M1: =(M3)/(M2+M3) -> 0.098876404 | N1: =(N3)/(N2+N3) -> 0.12359551 | O1: =(O3)/(O2+O3) -> 0.10337079 | P1: =(P3)/(P2+P3) -> 0.1011236 | Q1: =(Q3)/(Q2+Q3) -> 0 | R1: =(R3)/(R2+R3) -> 0 | S1: =(S3)/(S2+S3) -> 0 | ... AO1: =(AO3)/(AO2+AO3) -> 0
D2: FUNCIONAN | L2: =B1-L3 -> 389 | M2: =CANTIDAD_DE_CAMARAS-M3 -> 401 | N2: =CANTIDAD_DE_CAMARAS-N3 -> 390 | O2: =CANTIDAD_DE_CAMARAS-O3 -> 399 | P2: =CANTIDAD_DE_CAMARAS-P3 -> 400 | Q2: =CANTIDAD_DE_CAMARAS-Q3 -> 445 | R2: =CANTIDAD_DE_CAMARAS-R3 -> 445 | S2: =CANTIDAD_DE_CAMARAS-S3 -> 445 | T2: =CANTIDAD_DE_CAMARAS-T3 -> 445 | ... AO2: =CANTIDAD_DE_CAMARAS-AO3 -> 445
D3: CAIDAS | L3: =COUNTIF(L4:L463, "apagado") -> 56 | M3: =COUNTIF(M4:M463, "apagado") -> 44 | N3: =COUNTIF(N4:N463, "apagado") -> 55 | O3: =COUNTIF(O4:O463, "apagado") -> 46 | P3: =COUNTIF(P4:P463, "apagado") -> 45 | Q3: =COUNTIF(Q4:Q463, "apagado") -> 0 | R3: =COUNTIF(R4:R463, "apagado") -> 0 | S3: =COUNTIF(S4:S463, "apagado") -> 0 | ... AO3: =COUNTIF(AO4:AO463, "apagado") -> 0
A4: Barrio | B4: [Denominacion] | C4: [Empresa Mantenimiento] | D4: [Ubicacion] | E4: [Tipo de Camara] | F4: [Tipo de Conexion] | G4: Destino | I4: DIAS FUNCIONANDO | J4: DIAS CAIDA | K4: EFECTIVIDAD | L4: 45078 | M4: 45079 | N4: 45080 | O4: 45081 | P4: 45082 | Q4: 45083 | R4: 45084 | S4: 45085 | T4: 45086 | U4: 45087 | V4: 45088 | W4: 45089 | X4: 45090 | Y4: 45091 | Z4: 45092 | AA4: 45093 | AB4: 45094 | AC4: 45095 | AD4: 45096 | AE4: 45097 | AF4: 45098 | AG4: 45099 | AH4: 45100 | AI4: 45101 | AJ4: 45102 | AK4: 45103 | AL4: 45104 | AM4: 45105 | AN4: 45106 | AO4: 45107
A5: ALTAMIRA | B5: ALT01 | C5: BONOMO | D5: Calchaqui y Sgto. Cabral | E5: Domo | F5: Fibra Optica | H5: 172.20.10.6 | I5: =COUNTIF(L5:AM5,"") -> 28 | J5: =COUNTIF(L5:AM5,"APAGADO") -> 0 | K5: =(I5)/(J5+I5) -> 1
A6: ALTAMIRA | B6: ALT02 | C6: BONOMO | D6: Calchaqui y Lope de Vega | E6: Domo | F6: PTO A FO | H6: 172.20.12.218 | I6: =COUNTIF(L6:AM6,"") -> 28 | J6: =COUNTIF(L6:AM6,"APAGADO") -> 0 | K6: =(I6)/(J6+I6) -> 1
A7: ALTAMIRA | B7: ALT 03 | C7: BONOMO | D7: Bombero Galarza y Necochea | E7: Domo | F7: FIBRA OPTICA | H7: 172.20.12.54 | I7: =COUNTIF(L7:AM7,"") -> 28 | J7: =COUNTIF(L7:AM7,"APAGADO") -> 0 | K7: =(I7)/(J7+I7) -> 1
A8: ALTAMIRA | B8: ALT 04 | C8: BONOMO | D8: Francia y Necochea | E8: Domo | F8: FIBRA OPTICA | H8: 172.20.12.55 | I8: =COUNTIF(L8:AM8,"") -> 28 | J8: =COUNTIF(L8:AM8,"APAGADO") -> 0 | K8: =(I8)/(J8+I8) -> 1
A9: ALTAMIRA | B9: ALT05 | C9: BONOMO | D9: Av. Calchaqui y Bombero Galarza | E9: Domo | F9: PTO A FO | H9: 172.20.12.216 | I9: =COUNTIF(L9:AM9,"") -> 28 | J9: =COUNTIF(L9:AM9,"APAGADO") -> 0 | K9: =(I9)/(J9+I9) -> 1
A10: ALTAMIRA | B10: ALT 06 | C10: BONOMO | D10: LOPE DE VEGA Y NECOCHEA | E10: Domo | F10: PTO A FO | H10: 172.20.12.12 | I10: =COUNTIF(L10:AM10,"") -> 28 | J10: =COUNTIF(L10:AM10,"APAGADO") -> 0 | K10: =(I10)/(J10+I10) -> 1
A11: ALTAMIRA | B11: ALT07 | C11: BONOMO | D11: AV. CALCHAQUI Y AV. DEL TRABAJO | E11: DOMO | F11: PTO A FO | H11: 172.20.10.57 | I11: =COUNTIF(L11:AM11,"") -> 28 | J11: =COUNTIF(L11:AM11,"APAGADO") -> 0 | K11: =(I11)/(J11+I11) -> 1
A12: ALTAMIRA | B12: ALT 08 | C12: BONOMO | D12: HUMAITA Y NECOCHEA | E12: DOMO | F12: Fibra Optica | H12: 172.20.11.215 | I12: =COUNTIF(L12:AM12,"") -> 28 | J12: =COUNTIF(L12:AM12,"APAGADO") -> 0 | K12: =(I12)/(J12+I12) -> 1
A13: ALTAMIRA | B13: ALT 09 | C13: BONOMO | D13: NECOCHEA Y CURUPAITY | E13: DOMO | F13: Fibra Optica | H13: 172.20.11.216 | I13: =COUNTIF(L13:AM13,"") -> 28 | J13: =COUNTIF(L13:AM13,"APAGADO") -> 0 | K13: =(I13)/(J13+I13) -> 1
A14: ALTAMIRA | B14: ALT 10 | C14: BONOMO | D14: Calchaqui y Francia | E14: Domo | F14: Radio | H14: 172.20.12.156 | I14: =COUNTIF(L14:AM14,"") -> 28 | J14: =COUNTIF(L14:AM14,"APAGADO") -> 0 | K14: =(I14)/(J14+I14) -> 1
A15: AGUSTIN RAMIREZ | B15: ARA 01 | C15: COSEIDI | D15: Malambo y Tranquera | E15: Domo | F15: FIBRA OPTICA | H15: 172.20.12.110 | I15: =COUNTIF(L15:AM15,"") -> 28 | J15: =COUNTIF(L15:AM15,"APAGADO") -> 0 | K15: =(I15)/(J15+I15) -> 1
A16: BELGRANO | B16: BEL 01 | C16: BONOMO | D16: San Martin y Dardo Rocha | E16: DOMO | F16: FIBRA OPTICA | H16: 172.20.12.64 | I16: =COUNTIF(L16:AM16,"") -> 28 | J16: =COUNTIF(L16:AM16,"APAGADO") -> 0 | K16: =(I16)/(J16+I16) -> 1
... A86: CENTRO | B86: CEN64 | C86: BONOMO | D86: SAN MARTIN Y BOCCUZZI | E86: FIJA | F86: Fibra Optica | H86: 172.20.11.134 | I86: =COUNTIF(L86:AM86,"") -> 28 | J86: =COUNTIF(L86:AM86,"APAGADO") -> 0 | K86: =(I86)/(J86+I86) -> 1
A87: º | B87: CEN 65 | C87: BONOMO | D87: SAN MARTIN Y JUAN PERON | E87: FIJA | F87: Fibra Optica | H87: 172.20.11.135 | I87: =COUNTIF(L87:AM87,"") -> 26 | J87: =COUNTIF(L87:AM87,"APAGADO") -> 2 | K87: =(I87)/(J87+I87) -> 0.92857143 | L87: APAGADO | N87: APAGADO
A88: CENTRO | B88: CEN66 | C88: BONOMO | D88: SAN MARTIN Y JUAN PERON | E88: FIJA | F88: Fibra Optica | H88: 172.20.11.136 | I88: =COUNTIF(L88:AM88,"") -> 26 | J88: =COUNTIF(L88:AM88,"APAGADO") -> 2 | K88: =(I88)/(J88+I88) -> 0.92857143 | L88: APAGADO | N88: APAGADO
A89: CENTRO | B89: CEN67 (fija 1) | C89: BONOMO | D89: 9 DE JULIO Y BROWN | E89: Fija | F89: Fibra Optica | H89: 172.20.11.188 | I89: =COUNTIF(L89:AM89,"") -> 28 | J89: =COUNTIF(L89:AM89,"APAGADO") -> 0 | K89: =(I89)/(J89+I89) -> 1
A90: CENTRO | B90: CEN68 (fija 2) | C90: BONOMO | D90: 9 DE JULIO Y BROWN | E90: Fija | F90: Fibra Optica | H90: 172.20.11.189 | I90: =COUNTIF(L90:AM90,"") -> 28 | J90: =COUNTIF(L90:AM90,"APAGADO") -> 0 | K90: =(I90)/(J90+I90) -> 1
A91: CENTRO | B91: CEN69 | C91: BONOMO | D91: RIVADAVIA Y BOUREL | E91: DOMO | F91: Fibra Optica | H91: 172.20.11.222 | I91: =COUNTIF(L91:AM91,"") -> 28 | J91: =COUNTIF(L91:AM91,"APAGADO") -> 0 | K91: =(I91)/(J91+I91) -> 1
A92: CENTRO | B92: CEN 70 | C92: BONOMO | D92: RIVADAVIA Y 25 MAYO | E92: Domo | F92: Fibra Optica | H92: 172.20.11.221 | I92: =COUNTIF(L92:AM92,"") -> 28 | J92: =COUNTIF(L92:AM92,"APAGADO") -> 0 | K92: =(I92)/(J92+I92) -> 1
A93: CENTRO | B93: CEN 71 | C93: BONOMO | D93: MORENO Y BOUREL | E93: Domo | F93: Fibra Optica | H93: 172.20.11.220 | I93: =COUNTIF(L93:AM93,"") -> 28 | J93: =COUNTIF(L93:AM93,"APAGADO") -> 0 | K93: =(I93)/(J93+I93) -> 1
A94: CENTRO | B94: CEN 72 | C94: BONOMO | D94: MORENO Y 25 DE MAYO | E94: Domo | F94: Fibra Optica | H94: 172.20.11.219 | I94: =COUNTIF(L94:AM94,"") -> 23 | J94: =COUNTIF(L94:AM94,"APAGADO") -> 5 | K94: =(I94)/(J94+I94) -> 0.82142857 | L94: APAGADO | M94: APAGADO | N94: APAGADO | O94: APAGADO | P94: APAGADO
A95: CENTRO | B95: CEN73 | C95: BONOMO | D95: BOUREL Y DEFENSA | E95: DOMO | F95: Fibra Optica | H95: 172.20.11.223 | I95: =COUNTIF(L95:AM95,"") -> 28 | J95: =COUNTIF(L95:AM95,"APAGADO") -> 0 | K95: =(I95)/(J95+I95) -> 1
A96: CENTRO | B96: CEN74 | C96: BONOMO | D96: Las Heras y Maipu | E96: Domo | F96: FIBRA OPTICA | H96: 172.20.11.53 | I96: =COUNTIF(L96:AM96,"") -> 28 | J96: =COUNTIF(L96:AM96,"APAGADO") -> 0 | K96: =(I96)/(J96+I96) -> 1
A97: CENTRO | B97: CEN 75 | C97: BONOMO | D97: 25 DE MAYO Y CASTELLI | E97: Domo | F97: Fibra Optica | H97: 172.20.11.114 | I97: =COUNTIF(L97:AM97,"") -> 28 | J97: =COUNTIF(L97:AM97,"APAGADO") -> 0 | K97: =(I97)/(J97+I97) -> 1
A98: CENTRO | B98: CEN 76 | C98: BONOMO | D98: ESPAÑA E/MITRE Y BOCUZZI | E98: Fija | F98: Fibra Optica | H98: 172-20.11.110 | I98: =COUNTIF(L98:AM98,"") -> 28 | J98: =COUNTIF(L98:AM98,"APAGADO") -> 0 | K98: =(I98)/(J98+I98) -> 1
A99: CENTRO | B99: CEN 77 | C99: BONOMO | D99: Monteagudo e/ Mitre y Boccuzzi | E99: Fija | F99: Fibra Optica | H99: 172.20.11.241 | I99: =COUNTIF(L99:AM99,"") -> 28 | J99: =COUNTIF(L99:AM99,"APAGADO") -> 0 | K99: =(I99)/(J99+I99) -> 1
A100: CENTRO | B100: CEN 78 | C100: BONOMO | D100: Mitre e/Monteagudo y Alberdi | E100: Fija | F100: Fibra Optica | H100: 172.20.11.240 | I100: =COUNTIF(L100:AM100,"") -> 28 | J100: =COUNTIF(L100:AM100,"APAGADO") -> 0 | K100: =(I100)/(J100+I100) -> 1
A101: CENTRO | B101: CEN 79 | C101: BONOMO | D101: Diag. Constituyente y Brown | E101: Fija | F101: Fibra Optica | H101: 172.20.11.243 | I101: =COUNTIF(L101:AM101,"") -> 28 | J101: =COUNTIF(L101:AM101,"APAGADO") -> 0 | K101: =(I101)/(J101+I101) -> 1
A102: CENTRO | B102: CEN 80 | C102: BONOMO | D102: Diag. Constituyente y Brown | E102: Fija | F102: Fibra Optica | H102: 172.20.11.244 | I102: =COUNTIF(L102:AM102,"") -> 28 | J102: =COUNTIF(L102:AM102,"APAGADO") -> 0 | K102: =(I102)/(J102+I102) -> 1
A103: CENTRO | B103: CEN 81 | C103: BONOMO | D103: Alberdi y A.del Valle | E103: Fija | F103: Fibra Optica | H103: 172.20.11.242 | I103: =COUNTIF(L103:AM103,"") -> 28 | J103: =COUNTIF(L103:AM103,"APAGADO") -> 0 | K103: =(I103)/(J103+I103) -> 1
A104: CENTRO | B104: CEN 82 | C104: BONOMO | D104: DORREGO Y BOUREL | E104: Domo | F104: Fibra Optica | H104: 172.20.11.198 | I104: =COUNTIF(L104:AM104,"") -> 28 | J104: =COUNTIF(L104:AM104,"APAGADO") -> 0 | K104: =(I104)/(J104+I104) -> 1
A105: CENTRO | B105: CEN83 | C105: BONOMO | D105: RECONQUISTA Y 25 DE MAYO | E105: Domo | F105: Radio | H105: 172.20.11.123 | I105: =COUNTIF(L105:AM105,"") -> 28 | J105: =COUNTIF(L105:AM105,"APAGADO") -> 0 | K105: =(I105)/(J105+I105) -> 1
A106: CENTRO | B106: CEN 84 | C106: BONOMO | D106: 25 DE MAYO Y MAIPU | E106: Fija | F106: Fibra Optica | I106: =COUNTIF(L106:AM106,"") -> 28 | J106: =COUNTIF(L106:AM106,"APAGADO") -> 0 | K106: =(I106)/(J106+I106) -> 1
A107: CENTRO | B107: CEN 85 | C107: BONOMO | D107: PTE PERON E/ PRINGLES Y BROWN | E107: Fija | F107: Fibra Optica | H107: 172.20.10.21 | I107: =COUNTIF(L107:AM107,"") -> 28 | J107: =COUNTIF(L107:AM107,"APAGADO") -> 0 | K107: =(I107)/(J107+I107) -> 1
A108: SAN NICOLAS | B108: CHA01 | C108: BONOMO | D108: Novak y Pte Illia | E108: Domo | F108: Radio | H108: 172.20.200.126 | I108: =COUNTIF(L108:AM108,"") -> 28 | J108: =COUNTIF(L108:AM108,"APAGADO") -> 0 | K108: =(I108)/(J108+I108) -> 1
A109: CHACABUCO | B109: CHA02 | C109: BONOMO | D109: Pte. Illia y Posadas | E109: Domo | F109: Radio | H109: 172.20.200.186 | I109: =COUNTIF(L109:AM109,"") -> 28 | J109: =COUNTIF(L109:AM109,"APAGADO") -> 0 | K109: =(I109)/(J109+I109) -> 1
...

Sheet Hoja4
A10: Barrio | B10: [Denominacion] | C10: [Empresa Mantenimiento] | D10: [Ubicacion] | E10: [Tipo de Camara] | F10: [Tipo de Conexion]
A11: CENTRO | B11: CEN 72 | C11: BONOMO | D11: MORENO Y 25 DE MAYO | E11: Domo | F11: Fibra Optica | G11: 172.20.11.219
A12: DON JOSE | B12: DJO 02 (fija 1) | C12: BONOMO | D12: DONATO ALVAREZ Y EL APERO | E12: Fija | F12: PTO A FO | G12: 172.20.12.97
A13: DON JOSE | B13: DJO 03 (fija 2) | C13: BONOMO | D13: DONATO ALVAREZ Y EL APERO | E13: Fija | F13: PTO A FO | G13: 172.20.12.98
A14: DON JOSE | B14: DJO 04 (Fija 1) | C14: BONOMO | D14: MONTEVERDE Y EL INDIO | E14: Fija | F14: PTO A FO | G14: 172.20.12.91
A15: DON JOSE | B15: DJO 05 (Fija 2) | C15: BONOMO | D15: MONTEVERDE Y EL INDIO | E15: Fija | F15: PTO A FO | G15: 172.20.12.92
A16: DON JOSE | B16: DJ O6 | C16: BONOMO | D16: Calle 414 y El Indio | E16: Fija | F16: PTO A FO | G16: 172.20.12.121
A17: DON JOSE | B17: DJ 07 | C17: BONOMO | D17: Calle 414 y El Indio | E17: Fija | F17: PTO A FO | G17: 172.20.12.122
A18: KM 26700 (JULIO A. COSTA) | B18: KM 14 (fija 1) | C18: BONOMO | D18: EL GAUCHO Y EL ZONDA | E18: Fija | F18: PTO A FO | G18: 172.20.12.94
A19: KM 26700 (JULIO A. COSTA) | B19: KM 15 (fija 2) | C19: BONOMO | D19: EL GAUCHO Y EL ZONDA | E19: Fija | F19: PTO A FO | G19: 172.20.12.95
A20: KM 26700 (JULIO A. COSTA) | B20: KM 16 (fija 1) | C20: BONOMO | D20: EL GAUCHO Y MARTIN FIERRO | E20: Fija | F20: PTO A FO | G20: 172.20.12.88
A21: KM 26700 (JULIO A. COSTA) | B21: KM 17 (fija 2) | C21: BONOMO | D21: EL GAUCHO Y MARTIN FIERRO | E21: Fija | F21: PTO A FO | G21: 172.20.12.89
A22: MARTIN FIERRO | B22: MFI 07 | C22: BONOMO | D22: Sargento Cabral y Carlos Gardel | E22: Domo | F22: PTO A FO | G22: 172.20.10.104
... A24: 9 DE JULIO | B24: NJU09 | C24: BONOMO | D24: PARRILLO Y CONTRERAS | E24: DOMO | F24: Fibra Optica | G24: 172.20.11.190
A25: DON JOSE | B25: PUNTO SEGURO AGUSTIN RAMIREZ INTERCOMUNICADOR | C25: BONOMO | D25: MALAMBO Y LA TRANQUERA | E25: Fija | F25: Fibra Optica
A26: SAN EDUARDO | B26: SEDU01 | C26: BONOMO | D26: San Martin y Sperandio | E26: Domo | F26: Fibra Optica | G26: 172.20.10.10
A27: VILLA CIRIO | B27: SEDU03 | C27: BONOMO | D27: Av. San Martin y Las Americas | E27: Domo | F27: Radio | G27: 172.20.200.183
A28: LA SIRENA | B28: SIR09 (fija 1) | C28: BONOMO | D28: GUIDO SPANO Y MORAN | E28: Fija | F28: Fibra Optica | G28: 172.20.11.96
A29: LA SIRENA | B29: SIR10 (fija 2) | C29: BONOMO | D29: GUIDO SPANO Y MORAN | E29: Fija | F29: Fibra Optica | G29: 172.20.11.97
A30: LA SIRENA | B30: SIR 14 | C30: BONOMO | D30: MANUEL IGLESIAS Y PEDRAZA | E30: Domo | F30: Fibra Optica | G30: 172.20.11.100
A31: VILLA DEL PLATA | B31: VDPL05 | C31: BONOMO | D31: Ruta 36 y Abraham | E31: Domo | F31: PTO A FO | G31: 172.20.12.219
A32: VILLA ANGELICA | B32: VDPL06 | C32: BONOMO | D32: Thevenet e/ Islas Orcadas y Gardel | E32: Domo | F32: Radio | G32: 172.20.200.196
A35: CAMARAS SIN FUNCIONAMIENTO DEL DIA 05 DE JUNIO DE 2023
A38: RECIBIDO: | D38: FIRMA:
A41: EMPRESA: BONOMO SISTEMAS
D43: ACALARCION:

Sheet ESTADISTICA
A1: ='RESUMEN TOTAL'!A4 -> Barrio | B1: ='RESUMEN TOTAL'!B4 -> [Denominacion] | C1: ='RESUMEN TOTAL'!D4 -> [Ubicacion] | D1: ='RESUMEN TOTAL'!E4 -> [Tipo de Camara] | E1: ='RESUMEN TOTAL'!F4 -> [Tipo de Conexion] | F1: ='RESUMEN TOTAL'!L4 -> 45078 | G1: ='RESUMEN TOTAL'!M4 -> 45079 | H1: ='RESUMEN TOTAL'!N4 -> 45080 | I1: ='RESUMEN TOTAL'!O4 -> 45081 | J1: ='RESUMEN TOTAL'!P4 -> 45082 | K1: ='RESUMEN TOTAL'!Q4 -> 45083 | L1: ='RESUMEN TOTAL'!R4 -> 45084 | M1: ='RESUMEN TOTAL'!S4 -> 45085 | ... AI1: ='RESUMEN TOTAL'!AO4 -> 45107 | AJ1: ='RESUMEN TOTAL'!#REF! -> #REF!
A2: ='RESUMEN TOTAL'!A5 -> ALTAMIRA | B2: ='RESUMEN TOTAL'!B5 -> ALT01 | C2: ='RESUMEN TOTAL'!D5 -> Calchaqui y Sgto. Cabral | D2: ='RESUMEN TOTAL'!E5 -> Domo | E2: ='RESUMEN TOTAL'!F5 -> Fibra Optica | F2: ='RESUMEN TOTAL'!L5 -> 0 | G2: ='RESUMEN TOTAL'!M5 -> 0 | H2: ='RESUMEN TOTAL'!N5 -> 0 | I2: ='RESUMEN TOTAL'!O5 -> 0 | J2: ='RESUMEN TOTAL'!P5 -> 0 | K2: ='RESUMEN TOTAL'!Q5 -> 0 | L2: ='RESUMEN TOTAL'!R5 -> 0 | M2: ='RESUMEN TOTAL'!S5 -> 0 | ... AI2: ='RESUMEN TOTAL'!AO5 -> 0 | AJ2: ='RESUMEN TOTAL'!#REF! -> #REF!
A3: ='RESUMEN TOTAL'!A6 -> ALTAMIRA | B3: ='RESUMEN TOTAL'!B6 -> ALT02 | C3: ='RESUMEN TOTAL'!D6 -> Calchaqui y Lope de Vega | D3: ='RESUMEN TOTAL'!E6 -> Domo | E3: ='RESUMEN TOTAL'!F6 -> PTO A FO | F3: ='RESUMEN TOTAL'!L6 -> 0 | G3: ='RESUMEN TOTAL'!M6 -> 0 | H3: ='RESUMEN TOTAL'!N6 -> 0 | I3: ='RESUMEN TOTAL'!O6 -> 0 | J3: ='RESUMEN TOTAL'!P6 -> 0 | K3: ='RESUMEN TOTAL'!Q6 -> 0 | L3: ='RESUMEN TOTAL'!R6 -> 0 | M3: ='RESUMEN TOTAL'!S6 -> 0 | ... AI3: ='RESUMEN TOTAL'!AO6 -> 0 | AJ3: ='RESUMEN TOTAL'!#REF! -> #REF!
A4: ='RESUMEN TOTAL'!A7 -> ALTAMIRA | B4: ='RESUMEN TOTAL'!B7 -> ALT 03 | C4: ='RESUMEN TOTAL'!D7 -> Bombero Galarza y Necochea | D4: ='RESUMEN TOTAL'!E7 -> Domo | E4: ='RESUMEN TOTAL'!F7 -> FIBRA OPTICA | F4: ='RESUMEN TOTAL'!L7 -> 0 | G4: ='RESUMEN TOTAL'!M7 -> 0 | H4: ='RESUMEN TOTAL'!N7 -> 0 | I4: ='RESUMEN TOTAL'!O7 -> 0 | J4: ='RESUMEN TOTAL'!P7 -> 0 | K4: ='RESUMEN TOTAL'!Q7 -> 0 | L4: ='RESUMEN TOTAL'!R7 -> 0 | M4: ='RESUMEN TOTAL'!S7 -> 0 | ... AI4: ='RESUMEN TOTAL'!AO7 -> 0 | AJ4: ='RESUMEN TOTAL'!#REF! -> #REF!
A5: ='RESUMEN TOTAL'!A8 -> ALTAMIRA | B5: ='RESUMEN TOTAL'!B8 -> ALT 04 | C5: ='RESUMEN TOTAL'!D8 -> Francia y Necochea | D5: ='RESUMEN TOTAL'!E8 -> Domo | E5: ='RESUMEN TOTAL'!F8 -> FIBRA OPTICA | F5: ='RESUMEN TOTAL'!L8 -> 0 | G5: ='RESUMEN TOTAL'!M8 -> 0 | H5: ='RESUMEN TOTAL'!N8 -> 0 | I5: ='RESUMEN TOTAL'!O8 -> 0 | J5: ='RESUMEN TOTAL'!P8 -> 0 | K5: ='RESUMEN TOTAL'!Q8 -> 0 | L5: ='RESUMEN TOTAL'!R8 -> 0 | M5: ='RESUMEN TOTAL'!S8 -> 0 | ... AI5: ='RESUMEN TOTAL'!AO8 -> 0 | AJ5: ='RESUMEN TOTAL'!#REF! -> #REF!
A6: ='RESUMEN TOTAL'!A9 -> ALTAMIRA | B6: ='RESUMEN TOTAL'!B9 -> ALT05 | C6: ='RESUMEN TOTAL'!D9 -> Av. Calchaqui y Bombero Galarza | D6: ='RESUMEN TOTAL'!E9 -> Domo | E6: ='RESUMEN TOTAL'!F9 -> PTO A FO | F6: ='RESUMEN TOTAL'!L9 -> 0 | G6: ='RESUMEN TOTAL'!M9 -> 0 | H6: ='RESUMEN TOTAL'!N9 -> 0 | I6: ='RESUMEN TOTAL'!O9 -> 0 | J6: ='RESUMEN TOTAL'!P9 -> 0 | K6: ='RESUMEN TOTAL'!Q9 -> 0 | L6: ='RESUMEN TOTAL'!R9 -> 0 | M6: ='RESUMEN TOTAL'!S9 -> 0 | ... AI6: ='RESUMEN TOTAL'!AO9 -> 0 | AJ6: ='RESUMEN TOTAL'!#REF! -> #REF!
A7: ='RESUMEN TOTAL'!A10 -> ALTAMIRA | B7: ='RESUMEN TOTAL'!B10 -> ALT 06 | C7: ='RESUMEN TOTAL'!D10 -> LOPE DE VEGA Y NECOCHEA | D7: ='RESUMEN TOTAL'!E10 -> Domo | E7: ='RESUMEN TOTAL'!F10 -> PTO A FO | F7: ='RESUMEN TOTAL'!L10 -> 0 | G7: ='RESUMEN TOTAL'!M10 -> 0 | H7: ='RESUMEN TOTAL'!N10 -> 0 | I7: ='RESUMEN TOTAL'!O10 -> 0 | J7: ='RESUMEN TOTAL'!P10 -> 0 | K7: ='RESUMEN TOTAL'!Q10 -> 0 | L7: ='RESUMEN TOTAL'!R10 -> 0 | M7: ='RESUMEN TOTAL'!S10 -> 0 | ... AI7: ='RESUMEN TOTAL'!AO10 -> 0 | AJ7: ='RESUMEN TOTAL'!#REF! -> #REF!
A8: ='RESUMEN TOTAL'!A11 -> ALTAMIRA | B8: ='RESUMEN TOTAL'!B11 -> ALT07 | C8: ='RESUMEN TOTAL'!D11 -> AV. CALCHAQUI Y AV. DEL TRABAJO | D8: ='RESUMEN TOTAL'!E11 -> DOMO | E8: ='RESUMEN TOTAL'!F11 -> PTO A FO | F8: ='RESUMEN TOTAL'!L11 -> 0 | G8: ='RESUMEN TOTAL'!M11 -> 0 | H8: ='RESUMEN TOTAL'!N11 -> 0 | I8: ='RESUMEN TOTAL'!O11 -> 0 | J8: ='RESUMEN TOTAL'!P11 -> 0 | K8: ='RESUMEN TOTAL'!Q11 -> 0 | L8: ='RESUMEN TOTAL'!R11 -> 0 | M8: ='RESUMEN TOTAL'!S11 -> 0 | ... AI8: ='RESUMEN TOTAL'!AO11 -> 0 | AJ8: ='RESUMEN TOTAL'!#REF! -> #REF!
A9: ='RESUMEN TOTAL'!A12 -> ALTAMIRA | B9: ='RESUMEN TOTAL'!B12 -> ALT 08 | C9: ='RESUMEN TOTAL'!D12 -> HUMAITA Y NECOCHEA | D9: ='RESUMEN TOTAL'!E12 -> DOMO | E9: ='RESUMEN TOTAL'!F12 -> Fibra Optica | F9: ='RESUMEN TOTAL'!L12 -> 0 | G9: ='RESUMEN TOTAL'!M12 -> 0 | H9: ='RESUMEN TOTAL'!N12 -> 0 | I9: ='RESUMEN TOTAL'!O12 -> 0 | J9: ='RESUMEN TOTAL'!P12 -> 0 | K9: ='RESUMEN TOTAL'!Q12 -> 0 | L9: ='RESUMEN TOTAL'!R12 -> 0 | M9: ='RESUMEN TOTAL'!S12 -> 0 | ... AI9: ='RESUMEN TOTAL'!AO12 -> 0 | AJ9: ='RESUMEN TOTAL'!#REF! -> #REF!
A10: ='RESUMEN TOTAL'!A13 -> ALTAMIRA | B10: ='RESUMEN TOTAL'!B13 -> ALT 09 | C10: ='RESUMEN TOTAL'!D13 -> NECOCHEA Y CURUPAITY | D10: ='RESUMEN TOTAL'!E13 -> DOMO | E10: ='RESUMEN TOTAL'!F13 -> Fibra Optica | F10: ='RESUMEN TOTAL'!L13 -> 0 | G10: ='RESUMEN TOTAL'!M13 -> 0 | H10: ='RESUMEN TOTAL'!N13 -> 0 | I10: ='RESUMEN TOTAL'!O13 -> 0 | J10: ='RESUMEN TOTAL'!P13 -> 0 | K10: ='RESUMEN TOTAL'!Q13 -> 0 | L10: ='RESUMEN TOTAL'!R13 -> 0 | M10: ='RESUMEN TOTAL'!S13 -> 0 | ... AI10: ='RESUMEN TOTAL'!AO13 -> 0 | AJ10: ='RESUMEN TOTAL'!#REF! -> #REF!
A11: ='RESUMEN TOTAL'!A14 -> ALTAMIRA | B11: ='RESUMEN TOTAL'!B14 -> ALT 10 | C11: ='RESUMEN TOTAL'!D14 -> Calchaqui y Francia | D11: ='RESUMEN TOTAL'!E14 -> Domo | E11: ='RESUMEN TOTAL'!F14 -> Radio | F11: ='RESUMEN TOTAL'!L14 -> 0 | G11: ='RESUMEN TOTAL'!M14 -> 0 | H11: ='RESUMEN TOTAL'!N14 -> 0 | I11: ='RESUMEN TOTAL'!O14 -> 0 | J11: ='RESUMEN TOTAL'!P14 -> 0 | K11: ='RESUMEN TOTAL'!Q14 -> 0 | L11: ='RESUMEN TOTAL'!R14 -> 0 | M11: ='RESUMEN TOTAL'!S14 -> 0 | ... AI11: ='RESUMEN TOTAL'!AO14 -> 0 | AJ11: ='RESUMEN TOTAL'!#REF! -> #REF!
A12: ='RESUMEN TOTAL'!A15 -> AGUSTIN RAMIREZ | B12: ='RESUMEN TOTAL'!B15 -> ARA 01 | C12: ='RESUMEN TOTAL'!D15 -> Malambo y Tranquera | D12: ='RESUMEN TOTAL'!E15 -> Domo | E12: ='RESUMEN TOTAL'!F15 -> FIBRA OPTICA | F12: ='RESUMEN TOTAL'!L15 -> 0 | G12: ='RESUMEN TOTAL'!M15 -> 0 | H12: ='RESUMEN TOTAL'!N15 -> 0 | I12: ='RESUMEN TOTAL'!O15 -> 0 | J12: ='RESUMEN TOTAL'!P15 -> 0 | K12: ='RESUMEN TOTAL'!Q15 -> 0 | L12: ='RESUMEN TOTAL'!R15 -> 0 | M12: ='RESUMEN TOTAL'!S15 -> 0 | ... AI12: ='RESUMEN TOTAL'!AO15 -> 0 | AJ12: ='RESUMEN TOTAL'!#REF! -> #REF!
... A635: ='RESUMEN TOTAL'!A638 -> 0 | B635: ='RESUMEN TOTAL'!B638 -> 0 | C635: ='RESUMEN TOTAL'!D638 -> 0 | D635: ='RESUMEN TOTAL'!E638 -> 0 | E635: ='RESUMEN TOTAL'!F638 -> 0 | F635: ='RESUMEN TOTAL'!L638 -> 0 | G635: ='RESUMEN TOTAL'!M638 -> 0 | H635: ='RESUMEN TOTAL'!N638 -> 0 | I635: ='RESUMEN TOTAL'!O638 -> 0 | J635: ='RESUMEN TOTAL'!P638 -> 0 | K635: ='RESUMEN TOTAL'!Q638 -> 0 | L635: ='RESUMEN TOTAL'!R638 -> 0 | M635: ='RESUMEN TOTAL'!S638 -> 0 | ... AI635: ='RESUMEN TOTAL'!AO638 -> 0 | AJ635: ='RESUMEN TOTAL'!#REF! -> #REF!

Sheet APAGADOS
E1: APAGADOS | F1: =COUNTIF(F3:F401, "APAGADO") -> 47 | G1: =COUNTIF(G3:G401, "APAGADO") -> 38 | H1: =COUNTIF(H3:H501, "APAGADO") -> 55 | I1: =COUNTIF(I3:I401, "APAGADO") -> 40 | J1: =COUNTIF(J3:J401, "APAGADO") -> 39 | K1: =COUNTIF(K3:K401, "APAGADO") -> 0 | L1: =COUNTIF(L3:L401, "APAGADO") -> 0 | M1: =COUNTIF(M3:M401, "APAGADO") -> 0 | N1: =COUNTIF(N3:N401, "APAGADO") -> 0 | O1: =COUNTIF(O3:O401, "APAGADO") -> 0 | P1: =COUNTIF(P3:P401, "APAGADO") -> 0 | ... AD1: =COUNTIF(AD3:AD401, "APAGADO") -> 0 | AE1: =COUNTIF(AE3:AE501, "APAGADO") -> 0 | AF1: =COUNTIF(AF3:AF401, "APAGADO") -> 0 | AG1: =COUNTIF(AG3:AG401, "APAGADO") -> 0 | AH1: =COUNTIF(AH3:AH401, "APAGADO") -> 0 | AI1: =COUNTIF(AI3:AI401, "APAGADO") -> 0 | AJ1: =COUNTIF(AJ3:AJ401, "APAGADO") -> 0
A2: =ESTADISTICA!A1 -> Barrio | B2: =ESTADISTICA!B1 -> [Denominacion] | C2: =ESTADISTICA!C1 -> [Ubicacion] | D2: =ESTADISTICA!D1 -> [Tipo de Camara] | E2: =ESTADISTICA!E1 -> [Tipo de Conexion] | F2: =ESTADISTICA!F1 -> 45078 | G2: =ESTADISTICA!G1 -> 45079 | H2: =ESTADISTICA!H1 -> 45080 | ... AJ2: =ESTADISTICA!AJ1 -> #REF!
A3: =ESTADISTICA!A2 -> ALTAMIRA | B3: =ESTADISTICA!B2 -> ALT01 | C3: =ESTADISTICA!C2 -> Calchaqui y Sgto. Cabral | D3: =ESTADISTICA!D2 -> Domo | E3: =ESTADISTICA!E2 -> Fibra Optica | F3: =ESTADISTICA!F2 -> 0 | G3: =ESTADISTICA!G2 -> 0 | H3: =ESTADISTICA!H2 -> 0 | ... AJ3: =ESTADISTICA!AJ2 -> #REF!
A4: =ESTADISTICA!A3 -> ALTAMIRA | B4: =ESTADISTICA!B3 -> ALT02 | C4: =ESTADISTICA!C3 -> Calchaqui y Lope de Vega | D4: =ESTADISTICA!D3 -> Domo | E4: =ESTADISTICA!E3 -> PTO A FO | F4: =ESTADISTICA!F3 -> 0 | G4: =ESTADISTICA!G3 -> 0 | H4: =ESTADISTICA!H3 -> 0 | ... AJ4: =ESTADISTICA!AJ3 -> #REF!
A5: =ESTADISTICA!A4 -> ALTAMIRA | B5: =ESTADISTICA!B4 -> ALT 03 | C5: =ESTADISTICA!C4 -> Bombero Galarza y Necochea | D5: =ESTADISTICA!D4 -> Domo | E5: =ESTADISTICA!E4 -> FIBRA OPTICA | F5: =ESTADISTICA!F4 -> 0 | G5: =ESTADISTICA!G4 -> 0 | H5: =ESTADISTICA!H4 -> 0 | ... AJ5: =ESTADISTICA!AJ4 -> #REF!
A6: =ESTADISTICA!A5 -> ALTAMIRA | B6: =ESTADISTICA!B5 -> ALT 04 | C6: =ESTADISTICA!C5 -> Francia y Necochea | D6: =ESTADISTICA!D5 -> Domo | E6: =ESTADISTICA!E5 -> FIBRA OPTICA | F6: =ESTADISTICA!F5 -> 0 | G6: =ESTADISTICA!G5 -> 0 | H6: =ESTADISTICA!H5 -> 0 | ... AJ6: =ESTADISTICA!AJ5 -> #REF!
A7: =ESTADISTICA!A6 -> ALTAMIRA | B7: =ESTADISTICA!B6 -> ALT05 | C7: =ESTADISTICA!C6 -> Av. Calchaqui y Bombero Galarza | D7: =ESTADISTICA!D6 -> Domo | E7: =ESTADISTICA!E6 -> PTO A FO | F7: =ESTADISTICA!F6 -> 0 | G7: =ESTADISTICA!G6 -> 0 | H7: =ESTADISTICA!H6 -> 0 | ... AJ7: =ESTADISTICA!AJ6 -> #REF!
A8: =ESTADISTICA!A7 -> ALTAMIRA | B8: =ESTADISTICA!B7 -> ALT 06 | C8: =ESTADISTICA!C7 -> LOPE DE VEGA Y NECOCHEA | D8: =ESTADISTICA!D7 -> Domo | E8: =ESTADISTICA!E7 -> PTO A FO | F8: =ESTADISTICA!F7 -> 0 | G8: =ESTADISTICA!G7 -> 0 | H8: =ESTADISTICA!H7 -> 0 | ... AJ8: =ESTADISTICA!AJ7 -> #REF!
A9: =ESTADISTICA!A8 -> ALTAMIRA | B9: =ESTADISTICA!B8 -> ALT07 | C9: =ESTADISTICA!C8 -> AV. CALCHAQUI Y AV. DEL TRABAJO | D9: =ESTADISTICA!D8 -> DOMO | E9: =ESTADISTICA!E8 -> PTO A FO | F9: =ESTADISTICA!F8 -> 0 | G9: =ESTADISTICA!G8 -> 0 | H9: =ESTADISTICA!H8 -> 0 | ... AJ9: =ESTADISTICA!AJ8 -> #REF!
A10: =ESTADISTICA!A9 -> ALTAMIRA | B10: =ESTADISTICA!B9 -> ALT 08 | C10: =ESTADISTICA!C9 -> HUMAITA Y NECOCHEA | D10: =ESTADISTICA!D9 -> DOMO | E10: =ESTADISTICA!E9 -> Fibra Optica | F10: =ESTADISTICA!F9 -> 0 | G10: =ESTADISTICA!G9 -> 0 | H10: =ESTADISTICA!H9 -> 0 | ... AJ10: =ESTADISTICA!AJ9 -> #REF!
A11: =ESTADISTICA!A10 -> ALTAMIRA | B11: =ESTADISTICA!B10 -> ALT 09 | C11: =ESTADISTICA!C10 -> NECOCHEA Y CURUPAITY | D11: =ESTADISTICA!D10 -> DOMO | E11: =ESTADISTICA!E10 -> Fibra Optica | F11: =ESTADISTICA!F10 -> 0 | G11: =ESTADISTICA!G10 -> 0 | H11: =ESTADISTICA!H10 -> 0 | ... AJ11: =ESTADISTICA!AJ10 -> #REF!
A12: =ESTADISTICA!A11 -> ALTAMIRA | B12: =ESTADISTICA!B11 -> ALT 10 | C12: =ESTADISTICA!C11 -> Calchaqui y Francia | D12: =ESTADISTICA!D11 -> Domo | E12: =ESTADISTICA!E11 -> Radio | F12: =ESTADISTICA!F11 -> 0 | G12: =ESTADISTICA!G11 -> 0 | H12: =ESTADISTICA!H11 -> 0 | ... AJ12: =ESTADISTICA!AJ11 -> #REF!
A13: =ESTADISTICA!A12 -> AGUSTIN RAMIREZ | B13: =ESTADISTICA!B12 -> ARA 01 | C13: =ESTADISTICA!C12 -> Malambo y Tranquera | D13: =ESTADISTICA!D12 -> Domo | E13: =ESTADISTICA!E12 -> FIBRA OPTICA | F13: =ESTADISTICA!F12 -> 0 | G13: =ESTADISTICA!G12 -> 0 | H13: =ESTADISTICA!H12 -> 0 | ... AJ13: =ESTADISTICA!AJ12 -> #REF!
... A514: =ESTADISTICA!A513 -> 0 | B514: =ESTADISTICA!B513 -> 0 | C514: =ESTADISTICA!C513 -> 0 | D514: =ESTADISTICA!D513 -> 0 | E514: =ESTADISTICA!E513 -> 0 | F514: =ESTADISTICA!F513 -> 0 | G514: =ESTADISTICA!G513 -> 0 | H514: =ESTADISTICA!H513 -> 0 | ... AJ514: =ESTADISTICA!AJ513 -> #REF!

Sheet APAGADOS FIBRA
C1: TOTAL FIBRA | D1: =COUNTIFS(E4:E400,"=Fibra Optica") -> 266
E2: APAGADOS | F2: =COUNTIFS(F4:F500, "=APAGADO",E4:E500,"=Fibra Optica") -> 35 | G2: =COUNTIFS(G4:G500, "=APAGADO",E4:E500,"=Fibra Optica") -> 27 | H2: =COUNTIFS(H4:H500, "=APAGADO",E4:E500,"=Fibra Optica") -> 34 | I2: =COUNTIFS(I4:I500, "=APAGADO",E4:E500,"=Fibra Optica") -> 29 | J2: =COUNTIFS(J4:J500, "=APAGADO",E4:E500,"=Fibra Optica") -> 29 | K2: =COUNTIFS(K4:K500, "=APAGADO",E4:E500,"=Fibra Optica") -> 0 | L2: =COUNTIFS(L4:L500, "=APAGADO",E4:E500,"=Fibra Optica") -> 0 | M2: =COUNTIFS(M4:M500, "=APAGADO",E4:E500,"=Fibra Optica") -> 0 | N2: =COUNTIFS(N4:N500, "=APAGADO",E4:E500,"=Fibra Optica") -> 0 | O2: =COUNTIFS(O4:O500, "=APAGADO",E4:E500,"=Fibra Optica") -> 0 | P2: =COUNTIFS(P4:P500, "=APAGADO",E4:E500,"=Fibra Optica") -> 0 | Q2: =COUNTIFS(Q4:Q500, "=APAGADO",E4:E500,"=Fibra Optica") -> 0 | R2: =COUNTIFS(R4:R500, "=APAGADO",E4:E500,"=Fibra Optica") -> 0 | S2: =COUNTIFS(S4:S500, "=APAGADO",E4:E500,"=Fibra Optica") -> 0 | T2: =COUNTIFS(T4:T500, "=APAGADO",E4:E500,"=Fibra Optica") -> 0 | U2: =COUNTIFS(U4:U500, "=APAGADO",E4:E500,"=Fibra Optica") -> 0 | V2: =COUNTIFS(V4:V500, "=APAGADO",E4:E500,"=Fibra Optica") -> 0 | W2: =COUNTIFS(W4:W500, "=APAGADO",E4:E500,"=Fibra Optica") -> 0 | X2: =COUNTIFS(X4:X500, "=APAGADO",E4:E500,"=Fibra Optica") -> 0 | Y2: =COUNTIFS(Y4:Y500, "=APAGADO",E4:E500,"=Fibra Optica") -> 0 | Z2: =COUNTIFS(Z4:Z500, "=APAGADO",E4:E500,"=Fibra Optica") -> 0 | AA2: =COUNTIFS(AA4:AA500, "=APAGADO",E4:E500,"=Fibra Optica") -> 0 | AB2: =COUNTIFS(AB4:AB500, "=APAGADO",E4:E500,"=Fibra Optica") -> 0 | AC2: =COUNTIFS(AC4:AC500, "=APAGADO",E4:E500,"=Fibra Optica") -> 0 | AD2: =COUNTIFS(AD4:AD500, "=APAGADO",E4:E500,"=Fibra Optica") -> 0 | AE2: =COUNTIFS(AE4:AE500, "=APAGADO",E4:E500,"=Fibra Optica") -> 0 | AF2: =COUNTIFS(AF4:AF500, "=APAGADO",E4:E500,"=Fibra Optica") -> 0 | AG2: =COUNTIFS(AG4:AG500, "=APAGADO",E4:E500,"=Fibra Optica") -> 0 | AH2: =COUNTIFS(AH4:AH500, "=APAGADO",E4:E500,"=Fibra Optica") -> 0 | AI2: =COUNTIFS(AI4:AI400, "=APAGADO",E4:E400,"=Fibra Optica") -> 0 | AJ2: =COUNTIFS(AJ4:AJ400, "=APAGADO",F4:F400,"=Fibra Optica") -> 0
A3: =ESTADISTICA!A1 -> Barrio | B3: =ESTADISTICA!B1 -> [Denominacion] | C3: =ESTADISTICA!C1 -> [Ubicacion] | D3: =ESTADISTICA!D1 -> [Tipo de Camara] | E3: =ESTADISTICA!E1 -> [Tipo de Conexion] | F3: =ESTADISTICA!F1 -> 45078 | G3: =ESTADISTICA!G1 -> 45079 | H3: =ESTADISTICA!H1 -> 45080 | ... AJ3: =ESTADISTICA!AJ1 -> #REF!
A4: =ESTADISTICA!A2 -> ALTAMIRA | B4: =ESTADISTICA!B2 -> ALT01 | C4: =ESTADISTICA!C2 -> Calchaqui y Sgto. Cabral | D4: =ESTADISTICA!D2 -> Domo | E4: =ESTADISTICA!E2 -> Fibra Optica | F4: =ESTADISTICA!F2 -> 0 | G4: =ESTADISTICA!G2 -> 0 | H4: =ESTADISTICA!H2 -> 0 | ... AJ4: =ESTADISTICA!AJ2 -> #REF!
A5: =ESTADISTICA!A3 -> ALTAMIRA | B5: =ESTADISTICA!B3 -> ALT02 | C5: =ESTADISTICA!C3 -> Calchaqui y Lope de Vega | D5: =ESTADISTICA!D3 -> Domo | E5: =ESTADISTICA!E3 -> PTO A FO | F5: =ESTADISTICA!F3 -> 0 | G5: =ESTADISTICA!G3 -> 0 | H5: =ESTADISTICA!H3 -> 0 | ... AJ5: =ESTADISTICA!AJ3 -> #REF!
A6: =ESTADISTICA!A4 -> ALTAMIRA | B6: =ESTADISTICA!B4 -> ALT 03 | C6: =ESTADISTICA!C4 -> Bombero Galarza y Necochea | D6: =ESTADISTICA!D4 -> Domo | E6: =ESTADISTICA!E4 -> FIBRA OPTICA | F6: =ESTADISTICA!F4 -> 0 | G6: =ESTADISTICA!G4 -> 0 | H6: =ESTADISTICA!H4 -> 0 | ... AJ6: =ESTADISTICA!AJ4 -> #REF!
A7: =ESTADISTICA!A5 -> ALTAMIRA | B7: =ESTADISTICA!B5 -> ALT 04 | C7: =ESTADISTICA!C5 -> Francia y Necochea | D7: =ESTADISTICA!D5 -> Domo | E7: =ESTADISTICA!E5 -> FIBRA OPTICA | F7: =ESTADISTICA!F5 -> 0 | G7: =ESTADISTICA!G5 -> 0 | H7: =ESTADISTICA!H5 -> 0 | ... AJ7: =ESTADISTICA!AJ5 -> #REF!
A8: =ESTADISTICA!A6 -> ALTAMIRA | B8: =ESTADISTICA!B6 -> ALT05 | C8: =ESTADISTICA!C6 -> Av. Calchaqui y Bombero Galarza | D8: =ESTADISTICA!D6 -> Domo | E8: =ESTADISTICA!E6 -> PTO A FO | F8: =ESTADISTICA!F6 -> 0 | G8: =ESTADISTICA!G6 -> 0 | H8: =ESTADISTICA!H6 -> 0 | ... AJ8: =ESTADISTICA!AJ6 -> #REF!
A9: =ESTADISTICA!A7 -> ALTAMIRA | B9: =ESTADISTICA!B7 -> ALT 06 | C9: =ESTADISTICA!C7 -> LOPE DE VEGA Y NECOCHEA | D9: =ESTADISTICA!D7 -> Domo | E9: =ESTADISTICA!E7 -> PTO A FO | F9: =ESTADISTICA!F7 -> 0 | G9: =ESTADISTICA!G7 -> 0 | H9: =ESTADISTICA!H7 -> 0 | ... AJ9: =ESTADISTICA!AJ7 -> #REF!
A10: =ESTADISTICA!A8 -> ALTAMIRA | B10: =ESTADISTICA!B8 -> ALT07 | C10: =ESTADISTICA!C8 -> AV. CALCHAQUI Y AV. DEL TRABAJO | D10: =ESTADISTICA!D8 -> DOMO | E10: =ESTADISTICA!E8 -> PTO A FO | F10: =ESTADISTICA!F8 -> 0 | G10: =ESTADISTICA!G8 -> 0 | H10: =ESTADISTICA!H8 -> 0 | ... AJ10: =ESTADISTICA!AJ8 -> #REF!
A11: =ESTADISTICA!A9 -> ALTAMIRA | B11: =ESTADISTICA!B9 -> ALT 08 | C11: =ESTADISTICA!C9 -> HUMAITA Y NECOCHEA | D11: =ESTADISTICA!D9 -> DOMO | E11: =ESTADISTICA!E9 -> Fibra Optica | F11: =ESTADISTICA!F9 -> 0 | G11: =ESTADISTICA!G9 -> 0 | H11: =ESTADISTICA!H9 -> 0 | ... AJ11: =ESTADISTICA!AJ9 -> #REF!
A12: =ESTADISTICA!A10 -> ALTAMIRA | B12: =ESTADISTICA!B10 -> ALT 09 | C12: =ESTADISTICA!C10 -> NECOCHEA Y CURUPAITY | D12: =ESTADISTICA!D10 -> DOMO | E12: =ESTADISTICA!E10 -> Fibra Optica | F12: =ESTADISTICA!F10 -> 0 | G12: =ESTADISTICA!G10 -> 0 | H12: =ESTADISTICA!H10 -> 0 | ... AJ12: =ESTADISTICA!AJ10 -> #REF!
A13: =ESTADISTICA!A11 -> ALTAMIRA | B13: =ESTADISTICA!B11 -> ALT 10 | C13: =ESTADISTICA!C11 -> Calchaqui y Francia | D13: =ESTADISTICA!D11 -> Domo | E13: =ESTADISTICA!E11 -> Radio | F13: =ESTADISTICA!F11 -> 0 | G13: =ESTADISTICA!G11 -> 0 | H13: =ESTADISTICA!H11 -> 0 | ... AJ13: =ESTADISTICA!AJ11 -> #REF!
A14: =ESTADISTICA!A12 -> AGUSTIN RAMIREZ | B14: =ESTADISTICA!B12 -> ARA 01 | C14: =ESTADISTICA!C12 -> Malambo y Tranquera | D14: =ESTADISTICA!D12 -> Domo | E14: =ESTADISTICA!E12 -> FIBRA OPTICA | F14: =ESTADISTICA!F12 -> 0 | G14: =ESTADISTICA!G12 -> 0 | H14: =ESTADISTICA!H12 -> 0 | ... AJ14: =ESTADISTICA!AJ12 -> #REF!
... A206: =ESTADISTICA!A204 -> SAN EMILIO | B206: =ESTADISTICA!B204 -> MFI06 | C206: =ESTADISTICA!C204 -> Con. Gral. Belgrano y Bombero Galarza | D206: =ESTADISTICA!D204 -> DOMO | E206: =ESTADISTICA!E204 -> Radio | F206: =ESTADISTICA!F204 -> 0 | G206: =ESTADISTICA!G204 -> 0 | H206: =ESTADISTICA!H204 -> 0 | ... AJ206: =ESTADISTICA!AJ204 -> #REF!
A207: =ESTADISTICA!A206 -> GOBERNADOR MONTEVERDE | B207: =ESTADISTICA!B206 -> MON01 | C207: =ESTADISTICA!C206 -> San Martin y Patricias Argentinas | D207: =ESTADISTICA!D206 -> Fija | E207: =ESTADISTICA!E206 -> Fibra Optica | F207: =ESTADISTICA!F206 -> 0 | G207: =ESTADISTICA!G206 -> 0 | H207: =ESTADISTICA!H206 -> 0 | ... AJ207: =ESTADISTICA!AJ206 -> #REF!
A208: =ESTADISTICA!A207 -> GOBERNADOR MONTEVERDE | B208: =ESTADISTICA!B207 -> MON02 | C208: =ESTADISTICA!C207 -> Senzabello y Famatina | D208: =ESTADISTICA!D207 -> Domo | E208: =ESTADISTICA!E207 -> Radio | F208: =ESTADISTICA!F207 -> 0 | G208: =ESTADISTICA!G207 -> 0 | H208: =ESTADISTICA!H207 -> 0 | ... AJ208: =ESTADISTICA!AJ207 -> #REF!
A209: =ESTADISTICA!A208 -> GOBERNADOR MONTEVERDE | B209: =ESTADISTICA!B208 -> MON03 | C209: =ESTADISTICA!C208 -> Senzabello y Guemes | D209: =ESTADISTICA!D208 -> Domo | E209: =ESTADISTICA!E208 -> Radio | F209: =ESTADISTICA!F208 -> 0 | G209: =ESTADISTICA!G208 -> 0 | H209: =ESTADISTICA!H208 -> 0 | ... AJ209: =ESTADISTICA!AJ208 -> #REF!
A210: =ESTADISTICA!A209 -> GOBERNADOR MONTEVERDE | B210: =ESTADISTICA!B209 -> MON04 | C210: =ESTADISTICA!C209 -> Av. Yrigoyen y San Lorenzo | D210: =ESTADISTICA!D209 -> Domo | E210: =ESTADISTICA!E209 -> Radio | F210: =ESTADISTICA!F209 -> 0 | G210: =ESTADISTICA!G209 -> 0 | H210: =ESTADISTICA!H209 -> 0 | ... AJ210: =ESTADISTICA!AJ209 -> #REF!
A211: =ESTADISTICA!A210 -> 9 DE JULIO | B211: =ESTADISTICA!B210 -> NJU 01 | C211: =ESTADISTICA!C210 -> Sallares y Parrillo | D211: =ESTADISTICA!D210 -> Domo | E211: =ESTADISTICA!E210 -> Fibra Optica | F211: =ESTADISTICA!F210 -> APAGADO | G211: =ESTADISTICA!G210 -> APAGADO | H211: =ESTADISTICA!H210 -> APAGADO | ... AJ211: =ESTADISTICA!AJ210 -> #REF!
A212: =ESTADISTICA!A211 -> 9 DE JULIO | B212: =ESTADISTICA!B211 -> NJU02 | C212: =ESTADISTICA!C211 -> Ituzaingo y Boccuzzi | D212: =ESTADISTICA!D211 -> Domo | E212: =ESTADISTICA!E211 -> Radio | F212: =ESTADISTICA!F211 -> 0 | G212: =ESTADISTICA!G211 -> 0 | H212: =ESTADISTICA!H211 -> 0 | ... AJ212: =ESTADISTICA!AJ211 -> #REF!
A213: =ESTADISTICA!A212 -> 9 DE JULIO | B213: =ESTADISTICA!B212 -> NJU03 | C213: =ESTADISTICA!C212 -> San Juan y Parrillo | D213: =ESTADISTICA!D212 -> Domo | E213: =ESTADISTICA!E212 -> PTO A FO | F213: =ESTADISTICA!F212 -> 0 | G213: =ESTADISTICA!G212 -> 0 | H213: =ESTADISTICA!H212 -> 0 | ... AJ213: =ESTADISTICA!AJ212 -> #REF!
A214: =ESTADISTICA!A213 -> 9 DE JULIO | B214: =ESTADISTICA!B213 -> NJU04 | C214: =ESTADISTICA!C213 -> Ituzaingo y 214 A | D214: =ESTADISTICA!D213 -> Domo | E214: =ESTADISTICA!E213 -> Radio | F214: =ESTADISTICA!F213 -> 0 | G214: =ESTADISTICA!G213 -> 0 | H214: =ESTADISTICA!H213 -> 0 | ... AJ214: =ESTADISTICA!AJ213 -> #REF!
A215: =ESTADISTICA!A214 -> ZEBALLOS CENTRO | B215: =ESTADISTICA!B214 -> NJU05 | C215: =ESTADISTICA!C214 -> Ituzaingo y Alem | D215: =ESTADISTICA!D214 -> Domo | E215: =ESTADISTICA!E214 -> Radio | F215: =ESTADISTICA!F214 -> 0 | G215: =ESTADISTICA!G214 -> 0 | H215: =ESTADISTICA!H214 -> APAGADO | ... AJ215: =ESTADISTICA!AJ214 -> #REF!
A216: =ESTADISTICA!A215 -> CENTRO | B216: =ESTADISTICA!B215 -> NJU06 | C216: =ESTADISTICA!C215 -> Sallares y Rodo | D216: =ESTADISTICA!D215 -> Domo | E216: =ESTADISTICA!E215 -> FIBRA OPTICA | F216: =ESTADISTICA!F215 -> 0 | G216: =ESTADISTICA!G215 -> 0 | H216: =ESTADISTICA!H215 -> 0 | ... AJ216: =ESTADISTICA!AJ215 -> #REF!
A217: =ESTADISTICA!A216 -> 9 DE JULIO | B217: =ESTADISTICA!B216 -> NJU07 | C217: =ESTADISTICA!C216 -> Gral. Juan Domingo Peron y Parrillo | D217: =ESTADISTICA!D216 -> Domo | E217: =ESTADISTICA!E216 -> FIBRA OPTICA | F217: =ESTADISTICA!F216 -> 0 | G217: =ESTADISTICA!G216 -> 0 | H217: =ESTADISTICA!H216 -> 0 | ... AJ217: =ESTADISTICA!AJ216 -> #REF!
A218: =ESTADISTICA!A217 -> 9 DE JULIO | B218: =ESTADISTICA!B217 -> NJU 08 | C218: =ESTADISTICA!C217 -> BOCCUZZI Y O HIGGINS | D218: =ESTADISTICA!D217 -> DOMO | E218: =ESTADISTICA!E217 -> Radio | F218: =ESTADISTICA!F217 -> 0 | G218: =ESTADISTICA!G217 -> 0 | H218: =ESTADISTICA!H217 -> 0 | ... AJ218: =ESTADISTICA!AJ217 -> #REF!
... A571: =ESTADISTICA!A570 -> 0 | B571: =ESTADISTICA!B570 -> 0 | C571: =ESTADISTICA!C570 -> 0 | D571: =ESTADISTICA!D570 -> 0 | E571: =ESTADISTICA!E570 -> 0 | F571: =ESTADISTICA!F570 -> 0 | G571: =ESTADISTICA!G570 -> 0 | H571: =ESTADISTICA!H570 -> 0 | ... AJ571: =ESTADISTICA!AJ570 -> #REF!
A572: =ESTADISTICA!A571 -> 0 | B572: =ESTADISTICA!B571 -> 0 | C572: =ESTADISTICA!C571 -> 0 | D572: =ESTADISTICA!D571 -> 0 | E572: =ESTADISTICA!E571 -> 0 | F572: =ESTADISTICA!F571 -> 0 | G572: =ESTADISTICA!G571 -> 0 | H572: =ESTADISTICA!H571 -> 0 | ... AI572: =ESTADISTICA!AI571 -> 0
A573: =ESTADISTICA!A572 -> 0 | B573: =ESTADISTICA!B572 -> 0 | C573: =ESTADISTICA!C572 -> 0 | D573: =ESTADISTICA!D572 -> 0 | E573: =ESTADISTICA!E572 -> 0 | F573: =ESTADISTICA!F572 -> 0 | G573: =ESTADISTICA!G572 -> 0 | H573: =ESTADISTICA!H572 -> 0 | ... AI573: =ESTADISTICA!AI572 -> 0
A574: =ESTADISTICA!A573 -> 0 | B574: =ESTADISTICA!B573 -> 0 | C574: =ESTADISTICA!C573 -> 0 | D574: =ESTADISTICA!D573 -> 0 | E574: =ESTADISTICA!E573 -> 0 | F574: =ESTADISTICA!F573 -> 0 | G574: =ESTADISTICA!G573 -> 0 | H574: =ESTADISTICA!H573 -> 0 | ... AI574: =ESTADISTICA!AI573 -> 0
A575: =ESTADISTICA!A574 -> 0 | B575: =ESTADISTICA!B574 -> 0 | C575: =ESTADISTICA!C574 -> 0 | D575: =ESTADISTICA!D574 -> 0 | E575: =ESTADISTICA!E574 -> 0 | F575: =ESTADISTICA!F574 -> 0 | G575: =ESTADISTICA!G574 -> 0 | H575: =ESTADISTICA!H574 -> 0 | ... AI575: =ESTADISTICA!AI574 -> 0
A576: =ESTADISTICA!A575 -> 0 | B576: =ESTADISTICA!B575 -> 0 | C576: =ESTADISTICA!C575 -> 0 | D576: =ESTADISTICA!D575 -> 0 | E576: =ESTADISTICA!E575 -> 0 | F576: =ESTADISTICA!F575 -> 0 | G576: =ESTADISTICA!G575 -> 0 | H576: =ESTADISTICA!H575 -> 0 | ... AI576: =ESTADISTICA!AI575 -> 0
A577: =ESTADISTICA!A576 -> 0 | B577: =ESTADISTICA!B576 -> 0 | C577: =ESTADISTICA!C576 -> 0 | D577: =ESTADISTICA!D576 -> 0 | E577: =ESTADISTICA!E576 -> 0 | F577: =ESTADISTICA!F576 -> 0 | G577: =ESTADISTICA!G576 -> 0 | H577: =ESTADISTICA!H576 -> 0 | ... AI577: =ESTADISTICA!AI576 -> 0
A578: =ESTADISTICA!A577 -> 0 | B578: =ESTADISTICA!B577 -> 0 | C578: =ESTADISTICA!C577 -> 0 | D578: =ESTADISTICA!D577 -> 0 | E578: =ESTADISTICA!E577 -> 0 | F578: =ESTADISTICA!F577 -> 0 | G578: =ESTADISTICA!G577 -> 0 | H578: =ESTADISTICA!H577 -> 0 | ... AI578: =ESTADISTICA!AI577 -> 0
A579: =ESTADISTICA!A578 -> 0 | B579: =ESTADISTICA!B578 -> 0 | C579: =ESTADISTICA!C578 -> 0 | D579: =ESTADISTICA!D578 -> 0 | E579: =ESTADISTICA!E578 -> 0 | F579: =ESTADISTICA!F578 -> 0 | G579: =ESTADISTICA!G578 -> 0 | H579: =ESTADISTICA!H578 -> 0 | ... AI579: =ESTADISTICA!AI578 -> 0
A580: =ESTADISTICA!A579 -> 0 | B580: =ESTADISTICA!B579 -> 0 | C580: =ESTADISTICA!C579 -> 0 | D580: =ESTADISTICA!D579 -> 0 | E580: =ESTADISTICA!E579 -> 0 | F580: =ESTADISTICA!F579 -> 0 | G580: =ESTADISTICA!G579 -> 0 | H580: =ESTADISTICA!H579 -> 0 | ... AI580: =ESTADISTICA!AI579 -> 0
A581: =ESTADISTICA!A580 -> 0 | B581: =ESTADISTICA!B580 -> 0 | C581: =ESTADISTICA!C580 -> 0 | D581: =ESTADISTICA!D580 -> 0 | E581: =ESTADISTICA!E580 -> 0 | F581: =ESTADISTICA!F580 -> 0 | G581: =ESTADISTICA!G580 -> 0 | H581: =ESTADISTICA!H580 -> 0 | ... AI581: =ESTADISTICA!AI580 -> 0
A582: =ESTADISTICA!A581 -> 0 | B582: =ESTADISTICA!B581 -> 0 | C582: =ESTADISTICA!C581 -> 0 | D582: =ESTADISTICA!D581 -> 0 | E582: =ESTADISTICA!E581 -> 0 | F582: =ESTADISTICA!F581 -> 0 | G582: =ESTADISTICA!G581 -> 0 | H582: =ESTADISTICA!H581 -> 0 | ... AI582: =ESTADISTICA!AI581 -> 0
A583: =ESTADISTICA!A582 -> 0 | B583: =ESTADISTICA!B582 -> 0 | C583: =ESTADISTICA!C582 -> 0 | D583: =ESTADISTICA!D582 -> 0 | E583: =ESTADISTICA!E582 -> 0 | F583: =ESTADISTICA!F582 -> 0 | G583: =ESTADISTICA!G582 -> 0 | H583: =ESTADISTICA!H582 -> 0 | ... AI583: =ESTADISTICA!AI582 -> 0
...

Sheet APAGADOS ANTENA
C1: TOTAL PTO A FO
E2: APAGADOS | F2: =COUNTIFS(F4:F500, "=APAGADO",E4:E500,"=PTO A FO") -> 14 | G2: =COUNTIFS(G4:G500, "=APAGADO",E4:E500,"=PTO A FO") -> 12 | H2: =COUNTIFS(H4:H500, "=APAGADO",E4:E500,"=PTO A FO") -> 14 | I2: =COUNTIFS(I4:I500, "=APAGADO",E4:E500,"=PTO A FO") -> 12 | J2: =COUNTIFS(J4:J500, "=APAGADO",E4:E500,"=PTO A FO") -> 12 | K2: =COUNTIFS(K4:K500, "=APAGADO",E4:E500,"=PTO A FO") -> 0 | L2: =COUNTIFS(L4:L500, "=APAGADO",E4:E500,"=PTO A FO") -> 0 | M2: =COUNTIFS(M4:M500, "=APAGADO",E4:E500,"=PTO A FO") -> 0 | N2: =COUNTIFS(N4:N500, "=APAGADO",E4:E500,"=PTO A FO") -> 0 | O2: =COUNTIFS(O4:O500, "=APAGADO",E4:E500,"=PTO A FO") -> 0 | P2: =COUNTIFS(P4:P500, "=APAGADO",E4:E500,"=PTO A FO") -> 0 | Q2: =COUNTIFS(Q4:Q500, "=APAGADO",E4:E500,"=PTO A FO") -> 0 | R2: =COUNTIFS(R4:R500, "=APAGADO",E4:E500,"=PTO A FO") -> 0 | S2: =COUNTIFS(S4:S500, "=APAGADO",E4:E500,"=PTO A FO") -> 0 | T2: =COUNTIFS(T4:T500, "=APAGADO",E4:E500,"=PTO A FO") -> 0 | U2: =COUNTIFS(U4:U500, "=APAGADO",E4:E500,"=PTO A FO") -> 0 | V2: =COUNTIFS(V4:V500, "=APAGADO",E4:E500,"=PTO A FO") -> 0 | W2: =COUNTIFS(W4:W500, "=APAGADO",E4:E500,"=PTO A FO") -> 0 | X2: =COUNTIFS(X4:X500, "=APAGADO",E4:E500,"=PTO A FO") -> 0 | Y2: =COUNTIFS(Y4:Y500, "=APAGADO",E4:E500,"=PTO A FO") -> 0 | Z2: =COUNTIFS(Z4:Z500, "=APAGADO",E4:E500,"=PTO A FO") -> 0 | AA2: =COUNTIFS(AA4:AA500, "=APAGADO",E4:E500,"=PTO A FO") -> 0 | AB2: =COUNTIFS(AB4:AB500, "=APAGADO",E4:E500,"=PTO A FO") -> 0 | AC2: =COUNTIFS(AC4:AC500, "=APAGADO",E4:E500,"=PTO A FO") -> 0 | AD2: =COUNTIFS(AD4:AD500, "=APAGADO",E4:E500,"=PTO A FO") -> 0 | AE2: =COUNTIFS(AE4:AE500, "=APAGADO",E4:E500,"=PTO A FO") -> 0 | AF2: =COUNTIFS(AF4:AF500, "=APAGADO",E4:E500,"=PTO A FO") -> 0 | AG2: =COUNTIFS(AG4:AG500, "=APAGADO",E4:E500,"=PTO A FO") -> 0 | AH2: =COUNTIFS(AH4:AH500, "=APAGADO",E4:E500,"=PTO A FO") -> 0 | AI2: =COUNTIFS(AI4:AI500, "=APAGADO",E4:E500,"=PTO A FO") -> 0
A3: =ESTADISTICA!A1 -> Barrio | B3: =ESTADISTICA!B1 -> [Denominacion] | C3: =ESTADISTICA!C1 -> [Ubicacion] | D3: =ESTADISTICA!D1 -> [Tipo de Camara] | E3: =ESTADISTICA!E1 -> [Tipo de Conexion] | F3: =ESTADISTICA!F1 -> 45078 | G3: =ESTADISTICA!G1 -> 45079 | H3: =ESTADISTICA!H1 -> 45080 | ... AI3: =ESTADISTICA!AI1 -> 45107
A4: =ESTADISTICA!A2 -> ALTAMIRA | B4: =ESTADISTICA!B2 -> ALT01 | C4: =ESTADISTICA!C2 -> Calchaqui y Sgto. Cabral | D4: =ESTADISTICA!D2 -> Domo | E4: =ESTADISTICA!E2 -> Fibra Optica | F4: =ESTADISTICA!F2 -> 0 | G4: =ESTADISTICA!G2 -> 0 | H4: =ESTADISTICA!H2 -> 0 | ... AI4: =ESTADISTICA!AI2 -> 0
A5: =ESTADISTICA!A3 -> ALTAMIRA | B5: =ESTADISTICA!B3 -> ALT02 | C5: =ESTADISTICA!C3 -> Calchaqui y Lope de Vega | D5: =ESTADISTICA!D3 -> Domo | E5: =ESTADISTICA!E3 -> PTO A FO | F5: =ESTADISTICA!F3 -> 0 | G5: =ESTADISTICA!G3 -> 0 | H5: =ESTADISTICA!H3 -> 0 | ... AI5: =ESTADISTICA!AI3 -> 0
A6: =ESTADISTICA!A4 -> ALTAMIRA | B6: =ESTADISTICA!B4 -> ALT 03 | C6: =ESTADISTICA!C4 -> Bombero Galarza y Necochea | D6: =ESTADISTICA!D4 -> Domo | E6: =ESTADISTICA!E4 -> FIBRA OPTICA | F6: =ESTADISTICA!F4 -> 0 | G6: =ESTADISTICA!G4 -> 0 | H6: =ESTADISTICA!H4 -> 0 | ... AI6: =ESTADISTICA!AI4 -> 0
A7: =ESTADISTICA!A5 -> ALTAMIRA | B7: =ESTADISTICA!B5 -> ALT 04 | C7: =ESTADISTICA!C5 -> Francia y Necochea | D7: =ESTADISTICA!D5 -> Domo | E7: =ESTADISTICA!E5 -> FIBRA OPTICA | F7: =ESTADISTICA!F5 -> 0 | G7: =ESTADISTICA!G5 -> 0 | H7: =ESTADISTICA!H5 -> 0 | ... AI7: =ESTADISTICA!AI5 -> 0
A8: =ESTADISTICA!A6 -> ALTAMIRA | B8: =ESTADISTICA!B6 -> ALT05 | C8: =ESTADISTICA!C6 -> Av. Calchaqui y Bombero Galarza | D8: =ESTADISTICA!D6 -> Domo | E8: =ESTADISTICA!E6 -> PTO A FO | F8: =ESTADISTICA!F6 -> 0 | G8: =ESTADISTICA!G6 -> 0 | H8: =ESTADISTICA!H6 -> 0 | ... AI8: =ESTADISTICA!AI6 -> 0
A9: =ESTADISTICA!A7 -> ALTAMIRA | B9: =ESTADISTICA!B7 -> ALT 06 | C9: =ESTADISTICA!C7 -> LOPE DE VEGA Y NECOCHEA | D9: =ESTADISTICA!D7 -> Domo | E9: =ESTADISTICA!E7 -> PTO A FO | F9: =ESTADISTICA!F7 -> 0 | G9: =ESTADISTICA!G7 -> 0 | H9: =ESTADISTICA!H7 -> 0 | ... AI9: =ESTADISTICA!AI7 -> 0
A10: =ESTADISTICA!A8 -> ALTAMIRA | B10: =ESTADISTICA!B8 -> ALT07 | C10: =ESTADISTICA!C8 -> AV. CALCHAQUI Y AV. DEL TRABAJO | D10: =ESTADISTICA!D8 -> DOMO | E10: =ESTADISTICA!E8 -> PTO A FO | F10: =ESTADISTICA!F8 -> 0 | G10: =ESTADISTICA!G8 -> 0 | H10: =ESTADISTICA!H8 -> 0 | ... AI10: =ESTADISTICA!AI8 -> 0
A11: =ESTADISTICA!A9 -> ALTAMIRA | B11: =ESTADISTICA!B9 -> ALT 08 | C11: =ESTADISTICA!C9 -> HUMAITA Y NECOCHEA | D11: =ESTADISTICA!D9 -> DOMO | E11: =ESTADISTICA!E9 -> Fibra Optica | F11: =ESTADISTICA!F9 -> 0 | G11: =ESTADISTICA!G9 -> 0 | H11: =ESTADISTICA!H9 -> 0 | ... AI11: =ESTADISTICA!AI9 -> 0
A12: =ESTADISTICA!A10 -> ALTAMIRA | B12: =ESTADISTICA!B10 -> ALT 09 | C12: =ESTADISTICA!C10 -> NECOCHEA Y CURUPAITY | D12: =ESTADISTICA!D10 -> DOMO | E12: =ESTADISTICA!E10 -> Fibra Optica | F12: =ESTADISTICA!F10 -> 0 | G12: =ESTADISTICA!G10 -> 0 | H12: =ESTADISTICA!H10 -> 0 | ... AI12: =ESTADISTICA!AI10 -> 0
A13: =ESTADISTICA!A11 -> ALTAMIRA | B13: =ESTADISTICA!B11 -> ALT 10 | C13: =ESTADISTICA!C11 -> Calchaqui y Francia | D13: =ESTADISTICA!D11 -> Domo | E13: =ESTADISTICA!E11 -> Radio | F13: =ESTADISTICA!F11 -> 0 | G13: =ESTADISTICA!G11 -> 0 | H13: =ESTADISTICA!H11 -> 0 | ... AI13: =ESTADISTICA!AI11 -> 0
A14: =ESTADISTICA!A12 -> AGUSTIN RAMIREZ | B14: =ESTADISTICA!B12 -> ARA 01 | C14: =ESTADISTICA!C12 -> Malambo y Tranquera | D14: =ESTADISTICA!D12 -> Domo | E14: =ESTADISTICA!E12 -> FIBRA OPTICA | F14: =ESTADISTICA!F12 -> 0 | G14: =ESTADISTICA!G12 -> 0 | H14: =ESTADISTICA!H12 -> 0 | ... AI14: =ESTADISTICA!AI12 -> 0
... A206: =ESTADISTICA!A204 -> SAN EMILIO | B206: =ESTADISTICA!B204 -> MFI06 | C206: =ESTADISTICA!C204 -> Con. Gral. Belgrano y Bombero Galarza | D206: =ESTADISTICA!D204 -> DOMO | E206: =ESTADISTICA!E204 -> Radio | F206: =ESTADISTICA!F204 -> 0 | G206: =ESTADISTICA!G204 -> 0 | H206: =ESTADISTICA!H204 -> 0 | ... AI206: =ESTADISTICA!AI204 -> 0
A207: =ESTADISTICA!A206 -> GOBERNADOR MONTEVERDE | B207: =ESTADISTICA!B206 -> MON01 | C207: =ESTADISTICA!C206 -> San Martin y Patricias Argentinas | D207: =ESTADISTICA!D206 -> Fija | E207: =ESTADISTICA!E206 -> Fibra Optica | F207: =ESTADISTICA!F206 -> 0 | G207: =ESTADISTICA!G206 -> 0 | H207: =ESTADISTICA!H206 -> 0 | ... AI207: =ESTADISTICA!AI206 -> 0
A208: =ESTADISTICA!A207 -> GOBERNADOR MONTEVERDE | B208: =ESTADISTICA!B207 -> MON02 | C208: =ESTADISTICA!C207 -> Senzabello y Famatina | D208: =ESTADISTICA!D207 -> Domo | E208: =ESTADISTICA!E207 -> Radio | F208: =ESTADISTICA!F207 -> 0 | G208: =ESTADISTICA!G207 -> 0 | H208: =ESTADISTICA!H207 -> 0 | ... AI208: =ESTADISTICA!AI207 -> 0
A209: =ESTADISTICA!A208 -> GOBERNADOR MONTEVERDE | B209: =ESTADISTICA!B208 -> MON03 | C209: =ESTADISTICA!C208 -> Senzabello y Guemes | D209: =ESTADISTICA!D208 -> Domo | E209: =ESTADISTICA!E208 -> Radio | F209: =ESTADISTICA!F208 -> 0 | G209: =ESTADISTICA!G208 -> 0 | H209: =ESTADISTICA!H208 -> 0 | ... AI209: =ESTADISTICA!AI208 -> 0
A210: =ESTADISTICA!A209 -> GOBERNADOR MONTEVERDE | B210: =ESTADISTICA!B209 -> MON04 | C210: =ESTADISTICA!C209 -> Av. Yrigoyen y San Lorenzo | D210: =ESTADISTICA!D209 -> Domo | E210: =ESTADISTICA!E209 -> Radio | F210: =ESTADISTICA!F209 -> 0 | G210: =ESTADISTICA!G209 -> 0 | H210: =ESTADISTICA!H209 -> 0 | ... AI210: =ESTADISTICA!AI209 -> 0
A211: =ESTADISTICA!A210 -> 9 DE JULIO | B211: =ESTADISTICA!B210 -> NJU 01 | C211: =ESTADISTICA!C210 -> Sallares y Parrillo | D211: =ESTADISTICA!D210 -> Domo | E211: =ESTADISTICA!E210 -> Fibra Optica | F211: =ESTADISTICA!F210 -> APAGADO | G211: =ESTADISTICA!G210 -> APAGADO | H211: =ESTADISTICA!H210 -> APAGADO | ... AI211: =ESTADISTICA!AI210 -> 0
A212: =ESTADISTICA!A211 -> 9 DE JULIO | B212: =ESTADISTICA!B211 -> NJU02 | C212: =ESTADISTICA!C211 -> Ituzaingo y Boccuzzi | D212: =ESTADISTICA!D211 -> Domo | E212: =ESTADISTICA!E211 -> Radio | F212: =ESTADISTICA!F211 -> 0 | G212: =ESTADISTICA!G211 -> 0 | H212: =ESTADISTICA!H211 -> 0 | ... AI212: =ESTADISTICA!AI211 -> 0
A213: =ESTADISTICA!A212 -> 9 DE JULIO | B213: =ESTADISTICA!B212 -> NJU03 | C213: =ESTADISTICA!C212 -> San Juan y Parrillo | D213: =ESTADISTICA!D212 -> Domo | E213: =ESTADISTICA!E212 -> PTO A FO | F213: =ESTADISTICA!F212 -> 0 | G213: =ESTADISTICA!G212 -> 0 | H213: =ESTADISTICA!H212 -> 0 | ... AI213: =ESTADISTICA!AI212 -> 0
A214: =ESTADISTICA!A213 -> 9 DE JULIO | B214: =ESTADISTICA!B213 -> NJU04 | C214: =ESTADISTICA!C213 -> Ituzaingo y 214 A | D214: =ESTADISTICA!D213 -> Domo | E214: =ESTADISTICA!E213 -> Radio | F214: =ESTADISTICA!F213 -> 0 | G214: =ESTADISTICA!G213 -> 0 | H214: =ESTADISTICA!H213 -> 0 | ... AI214: =ESTADISTICA!AI213 -> 0
A215: =ESTADISTICA!A214 -> ZEBALLOS CENTRO | B215: =ESTADISTICA!B214 -> NJU05 | C215: =ESTADISTICA!C214 -> Ituzaingo y Alem | D215: =ESTADISTICA!D214 -> Domo | E215: =ESTADISTICA!E214 -> Radio | F215: =ESTADISTICA!F214 -> 0 | G215: =ESTADISTICA!G214 -> 0 | H215: =ESTADISTICA!H214 -> APAGADO | ... AI215: =ESTADISTICA!AI214 -> 0
A216: =ESTADISTICA!A215 -> CENTRO | B216: =ESTADISTICA!B215 -> NJU06 | C216: =ESTADISTICA!C215 -> Sallares y Rodo | D216: =ESTADISTICA!D215 -> Domo | E216: =ESTADISTICA!E215 -> FIBRA OPTICA | F216: =ESTADISTICA!F215 -> 0 | G216: =ESTADISTICA!G215 -> 0 | H216: =ESTADISTICA!H215 -> 0 | ... AI216: =ESTADISTICA!AI215 -> 0
A217: =ESTADISTICA!A216 -> 9 DE JULIO | B217: =ESTADISTICA!B216 -> NJU07 | C217: =ESTADISTICA!C216 -> Gral. Juan Domingo Peron y Parrillo | D217: =ESTADISTICA!D216 -> Domo | E217: =ESTADISTICA!E216 -> FIBRA OPTICA | F217: =ESTADISTICA!F216 -> 0 | G217: =ESTADISTICA!G216 -> 0 | H217: =ESTADISTICA!H216 -> 0 | ... AI217: =ESTADISTICA!AI216 -> 0
A218: =ESTADISTICA!A217 -> 9 DE JULIO | B218: =ESTADISTICA!B217 -> NJU 08 | C218: =ESTADISTICA!C217 -> BOCCUZZI Y O HIGGINS | D218: =ESTADISTICA!D217 -> DOMO | E218: =ESTADISTICA!E217 -> Radio | F218: =ESTADISTICA!F217 -> 0 | G218: =ESTADISTICA!G217 -> 0 | H218: =ESTADISTICA!H217 -> 0 | ... AI218: =ESTADISTICA!AI217 -> 0
... A539: =ESTADISTICA!A538 -> 0 | B539: =ESTADISTICA!B538 -> 0 | C539: =ESTADISTICA!C538 -> 0 | D539: =ESTADISTICA!D538 -> 0 | E539: =ESTADISTICA!E538 -> 0 | F539: =ESTADISTICA!F538 -> 0 | G539: =ESTADISTICA!G538 -> 0 | H539: =ESTADISTICA!H538 -> 0 | ... AI539: =ESTADISTICA!AI538 -> 0

Sheet APAGADOS RADIO
C1: TOTAL RADIO | D1: =COUNTIFS(E4:E400,"=radio") -> 91
E2: APAGADOS | F2: =COUNTIFS(F4:F500, "=APAGADO",E4:E500,"=radio") -> 7 | G2: =COUNTIFS(G4:G500, "=APAGADO",E4:E500,"=radio") -> 4 | H2: =COUNTIFS(H4:H500, "=APAGADO",E4:E500,"=radio") -> 6 | I2: =COUNTIFS(I4:I500, "=APAGADO",E4:E500,"=radio") -> 4 | J2: =COUNTIFS(J4:J500, "=APAGADO",E4:E500,"=radio") -> 3 | K2: =COUNTIFS(K4:K500, "=APAGADO",E4:E500,"=radio") -> 0 | L2: =COUNTIFS(L4:L500, "=APAGADO",E4:E500,"=radio") -> 0 | M2: =COUNTIFS(M4:M500, "=APAGADO",E4:E500,"=radio") -> 0 | N2: =COUNTIFS(N4:N500, "=APAGADO",E4:E500,"=radio") -> 0 | O2: =COUNTIFS(O4:O500, "=APAGADO",E4:E500,"=radio") -> 0 | P2: =COUNTIFS(P4:P500, "=APAGADO",E4:E500,"=radio") -> 0 | Q2: =COUNTIFS(Q4:Q367, "=APAGADO",E4:E367,"=radio") -> 0 | R2: =COUNTIFS(R4:R500, "=APAGADO",E4:E500,"=radio") -> 0 | S2: =COUNTIFS(S4:S500, "=APAGADO",E4:E500,"=radio") -> 0 | T2: =COUNTIFS(T4:T500, "=APAGADO",E4:E500,"=radio") -> 0 | U2: =COUNTIFS(U4:U500, "=APAGADO",E4:E500,"=radio") -> 0 | V2: =COUNTIFS(V4:V500, "=APAGADO",E4:E500,"=radio") -> 0 | W2: =COUNTIFS(W4:W500, "=APAGADO",E4:E500,"=radio") -> 0 | X2: =COUNTIFS(X4:X500, "=APAGADO",E4:E500,"=radio") -> 0 | Y2: =COUNTIFS(Y4:Y500, "=APAGADO",E4:E500,"=radio") -> 0 | Z2: =COUNTIFS(Z4:Z500, "=APAGADO",E4:E500,"=radio") -> 0 | AA2: =COUNTIFS(AA4:AA500, "=APAGADO",E4:E500,"=radio") -> 0 | AB2: =COUNTIFS(AB4:AB500, "=APAGADO",E4:E500,"=radio") -> 0 | AC2: =COUNTIFS(AC4:AC500, "=APAGADO",E4:E500,"=radio") -> 0 | AD2: =COUNTIFS(AD4:AD500, "=APAGADO",E4:E500,"=radio") -> 0 | AE2: =COUNTIFS(AE4:AE500, "=APAGADO",E4:E500,"=radio") -> 0 | AF2: =COUNTIFS(AF4:AF500, "=APAGADO",E4:E500,"=radio") -> 0 | AG2: =COUNTIFS(AG4:AG500, "=APAGADO",E4:E500,"=radio") -> 0 | AH2: =COUNTIFS(AH4:AH500, "=APAGADO",F4:F500,"=radio") -> 0 | AI2: =COUNTIFS(AI4:AI500, "=APAGADO",G4:G500,"=radio") -> 0 | AJ2: =COUNTIFS(AJ4:AJ500, "=APAGADO",H4:H500,"=radio") -> 0
A3: =ESTADISTICA!A1 -> Barrio | B3: =ESTADISTICA!B1 -> [Denominacion] | C3: =ESTADISTICA!C1 -> [Ubicacion] | D3: =ESTADISTICA!D1 -> [Tipo de Camara] | E3: =ESTADISTICA!E1 -> [Tipo de Conexion] | F3: =ESTADISTICA!F1 -> 45078 | G3: =ESTADISTICA!G1 -> 45079 | H3: =ESTADISTICA!H1 -> 45080 | ... AJ3: =ESTADISTICA!AJ1 -> #REF!
A4: =ESTADISTICA!A2 -> ALTAMIRA | B4: =ESTADISTICA!B2 -> ALT01 | C4: =ESTADISTICA!C2 -> Calchaqui y Sgto. Cabral | D4: =ESTADISTICA!D2 -> Domo | E4: =ESTADISTICA!E2 -> Fibra Optica | F4: =ESTADISTICA!F2 -> 0 | G4: =ESTADISTICA!G2 -> 0 | H4: =ESTADISTICA!H2 -> 0 | ... AI4: =ESTADISTICA!AI2 -> 0
A5: =ESTADISTICA!A3 -> ALTAMIRA | B5: =ESTADISTICA!B3 -> ALT02 | C5: =ESTADISTICA!C3 -> Calchaqui y Lope de Vega | D5: =ESTADISTICA!D3 -> Domo | E5: =ESTADISTICA!E3 -> PTO A FO | F5: =ESTADISTICA!F3 -> 0 | G5: =ESTADISTICA!G3 -> 0 | H5: =ESTADISTICA!H3 -> 0 | ... AI5: =ESTADISTICA!AI3 -> 0
A6: =ESTADISTICA!A4 -> ALTAMIRA | B6: =ESTADISTICA!B4 -> ALT 03 | C6: =ESTADISTICA!C4 -> Bombero Galarza y Necochea | D6: =ESTADISTICA!D4 -> Domo | E6: =ESTADISTICA!E4 -> FIBRA OPTICA | F6: =ESTADISTICA!F4 -> 0 | G6: =ESTADISTICA!G4 -> 0 | H6: =ESTADISTICA!H4 -> 0 | ... AI6: =ESTADISTICA!AI4 -> 0
A7: =ESTADISTICA!A5 -> ALTAMIRA | B7: =ESTADISTICA!B5 -> ALT 04 | C7: =ESTADISTICA!C5 -> Francia y Necochea | D7: =ESTADISTICA!D5 -> Domo | E7: =ESTADISTICA!E5 -> FIBRA OPTICA | F7: =ESTADISTICA!F5 -> 0 | G7: =ESTADISTICA!G5 -> 0 | H7: =ESTADISTICA!H5 -> 0 | ... AI7: =ESTADISTICA!AI5 -> 0
A8: =ESTADISTICA!A6 -> ALTAMIRA | B8: =ESTADISTICA!B6 -> ALT05 | C8: =ESTADISTICA!C6 -> Av. Calchaqui y Bombero Galarza | D8: =ESTADISTICA!D6 -> Domo | E8: =ESTADISTICA!E6 -> PTO A FO | F8: =ESTADISTICA!F6 -> 0 | G8: =ESTADISTICA!G6 -> 0 | H8: =ESTADISTICA!H6 -> 0 | ... AI8: =ESTADISTICA!AI6 -> 0
A9: =ESTADISTICA!A7 -> ALTAMIRA | B9: =ESTADISTICA!B7 -> ALT 06 | C9: =ESTADISTICA!C7 -> LOPE DE VEGA Y NECOCHEA | D9: =ESTADISTICA!D7 -> Domo | E9: =ESTADISTICA!E7 -> PTO A FO | F9: =ESTADISTICA!F7 -> 0 | G9: =ESTADISTICA!G7 -> 0 | H9: =ESTADISTICA!H7 -> 0 | ... AI9: =ESTADISTICA!AI7 -> 0
A10: =ESTADISTICA!A8 -> ALTAMIRA | B10: =ESTADISTICA!B8 -> ALT07 | C10: =ESTADISTICA!C8 -> AV. CALCHAQUI Y AV. DEL TRABAJO | D10: =ESTADISTICA!D8 -> DOMO | E10: =ESTADISTICA!E8 -> PTO A FO | F10: =ESTADISTICA!F8 -> 0 | G10: =ESTADISTICA!G8 -> 0 | H10: =ESTADISTICA!H8 -> 0 | ... AI10: =ESTADISTICA!AI8 -> 0
A11: =ESTADISTICA!A9 -> ALTAMIRA | B11: =ESTADISTICA!B9 -> ALT 08 | C11: =ESTADISTICA!C9 -> HUMAITA Y NECOCHEA | D11: =ESTADISTICA!D9 -> DOMO | E11: =ESTADISTICA!E9 -> Fibra Optica | F11: =ESTADISTICA!F9 -> 0 | G11: =ESTADISTICA!G9 -> 0 | H11: =ESTADISTICA!H9 -> 0 | ... AI11: =ESTADISTICA!AI9 -> 0
A12: =ESTADISTICA!A10 -> ALTAMIRA | B12: =ESTADISTICA!B10 -> ALT 09 | C12: =ESTADISTICA!C10 -> NECOCHEA Y CURUPAITY | D12: =ESTADISTICA!D10 -> DOMO | E12: =ESTADISTICA!E10 -> Fibra Optica | F12: =ESTADISTICA!F10 -> 0 | G12: =ESTADISTICA!G10 -> 0 | H12: =ESTADISTICA!H10 -> 0 | ... AI12: =ESTADISTICA!AI10 -> 0
A13: =ESTADISTICA!A11 -> ALTAMIRA | B13: =ESTADISTICA!B11 -> ALT 10 | C13: =ESTADISTICA!C11 -> Calchaqui y Francia | D13: =ESTADISTICA!D11 -> Domo | E13: =ESTADISTICA!E11 -> Radio | F13: =ESTADISTICA!F11 -> 0 | G13: =ESTADISTICA!G11 -> 0 | H13: =ESTADISTICA!H11 -> 0 | ... AI13: =ESTADISTICA!AI11 -> 0
A14: =ESTADISTICA!A12 -> AGUSTIN RAMIREZ | B14: =ESTADISTICA!B12 -> ARA 01 | C14: =ESTADISTICA!C12 -> Malambo y Tranquera | D14: =ESTADISTICA!D12 -> Domo | E14: =ESTADISTICA!E12 -> FIBRA OPTICA | F14: =ESTADISTICA!F12 -> 0 | G14: =ESTADISTICA!G12 -> 0 | H14: =ESTADISTICA!H12 -> 0 | ... AI14: =ESTADISTICA!AI12 -> 0
A15: =ESTADISTICA!A13 -> BELGRANO | B15: =ESTADISTICA!B13 -> BEL 01 | C15: =ESTADISTICA!C13 -> San Martin y Dardo Rocha | D15: =ESTADISTICA!D13 -> DOMO | E15: =ESTADISTICA!E13 -> FIBRA OPTICA | F15: =ESTADISTICA!F13 -> 0 | G15: =ESTADISTICA!G13 -> 0 | H15: =ESTADISTICA!H13 -> 0 | ... AJ15: =ESTADISTICA!AJ13 -> #REF!
A16: =ESTADISTICA!A14 -> BOSQUES CENTRO | B16: =ESTADISTICA!B14 -> BOSQC 01 | C16: =ESTADISTICA!C14 -> LUIS AGOTE E/DANUNCIO Y CAMPOAMOR | D16: =ESTADISTICA!D14 -> Fija | E16: =ESTADISTICA!E14 -> Radio | F16: =ESTADISTICA!F14 -> 0 | G16: =ESTADISTICA!G14 -> 0 | H16: =ESTADISTICA!H14 -> 0 | ... AI16: =ESTADISTICA!AI14 -> 0
A17: =ESTADISTICA!A15 -> BOSQUES CENTRO | B17: =ESTADISTICA!B15 -> BOSQC 02 | C17: =ESTADISTICA!C15 -> LUIS AGOTE E/DANUNCIO Y CAMPOAMOR | D17: =ESTADISTICA!D15 -> Fija | E17: =ESTADISTICA!E15 -> Radio | F17: =ESTADISTICA!F15 -> 0 | G17: =ESTADISTICA!G15 -> 0 | H17: =ESTADISTICA!H15 -> 0 | ... AI17: =ESTADISTICA!AI15 -> 0
A18: =ESTADISTICA!A16 -> BOSQUES CENTRO | B18: =ESTADISTICA!B16 -> BOSQC 03 | C18: =ESTADISTICA!C16 -> BENAVENTE Y LUIS AGOTE | D18: =ESTADISTICA!D16 -> Fija | E18: =ESTADISTICA!E16 -> Radio | F18: =ESTADISTICA!F16 -> 0 | G18: =ESTADISTICA!G16 -> 0 | H18: =ESTADISTICA!H16 -> 0 | ... AI18: =ESTADISTICA!AI16 -> 0
A19: =ESTADISTICA!A17 -> BOSQUES CENTRO | B19: =ESTADISTICA!B17 -> BOSQC 04 | C19: =ESTADISTICA!C17 -> BENAVENTE Y LUIS AGOTE | D19: =ESTADISTICA!D17 -> Fija | E19: =ESTADISTICA!E17 -> Radio | F19: =ESTADISTICA!F17 -> 0 | G19: =ESTADISTICA!G17 -> 0 | H19: =ESTADISTICA!H17 -> 0 | ... AI19: =ESTADISTICA!AI17 -> 0
A20: =ESTADISTICA!A18 -> BOSQUES CENTRO | B20: =ESTADISTICA!B18 -> BOSQC 05 | C20: =ESTADISTICA!C18 -> LUIS AGOTE Y RUTA 36 | D20: =ESTADISTICA!D18 -> Fija | E20: =ESTADISTICA!E18 -> Radio | F20: =ESTADISTICA!F18 -> 0 | G20: =ESTADISTICA!G18 -> 0 | H20: =ESTADISTICA!H18 -> 0 | ... AI20: =ESTADISTICA!AI18 -> 0
A21: =ESTADISTICA!A19 -> BOSQUES CENTRO | B21: =ESTADISTICA!B19 -> BOSQC 06 | C21: =ESTADISTICA!C19 -> LUIS AGOTE Y RUTA 36 | D21: =ESTADISTICA!D19 -> Fija | E21: =ESTADISTICA!E19 -> Radio | F21: =ESTADISTICA!F19 -> 0 | G21: =ESTADISTICA!G19 -> 0 | H21: =ESTADISTICA!H19 -> 0 | ... AI21: =ESTADISTICA!AI19 -> 0
A22: =ESTADISTICA!A20 -> CENTRO | B22: =ESTADISTICA!B20 -> CEN01 | C22: =ESTADISTICA!C20 -> San Martin y 9 de Julio | D22: =ESTADISTICA!D20 -> Fija | E22: =ESTADISTICA!E20 -> Fibra Optica | F22: =ESTADISTICA!F20 -> 0 | G22: =ESTADISTICA!G20 -> 0 | H22: =ESTADISTICA!H20 -> 0 | ... AI22: =ESTADISTICA!AI20 -> 0
A23: =ESTADISTICA!A21 -> CENTRO | B23: =ESTADISTICA!B21 -> CEN02 | C23: =ESTADISTICA!C21 -> San Martin y Almafuerte | D23: =ESTADISTICA!D21 -> Fija | E23: =ESTADISTICA!E21 -> Fibra Optica | F23: =ESTADISTICA!F21 -> 0 | G23: =ESTADISTICA!G21 -> 0 | H23: =ESTADISTICA!H21 -> 0 | ... AI23: =ESTADISTICA!AI21 -> 0
A24: =ESTADISTICA!A22 -> CENTRO | B24: =ESTADISTICA!B22 -> CEN03 | C24: =ESTADISTICA!C22 -> San Martin y Sallares | D24: =ESTADISTICA!D22 -> Domo | E24: =ESTADISTICA!E22 -> Fibra Optica | F24: =ESTADISTICA!F22 -> 0 | G24: =ESTADISTICA!G22 -> 0 | H24: =ESTADISTICA!H22 -> 0 | ... AI24: =ESTADISTICA!AI22 -> 0
A25: =ESTADISTICA!A23 -> CENTRO | B25: =ESTADISTICA!B23 -> CEN04 | C25: =ESTADISTICA!C23 -> San Martin y Contreras | D25: =ESTADISTICA!D23 -> Domo | E25: =ESTADISTICA!E23 -> Fibra Optica | F25: =ESTADISTICA!F23 -> 0 | G25: =ESTADISTICA!G23 -> 0 | H25: =ESTADISTICA!H23 -> 0 | ... AI25: =ESTADISTICA!AI23 -> 0
A26: =ESTADISTICA!A24 -> CENTRO | B26: =ESTADISTICA!B24 -> CEN 05 | C26: =ESTADISTICA!C24 -> Bocuzzi e/España y San Martin | D26: =ESTADISTICA!D24 -> DOMO | E26: =ESTADISTICA!E24 -> Fibra Optica | F26: =ESTADISTICA!F24 -> 0 | G26: =ESTADISTICA!G24 -> 0 | H26: =ESTADISTICA!H24 -> 0 | ... AI26: =ESTADISTICA!AI24 -> 0
A27: =ESTADISTICA!A25 -> CENTRO | B27: =ESTADISTICA!B25 -> CEN06 | C27: =ESTADISTICA!C25 -> Monteagudo y A.del Valle | D27: =ESTADISTICA!D25 -> Fija | E27: =ESTADISTICA!E25 -> Fibra Optica | F27: =ESTADISTICA!F25 -> 0 | G27: =ESTADISTICA!G25 -> 0 | H27: =ESTADISTICA!H25 -> 0 | ... AI27: =ESTADISTICA!AI25 -> 0
... A39: =ESTADISTICA!A37 -> CENTRO | B39: =ESTADISTICA!B37 -> CEN18 | C39: =ESTADISTICA!C37 -> Monteagudo e/Mitre y Sallares | D39: =ESTADISTICA!D37 -> Fija | E39: =ESTADISTICA!E37 -> Fibra Optica | F39: =ESTADISTICA!F37 -> 0 | G39: =ESTADISTICA!G37 -> 0 | H39: =ESTADISTICA!H37 -> 0 | ... AI39: =ESTADISTICA!AI37 -> 0
A40: =ESTADISTICA!A38 -> CENTRO | B40: =ESTADISTICA!B38 -> CEN19 | C40: =ESTADISTICA!C38 -> Chacabuco y 25 de Mayo | D40: =ESTADISTICA!D38 -> Fija | E40: =ESTADISTICA!E38 -> Fibra Optica | F40: =ESTADISTICA!F38 -> 0 | G40: =ESTADISTICA!G38 -> 0 | H40: =ESTADISTICA!H38 -> 0 | ... AJ40: =ESTADISTICA!AJ38 -> #REF!
A41: =ESTADISTICA!A39 -> LOMAS DE MONTEVERDE | B41: =ESTADISTICA!B39 -> CEN20 | C41: =ESTADISTICA!C39 -> Pte. Illia y Las Heras | D41: =ESTADISTICA!D39 -> Domo | E41: =ESTADISTICA!E39 -> Fibra Optica | F41: =ESTADISTICA!F39 -> 0 | G41: =ESTADISTICA!G39 -> 0 | H41: =ESTADISTICA!H39 -> 0 | ... AI41: =ESTADISTICA!AI39 -> 0
