Workbook
Name _25_de_agosto: 'RESUMEN TOTAL'!$A$4:$D$383
Name _25_de_agosto_3: 'RESUMEN TOTAL'!$A$4:$D$395
Name BONOMOcam: Hoja1!$B$2
Name CANTIDAD_DE_CAMARAS: 'RESUMEN TOTAL'!$B$1
Name COSEIDIcam: Hoja1!$B$4

Sheet RESUMEN TOTAL
A1: CANTIDAD DE CAMARAS | B1: =COUNTA(B5:B617) -> 523 | D1: PORCIENTO DE CAIDAS | L1: =(L3)/(L2+L3) -> 0.070745698 | M1: =(M3)/(M2+M3) -> 0.07456979 | N1: =(N3)/(N2+N3) -> 0.066921606 | O1: =(O3)/(O2+O3) -> 0.055449331 | P1: =(P3)/(P2+P3) -> 0.063097514 | Q1: =(Q3)/(Q2+Q3) -> 0 | R1: =(R3)/(R2+R3) -> 0 | S1: =(S3)/(S2+S3) -> 0 | ... X1: =(X3)/(X2+X3) -> 0 | Z1: =(Z3)/(Z2+Z3) -> 0 | AA1: =(AA3)/(AA2+AA3) -> 0 | AB1: =(AB3)/(AB2+AB3) -> 0 | AC1: =(AC3)/(AC2+AC3) -> 0 | AD1: =(AD3)/(AD2+AD3) -> 0 | AE1: =(AE3)/(AE2+AE3) -> 0 | AF1: =(AF3)/(AF2+AF3) -> 0 | AG1: =(AG3)/(AG2+AG3) -> 0 | ... AP1: =(AP3)/(AP2+AP3) -> 0
D2: FUNCIONAN | L2: =B1-L3 -> 486 | M2: =CANTIDAD_DE_CAMARAS-M3 -> 484 | N2: =CANTIDAD_DE_CAMARAS-N3 -> 488 | O2: =CANTIDAD_DE_CAMARAS-O3 -> 494 | P2: =CANTIDAD_DE_CAMARAS-P3 -> 490 | Q2: =CANTIDAD_DE_CAMARAS-Q3 -> 523 | R2: =CANTIDAD_DE_CAMARAS-R3 -> 523 | S2: =CANTIDAD_DE_CAMARAS-S3 -> 523 | T2: =CANTIDAD_DE_CAMARAS-T3 -> 523 | ... AP2: =CANTIDAD_DE_CAMARAS-AP3 -> 523
D3: CAIDAS | L3: =COUNTIF(L4:L617, "apagado") -> 37 | M3: =COUNTIF(M4:M617, "apagado") -> 39 | N3: =COUNTIF(N4:N617, "apagado") -> 35 | O3: =COUNTIF(O4:O617, "apagado") -> 29 | P3: =COUNTIF(P4:P617, "apagado") -> 33 | Q3: =COUNTIF(Q4:Q617, "apagado") -> 0 | R3: =COUNTIF(R4:R617, "apagado") -> 0 | S3: =COUNTIF(S4:S617, "apagado") -> 0 | ... W3: =COUNTIF(W4:W617, "apagado") -> 0 | X3: =COUNTIF(X4:X517, "apagado") -> 0 | Y3: =COUNTIF(Y4:Y517, "apagado") -> 0 | Z3: =COUNTIF(Z4:Z617, "apagado") -> 0 | AA3: =COUNTIF(AA4:AA617, "apagado") -> 0 | AB3: =COUNTIF(AB4:AB617, "apagado") -> 0 | AC3: =COUNTIF(AC4:AC617, "apagado") -> 0 | AD3: =COUNTIF(AD4:AD617, "apagado") -> 0 | AE3: =COUNTIF(AE4:AE617, "apagado") -> 0 | AF3: =COUNTIF(AF4:AF617, "apagado") -> 0 | AG3: =COUNTIF(AG4:AG617, "apagado") -> 0 | ... AP3: =COUNTIF(AP4:AP617, "apagado") -> 0
A4: Barrio | B4: [Denominacion] | C4: [Empresa Mantenimiento] | D4: [Ubicacion] | E4: [Tipo de Camara] | F4: [Tipo de Conexion] | G4: Destino | I4: DIAS FUNCIONANDO | J4: DIAS CAIDA | K4: EFECTIVIDAD | L4: 45200 | M4: 45201 | N4: 45202 | O4: 45203 | P4: 45204 | Q4: 45205 | R4: 45206 | S4: 45207 | T4: 45208 | U4: 45209 | V4: 45210 | W4: 45211 | X4: 45212 | Y4: 45213 | Z4: 45214 | AA4: 45215 | AB4: 45216 | AC4: 45217 | AD4: 45218 | AE4: 45219 | AF4: 45220 | AG4: 45221 | AH4: 45222 | AI4: 45223 | AJ4: 45224 | AK4: 45225 | AL4: 45226 | AM4: 45227 | AN4: 45228 | AO4: 45229 | AP4: 45230
A5: ALTAMIRA | B5: ALT01 | C5: BONOMO | D5: Calchaqui y Sgto. Cabral | E5: Domo | F5: Fibra Optica | H5: 172.20.10.6 | I5: =COUNTIF(L5:AM5,"") -> 28 | J5: =COUNTIF(L5:AM5,"APAGADO") -> 0 | K5: =(I5)/(J5+I5) -> 1
A6: ALTAMIRA | B6: ALT02 | C6: BONOMO | D6: Calchaqui y Lope de Vega | E6: Domo | F6: PTO A FO | G6: CABRAL Y CALCHAQUI | H6: 172.20.12.218 | I6: =COUNTIF(L6:AM6,"") -> 28 | J6: =COUNTIF(L6:AM6,"APAGADO") -> 0 | K6: =(I6)/(J6+I6) -> 1
A7: ALTAMIRA | B7: ALT 03 | C7: BONOMO | D7: Bombero Galarza y Necochea | E7: Domo | F7: Fibra Optica | H7: 172.20.12.54 | I7: =COUNTIF(L7:AM7,"") -> 28 | J7: =COUNTIF(L7:AM7,"APAGADO") -> 0 | K7: =(I7)/(J7+I7) -> 1
A8: ALTAMIRA | B8: ALT 04 | C8: BONOMO | D8: Francia y Necochea | E8: Domo | F8: Fibra Optica | H8: 172.20.12.55 | I8: =COUNTIF(L8:AM8,"") -> 28 | J8: =COUNTIF(L8:AM8,"APAGADO") -> 0 | K8: =(I8)/(J8+I8) -> 1
A9: ALTAMIRA | B9: ALT05 | C9: BONOMO | D9: Av. Calchaqui y Bombero Galarza | E9: Domo | F9: PTO A FO | G9: NECOCHEA Y GALARZA | H9: 172.20.12.216 | I9: =COUNTIF(L9:AM9,"") -> 28 | J9: =COUNTIF(L9:AM9,"APAGADO") -> 0 | K9: =(I9)/(J9+I9) -> 1
A10: ALTAMIRA | B10: ALT 06 | C10: BONOMO | D10: LOPE DE VEGA Y NECOCHEA | E10: Domo | F10: PTO A FO | G10: NECOCHEA Y GALARZA | H10: 172.20.12.12 | I10: =COUNTIF(L10:AM10,"") -> 28 | J10: =COUNTIF(L10:AM10,"APAGADO") -> 0 | K10: =(I10)/(J10+I10) -> 1
A11: ALTAMIRA | B11: ALT07 | C11: BONOMO | D11: AV. CALCHAQUI Y AV. DEL TRABAJO | E11: DOMO | F11: PTO A FO | G11: CABRAL Y CALCHAQUI | H11: 172.20.10.57 | I11: =COUNTIF(L11:AM11,"") -> 28 | J11: =COUNTIF(L11:AM11,"APAGADO") -> 0 | K11: =(I11)/(J11+I11) -> 1
A12: ALTAMIRA | B12: ALT 08 | C12: BONOMO | D12: HUMAITA Y NECOCHEA | E12: DOMO | F12: Fibra Optica | H12: 172.20.11.215 | I12: =COUNTIF(L12:AM12,"") -> 28 | J12: =COUNTIF(L12:AM12,"APAGADO") -> 0 | K12: =(I12)/(J12+I12) -> 1
A13: ALTAMIRA | B13: ALT 09 | C13: BONOMO | D13: NECOCHEA Y CURUPAITY | E13: DOMO | F13: Fibra Optica | H13: 172.20.11.216 | I13: =COUNTIF(L13:AM13,"") -> 28 | J13: =COUNTIF(L13:AM13,"APAGADO") -> 0 | K13: =(I13)/(J13+I13) -> 1
A14: ALTAMIRA | B14: ALT 10 | C14: BONOMO | D14: Calchaqui y Francia | E14: Domo | F14: Radio | H14: 172.20.12.156 | I14: =COUNTIF(L14:AM14,"") -> 28 | J14: =COUNTIF(L14:AM14,"APAGADO") -> 0 | K14: =(I14)/(J14+I14) -> 1
A15: AGUSTIN RAMIREZ | B15: ARA 01 | C15: COSEIDI | D15: Malambo y Tranquera | E15: Domo | F15: Fibra Optica | H15: 172.20.12.110 | I15: =COUNTIF(L15:AM15,"") -> 23 | J15: =COUNTIF(L15:AM15,"APAGADO") -> 5 | K15: =(I15)/(J15+I15) -> 0.82142857 | L15: APAGADO | M15: APAGADO | N15: APAGADO | O15: APAGADO | P15: APAGADO
A16: BELGRANO | B16: BEL 01 | C16: BONOMO | D16: San Martin y Dardo Rocha | E16: DOMO | F16: Fibra Optica | H16: 172.20.12.64 | I16: =COUNTIF(L16:AM16,"") -> 28 | J16: =COUNTIF(L16:AM16,"APAGADO") -> 0 | K16: =(I16)/(J16+I16) -> 1
A17: BELGRANO | B17: BEL 02 | C17: BONOMO | D17: Guardia vieja y Fronteriz | E17: DOMO | F17: Fibra Optica | I17: =COUNTIF(L17:AM17,"") -> 28 | J17: =COUNTIF(L17:AM17,"APAGADO") -> 0 | K17: =(I17)/(J17+I17) -> 1
A18: BOSQUES CENTRO | B18: BOSQC 01 | C18: COSEIDI | D18: LUIS AGOTE E/DANUNCIO Y CAMPOAMOR | E18: Fija | F18: Radio | H18: 172.20.11.15 | I18: =COUNTIF(L18:AM18,"") -> 25 | J18: =COUNTIF(L18:AM18,"APAGADO") -> 3 | K18: =(I18)/(J18+I18) -> 0.89285714 | L18: APAGADO | M18: APAGADO | P18: APAGADO
A19: BOSQUES CENTRO | B19: BOSQC 02 | C19: COSEIDI | D19: LUIS AGOTE E/DANUNCIO Y CAMPOAMOR | E19: Fija | F19: Radio | H19: 172.20.11.16 | I19: =COUNTIF(L19:AM19,"") -> 25 | J19: =COUNTIF(L19:AM19,"APAGADO") -> 3 | K19: =(I19)/(J19+I19) -> 0.89285714 | L19: APAGADO | M19: APAGADO | P19: APAGADO
A20: BOSQUES CENTRO | B20: BOSQC 03 | C20: COSEIDI | D20: BENAVENTE Y LUIS AGOTE | E20: Fija | F20: Radio | H20: 172.20.11.13 | I20: =COUNTIF(L20:AM20,"") -> 25 | J20: =COUNTIF(L20:AM20,"APAGADO") -> 3 | K20: =(I20)/(J20+I20) -> 0.89285714 | L20: APAGADO | M20: APAGADO | P20: APAGADO
A21: BOSQUES CENTRO | B21: BOSQC 04 | C21: COSEIDI | D21: BENAVENTE Y LUIS AGOTE | E21: Fija | F21: Radio | H21: 172.20.11.113 | I21: =COUNTIF(L21:AM21,"") -> 25 | J21: =COUNTIF(L21:AM21,"APAGADO") -> 3 | K21: =(I21)/(J21+I21) -> 0.89285714 | L21: APAGADO | M21: APAGADO | P21: APAGADO
A22: BOSQUES CENTRO | B22: BOSQC 05 | C22: COSEIDI | D22: LUIS AGOTE Y RUTA 36 | E22: Fija | F22: Radio | H22: 172.20.11.17 | I22: =COUNTIF(L22:AM22,"") -> 28 | J22: =COUNTIF(L22:AM22,"APAGADO") -> 0 | K22: =(I22)/(J22+I22) -> 1
A23: BOSQUES CENTRO | B23: BOSQC 06 | C23: COSEIDI | D23: LUIS AGOTE Y RUTA 36 | E23: Fija | F23: Radio | H23: 172.20.11.18 | I23: =COUNTIF(L23:AM23,"") -> 28 | J23: =COUNTIF(L23:AM23,"APAGADO") -> 0 | K23: =(I23)/(J23+I23) -> 1
A24: CENTRO | B24: CEN01 | C24: BONOMO | D24: San Martin y 9 de Julio | E24: Fija | F24: Fibra Optica | H24: 172.20.11.10 | I24: =COUNTIF(L24:AM24,"") -> 28 | J24: =COUNTIF(L24:AM24,"APAGADO") -> 0 | K24: =(I24)/(J24+I24) -> 1
A25: CENTRO | B25: CEN02 | C25: BONOMO | D25: San Martin y Almafuerte | E25: Fija | F25: Fibra Optica | H25: 172.20.11.11 | I25: =COUNTIF(L25:AM25,"") -> 23 | J25: =COUNTIF(L25:AM25,"APAGADO") -> 5 | K25: =(I25)/(J25+I25) -> 0.82142857 | L25: APAGADO | M25: APAGADO | N25: APAGADO | O25: APAGADO | P25: APAGADO
A26: CENTRO | B26: CEN03 | C26: BONOMO | D26: San Martin y Sallares | E26: Domo | F26: Fibra Optica | H26: 172.20.12.30 | I26: =COUNTIF(L26:AM26,"") -> 28 | J26: =COUNTIF(L26:AM26,"APAGADO") -> 0 | K26: =(I26)/(J26+I26) -> 1
A27: CENTRO | B27: CEN04 | C27: BONOMO | D27: San Martin y Contreras | E27: Domo | F27: Fibra Optica | H27: 172.20.12.29 | I27: =COUNTIF(L27:AM27,"") -> 28 | J27: =COUNTIF(L27:AM27,"APAGADO") -> 0 | K27: =(I27)/(J27+I27) -> 1
A28: CENTRO | B28: CEN 05 | C28: BONOMO | D28: Bocuzzi e/España y San Martin | E28: DOMO | F28: Fibra Optica | H28: 172.20.10.200 | I28: =COUNTIF(L28:AM28,"") -> 28 | J28: =COUNTIF(L28:AM28,"APAGADO") -> 0 | K28: =(I28)/(J28+I28) -> 1
A29: CENTRO | B29: CEN06 | C29: BONOMO | D29: Monteagudo y A.del Valle | E29: Fija | F29: Fibra Optica | H29: 172.20.10.02 | I29: =COUNTIF(L29:AM29,"") -> 28 | J29: =COUNTIF(L29:AM29,"APAGADO") -> 0 | K29: =(I29)/(J29+I29) -> 1
A30: CENTRO | B30: CEN07 | C30: BONOMO | D30: San Martin y Guemes | E30: DOMO | F30: Fibra Optica | H30: 172.20.11.20 | I30: =COUNTIF(L30:AM30,"") -> 28 | J30: =COUNTIF(L30:AM30,"APAGADO") -> 0 | K30: =(I30)/(J30+I30) -> 1
A31: CENTRO | B31: CEN08 | C31: BONOMO | D31: San Martin y Pte.Peron | E31: Domo | F31: Fibra Optica | H31: 172.20.11.21 | I31: =COUNTIF(L31:AM31,"") -> 28 | J31: =COUNTIF(L31:AM31,"APAGADO") -> 0 | K31: =(I31)/(J31+I31) -> 1
A32: CENTRO | B32: CEN09 | C32: BONOMO | D32: Chacabuco y 25 de Mayo | E32: Domo | F32: Fibra Optica | H32: 172.20.11.22 | I32: =COUNTIF(L32:AM32,"") -> 28 | J32: =COUNTIF(L32:AM32,"APAGADO") -> 0 | K32: =(I32)/(J32+I32) -> 1
A33: CENTRO | B33: CEN10 | C33: BONOMO | D33: Monteagudo y Pte. Peron | E33: Domo | F33: Fibra Optica | H33: 172.20.11.23 | I33: =COUNTIF(L33:AM33,"") -> 28 | J33: =COUNTIF(L33:AM33,"APAGADO") -> 0 | K33: =(I33)/(J33+I33) -> 1
A34: CENTRO | B34: CEN11 | C34: BONOMO | D34: Monteagudo y Bocuzzi | E34: Domo | F34: Fibra Optica | H34: 172.20.10.24 | I34: =COUNTIF(L34:AM34,"") -> 28 | J34: =COUNTIF(L34:AM34,"APAGADO") -> 0 | K34: =(I34)/(J34+I34) -> 1
A35: CENTRO | B35: CEN 12 | C35: BONOMO | D35: Monteagudo y Mitre | E35: Domo | F35: Fibra Optica | H35: 172.20.10.23 | I35: =COUNTIF(L35:AM35,"") -> 28 | J35: =COUNTIF(L35:AM35,"APAGADO") -> 0 | K35: =(I35)/(J35+I35) -> 1
A36: CENTRO | B36: CEN 13 | C36: BONOMO | D36: 25 de Mayo y Maipu | E36: DOMO | F36: Fibra Optica | H36: 172.20.10.20 | I36: =COUNTIF(L36:AM36,"") -> 28 | J36: =COUNTIF(L36:AM36,"APAGADO") -> 0 | K36: =(I36)/(J36+I36) -> 1
A37: CENTRO | B37: CEN14 | C37: BONOMO | D37: Pte.Peron e/Pringles y Brown | E37: Domo | F37: Fibra Optica | H37: 172.20.10.21 | I37: =COUNTIF(L37:AM37,"") -> 28 | J37: =COUNTIF(L37:AM37,"APAGADO") -> 0 | K37: =(I37)/(J37+I37) -> 1
... A39: CENTRO | B39: CEN16 | C39: BONOMO | D39: San Martin y Pte. Peron | E39: Fija | F39: Fibra Optica | H39: 172.20.12.36 | I39: =COUNTIF(L39:AM39,"") -> 28 | J39: =COUNTIF(L39:AM39,"APAGADO") -> 0 | K39: =(I39)/(J39+I39) -> 1
A40: CENTRO | B40: CEN17 | C40: BONOMO | D40: San Martin y Mitre | E40: Domo | F40: PTO A FO | G40: SAN MARTIN Y SALLARES | H40: 172.20.12.200 | I40: =COUNTIF(L40:AM40,"") -> 28 | J40: =COUNTIF(L40:AM40,"APAGADO") -> 0 | K40: =(I40)/(J40+I40) -> 1
A41: CENTRO | B41: CEN18 | C41: BONOMO | D41: Monteagudo e/Mitre y Sallares | E41: Fija | F41: Fibra Optica | H41: 172.20.10.26 | I41: =COUNTIF(L41:AM41,"") -> 28 | J41: =COUNTIF(L41:AM41,"APAGADO") -> 0 | K41: =(I41)/(J41+I41) -> 1
...

Sheet ESTADISTICA
A1: ='RESUMEN TOTAL'!A4 -> Barrio | B1: ='RESUMEN TOTAL'!B4 -> [Denominacion] | C1: ='RESUMEN TOTAL'!D4 -> [Ubicacion] | D1: ='RESUMEN TOTAL'!E4 -> [Tipo de Camara] | E1: ='RESUMEN TOTAL'!F4 -> [Tipo de Conexion] | F1: ='RESUMEN TOTAL'!L4 -> 45200 | G1: ='RESUMEN TOTAL'!M4 -> 45201 | H1: ='RESUMEN TOTAL'!N4 -> 45202 | I1: ='RESUMEN TOTAL'!O4 -> 45203 | J1: ='RESUMEN TOTAL'!P4 -> 45204 | K1: ='RESUMEN TOTAL'!Q4 -> 45205 | L1: ='RESUMEN TOTAL'!R4 -> 45206 | M1: ='RESUMEN TOTAL'!S4 -> 45207 | ... AI1: ='RESUMEN TOTAL'!AO4 -> 45229 | AJ1: ='RESUMEN TOTAL'!#REF! -> #REF!
A2: ='RESUMEN TOTAL'!A5 -> ALTAMIRA | B2: ='RESUMEN TOTAL'!B5 -> ALT01 | C2: ='RESUMEN TOTAL'!D5 -> Calchaqui y Sgto. Cabral | D2: ='RESUMEN TOTAL'!E5 -> Domo | E2: ='RESUMEN TOTAL'!F5 -> Fibra Optica | F2: ='RESUMEN TOTAL'!L5 -> 0 | G2: ='RESUMEN TOTAL'!M5 -> 0 | H2: ='RESUMEN TOTAL'!N5 -> 0 | I2: ='RESUMEN TOTAL'!O5 -> 0 | J2: ='RESUMEN TOTAL'!P5 -> 0 | K2: ='RESUMEN TOTAL'!Q5 -> 0 | L2: ='RESUMEN TOTAL'!R5 -> 0 | M2: ='RESUMEN TOTAL'!S5 -> 0 | ... AI2: ='RESUMEN TOTAL'!AO5 -> 0 | AJ2: ='RESUMEN TOTAL'!#REF! -> #REF!
A3: ='RESUMEN TOTAL'!A6 -> ALTAMIRA | B3: ='RESUMEN TOTAL'!B6 -> ALT02 | C3: ='RESUMEN TOTAL'!D6 -> Calchaqui y Lope de Vega | D3: ='RESUMEN TOTAL'!E6 -> Domo | E3: ='RESUMEN TOTAL'!F6 -> PTO A FO | F3: ='RESUMEN TOTAL'!L6 -> 0 | G3: ='RESUMEN TOTAL'!M6 -> 0 | H3: ='RESUMEN TOTAL'!N6 -> 0 | I3: ='RESUMEN TOTAL'!O6 -> 0 | J3: ='RESUMEN TOTAL'!P6 -> 0 | K3: ='RESUMEN TOTAL'!Q6 -> 0 | L3: ='RESUMEN TOTAL'!R6 -> 0 | M3: ='RESUMEN TOTAL'!S6 -> 0 | ... AI3: ='RESUMEN TOTAL'!AO6 -> 0 | AJ3: ='RESUMEN TOTAL'!#REF! -> #REF!
A4: ='RESUMEN TOTAL'!A7 -> ALTAMIRA | B4: ='RESUMEN TOTAL'!B7 -> ALT 03 | C4: ='RESUMEN TOTAL'!D7 -> Bombero Galarza y Necochea | D4: ='RESUMEN TOTAL'!E7 -> Domo | E4: ='RESUMEN TOTAL'!F7 -> Fibra Optica | F4: ='RESUMEN TOTAL'!L7 -> 0 | G4: ='RESUMEN TOTAL'!M7 -> 0 | H4: ='RESUMEN TOTAL'!N7 -> 0 | I4: ='RESUMEN TOTAL'!O7 -> 0 | J4: ='RESUMEN TOTAL'!P7 -> 0 | K4: ='RESUMEN TOTAL'!Q7 -> 0 | L4: ='RESUMEN TOTAL'!R7 -> 0 | M4: ='RESUMEN TOTAL'!S7 -> 0 | ... AI4: ='RESUMEN TOTAL'!AO7 -> 0 | AJ4: ='RESUMEN TOTAL'!#REF! -> #REF!
A5: ='RESUMEN TOTAL'!A8 -> ALTAMIRA | B5: ='RESUMEN TOTAL'!B8 -> ALT 04 | C5: ='RESUMEN TOTAL'!D8 -> Francia y Necochea | D5: ='RESUMEN TOTAL'!E8 -> Domo | E5: ='RESUMEN TOTAL'!F8 -> Fibra Optica | F5: ='RESUMEN TOTAL'!L8 -> 0 | G5: ='RESUMEN TOTAL'!M8 -> 0 | H5: ='RESUMEN TOTAL'!N8 -> 0 | I5: ='RESUMEN TOTAL'!O8 -> 0 | J5: ='RESUMEN TOTAL'!P8 -> 0 | K5: ='RESUMEN TOTAL'!Q8 -> 0 | L5: ='RESUMEN TOTAL'!R8 -> 0 | M5: ='RESUMEN TOTAL'!S8 -> 0 | ... AI5: ='RESUMEN TOTAL'!AO8 -> 0 | AJ5: ='RESUMEN TOTAL'!#REF! -> #REF!
A6: ='RESUMEN TOTAL'!A9 -> ALTAMIRA | B6: ='RESUMEN TOTAL'!B9 -> ALT05 | C6: ='RESUMEN TOTAL'!D9 -> Av. Calchaqui y Bombero Galarza | D6: ='RESUMEN TOTAL'!E9 -> Domo | E6: ='RESUMEN TOTAL'!F9 -> PTO A FO | F6: ='RESUMEN TOTAL'!L9 -> 0 | G6: ='RESUMEN TOTAL'!M9 -> 0 | H6: ='RESUMEN TOTAL'!N9 -> 0 | I6: ='RESUMEN TOTAL'!O9 -> 0 | J6: ='RESUMEN TOTAL'!P9 -> 0 | K6: ='RESUMEN TOTAL'!Q9 -> 0 | L6: ='RESUMEN TOTAL'!R9 -> 0 | M6: ='RESUMEN TOTAL'!S9 -> 0 | ... AI6: ='RESUMEN TOTAL'!AO9 -> 0 | AJ6: ='RESUMEN TOTAL'!#REF! -> #REF!
A7: ='RESUMEN TOTAL'!A10 -> ALTAMIRA | B7: ='RESUMEN TOTAL'!B10 -> ALT 06 | C7: ='RESUMEN TOTAL'!D10 -> LOPE DE VEGA Y NECOCHEA | D7: ='RESUMEN TOTAL'!E10 -> Domo | E7: ='RESUMEN TOTAL'!F10 -> PTO A FO | F7: ='RESUMEN TOTAL'!L10 -> 0 | G7: ='RESUMEN TOTAL'!M10 -> 0 | H7: ='RESUMEN TOTAL'!N10 -> 0 | I7: ='RESUMEN TOTAL'!O10 -> 0 | J7: ='RESUMEN TOTAL'!P10 -> 0 | K7: ='RESUMEN TOTAL'!Q10 -> 0 | L7: ='RESUMEN TOTAL'!R10 -> 0 | M7: ='RESUMEN TOTAL'!S10 -> 0 | ... AI7: ='RESUMEN TOTAL'!AO10 -> 0 | AJ7: ='RESUMEN TOTAL'!#REF! -> #REF!
A8: ='RESUMEN TOTAL'!A11 -> ALTAMIRA | B8: ='RESUMEN TOTAL'!B11 -> ALT07 | C8: ='RESUMEN TOTAL'!D11 -> AV. CALCHAQUI Y AV. DEL TRABAJO | D8: ='RESUMEN TOTAL'!E11 -> DOMO | E8: ='RESUMEN TOTAL'!F11 -> PTO A FO | F8: ='RESUMEN TOTAL'!L11 -> 0 | G8: ='RESUMEN TOTAL'!M11 -> 0 | H8: ='RESUMEN TOTAL'!N11 -> 0 | I8: ='RESUMEN TOTAL'!O11 -> 0 | J8: ='RESUMEN TOTAL'!P11 -> 0 | K8: ='RESUMEN TOTAL'!Q11 -> 0 | L8: ='RESUMEN TOTAL'!R11 -> 0 | M8: ='RESUMEN TOTAL'!S11 -> 0 | ... AI8: ='RESUMEN TOTAL'!AO11 -> 0 | AJ8: ='RESUMEN TOTAL'!#REF! -> #REF!
A9: ='RESUMEN TOTAL'!A12 -> ALTAMIRA | B9: ='RESUMEN TOTAL'!B12 -> ALT 08 | C9: ='RESUMEN TOTAL'!D12 -> HUMAITA Y NECOCHEA | D9: ='RESUMEN TOTAL'!E12 -> DOMO | E9: ='RESUMEN TOTAL'!F12 -> Fibra Optica | F9: ='RESUMEN TOTAL'!L12 -> 0 | G9: ='RESUMEN TOTAL'!M12 -> 0 | H9: ='RESUMEN TOTAL'!N12 -> 0 | I9: ='RESUMEN TOTAL'!O12 -> 0 | J9: ='RESUMEN TOTAL'!P12 -> 0 | K9: ='RESUMEN TOTAL'!Q12 -> 0 | L9: ='RESUMEN TOTAL'!R12 -> 0 | M9: ='RESUMEN TOTAL'!S12 -> 0 | ... AI9: ='RESUMEN TOTAL'!AO12 -> 0 | AJ9: ='RESUMEN TOTAL'!#REF! -> #REF!
A10: ='RESUMEN TOTAL'!A13 -> ALTAMIRA | B10: ='RESUMEN TOTAL'!B13 -> ALT 09 | C10: ='RESUMEN TOTAL'!D13 -> NECOCHEA Y CURUPAITY | D10: ='RESUMEN TOTAL'!E13 -> DOMO | E10: ='RESUMEN TOTAL'!F13 -> Fibra Optica | F10: ='RESUMEN TOTAL'!L13 -> 0 | G10: ='RESUMEN TOTAL'!M13 -> 0 | H10: ='RESUMEN TOTAL'!N13 -> 0 | I10: ='RESUMEN TOTAL'!O13 -> 0 | J10: ='RESUMEN TOTAL'!P13 -> 0 | K10: ='RESUMEN TOTAL'!Q13 -> 0 | L10: ='RESUMEN TOTAL'!R13 -> 0 | M10: ='RESUMEN TOTAL'!S13 -> 0 | ... AI10: ='RESUMEN TOTAL'!AO13 -> 0 | AJ10: ='RESUMEN TOTAL'!#REF! -> #REF!
A11: ='RESUMEN TOTAL'!A14 -> ALTAMIRA | B11: ='RESUMEN TOTAL'!B14 -> ALT 10 | C11: ='RESUMEN TOTAL'!D14 -> Calchaqui y Francia | D11: ='RESUMEN TOTAL'!E14 -> Domo | E11: ='RESUMEN TOTAL'!F14 -> Radio | F11: ='RESUMEN TOTAL'!L14 -> 0 | G11: ='RESUMEN TOTAL'!M14 -> 0 | H11: ='RESUMEN TOTAL'!N14 -> 0 | I11: ='RESUMEN TOTAL'!O14 -> 0 | J11: ='RESUMEN TOTAL'!P14 -> 0 | K11: ='RESUMEN TOTAL'!Q14 -> 0 | L11: ='RESUMEN TOTAL'!R14 -> 0 | M11: ='RESUMEN TOTAL'!S14 -> 0 | ... AI11: ='RESUMEN TOTAL'!AO14 -> 0 | AJ11: ='RESUMEN TOTAL'!#REF! -> #REF!
A12: ='RESUMEN TOTAL'!A15 -> AGUSTIN RAMIREZ | B12: ='RESUMEN TOTAL'!B15 -> ARA 01 | C12: ='RESUMEN TOTAL'!D15 -> Malambo y Tranquera | D12: ='RESUMEN TOTAL'!E15 -> Domo | E12: ='RESUMEN TOTAL'!F15 -> Fibra Optica | F12: ='RESUMEN TOTAL'!L15 -> APAGADO | G12: ='RESUMEN TOTAL'!M15 -> APAGADO | H12: ='RESUMEN TOTAL'!N15 -> APAGADO | I12: ='RESUMEN TOTAL'!O15 -> APAGADO | J12: ='RESUMEN TOTAL'!P15 -> APAGADO | K12: ='RESUMEN TOTAL'!Q15 -> 0 | L12: ='RESUMEN TOTAL'!R15 -> 0 | M12: ='RESUMEN TOTAL'!S15 -> 0 | ... AI12: ='RESUMEN TOTAL'!AO15 -> 0 | AJ12: ='RESUMEN TOTAL'!#REF! -> #REF!
... A424: ='RESUMEN TOTAL'!A427 -> VILLA ANGELICA | B424: ='RESUMEN TOTAL'!B427 -> VDPL06 | C424: ='RESUMEN TOTAL'!D427 -> Thevenet e/ Islas Orcadas y Gardel | D424: ='RESUMEN TOTAL'!E427 -> Domo | E424: ='RESUMEN TOTAL'!F427 -> Radio | F424: ='RESUMEN TOTAL'!L427 -> 0 | G424: ='RESUMEN TOTAL'!M427 -> 0 | H424: ='RESUMEN TOTAL'!N427 -> 0 | I424: ='RESUMEN TOTAL'!O427 -> 0 | J424: ='RESUMEN TOTAL'!P427 -> 0 | K424: ='RESUMEN TOTAL'!Q427 -> 0 | L424: ='RESUMEN TOTAL'!R427 -> 0 | M424: ='RESUMEN TOTAL'!S427 -> 0 | ... AI424: ='RESUMEN TOTAL'!AO427 -> 0 | AJ424: ='RESUMEN TOTAL'!#REF! -> #REF!
A425: ='RESUMEN TOTAL'!A429 -> VILLA HUDSON | B425: ='RESUMEN TOTAL'!B429 -> VHS 01 | C425: ='RESUMEN TOTAL'!D429 -> AV. HUDSON Y AV. LUJAN | D425: ='RESUMEN TOTAL'!E429 -> DOMO | E425: ='RESUMEN TOTAL'!F429 -> Fibra Optica | F425: ='RESUMEN TOTAL'!L429 -> 0 | G425: ='RESUMEN TOTAL'!M429 -> 0 | H425: ='RESUMEN TOTAL'!N429 -> 0 | I425: ='RESUMEN TOTAL'!O429 -> 0 | J425: ='RESUMEN TOTAL'!P429 -> 0 | K425: ='RESUMEN TOTAL'!Q429 -> 0 | L425: ='RESUMEN TOTAL'!R429 -> 0 | M425: ='RESUMEN TOTAL'!S429 -> 0 | ... AI425: ='RESUMEN TOTAL'!AO429 -> 0 | AJ425: ='RESUMEN TOTAL'!#REF! -> #REF!
A426: ='RESUMEN TOTAL'!A430 -> VILLA HUDSON | B426: ='RESUMEN TOTAL'!B430 -> VHS 02 | C426: ='RESUMEN TOTAL'!D430 -> AV. LUJAN Y CALLE 909 A | D426: ='RESUMEN TOTAL'!E430 -> DOMO | E426: ='RESUMEN TOTAL'!F430 -> Fibra Optica | F426: ='RESUMEN TOTAL'!L430 -> 0 | G426: ='RESUMEN TOTAL'!M430 -> 0 | H426: ='RESUMEN TOTAL'!N430 -> 0 | I426: ='RESUMEN TOTAL'!O430 -> 0 | J426: ='RESUMEN TOTAL'!P430 -> 0 | K426: ='RESUMEN TOTAL'!Q430 -> 0 | L426: ='RESUMEN TOTAL'!R430 -> 0 | M426: ='RESUMEN TOTAL'!S430 -> 0 | ... AI426: ='RESUMEN TOTAL'!AO430 -> 0 | AJ426: ='RESUMEN TOTAL'!#REF! -> #REF!
A427: ='RESUMEN TOTAL'!A431 -> VILLA HUDSON | B427: ='RESUMEN TOTAL'!B431 -> VHS 03 (fija 1) | C427: ='RESUMEN TOTAL'!D431 -> AV. HUDSON Y LOS INMIGRANTES | D427: ='RESUMEN TOTAL'!E431 -> Fija | E427: ='RESUMEN TOTAL'!F431 -> Fibra Optica | F427: ='RESUMEN TOTAL'!L431 -> 0 | G427: ='RESUMEN TOTAL'!M431 -> 0 | H427: ='RESUMEN TOTAL'!N431 -> 0 | I427: ='RESUMEN TOTAL'!O431 -> 0 | J427: ='RESUMEN TOTAL'!P431 -> 0 | K427: ='RESUMEN TOTAL'!Q431 -> 0 | L427: ='RESUMEN TOTAL'!R431 -> 0 | M427: ='RESUMEN TOTAL'!S431 -> 0 | ... AI427: ='RESUMEN TOTAL'!AO431 -> 0 | AJ427: ='RESUMEN TOTAL'!#REF! -> #REF!
A428: ='RESUMEN TOTAL'!A432 -> VILLA HUDSON | B428: ='RESUMEN TOTAL'!B432 -> VHS 04 (fija 2) | C428: ='RESUMEN TOTAL'!D432 -> AV. HUDSON Y LOS INMIGRANTES | D428: ='RESUMEN TOTAL'!E432 -> Fija | E428: ='RESUMEN TOTAL'!F432 -> Fibra Optica | F428: ='RESUMEN TOTAL'!L432 -> 0 | G428: ='RESUMEN TOTAL'!M432 -> 0 | H428: ='RESUMEN TOTAL'!N432 -> 0 | I428: ='RESUMEN TOTAL'!O432 -> 0 | J428: ='RESUMEN TOTAL'!P432 -> 0 | K428: ='RESUMEN TOTAL'!Q432 -> 0 | L428: ='RESUMEN TOTAL'!R432 -> 0 | M428: ='RESUMEN TOTAL'!S432 -> 0 | ... AI428: ='RESUMEN TOTAL'!AO432 -> 0 | AJ428: ='RESUMEN TOTAL'!#REF! -> #REF!
A429: ='RESUMEN TOTAL'!A433 -> VILLA ARIAS | B429: ='RESUMEN TOTAL'!B433 -> VLA 01 (fija 1) | C429: ='RESUMEN TOTAL'!D433 -> 820 Y SOLER | D429: ='RESUMEN TOTAL'!E433 -> Fija | E429: ='RESUMEN TOTAL'!F433 -> Fibra Optica | F429: ='RESUMEN TOTAL'!L433 -> 0 | G429: ='RESUMEN TOTAL'!M433 -> 0 | H429: ='RESUMEN TOTAL'!N433 -> 0 | I429: ='RESUMEN TOTAL'!O433 -> 0 | J429: ='RESUMEN TOTAL'!P433 -> 0 | K429: ='RESUMEN TOTAL'!Q433 -> 0 | L429: ='RESUMEN TOTAL'!R433 -> 0 | M429: ='RESUMEN TOTAL'!S433 -> 0 | ... AI429: ='RESUMEN TOTAL'!AO433 -> 0 | AJ429: ='RESUMEN TOTAL'!#REF! -> #REF!
A430: ='RESUMEN TOTAL'!A434 -> VILLA ARIAS | B430: ='RESUMEN TOTAL'!B434 -> VLA 02 | C430: ='RESUMEN TOTAL'!D434 -> ESPORA Y HUDSON | D430: ='RESUMEN TOTAL'!E434 -> DOMO | E430: ='RESUMEN TOTAL'!F434 -> Fibra Optica | F430: ='RESUMEN TOTAL'!L434 -> 0 | G430: ='RESUMEN TOTAL'!M434 -> 0 | H430: ='RESUMEN TOTAL'!N434 -> 0 | I430: ='RESUMEN TOTAL'!O434 -> 0 | J430: ='RESUMEN TOTAL'!P434 -> 0 | K430: ='RESUMEN TOTAL'!Q434 -> 0 | L430: ='RESUMEN TOTAL'!R434 -> 0 | M430: ='RESUMEN TOTAL'!S434 -> 0 | ... AI430: ='RESUMEN TOTAL'!AO434 -> 0 | AJ430: ='RESUMEN TOTAL'!#REF! -> #REF!
A431: ='RESUMEN TOTAL'!A435 -> VILLA ARIAS | B431: ='RESUMEN TOTAL'!B435 -> VLA03 (fija 2) | C431: ='RESUMEN TOTAL'!D435 -> 820 y SOLER | D431: ='RESUMEN TOTAL'!E435 -> Fija | E431: ='RESUMEN TOTAL'!F435 -> Fibra Optica | F431: ='RESUMEN TOTAL'!L435 -> 0 | G431: ='RESUMEN TOTAL'!M435 -> 0 | H431: ='RESUMEN TOTAL'!N435 -> 0 | I431: ='RESUMEN TOTAL'!O435 -> 0 | J431: ='RESUMEN TOTAL'!P435 -> 0 | K431: ='RESUMEN TOTAL'!Q435 -> 0 | L431: ='RESUMEN TOTAL'!R435 -> 0 | M431: ='RESUMEN TOTAL'!S435 -> 0 | ... AI431: ='RESUMEN TOTAL'!AO435 -> 0 | AJ431: ='RESUMEN TOTAL'!#REF! -> #REF!
A432: ='RESUMEN TOTAL'!A436 -> VILLA ARIAS | B432: ='RESUMEN TOTAL'!B436 -> VLA04 | C432: ='RESUMEN TOTAL'!D436 -> ESPORA Y MARTIN GRASS | D432: ='RESUMEN TOTAL'!E436 -> DOMO | E432: ='RESUMEN TOTAL'!F436 -> Fibra Optica | F432: ='RESUMEN TOTAL'!L436 -> 0 | G432: ='RESUMEN TOTAL'!M436 -> 0 | H432: ='RESUMEN TOTAL'!N436 -> 0 | I432: ='RESUMEN TOTAL'!O436 -> 0 | J432: ='RESUMEN TOTAL'!P436 -> 0 | K432: ='RESUMEN TOTAL'!Q436 -> 0 | L432: ='RESUMEN TOTAL'!R436 -> 0 | M432: ='RESUMEN TOTAL'!S436 -> 0 | ... AI432: ='RESUMEN TOTAL'!AO436 -> 0 | AJ432: ='RESUMEN TOTAL'!#REF! -> #REF!
A433: ='RESUMEN TOTAL'!A437 -> VILLA ARIAS | B433: ='RESUMEN TOTAL'!B437 -> VLA05 | C433: ='RESUMEN TOTAL'!D437 -> ESPORA Y 802 | D433: ='RESUMEN TOTAL'!E437 -> DOMO | E433: ='RESUMEN TOTAL'!F437 -> Fibra Optica | F433: ='RESUMEN TOTAL'!L437 -> 0 | G433: ='RESUMEN TOTAL'!M437 -> 0 | H433: ='RESUMEN TOTAL'!N437 -> 0 | I433: ='RESUMEN TOTAL'!O437 -> 0 | J433: ='RESUMEN TOTAL'!P437 -> 0 | K433: ='RESUMEN TOTAL'!Q437 -> 0 | L433: ='RESUMEN TOTAL'!R437 -> 0 | M433: ='RESUMEN TOTAL'!S437 -> 0 | ... AI433: ='RESUMEN TOTAL'!AO437 -> 0 | AJ433: ='RESUMEN TOTAL'!#REF! -> #REF!
A434: ='RESUMEN TOTAL'!A438 -> VILLA MONICA NUEVA | B434: ='RESUMEN TOTAL'!B438 -> VMO 02 | C434: ='RESUMEN TOTAL'!D438 -> Rio Carapachay y Oroño | D434: ='RESUMEN TOTAL'!E438 -> Domo | E434: ='RESUMEN TOTAL'!F438 -> Radio | F434: ='RESUMEN TOTAL'!L438 -> 0 | G434: ='RESUMEN TOTAL'!M438 -> 0 | H434: ='RESUMEN TOTAL'!N438 -> 0 | I434: ='RESUMEN TOTAL'!O438 -> 0 | J434: ='RESUMEN TOTAL'!P438 -> 0 | K434: ='RESUMEN TOTAL'!Q438 -> 0 | L434: ='RESUMEN TOTAL'!R438 -> 0 | M434: ='RESUMEN TOTAL'!S438 -> 0 | ... AI434: ='RESUMEN TOTAL'!AO438 -> 0 | AJ434: ='RESUMEN TOTAL'!#REF! -> #REF!
A435: ='RESUMEN TOTAL'!A439 -> VILLA MONICA NUEVA | B435: ='RESUMEN TOTAL'!B439 -> VMO 03 (fija 1) | C435: ='RESUMEN TOTAL'!D439 -> EVA PERON E/ OROÑO Y 734 A | D435: ='RESUMEN TOTAL'!E439 -> Fija | E435: ='RESUMEN TOTAL'!F439 -> Fibra Optica | F435: ='RESUMEN TOTAL'!L439 -> 0 | G435: ='RESUMEN TOTAL'!M439 -> 0 | H435: ='RESUMEN TOTAL'!N439 -> 0 | I435: ='RESUMEN TOTAL'!O439 -> 0 | J435: ='RESUMEN TOTAL'!P439 -> 0 | K435: ='RESUMEN TOTAL'!Q439 -> 0 | L435: ='RESUMEN TOTAL'!R439 -> 0 | M435: ='RESUMEN TOTAL'!S439 -> 0 | ... AI435: ='RESUMEN TOTAL'!AO439 -> 0 | AJ435: ='RESUMEN TOTAL'!#REF! -> #REF!
A436: ='RESUMEN TOTAL'!A440 -> VILLA MONICA NUEVA | B436: ='RESUMEN TOTAL'!B440 -> VMO 04 (fija 2) | C436: ='RESUMEN TOTAL'!D440 -> EVA PERON E/ OROÑO Y 734 A | D436: ='RESUMEN TOTAL'!E440 -> Fija | E436: ='RESUMEN TOTAL'!F440 -> Fibra Optica | F436: ='RESUMEN TOTAL'!L440 -> 0 | G436: ='RESUMEN TOTAL'!M440 -> 0 | H436: ='RESUMEN TOTAL'!N440 -> 0 | I436: ='RESUMEN TOTAL'!O440 -> 0 | J436: ='RESUMEN TOTAL'!P440 -> 0 | K436: ='RESUMEN TOTAL'!Q440 -> 0 | L436: ='RESUMEN TOTAL'!R440 -> 0 | M436: ='RESUMEN TOTAL'!S440 -> 0 | ... AI436: ='RESUMEN TOTAL'!AO440 -> 0 | AJ436: ='RESUMEN TOTAL'!#REF! -> #REF!
... A453: ='RESUMEN TOTAL'!A457 -> ZEBALLOS | B453: ='RESUMEN TOTAL'!B457 -> ZEB 05 | C453: ='RESUMEN TOTAL'!D457 -> DIAG. GRANADEROS Y 214 BIS | D453: ='RESUMEN TOTAL'!E457 -> Domo | E453: ='RESUMEN TOTAL'!F457 -> Radio | F453: ='RESUMEN TOTAL'!L457 -> 0 | G453: ='RESUMEN TOTAL'!M457 -> 0 | H453: ='RESUMEN TOTAL'!N457 -> 0 | I453: ='RESUMEN TOTAL'!O457 -> 0 | J453: ='RESUMEN TOTAL'!P457 -> 0 | K453: ='RESUMEN TOTAL'!Q457 -> 0 | L453: ='RESUMEN TOTAL'!R457 -> 0 | M453: ='RESUMEN TOTAL'!S457 -> 0 | ... AI453: ='RESUMEN TOTAL'!AO457 -> 0 | AJ453: ='RESUMEN TOTAL'!#REF! -> #REF!
A454: ='RESUMEN TOTAL'!A478 -> PARADAS SEGURAS | B454: ='RESUMEN TOTAL'!B478 -> 21 | C454: ='RESUMEN TOTAL'!D478 -> HUDSON Y CABILDO OESTE | D454: ='RESUMEN TOTAL'!E478 -> GFIJA | E454: ='RESUMEN TOTAL'!F478 -> GPON | F454: ='RESUMEN TOTAL'!L478 -> 0 | G454: ='RESUMEN TOTAL'!M478 -> 0 | H454: ='RESUMEN TOTAL'!N478 -> 0 | I454: ='RESUMEN TOTAL'!O478 -> 0 | J454: ='RESUMEN TOTAL'!P478 -> 0 | K454: ='RESUMEN TOTAL'!Q478 -> 0 | L454: ='RESUMEN TOTAL'!R478 -> 0 | M454: ='RESUMEN TOTAL'!S478 -> 0 | ... AI454: ='RESUMEN TOTAL'!AO478 -> 0 | AJ454: ='RESUMEN TOTAL'!#REF! -> #REF!
A455: ='RESUMEN TOTAL'!A479 -> PARADAS SEGURAS | B455: ='RESUMEN TOTAL'!B479 -> 21 I | C455: ='RESUMEN TOTAL'!D479 -> HUDSON Y CABILDO OESTE | D455: ='RESUMEN TOTAL'!E479 -> INTERCOMUNICADOR | E455: ='RESUMEN TOTAL'!F479 -> GPON | F455: ='RESUMEN TOTAL'!L479 -> 0 | G455: ='RESUMEN TOTAL'!M479 -> 0 | H455: ='RESUMEN TOTAL'!N479 -> 0 | I455: ='RESUMEN TOTAL'!O479 -> 0 | J455: ='RESUMEN TOTAL'!P479 -> 0 | K455: ='RESUMEN TOTAL'!Q479 -> 0 | L455: ='RESUMEN TOTAL'!R479 -> 0 | M455: ='RESUMEN TOTAL'!S479 -> 0 | ... AI455: ='RESUMEN TOTAL'!AO479 -> 0 | AJ455: ='RESUMEN TOTAL'!#REF! -> #REF!
A456: ='RESUMEN TOTAL'!A480 -> PARADAS SEGURAS | B456: ='RESUMEN TOTAL'!B480 -> 22 | C456: ='RESUMEN TOTAL'!D480 -> HUDSON Y CABILDO ESTE | D456: ='RESUMEN TOTAL'!E480 -> GFIJA | E456: ='RESUMEN TOTAL'!F480 -> GPON | F456: ='RESUMEN TOTAL'!L480 -> 0 | G456: ='RESUMEN TOTAL'!M480 -> 0 | H456: ='RESUMEN TOTAL'!N480 -> 0 | I456: ='RESUMEN TOTAL'!O480 -> 0 | J456: ='RESUMEN TOTAL'!P480 -> 0 | K456: ='RESUMEN TOTAL'!Q480 -> 0 | L456: ='RESUMEN TOTAL'!R480 -> 0 | M456: ='RESUMEN TOTAL'!S480 -> 0 | ... AI456: ='RESUMEN TOTAL'!AO480 -> 0 | AJ456: ='RESUMEN TOTAL'!#REF! -> #REF!
A457: ='RESUMEN TOTAL'!A481 -> PARADAS SEGURAS | B457: ='RESUMEN TOTAL'!B481 -> 22 I | C457: ='RESUMEN TOTAL'!D481 -> HUDSON Y CABILDO ESTE | D457: ='RESUMEN TOTAL'!E481 -> INTERCOMUNICADOR | E457: ='RESUMEN TOTAL'!F481 -> GPON | F457: ='RESUMEN TOTAL'!L481 -> 0 | G457: ='RESUMEN TOTAL'!M481 -> 0 | H457: ='RESUMEN TOTAL'!N481 -> 0 | I457: ='RESUMEN TOTAL'!O481 -> 0 | J457: ='RESUMEN TOTAL'!P481 -> 0 | K457: ='RESUMEN TOTAL'!Q481 -> 0 | L457: ='RESUMEN TOTAL'!R481 -> 0 | M457: ='RESUMEN TOTAL'!S481 -> 0 | ... AI457: ='RESUMEN TOTAL'!AO481 -> 0 | AJ457: ='RESUMEN TOTAL'!#REF! -> #REF!
A458: ='RESUMEN TOTAL'!A482 -> PARADAS SEGURAS | B458: ='RESUMEN TOTAL'!B482 -> 23 | C458: ='RESUMEN TOTAL'!D482 -> HUDSON Y SAN NICOLAS OESTE | D458: ='RESUMEN TOTAL'!E482 -> GFIJA | E458: ='RESUMEN TOTAL'!F482 -> GPON | F458: ='RESUMEN TOTAL'!L482 -> 0 | G458: ='RESUMEN TOTAL'!M482 -> 0 | H458: ='RESUMEN TOTAL'!N482 -> 0 | I458: ='RESUMEN TOTAL'!O482 -> 0 | J458: ='RESUMEN TOTAL'!P482 -> 0 | K458: ='RESUMEN TOTAL'!Q482 -> 0 | L458: ='RESUMEN TOTAL'!R482 -> 0 | M458: ='RESUMEN TOTAL'!S482 -> 0 | ... AI458: ='RESUMEN TOTAL'!AO482 -> 0 | AJ458: ='RESUMEN TOTAL'!#REF! -> #REF!
A459: ='RESUMEN TOTAL'!A483 -> PARADAS SEGURAS | B459: ='RESUMEN TOTAL'!B483 -> 23 I | C459: ='RESUMEN TOTAL'!D483 -> HUDSON Y SAN NICOLAS OESTE | D459: ='RESUMEN TOTAL'!E483 -> INTERCOMUNICADOR | E459: ='RESUMEN TOTAL'!F483 -> GPON | F459: ='RESUMEN TOTAL'!L483 -> 0 | G459: ='RESUMEN TOTAL'!M483 -> 0 | H459: ='RESUMEN TOTAL'!N483 -> 0 | I459: ='RESUMEN TOTAL'!O483 -> 0 | J459: ='RESUMEN TOTAL'!P483 -> 0 | K459: ='RESUMEN TOTAL'!Q483 -> 0 | L459: ='RESUMEN TOTAL'!R483 -> 0 | M459: ='RESUMEN TOTAL'!S483 -> 0 | ... AI459: ='RESUMEN TOTAL'!AO483 -> 0 | AJ459: ='RESUMEN TOTAL'!#REF! -> #REF!
A460: ='RESUMEN TOTAL'!A484 -> PARADAS SEGURAS | B460: ='RESUMEN TOTAL'!B484 -> 24 | C460: ='RESUMEN TOTAL'!D484 -> HUDSON Y ALDAO ESTE | D460: ='RESUMEN TOTAL'!E484 -> GFIJA | E460: ='RESUMEN TOTAL'!F484 -> GPON | F460: ='RESUMEN TOTAL'!L484 -> 0 | G460: ='RESUMEN TOTAL'!M484 -> 0 | H460: ='RESUMEN TOTAL'!N484 -> 0 | I460: ='RESUMEN TOTAL'!O484 -> 0 | J460: ='RESUMEN TOTAL'!P484 -> 0 | K460: ='RESUMEN TOTAL'!Q484 -> 0 | L460: ='RESUMEN TOTAL'!R484 -> 0 | M460: ='RESUMEN TOTAL'!S484 -> 0 | ... AI460: ='RESUMEN TOTAL'!AO484 -> 0 | AJ460: ='RESUMEN TOTAL'!#REF! -> #REF!
A461: ='RESUMEN TOTAL'!A485 -> PARADAS SEGURAS | B461: ='RESUMEN TOTAL'!B485 -> 24 I | C461: ='RESUMEN TOTAL'!D485 -> HUDSON Y ALDAO ESTE | D461: ='RESUMEN TOTAL'!E485 -> INTERCOMUNICADOR | E461: ='RESUMEN TOTAL'!F485 -> GPON | F461: ='RESUMEN TOTAL'!L485 -> 0 | G461: ='RESUMEN TOTAL'!M485 -> 0 | H461: ='RESUMEN TOTAL'!N485 -> 0 | I461: ='RESUMEN TOTAL'!O485 -> 0 | J461: ='RESUMEN TOTAL'!P485 -> 0 | K461: ='RESUMEN TOTAL'!Q485 -> 0 | L461: ='RESUMEN TOTAL'!R485 -> 0 | M461: ='RESUMEN TOTAL'!S485 -> 0 | ... AI461: ='RESUMEN TOTAL'!AO485 -> 0 | AJ461: ='RESUMEN TOTAL'!#REF! -> #REF!
A462: ='RESUMEN TOTAL'!A486 -> PARADAS SEGURAS | B462: ='RESUMEN TOTAL'!B486 -> 25 | C462: ='RESUMEN TOTAL'!D486 -> HUDSON Y RIO JACHAL | D462: ='RESUMEN TOTAL'!E486 -> GFIJA | E462: ='RESUMEN TOTAL'!F486 -> GPON | F462: ='RESUMEN TOTAL'!L486 -> 0 | G462: ='RESUMEN TOTAL'!M486 -> 0 | H462: ='RESUMEN TOTAL'!N486 -> 0 | I462: ='RESUMEN TOTAL'!O486 -> 0 | J462: ='RESUMEN TOTAL'!P486 -> 0 | K462: ='RESUMEN TOTAL'!Q486 -> 0 | L462: ='RESUMEN TOTAL'!R486 -> 0 | M462: ='RESUMEN TOTAL'!S486 -> 0 | ... AI462: ='RESUMEN TOTAL'!AO486 -> 0 | AJ462: ='RESUMEN TOTAL'!#REF! -> #REF!
A463: ='RESUMEN TOTAL'!A487 -> PARADAS SEGURAS | B463: ='RESUMEN TOTAL'!B487 -> 25 I | C463: ='RESUMEN TOTAL'!D487 -> HUDSON Y RIO JACHAL | D463: ='RESUMEN TOTAL'!E487 -> INTERCOMUNICADOR | E463: ='RESUMEN TOTAL'!F487 -> GPON | F463: ='RESUMEN TOTAL'!L487 -> 0 | G463: ='RESUMEN TOTAL'!M487 -> 0 | H463: ='RESUMEN TOTAL'!N487 -> 0 | I463: ='RESUMEN TOTAL'!O487 -> 0 | J463: ='RESUMEN TOTAL'!P487 -> 0 | K463: ='RESUMEN TOTAL'!Q487 -> 0 | L463: ='RESUMEN TOTAL'!R487 -> 0 | M463: ='RESUMEN TOTAL'!S487 -> 0 | ... AI463: ='RESUMEN TOTAL'!AO487 -> 0 | AJ463: ='RESUMEN TOTAL'!#REF! -> #REF!
A464: ='RESUMEN TOTAL'!A488 -> PARADAS SEGURAS | B464: ='RESUMEN TOTAL'!B488 -> 26 | C464: ='RESUMEN TOTAL'!D488 -> HUDSON Y RIO COLORADO OESTE | D464: ='RESUMEN TOTAL'!E488 -> GFIJA | E464: ='RESUMEN TOTAL'!F488 -> GPON | F464: ='RESUMEN TOTAL'!L488 -> 0 | G464: ='RESUMEN TOTAL'!M488 -> 0 | H464: ='RESUMEN TOTAL'!N488 -> 0 | I464: ='RESUMEN TOTAL'!O488 -> 0 | J464: ='RESUMEN TOTAL'!P488 -> 0 | K464: ='RESUMEN TOTAL'!Q488 -> 0 | L464: ='RESUMEN TOTAL'!R488 -> 0 | M464: ='RESUMEN TOTAL'!S488 -> 0 | ... AI464: ='RESUMEN TOTAL'!AO488 -> 0 | AJ464: ='RESUMEN TOTAL'!#REF! -> #REF!
A465: ='RESUMEN TOTAL'!A489 -> PARADAS SEGURAS | B465: ='RESUMEN TOTAL'!B489 -> 26 I | C465: ='RESUMEN TOTAL'!D490 -> HUDON Y 818 ESTE | D465: ='RESUMEN TOTAL'!E489 -> INTERCOMUNICADOR | E465: ='RESUMEN TOTAL'!F489 -> GPON | F465: ='RESUMEN TOTAL'!L489 -> 0 | G465: ='RESUMEN TOTAL'!M489 -> 0 | H465: ='RESUMEN TOTAL'!N489 -> 0 | I465: ='RESUMEN TOTAL'!O489 -> 0 | J465: ='RESUMEN TOTAL'!P489 -> 0 | K465: ='RESUMEN TOTAL'!Q489 -> 0 | L465: ='RESUMEN TOTAL'!R489 -> 0 | M465: ='RESUMEN TOTAL'!S489 -> 0 | ... AI465: ='RESUMEN TOTAL'!AO489 -> 0 | AJ465: ='RESUMEN TOTAL'!#REF! -> #REF!
A466: ='RESUMEN TOTAL'!A490 -> PARADAS SEGURAS | B466: ='RESUMEN TOTAL'!B490 -> 27 | C466: ='RESUMEN TOTAL'!D492 -> HUDSON Y RIO TRAFUL OESTE | D466: ='RESUMEN TOTAL'!E490 -> GFIJA | E466: ='RESUMEN TOTAL'!F490 -> GPON | F466: ='RESUMEN TOTAL'!L490 -> 0 | G466: ='RESUMEN TOTAL'!M490 -> 0 | H466: ='RESUMEN TOTAL'!N490 -> 0 | I466: ='RESUMEN TOTAL'!O490 -> 0 | J466: ='RESUMEN TOTAL'!P490 -> 0 | K466: ='RESUMEN TOTAL'!Q490 -> 0 | L466: ='RESUMEN TOTAL'!R490 -> 0 | M466: ='RESUMEN TOTAL'!S490 -> 0 | ... AI466: ='RESUMEN TOTAL'!AO490 -> 0 | AJ466: ='RESUMEN TOTAL'!#REF! -> #REF!
A467: ='RESUMEN TOTAL'!A491 -> PARADAS SEGURAS | B467: ='RESUMEN TOTAL'!B491 -> 27 I | C467: ='RESUMEN TOTAL'!D494 -> HUDSON Y ESTOMBA ESTE | D467: ='RESUMEN TOTAL'!E491 -> INTERCOMUNICADOR | E467: ='RESUMEN TOTAL'!F491 -> GPON | F467: ='RESUMEN TOTAL'!L491 -> 0 | G467: ='RESUMEN TOTAL'!M491 -> 0 | H467: ='RESUMEN TOTAL'!N491 -> 0 | I467: ='RESUMEN TOTAL'!O491 -> 0 | J467: ='RESUMEN TOTAL'!P491 -> 0 | K467: ='RESUMEN TOTAL'!Q491 -> 0 | L467: ='RESUMEN TOTAL'!R491 -> 0 | M467: ='RESUMEN TOTAL'!S491 -> 0 | ... AI467: ='RESUMEN TOTAL'!AO491 -> 0 | AJ467: ='RESUMEN TOTAL'!#REF! -> #REF!
...

Sheet APAGADOS
E1: APAGADOS | F1: =COUNTIF(F3:F403, "APAGADO") -> 28 | G1: =COUNTIF(G3:G403, "APAGADO") -> 30 | H1: =COUNTIF(H3:H503, "APAGADO") -> 35 | I1: =COUNTIF(I3:I403, "APAGADO") -> 17 | J1: =COUNTIF(J3:J403, "APAGADO") -> 21 | K1: =COUNTIF(K3:K403, "APAGADO") -> 0 | L1: =COUNTIF(L3:L403, "APAGADO") -> 0 | M1: =COUNTIF(M3:M403, "APAGADO") -> 0 | N1: =COUNTIF(N3:N403, "APAGADO") -> 0 | O1: =COUNTIF(O3:O403, "APAGADO") -> 0 | P1: =COUNTIF(P3:P403, "APAGADO") -> 0 | ... AD1: =COUNTIF(AD3:AD403, "APAGADO") -> 0 | AE1: =COUNTIF(AE3:AE503, "APAGADO") -> 0 | AF1: =COUNTIF(AF3:AF403, "APAGADO") -> 0 | AG1: =COUNTIF(AG3:AG403, "APAGADO") -> 0 | AH1: =COUNTIF(AH3:AH403, "APAGADO") -> 0 | AI1: =COUNTIF(AI3:AI403, "APAGADO") -> 0 | AJ1: =COUNTIF(AJ3:AJ403, "APAGADO") -> 0
A2: =ESTADISTICA!A1 -> Barrio | B2: =ESTADISTICA!B1 -> [Denominacion] | C2: =ESTADISTICA!C1 -> [Ubicacion] | D2: =ESTADISTICA!D1 -> [Tipo de Camara] | E2: =ESTADISTICA!E1 -> [Tipo de Conexion] | F2: =ESTADISTICA!F1 -> 45200 | G2: =ESTADISTICA!G1 -> 45201 | H2: =ESTADISTICA!H1 -> 45202 | ... AJ2: =ESTADISTICA!AJ1 -> #REF!
A3: =ESTADISTICA!A2 -> ALTAMIRA | B3: =ESTADISTICA!B2 -> ALT01 | C3: =ESTADISTICA!C2 -> Calchaqui y Sgto. Cabral | D3: =ESTADISTICA!D2 -> Domo | E3: =ESTADISTICA!E2 -> Fibra Optica | F3: =ESTADISTICA!F2 -> 0 | G3: =ESTADISTICA!G2 -> 0 | H3: =ESTADISTICA!H2 -> 0 | ... AJ3: =ESTADISTICA!AJ2 -> #REF!
A4: =ESTADISTICA!A3 -> ALTAMIRA | B4: =ESTADISTICA!B3 -> ALT02 | C4: =ESTADISTICA!C3 -> Calchaqui y Lope de Vega | D4: =ESTADISTICA!D3 -> Domo | E4: =ESTADISTICA!E3 -> PTO A FO | F4: =ESTADISTICA!F3 -> 0 | G4: =ESTADISTICA!G3 -> 0 | H4: =ESTADISTICA!H3 -> 0 | ... AJ4: =ESTADISTICA!AJ3 -> #REF!
A5: =ESTADISTICA!A4 -> ALTAMIRA | B5: =ESTADISTICA!B4 -> ALT 03 | C5: =ESTADISTICA!C4 -> Bombero Galarza y Necochea | D5: =ESTADISTICA!D4 -> Domo | E5: =ESTADISTICA!E4 -> Fibra Optica | F5: =ESTADISTICA!F4 -> 0 | G5: =ESTADISTICA!G4 -> 0 | H5: =ESTADISTICA!H4 -> 0 | ... AJ5: =ESTADISTICA!AJ4 -> #REF!
A6: =ESTADISTICA!A5 -> ALTAMIRA | B6: =ESTADISTICA!B5 -> ALT 04 | C6: =ESTADISTICA!C5 -> Francia y Necochea | D6: =ESTADISTICA!D5 -> Domo | E6: =ESTADISTICA!E5 -> Fibra Optica | F6: =ESTADISTICA!F5 -> 0 | G6: =ESTADISTICA!G5 -> 0 | H6: =ESTADISTICA!H5 -> 0 | ... AJ6: =ESTADISTICA!AJ5 -> #REF!
A7: =ESTADISTICA!A6 -> ALTAMIRA | B7: =ESTADISTICA!B6 -> ALT05 | C7: =ESTADISTICA!C6 -> Av. Calchaqui y Bombero Galarza | D7: =ESTADISTICA!D6 -> Domo | E7: =ESTADISTICA!E6 -> PTO A FO | F7: =ESTADISTICA!F6 -> 0 | G7: =ESTADISTICA!G6 -> 0 | H7: =ESTADISTICA!H6 -> 0 | ... AJ7: =ESTADISTICA!AJ6 -> #REF!
A8: =ESTADISTICA!A7 -> ALTAMIRA | B8: =ESTADISTICA!B7 -> ALT 06 | C8: =ESTADISTICA!C7 -> LOPE DE VEGA Y NECOCHEA | D8: =ESTADISTICA!D7 -> Domo | E8: =ESTADISTICA!E7 -> PTO A FO | F8: =ESTADISTICA!F7 -> 0 | G8: =ESTADISTICA!G7 -> 0 | H8: =ESTADISTICA!H7 -> 0 | ... AJ8: =ESTADISTICA!AJ7 -> #REF!
A9: =ESTADISTICA!A8 -> ALTAMIRA | B9: =ESTADISTICA!B8 -> ALT07 | C9: =ESTADISTICA!C8 -> AV. CALCHAQUI Y AV. DEL TRABAJO | D9: =ESTADISTICA!D8 -> DOMO | E9: =ESTADISTICA!E8 -> PTO A FO | F9: =ESTADISTICA!F8 -> 0 | G9: =ESTADISTICA!G8 -> 0 | H9: =ESTADISTICA!H8 -> 0 | ... AJ9: =ESTADISTICA!AJ8 -> #REF!
A10: =ESTADISTICA!A9 -> ALTAMIRA | B10: =ESTADISTICA!B9 -> ALT 08 | C10: =ESTADISTICA!C9 -> HUMAITA Y NECOCHEA | D10: =ESTADISTICA!D9 -> DOMO | E10: =ESTADISTICA!E9 -> Fibra Optica | F10: =ESTADISTICA!F9 -> 0 | G10: =ESTADISTICA!G9 -> 0 | H10: =ESTADISTICA!H9 -> 0 | ... AJ10: =ESTADISTICA!AJ9 -> #REF!
A11: =ESTADISTICA!A10 -> ALTAMIRA | B11: =ESTADISTICA!B10 -> ALT 09 | C11: =ESTADISTICA!C10 -> NECOCHEA Y CURUPAITY | D11: =ESTADISTICA!D10 -> DOMO | E11: =ESTADISTICA!E10 -> Fibra Optica | F11: =ESTADISTICA!F10 -> 0 | G11: =ESTADISTICA!G10 -> 0 | H11: =ESTADISTICA!H10 -> 0 | ... AJ11: =ESTADISTICA!AJ10 -> #REF!
A12: =ESTADISTICA!A11 -> ALTAMIRA | B12: =ESTADISTICA!B11 -> ALT 10 | C12: =ESTADISTICA!C11 -> Calchaqui y Francia | D12: =ESTADISTICA!D11 -> Domo | E12: =ESTADISTICA!E11 -> Radio | F12: =ESTADISTICA!F11 -> 0 | G12: =ESTADISTICA!G11 -> 0 | H12: =ESTADISTICA!H11 -> 0 | ... AJ12: =ESTADISTICA!AJ11 -> #REF!
A13: =ESTADISTICA!A12 -> AGUSTIN RAMIREZ | B13: =ESTADISTICA!B12 -> ARA 01 | C13: =ESTADISTICA!C12 -> Malambo y Tranquera | D13: =ESTADISTICA!D12 -> Domo | E13: =ESTADISTICA!E12 -> Fibra Optica | F13: =ESTADISTICA!F12 -> APAGADO | G13: =ESTADISTICA!G12 -> APAGADO | H13: =ESTADISTICA!H12 -> APAGADO | ... AJ13: =ESTADISTICA!AJ12 -> #REF!
... A207: =ESTADISTICA!A206 -> SAN EMILIO | B207: =ESTADISTICA!B206 -> MFI06 | C207: =ESTADISTICA!C206 -> Con. Gral. Belgrano y Bombero Galarza | D207: =ESTADISTICA!D206 -> DOMO | E207: =ESTADISTICA!E206 -> Radio | F207: =ESTADISTICA!F206 -> 0 | G207: =ESTADISTICA!G206 -> 0 | H207: =ESTADISTICA!H206 -> 0 | ... AJ207: =ESTADISTICA!AJ206 -> #REF!
A208: =ESTADISTICA!A208 -> MARTIN FIERRO | B208: =ESTADISTICA!B208 -> MFI 08 | C208: =ESTADISTICA!C208 -> Braile y Batalla de Callao | D208: =ESTADISTICA!D208 -> Domo | E208: =ESTADISTICA!E208 -> PTO A FO | F208: =ESTADISTICA!F208 -> 0 | G208: =ESTADISTICA!G208 -> 0 | H208: =ESTADISTICA!H208 -> 0 | ... AJ208: =ESTADISTICA!AJ208 -> #REF!
A209: =ESTADISTICA!A209 -> GOBERNADOR MONTEVERDE | B209: =ESTADISTICA!B209 -> MON01 | C209: =ESTADISTICA!C209 -> San Martin y Patricias Argentinas | D209: =ESTADISTICA!D209 -> Fija | E209: =ESTADISTICA!E209 -> Fibra Optica | F209: =ESTADISTICA!F209 -> 0 | G209: =ESTADISTICA!G209 -> 0 | H209: =ESTADISTICA!H209 -> 0 | ... AJ209: =ESTADISTICA!AJ209 -> #REF!
A210: =ESTADISTICA!A210 -> GOBERNADOR MONTEVERDE | B210: =ESTADISTICA!B210 -> MON02 | C210: =ESTADISTICA!C210 -> Senzabello y Famatina | D210: =ESTADISTICA!D210 -> Domo | E210: =ESTADISTICA!E210 -> Radio | F210: =ESTADISTICA!F210 -> 0 | G210: =ESTADISTICA!G210 -> 0 | H210: =ESTADISTICA!H210 -> 0 | ... AJ210: =ESTADISTICA!AJ210 -> #REF!
A211: =ESTADISTICA!A211 -> GOBERNADOR MONTEVERDE | B211: =ESTADISTICA!B211 -> MON03 | C211: =ESTADISTICA!C211 -> Senzabello y Guemes | D211: =ESTADISTICA!D211 -> Domo | E211: =ESTADISTICA!E211 -> Radio | F211: =ESTADISTICA!F211 -> 0 | G211: =ESTADISTICA!G211 -> 0 | H211: =ESTADISTICA!H211 -> 0 | ... AJ211: =ESTADISTICA!AJ211 -> #REF!
A212: =ESTADISTICA!A212 -> GOBERNADOR MONTEVERDE | B212: =ESTADISTICA!B212 -> MON04 | C212: =ESTADISTICA!C212 -> Av. Yrigoyen y San Lorenzo | D212: =ESTADISTICA!D212 -> Domo | E212: =ESTADISTICA!E212 -> Radio | F212: =ESTADISTICA!F212 -> 0 | G212: =ESTADISTICA!G212 -> 0 | H212: =ESTADISTICA!H212 -> 0 | ... AJ212: =ESTADISTICA!AJ212 -> #REF!
A213: =ESTADISTICA!A213 -> 9 DE JULIO | B213: =ESTADISTICA!B213 -> NJU 01 | C213: =ESTADISTICA!C213 -> Sallares y Parrillo | D213: =ESTADISTICA!D213 -> Domo | E213: =ESTADISTICA!E213 -> Fibra Optica | F213: =ESTADISTICA!F213 -> 0 | G213: =ESTADISTICA!G213 -> 0 | H213: =ESTADISTICA!H213 -> 0 | ... AJ213: =ESTADISTICA!AJ213 -> #REF!
A214: =ESTADISTICA!A214 -> 9 DE JULIO | B214: =ESTADISTICA!B214 -> NJU02 | C214: =ESTADISTICA!C214 -> Ituzaingo y Boccuzzi | D214: =ESTADISTICA!D214 -> Domo | E214: =ESTADISTICA!E214 -> Radio | F214: =ESTADISTICA!F214 -> 0 | G214: =ESTADISTICA!G214 -> 0 | H214: =ESTADISTICA!H214 -> 0 | ... AJ214: =ESTADISTICA!AJ214 -> #REF!
A215: =ESTADISTICA!A215 -> 9 DE JULIO | B215: =ESTADISTICA!B215 -> NJU03 | C215: =ESTADISTICA!C215 -> San Juan y Parrillo | D215: =ESTADISTICA!D215 -> Domo | E215: =ESTADISTICA!E215 -> PTO A FO | F215: =ESTADISTICA!F215 -> 0 | G215: =ESTADISTICA!G215 -> 0 | H215: =ESTADISTICA!H215 -> 0 | ... AJ215: =ESTADISTICA!AJ215 -> #REF!
A216: =ESTADISTICA!A216 -> 9 DE JULIO | B216: =ESTADISTICA!B216 -> NJU04 | C216: =ESTADISTICA!C216 -> Ituzaingo y 214 A | D216: =ESTADISTICA!D216 -> Domo | E216: =ESTADISTICA!E216 -> Radio | F216: =ESTADISTICA!F216 -> 0 | G216: =ESTADISTICA!G216 -> 0 | H216: =ESTADISTICA!H216 -> 0 | ... AJ216: =ESTADISTICA!AJ216 -> #REF!
A217: =ESTADISTICA!A217 -> ZEBALLOS CENTRO | B217: =ESTADISTICA!B217 -> NJU05 | C217: =ESTADISTICA!C217 -> Ituzaingo y Alem | D217: =ESTADISTICA!D217 -> Domo | E217: =ESTADISTICA!E217 -> Radio | F217: =ESTADISTICA!F217 -> 0 | G217: =ESTADISTICA!G217 -> 0 | H217: =ESTADISTICA!H217 -> 0 | ... AJ217: =ESTADISTICA!AJ217 -> #REF!
A218: =ESTADISTICA!A218 -> CENTRO | B218: =ESTADISTICA!B218 -> NJU06 | C218: =ESTADISTICA!C218 -> Sallares y Rodo | D218: =ESTADISTICA!D218 -> Domo | E218: =ESTADISTICA!E218 -> Fibra Optica | F218: =ESTADISTICA!F218 -> 0 | G218: =ESTADISTICA!G218 -> 0 | H218: =ESTADISTICA!H218 -> 0 | ... AJ218: =ESTADISTICA!AJ218 -> #REF!
A219: =ESTADISTICA!A219 -> 9 DE JULIO | B219: =ESTADISTICA!B219 -> NJU07 | C219: =ESTADISTICA!C219 -> Gral. Juan Domingo Peron y Parrillo | D219: =ESTADISTICA!D219 -> Domo | E219: =ESTADISTICA!E219 -> Fibra Optica | F219: =ESTADISTICA!F219 -> 0 | G219: =ESTADISTICA!G219 -> 0 | H219: =ESTADISTICA!H219 -> 0 | ... AJ219: =ESTADISTICA!AJ219 -> #REF!
... A516: =ESTADISTICA!A516 -> 0 | B516: =ESTADISTICA!B516 -> 0 | C516: =ESTADISTICA!C516 -> 0 | D516: =ESTADISTICA!D516 -> 0 | E516: =ESTADISTICA!E516 -> 0 | F516: =ESTADISTICA!F516 -> 0 | G516: =ESTADISTICA!G516 -> 0 | H516: =ESTADISTICA!H516 -> 0 | ... AJ516: =ESTADISTICA!AJ516 -> #REF!

Sheet APAGADOS FIBRA
C1: TOTAL FIBRA | D1: =COUNTIFS(E4:E401,"=Fibra Optica") -> 270
E2: APAGADOS | F2: =COUNTIFS(F4:F501, "=APAGADO",E4:E501,"=Fibra Optica") -> 15 | G2: =COUNTIFS(G4:G501, "=APAGADO",E4:E501,"=Fibra Optica") -> 16 | H2: =COUNTIFS(H4:H501, "=APAGADO",E4:E501,"=Fibra Optica") -> 15 | I2: =COUNTIFS(I4:I501, "=APAGADO",E4:E501,"=Fibra Optica") -> 12 | J2: =COUNTIFS(J4:J501, "=APAGADO",E4:E501,"=Fibra Optica") -> 13 | K2: =COUNTIFS(K4:K501, "=APAGADO",E4:E501,"=Fibra Optica") -> 0 | L2: =COUNTIFS(L4:L501, "=APAGADO",E4:E501,"=Fibra Optica") -> 0 | M2: =COUNTIFS(M4:M501, "=APAGADO",E4:E501,"=Fibra Optica") -> 0 | N2: =COUNTIFS(N4:N501, "=APAGADO",E4:E501,"=Fibra Optica") -> 0 | O2: =COUNTIFS(O4:O501, "=APAGADO",E4:E501,"=Fibra Optica") -> 0 | P2: =COUNTIFS(P4:P601, "=APAGADO",E4:E601,"=Fibra Optica") -> 0 | Q2: =COUNTIFS(Q4:Q501, "=APAGADO",E4:E501,"=Fibra Optica") -> 0 | R2: =COUNTIFS(R4:R501, "=APAGADO",E4:E501,"=Fibra Optica") -> 0 | S2: =COUNTIFS(S4:S501, "=APAGADO",E4:E501,"=Fibra Optica") -> 0 | T2: =COUNTIFS(T4:T501, "=APAGADO",E4:E501,"=Fibra Optica") -> 0 | U2: =COUNTIFS(U4:U501, "=APAGADO",E4:E501,"=Fibra Optica") -> 0 | V2: =COUNTIFS(V4:V501, "=APAGADO",E4:E501,"=Fibra Optica") -> 0 | W2: =COUNTIFS(W4:W501, "=APAGADO",E4:E501,"=Fibra Optica") -> 0 | X2: =COUNTIFS(X4:X501, "=APAGADO",E4:E501,"=Fibra Optica") -> 0 | Y2: =COUNTIFS(Y4:Y501, "=APAGADO",E4:E501,"=Fibra Optica") -> 0 | Z2: =COUNTIFS(Z4:Z501, "=APAGADO",E4:E501,"=Fibra Optica") -> 0 | AA2: =COUNTIFS(AA4:AA501, "=APAGADO",E4:E501,"=Fibra Optica") -> 0 | AB2: =COUNTIFS(AB4:AB501, "=APAGADO",E4:E501,"=Fibra Optica") -> 0 | AC2: =COUNTIFS(AC4:AC601, "=APAGADO",E4:E601,"=Fibra Optica") -> 0 | AD2: =COUNTIFS(AD4:AD501, "=APAGADO",E4:E501,"=Fibra Optica") -> 0 | AE2: =COUNTIFS(AE4:AE501, "=APAGADO",E4:E501,"=Fibra Optica") -> 0 | AF2: =COUNTIFS(AF4:AF501, "=APAGADO",E4:E501,"=Fibra Optica") -> 0 | AG2: =COUNTIFS(AG4:AG501, "=APAGADO",E4:E501,"=Fibra Optica") -> 0 | AH2: =COUNTIFS(AH4:AH501, "=APAGADO",E4:E501,"=Fibra Optica") -> 0 | AI2: =COUNTIFS(AI4:AI401, "=APAGADO",E4:E401,"=Fibra Optica") -> 0 | AJ2: =COUNTIFS(AJ4:AJ401, "=APAGADO",F4:F401,"=Fibra Optica") -> 0
A3: =ESTADISTICA!A1 -> Barrio | B3: =ESTADISTICA!B1 -> [Denominacion] | C3: =ESTADISTICA!C1 -> [Ubicacion] | D3: =ESTADISTICA!D1 -> [Tipo de Camara] | E3: =ESTADISTICA!E1 -> [Tipo de Conexion] | F3: =ESTADISTICA!F1 -> 45200 | G3: =ESTADISTICA!G1 -> 45201 | H3: =ESTADISTICA!H1 -> 45202 | ... AJ3: =ESTADISTICA!AJ1 -> #REF!
A4: ='RESUMEN TOTAL'!A7 -> ALTAMIRA | B4: ='RESUMEN TOTAL'!B7 -> ALT 03 | C4: ='RESUMEN TOTAL'!D7 -> Bombero Galarza y Necochea | D4: ='RESUMEN TOTAL'!E7 -> Domo | E4: ='RESUMEN TOTAL'!F7 -> Fibra Optica | F4: ='RESUMEN TOTAL'!L7 -> 0 | G4: ='RESUMEN TOTAL'!M7 -> 0 | H4: ='RESUMEN TOTAL'!N7 -> 0 | I4: ='RESUMEN TOTAL'!O7 -> 0 | J4: ='RESUMEN TOTAL'!P7 -> 0 | K4: ='RESUMEN TOTAL'!Q7 -> 0 | L4: ='RESUMEN TOTAL'!R7 -> 0 | M4: ='RESUMEN TOTAL'!S7 -> 0 | ... AI4: ='RESUMEN TOTAL'!AO7 -> 0 | AJ4: ='RESUMEN TOTAL'!#REF! -> #REF!
A5: ='RESUMEN TOTAL'!A8 -> ALTAMIRA | B5: ='RESUMEN TOTAL'!B8 -> ALT 04 | C5: ='RESUMEN TOTAL'!D8 -> Francia y Necochea | D5: ='RESUMEN TOTAL'!E8 -> Domo | E5: ='RESUMEN TOTAL'!F8 -> Fibra Optica | F5: ='RESUMEN TOTAL'!L8 -> 0 | G5: ='RESUMEN TOTAL'!M8 -> 0 | H5: ='RESUMEN TOTAL'!N8 -> 0 | I5: ='RESUMEN TOTAL'!O8 -> 0 | J5: ='RESUMEN TOTAL'!P8 -> 0 | K5: ='RESUMEN TOTAL'!Q8 -> 0 | L5: ='RESUMEN TOTAL'!R8 -> 0 | M5: ='RESUMEN TOTAL'!S8 -> 0 | ... AI5: ='RESUMEN TOTAL'!AO8 -> 0 | AJ5: ='RESUMEN TOTAL'!#REF! -> #REF!
A6: ='RESUMEN TOTAL'!A9 -> ALTAMIRA | B6: ='RESUMEN TOTAL'!B9 -> ALT05 | C6: ='RESUMEN TOTAL'!D9 -> Av. Calchaqui y Bombero Galarza | D6: ='RESUMEN TOTAL'!E9 -> Domo | E6: ='RESUMEN TOTAL'!F9 -> PTO A FO | F6: ='RESUMEN TOTAL'!L9 -> 0 | G6: ='RESUMEN TOTAL'!M9 -> 0 | H6: ='RESUMEN TOTAL'!N9 -> 0 | I6: ='RESUMEN TOTAL'!O9 -> 0 | J6: ='RESUMEN TOTAL'!P9 -> 0 | K6: ='RESUMEN TOTAL'!Q9 -> 0 | L6: ='RESUMEN TOTAL'!R9 -> 0 | M6: ='RESUMEN TOTAL'!S9 -> 0 | ... AI6: ='RESUMEN TOTAL'!AO9 -> 0 | AJ6: ='RESUMEN TOTAL'!#REF! -> #REF!
A7: ='RESUMEN TOTAL'!A10 -> ALTAMIRA | B7: ='RESUMEN TOTAL'!B10 -> ALT 06 | C7: ='RESUMEN TOTAL'!D10 -> LOPE DE VEGA Y NECOCHEA | D7: ='RESUMEN TOTAL'!E10 -> Domo | E7: ='RESUMEN TOTAL'!F10 -> PTO A FO | F7: ='RESUMEN TOTAL'!L10 -> 0 | G7: ='RESUMEN TOTAL'!M10 -> 0 | H7: ='RESUMEN TOTAL'!N10 -> 0 | I7: ='RESUMEN TOTAL'!O10 -> 0 | J7: ='RESUMEN TOTAL'!P10 -> 0 | K7: ='RESUMEN TOTAL'!Q10 -> 0 | L7: ='RESUMEN TOTAL'!R10 -> 0 | M7: ='RESUMEN TOTAL'!S10 -> 0 | ... AI7: ='RESUMEN TOTAL'!AO10 -> 0 | AJ7: ='RESUMEN TOTAL'!#REF! -> #REF!
A8: ='RESUMEN TOTAL'!A11 -> ALTAMIRA | B8: ='RESUMEN TOTAL'!B11 -> ALT07 | C8: ='RESUMEN TOTAL'!D11 -> AV. CALCHAQUI Y AV. DEL TRABAJO | D8: ='RESUMEN TOTAL'!E11 -> DOMO | E8: ='RESUMEN TOTAL'!F11 -> PTO A FO | F8: ='RESUMEN TOTAL'!L11 -> 0 | G8: ='RESUMEN TOTAL'!M11 -> 0 | H8: ='RESUMEN TOTAL'!N11 -> 0 | I8: ='RESUMEN TOTAL'!O11 -> 0 | J8: ='RESUMEN TOTAL'!P11 -> 0 | K8: ='RESUMEN TOTAL'!Q11 -> 0 | L8: ='RESUMEN TOTAL'!R11 -> 0 | M8: ='RESUMEN TOTAL'!S11 -> 0 | ... AI8: ='RESUMEN TOTAL'!AO11 -> 0 | AJ8: ='RESUMEN TOTAL'!#REF! -> #REF!
A9: ='RESUMEN TOTAL'!A12 -> ALTAMIRA | B9: ='RESUMEN TOTAL'!B12 -> ALT 08 | C9: ='RESUMEN TOTAL'!D12 -> HUMAITA Y NECOCHEA | D9: ='RESUMEN TOTAL'!E12 -> DOMO | E9: ='RESUMEN TOTAL'!F12 -> Fibra Optica | F9: ='RESUMEN TOTAL'!L12 -> 0 | G9: ='RESUMEN TOTAL'!M12 -> 0 | H9: ='RESUMEN TOTAL'!N12 -> 0 | I9: ='RESUMEN TOTAL'!O12 -> 0 | J9: ='RESUMEN TOTAL'!P12 -> 0 | K9: ='RESUMEN TOTAL'!Q12 -> 0 | L9: ='RESUMEN TOTAL'!R12 -> 0 | M9: ='RESUMEN TOTAL'!S12 -> 0 | ... AI9: ='RESUMEN TOTAL'!AO12 -> 0 | AJ9: ='RESUMEN TOTAL'!#REF! -> #REF!
A10: ='RESUMEN TOTAL'!A13 -> ALTAMIRA | B10: ='RESUMEN TOTAL'!B13 -> ALT 09 | C10: ='RESUMEN TOTAL'!D13 -> NECOCHEA Y CURUPAITY | D10: ='RESUMEN TOTAL'!E13 -> DOMO | E10: ='RESUMEN TOTAL'!F13 -> Fibra Optica | F10: ='RESUMEN TOTAL'!L13 -> 0 | G10: ='RESUMEN TOTAL'!M13 -> 0 | H10: ='RESUMEN TOTAL'!N13 -> 0 | I10: ='RESUMEN TOTAL'!O13 -> 0 | J10: ='RESUMEN TOTAL'!P13 -> 0 | K10: ='RESUMEN TOTAL'!Q13 -> 0 | L10: ='RESUMEN TOTAL'!R13 -> 0 | M10: ='RESUMEN TOTAL'!S13 -> 0 | ... AI10: ='RESUMEN TOTAL'!AO13 -> 0 | AJ10: ='RESUMEN TOTAL'!#REF! -> #REF!
A11: ='RESUMEN TOTAL'!A14 -> ALTAMIRA | B11: ='RESUMEN TOTAL'!B14 -> ALT 10 | C11: ='RESUMEN TOTAL'!D14 -> Calchaqui y Francia | D11: ='RESUMEN TOTAL'!E14 -> Domo | E11: ='RESUMEN TOTAL'!F14 -> Radio | F11: ='RESUMEN TOTAL'!L14 -> 0 | G11: ='RESUMEN TOTAL'!M14 -> 0 | H11: ='RESUMEN TOTAL'!N14 -> 0 | I11: ='RESUMEN TOTAL'!O14 -> 0 | J11: ='RESUMEN TOTAL'!P14 -> 0 | K11: ='RESUMEN TOTAL'!Q14 -> 0 | L11: ='RESUMEN TOTAL'!R14 -> 0 | M11: ='RESUMEN TOTAL'!S14 -> 0 | ... AI11: ='RESUMEN TOTAL'!AO14 -> 0 | AJ11: ='RESUMEN TOTAL'!#REF! -> #REF!
A12: ='RESUMEN TOTAL'!A15 -> AGUSTIN RAMIREZ | B12: ='RESUMEN TOTAL'!B15 -> ARA 01 | C12: ='RESUMEN TOTAL'!D15 -> Malambo y Tranquera | D12: ='RESUMEN TOTAL'!E15 -> Domo | E12: ='RESUMEN TOTAL'!F15 -> Fibra Optica | F12: ='RESUMEN TOTAL'!L15 -> APAGADO | G12: ='RESUMEN TOTAL'!M15 -> APAGADO | H12: ='RESUMEN TOTAL'!N15 -> APAGADO | I12: ='RESUMEN TOTAL'!O15 -> APAGADO | J12: ='RESUMEN TOTAL'!P15 -> APAGADO | K12: ='RESUMEN TOTAL'!Q15 -> 0 | L12: ='RESUMEN TOTAL'!R15 -> 0 | M12: ='RESUMEN TOTAL'!S15 -> 0 | ... AI12: ='RESUMEN TOTAL'!AO15 -> 0 | AJ12: ='RESUMEN TOTAL'!#REF! -> #REF!
A13: ='RESUMEN TOTAL'!A16 -> BELGRANO | B13: ='RESUMEN TOTAL'!B16 -> BEL 01 | C13: ='RESUMEN TOTAL'!D16 -> San Martin y Dardo Rocha | D13: ='RESUMEN TOTAL'!E16 -> DOMO | E13: ='RESUMEN TOTAL'!F16 -> Fibra Optica | F13: ='RESUMEN TOTAL'!L16 -> 0 | G13: ='RESUMEN TOTAL'!M16 -> 0 | H13: ='RESUMEN TOTAL'!N16 -> 0 | I13: ='RESUMEN TOTAL'!O16 -> 0 | J13: ='RESUMEN TOTAL'!P16 -> 0 | K13: ='RESUMEN TOTAL'!Q16 -> 0 | L13: ='RESUMEN TOTAL'!R16 -> 0 | M13: ='RESUMEN TOTAL'!S16 -> 0 | ... AI13: ='RESUMEN TOTAL'!AO16 -> 0 | AJ13: ='RESUMEN TOTAL'!#REF! -> #REF!
A14: ='RESUMEN TOTAL'!A17 -> BELGRANO | B14: ='RESUMEN TOTAL'!B17 -> BEL 02 | C14: ='RESUMEN TOTAL'!D17 -> Guardia vieja y Fronteriz | D14: ='RESUMEN TOTAL'!E17 -> DOMO | E14: ='RESUMEN TOTAL'!F17 -> Fibra Optica | F14: ='RESUMEN TOTAL'!L17 -> 0 | G14: ='RESUMEN TOTAL'!M17 -> 0 | H14: ='RESUMEN TOTAL'!N17 -> 0 | I14: ='RESUMEN TOTAL'!O17 -> 0 | J14: ='RESUMEN TOTAL'!P17 -> 0 | K14: ='RESUMEN TOTAL'!Q17 -> 0 | L14: ='RESUMEN TOTAL'!R17 -> 0 | M14: ='RESUMEN TOTAL'!S17 -> 0 | ... AI14: ='RESUMEN TOTAL'!AO17 -> 0 | AJ14: ='RESUMEN TOTAL'!#REF! -> #REF!
A15: ='RESUMEN TOTAL'!A18 -> BOSQUES CENTRO | B15: ='RESUMEN TOTAL'!B18 -> BOSQC 01 | C15: ='RESUMEN TOTAL'!D18 -> LUIS AGOTE E/DANUNCIO Y CAMPOAMOR | D15: ='RESUMEN TOTAL'!E18 -> Fija | E15: ='RESUMEN TOTAL'!F18 -> Radio | F15: ='RESUMEN TOTAL'!L18 -> APAGADO | G15: ='RESUMEN TOTAL'!M18 -> APAGADO | H15: ='RESUMEN TOTAL'!N18 -> 0 | I15: ='RESUMEN TOTAL'!O18 -> 0 | J15: ='RESUMEN TOTAL'!P18 -> APAGADO | K15: ='RESUMEN TOTAL'!Q18 -> 0 | L15: ='RESUMEN TOTAL'!R18 -> 0 | M15: ='RESUMEN TOTAL'!S18 -> 0 | ... AI15: ='RESUMEN TOTAL'!AO18 -> 0 | AJ15: ='RESUMEN TOTAL'!#REF! -> #REF!
... A424: ='RESUMEN TOTAL'!A427 -> VILLA ANGELICA | B424: ='RESUMEN TOTAL'!B427 -> VDPL06 | C424: ='RESUMEN TOTAL'!D427 -> Thevenet e/ Islas Orcadas y Gardel | D424: ='RESUMEN TOTAL'!E427 -> Domo | E424: ='RESUMEN TOTAL'!F427 -> Radio | F424: ='RESUMEN TOTAL'!L427 -> 0 | G424: ='RESUMEN TOTAL'!M427 -> 0 | H424: ='RESUMEN TOTAL'!N427 -> 0 | I424: ='RESUMEN TOTAL'!O427 -> 0 | J424: ='RESUMEN TOTAL'!P427 -> 0 | K424: ='RESUMEN TOTAL'!Q427 -> 0 | L424: ='RESUMEN TOTAL'!R427 -> 0 | M424: ='RESUMEN TOTAL'!S427 -> 0 | ... AI424: ='RESUMEN TOTAL'!AO427 -> 0 | AJ424: ='RESUMEN TOTAL'!#REF! -> #REF!
A425: ='RESUMEN TOTAL'!A429 -> VILLA HUDSON | B425: ='RESUMEN TOTAL'!B429 -> VHS 01 | C425: ='RESUMEN TOTAL'!D429 -> AV. HUDSON Y AV. LUJAN | D425: ='RESUMEN TOTAL'!E429 -> DOMO | E425: ='RESUMEN TOTAL'!F429 -> Fibra Optica | F425: ='RESUMEN TOTAL'!L429 -> 0 | G425: ='RESUMEN TOTAL'!M429 -> 0 | H425: ='RESUMEN TOTAL'!N429 -> 0 | I425: ='RESUMEN TOTAL'!O429 -> 0 | J425: ='RESUMEN TOTAL'!P429 -> 0 | K425: ='RESUMEN TOTAL'!Q429 -> 0 | L425: ='RESUMEN TOTAL'!R429 -> 0 | M425: ='RESUMEN TOTAL'!S429 -> 0 | ... AI425: ='RESUMEN TOTAL'!AO429 -> 0 | AJ425: ='RESUMEN TOTAL'!#REF! -> #REF!
A426: ='RESUMEN TOTAL'!A430 -> VILLA HUDSON | B426: ='RESUMEN TOTAL'!B430 -> VHS 02 | C426: ='RESUMEN TOTAL'!D430 -> AV. LUJAN Y CALLE 909 A | D426: ='RESUMEN TOTAL'!E430 -> DOMO | E426: ='RESUMEN TOTAL'!F430 -> Fibra Optica | F426: ='RESUMEN TOTAL'!L430 -> 0 | G426: ='RESUMEN TOTAL'!M430 -> 0 | H426: ='RESUMEN TOTAL'!N430 -> 0 | I426: ='RESUMEN TOTAL'!O430 -> 0 | J426: ='RESUMEN TOTAL'!P430 -> 0 | K426: ='RESUMEN TOTAL'!Q430 -> 0 | L426: ='RESUMEN TOTAL'!R430 -> 0 | M426: ='RESUMEN TOTAL'!S430 -> 0 | ... AI426: ='RESUMEN TOTAL'!AO430 -> 0 | AJ426: ='RESUMEN TOTAL'!#REF! -> #REF!
A427: ='RESUMEN TOTAL'!A431 -> VILLA HUDSON | B427: ='RESUMEN TOTAL'!B431 -> VHS 03 (fija 1) | C427: ='RESUMEN TOTAL'!D431 -> AV. HUDSON Y LOS INMIGRANTES | D427: ='RESUMEN TOTAL'!E431 -> Fija | E427: ='RESUMEN TOTAL'!F431 -> Fibra Optica | F427: ='RESUMEN TOTAL'!L431 -> 0 | G427: ='RESUMEN TOTAL'!M431 -> 0 | H427: ='RESUMEN TOTAL'!N431 -> 0 | I427: ='RESUMEN TOTAL'!O431 -> 0 | J427: ='RESUMEN TOTAL'!P431 -> 0 | K427: ='RESUMEN TOTAL'!Q431 -> 0 | L427: ='RESUMEN TOTAL'!R431 -> 0 | M427: ='RESUMEN TOTAL'!S431 -> 0 | ... AI427: ='RESUMEN TOTAL'!AO431 -> 0 | AJ427: ='RESUMEN TOTAL'!#REF! -> #REF!
A428: ='RESUMEN TOTAL'!A432 -> VILLA HUDSON | B428: ='RESUMEN TOTAL'!B432 -> VHS 04 (fija 2) | C428: ='RESUMEN TOTAL'!D432 -> AV. HUDSON Y LOS INMIGRANTES | D428: ='RESUMEN TOTAL'!E432 -> Fija | E428: ='RESUMEN TOTAL'!F432 -> Fibra Optica | F428: ='RESUMEN TOTAL'!L432 -> 0 | G428: ='RESUMEN TOTAL'!M432 -> 0 | H428: ='RESUMEN TOTAL'!N432 -> 0 | I428: ='RESUMEN TOTAL'!O432 -> 0 | J428: ='RESUMEN TOTAL'!P432 -> 0 | K428: ='RESUMEN TOTAL'!Q432 -> 0 | L428: ='RESUMEN TOTAL'!R432 -> 0 | M428: ='RESUMEN TOTAL'!S432 -> 0 | ... AI428: ='RESUMEN TOTAL'!AO432 -> 0 | AJ428: ='RESUMEN TOTAL'!#REF! -> #REF!
A429: ='RESUMEN TOTAL'!A433 -> VILLA ARIAS | B429: ='RESUMEN TOTAL'!B433 -> VLA 01 (fija 1) | C429: ='RESUMEN TOTAL'!D433 -> 820 Y SOLER | D429: ='RESUMEN TOTAL'!E433 -> Fija | E429: ='RESUMEN TOTAL'!F433 -> Fibra Optica | F429: ='RESUMEN TOTAL'!L433 -> 0 | G429: ='RESUMEN TOTAL'!M433 -> 0 | H429: ='RESUMEN TOTAL'!N433 -> 0 | I429: ='RESUMEN TOTAL'!O433 -> 0 | J429: ='RESUMEN TOTAL'!P433 -> 0 | K429: ='RESUMEN TOTAL'!Q433 -> 0 | L429: ='RESUMEN TOTAL'!R433 -> 0 | M429: ='RESUMEN TOTAL'!S433 -> 0 | ... AI429: ='RESUMEN TOTAL'!AO433 -> 0 | AJ429: ='RESUMEN TOTAL'!#REF! -> #REF!
A430: ='RESUMEN TOTAL'!A434 -> VILLA ARIAS | B430: ='RESUMEN TOTAL'!B434 -> VLA 02 | C430: ='RESUMEN TOTAL'!D434 -> ESPORA Y HUDSON | D430: ='RESUMEN TOTAL'!E434 -> DOMO | E430: ='RESUMEN TOTAL'!F434 -> Fibra Optica | F430: ='RESUMEN TOTAL'!L434 -> 0 | G430: ='RESUMEN TOTAL'!M434 -> 0 | H430: ='RESUMEN TOTAL'!N434 -> 0 | I430: ='RESUMEN TOTAL'!O434 -> 0 | J430: ='RESUMEN TOTAL'!P434 -> 0 | K430: ='RESUMEN TOTAL'!Q434 -> 0 | L430: ='RESUMEN TOTAL'!R434 -> 0 | M430: ='RESUMEN TOTAL'!S434 -> 0 | ... AI430: ='RESUMEN TOTAL'!AO434 -> 0 | AJ430: ='RESUMEN TOTAL'!#REF! -> #REF!
A431: ='RESUMEN TOTAL'!A435 -> VILLA ARIAS | B431: ='RESUMEN TOTAL'!B435 -> VLA03 (fija 2) | C431: ='RESUMEN TOTAL'!D435 -> 820 y SOLER | D431: ='RESUMEN TOTAL'!E435 -> Fija | E431: ='RESUMEN TOTAL'!F435 -> Fibra Optica | F431: ='RESUMEN TOTAL'!L435 -> 0 | G431: ='RESUMEN TOTAL'!M435 -> 0 | H431: ='RESUMEN TOTAL'!N435 -> 0 | I431: ='RESUMEN TOTAL'!O435 -> 0 | J431: ='RESUMEN TOTAL'!P435 -> 0 | K431: ='RESUMEN TOTAL'!Q435 -> 0 | L431: ='RESUMEN TOTAL'!R435 -> 0 | M431: ='RESUMEN TOTAL'!S435 -> 0 | ... AI431: ='RESUMEN TOTAL'!AO435 -> 0 | AJ431: ='RESUMEN TOTAL'!#REF! -> #REF!
A432: ='RESUMEN TOTAL'!A436 -> VILLA ARIAS | B432: ='RESUMEN TOTAL'!B436 -> VLA04 | C432: ='RESUMEN TOTAL'!D436 -> ESPORA Y MARTIN GRASS | D432: ='RESUMEN TOTAL'!E436 -> DOMO | E432: ='RESUMEN TOTAL'!F436 -> Fibra Optica | F432: ='RESUMEN TOTAL'!L436 -> 0 | G432: ='RESUMEN TOTAL'!M436 -> 0 | H432: ='RESUMEN TOTAL'!N436 -> 0 | I432: ='RESUMEN TOTAL'!O436 -> 0 | J432: ='RESUMEN TOTAL'!P436 -> 0 | K432: ='RESUMEN TOTAL'!Q436 -> 0 | L432: ='RESUMEN TOTAL'!R436 -> 0 | M432: ='RESUMEN TOTAL'!S436 -> 0 | ... AI432: ='RESUMEN TOTAL'!AO436 -> 0 | AJ432: ='RESUMEN TOTAL'!#REF! -> #REF!
A433: ='RESUMEN TOTAL'!A437 -> VILLA ARIAS | B433: ='RESUMEN TOTAL'!B437 -> VLA05 | C433: ='RESUMEN TOTAL'!D437 -> ESPORA Y 802 | D433: ='RESUMEN TOTAL'!E437 -> DOMO | E433: ='RESUMEN TOTAL'!F437 -> Fibra Optica | F433: ='RESUMEN TOTAL'!L437 -> 0 | G433: ='RESUMEN TOTAL'!M437 -> 0 | H433: ='RESUMEN TOTAL'!N437 -> 0 | I433: ='RESUMEN TOTAL'!O437 -> 0 | J433: ='RESUMEN TOTAL'!P437 -> 0 | K433: ='RESUMEN TOTAL'!Q437 -> 0 | L433: ='RESUMEN TOTAL'!R437 -> 0 | M433: ='RESUMEN TOTAL'!S437 -> 0 | ... AI433: ='RESUMEN TOTAL'!AO437 -> 0 | AJ433: ='RESUMEN TOTAL'!#REF! -> #REF!
A434: ='RESUMEN TOTAL'!A438 -> VILLA MONICA NUEVA | B434: ='RESUMEN TOTAL'!B438 -> VMO 02 | C434: ='RESUMEN TOTAL'!D438 -> Rio Carapachay y Oroño | D434: ='RESUMEN TOTAL'!E438 -> Domo | E434: ='RESUMEN TOTAL'!F438 -> Radio | F434: ='RESUMEN TOTAL'!L438 -> 0 | G434: ='RESUMEN TOTAL'!M438 -> 0 | H434: ='RESUMEN TOTAL'!N438 -> 0 | I434: ='RESUMEN TOTAL'!O438 -> 0 | J434: ='RESUMEN TOTAL'!P438 -> 0 | K434: ='RESUMEN TOTAL'!Q438 -> 0 | L434: ='RESUMEN TOTAL'!R438 -> 0 | M434: ='RESUMEN TOTAL'!S438 -> 0 | ... AI434: ='RESUMEN TOTAL'!AO438 -> 0 | AJ434: ='RESUMEN TOTAL'!#REF! -> #REF!
A435: ='RESUMEN TOTAL'!A439 -> VILLA MONICA NUEVA | B435: ='RESUMEN TOTAL'!B439 -> VMO 03 (fija 1) | C435: ='RESUMEN TOTAL'!D439 -> EVA PERON E/ OROÑO Y 734 A | D435: ='RESUMEN TOTAL'!E439 -> Fija | E435: ='RESUMEN TOTAL'!F439 -> Fibra Optica | F435: ='RESUMEN TOTAL'!L439 -> 0 | G435: ='RESUMEN TOTAL'!M439 -> 0 | H435: ='RESUMEN TOTAL'!N439 -> 0 | I435: ='RESUMEN TOTAL'!O439 -> 0 | J435: ='RESUMEN TOTAL'!P439 -> 0 | K435: ='RESUMEN TOTAL'!Q439 -> 0 | L435: ='RESUMEN TOTAL'!R439 -> 0 | M435: ='RESUMEN TOTAL'!S439 -> 0 | ... AI435: ='RESUMEN TOTAL'!AO439 -> 0 | AJ435: ='RESUMEN TOTAL'!#REF! -> #REF!
