Workbook
Name _25_de_agosto: 'RESUMEN TOTAL'!$A$4:$D$386
Name _25_de_agosto_3: 'RESUMEN TOTAL'!$A$4:$D$398
Name BONOMOcam: Hoja1!$B$2
Name CANTIDAD_DE_CAMARAS: 'RESUMEN TOTAL'!$B$1
Name COSEIDIcam: Hoja1!$B$4

Sheet RESUMEN TOTAL
A1: CANTIDAD DE CAMARAS | B1: =COUNTA(B5:B622) -> 534 | D1: PORCIENTO DE CAIDAS | L1: =(L3)/(L2+L3) -> 0.10486891 | M1: =(M3)/(M2+M3) -> 0.11048689 | N1: =(N3)/(N2+N3) -> 0.11985019 | O1: =(O3)/(O2+O3) -> 0.11985019 | P1: =(P3)/(P2+P3) -> 0.13483146 | Q1: =(Q3)/(Q2+Q3) -> 0 | R1: =(R3)/(R2+R3) -> 0 | S1: =(S3)/(S2+S3) -> 0 | ... X1: =(X3)/(X2+X3) -> 0 | Z1: =(Z3)/(Z2+Z3) -> 0 | AA1: =(AA3)/(AA2+AA3) -> 0 | AB1: =(AB3)/(AB2+AB3) -> 0 | AC1: =(AC3)/(AC2+AC3) -> 0 | AD1: =(AD3)/(AD2+AD3) -> 0 | AE1: =(AE3)/(AE2+AE3) -> 0 | AF1: =(AF3)/(AF2+AF3) -> 0 | AG1: =(AG3)/(AG2+AG3) -> 0 | ... AP1: =(AP3)/(AP2+AP3) -> 0
D2: FUNCIONAN | L2: =B1-L3 -> 478 | M2: =CANTIDAD_DE_CAMARAS-M3 -> 475 | N2: =CANTIDAD_DE_CAMARAS-N3 -> 470 | O2: =CANTIDAD_DE_CAMARAS-O3 -> 470 | P2: =CANTIDAD_DE_CAMARAS-P3 -> 462 | Q2: =CANTIDAD_DE_CAMARAS-Q3 -> 534 | R2: =CANTIDAD_DE_CAMARAS-R3 -> 534 | S2: =CANTIDAD_DE_CAMARAS-S3 -> 534 | T2: =CANTIDAD_DE_CAMARAS-T3 -> 534 | ... AP2: =CANTIDAD_DE_CAMARAS-AP3 -> 534
D3: CAIDAS | L3: =COUNTIF(L4:L622, "apagado") -> 56 | M3: =COUNTIF(M4:M622, "apagado") -> 59 | N3: =COUNTIF(N4:N622, "apagado") -> 64 | O3: =COUNTIF(O4:O622, "apagado") -> 64 | P3: =COUNTIF(P4:P622, "apagado") -> 72 | Q3: =COUNTIF(Q4:Q622, "apagado") -> 0 | R3: =COUNTIF(R4:R622, "apagado") -> 0 | S3: =COUNTIF(S4:S622, "apagado") -> 0 | ... W3: =COUNTIF(W4:W622, "apagado") -> 0 | X3: =COUNTIF(X4:X522, "apagado") -> 0 | Y3: =COUNTIF(Y4:Y522, "apagado") -> 0 | Z3: =COUNTIF(Z4:Z622, "apagado") -> 0 | AA3: =COUNTIF(AA4:AA622, "apagado") -> 0 | AB3: =COUNTIF(AB4:AB622, "apagado") -> 0 | AC3: =COUNTIF(AC4:AC622, "apagado") -> 0 | AD3: =COUNTIF(AD4:AD622, "apagado") -> 0 | AE3: =COUNTIF(AE4:AE622, "apagado") -> 0 | AF3: =COUNTIF(AF4:AF622, "apagado") -> 0 | AG3: =COUNTIF(AG4:AG622, "apagado") -> 0 | ... AP3: =COUNTIF(AP4:AP622, "apagado") -> 0
A4: Barrio | B4: [Denominacion] | C4: [Empresa Mantenimiento] | D4: [Ubicacion] | E4: [Tipo de Camara] | F4: [Tipo de Conexion] | G4: Destino | I4: DIAS FUNCIONANDO | J4: DIAS CAIDA | K4: EFECTIVIDAD | L4: 45261 | M4: 45262 | N4: 45263 | O4: 45264 | P4: 45265 | Q4: 45266 | R4: 45267 | S4: 45268 | T4: 45269 | U4: 45270 | V4: 45271 | W4: 45272 | X4: 45273 | Y4: 45274 | Z4: 45275 | AA4: 45276 | AB4: 45277 | AC4: 45278 | AD4: 45279 | AE4: 45280 | AF4: 45281 | AG4: 45282 | AH4: 45283 | AI4: 45284 | AJ4: 45285 | AK4: 45286 | AL4: 45287 | AM4: 45288 | AN4: 45289 | AO4: 45290 | AP4: 45291
A5: ALTAMIRA | B5: ALT01 | C5: BONOMO | D5: Calchaqui y Sgto. Cabral | E5: Domo | F5: Fibra Optica | H5: 172.20.10.6 | I5: =COUNTIF(L5:AM5,"") -> 28 | J5: =COUNTIF(L5:AM5,"APAGADO") -> 0 | K5: =(I5)/(J5+I5) -> 1
A6: ALTAMIRA | B6: ALT02 | C6: BONOMO | D6: Calchaqui y Lope de Vega | E6: Domo | F6: PTO A FO | G6: CABRAL Y CALCHAQUI | H6: 172.20.12.218 | I6: =COUNTIF(L6:AM6,"") -> 28 | J6: =COUNTIF(L6:AM6,"APAGADO") -> 0 | K6: =(I6)/(J6+I6) -> 1
A7: ALTAMIRA | B7: ALT 03 | C7: BONOMO | D7: Bombero Galarza y Necochea | E7: Domo | F7: Fibra Optica | H7: 172.20.12.54 | I7: =COUNTIF(L7:AM7,"") -> 28 | J7: =COUNTIF(L7:AM7,"APAGADO") -> 0 | K7: =(I7)/(J7+I7) -> 1
A8: ALTAMIRA | B8: ALT 04 | C8: BONOMO | D8: Francia y Necochea | E8: Domo | F8: Fibra Optica | H8: 172.20.12.55 | I8: =COUNTIF(L8:AM8,"") -> 28 | J8: =COUNTIF(L8:AM8,"APAGADO") -> 0 | K8: =(I8)/(J8+I8) -> 1
A9: ALTAMIRA | B9: ALT05 | C9: BONOMO | D9: Av. Calchaqui y Bombero Galarza | E9: Domo | F9: PTO A FO | G9: NECOCHEA Y GALARZA | H9: 172.20.12.216 | I9: =COUNTIF(L9:AM9,"") -> 28 | J9: =COUNTIF(L9:AM9,"APAGADO") -> 0 | K9: =(I9)/(J9+I9) -> 1
A10: ALTAMIRA | B10: ALT 06 | C10: BONOMO | D10: LOPE DE VEGA Y NECOCHEA | E10: Domo | F10: PTO A FO | G10: NECOCHEA Y GALARZA | H10: 172.20.12.12 | I10: =COUNTIF(L10:AM10,"") -> 28 | J10: =COUNTIF(L10:AM10,"APAGADO") -> 0 | K10: =(I10)/(J10+I10) -> 1
A11: ALTAMIRA | B11: ALT07 | C11: BONOMO | D11: AV. CALCHAQUI Y AV. DEL TRABAJO | E11: DOMO | F11: PTO A FO | G11: CABRAL Y CALCHAQUI | H11: 172.20.10.57 | I11: =COUNTIF(L11:AM11,"") -> 28 | J11: =COUNTIF(L11:AM11,"APAGADO") -> 0 | K11: =(I11)/(J11+I11) -> 1
A12: ALTAMIRA | B12: ALT 08 | C12: BONOMO | D12: HUMAITA Y NECOCHEA | E12: DOMO | F12: Fibra Optica | H12: 172.20.11.215 | I12: =COUNTIF(L12:AM12,"") -> 28 | J12: =COUNTIF(L12:AM12,"APAGADO") -> 0 | K12: =(I12)/(J12+I12) -> 1
A13: ALTAMIRA | B13: ALT 09 | C13: BONOMO | D13: NECOCHEA Y CURUPAITY | E13: DOMO | F13: Fibra Optica | H13: 172.20.11.216 | I13: =COUNTIF(L13:AM13,"") -> 28 | J13: =COUNTIF(L13:AM13,"APAGADO") -> 0 | K13: =(I13)/(J13+I13) -> 1
A14: ALTAMIRA | B14: ALT 10 | C14: BONOMO | D14: Calchaqui y Francia | E14: Domo | F14: Radio | H14: 172.20.12.156 | I14: =COUNTIF(L14:AM14,"") -> 28 | J14: =COUNTIF(L14:AM14,"APAGADO") -> 0 | K14: =(I14)/(J14+I14) -> 1
A15: AGUSTIN RAMIREZ | B15: ARA 01 | C15: BONOMO | D15: Malambo y Tranquera | E15: Domo | F15: Fibra Optica | H15: 172.20.12.110 | I15: =COUNTIF(L15:AM15,"") -> 25 | J15: =COUNTIF(L15:AM15,"APAGADO") -> 3 | K15: =(I15)/(J15+I15) -> 0.89285714 | N15: APAGADO | O15: APAGADO | P15: APAGADO
A16: BELGRANO | B16: BEL 01 | C16: BONOMO | D16: San Martin y Dardo Rocha | E16: DOMO | F16: Fibra Optica | H16: 172.20.12.64 | I16: =COUNTIF(L16:AM16,"") -> 28 | J16: =COUNTIF(L16:AM16,"APAGADO") -> 0 | K16: =(I16)/(J16+I16) -> 1
A17: BELGRANO | B17: BEL 02 | C17: BONOMO | D17: Guardia vieja y Fronteriz | E17: DOMO | F17: Fibra Optica | I17: =COUNTIF(L17:AM17,"") -> 28 | J17: =COUNTIF(L17:AM17,"APAGADO") -> 0 | K17: =(I17)/(J17+I17) -> 1
A18: BOSQUES CENTRO | B18: BOSQC 01 | C18: COSEIDI | D18: LUIS AGOTE E/DANUNCIO Y CAMPOAMOR | E18: Fija | F18: Radio | H18: 172.20.11.15 | I18: =COUNTIF(L18:AM18,"") -> 28 | J18: =COUNTIF(L18:AM18,"APAGADO") -> 0 | K18: =(I18)/(J18+I18) -> 1
A19: BOSQUES CENTRO | B19: BOSQC 02 | C19: COSEIDI | D19: LUIS AGOTE E/DANUNCIO Y CAMPOAMOR | E19: Fija | F19: Radio | H19: 172.20.11.16 | I19: =COUNTIF(L19:AM19,"") -> 28 | J19: =COUNTIF(L19:AM19,"APAGADO") -> 0 | K19: =(I19)/(J19+I19) -> 1
A20: BOSQUES CENTRO | B20: BOSQC 03 | C20: COSEIDI | D20: BENAVENTE Y LUIS AGOTE | E20: Fija | F20: Radio | H20: 172.20.11.13 | I20: =COUNTIF(L20:AM20,"") -> 28 | J20: =COUNTIF(L20:AM20,"APAGADO") -> 0 | K20: =(I20)/(J20+I20) -> 1
A21: BOSQUES CENTRO | B21: BOSQC 04 | C21: COSEIDI | D21: BENAVENTE Y LUIS AGOTE | E21: Fija | F21: Radio | H21: 172.20.11.113 | I21: =COUNTIF(L21:AM21,"") -> 28 | J21: =COUNTIF(L21:AM21,"APAGADO") -> 0 | K21: =(I21)/(J21+I21) -> 1
A22: BOSQUES CENTRO | B22: BOSQC 05 | C22: COSEIDI | D22: LUIS AGOTE Y RUTA 36 | E22: Fija | F22: Radio | H22: 172.20.11.17 | I22: =COUNTIF(L22:AM22,"") -> 28 | J22: =COUNTIF(L22:AM22,"APAGADO") -> 0 | K22: =(I22)/(J22+I22) -> 1
A23: BOSQUES CENTRO | B23: BOSQC 06 | C23: COSEIDI | D23: LUIS AGOTE Y RUTA 36 | E23: Fija | F23: Radio | H23: 172.20.11.18 | I23: =COUNTIF(L23:AM23,"") -> 28 | J23: =COUNTIF(L23:AM23,"APAGADO") -> 0 | K23: =(I23)/(J23+I23) -> 1
A24: CENTRO | B24: CEN01 | C24: BONOMO | D24: San Martin y 9 de Julio | E24: Fija | F24: Fibra Optica | H24: 172.20.11.10 | I24: =COUNTIF(L24:AM24,"") -> 28 | J24: =COUNTIF(L24:AM24,"APAGADO") -> 0 | K24: =(I24)/(J24+I24) -> 1
A25: CENTRO | B25: CEN02 | C25: BONOMO | D25: San Martin y Almafuerte | E25: Fija | F25: Fibra Optica | H25: 172.20.11.11 | I25: =COUNTIF(L25:AM25,"") -> 28 | J25: =COUNTIF(L25:AM25,"APAGADO") -> 0 | K25: =(I25)/(J25+I25) -> 1
A26: CENTRO | B26: CEN03 | C26: BONOMO | D26: San Martin y Sallares | E26: Domo | F26: Fibra Optica | H26: 172.20.12.30 | I26: =COUNTIF(L26:AM26,"") -> 28 | J26: =COUNTIF(L26:AM26,"APAGADO") -> 0 | K26: =(I26)/(J26+I26) -> 1
A27: CENTRO | B27: CEN04 | C27: BONOMO | D27: San Martin y Contreras | E27: Domo | F27: Fibra Optica | H27: 172.20.12.29 | I27: =COUNTIF(L27:AM27,"") -> 28 | J27: =COUNTIF(L27:AM27,"APAGADO") -> 0 | K27: =(I27)/(J27+I27) -> 1
A28: CENTRO | B28: CEN 05 | C28: BONOMO | D28: Bocuzzi e/España y San Martin | E28: DOMO | F28: Fibra Optica | H28: 172.20.10.200 | I28: =COUNTIF(L28:AM28,"") -> 28 | J28: =COUNTIF(L28:AM28,"APAGADO") -> 0 | K28: =(I28)/(J28+I28) -> 1
A29: CENTRO | B29: CEN06 | C29: BONOMO | D29: Monteagudo y A.del Valle | E29: Fija | F29: Fibra Optica | H29: 172.20.10.02 | I29: =COUNTIF(L29:AM29,"") -> 28 | J29: =COUNTIF(L29:AM29,"APAGADO") -> 0 | K29: =(I29)/(J29+I29) -> 1
... A34: CENTRO | B34: CEN11 | C34: BONOMO | D34: Monteagudo y Bocuzzi | E34: Domo | F34: Fibra Optica | H34: 172.20.10.24 | I34: =COUNTIF(L34:AM34,"") -> 28 | J34: =COUNTIF(L34:AM34,"APAGADO") -> 0 | K34: =(I34)/(J34+I34) -> 1
A35: CENTRO | B35: CEN 12 | C35: BONOMO | D35: Monteagudo y Mitre | E35: Domo | F35: Fibra Optica | H35: 172.20.10.23 | I35: =COUNTIF(L35:AM35,"") -> 27 | J35: =COUNTIF(L35:AM35,"APAGADO") -> 1 | K35: =(I35)/(J35+I35) -> 0.96428571 | P35: APAGADO
A36: CENTRO | B36: CEN 13 | C36: BONOMO | D36: 25 de Mayo y Maipu | E36: DOMO | F36: Fibra Optica | H36: 172.20.10.20 | I36: =COUNTIF(L36:AM36,"") -> 28 | J36: =COUNTIF(L36:AM36,"APAGADO") -> 0 | K36: =(I36)/(J36+I36) -> 1
A37: CENTRO | B37: CEN14 | C37: BONOMO | D37: Pte.Peron e/Pringles y Brown | E37: Domo | F37: Fibra Optica | H37: 172.20.10.21 | I37: =COUNTIF(L37:AM37,"") -> 28 | J37: =COUNTIF(L37:AM37,"APAGADO") -> 0 | K37: =(I37)/(J37+I37) -> 1
A38: CENTRO | B38: CEN15 | C38: BONOMO | D38: Alberdi y A.del Valle | E38: Domo | F38: Fibra Optica | H38: 172.20.10.35 | I38: =COUNTIF(L38:AM38,"") -> 28 | J38: =COUNTIF(L38:AM38,"APAGADO") -> 0 | K38: =(I38)/(J38+I38) -> 1
A39: CENTRO | B39: CEN16 | C39: BONOMO | D39: San Martin y Pte. Peron | E39: Fija | F39: Fibra Optica | H39: 172.20.12.36 | I39: =COUNTIF(L39:AM39,"") -> 28 | J39: =COUNTIF(L39:AM39,"APAGADO") -> 0 | K39: =(I39)/(J39+I39) -> 1
A40: CENTRO | B40: CEN17 | C40: BONOMO | D40: San Martin y Mitre | E40: Domo | F40: PTO A FO | G40: SAN MARTIN Y SALLARES | H40: 172.20.12.200 | I40: =COUNTIF(L40:AM40,"") -> 28 | J40: =COUNTIF(L40:AM40,"APAGADO") -> 0 | K40: =(I40)/(J40+I40) -> 1
A41: CENTRO | B41: CEN18 | C41: BONOMO | D41: Monteagudo e/Mitre y Sallares | E41: Fija | F41: Fibra Optica | H41: 172.20.10.26 | I41: =COUNTIF(L41:AM41,"") -> 27 | J41: =COUNTIF(L41:AM41,"APAGADO") -> 1 | K41: =(I41)/(J41+I41) -> 0.96428571 | P41: APAGADO
A42: CENTRO | B42: CEN19 | C42: BONOMO | D42: Chacabuco y 25 de Mayo | E42: Fija | F42: Fibra Optica | H42: 172.20.10.27 | I42: =COUNTIF(L42:AM42,"") -> 28 | J42: =COUNTIF(L42:AM42,"APAGADO") -> 0 | K42: =(I42)/(J42+I42) -> 1
A43: LOMAS DE MONTEVERDE | B43: CEN20 | C43: BONOMO | D43: Pte. Illia y Las Heras | E43: Domo | F43: Fibra Optica | H43: 172.20.10.33 | I43: =COUNTIF(L43:AM43,"") -> 28 | J43: =COUNTIF(L43:AM43,"APAGADO") -> 0 | K43: =(I43)/(J43+I43) -> 1
A44: CENTRO | B44: CEN21 | C44: BONOMO | D44: Misiones y Urquiza | E44: Fija | F44: Radio | H44: 172.20.200.132 | I44: =COUNTIF(L44:AM44,"") -> 23 | J44: =COUNTIF(L44:AM44,"APAGADO") -> 5 | K44: =(I44)/(J44+I44) -> 0.82142857 | L44: APAGADO | M44: APAGADO | N44: APAGADO | O44: APAGADO | P44: APAGADO
...

Sheet Hoja3

Sheet ESTADISTICA
A1: ='RESUMEN TOTAL'!A4 -> Barrio | B1: ='RESUMEN TOTAL'!B4 -> [Denominacion] | C1: ='RESUMEN TOTAL'!D4 -> [Ubicacion] | D1: ='RESUMEN TOTAL'!E4 -> [Tipo de Camara] | E1: ='RESUMEN TOTAL'!F4 -> [Tipo de Conexion] | F1: ='RESUMEN TOTAL'!L4 -> 45261 | G1: ='RESUMEN TOTAL'!M4 -> 45262 | H1: ='RESUMEN TOTAL'!N4 -> 45263 | I1: ='RESUMEN TOTAL'!O4 -> 45264 | J1: ='RESUMEN TOTAL'!P4 -> 45265 | K1: ='RESUMEN TOTAL'!Q4 -> 45266 | L1: ='RESUMEN TOTAL'!R4 -> 45267 | M1: ='RESUMEN TOTAL'!S4 -> 45268 | ... AI1: ='RESUMEN TOTAL'!AO4 -> 45290 | AJ1: ='RESUMEN TOTAL'!#REF! -> #REF!
A2: ='RESUMEN TOTAL'!A5 -> ALTAMIRA | B2: ='RESUMEN TOTAL'!B5 -> ALT01 | C2: ='RESUMEN TOTAL'!D5 -> Calchaqui y Sgto. Cabral | D2: ='RESUMEN TOTAL'!E5 -> Domo | E2: ='RESUMEN TOTAL'!F5 -> Fibra Optica | F2: ='RESUMEN TOTAL'!L5 -> 0 | G2: ='RESUMEN TOTAL'!M5 -> 0 | H2: ='RESUMEN TOTAL'!N5 -> 0 | I2: ='RESUMEN TOTAL'!O5 -> 0 | J2: ='RESUMEN TOTAL'!P5 -> 0 | K2: ='RESUMEN TOTAL'!Q5 -> 0 | L2: ='RESUMEN TOTAL'!R5 -> 0 | M2: ='RESUMEN TOTAL'!S5 -> 0 | ... AI2: ='RESUMEN TOTAL'!AO5 -> 0 | AJ2: ='RESUMEN TOTAL'!#REF! -> #REF!
A3: ='RESUMEN TOTAL'!A6 -> ALTAMIRA | B3: ='RESUMEN TOTAL'!B6 -> ALT02 | C3: ='RESUMEN TOTAL'!D6 -> Calchaqui y Lope de Vega | D3: ='RESUMEN TOTAL'!E6 -> Domo | E3: ='RESUMEN TOTAL'!F6 -> PTO A FO | F3: ='RESUMEN TOTAL'!L6 -> 0 | G3: ='RESUMEN TOTAL'!M6 -> 0 | H3: ='RESUMEN TOTAL'!N6 -> 0 | I3: ='RESUMEN TOTAL'!O6 -> 0 | J3: ='RESUMEN TOTAL'!P6 -> 0 | K3: ='RESUMEN TOTAL'!Q6 -> 0 | L3: ='RESUMEN TOTAL'!R6 -> 0 | M3: ='RESUMEN TOTAL'!S6 -> 0 | ... AI3: ='RESUMEN TOTAL'!AO6 -> 0 | AJ3: ='RESUMEN TOTAL'!#REF! -> #REF!
A4: ='RESUMEN TOTAL'!A7 -> ALTAMIRA | B4: ='RESUMEN TOTAL'!B7 -> ALT 03 | C4: ='RESUMEN TOTAL'!D7 -> Bombero Galarza y Necochea | D4: ='RESUMEN TOTAL'!E7 -> Domo | E4: ='RESUMEN TOTAL'!F7 -> Fibra Optica | F4: ='RESUMEN TOTAL'!L7 -> 0 | G4: ='RESUMEN TOTAL'!M7 -> 0 | H4: ='RESUMEN TOTAL'!N7 -> 0 | I4: ='RESUMEN TOTAL'!O7 -> 0 | J4: ='RESUMEN TOTAL'!P7 -> 0 | K4: ='RESUMEN TOTAL'!Q7 -> 0 | L4: ='RESUMEN TOTAL'!R7 -> 0 | M4: ='RESUMEN TOTAL'!S7 -> 0 | ... AI4: ='RESUMEN TOTAL'!AO7 -> 0 | AJ4: ='RESUMEN TOTAL'!#REF! -> #REF!
A5: ='RESUMEN TOTAL'!A8 -> ALTAMIRA | B5: ='RESUMEN TOTAL'!B8 -> ALT 04 | C5: ='RESUMEN TOTAL'!D8 -> Francia y Necochea | D5: ='RESUMEN TOTAL'!E8 -> Domo | E5: ='RESUMEN TOTAL'!F8 -> Fibra Optica | F5: ='RESUMEN TOTAL'!L8 -> 0 | G5: ='RESUMEN TOTAL'!M8 -> 0 | H5: ='RESUMEN TOTAL'!N8 -> 0 | I5: ='RESUMEN TOTAL'!O8 -> 0 | J5: ='RESUMEN TOTAL'!P8 -> 0 | K5: ='RESUMEN TOTAL'!Q8 -> 0 | L5: ='RESUMEN TOTAL'!R8 -> 0 | M5: ='RESUMEN TOTAL'!S8 -> 0 | ... AI5: ='RESUMEN TOTAL'!AO8 -> 0 | AJ5: ='RESUMEN TOTAL'!#REF! -> #REF!
A6: ='RESUMEN TOTAL'!A9 -> ALTAMIRA | B6: ='RESUMEN TOTAL'!B9 -> ALT05 | C6: ='RESUMEN TOTAL'!D9 -> Av. Calchaqui y Bombero Galarza | D6: ='RESUMEN TOTAL'!E9 -> Domo | E6: ='RESUMEN TOTAL'!F9 -> PTO A FO | F6: ='RESUMEN TOTAL'!L9 -> 0 | G6: ='RESUMEN TOTAL'!M9 -> 0 | H6: ='RESUMEN TOTAL'!N9 -> 0 | I6: ='RESUMEN TOTAL'!O9 -> 0 | J6: ='RESUMEN TOTAL'!P9 -> 0 | K6: ='RESUMEN TOTAL'!Q9 -> 0 | L6: ='RESUMEN TOTAL'!R9 -> 0 | M6: ='RESUMEN TOTAL'!S9 -> 0 | ... AI6: ='RESUMEN TOTAL'!AO9 -> 0 | AJ6: ='RESUMEN TOTAL'!#REF! -> #REF!
A7: ='RESUMEN TOTAL'!A10 -> ALTAMIRA | B7: ='RESUMEN TOTAL'!B10 -> ALT 06 | C7: ='RESUMEN TOTAL'!D10 -> LOPE DE VEGA Y NECOCHEA | D7: ='RESUMEN TOTAL'!E10 -> Domo | E7: ='RESUMEN TOTAL'!F10 -> PTO A FO | F7: ='RESUMEN TOTAL'!L10 -> 0 | G7: ='RESUMEN TOTAL'!M10 -> 0 | H7: ='RESUMEN TOTAL'!N10 -> 0 | I7: ='RESUMEN TOTAL'!O10 -> 0 | J7: ='RESUMEN TOTAL'!P10 -> 0 | K7: ='RESUMEN TOTAL'!Q10 -> 0 | L7: ='RESUMEN TOTAL'!R10 -> 0 | M7: ='RESUMEN TOTAL'!S10 -> 0 | ... AI7: ='RESUMEN TOTAL'!AO10 -> 0 | AJ7: ='RESUMEN TOTAL'!#REF! -> #REF!
A8: ='RESUMEN TOTAL'!A11 -> ALTAMIRA | B8: ='RESUMEN TOTAL'!B11 -> ALT07 | C8: ='RESUMEN TOTAL'!D11 -> AV. CALCHAQUI Y AV. DEL TRABAJO | D8: ='RESUMEN TOTAL'!E11 -> DOMO | E8: ='RESUMEN TOTAL'!F11 -> PTO A FO | F8: ='RESUMEN TOTAL'!L11 -> 0 | G8: ='RESUMEN TOTAL'!M11 -> 0 | H8: ='RESUMEN TOTAL'!N11 -> 0 | I8: ='RESUMEN TOTAL'!O11 -> 0 | J8: ='RESUMEN TOTAL'!P11 -> 0 | K8: ='RESUMEN TOTAL'!Q11 -> 0 | L8: ='RESUMEN TOTAL'!R11 -> 0 | M8: ='RESUMEN TOTAL'!S11 -> 0 | ... AI8: ='RESUMEN TOTAL'!AO11 -> 0 | AJ8: ='RESUMEN TOTAL'!#REF! -> #REF!
A9: ='RESUMEN TOTAL'!A12 -> ALTAMIRA | B9: ='RESUMEN TOTAL'!B12 -> ALT 08 | C9: ='RESUMEN TOTAL'!D12 -> HUMAITA Y NECOCHEA | D9: ='RESUMEN TOTAL'!E12 -> DOMO | E9: ='RESUMEN TOTAL'!F12 -> Fibra Optica | F9: ='RESUMEN TOTAL'!L12 -> 0 | G9: ='RESUMEN TOTAL'!M12 -> 0 | H9: ='RESUMEN TOTAL'!N12 -> 0 | I9: ='RESUMEN TOTAL'!O12 -> 0 | J9: ='RESUMEN TOTAL'!P12 -> 0 | K9: ='RESUMEN TOTAL'!Q12 -> 0 | L9: ='RESUMEN TOTAL'!R12 -> 0 | M9: ='RESUMEN TOTAL'!S12 -> 0 | ... AI9: ='RESUMEN TOTAL'!AO12 -> 0 | AJ9: ='RESUMEN TOTAL'!#REF! -> #REF!
A10: ='RESUMEN TOTAL'!A13 -> ALTAMIRA | B10: ='RESUMEN TOTAL'!B13 -> ALT 09 | C10: ='RESUMEN TOTAL'!D13 -> NECOCHEA Y CURUPAITY | D10: ='RESUMEN TOTAL'!E13 -> DOMO | E10: ='RESUMEN TOTAL'!F13 -> Fibra Optica | F10: ='RESUMEN TOTAL'!L13 -> 0 | G10: ='RESUMEN TOTAL'!M13 -> 0 | H10: ='RESUMEN TOTAL'!N13 -> 0 | I10: ='RESUMEN TOTAL'!O13 -> 0 | J10: ='RESUMEN TOTAL'!P13 -> 0 | K10: ='RESUMEN TOTAL'!Q13 -> 0 | L10: ='RESUMEN TOTAL'!R13 -> 0 | M10: ='RESUMEN TOTAL'!S13 -> 0 | ... AI10: ='RESUMEN TOTAL'!AO13 -> 0 | AJ10: ='RESUMEN TOTAL'!#REF! -> #REF!
A11: ='RESUMEN TOTAL'!A14 -> ALTAMIRA | B11: ='RESUMEN TOTAL'!B14 -> ALT 10 | C11: ='RESUMEN TOTAL'!D14 -> Calchaqui y Francia | D11: ='RESUMEN TOTAL'!E14 -> Domo | E11: ='RESUMEN TOTAL'!F14 -> Radio | F11: ='RESUMEN TOTAL'!L14 -> 0 | G11: ='RESUMEN TOTAL'!M14 -> 0 | H11: ='RESUMEN TOTAL'!N14 -> 0 | I11: ='RESUMEN TOTAL'!O14 -> 0 | J11: ='RESUMEN TOTAL'!P14 -> 0 | K11: ='RESUMEN TOTAL'!Q14 -> 0 | L11: ='RESUMEN TOTAL'!R14 -> 0 | M11: ='RESUMEN TOTAL'!S14 -> 0 | ... AI11: ='RESUMEN TOTAL'!AO14 -> 0 | AJ11: ='RESUMEN TOTAL'!#REF! -> #REF!
A12: ='RESUMEN TOTAL'!A15 -> AGUSTIN RAMIREZ | B12: ='RESUMEN TOTAL'!B15 -> ARA 01 | C12: ='RESUMEN TOTAL'!D15 -> Malambo y Tranquera | D12: ='RESUMEN TOTAL'!E15 -> Domo | E12: ='RESUMEN TOTAL'!F15 -> Fibra Optica | F12: ='RESUMEN TOTAL'!L15 -> 0 | G12: ='RESUMEN TOTAL'!M15 -> 0 | H12: ='RESUMEN TOTAL'!N15 -> APAGADO | I12: ='RESUMEN TOTAL'!O15 -> APAGADO | J12: ='RESUMEN TOTAL'!P15 -> APAGADO | K12: ='RESUMEN TOTAL'!Q15 -> 0 | L12: ='RESUMEN TOTAL'!R15 -> 0 | M12: ='RESUMEN TOTAL'!S15 -> 0 | ... AI12: ='RESUMEN TOTAL'!AO15 -> 0 | AJ12: ='RESUMEN TOTAL'!#REF! -> #REF!
... A121: ='RESUMEN TOTAL'!A124 -> DON JOSE | B121: ='RESUMEN TOTAL'!B124 -> DJ 07 | C121: ='RESUMEN TOTAL'!D124 -> Calle 414 y El Indio | D121: ='RESUMEN TOTAL'!E124 -> Fija | E121: ='RESUMEN TOTAL'!F124 -> PTO A FO | F121: ='RESUMEN TOTAL'!L124 -> 0 | G121: ='RESUMEN TOTAL'!M124 -> 0 | H121: ='RESUMEN TOTAL'!N124 -> 0 | I121: ='RESUMEN TOTAL'!O124 -> 0 | J121: ='RESUMEN TOTAL'!P124 -> 0 | K121: ='RESUMEN TOTAL'!Q124 -> 0 | L121: ='RESUMEN TOTAL'!R124 -> 0 | M121: ='RESUMEN TOTAL'!S124 -> 0 | ... AI121: ='RESUMEN TOTAL'!AO124 -> 0 | AJ121: ='RESUMEN TOTAL'!#REF! -> #REF!
A122: ='RESUMEN TOTAL'!A126 -> EL PARQUE | B122: ='RESUMEN TOTAL'!B126 -> EPQ 01 | C122: ='RESUMEN TOTAL'!D126 -> 1282 Y GRIERSON | D122: ='RESUMEN TOTAL'!E126 -> DOMO | E122: ='RESUMEN TOTAL'!F126 -> Fibra Optica | F122: ='RESUMEN TOTAL'!L126 -> 0 | G122: ='RESUMEN TOTAL'!M126 -> 0 | H122: ='RESUMEN TOTAL'!N126 -> 0 | I122: ='RESUMEN TOTAL'!O126 -> 0 | J122: ='RESUMEN TOTAL'!P126 -> 0 | K122: ='RESUMEN TOTAL'!Q126 -> 0 | L122: ='RESUMEN TOTAL'!R126 -> 0 | M122: ='RESUMEN TOTAL'!S126 -> 0 | ... AI122: ='RESUMEN TOTAL'!AO126 -> 0 | AJ122: ='RESUMEN TOTAL'!#REF! -> #REF!
A123: ='RESUMEN TOTAL'!A127 -> EL PARQUE | B123: ='RESUMEN TOTAL'!B127 -> EPQ 02 | C123: ='RESUMEN TOTAL'!D127 -> 1282 Y MASSE | D123: ='RESUMEN TOTAL'!E127 -> DOMO | E123: ='RESUMEN TOTAL'!F127 -> Fibra Optica | F123: ='RESUMEN TOTAL'!L127 -> 0 | G123: ='RESUMEN TOTAL'!M127 -> 0 | H123: ='RESUMEN TOTAL'!N127 -> 0 | I123: ='RESUMEN TOTAL'!O127 -> 0 | J123: ='RESUMEN TOTAL'!P127 -> 0 | K123: ='RESUMEN TOTAL'!Q127 -> 0 | L123: ='RESUMEN TOTAL'!R127 -> 0 | M123: ='RESUMEN TOTAL'!S127 -> 0 | ... AI123: ='RESUMEN TOTAL'!AO127 -> 0 | AJ123: ='RESUMEN TOTAL'!#REF! -> #REF!
A124: ='RESUMEN TOTAL'!A128 -> EL PARQUE | B124: ='RESUMEN TOTAL'!B128 -> EPQ 03 | C124: ='RESUMEN TOTAL'!D128 -> 1282 Y RP 36 | D124: ='RESUMEN TOTAL'!E128 -> Domo | E124: ='RESUMEN TOTAL'!F128 -> Fibra Optica | F124: ='RESUMEN TOTAL'!L128 -> 0 | G124: ='RESUMEN TOTAL'!M128 -> 0 | H124: ='RESUMEN TOTAL'!N128 -> 0 | I124: ='RESUMEN TOTAL'!O128 -> 0 | J124: ='RESUMEN TOTAL'!P128 -> 0 | K124: ='RESUMEN TOTAL'!Q128 -> 0 | L124: ='RESUMEN TOTAL'!R128 -> 0 | M124: ='RESUMEN TOTAL'!S128 -> 0 | ... AI124: ='RESUMEN TOTAL'!AO128 -> 0 | AJ124: ='RESUMEN TOTAL'!#REF! -> #REF!
A125: ='RESUMEN TOTAL'!A129 -> EL PARQUE | B125: ='RESUMEN TOTAL'!B129 -> EPQ 04 | C125: ='RESUMEN TOTAL'!D129 -> 1282 Y MORENO | D125: ='RESUMEN TOTAL'!E129 -> DOMO | E125: ='RESUMEN TOTAL'!F129 -> Fibra Optica | F125: ='RESUMEN TOTAL'!L129 -> 0 | G125: ='RESUMEN TOTAL'!M129 -> 0 | H125: ='RESUMEN TOTAL'!N129 -> 0 | I125: ='RESUMEN TOTAL'!O129 -> 0 | J125: ='RESUMEN TOTAL'!P129 -> 0 | K125: ='RESUMEN TOTAL'!Q129 -> 0 | L125: ='RESUMEN TOTAL'!R129 -> 0 | M125: ='RESUMEN TOTAL'!S129 -> 0 | ... AI125: ='RESUMEN TOTAL'!AO129 -> 0 | AJ125: ='RESUMEN TOTAL'!#REF! -> #REF!
A126: ='RESUMEN TOTAL'!A130 -> LA ESMERALDA | B126: ='RESUMEN TOTAL'!B130 -> ESM01 | C126: ='RESUMEN TOTAL'!D130 -> Cabello y Brasil | D126: ='RESUMEN TOTAL'!E130 -> Domo | E126: ='RESUMEN TOTAL'!F130 -> Radio | F126: ='RESUMEN TOTAL'!L130 -> 0 | G126: ='RESUMEN TOTAL'!M130 -> 0 | H126: ='RESUMEN TOTAL'!N130 -> 0 | I126: ='RESUMEN TOTAL'!O130 -> 0 | J126: ='RESUMEN TOTAL'!P130 -> 0 | K126: ='RESUMEN TOTAL'!Q130 -> 0 | L126: ='RESUMEN TOTAL'!R130 -> 0 | M126: ='RESUMEN TOTAL'!S130 -> 0 | ... AI126: ='RESUMEN TOTAL'!AO130 -> 0 | AJ126: ='RESUMEN TOTAL'!#REF! -> #REF!
A127: ='RESUMEN TOTAL'!A131 -> SAN JORGE | B127: ='RESUMEN TOTAL'!B131 -> ESM02 | C127: ='RESUMEN TOTAL'!D131 -> Novak y Cabello | D127: ='RESUMEN TOTAL'!E131 -> Domo | E127: ='RESUMEN TOTAL'!F131 -> PTO A FO | F127: ='RESUMEN TOTAL'!L131 -> 0 | G127: ='RESUMEN TOTAL'!M131 -> 0 | H127: ='RESUMEN TOTAL'!N131 -> 0 | I127: ='RESUMEN TOTAL'!O131 -> 0 | J127: ='RESUMEN TOTAL'!P131 -> 0 | K127: ='RESUMEN TOTAL'!Q131 -> 0 | L127: ='RESUMEN TOTAL'!R131 -> 0 | M127: ='RESUMEN TOTAL'!S131 -> 0 | ... AI127: ='RESUMEN TOTAL'!AO131 -> 0 | AJ127: ='RESUMEN TOTAL'!#REF! -> #REF!
A128: ='RESUMEN TOTAL'!A132 -> 0 | B128: ='RESUMEN TOTAL'!B132 -> ESM03 | C128: ='RESUMEN TOTAL'!D132 -> Novak y Humahuaca | D128: ='RESUMEN TOTAL'!E132 -> DOMO | E128: ='RESUMEN TOTAL'!F132 -> PTO A FO | F128: ='RESUMEN TOTAL'!L132 -> 0 | G128: ='RESUMEN TOTAL'!M132 -> 0 | H128: ='RESUMEN TOTAL'!N132 -> 0 | I128: ='RESUMEN TOTAL'!O132 -> 0 | J128: ='RESUMEN TOTAL'!P132 -> 0 | K128: ='RESUMEN TOTAL'!Q132 -> 0 | L128: ='RESUMEN TOTAL'!R132 -> 0 | M128: ='RESUMEN TOTAL'!S132 -> 0 | ... AI128: ='RESUMEN TOTAL'!AO132 -> 0 | AJ128: ='RESUMEN TOTAL'!#REF! -> #REF!
A129: ='RESUMEN TOTAL'!A133 -> LA ESMERALDA | B129: ='RESUMEN TOTAL'!B133 -> ESM04 | C129: ='RESUMEN TOTAL'!D133 -> Basualdo y Bengochea | D129: ='RESUMEN TOTAL'!E133 -> Domo | E129: ='RESUMEN TOTAL'!F133 -> Fibra Optica | F129: ='RESUMEN TOTAL'!L133 -> APAGADO | G129: ='RESUMEN TOTAL'!M133 -> APAGADO | H129: ='RESUMEN TOTAL'!N133 -> APAGADO | I129: ='RESUMEN TOTAL'!O133 -> APAGADO | J129: ='RESUMEN TOTAL'!P133 -> APAGADO | K129: ='RESUMEN TOTAL'!Q133 -> 0 | L129: ='RESUMEN TOTAL'!R133 -> 0 | M129: ='RESUMEN TOTAL'!S133 -> 0 | ... AI129: ='RESUMEN TOTAL'!AO133 -> 0 | AJ129: ='RESUMEN TOTAL'!#REF! -> #REF!
A130: ='RESUMEN TOTAL'!A134 -> LA ESMERALDA | B130: ='RESUMEN TOTAL'!B134 -> ESM05 | C130: ='RESUMEN TOTAL'!D134 -> Aniceto Diaz y Villar | D130: ='RESUMEN TOTAL'!E134 -> Domo | E130: ='RESUMEN TOTAL'!F134 -> Fibra Optica | F130: ='RESUMEN TOTAL'!L134 -> APAGADO | G130: ='RESUMEN TOTAL'!M134 -> APAGADO | H130: ='RESUMEN TOTAL'!N134 -> APAGADO | I130: ='RESUMEN TOTAL'!O134 -> APAGADO | J130: ='RESUMEN TOTAL'!P134 -> APAGADO | K130: ='RESUMEN TOTAL'!Q134 -> 0 | L130: ='RESUMEN TOTAL'!R134 -> 0 | M130: ='RESUMEN TOTAL'!S134 -> 0 | ... AI130: ='RESUMEN TOTAL'!AO134 -> 0 | AJ130: ='RESUMEN TOTAL'!#REF! -> #REF!
A131: ='RESUMEN TOTAL'!A135 -> LA ESMERALDA | B131: ='RESUMEN TOTAL'!B135 -> ESM06 | C131: ='RESUMEN TOTAL'!D135 -> Roselli y Cabello | D131: ='RESUMEN TOTAL'!E135 -> Domo | E131: ='RESUMEN TOTAL'!F135 -> Radio | F131: ='RESUMEN TOTAL'!L135 -> 0 | G131: ='RESUMEN TOTAL'!M135 -> 0 | H131: ='RESUMEN TOTAL'!N135 -> 0 | I131: ='RESUMEN TOTAL'!O135 -> 0 | J131: ='RESUMEN TOTAL'!P135 -> 0 | K131: ='RESUMEN TOTAL'!Q135 -> 0 | L131: ='RESUMEN TOTAL'!R135 -> 0 | M131: ='RESUMEN TOTAL'!S135 -> 0 | ... AI131: ='RESUMEN TOTAL'!AO135 -> 0 | AJ131: ='RESUMEN TOTAL'!#REF! -> #REF!
A132: ='RESUMEN TOTAL'!A136 -> LA ESMERALDA | B132: ='RESUMEN TOTAL'!B136 -> ESM07 | C132: ='RESUMEN TOTAL'!D136 -> AV. NOVAK Y SERRANO | D132: ='RESUMEN TOTAL'!E136 -> DOMO | E132: ='RESUMEN TOTAL'!F136 -> PTO A FO | F132: ='RESUMEN TOTAL'!L136 -> 0 | G132: ='RESUMEN TOTAL'!M136 -> 0 | H132: ='RESUMEN TOTAL'!N136 -> 0 | I132: ='RESUMEN TOTAL'!O136 -> 0 | J132: ='RESUMEN TOTAL'!P136 -> 0 | K132: ='RESUMEN TOTAL'!Q136 -> 0 | L132: ='RESUMEN TOTAL'!R136 -> 0 | M132: ='RESUMEN TOTAL'!S136 -> 0 | ... AI132: ='RESUMEN TOTAL'!AO136 -> 0 | AJ132: ='RESUMEN TOTAL'!#REF! -> #REF!
A133: ='RESUMEN TOTAL'!A137 -> LA ESMERALDA | B133: ='RESUMEN TOTAL'!B137 -> ESM 08 | C133: ='RESUMEN TOTAL'!D137 -> DAVINSON Y MORANCHEL | D133: ='RESUMEN TOTAL'!E137 -> FIJA | E133: ='RESUMEN TOTAL'!F137 -> Radio | F133: ='RESUMEN TOTAL'!L137 -> 0 | G133: ='RESUMEN TOTAL'!M137 -> 0 | H133: ='RESUMEN TOTAL'!N137 -> 0 | I133: ='RESUMEN TOTAL'!O137 -> 0 | J133: ='RESUMEN TOTAL'!P137 -> 0 | K133: ='RESUMEN TOTAL'!Q137 -> 0 | L133: ='RESUMEN TOTAL'!R137 -> 0 | M133: ='RESUMEN TOTAL'!S137 -> 0 | ... AI133: ='RESUMEN TOTAL'!AO137 -> 0 | AJ133: ='RESUMEN TOTAL'!#REF! -> #REF!
... A200: ='RESUMEN TOTAL'!A204 -> 0 | B200: ='RESUMEN TOTAL'!B204 -> MCUD 01 | C200: ='RESUMEN TOTAL'!D204 -> TINOGASTA Y SAN LORENZO | D200: ='RESUMEN TOTAL'!E204 -> Domo | E200: ='RESUMEN TOTAL'!F204 -> Fibra Optica | F200: ='RESUMEN TOTAL'!L204 -> 0 | G200: ='RESUMEN TOTAL'!M204 -> 0 | H200: ='RESUMEN TOTAL'!N204 -> 0 | I200: ='RESUMEN TOTAL'!O204 -> 0 | J200: ='RESUMEN TOTAL'!P204 -> 0 | K200: ='RESUMEN TOTAL'!Q204 -> 0 | L200: ='RESUMEN TOTAL'!R204 -> 0 | M200: ='RESUMEN TOTAL'!S204 -> 0 | ... AI200: ='RESUMEN TOTAL'!AO204 -> 0 | AJ200: ='RESUMEN TOTAL'!#REF! -> #REF!
A201: ='RESUMEN TOTAL'!A206 -> MARTIN FIERRO | B201: ='RESUMEN TOTAL'!B206 -> MFI 01 | C201: ='RESUMEN TOTAL'!D206 -> Belgrano y Sgto. Cabral | D201: ='RESUMEN TOTAL'!E206 -> Fija | E201: ='RESUMEN TOTAL'!F206 -> Fibra Optica | F201: ='RESUMEN TOTAL'!L206 -> 0 | G201: ='RESUMEN TOTAL'!M206 -> 0 | H201: ='RESUMEN TOTAL'!N206 -> 0 | I201: ='RESUMEN TOTAL'!O206 -> 0 | J201: ='RESUMEN TOTAL'!P206 -> 0 | K201: ='RESUMEN TOTAL'!Q206 -> 0 | L201: ='RESUMEN TOTAL'!R206 -> 0 | M201: ='RESUMEN TOTAL'!S206 -> 0 | ... AI201: ='RESUMEN TOTAL'!AO206 -> 0 | AJ201: ='RESUMEN TOTAL'!#REF! -> #REF!
A202: ='RESUMEN TOTAL'!A207 -> LOPEZ ROMERO | B202: ='RESUMEN TOTAL'!B207 -> MFI02 | C202: ='RESUMEN TOTAL'!D207 -> Calchaqui y Balcarce | D202: ='RESUMEN TOTAL'!E207 -> Fija | E202: ='RESUMEN TOTAL'!F207 -> Fibra Optica | F202: ='RESUMEN TOTAL'!L207 -> 0 | G202: ='RESUMEN TOTAL'!M207 -> 0 | H202: ='RESUMEN TOTAL'!N207 -> 0 | I202: ='RESUMEN TOTAL'!O207 -> 0 | J202: ='RESUMEN TOTAL'!P207 -> 0 | K202: ='RESUMEN TOTAL'!Q207 -> 0 | L202: ='RESUMEN TOTAL'!R207 -> 0 | M202: ='RESUMEN TOTAL'!S207 -> 0 | ... AI202: ='RESUMEN TOTAL'!AO207 -> 0 | AJ202: ='RESUMEN TOTAL'!#REF! -> #REF!
A203: ='RESUMEN TOTAL'!A208 -> SAN EMILIO | B203: ='RESUMEN TOTAL'!B208 -> MFI 03 | C203: ='RESUMEN TOTAL'!D208 -> Cno. Gral. Belgrano y Av. del Trabajo | D203: ='RESUMEN TOTAL'!E208 -> Domo | E203: ='RESUMEN TOTAL'!F208 -> Fibra Optica | F203: ='RESUMEN TOTAL'!L208 -> 0 | G203: ='RESUMEN TOTAL'!M208 -> 0 | H203: ='RESUMEN TOTAL'!N208 -> 0 | I203: ='RESUMEN TOTAL'!O208 -> 0 | J203: ='RESUMEN TOTAL'!P208 -> 0 | K203: ='RESUMEN TOTAL'!Q208 -> 0 | L203: ='RESUMEN TOTAL'!R208 -> 0 | M203: ='RESUMEN TOTAL'!S208 -> 0 | ... AI203: ='RESUMEN TOTAL'!AO208 -> 0 | AJ203: ='RESUMEN TOTAL'!#REF! -> #REF!
A204: ='RESUMEN TOTAL'!A209 -> MARTIN FIERRO | B204: ='RESUMEN TOTAL'!B209 -> MFI04 | C204: ='RESUMEN TOTAL'!D209 -> Calchaqui y balcarce | D204: ='RESUMEN TOTAL'!E209 -> Domo | E204: ='RESUMEN TOTAL'!F209 -> Fibra Optica | F204: ='RESUMEN TOTAL'!L209 -> 0 | G204: ='RESUMEN TOTAL'!M209 -> 0 | H204: ='RESUMEN TOTAL'!N209 -> 0 | I204: ='RESUMEN TOTAL'!O209 -> 0 | J204: ='RESUMEN TOTAL'!P209 -> 0 | K204: ='RESUMEN TOTAL'!Q209 -> 0 | L204: ='RESUMEN TOTAL'!R209 -> 0 | M204: ='RESUMEN TOTAL'!S209 -> 0 | ... AI204: ='RESUMEN TOTAL'!AO209 -> 0 | AJ204: ='RESUMEN TOTAL'!#REF! -> #REF!
A205: ='RESUMEN TOTAL'!A210 -> SAN EMILIO | B205: ='RESUMEN TOTAL'!B210 -> MFI 05 | C205: ='RESUMEN TOTAL'!D210 -> Cno. Gral. Belgrano y Guayaquil | D205: ='RESUMEN TOTAL'!E210 -> Domo | E205: ='RESUMEN TOTAL'!F210 -> Fibra Optica | F205: ='RESUMEN TOTAL'!L210 -> 0 | G205: ='RESUMEN TOTAL'!M210 -> 0 | H205: ='RESUMEN TOTAL'!N210 -> 0 | I205: ='RESUMEN TOTAL'!O210 -> 0 | J205: ='RESUMEN TOTAL'!P210 -> 0 | K205: ='RESUMEN TOTAL'!Q210 -> 0 | L205: ='RESUMEN TOTAL'!R210 -> 0 | M205: ='RESUMEN TOTAL'!S210 -> 0 | ... AI205: ='RESUMEN TOTAL'!AO210 -> 0 | AJ205: ='RESUMEN TOTAL'!#REF! -> #REF!
A206: ='RESUMEN TOTAL'!A211 -> SAN EMILIO | B206: ='RESUMEN TOTAL'!B211 -> MFI06 | C206: ='RESUMEN TOTAL'!D211 -> Con. Gral. Belgrano y Bombero Galarza | D206: ='RESUMEN TOTAL'!E211 -> DOMO | E206: ='RESUMEN TOTAL'!F211 -> Radio | F206: ='RESUMEN TOTAL'!L211 -> 0 | G206: ='RESUMEN TOTAL'!M211 -> 0 | H206: ='RESUMEN TOTAL'!N211 -> 0 | I206: ='RESUMEN TOTAL'!O211 -> 0 | J206: ='RESUMEN TOTAL'!P211 -> 0 | K206: ='RESUMEN TOTAL'!Q211 -> 0 | L206: ='RESUMEN TOTAL'!R211 -> 0 | M206: ='RESUMEN TOTAL'!S211 -> 0 | ... AI206: ='RESUMEN TOTAL'!AO211 -> 0 | AJ206: ='RESUMEN TOTAL'!#REF! -> #REF!
A207: ='RESUMEN TOTAL'!A212 -> MARTIN FIERRO | B207: ='RESUMEN TOTAL'!B212 -> MFI 07 | C207: ='RESUMEN TOTAL'!D212 -> Sargento Cabral y Carlos Gardel | D207: ='RESUMEN TOTAL'!E212 -> Domo | E207: ='RESUMEN TOTAL'!F212 -> PTO A FO | F207: ='RESUMEN TOTAL'!L212 -> 0 | G207: ='RESUMEN TOTAL'!M212 -> 0 | H207: ='RESUMEN TOTAL'!N212 -> 0 | I207: ='RESUMEN TOTAL'!O212 -> 0 | J207: ='RESUMEN TOTAL'!P212 -> 0 | K207: ='RESUMEN TOTAL'!Q212 -> 0 | L207: ='RESUMEN TOTAL'!R212 -> 0 | M207: ='RESUMEN TOTAL'!S212 -> 0 | ... AI207: ='RESUMEN TOTAL'!AO212 -> 0 | AJ207: ='RESUMEN TOTAL'!#REF! -> #REF!
A208: ='RESUMEN TOTAL'!A213 -> MARTIN FIERRO | B208: ='RESUMEN TOTAL'!B213 -> MFI 08 | C208: ='RESUMEN TOTAL'!D213 -> Braile y Batalla de Callao | D208: ='RESUMEN TOTAL'!E213 -> Domo | E208: ='RESUMEN TOTAL'!F213 -> PTO A FO | F208: ='RESUMEN TOTAL'!L213 -> 0 | G208: ='RESUMEN TOTAL'!M213 -> 0 | H208: ='RESUMEN TOTAL'!N213 -> 0 | I208: ='RESUMEN TOTAL'!O213 -> 0 | J208: ='RESUMEN TOTAL'!P213 -> 0 | K208: ='RESUMEN TOTAL'!Q213 -> 0 | L208: ='RESUMEN TOTAL'!R213 -> 0 | M208: ='RESUMEN TOTAL'!S213 -> 0 | ... AI208: ='RESUMEN TOTAL'!AO213 -> 0 | AJ208: ='RESUMEN TOTAL'!#REF! -> #REF!
A209: ='RESUMEN TOTAL'!A214 -> GOBERNADOR MONTEVERDE | B209: ='RESUMEN TOTAL'!B214 -> MON01 | C209: ='RESUMEN TOTAL'!D214 -> San Martin y Patricias Argentinas | D209: ='RESUMEN TOTAL'!E214 -> Fija | E209: ='RESUMEN TOTAL'!F214 -> Fibra Optica | F209: ='RESUMEN TOTAL'!L214 -> 0 | G209: ='RESUMEN TOTAL'!M214 -> 0 | H209: ='RESUMEN TOTAL'!N214 -> 0 | I209: ='RESUMEN TOTAL'!O214 -> 0 | J209: ='RESUMEN TOTAL'!P214 -> 0 | K209: ='RESUMEN TOTAL'!Q214 -> 0 | L209: ='RESUMEN TOTAL'!R214 -> 0 | M209: ='RESUMEN TOTAL'!S214 -> 0 | ... AI209: ='RESUMEN TOTAL'!AO214 -> 0 | AJ209: ='RESUMEN TOTAL'!#REF! -> #REF!
A210: ='RESUMEN TOTAL'!A215 -> GOBERNADOR MONTEVERDE | B210: ='RESUMEN TOTAL'!B215 -> MON02 | C210: ='RESUMEN TOTAL'!D215 -> Senzabello y Famatina | D210: ='RESUMEN TOTAL'!E215 -> Domo | E210: ='RESUMEN TOTAL'!F215 -> Radio | F210: ='RESUMEN TOTAL'!L215 -> 0 | G210: ='RESUMEN TOTAL'!M215 -> 0 | H210: ='RESUMEN TOTAL'!N215 -> 0 | I210: ='RESUMEN TOTAL'!O215 -> 0 | J210: ='RESUMEN TOTAL'!P215 -> 0 | K210: ='RESUMEN TOTAL'!Q215 -> 0 | L210: ='RESUMEN TOTAL'!R215 -> 0 | M210: ='RESUMEN TOTAL'!S215 -> 0 | ... AI210: ='RESUMEN TOTAL'!AO215 -> 0 | AJ210: ='RESUMEN TOTAL'!#REF! -> #REF!
A211: ='RESUMEN TOTAL'!A216 -> GOBERNADOR MONTEVERDE | B211: ='RESUMEN TOTAL'!B216 -> MON03 | C211: ='RESUMEN TOTAL'!D216 -> Senzabello y Guemes | D211: ='RESUMEN TOTAL'!E216 -> Domo | E211: ='RESUMEN TOTAL'!F216 -> Radio | F211: ='RESUMEN TOTAL'!L216 -> 0 | G211: ='RESUMEN TOTAL'!M216 -> 0 | H211: ='RESUMEN TOTAL'!N216 -> 0 | I211: ='RESUMEN TOTAL'!O216 -> 0 | J211: ='RESUMEN TOTAL'!P216 -> 0 | K211: ='RESUMEN TOTAL'!Q216 -> 0 | L211: ='RESUMEN TOTAL'!R216 -> 0 | M211: ='RESUMEN TOTAL'!S216 -> 0 | ... AI211: ='RESUMEN TOTAL'!AO216 -> 0 | AJ211: ='RESUMEN TOTAL'!#REF! -> #REF!
A212: ='RESUMEN TOTAL'!A217 -> GOBERNADOR MONTEVERDE | B212: ='RESUMEN TOTAL'!B217 -> MON04 | C212: ='RESUMEN TOTAL'!D217 -> Av. Yrigoyen y San Lorenzo | D212: ='RESUMEN TOTAL'!E217 -> Domo | E212: ='RESUMEN TOTAL'!F217 -> Radio | F212: ='RESUMEN TOTAL'!L217 -> 0 | G212: ='RESUMEN TOTAL'!M217 -> 0 | H212: ='RESUMEN TOTAL'!N217 -> 0 | I212: ='RESUMEN TOTAL'!O217 -> 0 | J212: ='RESUMEN TOTAL'!P217 -> 0 | K212: ='RESUMEN TOTAL'!Q217 -> 0 | L212: ='RESUMEN TOTAL'!R217 -> 0 | M212: ='RESUMEN TOTAL'!S217 -> 0 | ... AI212: ='RESUMEN TOTAL'!AO217 -> 0 | AJ212: ='RESUMEN TOTAL'!#REF! -> #REF!
... A267: ='RESUMEN TOTAL'!A272 -> RICARDO ROJAS | B267: ='RESUMEN TOTAL'!B272 -> RRJ 07 | C267: ='RESUMEN TOTAL'!D272 -> Constancio Vigil y Estanislao del Campo | D267: ='RESUMEN TOTAL'!E272 -> Domo | E267: ='RESUMEN TOTAL'!F272 -> Fibra Optica | F267: ='RESUMEN TOTAL'!L272 -> 0 | G267: ='RESUMEN TOTAL'!M272 -> 0 | H267: ='RESUMEN TOTAL'!N272 -> 0 | I267: ='RESUMEN TOTAL'!O272 -> 0 | J267: ='RESUMEN TOTAL'!P272 -> 0 | K267: ='RESUMEN TOTAL'!Q272 -> 0 | L267: ='RESUMEN TOTAL'!R272 -> 0 | M267: ='RESUMEN TOTAL'!S272 -> 0 | ... AI267: ='RESUMEN TOTAL'!AO272 -> 0 | AJ267: ='RESUMEN TOTAL'!#REF! -> #REF!
A268: ='RESUMEN TOTAL'!A273 -> RICARDO ROJAS | B268: ='RESUMEN TOTAL'!B273 -> RRJ 08 | C268: ='RESUMEN TOTAL'!D273 -> Constancio Vigil y Pablo Podesta | D268: ='RESUMEN TOTAL'!E273 -> Domo | E268: ='RESUMEN TOTAL'!F273 -> Fibra Optica | F268: ='RESUMEN TOTAL'!L273 -> 0 | G268: ='RESUMEN TOTAL'!M273 -> 0 | H268: ='RESUMEN TOTAL'!N273 -> 0 | I268: ='RESUMEN TOTAL'!O273 -> 0 | J268: ='RESUMEN TOTAL'!P273 -> 0 | K268: ='RESUMEN TOTAL'!Q273 -> 0 | L268: ='RESUMEN TOTAL'!R273 -> 0 | M268: ='RESUMEN TOTAL'!S273 -> 0 | ... U268: ='RESUMEN TOTAL'!AA273 -> 0 | V268: ='RESUMEN TOTAL'!AB274 -> 0 | W268: ='RESUMEN TOTAL'!AC273 -> 0 | X268: ='RESUMEN TOTAL'!AD273 -> 0 | Y268: ='RESUMEN TOTAL'!AE273 -> 0 | Z268: ='RESUMEN TOTAL'!AF273 -> 0 | AA268: ='RESUMEN TOTAL'!AG273 -> 0 | AB268: ='RESUMEN TOTAL'!AH273 -> 0 | AC268: ='RESUMEN TOTAL'!AI273 -> 0 | AD268: ='RESUMEN TOTAL'!AJ273 -> 0 | ... AI268: ='RESUMEN TOTAL'!AO273 -> 0 | AJ268: ='RESUMEN TOTAL'!#REF! -> #REF!
...

Sheet APAGADOS
E1: APAGADOS | F1: =COUNTIF(F3:F403, "APAGADO") -> 29 | G1: =COUNTIF(G3:G403, "APAGADO") -> 30 | H1: =COUNTIF(H3:H503, "APAGADO") -> 50 | I1: =COUNTIF(I3:I403, "APAGADO") -> 37 | J1: =COUNTIF(J3:J403, "APAGADO") -> 45 | K1: =COUNTIF(K3:K403, "APAGADO") -> 0 | L1: =COUNTIF(L3:L403, "APAGADO") -> 0 | M1: =COUNTIF(M3:M403, "APAGADO") -> 0 | N1: =COUNTIF(N3:N403, "APAGADO") -> 0 | O1: =COUNTIF(O3:O403, "APAGADO") -> 0 | P1: =COUNTIF(P3:P403, "APAGADO") -> 0 | ... AD1: =COUNTIF(AD3:AD403, "APAGADO") -> 0 | AE1: =COUNTIF(AE3:AE503, "APAGADO") -> 0 | AF1: =COUNTIF(AF3:AF403, "APAGADO") -> 0 | AG1: =COUNTIF(AG3:AG403, "APAGADO") -> 0 | AH1: =COUNTIF(AH3:AH403, "APAGADO") -> 0 | AI1: =COUNTIF(AI3:AI403, "APAGADO") -> 0 | AJ1: =COUNTIF(AJ3:AJ403, "APAGADO") -> 0
A2: =ESTADISTICA!A1 -> Barrio | B2: =ESTADISTICA!B1 -> [Denominacion] | C2: =ESTADISTICA!C1 -> [Ubicacion] | D2: =ESTADISTICA!D1 -> [Tipo de Camara] | E2: =ESTADISTICA!E1 -> [Tipo de Conexion] | F2: =ESTADISTICA!F1 -> 45261 | G2: =ESTADISTICA!G1 -> 45262 | H2: =ESTADISTICA!H1 -> 45263 | ... AJ2: =ESTADISTICA!AJ1 -> #REF!
A3: =ESTADISTICA!A2 -> ALTAMIRA | B3: =ESTADISTICA!B2 -> ALT01 | C3: =ESTADISTICA!C2 -> Calchaqui y Sgto. Cabral | D3: =ESTADISTICA!D2 -> Domo | E3: =ESTADISTICA!E2 -> Fibra Optica | F3: =ESTADISTICA!F2 -> 0 | G3: =ESTADISTICA!G2 -> 0 | H3: =ESTADISTICA!H2 -> 0 | ... AJ3: =ESTADISTICA!AJ2 -> #REF!
A4: =ESTADISTICA!A3 -> ALTAMIRA | B4: =ESTADISTICA!B3 -> ALT02 | C4: =ESTADISTICA!C3 -> Calchaqui y Lope de Vega | D4: =ESTADISTICA!D3 -> Domo | E4: =ESTADISTICA!E3 -> PTO A FO | F4: =ESTADISTICA!F3 -> 0 | G4: =ESTADISTICA!G3 -> 0 | H4: =ESTADISTICA!H3 -> 0 | ... AJ4: =ESTADISTICA!AJ3 -> #REF!
A5: =ESTADISTICA!A4 -> ALTAMIRA | B5: =ESTADISTICA!B4 -> ALT 03 | C5: =ESTADISTICA!C4 -> Bombero Galarza y Necochea | D5: =ESTADISTICA!D4 -> Domo | E5: =ESTADISTICA!E4 -> Fibra Optica | F5: =ESTADISTICA!F4 -> 0 | G5: =ESTADISTICA!G4 -> 0 | H5: =ESTADISTICA!H4 -> 0 | ... AJ5: =ESTADISTICA!AJ4 -> #REF!
A6: =ESTADISTICA!A5 -> ALTAMIRA | B6: =ESTADISTICA!B5 -> ALT 04 | C6: =ESTADISTICA!C5 -> Francia y Necochea | D6: =ESTADISTICA!D5 -> Domo | E6: =ESTADISTICA!E5 -> Fibra Optica | F6: =ESTADISTICA!F5 -> 0 | G6: =ESTADISTICA!G5 -> 0 | H6: =ESTADISTICA!H5 -> 0 | ... AJ6: =ESTADISTICA!AJ5 -> #REF!
A7: =ESTADISTICA!A6 -> ALTAMIRA | B7: =ESTADISTICA!B6 -> ALT05 | C7: =ESTADISTICA!C6 -> Av. Calchaqui y Bombero Galarza | D7: =ESTADISTICA!D6 -> Domo | E7: =ESTADISTICA!E6 -> PTO A FO | F7: =ESTADISTICA!F6 -> 0 | G7: =ESTADISTICA!G6 -> 0 | H7: =ESTADISTICA!H6 -> 0 | ... AJ7: =ESTADISTICA!AJ6 -> #REF!
A8: =ESTADISTICA!A7 -> ALTAMIRA | B8: =ESTADISTICA!B7 -> ALT 06 | C8: =ESTADISTICA!C7 -> LOPE DE VEGA Y NECOCHEA | D8: =ESTADISTICA!D7 -> Domo | E8: =ESTADISTICA!E7 -> PTO A FO | F8: =ESTADISTICA!F7 -> 0 | G8: =ESTADISTICA!G7 -> 0 | H8: =ESTADISTICA!H7 -> 0 | ... AJ8: =ESTADISTICA!AJ7 -> #REF!
A9: =ESTADISTICA!A8 -> ALTAMIRA | B9: =ESTADISTICA!B8 -> ALT07 | C9: =ESTADISTICA!C8 -> AV. CALCHAQUI Y AV. DEL TRABAJO | D9: =ESTADISTICA!D8 -> DOMO | E9: =ESTADISTICA!E8 -> PTO A FO | F9: =ESTADISTICA!F8 -> 0 | G9: =ESTADISTICA!G8 -> 0 | H9: =ESTADISTICA!H8 -> 0 | ... AJ9: =ESTADISTICA!AJ8 -> #REF!
A10: =ESTADISTICA!A9 -> ALTAMIRA | B10: =ESTADISTICA!B9 -> ALT 08 | C10: =ESTADISTICA!C9 -> HUMAITA Y NECOCHEA | D10: =ESTADISTICA!D9 -> DOMO | E10: =ESTADISTICA!E9 -> Fibra Optica | F10: =ESTADISTICA!F9 -> 0 | G10: =ESTADISTICA!G9 -> 0 | H10: =ESTADISTICA!H9 -> 0 | ... AJ10: =ESTADISTICA!AJ9 -> #REF!
A11: =ESTADISTICA!A10 -> ALTAMIRA | B11: =ESTADISTICA!B10 -> ALT 09 | C11: =ESTADISTICA!C10 -> NECOCHEA Y CURUPAITY | D11: =ESTADISTICA!D10 -> DOMO | E11: =ESTADISTICA!E10 -> Fibra Optica | F11: =ESTADISTICA!F10 -> 0 | G11: =ESTADISTICA!G10 -> 0 | H11: =ESTADISTICA!H10 -> 0 | ... AJ11: =ESTADISTICA!AJ10 -> #REF!
A12: =ESTADISTICA!A11 -> ALTAMIRA | B12: =ESTADISTICA!B11 -> ALT 10 | C12: =ESTADISTICA!C11 -> Calchaqui y Francia | D12: =ESTADISTICA!D11 -> Domo | E12: =ESTADISTICA!E11 -> Radio | F12: =ESTADISTICA!F11 -> 0 | G12: =ESTADISTICA!G11 -> 0 | H12: =ESTADISTICA!H11 -> 0 | ... AJ12: =ESTADISTICA!AJ11 -> #REF!
A13: =ESTADISTICA!A12 -> AGUSTIN RAMIREZ | B13: =ESTADISTICA!B12 -> ARA 01 | C13: =ESTADISTICA!C12 -> Malambo y Tranquera | D13: =ESTADISTICA!D12 -> Domo | E13: =ESTADISTICA!E12 -> Fibra Optica | F13: =ESTADISTICA!F12 -> 0 | G13: =ESTADISTICA!G12 -> 0 | H13: =ESTADISTICA!H12 -> APAGADO | ... AJ13: =ESTADISTICA!AJ12 -> #REF!
... A207: =ESTADISTICA!A206 -> SAN EMILIO | B207: =ESTADISTICA!B206 -> MFI06 | C207: =ESTADISTICA!C206 -> Con. Gral. Belgrano y Bombero Galarza | D207: =ESTADISTICA!D206 -> DOMO | E207: =ESTADISTICA!E206 -> Radio | F207: =ESTADISTICA!F206 -> 0 | G207: =ESTADISTICA!G206 -> 0 | H207: =ESTADISTICA!H206 -> 0 | ... AJ207: =ESTADISTICA!AJ206 -> #REF!
A208: =ESTADISTICA!A208 -> MARTIN FIERRO | B208: =ESTADISTICA!B208 -> MFI 08 | C208: =ESTADISTICA!C208 -> Braile y Batalla de Callao | D208: =ESTADISTICA!D208 -> Domo | E208: =ESTADISTICA!E208 -> PTO A FO | F208: =ESTADISTICA!F208 -> 0 | G208: =ESTADISTICA!G208 -> 0 | H208: =ESTADISTICA!H208 -> 0 | ... AJ208: =ESTADISTICA!AJ208 -> #REF!
A209: =ESTADISTICA!A209 -> GOBERNADOR MONTEVERDE | B209: =ESTADISTICA!B209 -> MON01 | C209: =ESTADISTICA!C209 -> San Martin y Patricias Argentinas | D209: =ESTADISTICA!D209 -> Fija | E209: =ESTADISTICA!E209 -> Fibra Optica | F209: =ESTADISTICA!F209 -> 0 | G209: =ESTADISTICA!G209 -> 0 | H209: =ESTADISTICA!H209 -> 0 | ... AJ209: =ESTADISTICA!AJ209 -> #REF!
A210: =ESTADISTICA!A210 -> GOBERNADOR MONTEVERDE | B210: =ESTADISTICA!B210 -> MON02 | C210: =ESTADISTICA!C210 -> Senzabello y Famatina | D210: =ESTADISTICA!D210 -> Domo | E210: =ESTADISTICA!E210 -> Radio | F210: =ESTADISTICA!F210 -> 0 | G210: =ESTADISTICA!G210 -> 0 | H210: =ESTADISTICA!H210 -> 0 | ... AJ210: =ESTADISTICA!AJ210 -> #REF!
A211: =ESTADISTICA!A211 -> GOBERNADOR MONTEVERDE | B211: =ESTADISTICA!B211 -> MON03 | C211: =ESTADISTICA!C211 -> Senzabello y Guemes | D211: =ESTADISTICA!D211 -> Domo | E211: =ESTADISTICA!E211 -> Radio | F211: =ESTADISTICA!F211 -> 0 | G211: =ESTADISTICA!G211 -> 0 | H211: =ESTADISTICA!H211 -> 0 | ... AJ211: =ESTADISTICA!AJ211 -> #REF!
A212: =ESTADISTICA!A212 -> GOBERNADOR MONTEVERDE | B212: =ESTADISTICA!B212 -> MON04 | C212: =ESTADISTICA!C212 -> Av. Yrigoyen y San Lorenzo | D212: =ESTADISTICA!D212 -> Domo | E212: =ESTADISTICA!E212 -> Radio | F212: =ESTADISTICA!F212 -> 0 | G212: =ESTADISTICA!G212 -> 0 | H212: =ESTADISTICA!H212 -> 0 | ... AJ212: =ESTADISTICA!AJ212 -> #REF!
A213: =ESTADISTICA!A213 -> 9 DE JULIO | B213: =ESTADISTICA!B213 -> NJU 01 | C213: =ESTADISTICA!C213 -> Sallares y Parrillo | D213: =ESTADISTICA!D213 -> Domo | E213: =ESTADISTICA!E213 -> Fibra Optica | F213: =ESTADISTICA!F213 -> 0 | G213: =ESTADISTICA!G213 -> 0 | H213: =ESTADISTICA!H213 -> 0 | ... AJ213: =ESTADISTICA!AJ213 -> #REF!
A214: =ESTADISTICA!A214 -> 9 DE JULIO | B214: =ESTADISTICA!B214 -> NJU02 | C214: =ESTADISTICA!C214 -> Ituzaingo y Boccuzzi | D214: =ESTADISTICA!D214 -> Domo | E214: =ESTADISTICA!E214 -> Radio | F214: =ESTADISTICA!F214 -> 0 | G214: =ESTADISTICA!G214 -> 0 | H214: =ESTADISTICA!H214 -> 0 | ... AJ214: =ESTADISTICA!AJ214 -> #REF!
A215: =ESTADISTICA!A215 -> 9 DE JULIO | B215: =ESTADISTICA!B215 -> NJU03 | C215: =ESTADISTICA!C215 -> San Juan y Parrillo | D215: =ESTADISTICA!D215 -> Domo | E215: =ESTADISTICA!E215 -> PTO A FO | F215: =ESTADISTICA!F215 -> 0 | G215: =ESTADISTICA!G215 -> 0 | H215: =ESTADISTICA!H215 -> 0 | ... AJ215: =ESTADISTICA!AJ215 -> #REF!
A216: =ESTADISTICA!A216 -> 9 DE JULIO | B216: =ESTADISTICA!B216 -> NJU04 | C216: =ESTADISTICA!C216 -> Ituzaingo y 214 A | D216: =ESTADISTICA!D216 -> Domo | E216: =ESTADISTICA!E216 -> Radio | F216: =ESTADISTICA!F216 -> 0 | G216: =ESTADISTICA!G216 -> 0 | H216: =ESTADISTICA!H216 -> 0 | ... AJ216: =ESTADISTICA!AJ216 -> #REF!
A217: =ESTADISTICA!A217 -> ZEBALLOS CENTRO | B217: =ESTADISTICA!B217 -> NJU05 | C217: =ESTADISTICA!C217 -> Ituzaingo y Alem | D217: =ESTADISTICA!D217 -> Domo | E217: =ESTADISTICA!E217 -> Radio | F217: =ESTADISTICA!F217 -> 0 | G217: =ESTADISTICA!G217 -> 0 | H217: =ESTADISTICA!H217 -> 0 | ... AJ217: =ESTADISTICA!AJ217 -> #REF!
A218: =ESTADISTICA!A218 -> CENTRO | B218: =ESTADISTICA!B218 -> NJU06 | C218: =ESTADISTICA!C218 -> Sallares y Rodo | D218: =ESTADISTICA!D218 -> Domo | E218: =ESTADISTICA!E218 -> Fibra Optica | F218: =ESTADISTICA!F218 -> 0 | G218: =ESTADISTICA!G218 -> 0 | H218: =ESTADISTICA!H218 -> 0 | ... AJ218: =ESTADISTICA!AJ218 -> #REF!
A219: =ESTADISTICA!A219 -> 9 DE JULIO | B219: =ESTADISTICA!B219 -> NJU07 | C219: =ESTADISTICA!C219 -> Gral. Juan Domingo Peron y Parrillo | D219: =ESTADISTICA!D219 -> Domo | E219: =ESTADISTICA!E219 -> Fibra Optica | F219: =ESTADISTICA!F219 -> 0 | G219: =ESTADISTICA!G219 -> 0 | H219: =ESTADISTICA!H219 -> 0 | ... AJ219: =ESTADISTICA!AJ219 -> #REF!
... A516: =ESTADISTICA!A516 -> 0 | B516: =ESTADISTICA!B516 -> 0 | C516: =ESTADISTICA!C516 -> 0 | D516: =ESTADISTICA!D516 -> 0 | E516: =ESTADISTICA!E516 -> 0 | F516: =ESTADISTICA!F516 -> 0 | G516: =ESTADISTICA!G516 -> 0 | H516: =ESTADISTICA!H516 -> 0 | ... AJ516: =ESTADISTICA!AJ516 -> #REF!

Sheet APAGADOS FIBRA
C1: TOTAL FIBRA | D1: =COUNTIFS(E4:E401,"=Fibra Optica") -> 270
E2: APAGADOS | F2: =COUNTIFS(F4:F501, "=APAGADO",E4:E501,"=Fibra Optica") -> 25 | G2: =COUNTIFS(G4:G501, "=APAGADO",E4:E501,"=Fibra Optica") -> 27 | H2: =COUNTIFS(H4:H501, "=APAGADO",E4:E501,"=Fibra Optica") -> 32 | I2: =COUNTIFS(I4:I501, "=APAGADO",E4:E501,"=Fibra Optica") -> 33 | J2: =COUNTIFS(J4:J501, "=APAGADO",E4:E501,"=Fibra Optica") -> 41 | K2: =COUNTIFS(K4:K501, "=APAGADO",E4:E501,"=Fibra Optica") -> 0 | L2: =COUNTIFS(L4:L501, "=APAGADO",E4:E501,"=Fibra Optica") -> 0 | M2: =COUNTIFS(M4:M501, "=APAGADO",E4:E501,"=Fibra Optica") -> 0 | N2: =COUNTIFS(N4:N501, "=APAGADO",E4:E501,"=Fibra Optica") -> 0 | O2: =COUNTIFS(O4:O501, "=APAGADO",E4:E501,"=Fibra Optica") -> 0 | P2: =COUNTIFS(P4:P601, "=APAGADO",E4:E601,"=Fibra Optica") -> 0 | Q2: =COUNTIFS(Q4:Q501, "=APAGADO",E4:E501,"=Fibra Optica") -> 0 | R2: =COUNTIFS(R4:R501, "=APAGADO",E4:E501,"=Fibra Optica") -> 0 | S2: =COUNTIFS(S4:S501, "=APAGADO",E4:E501,"=Fibra Optica") -> 0 | T2: =COUNTIFS(T4:T501, "=APAGADO",E4:E501,"=Fibra Optica") -> 0 | U2: =COUNTIFS(U4:U501, "=APAGADO",E4:E501,"=Fibra Optica") -> 0 | V2: =COUNTIFS(V4:V501, "=APAGADO",E4:E501,"=Fibra Optica") -> 0 | W2: =COUNTIFS(W4:W501, "=APAGADO",E4:E501,"=Fibra Optica") -> 0 | X2: =COUNTIFS(X4:X501, "=APAGADO",E4:E501,"=Fibra Optica") -> 0 | Y2: =COUNTIFS(Y4:Y501, "=APAGADO",E4:E501,"=Fibra Optica") -> 0 | Z2: =COUNTIFS(Z4:Z501, "=APAGADO",E4:E501,"=Fibra Optica") -> 0 | AA2: =COUNTIFS(AA4:AA501, "=APAGADO",E4:E501,"=Fibra Optica") -> 0 | AB2: =COUNTIFS(AB4:AB501, "=APAGADO",E4:E501,"=Fibra Optica") -> 0 | AC2: =COUNTIFS(AC4:AC601, "=APAGADO",E4:E601,"=Fibra Optica") -> 0 | AD2: =COUNTIFS(AD4:AD501, "=APAGADO",E4:E501,"=Fibra Optica") -> 0 | AE2: =COUNTIFS(AE4:AE501, "=APAGADO",E4:E501,"=Fibra Optica") -> 0 | AF2: =COUNTIFS(AF4:AF501, "=APAGADO",E4:E501,"=Fibra Optica") -> 0 | AG2: =COUNTIFS(AG4:AG501, "=APAGADO",E4:E501,"=Fibra Optica") -> 0 | AH2: =COUNTIFS(AH4:AH501, "=APAGADO",E4:E501,"=Fibra Optica") -> 0 | AI2: =COUNTIFS(AI4:AI401, "=APAGADO",E4:E401,"=Fibra Optica") -> 0 | AJ2: =COUNTIFS(AJ4:AJ401, "=APAGADO",F4:F401,"=Fibra Optica") -> 0
A3: =ESTADISTICA!A1 -> Barrio | B3: =ESTADISTICA!B1 -> [Denominacion] | C3: =ESTADISTICA!C1 -> [Ubicacion] | D3: =ESTADISTICA!D1 -> [Tipo de Camara] | E3: =ESTADISTICA!E1 -> [Tipo de Conexion] | F3: =ESTADISTICA!F1 -> 45261 | G3: =ESTADISTICA!G1 -> 45262 | H3: =ESTADISTICA!H1 -> 45263 | ... AJ3: =ESTADISTICA!AJ1 -> #REF!
A4: ='RESUMEN TOTAL'!A7 -> ALTAMIRA | B4: ='RESUMEN TOTAL'!B7 -> ALT 03 | C4: ='RESUMEN TOTAL'!D7 -> Bombero Galarza y Necochea | D4: ='RESUMEN TOTAL'!E7 -> Domo | E4: ='RESUMEN TOTAL'!F7 -> Fibra Optica | F4: ='RESUMEN TOTAL'!L7 -> 0 | G4: ='RESUMEN TOTAL'!M7 -> 0 | H4: ='RESUMEN TOTAL'!N7 -> 0 | I4: ='RESUMEN TOTAL'!O7 -> 0 | J4: ='RESUMEN TOTAL'!P7 -> 0 | K4: ='RESUMEN TOTAL'!Q7 -> 0 | L4: ='RESUMEN TOTAL'!R7 -> 0 | M4: ='RESUMEN TOTAL'!S7 -> 0 | ... AI4: ='RESUMEN TOTAL'!AO7 -> 0 | AJ4: ='RESUMEN TOTAL'!#REF! -> #REF!
A5: ='RESUMEN TOTAL'!A8 -> ALTAMIRA | B5: ='RESUMEN TOTAL'!B8 -> ALT 04 | C5: ='RESUMEN TOTAL'!D8 -> Francia y Necochea | D5: ='RESUMEN TOTAL'!E8 -> Domo | E5: ='RESUMEN TOTAL'!F8 -> Fibra Optica | F5: ='RESUMEN TOTAL'!L8 -> 0 | G5: ='RESUMEN TOTAL'!M8 -> 0 | H5: ='RESUMEN TOTAL'!N8 -> 0 | I5: ='RESUMEN TOTAL'!O8 -> 0 | J5: ='RESUMEN TOTAL'!P8 -> 0 | K5: ='RESUMEN TOTAL'!Q8 -> 0 | L5: ='RESUMEN TOTAL'!R8 -> 0 | M5: ='RESUMEN TOTAL'!S8 -> 0 | ... AI5: ='RESUMEN TOTAL'!AO8 -> 0 | AJ5: ='RESUMEN TOTAL'!#REF! -> #REF!
A6: ='RESUMEN TOTAL'!A9 -> ALTAMIRA | B6: ='RESUMEN TOTAL'!B9 -> ALT05 | C6: ='RESUMEN TOTAL'!D9 -> Av. Calchaqui y Bombero Galarza | D6: ='RESUMEN TOTAL'!E9 -> Domo | E6: ='RESUMEN TOTAL'!F9 -> PTO A FO | F6: ='RESUMEN TOTAL'!L9 -> 0 | G6: ='RESUMEN TOTAL'!M9 -> 0 | H6: ='RESUMEN TOTAL'!N9 -> 0 | I6: ='RESUMEN TOTAL'!O9 -> 0 | J6: ='RESUMEN TOTAL'!P9 -> 0 | K6: ='RESUMEN TOTAL'!Q9 -> 0 | L6: ='RESUMEN TOTAL'!R9 -> 0 | M6: ='RESUMEN TOTAL'!S9 -> 0 | ... AI6: ='RESUMEN TOTAL'!AO9 -> 0 | AJ6: ='RESUMEN TOTAL'!#REF! -> #REF!
A7: ='RESUMEN TOTAL'!A10 -> ALTAMIRA | B7: ='RESUMEN TOTAL'!B10 -> ALT 06 | C7: ='RESUMEN TOTAL'!D10 -> LOPE DE VEGA Y NECOCHEA | D7: ='RESUMEN TOTAL'!E10 -> Domo | E7: ='RESUMEN TOTAL'!F10 -> PTO A FO | F7: ='RESUMEN TOTAL'!L10 -> 0 | G7: ='RESUMEN TOTAL'!M10 -> 0 | H7: ='RESUMEN TOTAL'!N10 -> 0 | I7: ='RESUMEN TOTAL'!O10 -> 0 | J7: ='RESUMEN TOTAL'!P10 -> 0 | K7: ='RESUMEN TOTAL'!Q10 -> 0 | L7: ='RESUMEN TOTAL'!R10 -> 0 | M7: ='RESUMEN TOTAL'!S10 -> 0 | ... AI7: ='RESUMEN TOTAL'!AO10 -> 0 | AJ7: ='RESUMEN TOTAL'!#REF! -> #REF!
A8: ='RESUMEN TOTAL'!A11 -> ALTAMIRA | B8: ='RESUMEN TOTAL'!B11 -> ALT07 | C8: ='RESUMEN TOTAL'!D11 -> AV. CALCHAQUI Y AV. DEL TRABAJO | D8: ='RESUMEN TOTAL'!E11 -> DOMO | E8: ='RESUMEN TOTAL'!F11 -> PTO A FO | F8: ='RESUMEN TOTAL'!L11 -> 0 | G8: ='RESUMEN TOTAL'!M11 -> 0 | H8: ='RESUMEN TOTAL'!N11 -> 0 | I8: ='RESUMEN TOTAL'!O11 -> 0 | J8: ='RESUMEN TOTAL'!P11 -> 0 | K8: ='RESUMEN TOTAL'!Q11 -> 0 | L8: ='RESUMEN TOTAL'!R11 -> 0 | M8: ='RESUMEN TOTAL'!S11 -> 0 | ... AI8: ='RESUMEN TOTAL'!AO11 -> 0 | AJ8: ='RESUMEN TOTAL'!#REF! -> #REF!
A9: ='RESUMEN TOTAL'!A12 -> ALTAMIRA | B9: ='RESUMEN TOTAL'!B12 -> ALT 08 | C9: ='RESUMEN TOTAL'!D12 -> HUMAITA Y NECOCHEA | D9: ='RESUMEN TOTAL'!E12 -> DOMO | E9: ='RESUMEN TOTAL'!F12 -> Fibra Optica | F9: ='RESUMEN TOTAL'!L12 -> 0 | G9: ='RESUMEN TOTAL'!M12 -> 0 | H9: ='RESUMEN TOTAL'!N12 -> 0 | I9: ='RESUMEN TOTAL'!O12 -> 0 | J9: ='RESUMEN TOTAL'!P12 -> 0 | K9: ='RESUMEN TOTAL'!Q12 -> 0 | L9: ='RESUMEN TOTAL'!R12 -> 0 | M9: ='RESUMEN TOTAL'!S12 -> 0 | ... AI9: ='RESUMEN TOTAL'!AO12 -> 0 | AJ9: ='RESUMEN TOTAL'!#REF! -> #REF!
A10: ='RESUMEN TOTAL'!A13 -> ALTAMIRA | B10: ='RESUMEN TOTAL'!B13 -> ALT 09 | C10: ='RESUMEN TOTAL'!D13 -> NECOCHEA Y CURUPAITY | D10: ='RESUMEN TOTAL'!E13 -> DOMO | E10: ='RESUMEN TOTAL'!F13 -> Fibra Optica | F10: ='RESUMEN TOTAL'!L13 -> 0 | G10: ='RESUMEN TOTAL'!M13 -> 0 | H10: ='RESUMEN TOTAL'!N13 -> 0 | I10: ='RESUMEN TOTAL'!O13 -> 0 | J10: ='RESUMEN TOTAL'!P13 -> 0 | K10: ='RESUMEN TOTAL'!Q13 -> 0 | L10: ='RESUMEN TOTAL'!R13 -> 0 | M10: ='RESUMEN TOTAL'!S13 -> 0 | ... AI10: ='RESUMEN TOTAL'!AO13 -> 0 | AJ10: ='RESUMEN TOTAL'!#REF! -> #REF!
A11: ='RESUMEN TOTAL'!A14 -> ALTAMIRA | B11: ='RESUMEN TOTAL'!B14 -> ALT 10 | C11: ='RESUMEN TOTAL'!D14 -> Calchaqui y Francia | D11: ='RESUMEN TOTAL'!E14 -> Domo | E11: ='RESUMEN TOTAL'!F14 -> Radio | F11: ='RESUMEN TOTAL'!L14 -> 0 | G11: ='RESUMEN TOTAL'!M14 -> 0 | H11: ='RESUMEN TOTAL'!N14 -> 0 | I11: ='RESUMEN TOTAL'!O14 -> 0 | J11: ='RESUMEN TOTAL'!P14 -> 0 | K11: ='RESUMEN TOTAL'!Q14 -> 0 | L11: ='RESUMEN TOTAL'!R14 -> 0 | M11: ='RESUMEN TOTAL'!S14 -> 0 | ... AI11: ='RESUMEN TOTAL'!AO14 -> 0 | AJ11: ='RESUMEN TOTAL'!#REF! -> #REF!
A12: ='RESUMEN TOTAL'!A15 -> AGUSTIN RAMIREZ | B12: ='RESUMEN TOTAL'!B15 -> ARA 01 | C12: ='RESUMEN TOTAL'!D15 -> Malambo y Tranquera | D12: ='RESUMEN TOTAL'!E15 -> Domo | E12: ='RESUMEN TOTAL'!F15 -> Fibra Optica | F12: ='RESUMEN TOTAL'!L15 -> 0 | G12: ='RESUMEN TOTAL'!M15 -> 0 | H12: ='RESUMEN TOTAL'!N15 -> APAGADO | I12: ='RESUMEN TOTAL'!O15 -> APAGADO | J12: ='RESUMEN TOTAL'!P15 -> APAGADO | K12: ='RESUMEN TOTAL'!Q15 -> 0 | L12: ='RESUMEN TOTAL'!R15 -> 0 | M12: ='RESUMEN TOTAL'!S15 -> 0 | ... AI12: ='RESUMEN TOTAL'!AO15 -> 0 | AJ12: ='RESUMEN TOTAL'!#REF! -> #REF!
A13: ='RESUMEN TOTAL'!A16 -> BELGRANO | B13: ='RESUMEN TOTAL'!B16 -> BEL 01 | C13: ='RESUMEN TOTAL'!D16 -> San Martin y Dardo Rocha | D13: ='RESUMEN TOTAL'!E16 -> DOMO | E13: ='RESUMEN TOTAL'!F16 -> Fibra Optica | F13: ='RESUMEN TOTAL'!L16 -> 0 | G13: ='RESUMEN TOTAL'!M16 -> 0 | H13: ='RESUMEN TOTAL'!N16 -> 0 | I13: ='RESUMEN TOTAL'!O16 -> 0 | J13: ='RESUMEN TOTAL'!P16 -> 0 | K13: ='RESUMEN TOTAL'!Q16 -> 0 | L13: ='RESUMEN TOTAL'!R16 -> 0 | M13: ='RESUMEN TOTAL'!S16 -> 0 | ... AI13: ='RESUMEN TOTAL'!AO16 -> 0 | AJ13: ='RESUMEN TOTAL'!#REF! -> #REF!
A14: ='RESUMEN TOTAL'!A17 -> BELGRANO | B14: ='RESUMEN TOTAL'!B17 -> BEL 02 | C14: ='RESUMEN TOTAL'!D17 -> Guardia vieja y Fronteriz | D14: ='RESUMEN TOTAL'!E17 -> DOMO | E14: ='RESUMEN TOTAL'!F17 -> Fibra Optica | F14: ='RESUMEN TOTAL'!L17 -> 0 | G14: ='RESUMEN TOTAL'!M17 -> 0 | H14: ='RESUMEN TOTAL'!N17 -> 0 | I14: ='RESUMEN TOTAL'!O17 -> 0 | J14: ='RESUMEN TOTAL'!P17 -> 0 | K14: ='RESUMEN TOTAL'!Q17 -> 0 | L14: ='RESUMEN TOTAL'!R17 -> 0 | M14: ='RESUMEN TOTAL'!S17 -> 0 | ... AI14: ='RESUMEN TOTAL'!AO17 -> 0 | AJ14: ='RESUMEN TOTAL'!#REF! -> #REF!
A15: ='RESUMEN TOTAL'!A18 -> BOSQUES CENTRO | B15: ='RESUMEN TOTAL'!B18 -> BOSQC 01 | C15: ='RESUMEN TOTAL'!D18 -> LUIS AGOTE E/DANUNCIO Y CAMPOAMOR | D15: ='RESUMEN TOTAL'!E18 -> Fija | E15: ='RESUMEN TOTAL'!F18 -> Radio | F15: ='RESUMEN TOTAL'!L18 -> 0 | G15: ='RESUMEN TOTAL'!M18 -> 0 | H15: ='RESUMEN TOTAL'!N18 -> 0 | I15: ='RESUMEN TOTAL'!O18 -> 0 | J15: ='RESUMEN TOTAL'!P18 -> 0 | K15: ='RESUMEN TOTAL'!Q18 -> 0 | L15: ='RESUMEN TOTAL'!R18 -> 0 | M15: ='RESUMEN TOTAL'!S18 -> 0 | ... AI15: ='RESUMEN TOTAL'!AO18 -> 0 | AJ15: ='RESUMEN TOTAL'!#REF! -> #REF!
... A121: ='RESUMEN TOTAL'!A124 -> DON JOSE | B121: ='RESUMEN TOTAL'!B124 -> DJ 07 | C121: ='RESUMEN TOTAL'!D124 -> Calle 414 y El Indio | D121: ='RESUMEN TOTAL'!E124 -> Fija | E121: ='RESUMEN TOTAL'!F124 -> PTO A FO | F121: ='RESUMEN TOTAL'!L124 -> 0 | G121: ='RESUMEN TOTAL'!M124 -> 0 | H121: ='RESUMEN TOTAL'!N124 -> 0 | I121: ='RESUMEN TOTAL'!O124 -> 0 | J121: ='RESUMEN TOTAL'!P124 -> 0 | K121: ='RESUMEN TOTAL'!Q124 -> 0 | L121: ='RESUMEN TOTAL'!R124 -> 0 | M121: ='RESUMEN TOTAL'!S124 -> 0 | ... AI121: ='RESUMEN TOTAL'!AO124 -> 0 | AJ121: ='RESUMEN TOTAL'!#REF! -> #REF!
A122: ='RESUMEN TOTAL'!A126 -> EL PARQUE | B122: ='RESUMEN TOTAL'!B126 -> EPQ 01 | C122: ='RESUMEN TOTAL'!D126 -> 1282 Y GRIERSON | D122: ='RESUMEN TOTAL'!E126 -> DOMO | E122: ='RESUMEN TOTAL'!F126 -> Fibra Optica | F122: ='RESUMEN TOTAL'!L126 -> 0 | G122: ='RESUMEN TOTAL'!M126 -> 0 | H122: ='RESUMEN TOTAL'!N126 -> 0 | I122: ='RESUMEN TOTAL'!O126 -> 0 | J122: ='RESUMEN TOTAL'!P126 -> 0 | K122: ='RESUMEN TOTAL'!Q126 -> 0 | L122: ='RESUMEN TOTAL'!R126 -> 0 | M122: ='RESUMEN TOTAL'!S126 -> 0 | ... AI122: ='RESUMEN TOTAL'!AO126 -> 0 | AJ122: ='RESUMEN TOTAL'!#REF! -> #REF!
A123: ='RESUMEN TOTAL'!A127 -> EL PARQUE | B123: ='RESUMEN TOTAL'!B127 -> EPQ 02 | C123: ='RESUMEN TOTAL'!D127 -> 1282 Y MASSE | D123: ='RESUMEN TOTAL'!E127 -> DOMO | E123: ='RESUMEN TOTAL'!F127 -> Fibra Optica | F123: ='RESUMEN TOTAL'!L127 -> 0 | G123: ='RESUMEN TOTAL'!M127 -> 0 | H123: ='RESUMEN TOTAL'!N127 -> 0 | I123: ='RESUMEN TOTAL'!O127 -> 0 | J123: ='RESUMEN TOTAL'!P127 -> 0 | K123: ='RESUMEN TOTAL'!Q127 -> 0 | L123: ='RESUMEN TOTAL'!R127 -> 0 | M123: ='RESUMEN TOTAL'!S127 -> 0 | ... AI123: ='RESUMEN TOTAL'!AO127 -> 0 | AJ123: ='RESUMEN TOTAL'!#REF! -> #REF!
A124: ='RESUMEN TOTAL'!A128 -> EL PARQUE | B124: ='RESUMEN TOTAL'!B128 -> EPQ 03 | C124: ='RESUMEN TOTAL'!D128 -> 1282 Y RP 36 | D124: ='RESUMEN TOTAL'!E128 -> Domo | E124: ='RESUMEN TOTAL'!F128 -> Fibra Optica | F124: ='RESUMEN TOTAL'!L128 -> 0 | G124: ='RESUMEN TOTAL'!M128 -> 0 | H124: ='RESUMEN TOTAL'!N128 -> 0 | I124: ='RESUMEN TOTAL'!O128 -> 0 | J124: ='RESUMEN TOTAL'!P128 -> 0 | K124: ='RESUMEN TOTAL'!Q128 -> 0 | L124: ='RESUMEN TOTAL'!R128 -> 0 | M124: ='RESUMEN TOTAL'!S128 -> 0 | ... AI124: ='RESUMEN TOTAL'!AO128 -> 0 | AJ124: ='RESUMEN TOTAL'!#REF! -> #REF!
A125: ='RESUMEN TOTAL'!A129 -> EL PARQUE | B125: ='RESUMEN TOTAL'!B129 -> EPQ 04 | C125: ='RESUMEN TOTAL'!D129 -> 1282 Y MORENO | D125: ='RESUMEN TOTAL'!E129 -> DOMO | E125: ='RESUMEN TOTAL'!F129 -> Fibra Optica | F125: ='RESUMEN TOTAL'!L129 -> 0 | G125: ='RESUMEN TOTAL'!M129 -> 0 | H125: ='RESUMEN TOTAL'!N129 -> 0 | I125: ='RESUMEN TOTAL'!O129 -> 0 | J125: ='RESUMEN TOTAL'!P129 -> 0 | K125: ='RESUMEN TOTAL'!Q129 -> 0 | L125: ='RESUMEN TOTAL'!R129 -> 0 | M125: ='RESUMEN TOTAL'!S129 -> 0 | ... AI125: ='RESUMEN TOTAL'!AO129 -> 0 | AJ125: ='RESUMEN TOTAL'!#REF! -> #REF!
A126: ='RESUMEN TOTAL'!A130 -> LA ESMERALDA | B126: ='RESUMEN TOTAL'!B130 -> ESM01 | C126: ='RESUMEN TOTAL'!D130 -> Cabello y Brasil | D126: ='RESUMEN TOTAL'!E130 -> Domo | E126: ='RESUMEN TOTAL'!F130 -> Radio | F126: ='RESUMEN TOTAL'!L130 -> 0 | G126: ='RESUMEN TOTAL'!M130 -> 0 | H126: ='RESUMEN TOTAL'!N130 -> 0 | I126: ='RESUMEN TOTAL'!O130 -> 0 | J126: ='RESUMEN TOTAL'!P130 -> 0 | K126: ='RESUMEN TOTAL'!Q130 -> 0 | L126: ='RESUMEN TOTAL'!R130 -> 0 | M126: ='RESUMEN TOTAL'!S130 -> 0 | ... AI126: ='RESUMEN TOTAL'!AO130 -> 0 | AJ126: ='RESUMEN TOTAL'!#REF! -> #REF!
A127: ='RESUMEN TOTAL'!A131 -> SAN JORGE | B127: ='RESUMEN TOTAL'!B131 -> ESM02 | C127: ='RESUMEN TOTAL'!D131 -> Novak y Cabello | D127: ='RESUMEN TOTAL'!E131 -> Domo | E127: ='RESUMEN TOTAL'!F131 -> PTO A FO | F127: ='RESUMEN TOTAL'!L131 -> 0 | G127: ='RESUMEN TOTAL'!M131 -> 0 | H127: ='RESUMEN TOTAL'!N131 -> 0 | I127: ='RESUMEN TOTAL'!O131 -> 0 | J127: ='RESUMEN TOTAL'!P131 -> 0 | K127: ='RESUMEN TOTAL'!Q131 -> 0 | L127: ='RESUMEN TOTAL'!R131 -> 0 | M127: ='RESUMEN TOTAL'!S131 -> 0 | ... AI127: ='RESUMEN TOTAL'!AO131 -> 0 | AJ127: ='RESUMEN TOTAL'!#REF! -> #REF!
A128: ='RESUMEN TOTAL'!A132 -> 0 | B128: ='RESUMEN TOTAL'!B132 -> ESM03 | C128: ='RESUMEN TOTAL'!D132 -> Novak y Humahuaca | D128: ='RESUMEN TOTAL'!E132 -> DOMO | E128: ='RESUMEN TOTAL'!F132 -> PTO A FO | F128: ='RESUMEN TOTAL'!L132 -> 0 | G128: ='RESUMEN TOTAL'!M132 -> 0 | H128: ='RESUMEN TOTAL'!N132 -> 0 | I128: ='RESUMEN TOTAL'!O132 -> 0 | J128: ='RESUMEN TOTAL'!P132 -> 0 | K128: ='RESUMEN TOTAL'!Q132 -> 0 | L128: ='RESUMEN TOTAL'!R132 -> 0 | M128: ='RESUMEN TOTAL'!S132 -> 0 | ... AI128: ='RESUMEN TOTAL'!AO132 -> 0 | AJ128: ='RESUMEN TOTAL'!#REF! -> #REF!
A129: ='RESUMEN TOTAL'!A133 -> LA ESMERALDA | B129: ='RESUMEN TOTAL'!B133 -> ESM04 | C129: ='RESUMEN TOTAL'!D133 -> Basualdo y Bengochea | D129: ='RESUMEN TOTAL'!E133 -> Domo | E129: ='RESUMEN TOTAL'!F133 -> Fibra Optica | F129: ='RESUMEN TOTAL'!L133 -> APAGADO | G129: ='RESUMEN TOTAL'!M133 -> APAGADO | H129: ='RESUMEN TOTAL'!N133 -> APAGADO | I129: ='RESUMEN TOTAL'!O133 -> APAGADO | J129: ='RESUMEN TOTAL'!P133 -> APAGADO | K129: ='RESUMEN TOTAL'!Q133 -> 0 | L129: ='RESUMEN TOTAL'!R133 -> 0 | M129: ='RESUMEN TOTAL'!S133 -> 0 | ... AI129: ='RESUMEN TOTAL'!AO133 -> 0 | AJ129: ='RESUMEN TOTAL'!#REF! -> #REF!
A130: ='RESUMEN TOTAL'!A134 -> LA ESMERALDA | B130: ='RESUMEN TOTAL'!B134 -> ESM05 | C130: ='RESUMEN TOTAL'!D134 -> Aniceto Diaz y Villar | D130: ='RESUMEN TOTAL'!E134 -> Domo | E130: ='RESUMEN TOTAL'!F134 -> Fibra Optica | F130: ='RESUMEN TOTAL'!L134 -> APAGADO | G130: ='RESUMEN TOTAL'!M134 -> APAGADO | H130: ='RESUMEN TOTAL'!N134 -> APAGADO | I130: ='RESUMEN TOTAL'!O134 -> APAGADO | J130: ='RESUMEN TOTAL'!P134 -> APAGADO | K130: ='RESUMEN TOTAL'!Q134 -> 0 | L130: ='RESUMEN TOTAL'!R134 -> 0 | M130: ='RESUMEN TOTAL'!S134 -> 0 | ... AI130: ='RESUMEN TOTAL'!AO134 -> 0 | AJ130: ='RESUMEN TOTAL'!#REF! -> #REF!
A131: ='RESUMEN TOTAL'!A135 -> LA ESMERALDA | B131: ='RESUMEN TOTAL'!B135 -> ESM06 | C131: ='RESUMEN TOTAL'!D135 -> Roselli y Cabello | D131: ='RESUMEN TOTAL'!E135 -> Domo | E131: ='RESUMEN TOTAL'!F135 -> Radio | F131: ='RESUMEN TOTAL'!L135 -> 0 | G131: ='RESUMEN TOTAL'!M135 -> 0 | H131: ='RESUMEN TOTAL'!N135 -> 0 | I131: ='RESUMEN TOTAL'!O135 -> 0 | J131: ='RESUMEN TOTAL'!P135 -> 0 | K131: ='RESUMEN TOTAL'!Q135 -> 0 | L131: ='RESUMEN TOTAL'!R135 -> 0 | M131: ='RESUMEN TOTAL'!S135 -> 0 | ... AI131: ='RESUMEN TOTAL'!AO135 -> 0 | AJ131: ='RESUMEN TOTAL'!#REF! -> #REF!
A132: ='RESUMEN TOTAL'!A136 -> LA ESMERALDA | B132: ='RESUMEN TOTAL'!B136 -> ESM07 | C132: ='RESUMEN TOTAL'!D136 -> AV. NOVAK Y SERRANO | D132: ='RESUMEN TOTAL'!E136 -> DOMO | E132: ='RESUMEN TOTAL'!F136 -> PTO A FO | F132: ='RESUMEN TOTAL'!L136 -> 0 | G132: ='RESUMEN TOTAL'!M136 -> 0 | H132: ='RESUMEN TOTAL'!N136 -> 0 | I132: ='RESUMEN TOTAL'!O136 -> 0 | J132: ='RESUMEN TOTAL'!P136 -> 0 | K132: ='RESUMEN TOTAL'!Q136 -> 0 | L132: ='RESUMEN TOTAL'!R136 -> 0 | M132: ='RESUMEN TOTAL'!S136 -> 0 | ... AI132: ='RESUMEN TOTAL'!AO136 -> 0 | AJ132: ='RESUMEN TOTAL'!#REF! -> #REF!
