Workbook
Name _25_de_agosto: 'RESUMEN TOTAL'!$A$4:$C$347

Sheet RESUMEN TOTAL
A1: CANTIDAD DE CAMARAS | B1: =COUNTA(B5:B525) -> 366 | C1: PORCIENTO DE CAIDAS | N1: =(N3)/(N2+N3) -> 0.17032967 | O1: =(O3)/(O2+O3) -> 0.21978022 | P1: =(P3)/(P2+P3) -> 0.21153846 | Q1: =(Q3)/(Q2+Q3) -> 0.19230769 | R1: =(R3)/(R2+R3) -> 0.19230769 | S1: =(S3)/(S2+S3) -> 0 | T1: =(T3)/(T2+T3) -> 0 | U1: =(U3)/(U2+U3) -> 0 | ... AR1: =(AR3)/(AR2+AR3) -> 0
C2: FUNCIONAN | N2: =COUNTIF(N5:N368, "") -> 302 | O2: =COUNTIF(O5:O368, "") -> 284 | P2: =COUNTIF(P5:P368, "") -> 287 | Q2: =COUNTIF(Q5:Q368, "") -> 294 | R2: =COUNTIF(R5:R368, "") -> 294 | S2: =COUNTIF(S5:S368, "") -> 364 | T2: =COUNTIF(T5:T368, "") -> 364 | U2: =COUNTIF(U5:U368, "") -> 364 | ... AR2: =COUNTIF(AR5:AR368, "") -> 364
C3: CAIDAS | N3: =COUNTIF(N4:N445, "apagado") -> 62 | O3: =COUNTIF(O4:O445, "apagado") -> 80 | P3: =COUNTIF(P4:P445, "apagado") -> 77 | Q3: =COUNTIF(Q4:Q445, "apagado") -> 70 | R3: =COUNTIF(R4:R445, "apagado") -> 70 | S3: =COUNTIF(S4:S445, "apagado") -> 0 | T3: =COUNTIF(T4:T445, "apagado") -> 0 | U3: =COUNTIF(U4:U445, "apagado") -> 0 | ... AR3: =COUNTIF(AR4:AR445, "apagado") -> 0
A4: Barrio | B4: [Denominacion] | C4: [Ubicacion] | D4: [Tipo de Camara] | E4: [Tipo de Conexion] | F4: [Fundamento] | G4: [Detalle] | H4: Latitud | I4: Longitud | K4: DIAS FUNCIONANDO | L4: DIAS CAIDA | M4: EFECTIVIDAD | N4: 44621 | O4: 44622 | P4: 44623 | Q4: 44624 | R4: 44625 | S4: 44626 | T4: 44627 | U4: 44628 | V4: 44629 | W4: 44630 | X4: 44631 | Y4: 44632 | Z4: 44633 | AA4: 44634 | AB4: 44635 | AC4: 44636 | AD4: 44637 | AE4: 44638 | AF4: 44639 | AG4: 44640 | AH4: 44641 | AI4: 44642 | AJ4: 44643 | AK4: 44644 | AL4: 44645 | AM4: 44646 | AN4: 44647 | AO4: 44648 | AP4: 44649 | AQ4: 44650 | AR4: 44651
A5: PRESIDENTE PERON (PEPSI) | B5: MAR 01 | C5: RP36 Y LA ESMERALDA | D5: DOMO | E5: Fibra Optica | F5: POSIBLE VIA DE ESCAPE. FLUJO VEHICULAR | H5: -348296270000 | I5: -582165860000 | J5: 172.20.11.101 | K5: =COUNTIF(N5:AO5,"") -> 23 | L5: =COUNTIF(N5:AO5,"APAGADO") -> 5 | M5: =(K5)/(L5+K5) -> 0.82142857 | N5: APAGADO | O5: APAGADO | P5: APAGADO | Q5: APAGADO | R5: APAGADO
A6: MAYOL | B6: MAY 01 | C6: Eva Peron y Cabildo | D6: Domo | E6: Radio | F6: Flujo Vehicular, Futuro corredor escolar, Zona Comercial | H6: -348239900000 | I6: -582772350000 | J6: 172.20.200.194 | K6: =COUNTIF(N6:AO6,"") -> 28 | L6: =COUNTIF(N6:AO6,"APAGADO") -> 0 | M6: =(K6)/(L6+K6) -> 1
B7: MAY 02 | C7: EVA PERON Y MONTEVIDEO | D7: Domo | E7: Radio | H7: -348218190000 | I7: -582771380000 | J7: 172.20.200.168 | K7: =COUNTIF(N7:AO7,"") -> 28 | L7: =COUNTIF(N7:AO7,"APAGADO") -> 0 | M7: =(K7)/(L7+K7) -> 1
A8: MAYOL | B8: MAY 03 | C8: CHAÑAR Y SAN NICOLAS | D8: DOMO | E8: PTP A FO | G8: ALTA 29/10/2019 | H8: -348230700000 | I8: -582702540000 | J8: 172.20.10.18 | K8: =COUNTIF(N8:AO8,"") -> 28 | L8: =COUNTIF(N8:AO8,"APAGADO") -> 0 | M8: =(K8)/(L8+K8) -> 1
B9: MAY 04 | C9: MAR CHIQUITA Y RIO JACHAL | D9: DOMO | E9: Radio | G9: 08/07/2020 COMIENZA A REPORTAR IMAGEN | H9: -348252070000 | I9: -582711820000 | J9: 10.20.30.34 | K9: =COUNTIF(N9:AO9,"") -> 28 | L9: =COUNTIF(N9:AO9,"APAGADO") -> 0 | M9: =(K9)/(L9+K9) -> 1
A10: ALTAMIRA | B10: ALT06 | C10: LOPE DE VEGA Y NECOCHEA | D10: Domo | E10: PTP A FO | G10: Instalada sin alta en sistema. ALTA en sistema y en funcionamiento 04/05/2020 | H10: -347738090000 | I10: -582721410000 | J10: 172.20.12.12 | K10: =COUNTIF(N10:AO10,"") -> 28 | L10: =COUNTIF(N10:AO10,"APAGADO") -> 0 | M10: =(K10)/(L10+K10) -> 1
A11: ALTAMIRA | B11: ALT01 | C11: Calchaqui y Sgto. Cabral | D11: Domo | E11: Fibra Optica | F11: Universidad, Zona Bancaria, Flujo Vehicular, Posible Via de Escape | H11: -347769580000 | I11: -582650900000 | J11: 172.20.10.6 | K11: =COUNTIF(N11:AO11,"") -> 28 | L11: =COUNTIF(N11:AO11,"APAGADO") -> 0 | M11: =(K11)/(L11+K11) -> 1
A12: ALTAMIRA | B12: ALT02 | C12: Calchaqui y Lope de Vega | D12: Domo | E12: PTP A FO | F12: Hospital, Flujo Vehicular, Peatonal | H12: -347718470000 | I12: -582688560000 | J12: 172.20.12.218 | K12: =COUNTIF(N12:AO12,"") -> 28 | L12: =COUNTIF(N12:AO12,"APAGADO") -> 0 | M12: =(K12)/(L12+K12) -> 1
A13: ALTAMIRA | B13: ALT03 | C13: Bombero Galarza y Necochea | D13: Domo | E13: Fibra Optica | F13: Hospital, Limite del Partido | H13: -347726570000 | I13: -582730620000 | J13: 172.20.12.54 | K13: =COUNTIF(N13:AO13,"") -> 28 | L13: =COUNTIF(N13:AO13,"APAGADO") -> 0 | M13: =(K13)/(L13+K13) -> 1
B14: ALT04 | C14: Francia y Necochea | D14: Domo | E14: Fibra Optica | F14: Zona RecreaciÃ³n | H14: -347705420000 | I14: -582748000000 | J14: 172.20.12.55 | K14: =COUNTIF(N14:AO14,"") -> 27 | L14: =COUNTIF(N14:AO14,"APAGADO") -> 1 | M14: =(K14)/(L14+K14) -> 0.96428571 | N14: APAGADO
A15: ALTAMIRA | B15: ALT05 | C15: Av. Calchaqui y Bombero Galarza | D15: Domo | E15: PTP A FO | F15: Zona Bancaria, Flujo Vehicular, Posible via de escape, Limite del partido | H15: -347708370000 | I15: -582698000000 | J15: 172.20.12.216 | K15: =COUNTIF(N15:AO15,"") -> 28 | L15: =COUNTIF(N15:AO15,"APAGADO") -> 0 | M15: =(K15)/(L15+K15) -> 1
A16: ALTAMIRA | B16: ALT07 | C16: AV. CALCHAQUI Y AV. DEL TRABAJO | D16: DOMO | E16: PTP A FO | G16: SE DA DE ALTA EL 17/09/2020 18:51HS | H16: -347737570000 | I16: -582676650000 | J16: 172.20.10.57 | K16: =COUNTIF(N16:AO16,"") -> 28 | L16: =COUNTIF(N16:AO16,"APAGADO") -> 0 | M16: =(K16)/(L16+K16) -> 1
A17: ALTAMIRA | B17: ALT08 | C17: HUMAITA Y NECOCHEA | D17: DOMO | E17: Fibra Optica | G17: REPORTA IMAGENES 20/08/2021 | H17: -347749440000 | I17: -582711610000 | J17: 172.20.11.215 | K17: =COUNTIF(N17:AO17,"") -> 28 | L17: =COUNTIF(N17:AO17,"APAGADO") -> 0 | M17: =(K17)/(L17+K17) -> 1
A18: ALTAMIRA | B18: ALT09 | C18: NECOCHEA Y CURUPAITY | D18: DOMO | E18: Fibra Optica | G18: SE DA DE ALTA 25/08/2021 | H18: -347743740000 | I18: -582715650000 | J18: 172.20.11.216 | K18: =COUNTIF(N18:AO18,"") -> 28 | L18: =COUNTIF(N18:AO18,"APAGADO") -> 0 | M18: =(K18)/(L18+K18) -> 1
A19: AGUSTIN RAMIREZ | B19: ARA01 | C19: Malambo y Tranquera | D19: Domo | E19: Fibra Optica | F19: Zona Escolar, Flujo Vehicular | H19: -347979380000 | I19: -583160950000 | J19: 172.20.12.110 | K19: =COUNTIF(N19:AO19,"") -> 24 | L19: =COUNTIF(N19:AO19,"APAGADO") -> 4 | M19: =(K19)/(L19+K19) -> 0.85714286 | O19: APAGADO | P19: APAGADO | Q19: APAGADO | R19: APAGADO
A20: ALTAMIRA | B20: ALT10 | C20: REP. FRANCIA Y CALCHAQUI (RP 36) | D20: DOMO | E20: PTP A FO | G20: SE DA DE ALTA 10/11/2021 | H20: -347689160000 | I20: -582717100000 | J20: 172.20.12.156 | K20: =COUNTIF(N20:AO20,"") -> 28 | L20: =COUNTIF(N20:AO20,"APAGADO") -> 0 | M20: =(K20)/(L20+K20) -> 1
A21: BELGRANO | B21: BEL01 | C21: San Martin y Dardo Rocha | D21: DOMO | E21: Fibra Optica | F21: Zona Escolar, Flujo Vehicular | G21: 19/03/2020 SE RETIRO DISPOSITIVO POR RIESGO DE CAIDA. 19/08/2020 comenzo a funcionar. | H21: -347918370000 | I21: -582786080000 | J21: 172.20.12.64 | K21: =COUNTIF(N21:AO21,"") -> 28 | L21: =COUNTIF(N21:AO21,"APAGADO") -> 0 | M21: =(K21)/(L21+K21) -> 1
B22: CEN51 | C22: ILLIA Y LAS HERAS | D22: FIJA | E22: Fibra Optica | F22: POSIBLE VIA DE ESCAPE, Y FLUJO VEHICULAR | H22: -347987830000 | I22: -582840920000 | J22: 172.20.11.29 | K22: =COUNTIF(N22:AO22,"") -> 28 | L22: =COUNTIF(N22:AO22,"APAGADO") -> 0 | M22: =(K22)/(L22+K22) -> 1
B23: CEN53 | C23: GUTIERREZ Y BROWN | D23: Domo | E23: Radio | H23: -348013650000 | I23: -582715700000 | J23: 172.20.200.166 | K23: =COUNTIF(N23:AO23,"") -> 28 | L23: =COUNTIF(N23:AO23,"APAGADO") -> 0 | M23: =(K23)/(L23+K23) -> 1
B24: CEN 54 | C24: GUTIERREZ Y PRINGLES | D24: Domo | E24: Radio | H24: -348013470000 | I24: -582698540000 | J24: 172.20.200.165 | K24: =COUNTIF(N24:AO24,"") -> 26 | L24: =COUNTIF(N24:AO24,"APAGADO") -> 2 | M24: =(K24)/(L24+K24) -> 0.92857143 | Q24: APAGADO | R24: APAGADO
B25: CEN 55 | C25: BOUREL Y URQUIZA | D25: Domo | E25: Radio | H25: -348019110000 | I25: -582819990000 | J25: 172.20.200.163 | K25: =COUNTIF(N25:AO25,"") -> 28 | L25: =COUNTIF(N25:AO25,"APAGADO") -> 0 | M25: =(K25)/(L25+K25) -> 1
A26: CENTRO | B26: CEN 56 | C26: Newbery y Falucho | D26: DOMO | E26: Radio | F26: Posible via de escape, Cruce Peligroso | H26: -348073990000 | I26: -582850080000 | J26: 172.20.200.161 | K26: =COUNTIF(N26:AO26,"") -> 28 | L26: =COUNTIF(N26:AO26,"APAGADO") -> 0 | M26: =(K26)/(L26+K26) -> 1
B27: CEN 57 | C27: 25 DE MAYO Y DORREGO | D27: DOMO | E27: Radio | H27: -348007360000 | I27: -582804240000 | J27: 172.20.200.199 | K27: =COUNTIF(N27:AO27,"") -> 28 | L27: =COUNTIF(N27:AO27,"APAGADO") -> 0 | M27: =(K27)/(L27+K27) -> 1
B28: CEN 58 | C28: EEUU Y MORENO | D28: DOMO | E28: Fibra Optica | G28: INSTALADA: 11/06/18. EN FUNCIONAMIENTO: 27/06/18. | H28: -348103030000 | I28: -582835720000 | J28: 172.20.11.84 | K28: =COUNTIF(N28:AO28,"") -> 28 | L28: =COUNTIF(N28:AO28,"APAGADO") -> 0 | M28: =(K28)/(L28+K28) -> 1
B29: CEN 59 | C29: CHACABUCO Y BOUREL | D29: DOMO | E29: Radio | G29: INSTALADA:11/06/18EN FUNCIONAMIENTO: 27/06/18 | H29: -348039300000 | I29: -582819780000 | J29: 172.20.200.188 | K29: =COUNTIF(N29:AO29,"") -> 28 | L29: =COUNTIF(N29:AO29,"APAGADO") -> 0 | M29: =(K29)/(L29+K29) -> 1
A30: CENTRO | B30: CEN 60 | C30: RECONQUISTA Y ILLIA | D30: DOMO | E30: PTP A FO | G30: ALTA 26/10/2019 | H30: -347999170000 | I30: -582863530000 | J30: 172.20.12.67 | K30: =COUNTIF(N30:AO30,"") -> 28 | L30: =COUNTIF(N30:AO30,"APAGADO") -> 0 | M30: =(K30)/(L30+K30) -> 1
A31: CENTRO | B31: CEN 61 | C31: BOUREL Y MAIPU | D31: DOMO | E31: Radio | G31: ALTA EN FUNCIONAMIENTO 12/04/2019 | H31: -348040550000 | I31: -582819380000 | J31: 172.20.200.159 | K31: =COUNTIF(N31:AO31,"") -> 28 | L31: =COUNTIF(N31:AO31,"APAGADO") -> 0 | M31: =(K31)/(L31+K31) -> 1
A32: CENTRO | B32: CEN 62 | C32: ESPAÑA Y ALEM | D32: DOMO | E32: PTP A FO | G32: ALTA: 16/06/2020 | H32: -348038200000 | I32: -582766160000 | J32: 172.20.12.82 | K32: =COUNTIF(N32:AO32,"") -> 28 | L32: =COUNTIF(N32:AO32,"APAGADO") -> 0 | M32: =(K32)/(L32+K32) -> 1
A33: CENTRO | B33: CEN 63 | C33: SAN MARTIN Y URQUIZA | D33: DOMO | E33: Fibra Optica | G33: DADA DE ALTA ABRIL 2021 | H33: -348017700000 | I33: -582785020000 | J33: 172.20.11.112 | K33: =COUNTIF(N33:AO33,"") -> 28 | L33: =COUNTIF(N33:AO33,"APAGADO") -> 0 | M33: =(K33)/(L33+K33) -> 1
A34: CENTRO | B34: CEN 70 | C34: RIVADAVIA Y 25 MAYO | D34: Domo | E34: Fibra Optica | G34: alta en sistema 25/11/2021 | H34: -348091950000 | I34: -582800930000 | J34: 172.20.11.221 | K34: =COUNTIF(N34:AO34,"") -> 28 | L34: =COUNTIF(N34:AO34,"APAGADO") -> 0 | M34: =(K34)/(L34+K34) -> 1
A35: CENTRO | B35: CEN 71 | C35: MORENO Y BOUREL | D35: Domo | E35: Fibra Optica | G35: alta en sistema 25/11/2021 | H35: -348103130000 | I35: -582818230000 | J35: 172.20.11.220 | K35: =COUNTIF(N35:AO35,"") -> 28 | L35: =COUNTIF(N35:AO35,"APAGADO") -> 0 | M35: =(K35)/(L35+K35) -> 1
A36: CENTRO | B36: CEN 72 | C36: MORENO Y 25 DE MAYO | D36: Domo | E36: Fibra Optica | G36: ALTA EN SISTEMA 25/11/2021 | H36: -348102250000 | I36: -582800780000 | J36: 172.20.11.219 | K36: =COUNTIF(N36:AO36,"") -> 28 | L36: =COUNTIF(N36:AO36,"APAGADO") -> 0 | M36: =(K36)/(L36+K36) -> 1
A37: CENTRO | B37: CEN01 | C37: San Martin y 9 de Julio | D37: Fija | E37: Fibra Optica | F37: Zona Comercial, Flujo Vehicular | H37: -348028100000 | I37: -582782860000 | J37: 172.20.11.10 | K37: =COUNTIF(N37:AO37,"") -> 23 | L37: =COUNTIF(N37:AO37,"APAGADO") -> 5 | M37: =(K37)/(L37+K37) -> 0.82142857 | N37: APAGADO | O37: APAGADO | P37: APAGADO | Q37: APAGADO | R37: APAGADO
A38: CENTRO | B38: CEN02 | C38: San Martin y Almafuerte | D38: Fija | E38: Fibra Optica | F38: Bomberos, Flujo Vehicular, Zona Comercial | H38: -348006070000 | I38: -582784580000 | J38: 172.20.11.11 | K38: =COUNTIF(N38:AO38,"") -> 28 | L38: =COUNTIF(N38:AO38,"APAGADO") -> 0 | M38: =(K38)/(L38+K38) -> 1
A39: CENTRO | B39: CEN03 | C39: San Martin y Sallares | D39: Domo | E39: Fibra Optica | F39: Zona Comercial, Flujo Vehicular | G39: 29/03/19 FUNCIONA EN COD 1 | H39: -348080340000 | I39: -582780930000 | J39: 172.20.12.30 | K39: =COUNTIF(N39:AO39,"") -> 28 | L39: =COUNTIF(N39:AO39,"APAGADO") -> 0 | M39: =(K39)/(L39+K39) -> 1
A40: CENTRO | B40: CEN04 | C40: San Martin y Contreras | D40: Domo | E40: Fibra Optica | F40: Zona de recreaciÃ³n, Flujo vehicular | H40: -348049240000 | I40: -582781680000 | J40: 172.20.12.29 | K40: =COUNTIF(N40:AO40,"") -> 28 | L40: =COUNTIF(N40:AO40,"APAGADO") -> 0 | M40: =(K40)/(L40+K40) -> 1
...

Sheet REPARACIONES DIARIAS
A1: REPARADOS POR DIA
A3: 44621
A4: 44622
A5: 44623
A6: 44624
A7: 44625
A8: 44626
A9: 44627
A10: 44628
A11: 44629
A12: 44630
A13: 44631
A14: 44632
... A33: 44651

Sheet ESTADISTICA
A1: ='RESUMEN TOTAL'!A4 -> Barrio | B1: ='RESUMEN TOTAL'!B4 -> [Denominacion] | C1: ='RESUMEN TOTAL'!C4 -> [Ubicacion] | D1: ='RESUMEN TOTAL'!D4 -> [Tipo de Camara] | E1: ='RESUMEN TOTAL'!E4 -> [Tipo de Conexion] | F1: ='RESUMEN TOTAL'!N4 -> 44621 | G1: ='RESUMEN TOTAL'!O4 -> 44622 | H1: ='RESUMEN TOTAL'!P4 -> 44623 | I1: ='RESUMEN TOTAL'!Q4 -> 44624 | J1: ='RESUMEN TOTAL'!R4 -> 44625 | K1: ='RESUMEN TOTAL'!S4 -> 44626 | L1: ='RESUMEN TOTAL'!T4 -> 44627 | M1: ='RESUMEN TOTAL'!U4 -> 44628 | ... AJ1: ='RESUMEN TOTAL'!AR4 -> 44651
A2: ='RESUMEN TOTAL'!A5 -> PRESIDENTE PERON (PEPSI) | B2: ='RESUMEN TOTAL'!B5 -> MAR 01 | C2: ='RESUMEN TOTAL'!C5 -> RP36 Y LA ESMERALDA | D2: ='RESUMEN TOTAL'!D5 -> DOMO | E2: ='RESUMEN TOTAL'!E5 -> Fibra Optica | F2: ='RESUMEN TOTAL'!N5 -> APAGADO | G2: ='RESUMEN TOTAL'!O5 -> APAGADO | H2: ='RESUMEN TOTAL'!P5 -> APAGADO | I2: ='RESUMEN TOTAL'!Q5 -> APAGADO | J2: ='RESUMEN TOTAL'!R5 -> APAGADO | K2: ='RESUMEN TOTAL'!S5 -> 0 | L2: ='RESUMEN TOTAL'!T5 -> 0 | M2: ='RESUMEN TOTAL'!U5 -> 0 | ... AG2: ='RESUMEN TOTAL'!AO5 -> 0
A3: ='RESUMEN TOTAL'!A6 -> MAYOL | B3: ='RESUMEN TOTAL'!B6 -> MAY 01 | C3: ='RESUMEN TOTAL'!C6 -> Eva Peron y Cabildo | D3: ='RESUMEN TOTAL'!D6 -> Domo | E3: ='RESUMEN TOTAL'!E6 -> Radio | F3: ='RESUMEN TOTAL'!N6 -> 0 | G3: ='RESUMEN TOTAL'!O6 -> 0 | H3: ='RESUMEN TOTAL'!P6 -> 0 | I3: ='RESUMEN TOTAL'!Q6 -> 0 | J3: ='RESUMEN TOTAL'!R6 -> 0 | K3: ='RESUMEN TOTAL'!S6 -> 0 | L3: ='RESUMEN TOTAL'!T6 -> 0 | M3: ='RESUMEN TOTAL'!U6 -> 0 | ... AG3: ='RESUMEN TOTAL'!AO6 -> 0
A4: ='RESUMEN TOTAL'!A7 -> 0 | B4: ='RESUMEN TOTAL'!B7 -> MAY 02 | C4: ='RESUMEN TOTAL'!C7 -> EVA PERON Y MONTEVIDEO | D4: ='RESUMEN TOTAL'!D7 -> Domo | E4: ='RESUMEN TOTAL'!E7 -> Radio | F4: ='RESUMEN TOTAL'!N7 -> 0 | G4: ='RESUMEN TOTAL'!O7 -> 0 | H4: ='RESUMEN TOTAL'!P7 -> 0 | I4: ='RESUMEN TOTAL'!Q7 -> 0 | J4: ='RESUMEN TOTAL'!R7 -> 0 | K4: ='RESUMEN TOTAL'!S7 -> 0 | L4: ='RESUMEN TOTAL'!T7 -> 0 | M4: ='RESUMEN TOTAL'!U7 -> 0 | ... AG4: ='RESUMEN TOTAL'!AO7 -> 0
A5: ='RESUMEN TOTAL'!A8 -> MAYOL | B5: ='RESUMEN TOTAL'!B8 -> MAY 03 | C5: ='RESUMEN TOTAL'!C8 -> CHAÑAR Y SAN NICOLAS | D5: ='RESUMEN TOTAL'!D8 -> DOMO | E5: ='RESUMEN TOTAL'!E8 -> PTP A FO | F5: ='RESUMEN TOTAL'!N8 -> 0 | G5: ='RESUMEN TOTAL'!O8 -> 0 | H5: ='RESUMEN TOTAL'!P8 -> 0 | I5: ='RESUMEN TOTAL'!Q8 -> 0 | J5: ='RESUMEN TOTAL'!R8 -> 0 | K5: ='RESUMEN TOTAL'!S8 -> 0 | L5: ='RESUMEN TOTAL'!T8 -> 0 | M5: ='RESUMEN TOTAL'!U8 -> 0 | ... AG5: ='RESUMEN TOTAL'!AO8 -> 0
A6: ='RESUMEN TOTAL'!A9 -> 0 | B6: ='RESUMEN TOTAL'!B9 -> MAY 04 | C6: ='RESUMEN TOTAL'!C9 -> MAR CHIQUITA Y RIO JACHAL | D6: ='RESUMEN TOTAL'!D9 -> DOMO | E6: ='RESUMEN TOTAL'!E9 -> Radio | F6: ='RESUMEN TOTAL'!N9 -> 0 | G6: ='RESUMEN TOTAL'!O9 -> 0 | H6: ='RESUMEN TOTAL'!P9 -> 0 | I6: ='RESUMEN TOTAL'!Q9 -> 0 | J6: ='RESUMEN TOTAL'!R9 -> 0 | K6: ='RESUMEN TOTAL'!S9 -> 0 | L6: ='RESUMEN TOTAL'!T9 -> 0 | M6: ='RESUMEN TOTAL'!U9 -> 0 | ... AG6: ='RESUMEN TOTAL'!AO9 -> 0
A7: ='RESUMEN TOTAL'!A10 -> ALTAMIRA | B7: ='RESUMEN TOTAL'!B10 -> ALT06 | C7: ='RESUMEN TOTAL'!C10 -> LOPE DE VEGA Y NECOCHEA | D7: ='RESUMEN TOTAL'!D10 -> Domo | E7: ='RESUMEN TOTAL'!E10 -> PTP A FO | F7: ='RESUMEN TOTAL'!N10 -> 0 | G7: ='RESUMEN TOTAL'!O10 -> 0 | H7: ='RESUMEN TOTAL'!P10 -> 0 | I7: ='RESUMEN TOTAL'!Q10 -> 0 | J7: ='RESUMEN TOTAL'!R10 -> 0 | K7: ='RESUMEN TOTAL'!S10 -> 0 | L7: ='RESUMEN TOTAL'!T10 -> 0 | M7: ='RESUMEN TOTAL'!U10 -> 0 | ... AG7: ='RESUMEN TOTAL'!AO10 -> 0
A8: ='RESUMEN TOTAL'!A11 -> ALTAMIRA | B8: ='RESUMEN TOTAL'!B11 -> ALT01 | C8: ='RESUMEN TOTAL'!C11 -> Calchaqui y Sgto. Cabral | D8: ='RESUMEN TOTAL'!D11 -> Domo | E8: ='RESUMEN TOTAL'!E11 -> Fibra Optica | F8: ='RESUMEN TOTAL'!N11 -> 0 | G8: ='RESUMEN TOTAL'!O11 -> 0 | H8: ='RESUMEN TOTAL'!P11 -> 0 | I8: ='RESUMEN TOTAL'!Q11 -> 0 | J8: ='RESUMEN TOTAL'!R11 -> 0 | K8: ='RESUMEN TOTAL'!S11 -> 0 | L8: ='RESUMEN TOTAL'!T11 -> 0 | M8: ='RESUMEN TOTAL'!U11 -> 0 | ... AG8: ='RESUMEN TOTAL'!AO11 -> 0
A9: ='RESUMEN TOTAL'!A12 -> ALTAMIRA | B9: ='RESUMEN TOTAL'!B12 -> ALT02 | C9: ='RESUMEN TOTAL'!C12 -> Calchaqui y Lope de Vega | D9: ='RESUMEN TOTAL'!D12 -> Domo | E9: ='RESUMEN TOTAL'!E12 -> PTP A FO | F9: ='RESUMEN TOTAL'!N12 -> 0 | G9: ='RESUMEN TOTAL'!O12 -> 0 | H9: ='RESUMEN TOTAL'!P12 -> 0 | I9: ='RESUMEN TOTAL'!Q12 -> 0 | J9: ='RESUMEN TOTAL'!R12 -> 0 | K9: ='RESUMEN TOTAL'!S12 -> 0 | L9: ='RESUMEN TOTAL'!T12 -> 0 | M9: ='RESUMEN TOTAL'!U12 -> 0 | ... AG9: ='RESUMEN TOTAL'!AO12 -> 0
A10: ='RESUMEN TOTAL'!A13 -> ALTAMIRA | B10: ='RESUMEN TOTAL'!B13 -> ALT03 | C10: ='RESUMEN TOTAL'!C13 -> Bombero Galarza y Necochea | D10: ='RESUMEN TOTAL'!D13 -> Domo | E10: ='RESUMEN TOTAL'!E13 -> Fibra Optica | F10: ='RESUMEN TOTAL'!N13 -> 0 | G10: ='RESUMEN TOTAL'!O13 -> 0 | H10: ='RESUMEN TOTAL'!P13 -> 0 | I10: ='RESUMEN TOTAL'!Q13 -> 0 | J10: ='RESUMEN TOTAL'!R13 -> 0 | K10: ='RESUMEN TOTAL'!S13 -> 0 | L10: ='RESUMEN TOTAL'!T13 -> 0 | M10: ='RESUMEN TOTAL'!U13 -> 0 | ... AG10: ='RESUMEN TOTAL'!AO13 -> 0
A11: ='RESUMEN TOTAL'!A14 -> 0 | B11: ='RESUMEN TOTAL'!B14 -> ALT04 | C11: ='RESUMEN TOTAL'!C14 -> Francia y Necochea | D11: ='RESUMEN TOTAL'!D14 -> Domo | E11: ='RESUMEN TOTAL'!E14 -> Fibra Optica | F11: ='RESUMEN TOTAL'!N14 -> APAGADO | G11: ='RESUMEN TOTAL'!O14 -> 0 | H11: ='RESUMEN TOTAL'!P14 -> 0 | I11: ='RESUMEN TOTAL'!Q14 -> 0 | J11: ='RESUMEN TOTAL'!R14 -> 0 | K11: ='RESUMEN TOTAL'!S14 -> 0 | L11: ='RESUMEN TOTAL'!T14 -> 0 | M11: ='RESUMEN TOTAL'!U14 -> 0 | ... AG11: ='RESUMEN TOTAL'!AO14 -> 0
A12: ='RESUMEN TOTAL'!A15 -> ALTAMIRA | B12: ='RESUMEN TOTAL'!B15 -> ALT05 | C12: ='RESUMEN TOTAL'!C15 -> Av. Calchaqui y Bombero Galarza | D12: ='RESUMEN TOTAL'!D15 -> Domo | E12: ='RESUMEN TOTAL'!E15 -> PTP A FO | F12: ='RESUMEN TOTAL'!N15 -> 0 | G12: ='RESUMEN TOTAL'!O15 -> 0 | H12: ='RESUMEN TOTAL'!P15 -> 0 | I12: ='RESUMEN TOTAL'!Q15 -> 0 | J12: ='RESUMEN TOTAL'!R15 -> 0 | K12: ='RESUMEN TOTAL'!S15 -> 0 | L12: ='RESUMEN TOTAL'!T15 -> 0 | M12: ='RESUMEN TOTAL'!U15 -> 0 | ... AG12: ='RESUMEN TOTAL'!AO15 -> 0
A13: ='RESUMEN TOTAL'!A16 -> ALTAMIRA | B13: ='RESUMEN TOTAL'!B16 -> ALT07 | C13: ='RESUMEN TOTAL'!C16 -> AV. CALCHAQUI Y AV. DEL TRABAJO | D13: ='RESUMEN TOTAL'!D16 -> DOMO | E13: ='RESUMEN TOTAL'!E16 -> PTP A FO | F13: ='RESUMEN TOTAL'!N16 -> 0 | G13: ='RESUMEN TOTAL'!O16 -> 0 | H13: ='RESUMEN TOTAL'!P16 -> 0 | I13: ='RESUMEN TOTAL'!Q16 -> 0 | J13: ='RESUMEN TOTAL'!R16 -> 0 | K13: ='RESUMEN TOTAL'!S16 -> 0 | L13: ='RESUMEN TOTAL'!T16 -> 0 | M13: ='RESUMEN TOTAL'!U16 -> 0 | ... AG13: ='RESUMEN TOTAL'!AO16 -> 0
... A365: ='RESUMEN TOTAL'!A368 -> 0 | B365: ='RESUMEN TOTAL'!B368 -> ZEB04 | C365: ='RESUMEN TOTAL'!C368 -> THEVENET Y DIAGONAL GRANADEROS | D365: ='RESUMEN TOTAL'!D368 -> DOMO | E365: ='RESUMEN TOTAL'!E368 -> Radio | F365: ='RESUMEN TOTAL'!N368 -> 0 | G365: ='RESUMEN TOTAL'!O368 -> 0 | H365: ='RESUMEN TOTAL'!P368 -> 0 | I365: ='RESUMEN TOTAL'!Q368 -> 0 | J365: ='RESUMEN TOTAL'!R368 -> 0 | K365: ='RESUMEN TOTAL'!S368 -> 0 | L365: ='RESUMEN TOTAL'!T368 -> 0 | M365: ='RESUMEN TOTAL'!U368 -> 0 | ... AG365: ='RESUMEN TOTAL'!AO368 -> 0

Sheet APAGADOS
E1: APAGADOS | F1: =COUNTIF(F3:F366, "APAGADO") -> 62 | G1: =COUNTIF(G3:G366, "APAGADO") -> 80 | H1: =COUNTIF(H3:H366, "APAGADO") -> 77 | I1: =COUNTIF(I3:I366, "APAGADO") -> 70 | J1: =COUNTIF(J3:J366, "APAGADO") -> 70 | K1: =COUNTIF(K3:K366, "APAGADO") -> 0 | L1: =COUNTIF(L3:L366, "APAGADO") -> 0 | M1: =COUNTIF(M3:M366, "APAGADO") -> 0 | ... AG1: =COUNTIF(AG3:AG366, "APAGADO") -> 0
A2: =ESTADISTICA!A1 -> Barrio | B2: =ESTADISTICA!B1 -> [Denominacion] | C2: =ESTADISTICA!C1 -> [Ubicacion] | D2: =ESTADISTICA!D1 -> [Tipo de Camara] | E2: =ESTADISTICA!E1 -> [Tipo de Conexion] | F2: =ESTADISTICA!F1 -> 44621 | G2: =ESTADISTICA!G1 -> 44622 | H2: =ESTADISTICA!H1 -> 44623 | ... AG2: =ESTADISTICA!AG1 -> 44648
A3: =ESTADISTICA!A2 -> PRESIDENTE PERON (PEPSI) | B3: =ESTADISTICA!B2 -> MAR 01 | C3: =ESTADISTICA!C2 -> RP36 Y LA ESMERALDA | D3: =ESTADISTICA!D2 -> DOMO | E3: =ESTADISTICA!E2 -> Fibra Optica | F3: =ESTADISTICA!F2 -> APAGADO | G3: =ESTADISTICA!G2 -> APAGADO | H3: =ESTADISTICA!H2 -> APAGADO | ... AG3: =ESTADISTICA!AG2 -> 0
A4: =ESTADISTICA!A3 -> MAYOL | B4: =ESTADISTICA!B3 -> MAY 01 | C4: =ESTADISTICA!C3 -> Eva Peron y Cabildo | D4: =ESTADISTICA!D3 -> Domo | E4: =ESTADISTICA!E3 -> Radio | F4: =ESTADISTICA!F3 -> 0 | G4: =ESTADISTICA!G3 -> 0 | H4: =ESTADISTICA!H3 -> 0 | ... AG4: =ESTADISTICA!AG3 -> 0
A5: =ESTADISTICA!A4 -> 0 | B5: =ESTADISTICA!B4 -> MAY 02 | C5: =ESTADISTICA!C4 -> EVA PERON Y MONTEVIDEO | D5: =ESTADISTICA!D4 -> Domo | E5: =ESTADISTICA!E4 -> Radio | F5: =ESTADISTICA!F4 -> 0 | G5: =ESTADISTICA!G4 -> 0 | H5: =ESTADISTICA!H4 -> 0 | ... AG5: =ESTADISTICA!AG4 -> 0
A6: =ESTADISTICA!A5 -> MAYOL | B6: =ESTADISTICA!B5 -> MAY 03 | C6: =ESTADISTICA!C5 -> CHAÑAR Y SAN NICOLAS | D6: =ESTADISTICA!D5 -> DOMO | E6: =ESTADISTICA!E5 -> PTP A FO | F6: =ESTADISTICA!F5 -> 0 | G6: =ESTADISTICA!G5 -> 0 | H6: =ESTADISTICA!H5 -> 0 | ... AG6: =ESTADISTICA!AG5 -> 0
A7: =ESTADISTICA!A6 -> 0 | B7: =ESTADISTICA!B6 -> MAY 04 | C7: =ESTADISTICA!C6 -> MAR CHIQUITA Y RIO JACHAL | D7: =ESTADISTICA!D6 -> DOMO | E7: =ESTADISTICA!E6 -> Radio | F7: =ESTADISTICA!F6 -> 0 | G7: =ESTADISTICA!G6 -> 0 | H7: =ESTADISTICA!H6 -> 0 | ... AG7: =ESTADISTICA!AG6 -> 0
A8: =ESTADISTICA!A7 -> ALTAMIRA | B8: =ESTADISTICA!B7 -> ALT06 | C8: =ESTADISTICA!C7 -> LOPE DE VEGA Y NECOCHEA | D8: =ESTADISTICA!D7 -> Domo | E8: =ESTADISTICA!E7 -> PTP A FO | F8: =ESTADISTICA!F7 -> 0 | G8: =ESTADISTICA!G7 -> 0 | H8: =ESTADISTICA!H7 -> 0 | ... AG8: =ESTADISTICA!AG7 -> 0
A9: =ESTADISTICA!A8 -> ALTAMIRA | B9: =ESTADISTICA!B8 -> ALT01 | C9: =ESTADISTICA!C8 -> Calchaqui y Sgto. Cabral | D9: =ESTADISTICA!D8 -> Domo | E9: =ESTADISTICA!E8 -> Fibra Optica | F9: =ESTADISTICA!F8 -> 0 | G9: =ESTADISTICA!G8 -> 0 | H9: =ESTADISTICA!H8 -> 0 | ... AG9: =ESTADISTICA!AG8 -> 0
A10: =ESTADISTICA!A9 -> ALTAMIRA | B10: =ESTADISTICA!B9 -> ALT02 | C10: =ESTADISTICA!C9 -> Calchaqui y Lope de Vega | D10: =ESTADISTICA!D9 -> Domo | E10: =ESTADISTICA!E9 -> PTP A FO | F10: =ESTADISTICA!F9 -> 0 | G10: =ESTADISTICA!G9 -> 0 | H10: =ESTADISTICA!H9 -> 0 | ... AG10: =ESTADISTICA!AG9 -> 0
A11: =ESTADISTICA!A10 -> ALTAMIRA | B11: =ESTADISTICA!B10 -> ALT03 | C11: =ESTADISTICA!C10 -> Bombero Galarza y Necochea | D11: =ESTADISTICA!D10 -> Domo | E11: =ESTADISTICA!E10 -> Fibra Optica | F11: =ESTADISTICA!F10 -> 0 | G11: =ESTADISTICA!G10 -> 0 | H11: =ESTADISTICA!H10 -> 0 | ... AG11: =ESTADISTICA!AG10 -> 0
A12: =ESTADISTICA!A11 -> 0 | B12: =ESTADISTICA!B11 -> ALT04 | C12: =ESTADISTICA!C11 -> Francia y Necochea | D12: =ESTADISTICA!D11 -> Domo | E12: =ESTADISTICA!E11 -> Fibra Optica | F12: =ESTADISTICA!F11 -> APAGADO | G12: =ESTADISTICA!G11 -> 0 | H12: =ESTADISTICA!H11 -> 0 | ... AG12: =ESTADISTICA!AG11 -> 0
A13: =ESTADISTICA!A12 -> ALTAMIRA | B13: =ESTADISTICA!B12 -> ALT05 | C13: =ESTADISTICA!C12 -> Av. Calchaqui y Bombero Galarza | D13: =ESTADISTICA!D12 -> Domo | E13: =ESTADISTICA!E12 -> PTP A FO | F13: =ESTADISTICA!F12 -> 0 | G13: =ESTADISTICA!G12 -> 0 | H13: =ESTADISTICA!H12 -> 0 | ... AG13: =ESTADISTICA!AG12 -> 0
... A366: =ESTADISTICA!A365 -> 0 | B366: =ESTADISTICA!B365 -> ZEB04 | C366: =ESTADISTICA!C365 -> THEVENET Y DIAGONAL GRANADEROS | D366: =ESTADISTICA!D365 -> DOMO | E366: =ESTADISTICA!E365 -> Radio | F366: =ESTADISTICA!F365 -> 0 | G366: =ESTADISTICA!G365 -> 0 | H366: =ESTADISTICA!H365 -> 0 | ... AG366: =ESTADISTICA!AG365 -> 0

Sheet APAGADOS FIBRA
E1: APAGADOS | F1: =COUNTIFS(F3:F366, "=APAGADO",E3:E366,"=Fibra Optica") -> 52 | G1: =COUNTIFS(G3:G366, "=APAGADO",E3:E366,"=Fibra Optica") -> 69 | H1: =COUNTIFS(H3:H366, "=APAGADO",E3:E366,"=Fibra Optica") -> 66 | I1: =COUNTIFS(I3:I366, "=APAGADO",E3:E366,"=Fibra Optica") -> 60 | J1: =COUNTIFS(J3:J366, "=APAGADO",E3:E366,"=Fibra Optica") -> 56 | K1: =COUNTIFS(K3:K366, "=APAGADO",E3:E366,"=Fibra Optica") -> 0 | L1: =COUNTIFS(L3:L366, "=APAGADO",E3:E366,"=Fibra Optica") -> 0 | M1: =COUNTIFS(M3:M366, "=APAGADO",E3:E366,"=Fibra Optica") -> 0 | N1: =COUNTIFS(N3:N366, "=APAGADO",E3:E366,"=Fibra Optica") -> 0 | O1: =COUNTIFS(O3:O366, "=APAGADO",E3:E366,"=Fibra Optica") -> 0 | P1: =COUNTIFS(P3:P366, "=APAGADO",E3:E366,"=Fibra Optica") -> 0 | Q1: =COUNTIFS(Q3:Q366, "=APAGADO",E3:E366,"=Fibra Optica") -> 0 | R1: =COUNTIFS(R3:R366, "=APAGADO",E3:E366,"=Fibra Optica") -> 0 | S1: =COUNTIFS(S3:S366, "=APAGADO",E3:E366,"=Fibra Optica") -> 0 | T1: =COUNTIFS(T3:T366, "=APAGADO",E3:E366,"=Fibra Optica") -> 0 | U1: =COUNTIFS(U3:U366, "=APAGADO",E3:E366,"=Fibra Optica") -> 0 | V1: =COUNTIFS(V3:V366, "=APAGADO",E3:E366,"=Fibra Optica") -> 0 | W1: =COUNTIFS(W3:W366, "=APAGADO",E3:E366,"=Fibra Optica") -> 0 | X1: =COUNTIFS(X3:X366, "=APAGADO",E3:E366,"=Fibra Optica") -> 0 | Y1: =COUNTIFS(Y3:Y366, "=APAGADO",E3:E366,"=Fibra Optica") -> 0 | Z1: =COUNTIFS(Z3:Z366, "=APAGADO",E3:E366,"=Fibra Optica") -> 0 | AA1: =COUNTIFS(AA3:AA366, "=APAGADO",E3:E366,"=Fibra Optica") -> 0 | AB1: =COUNTIFS(AB3:AB366, "=APAGADO",E3:E366,"=Fibra Optica") -> 0 | AC1: =COUNTIFS(AC3:AC366, "=APAGADO",E3:E366,"=Fibra Optica") -> 0 | AD1: =COUNTIFS(AD3:AD366, "=APAGADO",AC3:AC366,"=Fibra Optica") -> 0 | AE1: =COUNTIFS(AE3:AE366, "=APAGADO",AC3:AC366,"=Fibra Optica") -> 0 | AF1: =COUNTIFS(AF3:AF366, "=APAGADO",AC3:AC366,"=Fibra Optica") -> 0 | AG1: =COUNTIFS(AG3:AG366, "=APAGADO",AC3:AC366,"=Fibra Optica") -> 0 | AH1: =COUNTIFS(AH3:AH366, "=APAGADO",AD3:AD366,"=Fibra Optica") -> 0 | AI1: =COUNTIFS(AI3:AI366, "=APAGADO",AE3:AE366,"=Fibra Optica") -> 0 | AJ1: =COUNTIFS(AJ3:AJ366, "=APAGADO",AF3:AF366,"=Fibra Optica") -> 0
A2: =ESTADISTICA!A1 -> Barrio | B2: =ESTADISTICA!B1 -> [Denominacion] | C2: =ESTADISTICA!C1 -> [Ubicacion] | D2: =ESTADISTICA!D1 -> [Tipo de Camara] | E2: =ESTADISTICA!E1 -> [Tipo de Conexion] | F2: =ESTADISTICA!F1 -> 44621 | G2: =ESTADISTICA!G1 -> 44622 | H2: =ESTADISTICA!H1 -> 44623 | ... AJ2: =ESTADISTICA!AJ1 -> 44651
A3: =ESTADISTICA!A2 -> PRESIDENTE PERON (PEPSI) | B3: =ESTADISTICA!B2 -> MAR 01 | C3: =ESTADISTICA!C2 -> RP36 Y LA ESMERALDA | D3: =ESTADISTICA!D2 -> DOMO | E3: =ESTADISTICA!E2 -> Fibra Optica | F3: =ESTADISTICA!F2 -> APAGADO | G3: =ESTADISTICA!G2 -> APAGADO | H3: =ESTADISTICA!H2 -> APAGADO | ... AG3: =ESTADISTICA!AG2 -> 0
A4: =ESTADISTICA!A3 -> MAYOL | B4: =ESTADISTICA!B3 -> MAY 01 | C4: =ESTADISTICA!C3 -> Eva Peron y Cabildo | D4: =ESTADISTICA!D3 -> Domo | E4: =ESTADISTICA!E3 -> Radio | F4: =ESTADISTICA!F3 -> 0 | G4: =ESTADISTICA!G3 -> 0 | H4: =ESTADISTICA!H3 -> 0 | ... AG4: =ESTADISTICA!AG3 -> 0
A5: =ESTADISTICA!A4 -> 0 | B5: =ESTADISTICA!B4 -> MAY 02 | C5: =ESTADISTICA!C4 -> EVA PERON Y MONTEVIDEO | D5: =ESTADISTICA!D4 -> Domo | E5: =ESTADISTICA!E4 -> Radio | F5: =ESTADISTICA!F4 -> 0 | G5: =ESTADISTICA!G4 -> 0 | H5: =ESTADISTICA!H4 -> 0 | ... AG5: =ESTADISTICA!AG4 -> 0
A6: =ESTADISTICA!A5 -> MAYOL | B6: =ESTADISTICA!B5 -> MAY 03 | C6: =ESTADISTICA!C5 -> CHAÑAR Y SAN NICOLAS | D6: =ESTADISTICA!D5 -> DOMO | E6: =ESTADISTICA!E5 -> PTP A FO | F6: =ESTADISTICA!F5 -> 0 | G6: =ESTADISTICA!G5 -> 0 | H6: =ESTADISTICA!H5 -> 0 | ... AG6: =ESTADISTICA!AG5 -> 0
A7: =ESTADISTICA!A6 -> 0 | B7: =ESTADISTICA!B6 -> MAY 04 | C7: =ESTADISTICA!C6 -> MAR CHIQUITA Y RIO JACHAL | D7: =ESTADISTICA!D6 -> DOMO | E7: =ESTADISTICA!E6 -> Radio | F7: =ESTADISTICA!F6 -> 0 | G7: =ESTADISTICA!G6 -> 0 | H7: =ESTADISTICA!H6 -> 0 | ... AG7: =ESTADISTICA!AG6 -> 0
A8: =ESTADISTICA!A7 -> ALTAMIRA | B8: =ESTADISTICA!B7 -> ALT06 | C8: =ESTADISTICA!C7 -> LOPE DE VEGA Y NECOCHEA | D8: =ESTADISTICA!D7 -> Domo | E8: =ESTADISTICA!E7 -> PTP A FO | F8: =ESTADISTICA!F7 -> 0 | G8: =ESTADISTICA!G7 -> 0 | H8: =ESTADISTICA!H7 -> 0 | ... AG8: =ESTADISTICA!AG7 -> 0
A9: =ESTADISTICA!A8 -> ALTAMIRA | B9: =ESTADISTICA!B8 -> ALT01 | C9: =ESTADISTICA!C8 -> Calchaqui y Sgto. Cabral | D9: =ESTADISTICA!D8 -> Domo | E9: =ESTADISTICA!E8 -> Fibra Optica | F9: =ESTADISTICA!F8 -> 0 | G9: =ESTADISTICA!G8 -> 0 | H9: =ESTADISTICA!H8 -> 0 | ... AG9: =ESTADISTICA!AG8 -> 0
A10: =ESTADISTICA!A9 -> ALTAMIRA | B10: =ESTADISTICA!B9 -> ALT02 | C10: =ESTADISTICA!C9 -> Calchaqui y Lope de Vega | D10: =ESTADISTICA!D9 -> Domo | E10: =ESTADISTICA!E9 -> PTP A FO | F10: =ESTADISTICA!F9 -> 0 | G10: =ESTADISTICA!G9 -> 0 | H10: =ESTADISTICA!H9 -> 0 | ... AG10: =ESTADISTICA!AG9 -> 0
A11: =ESTADISTICA!A10 -> ALTAMIRA | B11: =ESTADISTICA!B10 -> ALT03 | C11: =ESTADISTICA!C10 -> Bombero Galarza y Necochea | D11: =ESTADISTICA!D10 -> Domo | E11: =ESTADISTICA!E10 -> Fibra Optica | F11: =ESTADISTICA!F10 -> 0 | G11: =ESTADISTICA!G10 -> 0 | H11: =ESTADISTICA!H10 -> 0 | ... AG11: =ESTADISTICA!AG10 -> 0
A12: =ESTADISTICA!A11 -> 0 | B12: =ESTADISTICA!B11 -> ALT04 | C12: =ESTADISTICA!C11 -> Francia y Necochea | D12: =ESTADISTICA!D11 -> Domo | E12: =ESTADISTICA!E11 -> Fibra Optica | F12: =ESTADISTICA!F11 -> APAGADO | G12: =ESTADISTICA!G11 -> 0 | H12: =ESTADISTICA!H11 -> 0 | ... AG12: =ESTADISTICA!AG11 -> 0
A13: =ESTADISTICA!A12 -> ALTAMIRA | B13: =ESTADISTICA!B12 -> ALT05 | C13: =ESTADISTICA!C12 -> Av. Calchaqui y Bombero Galarza | D13: =ESTADISTICA!D12 -> Domo | E13: =ESTADISTICA!E12 -> PTP A FO | F13: =ESTADISTICA!F12 -> 0 | G13: =ESTADISTICA!G12 -> 0 | H13: =ESTADISTICA!H12 -> 0 | ... AG13: =ESTADISTICA!AG12 -> 0
A14: =ESTADISTICA!A13 -> ALTAMIRA | B14: =ESTADISTICA!B13 -> ALT07 | C14: =ESTADISTICA!C13 -> AV. CALCHAQUI Y AV. DEL TRABAJO | D14: =ESTADISTICA!D13 -> DOMO | E14: =ESTADISTICA!E13 -> PTP A FO | F14: =ESTADISTICA!F13 -> 0 | G14: =ESTADISTICA!G13 -> 0 | H14: =ESTADISTICA!H13 -> 0 | ... AG14: =ESTADISTICA!AG13 -> 0
... A366: =ESTADISTICA!A365 -> 0 | B366: =ESTADISTICA!B365 -> ZEB04 | C366: =ESTADISTICA!C365 -> THEVENET Y DIAGONAL GRANADEROS | D366: =ESTADISTICA!D365 -> DOMO | E366: =ESTADISTICA!E365 -> Radio | F366: =ESTADISTICA!F365 -> 0 | G366: =ESTADISTICA!G365 -> 0 | H366: =ESTADISTICA!H365 -> 0 | ... AG366: =ESTADISTICA!AG365 -> 0

Sheet APAGADOS ANTENA
E1: APAGADOS | F1: =COUNTIFS(F3:F366, "=APAGADO",E3:E366,"=PTP A FO") -> 2 | G1: =COUNTIFS(G3:G366, "=APAGADO",E3:E366,"=PTP A FO") -> 4 | H1: =COUNTIFS(H3:H366, "=APAGADO",E3:E366,"=PTP A FO") -> 3 | I1: =COUNTIFS(I3:I366, "=APAGADO",E3:E366,"=PTP A FO") -> 1 | J1: =COUNTIFS(J3:J366, "=APAGADO",E3:E366,"=PTP A FO") -> 4 | K1: =COUNTIFS(K3:K366, "=APAGADO",E3:E366,"=PTP A FO") -> 0 | L1: =COUNTIFS(L3:L366, "=APAGADO",E3:E366,"=PTP A FO") -> 0 | M1: =COUNTIFS(M3:M366, "=APAGADO",E3:E366,"=PTP A FO") -> 0 | N1: =COUNTIFS(N3:N366, "=APAGADO",E3:E366,"=PTP A FO") -> 0 | O1: =COUNTIFS(O3:O366,"APAGADO", E3:E366,"=PTP A FO" ) -> 0 | P1: =COUNTIFS(P3:P366, "=APAGADO",E3:E366,"=PTP A FO") -> 0 | Q1: =COUNTIFS(Q3:Q366, "=APAGADO",E3:E366,"=PTP A FO") -> 0 | R1: =COUNTIFS(R3:R366, "=APAGADO",E3:E366,"=PTP A FO") -> 0 | S1: =COUNTIFS(S3:S366, "=APAGADO",E3:E366,"=PTP A FO") -> 0 | T1: =COUNTIFS(T3:T366, "=APAGADO",E3:E366,"=PTP A FO") -> 0 | U1: =COUNTIFS(U3:U366, "=APAGADO",E3:E366,"=PTP A FO") -> 0 | V1: =COUNTIFS(V3:V366, "=APAGADO",E3:E366,"=PTP A FO") -> 0 | W1: =COUNTIFS(W3:W366, "=APAGADO",E3:E366,"=PTP A FO") -> 0 | X1: =COUNTIFS(X3:X366, "=APAGADO",E3:E366,"=PTP A FO") -> 0 | Y1: =COUNTIFS(Y3:Y366, "=APAGADO",E3:E366,"=PTP A FO") -> 0 | Z1: =COUNTIFS(Z3:Z366, "=APAGADO",E3:E366,"=PTP A FO") -> 0 | AA1: =COUNTIFS(AA3:AA366, "=APAGADO",E3:E366,"=PTP A FO") -> 0 | AB1: =COUNTIFS(AB3:AB366, "=APAGADO",E3:E366,"=PTP A FO") -> 0 | AC1: =COUNTIFS(AC3:AC366, "=APAGADO",E3:E366,"=PTP A FO") -> 0 | AD1: =COUNTIFS(AD3:AD366, "=APAGADO",E3:E366,"=PTP A FO") -> 0 | AE1: =COUNTIFS(AE3:AE366, "=APAGADO",E3:E366,"=PTP A FO") -> 0 | AF1: =COUNTIFS(AF3:AF366, "=APAGADO",E3:E366,"=PTP A FO") -> 0 | AG1: =COUNTIFS(AG3:AG366, "=APAGADO",E3:E366,"=PTP A FO") -> 0 | AH1: =COUNTIFS(AH3:AH366, "=APAGADO",F3:F366,"=PTP A FO") -> 0 | AI1: =COUNTIFS(AI3:AI366, "=APAGADO",G3:G366,"=PTP A FO") -> 0 | AJ1: =COUNTIFS(AJ3:AJ366, "=APAGADO",H3:H366,"=PTP A FO") -> 0
A2: =ESTADISTICA!A1 -> Barrio | B2: =ESTADISTICA!B1 -> [Denominacion] | C2: =ESTADISTICA!C1 -> [Ubicacion] | D2: =ESTADISTICA!D1 -> [Tipo de Camara] | E2: =ESTADISTICA!E1 -> [Tipo de Conexion] | F2: =ESTADISTICA!F1 -> 44621 | G2: =ESTADISTICA!G1 -> 44622 | H2: =ESTADISTICA!H1 -> 44623 | ... AJ2: =ESTADISTICA!AJ1 -> 44651
A3: =ESTADISTICA!A2 -> PRESIDENTE PERON (PEPSI) | B3: =ESTADISTICA!B2 -> MAR 01 | C3: =ESTADISTICA!C2 -> RP36 Y LA ESMERALDA | D3: =ESTADISTICA!D2 -> DOMO | E3: =ESTADISTICA!E2 -> Fibra Optica | F3: =ESTADISTICA!F2 -> APAGADO | G3: =ESTADISTICA!G2 -> APAGADO | H3: =ESTADISTICA!H2 -> APAGADO | ... AG3: =ESTADISTICA!AG2 -> 0
A4: =ESTADISTICA!A3 -> MAYOL | B4: =ESTADISTICA!B3 -> MAY 01 | C4: =ESTADISTICA!C3 -> Eva Peron y Cabildo | D4: =ESTADISTICA!D3 -> Domo | E4: =ESTADISTICA!E3 -> Radio | F4: =ESTADISTICA!F3 -> 0 | G4: =ESTADISTICA!G3 -> 0 | H4: =ESTADISTICA!H3 -> 0 | ... AG4: =ESTADISTICA!AG3 -> 0
A5: =ESTADISTICA!A4 -> 0 | B5: =ESTADISTICA!B4 -> MAY 02 | C5: =ESTADISTICA!C4 -> EVA PERON Y MONTEVIDEO | D5: =ESTADISTICA!D4 -> Domo | E5: =ESTADISTICA!E4 -> Radio | F5: =ESTADISTICA!F4 -> 0 | G5: =ESTADISTICA!G4 -> 0 | H5: =ESTADISTICA!H4 -> 0 | ... AG5: =ESTADISTICA!AG4 -> 0
A6: =ESTADISTICA!A5 -> MAYOL | B6: =ESTADISTICA!B5 -> MAY 03 | C6: =ESTADISTICA!C5 -> CHAÑAR Y SAN NICOLAS | D6: =ESTADISTICA!D5 -> DOMO | E6: =ESTADISTICA!E5 -> PTP A FO | F6: =ESTADISTICA!F5 -> 0 | G6: =ESTADISTICA!G5 -> 0 | H6: =ESTADISTICA!H5 -> 0 | ... AG6: =ESTADISTICA!AG5 -> 0
A7: =ESTADISTICA!A6 -> 0 | B7: =ESTADISTICA!B6 -> MAY 04 | C7: =ESTADISTICA!C6 -> MAR CHIQUITA Y RIO JACHAL | D7: =ESTADISTICA!D6 -> DOMO | E7: =ESTADISTICA!E6 -> Radio | F7: =ESTADISTICA!F6 -> 0 | G7: =ESTADISTICA!G6 -> 0 | H7: =ESTADISTICA!H6 -> 0 | ... AG7: =ESTADISTICA!AG6 -> 0
A8: =ESTADISTICA!A7 -> ALTAMIRA | B8: =ESTADISTICA!B7 -> ALT06 | C8: =ESTADISTICA!C7 -> LOPE DE VEGA Y NECOCHEA | D8: =ESTADISTICA!D7 -> Domo | E8: =ESTADISTICA!E7 -> PTP A FO | F8: =ESTADISTICA!F7 -> 0 | G8: =ESTADISTICA!G7 -> 0 | H8: =ESTADISTICA!H7 -> 0 | ... AG8: =ESTADISTICA!AG7 -> 0
A9: =ESTADISTICA!A8 -> ALTAMIRA | B9: =ESTADISTICA!B8 -> ALT01 | C9: =ESTADISTICA!C8 -> Calchaqui y Sgto. Cabral | D9: =ESTADISTICA!D8 -> Domo | E9: =ESTADISTICA!E8 -> Fibra Optica | F9: =ESTADISTICA!F8 -> 0 | G9: =ESTADISTICA!G8 -> 0 | H9: =ESTADISTICA!H8 -> 0 | ... AG9: =ESTADISTICA!AG8 -> 0
A10: =ESTADISTICA!A9 -> ALTAMIRA | B10: =ESTADISTICA!B9 -> ALT02 | C10: =ESTADISTICA!C9 -> Calchaqui y Lope de Vega | D10: =ESTADISTICA!D9 -> Domo | E10: =ESTADISTICA!E9 -> PTP A FO | F10: =ESTADISTICA!F9 -> 0 | G10: =ESTADISTICA!G9 -> 0 | H10: =ESTADISTICA!H9 -> 0 | ... AG10: =ESTADISTICA!AG9 -> 0
A11: =ESTADISTICA!A10 -> ALTAMIRA | B11: =ESTADISTICA!B10 -> ALT03 | C11: =ESTADISTICA!C10 -> Bombero Galarza y Necochea | D11: =ESTADISTICA!D10 -> Domo | E11: =ESTADISTICA!E10 -> Fibra Optica | F11: =ESTADISTICA!F10 -> 0 | G11: =ESTADISTICA!G10 -> 0 | H11: =ESTADISTICA!H10 -> 0 | ... AG11: =ESTADISTICA!AG10 -> 0
A12: =ESTADISTICA!A11 -> 0 | B12: =ESTADISTICA!B11 -> ALT04 | C12: =ESTADISTICA!C11 -> Francia y Necochea | D12: =ESTADISTICA!D11 -> Domo | E12: =ESTADISTICA!E11 -> Fibra Optica | F12: =ESTADISTICA!F11 -> APAGADO | G12: =ESTADISTICA!G11 -> 0 | H12: =ESTADISTICA!H11 -> 0 | ... AG12: =ESTADISTICA!AG11 -> 0
A13: =ESTADISTICA!A12 -> ALTAMIRA | B13: =ESTADISTICA!B12 -> ALT05 | C13: =ESTADISTICA!C12 -> Av. Calchaqui y Bombero Galarza | D13: =ESTADISTICA!D12 -> Domo | E13: =ESTADISTICA!E12 -> PTP A FO | F13: =ESTADISTICA!F12 -> 0 | G13: =ESTADISTICA!G12 -> 0 | H13: =ESTADISTICA!H12 -> 0 | ... AG13: =ESTADISTICA!AG12 -> 0
A14: =ESTADISTICA!A13 -> ALTAMIRA | B14: =ESTADISTICA!B13 -> ALT07 | C14: =ESTADISTICA!C13 -> AV. CALCHAQUI Y AV. DEL TRABAJO | D14: =ESTADISTICA!D13 -> DOMO | E14: =ESTADISTICA!E13 -> PTP A FO | F14: =ESTADISTICA!F13 -> 0 | G14: =ESTADISTICA!G13 -> 0 | H14: =ESTADISTICA!H13 -> 0 | ... AG14: =ESTADISTICA!AG13 -> 0
... A277: =ESTADISTICA!A276 -> ZONA RURAL SANTA ROSA | B277: =ESTADISTICA!B276 -> SRO13 (fija 1) | C277: =ESTADISTICA!C276 -> BRUSELAS E/ GRECIA Y CHECOSLOVAQUIA | D277: =ESTADISTICA!D276 -> Fija | E277: =ESTADISTICA!E276 -> RADIO | F277: =ESTADISTICA!F276 -> 0 | G277: =ESTADISTICA!G276 -> 0 | H277: =ESTADISTICA!H276 -> 0 | ... AG277: =ESTADISTICA!AG276 -> 0
B278: =ESTADISTICA!B277 -> SRO14 (fija 2) | C278: =ESTADISTICA!C277 -> BRUSELAS E/ GRECIA Y CHECOSLOVAQUIA | D278: =ESTADISTICA!D277 -> Fija | E278: =ESTADISTICA!E277 -> RADIO | F278: =ESTADISTICA!F277 -> APAGADO | G278: =ESTADISTICA!G277 -> APAGADO | H278: =ESTADISTICA!H277 -> APAGADO | I278: =ESTADISTICA!I277 -> APAGADO | ... AG278: =ESTADISTICA!AG277 -> 0
A279: =ESTADISTICA!A278 -> SANTA ROSA | B279: =ESTADISTICA!B278 -> SRO15 | C279: =ESTADISTICA!C278 -> NOVAK Y TIRANA (614) | D279: =ESTADISTICA!D278 -> DOMO | E279: =ESTADISTICA!E278 -> Fibra Optica | F279: =ESTADISTICA!F278 -> 0 | G279: =ESTADISTICA!G278 -> 0 | H279: =ESTADISTICA!H278 -> 0 | ... AG279: =ESTADISTICA!AG278 -> 0
A280: =ESTADISTICA!A279 -> SANTA ROSA | B280: =ESTADISTICA!B279 -> SRO18 (fija 1) | C280: =ESTADISTICA!C279 -> GRAN CANARIA Y BUDAPEST | D280: =ESTADISTICA!D279 -> Fija | E280: =ESTADISTICA!E279 -> Fibra Optica | F280: =ESTADISTICA!F279 -> 0 | G280: =ESTADISTICA!G279 -> 0 | H280: =ESTADISTICA!H279 -> 0 | ... AG280: =ESTADISTICA!AG279 -> 0
A281: =ESTADISTICA!A280 -> SANTA ROSA | B281: =ESTADISTICA!B280 -> SRO19 (fija 2) | C281: =ESTADISTICA!C280 -> GRAN CANARIA Y BUDAPEST | D281: =ESTADISTICA!D280 -> Fija | E281: =ESTADISTICA!E280 -> Fibra Optica | F281: =ESTADISTICA!F280 -> 0 | G281: =ESTADISTICA!G280 -> 0 | H281: =ESTADISTICA!H280 -> 0 | ... AG281: =ESTADISTICA!AG280 -> 0
A282: =ESTADISTICA!A281 -> SAN RUDECINDO | B282: =ESTADISTICA!B281 -> SRU01 (fija 1) | C282: =ESTADISTICA!C281 -> HERNANDARIAS Y AMBATO | D282: =ESTADISTICA!D281 -> Fija | E282: =ESTADISTICA!E281 -> Fibra Optica | F282: =ESTADISTICA!F281 -> 0 | G282: =ESTADISTICA!G281 -> 0 | H282: =ESTADISTICA!H281 -> 0 | ... AG282: =ESTADISTICA!AG281 -> 0
A283: =ESTADISTICA!A282 -> SAN RUDECINDO | B283: =ESTADISTICA!B282 -> SRU02 (fija 2) | C283: =ESTADISTICA!C282 -> HERNANDARIAS Y AMBATO | D283: =ESTADISTICA!D282 -> Fija | E283: =ESTADISTICA!E282 -> Fibra Optica | F283: =ESTADISTICA!F282 -> 0 | G283: =ESTADISTICA!G282 -> 0 | H283: =ESTADISTICA!H282 -> 0 | ... AG283: =ESTADISTICA!AG282 -> 0
A284: =ESTADISTICA!A283 -> VILLA ANGELICA | B284: =ESTADISTICA!B283 -> VANG01 | C284: =ESTADISTICA!C283 -> Senzabello y Necochea | D284: =ESTADISTICA!D283 -> Domo | E284: =ESTADISTICA!E283 -> PTP A FO | F284: =ESTADISTICA!F283 -> 0 | G284: =ESTADISTICA!G283 -> 0 | H284: =ESTADISTICA!H283 -> 0 | ... AG284: =ESTADISTICA!AG283 -> 0
A285: =ESTADISTICA!A284 -> VILLA ANGELICA | B285: =ESTADISTICA!B284 -> VANG02 | C285: =ESTADISTICA!C284 -> Thevenet y Ruta 36 | D285: =ESTADISTICA!D284 -> Domo | E285: =ESTADISTICA!E284 -> Fibra Optica | F285: =ESTADISTICA!F284 -> 0 | G285: =ESTADISTICA!G284 -> 0 | H285: =ESTADISTICA!H284 -> 0 | ... AG285: =ESTADISTICA!AG284 -> 0
A286: =ESTADISTICA!A285 -> VILLA DEL PLATA | B286: =ESTADISTICA!B285 -> VANG03 | C286: =ESTADISTICA!C285 -> Thevenet 1950 | D286: =ESTADISTICA!D285 -> Domo | E286: =ESTADISTICA!E285 -> Fibra Optica | F286: =ESTADISTICA!F285 -> 0 | G286: =ESTADISTICA!G285 -> 0 | H286: =ESTADISTICA!H285 -> 0 | ... AG286: =ESTADISTICA!AG285 -> 0
A287: =ESTADISTICA!A286 -> VILLA ANGELICA | B287: =ESTADISTICA!B286 -> VANG04 | C287: =ESTADISTICA!C286 -> Storni e/Thevenet y Calle 158 | D287: =ESTADISTICA!D286 -> DOMO | E287: =ESTADISTICA!E286 -> Fibra Optica | F287: =ESTADISTICA!F286 -> 0 | G287: =ESTADISTICA!G286 -> 0 | H287: =ESTADISTICA!H286 -> 0 | ... AG287: =ESTADISTICA!AG286 -> 0
A288: =ESTADISTICA!A287 -> VILLA ANGELICA | B288: =ESTADISTICA!B287 -> VANG05 | C288: =ESTADISTICA!C287 -> Storni y Thevenet | D288: =ESTADISTICA!D287 -> Domo | E288: =ESTADISTICA!E287 -> Fibra Optica | F288: =ESTADISTICA!F287 -> 0 | G288: =ESTADISTICA!G287 -> 0 | H288: =ESTADISTICA!H287 -> 0 | ... AG288: =ESTADISTICA!AG287 -> 0
A289: =ESTADISTICA!A288 -> VILLA ANGELICA | B289: =ESTADISTICA!B288 -> VANG06 | C289: =ESTADISTICA!C288 -> Arenales e/Thevenet y Calle 158 | D289: =ESTADISTICA!D288 -> DOMO | E289: =ESTADISTICA!E288 -> Fibra Optica | F289: =ESTADISTICA!F288 -> 0 | G289: =ESTADISTICA!G288 -> 0 | H289: =ESTADISTICA!H288 -> 0 | ... AG289: =ESTADISTICA!AG288 -> 0
A290: =ESTADISTICA!A289 -> VILLA ANGELICA | B290: =ESTADISTICA!B289 -> VANG07 | C290: =ESTADISTICA!C289 -> Arenales y Thevenet | D290: =ESTADISTICA!D289 -> Domo | E290: =ESTADISTICA!E289 -> Fibra Optica | F290: =ESTADISTICA!F289 -> 0 | G290: =ESTADISTICA!G289 -> 0 | H290: =ESTADISTICA!H289 -> 0 | ... AG290: =ESTADISTICA!AG289 -> 0
... A366: =ESTADISTICA!A365 -> 0 | B366: =ESTADISTICA!B365 -> ZEB04 | C366: =ESTADISTICA!C365 -> THEVENET Y DIAGONAL GRANADEROS | D366: =ESTADISTICA!D365 -> DOMO | E366: =ESTADISTICA!E365 -> Radio | F366: =ESTADISTICA!F365 -> 0 | G366: =ESTADISTICA!G365 -> 0 | H366: =ESTADISTICA!H365 -> 0 | ... AG366: =ESTADISTICA!AG365 -> 0

Sheet APAGADOS RADIO
E1: APAGADOS | F1: =COUNTIFS(F3:F366, "=APAGADO",E3:E366,"=radio") -> 8 | G1: =COUNTIFS(G3:G366, "=APAGADO",E3:E366,"=radio") -> 7 | H1: =COUNTIFS(H3:H366, "=APAGADO",E3:E366,"=radio") -> 8 | I1: =COUNTIFS(I3:I366, "=APAGADO",E3:E366,"=radio") -> 9 | J1: =COUNTIFS(J3:J366, "=APAGADO",E3:E366,"=radio") -> 9 | K1: =COUNTIFS(K3:K366, "=APAGADO",E3:E366,"=radio") -> 0 | L1: =COUNTIFS(L3:L366, "=APAGADO",E3:E366,"=radio") -> 0 | M1: =COUNTIFS(M3:M366, "=APAGADO",E3:E366,"=radio") -> 0 | N1: =COUNTIFS(N3:N366, "=APAGADO",E3:E366,"=radio") -> 0 | O1: =COUNTIFS(O3:O366, "=APAGADO",E3:E366,"=radio",E3:E366,"=PTP A FO" ) -> 0 | P1: =COUNTIFS(P3:P366, "=APAGADO",E3:E366,"=radio") -> 0 | Q1: =COUNTIFS(Q3:Q366, "=APAGADO",E3:E366,"=radio") -> 0 | R1: =COUNTIFS(R3:R366, "=APAGADO",E3:E366,"=radio") -> 0 | S1: =COUNTIFS(S3:S366, "=APAGADO",E3:E366,"=radio") -> 0 | T1: =COUNTIFS(T3:T366, "=APAGADO",E3:E366,"=radio") -> 0 | U1: =COUNTIFS(U3:U366, "=APAGADO",E3:E366,"=radio") -> 0 | V1: =COUNTIFS(V3:V366, "=APAGADO",E3:E366,"=radio") -> 0 | W1: =COUNTIFS(W3:W366, "=APAGADO",E3:E366,"=radio") -> 0 | X1: =COUNTIFS(X3:X366, "=APAGADO",E3:E366,"=radio") -> 0 | Y1: =COUNTIFS(Y3:Y366, "=APAGADO",E3:E366,"=radio") -> 0 | Z1: =COUNTIFS(Z3:Z366, "=APAGADO",E3:E366,"=radio") -> 0 | AA1: =COUNTIFS(AA3:AA366, "=APAGADO",E3:E366,"=radio") -> 0 | AB1: =COUNTIFS(AB3:AB366, "=APAGADO",E3:E366,"=radio") -> 0 | AC1: =COUNTIFS(AC3:AC366, "=APAGADO",E3:E366,"=radio") -> 0 | AD1: =COUNTIFS(AD3:AD366, "=APAGADO",E3:E366,"=radio") -> 0 | AE1: =COUNTIFS(AE3:AE366, "=APAGADO",E3:E366,"=radio") -> 0 | AF1: =COUNTIFS(AF3:AF366, "=APAGADO",E3:E366,"=radio") -> 0 | AG1: =COUNTIFS(AG3:AG366, "=APAGADO",E3:E366,"=radio") -> 0 | AH1: =COUNTIFS(AH3:AH366, "=APAGADO",F3:F366,"=radio") -> 0 | AI1: =COUNTIFS(AI3:AI366, "=APAGADO",G3:G366,"=radio") -> 0 | AJ1: =COUNTIFS(AJ3:AJ366, "=APAGADO",H3:H366,"=radio") -> 0
A2: =ESTADISTICA!A1 -> Barrio | B2: =ESTADISTICA!B1 -> [Denominacion] | C2: =ESTADISTICA!C1 -> [Ubicacion] | D2: =ESTADISTICA!D1 -> [Tipo de Camara] | E2: =ESTADISTICA!E1 -> [Tipo de Conexion] | F2: =ESTADISTICA!F1 -> 44621 | G2: =ESTADISTICA!G1 -> 44622 | H2: =ESTADISTICA!H1 -> 44623 | ... AJ2: =ESTADISTICA!AJ1 -> 44651
A3: =ESTADISTICA!A2 -> PRESIDENTE PERON (PEPSI) | B3: =ESTADISTICA!B2 -> MAR 01 | C3: =ESTADISTICA!C2 -> RP36 Y LA ESMERALDA | D3: =ESTADISTICA!D2 -> DOMO | E3: =ESTADISTICA!E2 -> Fibra Optica | F3: =ESTADISTICA!F2 -> APAGADO | G3: =ESTADISTICA!G2 -> APAGADO | H3: =ESTADISTICA!H2 -> APAGADO | ... AG3: =ESTADISTICA!AG2 -> 0
A4: =ESTADISTICA!A3 -> MAYOL | B4: =ESTADISTICA!B3 -> MAY 01 | C4: =ESTADISTICA!C3 -> Eva Peron y Cabildo | D4: =ESTADISTICA!D3 -> Domo | E4: =ESTADISTICA!E3 -> Radio | F4: =ESTADISTICA!F3 -> 0 | G4: =ESTADISTICA!G3 -> 0 | H4: =ESTADISTICA!H3 -> 0 | ... AG4: =ESTADISTICA!AG3 -> 0
A5: =ESTADISTICA!A4 -> 0 | B5: =ESTADISTICA!B4 -> MAY 02 | C5: =ESTADISTICA!C4 -> EVA PERON Y MONTEVIDEO | D5: =ESTADISTICA!D4 -> Domo | E5: =ESTADISTICA!E4 -> Radio | F5: =ESTADISTICA!F4 -> 0 | G5: =ESTADISTICA!G4 -> 0 | H5: =ESTADISTICA!H4 -> 0 | ... AG5: =ESTADISTICA!AG4 -> 0
A6: =ESTADISTICA!A5 -> MAYOL | B6: =ESTADISTICA!B5 -> MAY 03 | C6: =ESTADISTICA!C5 -> CHAÑAR Y SAN NICOLAS | D6: =ESTADISTICA!D5 -> DOMO | E6: =ESTADISTICA!E5 -> PTP A FO | F6: =ESTADISTICA!F5 -> 0 | G6: =ESTADISTICA!G5 -> 0 | H6: =ESTADISTICA!H5 -> 0 | ... AG6: =ESTADISTICA!AG5 -> 0
A7: =ESTADISTICA!A6 -> 0 | B7: =ESTADISTICA!B6 -> MAY 04 | C7: =ESTADISTICA!C6 -> MAR CHIQUITA Y RIO JACHAL | D7: =ESTADISTICA!D6 -> DOMO | E7: =ESTADISTICA!E6 -> Radio | F7: =ESTADISTICA!F6 -> 0 | G7: =ESTADISTICA!G6 -> 0 | H7: =ESTADISTICA!H6 -> 0 | ... AG7: =ESTADISTICA!AG6 -> 0
A8: =ESTADISTICA!A7 -> ALTAMIRA | B8: =ESTADISTICA!B7 -> ALT06 | C8: =ESTADISTICA!C7 -> LOPE DE VEGA Y NECOCHEA | D8: =ESTADISTICA!D7 -> Domo | E8: =ESTADISTICA!E7 -> PTP A FO | F8: =ESTADISTICA!F7 -> 0 | G8: =ESTADISTICA!G7 -> 0 | H8: =ESTADISTICA!H7 -> 0 | ... AG8: =ESTADISTICA!AG7 -> 0
A9: =ESTADISTICA!A8 -> ALTAMIRA | B9: =ESTADISTICA!B8 -> ALT01 | C9: =ESTADISTICA!C8 -> Calchaqui y Sgto. Cabral | D9: =ESTADISTICA!D8 -> Domo | E9: =ESTADISTICA!E8 -> Fibra Optica | F9: =ESTADISTICA!F8 -> 0 | G9: =ESTADISTICA!G8 -> 0 | H9: =ESTADISTICA!H8 -> 0 | ... AG9: =ESTADISTICA!AG8 -> 0
A10: =ESTADISTICA!A9 -> ALTAMIRA | B10: =ESTADISTICA!B9 -> ALT02 | C10: =ESTADISTICA!C9 -> Calchaqui y Lope de Vega | D10: =ESTADISTICA!D9 -> Domo | E10: =ESTADISTICA!E9 -> PTP A FO | F10: =ESTADISTICA!F9 -> 0 | G10: =ESTADISTICA!G9 -> 0 | H10: =ESTADISTICA!H9 -> 0 | ... AG10: =ESTADISTICA!AG9 -> 0
A11: =ESTADISTICA!A10 -> ALTAMIRA | B11: =ESTADISTICA!B10 -> ALT03 | C11: =ESTADISTICA!C10 -> Bombero Galarza y Necochea | D11: =ESTADISTICA!D10 -> Domo | E11: =ESTADISTICA!E10 -> Fibra Optica | F11: =ESTADISTICA!F10 -> 0 | G11: =ESTADISTICA!G10 -> 0 | H11: =ESTADISTICA!H10 -> 0 | ... AG11: =ESTADISTICA!AG10 -> 0
A12: =ESTADISTICA!A11 -> 0 | B12: =ESTADISTICA!B11 -> ALT04 | C12: =ESTADISTICA!C11 -> Francia y Necochea | D12: =ESTADISTICA!D11 -> Domo | E12: =ESTADISTICA!E11 -> Fibra Optica | F12: =ESTADISTICA!F11 -> APAGADO | G12: =ESTADISTICA!G11 -> 0 | H12: =ESTADISTICA!H11 -> 0 | ... AG12: =ESTADISTICA!AG11 -> 0
A13: =ESTADISTICA!A12 -> ALTAMIRA | B13: =ESTADISTICA!B12 -> ALT05 | C13: =ESTADISTICA!C12 -> Av. Calchaqui y Bombero Galarza | D13: =ESTADISTICA!D12 -> Domo | E13: =ESTADISTICA!E12 -> PTP A FO | F13: =ESTADISTICA!F12 -> 0 | G13: =ESTADISTICA!G12 -> 0 | H13: =ESTADISTICA!H12 -> 0 | ... AG13: =ESTADISTICA!AG12 -> 0
A14: =ESTADISTICA!A13 -> ALTAMIRA | B14: =ESTADISTICA!B13 -> ALT07 | C14: =ESTADISTICA!C13 -> AV. CALCHAQUI Y AV. DEL TRABAJO | D14: =ESTADISTICA!D13 -> DOMO | E14: =ESTADISTICA!E13 -> PTP A FO | F14: =ESTADISTICA!F13 -> 0 | G14: =ESTADISTICA!G13 -> 0 | H14: =ESTADISTICA!H13 -> 0 | ... AG14: =ESTADISTICA!AG13 -> 0
... A277: =ESTADISTICA!A276 -> ZONA RURAL SANTA ROSA | B277: =ESTADISTICA!B276 -> SRO13 (fija 1) | C277: =ESTADISTICA!C276 -> BRUSELAS E/ GRECIA Y CHECOSLOVAQUIA | D277: =ESTADISTICA!D276 -> Fija | E277: =ESTADISTICA!E276 -> RADIO | F277: =ESTADISTICA!F276 -> 0 | G277: =ESTADISTICA!G276 -> 0 | H277: =ESTADISTICA!H276 -> 0 | ... AG277: =ESTADISTICA!AG276 -> 0
B278: =ESTADISTICA!B277 -> SRO14 (fija 2) | C278: =ESTADISTICA!C277 -> BRUSELAS E/ GRECIA Y CHECOSLOVAQUIA | D278: =ESTADISTICA!D277 -> Fija | E278: =ESTADISTICA!E277 -> RADIO | F278: =ESTADISTICA!F277 -> APAGADO | G278: =ESTADISTICA!G277 -> APAGADO | H278: =ESTADISTICA!H277 -> APAGADO | I278: =ESTADISTICA!I277 -> APAGADO | ... AG278: =ESTADISTICA!AG277 -> 0
A279: =ESTADISTICA!A278 -> SANTA ROSA | B279: =ESTADISTICA!B278 -> SRO15 | C279: =ESTADISTICA!C278 -> NOVAK Y TIRANA (614) | D279: =ESTADISTICA!D278 -> DOMO | E279: =ESTADISTICA!E278 -> Fibra Optica | F279: =ESTADISTICA!F278 -> 0 | G279: =ESTADISTICA!G278 -> 0 | H279: =ESTADISTICA!H278 -> 0 | ... AG279: =ESTADISTICA!AG278 -> 0
A280: =ESTADISTICA!A279 -> SANTA ROSA | B280: =ESTADISTICA!B279 -> SRO18 (fija 1) | C280: =ESTADISTICA!C279 -> GRAN CANARIA Y BUDAPEST | D280: =ESTADISTICA!D279 -> Fija | E280: =ESTADISTICA!E279 -> Fibra Optica | F280: =ESTADISTICA!F279 -> 0 | G280: =ESTADISTICA!G279 -> 0 | H280: =ESTADISTICA!H279 -> 0 | ... AG280: =ESTADISTICA!AG279 -> 0
A281: =ESTADISTICA!A280 -> SANTA ROSA | B281: =ESTADISTICA!B280 -> SRO19 (fija 2) | C281: =ESTADISTICA!C280 -> GRAN CANARIA Y BUDAPEST | D281: =ESTADISTICA!D280 -> Fija | E281: =ESTADISTICA!E280 -> Fibra Optica | F281: =ESTADISTICA!F280 -> 0 | G281: =ESTADISTICA!G280 -> 0 | H281: =ESTADISTICA!H280 -> 0 | ... AG281: =ESTADISTICA!AG280 -> 0
A282: =ESTADISTICA!A281 -> SAN RUDECINDO | B282: =ESTADISTICA!B281 -> SRU01 (fija 1) | C282: =ESTADISTICA!C281 -> HERNANDARIAS Y AMBATO | D282: =ESTADISTICA!D281 -> Fija | E282: =ESTADISTICA!E281 -> Fibra Optica | F282: =ESTADISTICA!F281 -> 0 | G282: =ESTADISTICA!G281 -> 0 | H282: =ESTADISTICA!H281 -> 0 | ... AG282: =ESTADISTICA!AG281 -> 0
A283: =ESTADISTICA!A282 -> SAN RUDECINDO | B283: =ESTADISTICA!B282 -> SRU02 (fija 2) | C283: =ESTADISTICA!C282 -> HERNANDARIAS Y AMBATO | D283: =ESTADISTICA!D282 -> Fija | E283: =ESTADISTICA!E282 -> Fibra Optica | F283: =ESTADISTICA!F282 -> 0 | G283: =ESTADISTICA!G282 -> 0 | H283: =ESTADISTICA!H282 -> 0 | ... AG283: =ESTADISTICA!AG282 -> 0
A284: =ESTADISTICA!A283 -> VILLA ANGELICA | B284: =ESTADISTICA!B283 -> VANG01 | C284: =ESTADISTICA!C283 -> Senzabello y Necochea | D284: =ESTADISTICA!D283 -> Domo | E284: =ESTADISTICA!E283 -> PTP A FO | F284: =ESTADISTICA!F283 -> 0 | G284: =ESTADISTICA!G283 -> 0 | H284: =ESTADISTICA!H283 -> 0 | ... AG284: =ESTADISTICA!AG283 -> 0
A285: =ESTADISTICA!A284 -> VILLA ANGELICA | B285: =ESTADISTICA!B284 -> VANG02 | C285: =ESTADISTICA!C284 -> Thevenet y Ruta 36 | D285: =ESTADISTICA!D284 -> Domo | E285: =ESTADISTICA!E284 -> Fibra Optica | F285: =ESTADISTICA!F284 -> 0 | G285: =ESTADISTICA!G284 -> 0 | H285: =ESTADISTICA!H284 -> 0 | ... AG285: =ESTADISTICA!AG284 -> 0
A286: =ESTADISTICA!A285 -> VILLA DEL PLATA | B286: =ESTADISTICA!B285 -> VANG03 | C286: =ESTADISTICA!C285 -> Thevenet 1950 | D286: =ESTADISTICA!D285 -> Domo | E286: =ESTADISTICA!E285 -> Fibra Optica | F286: =ESTADISTICA!F285 -> 0 | G286: =ESTADISTICA!G285 -> 0 | H286: =ESTADISTICA!H285 -> 0 | ... AG286: =ESTADISTICA!AG285 -> 0
A287: =ESTADISTICA!A286 -> VILLA ANGELICA | B287: =ESTADISTICA!B286 -> VANG04 | C287: =ESTADISTICA!C286 -> Storni e/Thevenet y Calle 158 | D287: =ESTADISTICA!D286 -> DOMO | E287: =ESTADISTICA!E286 -> Fibra Optica | F287: =ESTADISTICA!F286 -> 0 | G287: =ESTADISTICA!G286 -> 0 | H287: =ESTADISTICA!H286 -> 0 | ... AG287: =ESTADISTICA!AG286 -> 0
A288: =ESTADISTICA!A287 -> VILLA ANGELICA | B288: =ESTADISTICA!B287 -> VANG05 | C288: =ESTADISTICA!C287 -> Storni y Thevenet | D288: =ESTADISTICA!D287 -> Domo | E288: =ESTADISTICA!E287 -> Fibra Optica | F288: =ESTADISTICA!F287 -> 0 | G288: =ESTADISTICA!G287 -> 0 | H288: =ESTADISTICA!H287 -> 0 | ... AG288: =ESTADISTICA!AG287 -> 0
A289: =ESTADISTICA!A288 -> VILLA ANGELICA | B289: =ESTADISTICA!B288 -> VANG06 | C289: =ESTADISTICA!C288 -> Arenales e/Thevenet y Calle 158 | D289: =ESTADISTICA!D288 -> DOMO | E289: =ESTADISTICA!E288 -> Fibra Optica | F289: =ESTADISTICA!F288 -> 0 | G289: =ESTADISTICA!G288 -> 0 | H289: =ESTADISTICA!H288 -> 0 | ... AG289: =ESTADISTICA!AG288 -> 0
A290: =ESTADISTICA!A289 -> VILLA ANGELICA | B290: =ESTADISTICA!B289 -> VANG07 | C290: =ESTADISTICA!C289 -> Arenales y Thevenet | D290: =ESTADISTICA!D289 -> Domo | E290: =ESTADISTICA!E289 -> Fibra Optica | F290: =ESTADISTICA!F289 -> 0 | G290: =ESTADISTICA!G289 -> 0 | H290: =ESTADISTICA!H289 -> 0 | ... AG290: =ESTADISTICA!AG289 -> 0
... A366: =ESTADISTICA!A365 -> 0 | B366: =ESTADISTICA!B365 -> ZEB04 | C366: =ESTADISTICA!C365 -> THEVENET Y DIAGONAL GRANADEROS | D366: =ESTADISTICA!D365 -> DOMO | E366: =ESTADISTICA!E365 -> Radio | F366: =ESTADISTICA!F365 -> 0 | G366: =ESTADISTICA!G365 -> 0 | H366: =ESTADISTICA!H365 -> 0 | ... AG366: =ESTADISTICA!AG365 -> 0

Sheet GRAFICO

Sheet GRAFICO2

Sheet BARRAS

Sheet AUXILIAR
A1: FECHA | B1: RADIO | C1: FIBRA | D1: ANTENA | E1: TOTAL APAGADOS | F1: INSTALADAS
A2: ='APAGADOS RADIO'!F2 -> 44621 | B2: ='APAGADOS RADIO'!F1+D2 -> 10 | C2: ='APAGADOS FIBRA'!F1 -> 52 | D2: ='APAGADOS ANTENA'!F1 -> 2 | E2: =B2+C2 -> 62 | F2: ='RESUMEN TOTAL'!B1 -> 366
A3: ='APAGADOS RADIO'!G2 -> 44622 | B3: ='APAGADOS RADIO'!G1+D3 -> 11 | C3: ='APAGADOS FIBRA'!G1 -> 69 | D3: ='APAGADOS ANTENA'!G1 -> 4 | E3: =B3+C3 -> 80 | F3: ='RESUMEN TOTAL'!B1 -> 366
A4: ='APAGADOS RADIO'!H2 -> 44623 | F4: ='RESUMEN TOTAL'!B1 -> 366
A5: ='APAGADOS RADIO'!I2 -> 44624 | F5: ='RESUMEN TOTAL'!B1 -> 366
A6: ='APAGADOS RADIO'!J2 -> 44625 | F6: ='RESUMEN TOTAL'!B1 -> 366
A7: ='APAGADOS RADIO'!K2 -> 44626 | F7: ='RESUMEN TOTAL'!B1 -> 366
A8: ='APAGADOS RADIO'!L2 -> 44627 | F8: ='RESUMEN TOTAL'!B1 -> 366
A9: ='APAGADOS RADIO'!M2 -> 44628 | F9: ='RESUMEN TOTAL'!B1 -> 366
A10: ='APAGADOS RADIO'!N2 -> 44629 | F10: ='RESUMEN TOTAL'!B1 -> 366
A11: ='APAGADOS RADIO'!O2 -> 44630 | F11: ='RESUMEN TOTAL'!B1 -> 366
A12: ='APAGADOS RADIO'!P2 -> 44631 | F12: ='RESUMEN TOTAL'!B1 -> 366
A13: ='APAGADOS RADIO'!Q2 -> 44632 | F13: ='RESUMEN TOTAL'!B1 -> 366
A14: ='APAGADOS RADIO'!R2 -> 44633 | F14: ='RESUMEN TOTAL'!B1 -> 366
A15: ='APAGADOS RADIO'!S2 -> 44634 | F15: ='RESUMEN TOTAL'!B1 -> 366
A16: ='APAGADOS RADIO'!T2 -> 44635 | F16: ='RESUMEN TOTAL'!B1 -> 366
A17: ='APAGADOS RADIO'!U2 -> 44636 | F17: ='RESUMEN TOTAL'!B1 -> 366
A18: ='APAGADOS RADIO'!V2 -> 44637 | F18: ='RESUMEN TOTAL'!B1 -> 366
A19: ='APAGADOS RADIO'!W2 -> 44638 | F19: ='RESUMEN TOTAL'!B1 -> 366
A20: ='APAGADOS RADIO'!X2 -> 44639 | F20: ='RESUMEN TOTAL'!B1 -> 366
A21: ='APAGADOS RADIO'!Y2 -> 44640 | F21: ='RESUMEN TOTAL'!B1 -> 366
A22: ='APAGADOS RADIO'!Z2 -> 44641 | F22: ='RESUMEN TOTAL'!B1 -> 366
A23: ='APAGADOS RADIO'!AA2 -> 44642 | F23: ='RESUMEN TOTAL'!B1 -> 366
A24: ='APAGADOS RADIO'!AB2 -> 44643 | F24: ='RESUMEN TOTAL'!B1 -> 366
A25: ='APAGADOS RADIO'!AC2 -> 44644 | F25: ='RESUMEN TOTAL'!B1 -> 366
A26: ='APAGADOS RADIO'!AD2 -> 44645 | F26: ='RESUMEN TOTAL'!B1 -> 366
A27: ='APAGADOS RADIO'!AE2 -> 44646 | F27: ='RESUMEN TOTAL'!B1 -> 366
A28: ='APAGADOS RADIO'!AF2 -> 44647 | F28: ='RESUMEN TOTAL'!B1 -> 366
A29: ='APAGADOS RADIO'!AG2 -> 44648 | F29: ='RESUMEN TOTAL'!B1 -> 366
A30: ='APAGADOS RADIO'!AH2 -> 44649 | F30: ='RESUMEN TOTAL'!B1 -> 366
A31: ='APAGADOS RADIO'!AI2 -> 44650 | F31: ='RESUMEN TOTAL'!B1 -> 366
A32: ='APAGADOS RADIO'!AJ2 -> 44651 | F32: ='RESUMEN TOTAL'!B1 -> 366
