Workbook
Name _25_de_agosto: 'RESUMEN TOTAL'!$A$4:$D$366
Name _25_de_agosto_3: 'RESUMEN TOTAL'!$A$4:$D$378
Name BONOMOcam: Hoja1!$B$2
Name CANTIDAD_DE_CAMARAS: 'RESUMEN TOTAL'!$B$1
Name COSEIDIcam: Hoja1!$B$4

Sheet RESUMEN TOTAL
A1: CANTIDAD DE CAMARAS | B1: =COUNTA(B5:B533) -> 435 | D1: PORCIENTO DE CAIDAS | K1: =(K3)/(K2+K3) -> 0.059770115 | L1: =(L3)/(L2+L3) -> 0.068965517 | M1: =(M3)/(M2+M3) -> 0.082758621 | N1: =(N3)/(N2+N3) -> 0 | O1: =(O3)/(O2+O3) -> 0.075862069 | P1: =(P3)/(P2+P3) -> 0.071264368 | Q1: =(Q3)/(Q2+Q3) -> 0.087356322 | R1: =(R3)/(R2+R3) -> 0 | ... AL1: =(AL3)/(AL2+AL3) -> 0
D2: FUNCIONAN | K2: =B1-K3 -> 409 | L2: =CANTIDAD_DE_CAMARAS-L3 -> 405 | M2: =CANTIDAD_DE_CAMARAS-M3 -> 399 | N2: =CANTIDAD_DE_CAMARAS-N3 -> 435 | O2: =CANTIDAD_DE_CAMARAS-O3 -> 402 | P2: =CANTIDAD_DE_CAMARAS-P3 -> 404 | Q2: =CANTIDAD_DE_CAMARAS-Q3 -> 397 | R2: =CANTIDAD_DE_CAMARAS-R3 -> 435 | S2: =CANTIDAD_DE_CAMARAS-S3 -> 435 | ... AL2: =CANTIDAD_DE_CAMARAS-AL3 -> 435
D3: CAIDAS | K3: =COUNTIF(K4:K453, "apagado") -> 26 | L3: =COUNTIF(L4:L453, "apagado") -> 30 | M3: =COUNTIF(M4:M453, "apagado") -> 36 | N3: =COUNTIF(N4:N453, "apagado") -> 0 | O3: =COUNTIF(O4:O453, "apagado") -> 33 | P3: =COUNTIF(P4:P453, "apagado") -> 31 | Q3: =COUNTIF(Q4:Q453, "apagado") -> 38 | R3: =COUNTIF(R4:R453, "apagado") -> 0 | ... AL3: =COUNTIF(AL4:AL453, "apagado") -> 0
A4: Barrio | B4: [Denominacion] | C4: [Empresa Mantenimiento] | D4: [Ubicacion] | E4: [Tipo de Camara] | F4: [Tipo de Conexion] | H4: DIAS FUNCIONANDO | I4: DIAS CAIDA | J4: EFECTIVIDAD | K4: 44958 | L4: 44959 | M4: 44960 | N4: 44961 | O4: 44962 | P4: 44963 | Q4: 44964 | R4: 44965 | S4: 44966 | T4: 44967 | U4: 44968 | V4: 44969 | W4: 44970 | X4: 44971 | Y4: 44972 | Z4: 44973 | AA4: 44974 | AB4: 44975 | AC4: 44976 | AD4: 44977 | AE4: 44978 | AF4: 44979 | AG4: 44980 | AH4: 44981 | AI4: 44982 | AJ4: 44983 | AK4: 44984 | AL4: 44985
A5: ALTAMIRA | B5: ALT01 | C5: BONOMO | D5: Calchaqui y Sgto. Cabral | E5: Domo | F5: Fibra Optica | G5: 172.20.10.6 | H5: =COUNTIF(K5:AL5,"") -> 28 | I5: =COUNTIF(K5:AL5,"APAGADO") -> 0 | J5: =(H5)/(I5+H5) -> 1
A6: ALTAMIRA | B6: ALT02 | C6: BONOMO | D6: Calchaqui y Lope de Vega | E6: Domo | F6: PTO A FO | G6: 172.20.12.218 | H6: =COUNTIF(K6:AL6,"") -> 28 | I6: =COUNTIF(K6:AL6,"APAGADO") -> 0 | J6: =(H6)/(I6+H6) -> 1
A7: ALTAMIRA | B7: ALT 03 | C7: BONOMO | D7: Bombero Galarza y Necochea | E7: Domo | F7: FIBRA OPTICA | G7: 172.20.12.54 | H7: =COUNTIF(K7:AL7,"") -> 28 | I7: =COUNTIF(K7:AL7,"APAGADO") -> 0 | J7: =(H7)/(I7+H7) -> 1
A8: ALTAMIRA | B8: ALT 04 | C8: BONOMO | D8: Francia y Necochea | E8: Domo | F8: FIBRA OPTICA | G8: 172.20.12.55 | H8: =COUNTIF(K8:AL8,"") -> 28 | I8: =COUNTIF(K8:AL8,"APAGADO") -> 0 | J8: =(H8)/(I8+H8) -> 1
A9: ALTAMIRA | B9: ALT05 | C9: BONOMO | D9: Av. Calchaqui y Bombero Galarza | E9: Domo | F9: PTO A FO | G9: 172.20.12.216 | H9: =COUNTIF(K9:AL9,"") -> 28 | I9: =COUNTIF(K9:AL9,"APAGADO") -> 0 | J9: =(H9)/(I9+H9) -> 1
A10: ALTAMIRA | B10: ALT 06 | C10: BONOMO | D10: LOPE DE VEGA Y NECOCHEA | E10: Domo | F10: PTO A FO | G10: 172.20.12.12 | H10: =COUNTIF(K10:AL10,"") -> 28 | I10: =COUNTIF(K10:AL10,"APAGADO") -> 0 | J10: =(H10)/(I10+H10) -> 1
A11: ALTAMIRA | B11: ALT07 | C11: BONOMO | D11: AV. CALCHAQUI Y AV. DEL TRABAJO | E11: DOMO | F11: PTO A FO | G11: 172.20.10.57 | H11: =COUNTIF(K11:AL11,"") -> 28 | I11: =COUNTIF(K11:AL11,"APAGADO") -> 0 | J11: =(H11)/(I11+H11) -> 1
A12: ALTAMIRA | B12: ALT 08 | C12: BONOMO | D12: HUMAITA Y NECOCHEA | E12: DOMO | F12: Fibra Optica | G12: 172.20.11.215 | H12: =COUNTIF(K12:AL12,"") -> 28 | I12: =COUNTIF(K12:AL12,"APAGADO") -> 0 | J12: =(H12)/(I12+H12) -> 1
A13: ALTAMIRA | B13: ALT 09 | C13: BONOMO | D13: NECOCHEA Y CURUPAITY | E13: DOMO | F13: Fibra Optica | G13: 172.20.11.216 | H13: =COUNTIF(K13:AL13,"") -> 28 | I13: =COUNTIF(K13:AL13,"APAGADO") -> 0 | J13: =(H13)/(I13+H13) -> 1
A14: ALTAMIRA | B14: ALT 10 | C14: BONOMO | D14: Calchaqui y Francia | E14: Domo | F14: Radio | H14: =COUNTIF(K14:AL14,"") -> 28 | I14: =COUNTIF(K14:AL14,"APAGADO") -> 0 | J14: =(H14)/(I14+H14) -> 1
A15: AGUSTIN RAMIREZ | B15: ARA 01 | C15: COSEIDI | D15: Malambo y Tranquera | E15: Domo | F15: FIBRA OPTICA | G15: 172.20.12.110 | H15: =COUNTIF(K15:AL15,"") -> 28 | I15: =COUNTIF(K15:AL15,"APAGADO") -> 0 | J15: =(H15)/(I15+H15) -> 1
A16: BELGRANO | B16: BEL 01 | C16: BONOMO | D16: San Martin y Dardo Rocha | E16: DOMO | F16: FIBRA OPTICA | G16: 172.20.12.64 | H16: =COUNTIF(K16:AL16,"") -> 28 | I16: =COUNTIF(K16:AL16,"APAGADO") -> 0 | J16: =(H16)/(I16+H16) -> 1
A17: BOSQUES CENTRO | B17: BOSQC 01 | C17: COSEIDI | D17: LUIS AGOTE E/DANUNCIO Y CAMPOAMOR | E17: Fija | F17: Radio | G17: 172.20.11.15 | H17: =COUNTIF(K17:AL17,"") -> 28 | I17: =COUNTIF(K17:AL17,"APAGADO") -> 0 | J17: =(H17)/(I17+H17) -> 1
A18: BOSQUES CENTRO | B18: BOSQC 02 | C18: COSEIDI | D18: LUIS AGOTE E/DANUNCIO Y CAMPOAMOR | E18: Fija | F18: Radio | G18: 172.20.11.16 | H18: =COUNTIF(K18:AL18,"") -> 28 | I18: =COUNTIF(K18:AL18,"APAGADO") -> 0 | J18: =(H18)/(I18+H18) -> 1
A19: BOSQUES CENTRO | B19: BOSQC 03 | C19: COSEIDI | D19: BENAVENTE Y LUIS AGOTE | E19: Fija | F19: Radio | G19: 172.20.11.13 | H19: =COUNTIF(K19:AL19,"") -> 28 | I19: =COUNTIF(K19:AL19,"APAGADO") -> 0 | J19: =(H19)/(I19+H19) -> 1
A20: BOSQUES CENTRO | B20: BOSQC 04 | C20: COSEIDI | D20: BENAVENTE Y LUIS AGOTE | E20: Fija | F20: Radio | G20: 172.20.11.113 | H20: =COUNTIF(K20:AL20,"") -> 28 | I20: =COUNTIF(K20:AL20,"APAGADO") -> 0 | J20: =(H20)/(I20+H20) -> 1
A21: BOSQUES CENTRO | B21: BOSQC 05 | C21: COSEIDI | D21: LUIS AGOTE Y RUTA 36 | E21: Fija | F21: Radio | G21: 172.20.11.17 | H21: =COUNTIF(K21:AL21,"") -> 28 | I21: =COUNTIF(K21:AL21,"APAGADO") -> 0 | J21: =(H21)/(I21+H21) -> 1
A22: BOSQUES CENTRO | B22: BOSQC 06 | C22: COSEIDI | D22: LUIS AGOTE Y RUTA 36 | E22: Fija | F22: Radio | G22: 172.20.11.18 | H22: =COUNTIF(K22:AL22,"") -> 28 | I22: =COUNTIF(K22:AL22,"APAGADO") -> 0 | J22: =(H22)/(I22+H22) -> 1
A23: CENTRO | B23: CEN01 | C23: BONOMO | D23: San Martin y 9 de Julio | E23: Fija | F23: Fibra Optica | G23: 172.20.11.10 | H23: =COUNTIF(K23:AL23,"") -> 28 | I23: =COUNTIF(K23:AL23,"APAGADO") -> 0 | J23: =(H23)/(I23+H23) -> 1
A24: CENTRO | B24: CEN02 | C24: BONOMO | D24: San Martin y Almafuerte | E24: Fija | F24: Fibra Optica | G24: 172.20.11.11 | H24: =COUNTIF(K24:AL24,"") -> 28 | I24: =COUNTIF(K24:AL24,"APAGADO") -> 0 | J24: =(H24)/(I24+H24) -> 1
A25: CENTRO | B25: CEN03 | C25: BONOMO | D25: San Martin y Sallares | E25: Domo | F25: CENTRO | G25: 172.20.12.30 | H25: =COUNTIF(K25:AL25,"") -> 28 | I25: =COUNTIF(K25:AL25,"APAGADO") -> 0 | J25: =(H25)/(I25+H25) -> 1
A26: CENTRO | B26: CEN04 | C26: BONOMO | D26: San Martin y Contreras | E26: Domo | F26: Fibra Optica | G26: 172.20.12.29 | H26: =COUNTIF(K26:AL26,"") -> 28 | I26: =COUNTIF(K26:AL26,"APAGADO") -> 0 | J26: =(H26)/(I26+H26) -> 1
... A33: CENTRO | B33: CEN11 | C33: BONOMO | D33: Monteagudo y Bocuzzi | E33: Domo | F33: Fibra Optica | G33: 172.20.10.24 | H33: =COUNTIF(K33:AL33,"") -> 28 | I33: =COUNTIF(K33:AL33,"APAGADO") -> 0 | J33: =(H33)/(I33+H33) -> 1
A34: CENTRO | B34: CEN 12 | C34: BONOMO | D34: Monteagudo y Mitre | E34: Domo | F34: Fibra Optica | G34: 172.20.10.23 | H34: =COUNTIF(K34:AL34,"") -> 26 | I34: =COUNTIF(K34:AL34,"APAGADO") -> 2 | J34: =(H34)/(I34+H34) -> 0.92857143 | L34: APAGADO | M34: APAGADO
A35: CENTRO | B35: CEN 13 | C35: BONOMO | D35: 25 de Mayo y Maipu | E35: DOMO | F35: Fibra Optica | G35: 172.20.10.20 | H35: =COUNTIF(K35:AL35,"") -> 28 | I35: =COUNTIF(K35:AL35,"APAGADO") -> 0 | J35: =(H35)/(I35+H35) -> 1
A36: CENTRO | B36: CEN14 | C36: BONOMO | D36: Pte.Peron e/Pringles y Brown | E36: Domo | F36: Fibra Optica | G36: 172.20.10.21 | H36: =COUNTIF(K36:AL36,"") -> 28 | I36: =COUNTIF(K36:AL36,"APAGADO") -> 0 | J36: =(H36)/(I36+H36) -> 1
A37: CENTRO | B37: CEN15 | C37: BONOMO | D37: Alberdi y A.del Valle | E37: Domo | F37: Fibra Optica | G37: 172.20.10.35 | H37: =COUNTIF(K37:AL37,"") -> 28 | I37: =COUNTIF(K37:AL37,"APAGADO") -> 0 | J37: =(H37)/(I37+H37) -> 1
A38: CENTRO | B38: CEN16 | C38: BONOMO | D38: San Martin y Pte. Peron | E38: Fija | F38: Fibra Optica | G38: 172.20.12.36 | H38: =COUNTIF(K38:AL38,"") -> 28 | I38: =COUNTIF(K38:AL38,"APAGADO") -> 0 | J38: =(H38)/(I38+H38) -> 1
A39: CENTRO | B39: CEN17 | C39: BONOMO | D39: San Martin y Mitre | E39: Domo | F39: PTO A FO | G39: 172.20.12.200 | H39: =COUNTIF(K39:AL39,"") -> 28 | I39: =COUNTIF(K39:AL39,"APAGADO") -> 0 | J39: =(H39)/(I39+H39) -> 1
A40: CENTRO | B40: CEN18 | C40: BONOMO | D40: Monteagudo e/Mitre y Sallares | E40: Fija | F40: Fibra Optica | G40: 172.20.10.26 | H40: =COUNTIF(K40:AL40,"") -> 28 | I40: =COUNTIF(K40:AL40,"APAGADO") -> 0 | J40: =(H40)/(I40+H40) -> 1
A41: CENTRO | B41: CEN19 | C41: BONOMO | D41: Chacabuco y 25 de Mayo | E41: Fija | F41: Fibra Optica | G41: 172.20.10.27 | H41: =COUNTIF(K41:AL41,"") -> 28 | I41: =COUNTIF(K41:AL41,"APAGADO") -> 0 | J41: =(H41)/(I41+H41) -> 1
A42: LOMAS DE MONTEVERDE | B42: CEN20 | C42: BONOMO | D42: Pte. Illia y Las Heras | E42: Domo | F42: Fibra Optica | G42: 172.20.10.33 | H42: =COUNTIF(K42:AL42,"") -> 26 | I42: =COUNTIF(K42:AL42,"APAGADO") -> 2 | J42: =(H42)/(I42+H42) -> 0.92857143 | L42: APAGADO | M42: APAGADO
A43: CENTRO | B43: CEN21 | C43: BONOMO | D43: Misiones y Urquiza | E43: Fija | F43: Radio | G43: 172.20.200.132 | H43: =COUNTIF(K43:AL43,"") -> 28 | I43: =COUNTIF(K43:AL43,"APAGADO") -> 0 | J43: =(H43)/(I43+H43) -> 1
A44: CENTRO | B44: CEN22 | C44: BONOMO | D44: Las Heras y Chacabuco | E44: Domo | F44: Radio | G44: 172.20.200.125 | H44: =COUNTIF(K44:AL44,"") -> 28 | I44: =COUNTIF(K44:AL44,"APAGADO") -> 0 | J44: =(H44)/(I44+H44) -> 1
A45: CENTRO | B45: CEN23 | C45: BONOMO | D45: Sallares y Monteagudo | E45: Domo | F45: Fibra Optica | G45: 172.20.12.05 | H45: =COUNTIF(K45:AL45,"") -> 28 | I45: =COUNTIF(K45:AL45,"APAGADO") -> 0 | J45: =(H45)/(I45+H45) -> 1
A46: CENTRO | B46: CEN24 | C46: BONOMO | D46: Sallares y España | E46: Domo | F46: Fibra Optica | G46: 172.20.12.04 | H46: =COUNTIF(K46:AL46,"") -> 28 | I46: =COUNTIF(K46:AL46,"APAGADO") -> 0 | J46: =(H46)/(I46+H46) -> 1
...

Sheet Hoja4
A10: Barrio | B10: [Denominacion] | C10: [Empresa Mantenimiento] | D10: [Ubicacion] | E10: [Tipo de Camara] | F10: [Tipo de Conexion]
A11: CENTRO | B11: CEN35 | C11: BONOMO | D11: España y Marmol | E11: Domo | F11: Fibra Optica | G11: 172.20.12.50
A12: CENTRO | B12: CEN 37 | C12: BONOMO | D12: Diagonal Granaderos y Monteagudo | E12: Domo | F12: Fibra Optica | G12: 172.20.12.52
A13: CENTRO | B13: CEN38 | C13: BONOMO | D13: Diagonal Constituyentes y Almafuerte | E13: Domo | F13: Fibra Optica | G13: 172.20.12.53
A14: CENTRO | B14: CEN 65 | C14: BONOMO | D14: SAN MARTIN Y JUAN PERON | E14: FIJA | F14: Fibra Optica | G14: 172.20.11.135
A15: CENTRO | B15: CEN66 | C15: BONOMO | D15: SAN MARTIN Y JUAN PERON | E15: FIJA | F15: Fibra Optica | G15: 172.20.11.136
A16: CENTRO | B16: CEN 77 | C16: BONOMO | D16: Monteagudo e/ Mitre y Boccuzzi | E16: Fija | F16: Fibra Optica | G16: 172.20.11.241
A17: CENTRO | B17: CEN 79 | C17: BONOMO | D17: Diag. Constituyente y Brown | E17: Fija | F17: Fibra Optica | G17: 172.20.11.243
A18: CENTRO | B18: CEN 80 | C18: BONOMO | D18: Diag. Constituyente y Brown | E18: Fija | F18: Fibra Optica | G18: 172.20.11.244
A19: SAN NICOLAS | B19: CHA01 | C19: BONOMO | D19: Novak y Pte Illia | E19: Domo | F19: Radio | G19: 172.20.200.126
A20: KM 26700 (JULIO A. COSTA) | B20: KM03 | C20: BONOMO | D20: Novak y La Pulperia | E20: Domo | F20: Radio | G20: 172.20.200.185
A21: KM 26700 (JULIO A. COSTA) | B21: KM08 / UPA 03 | C21: BONOMO | D21: LOS CHARRUAS Y BLANDENGUES | E21: DOMO | F21: Radio | G21: 172.20.200.149
A22: KM 26700 (JULIO A. COSTA) | B22: KM09 / UPA 1 | C22: BONOMO | D22: NOVAK Y LA POSTA | E22: DOMO | F22: Radio | G22: 172.20.11.76
... A27: 9 DE JULIO | B27: NJU09 | C27: BONOMO | D27: PARRILLO Y CONTRERAS | E27: DOMO | F27: Fibra Optica | G27: 172.20.11.190
A28: DON JOSE | B28: PUNTO SEGURO AGUSTIN RAMIREZ INTERCOMUNICADOR | C28: BONOMO | D28: MALAMBO Y LA TRANQUERA | E28: Fija | F28: Fibra Optica
A29: PRESIDENTE SARMIENTO | B29: SAR 02 (fija 1) | C29: BONOMO | D29: DARDO ROCHA Y GABRIELA MISTRAL | E29: Fija | F29: Fibra Optica | G29: 172.20.11.184
A30: PRESIDENTE SARMIENTO | B30: SAR 03 (fija 2) | C30: BONOMO | D30: DARDO ROCHA Y GABRIELA MISTRAL | E30: Fija | F30: Fibra Optica | G30: 172.20.11.185
A31: SAN EDUARDO | B31: SEDU01 | C31: BONOMO | D31: San Martin y Sperandio | E31: Domo | F31: Fibra Optica | G31: 172.20.10.10
A32: VILLA ANGELICA | B32: VANG10 | C32: BONOMO | D32: Senzabello y Braile | E32: fija | F32: Fibra Optica | G32: 172.20.11.245
A33: VILLA ANGELICA | B33: VANG11 | C33: BONOMO | D33: Senzabello y Braile | E33: fija | F33: Fibra Optica | G33: 172.20.11.246
A34: VILLA VATTEONE CENTRO | B34: VAT07 | C34: BONOMO | D34: Eva Peron y Lavalle | F34: PTO A FO | G34: 172.20.11.26
A35: VILLA VATTEONE CENTRO | B35: VAT23 (fija 1) | C35: BONOMO | D35: EVA PERON Y "EL TUNEL" (BAJO NIVEL) | E35: Fija | F35: Fibra Optica | G35: 172.20.11.139
A36: VILLA VATTEONE CENTRO | B36: VAT24 (fija 2) | C36: BONOMO | D36: EVA PERON Y "EL TUNEL" (BAJO NIVEL) | E36: Fija | F36: Fibra Optica | G36: 172.20.11.140
A44: RECIBIDO: | D44: FIRMA:
A46: EMPRESA: BONOMO SISTEMAS
D48: ACALARCION:

Sheet ESTADISTICA
A1: ='RESUMEN TOTAL'!A4 -> Barrio | B1: ='RESUMEN TOTAL'!B4 -> [Denominacion] | C1: ='RESUMEN TOTAL'!D4 -> [Ubicacion] | D1: ='RESUMEN TOTAL'!E4 -> [Tipo de Camara] | E1: ='RESUMEN TOTAL'!F4 -> [Tipo de Conexion] | F1: ='RESUMEN TOTAL'!K4 -> 44958 | G1: ='RESUMEN TOTAL'!L4 -> 44959 | H1: ='RESUMEN TOTAL'!M4 -> 44960 | I1: ='RESUMEN TOTAL'!N4 -> 44961 | J1: ='RESUMEN TOTAL'!O4 -> 44962 | K1: ='RESUMEN TOTAL'!P4 -> 44963 | L1: ='RESUMEN TOTAL'!Q4 -> 44964 | M1: ='RESUMEN TOTAL'!R4 -> 44965 | ... AG1: ='RESUMEN TOTAL'!AL4 -> 44985 | AH1: ='RESUMEN TOTAL'!#REF! -> #REF! | AI1: ='RESUMEN TOTAL'!#REF! -> #REF! | AJ1: ='RESUMEN TOTAL'!#REF! -> #REF!
A2: ='RESUMEN TOTAL'!A5 -> ALTAMIRA | B2: ='RESUMEN TOTAL'!B5 -> ALT01 | C2: ='RESUMEN TOTAL'!D5 -> Calchaqui y Sgto. Cabral | D2: ='RESUMEN TOTAL'!E5 -> Domo | E2: ='RESUMEN TOTAL'!F5 -> Fibra Optica | F2: ='RESUMEN TOTAL'!K5 -> 0 | G2: ='RESUMEN TOTAL'!L5 -> 0 | H2: ='RESUMEN TOTAL'!M5 -> 0 | I2: ='RESUMEN TOTAL'!N5 -> 0 | J2: ='RESUMEN TOTAL'!O5 -> 0 | K2: ='RESUMEN TOTAL'!P5 -> 0 | L2: ='RESUMEN TOTAL'!Q5 -> 0 | M2: ='RESUMEN TOTAL'!R5 -> 0 | ... AG2: ='RESUMEN TOTAL'!AL5 -> 0 | AH2: ='RESUMEN TOTAL'!#REF! -> #REF! | AI2: ='RESUMEN TOTAL'!#REF! -> #REF! | AJ2: ='RESUMEN TOTAL'!#REF! -> #REF!
A3: ='RESUMEN TOTAL'!A6 -> ALTAMIRA | B3: ='RESUMEN TOTAL'!B6 -> ALT02 | C3: ='RESUMEN TOTAL'!D6 -> Calchaqui y Lope de Vega | D3: ='RESUMEN TOTAL'!E6 -> Domo | E3: ='RESUMEN TOTAL'!F6 -> PTO A FO | F3: ='RESUMEN TOTAL'!K6 -> 0 | G3: ='RESUMEN TOTAL'!L6 -> 0 | H3: ='RESUMEN TOTAL'!M6 -> 0 | I3: ='RESUMEN TOTAL'!N6 -> 0 | J3: ='RESUMEN TOTAL'!O6 -> 0 | K3: ='RESUMEN TOTAL'!P6 -> 0 | L3: ='RESUMEN TOTAL'!Q6 -> 0 | M3: ='RESUMEN TOTAL'!R6 -> 0 | ... AG3: ='RESUMEN TOTAL'!AL6 -> 0 | AH3: ='RESUMEN TOTAL'!#REF! -> #REF! | AI3: ='RESUMEN TOTAL'!#REF! -> #REF! | AJ3: ='RESUMEN TOTAL'!#REF! -> #REF!
A4: ='RESUMEN TOTAL'!A7 -> ALTAMIRA | B4: ='RESUMEN TOTAL'!B7 -> ALT 03 | C4: ='RESUMEN TOTAL'!D7 -> Bombero Galarza y Necochea | D4: ='RESUMEN TOTAL'!E7 -> Domo | E4: ='RESUMEN TOTAL'!F7 -> FIBRA OPTICA | F4: ='RESUMEN TOTAL'!K7 -> 0 | G4: ='RESUMEN TOTAL'!L7 -> 0 | H4: ='RESUMEN TOTAL'!M7 -> 0 | I4: ='RESUMEN TOTAL'!N7 -> 0 | J4: ='RESUMEN TOTAL'!O7 -> 0 | K4: ='RESUMEN TOTAL'!P7 -> 0 | L4: ='RESUMEN TOTAL'!Q7 -> 0 | M4: ='RESUMEN TOTAL'!R7 -> 0 | ... AG4: ='RESUMEN TOTAL'!AL7 -> 0 | AH4: ='RESUMEN TOTAL'!#REF! -> #REF! | AI4: ='RESUMEN TOTAL'!#REF! -> #REF! | AJ4: ='RESUMEN TOTAL'!#REF! -> #REF!
A5: ='RESUMEN TOTAL'!A8 -> ALTAMIRA | B5: ='RESUMEN TOTAL'!B8 -> ALT 04 | C5: ='RESUMEN TOTAL'!D8 -> Francia y Necochea | D5: ='RESUMEN TOTAL'!E8 -> Domo | E5: ='RESUMEN TOTAL'!F8 -> FIBRA OPTICA | F5: ='RESUMEN TOTAL'!K8 -> 0 | G5: ='RESUMEN TOTAL'!L8 -> 0 | H5: ='RESUMEN TOTAL'!M8 -> 0 | I5: ='RESUMEN TOTAL'!N8 -> 0 | J5: ='RESUMEN TOTAL'!O8 -> 0 | K5: ='RESUMEN TOTAL'!P8 -> 0 | L5: ='RESUMEN TOTAL'!Q8 -> 0 | M5: ='RESUMEN TOTAL'!R8 -> 0 | ... AG5: ='RESUMEN TOTAL'!AL8 -> 0 | AH5: ='RESUMEN TOTAL'!#REF! -> #REF! | AI5: ='RESUMEN TOTAL'!#REF! -> #REF! | AJ5: ='RESUMEN TOTAL'!#REF! -> #REF!
A6: ='RESUMEN TOTAL'!A9 -> ALTAMIRA | B6: ='RESUMEN TOTAL'!B9 -> ALT05 | C6: ='RESUMEN TOTAL'!D9 -> Av. Calchaqui y Bombero Galarza | D6: ='RESUMEN TOTAL'!E9 -> Domo | E6: ='RESUMEN TOTAL'!F9 -> PTO A FO | F6: ='RESUMEN TOTAL'!K9 -> 0 | G6: ='RESUMEN TOTAL'!L9 -> 0 | H6: ='RESUMEN TOTAL'!M9 -> 0 | I6: ='RESUMEN TOTAL'!N9 -> 0 | J6: ='RESUMEN TOTAL'!O9 -> 0 | K6: ='RESUMEN TOTAL'!P9 -> 0 | L6: ='RESUMEN TOTAL'!Q9 -> 0 | M6: ='RESUMEN TOTAL'!R9 -> 0 | ... AG6: ='RESUMEN TOTAL'!AL9 -> 0 | AH6: ='RESUMEN TOTAL'!#REF! -> #REF! | AI6: ='RESUMEN TOTAL'!#REF! -> #REF! | AJ6: ='RESUMEN TOTAL'!#REF! -> #REF!
A7: ='RESUMEN TOTAL'!A10 -> ALTAMIRA | B7: ='RESUMEN TOTAL'!B10 -> ALT 06 | C7: ='RESUMEN TOTAL'!D10 -> LOPE DE VEGA Y NECOCHEA | D7: ='RESUMEN TOTAL'!E10 -> Domo | E7: ='RESUMEN TOTAL'!F10 -> PTO A FO | F7: ='RESUMEN TOTAL'!K10 -> 0 | G7: ='RESUMEN TOTAL'!L10 -> 0 | H7: ='RESUMEN TOTAL'!M10 -> 0 | I7: ='RESUMEN TOTAL'!N10 -> 0 | J7: ='RESUMEN TOTAL'!O10 -> 0 | K7: ='RESUMEN TOTAL'!P10 -> 0 | L7: ='RESUMEN TOTAL'!Q10 -> 0 | M7: ='RESUMEN TOTAL'!R10 -> 0 | ... AG7: ='RESUMEN TOTAL'!AL10 -> 0 | AH7: ='RESUMEN TOTAL'!#REF! -> #REF! | AI7: ='RESUMEN TOTAL'!#REF! -> #REF! | AJ7: ='RESUMEN TOTAL'!#REF! -> #REF!
A8: ='RESUMEN TOTAL'!A11 -> ALTAMIRA | B8: ='RESUMEN TOTAL'!B11 -> ALT07 | C8: ='RESUMEN TOTAL'!D11 -> AV. CALCHAQUI Y AV. DEL TRABAJO | D8: ='RESUMEN TOTAL'!E11 -> DOMO | E8: ='RESUMEN TOTAL'!F11 -> PTO A FO | F8: ='RESUMEN TOTAL'!K11 -> 0 | G8: ='RESUMEN TOTAL'!L11 -> 0 | H8: ='RESUMEN TOTAL'!M11 -> 0 | I8: ='RESUMEN TOTAL'!N11 -> 0 | J8: ='RESUMEN TOTAL'!O11 -> 0 | K8: ='RESUMEN TOTAL'!P11 -> 0 | L8: ='RESUMEN TOTAL'!Q11 -> 0 | M8: ='RESUMEN TOTAL'!R11 -> 0 | ... AG8: ='RESUMEN TOTAL'!AL11 -> 0 | AH8: ='RESUMEN TOTAL'!#REF! -> #REF! | AI8: ='RESUMEN TOTAL'!#REF! -> #REF! | AJ8: ='RESUMEN TOTAL'!#REF! -> #REF!
A9: ='RESUMEN TOTAL'!A12 -> ALTAMIRA | B9: ='RESUMEN TOTAL'!B12 -> ALT 08 | C9: ='RESUMEN TOTAL'!D12 -> HUMAITA Y NECOCHEA | D9: ='RESUMEN TOTAL'!E12 -> DOMO | E9: ='RESUMEN TOTAL'!F12 -> Fibra Optica | F9: ='RESUMEN TOTAL'!K12 -> 0 | G9: ='RESUMEN TOTAL'!L12 -> 0 | H9: ='RESUMEN TOTAL'!M12 -> 0 | I9: ='RESUMEN TOTAL'!N12 -> 0 | J9: ='RESUMEN TOTAL'!O12 -> 0 | K9: ='RESUMEN TOTAL'!P12 -> 0 | L9: ='RESUMEN TOTAL'!Q12 -> 0 | M9: ='RESUMEN TOTAL'!R12 -> 0 | ... AG9: ='RESUMEN TOTAL'!AL12 -> 0 | AH9: ='RESUMEN TOTAL'!#REF! -> #REF! | AI9: ='RESUMEN TOTAL'!#REF! -> #REF! | AJ9: ='RESUMEN TOTAL'!#REF! -> #REF!
A10: ='RESUMEN TOTAL'!A13 -> ALTAMIRA | B10: ='RESUMEN TOTAL'!B13 -> ALT 09 | C10: ='RESUMEN TOTAL'!D13 -> NECOCHEA Y CURUPAITY | D10: ='RESUMEN TOTAL'!E13 -> DOMO | E10: ='RESUMEN TOTAL'!F13 -> Fibra Optica | F10: ='RESUMEN TOTAL'!K13 -> 0 | G10: ='RESUMEN TOTAL'!L13 -> 0 | H10: ='RESUMEN TOTAL'!M13 -> 0 | I10: ='RESUMEN TOTAL'!N13 -> 0 | J10: ='RESUMEN TOTAL'!O13 -> 0 | K10: ='RESUMEN TOTAL'!P13 -> 0 | L10: ='RESUMEN TOTAL'!Q13 -> 0 | M10: ='RESUMEN TOTAL'!R13 -> 0 | ... AG10: ='RESUMEN TOTAL'!AL13 -> 0 | AH10: ='RESUMEN TOTAL'!#REF! -> #REF! | AI10: ='RESUMEN TOTAL'!#REF! -> #REF! | AJ10: ='RESUMEN TOTAL'!#REF! -> #REF!
A11: ='RESUMEN TOTAL'!A14 -> ALTAMIRA | B11: ='RESUMEN TOTAL'!B14 -> ALT 10 | C11: ='RESUMEN TOTAL'!D14 -> Calchaqui y Francia | D11: ='RESUMEN TOTAL'!E14 -> Domo | E11: ='RESUMEN TOTAL'!F14 -> Radio | F11: ='RESUMEN TOTAL'!K14 -> 0 | G11: ='RESUMEN TOTAL'!L14 -> 0 | H11: ='RESUMEN TOTAL'!M14 -> 0 | I11: ='RESUMEN TOTAL'!N14 -> 0 | J11: ='RESUMEN TOTAL'!O14 -> 0 | K11: ='RESUMEN TOTAL'!P14 -> 0 | L11: ='RESUMEN TOTAL'!Q14 -> 0 | M11: ='RESUMEN TOTAL'!R14 -> 0 | ... AG11: ='RESUMEN TOTAL'!AL14 -> 0 | AH11: ='RESUMEN TOTAL'!#REF! -> #REF! | AI11: ='RESUMEN TOTAL'!#REF! -> #REF! | AJ11: ='RESUMEN TOTAL'!#REF! -> #REF!
A12: ='RESUMEN TOTAL'!A15 -> AGUSTIN RAMIREZ | B12: ='RESUMEN TOTAL'!B15 -> ARA 01 | C12: ='RESUMEN TOTAL'!D15 -> Malambo y Tranquera | D12: ='RESUMEN TOTAL'!E15 -> Domo | E12: ='RESUMEN TOTAL'!F15 -> FIBRA OPTICA | F12: ='RESUMEN TOTAL'!K15 -> 0 | G12: ='RESUMEN TOTAL'!L15 -> 0 | H12: ='RESUMEN TOTAL'!M15 -> 0 | I12: ='RESUMEN TOTAL'!N15 -> 0 | J12: ='RESUMEN TOTAL'!O15 -> 0 | K12: ='RESUMEN TOTAL'!P15 -> 0 | L12: ='RESUMEN TOTAL'!Q15 -> 0 | M12: ='RESUMEN TOTAL'!R15 -> 0 | ... AG12: ='RESUMEN TOTAL'!AL15 -> 0 | AH12: ='RESUMEN TOTAL'!#REF! -> #REF! | AI12: ='RESUMEN TOTAL'!#REF! -> #REF! | AJ12: ='RESUMEN TOTAL'!#REF! -> #REF!
... A182: ='RESUMEN TOTAL'!A185 -> LOPEZ ROMERO | B182: ='RESUMEN TOTAL'!B185 -> LRO14 | C182: ='RESUMEN TOTAL'!D185 -> YRIGOYEN Y STORNI | D182: ='RESUMEN TOTAL'!E185 -> DOMO | E182: ='RESUMEN TOTAL'!F185 -> Fibra Optica | F182: ='RESUMEN TOTAL'!K185 -> 0 | G182: ='RESUMEN TOTAL'!L185 -> 0 | H182: ='RESUMEN TOTAL'!M185 -> 0 | I182: ='RESUMEN TOTAL'!N185 -> 0 | J182: ='RESUMEN TOTAL'!O185 -> 0 | K182: ='RESUMEN TOTAL'!P185 -> 0 | L182: ='RESUMEN TOTAL'!Q185 -> 0 | M182: ='RESUMEN TOTAL'!R185 -> 0 | ... AG182: ='RESUMEN TOTAL'!AL185 -> 0 | AH182: ='RESUMEN TOTAL'!#REF! -> #REF! | AI182: ='RESUMEN TOTAL'!#REF! -> #REF! | AJ182: ='RESUMEN TOTAL'!#REF! -> #REF!
A183: ='RESUMEN TOTAL'!A187 -> LUJAN | B183: ='RESUMEN TOTAL'!B187 -> LUJ 01 | C183: ='RESUMEN TOTAL'!D187 -> ñandu y Los Pinos | D183: ='RESUMEN TOTAL'!E187 -> Domo | E183: ='RESUMEN TOTAL'!F187 -> Radio | F183: ='RESUMEN TOTAL'!K187 -> 0 | G183: ='RESUMEN TOTAL'!L187 -> 0 | H183: ='RESUMEN TOTAL'!M187 -> 0 | I183: ='RESUMEN TOTAL'!N187 -> 0 | J183: ='RESUMEN TOTAL'!O187 -> 0 | K183: ='RESUMEN TOTAL'!P187 -> 0 | L183: ='RESUMEN TOTAL'!Q187 -> 0 | M183: ='RESUMEN TOTAL'!R187 -> 0 | ... AG183: ='RESUMEN TOTAL'!AL187 -> 0 | AH183: ='RESUMEN TOTAL'!#REF! -> #REF! | AI183: ='RESUMEN TOTAL'!#REF! -> #REF! | AJ183: ='RESUMEN TOTAL'!#REF! -> #REF!
A184: ='RESUMEN TOTAL'!A188 -> VILLA ARGENTINA | B184: ='RESUMEN TOTAL'!B188 -> LUJ 02 | C184: ='RESUMEN TOTAL'!D188 -> DIAG. LOS TILOS Y 527 | D184: ='RESUMEN TOTAL'!E188 -> DOMO | E184: ='RESUMEN TOTAL'!F188 -> Fibra Optica | F184: ='RESUMEN TOTAL'!K188 -> 0 | G184: ='RESUMEN TOTAL'!L188 -> 0 | H184: ='RESUMEN TOTAL'!M188 -> 0 | I184: ='RESUMEN TOTAL'!N188 -> 0 | J184: ='RESUMEN TOTAL'!O188 -> 0 | K184: ='RESUMEN TOTAL'!P188 -> 0 | L184: ='RESUMEN TOTAL'!Q188 -> 0 | M184: ='RESUMEN TOTAL'!R188 -> 0 | ... AG184: ='RESUMEN TOTAL'!AL188 -> 0 | AH184: ='RESUMEN TOTAL'!#REF! -> #REF! | AI184: ='RESUMEN TOTAL'!#REF! -> #REF! | AJ184: ='RESUMEN TOTAL'!#REF! -> #REF!
A185: ='RESUMEN TOTAL'!A189 -> LUJAN | B185: ='RESUMEN TOTAL'!B189 -> LUJ03 | C185: ='RESUMEN TOTAL'!D189 -> LOS PINOS Y LOS TILOS | D185: ='RESUMEN TOTAL'!E189 -> DOMO | E185: ='RESUMEN TOTAL'!F189 -> Fibra Optica | F185: ='RESUMEN TOTAL'!K189 -> 0 | G185: ='RESUMEN TOTAL'!L189 -> 0 | H185: ='RESUMEN TOTAL'!M189 -> 0 | I185: ='RESUMEN TOTAL'!N189 -> 0 | J185: ='RESUMEN TOTAL'!O189 -> 0 | K185: ='RESUMEN TOTAL'!P189 -> 0 | L185: ='RESUMEN TOTAL'!Q189 -> 0 | M185: ='RESUMEN TOTAL'!R189 -> 0 | ... AG185: ='RESUMEN TOTAL'!AL189 -> 0 | AH185: ='RESUMEN TOTAL'!#REF! -> #REF! | AI185: ='RESUMEN TOTAL'!#REF! -> #REF! | AJ185: ='RESUMEN TOTAL'!#REF! -> #REF!
A186: ='RESUMEN TOTAL'!A190 -> PRESIDENTE PERON (PEPSI) | B186: ='RESUMEN TOTAL'!B190 -> MAR 01 | C186: ='RESUMEN TOTAL'!D190 -> RP36 Y LA ESMERALDA | D186: ='RESUMEN TOTAL'!E190 -> DOMO | E186: ='RESUMEN TOTAL'!F190 -> FIBRA OPTICA | F186: ='RESUMEN TOTAL'!K190 -> 0 | G186: ='RESUMEN TOTAL'!L190 -> 0 | H186: ='RESUMEN TOTAL'!M190 -> 0 | I186: ='RESUMEN TOTAL'!N190 -> 0 | J186: ='RESUMEN TOTAL'!O190 -> 0 | K186: ='RESUMEN TOTAL'!P190 -> 0 | L186: ='RESUMEN TOTAL'!Q190 -> 0 | M186: ='RESUMEN TOTAL'!R190 -> 0 | ... AG186: ='RESUMEN TOTAL'!AL190 -> 0 | AH186: ='RESUMEN TOTAL'!#REF! -> #REF! | AI186: ='RESUMEN TOTAL'!#REF! -> #REF! | AJ186: ='RESUMEN TOTAL'!#REF! -> #REF!
A187: ='RESUMEN TOTAL'!A191 -> RICARDO ROJAS | B187: ='RESUMEN TOTAL'!B191 -> MAR 02 (FIJA1) | C187: ='RESUMEN TOTAL'!D191 -> LUJAN Y PATAGONES | D187: ='RESUMEN TOTAL'!E191 -> Fija | E187: ='RESUMEN TOTAL'!F191 -> Fibra Optica | F187: ='RESUMEN TOTAL'!K191 -> 0 | G187: ='RESUMEN TOTAL'!L191 -> 0 | H187: ='RESUMEN TOTAL'!M191 -> 0 | I187: ='RESUMEN TOTAL'!N191 -> 0 | J187: ='RESUMEN TOTAL'!O191 -> 0 | K187: ='RESUMEN TOTAL'!P191 -> 0 | L187: ='RESUMEN TOTAL'!Q191 -> 0 | M187: ='RESUMEN TOTAL'!R191 -> 0 | ... AG187: ='RESUMEN TOTAL'!AL191 -> 0 | AH187: ='RESUMEN TOTAL'!#REF! -> #REF! | AI187: ='RESUMEN TOTAL'!#REF! -> #REF! | AJ187: ='RESUMEN TOTAL'!#REF! -> #REF!
A188: ='RESUMEN TOTAL'!A192 -> LAS MARGARITAS | B188: ='RESUMEN TOTAL'!B192 -> MAR 03(FIJA 2) | C188: ='RESUMEN TOTAL'!D192 -> LUJAN Y PATAGONES | D188: ='RESUMEN TOTAL'!E192 -> Fija | E188: ='RESUMEN TOTAL'!F192 -> Fibra Optica | F188: ='RESUMEN TOTAL'!K192 -> 0 | G188: ='RESUMEN TOTAL'!L192 -> 0 | H188: ='RESUMEN TOTAL'!M192 -> 0 | I188: ='RESUMEN TOTAL'!N192 -> 0 | J188: ='RESUMEN TOTAL'!O192 -> 0 | K188: ='RESUMEN TOTAL'!P192 -> 0 | L188: ='RESUMEN TOTAL'!Q192 -> 0 | M188: ='RESUMEN TOTAL'!R192 -> 0 | ... AG188: ='RESUMEN TOTAL'!AL192 -> 0 | AH188: ='RESUMEN TOTAL'!#REF! -> #REF! | AI188: ='RESUMEN TOTAL'!#REF! -> #REF! | AJ188: ='RESUMEN TOTAL'!#REF! -> #REF!
A189: ='RESUMEN TOTAL'!A193 -> MAYOL | B189: ='RESUMEN TOTAL'!B193 -> MAY 01 | C189: ='RESUMEN TOTAL'!D193 -> Eva Peron y Cabildo | D189: ='RESUMEN TOTAL'!E193 -> Domo | E189: ='RESUMEN TOTAL'!F193 -> Radio | F189: ='RESUMEN TOTAL'!K193 -> 0 | G189: ='RESUMEN TOTAL'!L193 -> 0 | H189: ='RESUMEN TOTAL'!M193 -> 0 | I189: ='RESUMEN TOTAL'!N193 -> 0 | J189: ='RESUMEN TOTAL'!O193 -> 0 | K189: ='RESUMEN TOTAL'!P193 -> 0 | L189: ='RESUMEN TOTAL'!Q193 -> 0 | M189: ='RESUMEN TOTAL'!R193 -> 0 | ... AG189: ='RESUMEN TOTAL'!AL193 -> 0 | AH189: ='RESUMEN TOTAL'!#REF! -> #REF! | AI189: ='RESUMEN TOTAL'!#REF! -> #REF! | AJ189: ='RESUMEN TOTAL'!#REF! -> #REF!
A190: ='RESUMEN TOTAL'!A194 -> MAYOL | B190: ='RESUMEN TOTAL'!B194 -> MAY 02 | C190: ='RESUMEN TOTAL'!D194 -> EVA PERON Y MONTEVIDEO | D190: ='RESUMEN TOTAL'!E194 -> Domo | E190: ='RESUMEN TOTAL'!F194 -> Radio | F190: ='RESUMEN TOTAL'!K194 -> 0 | G190: ='RESUMEN TOTAL'!L194 -> 0 | H190: ='RESUMEN TOTAL'!M194 -> 0 | I190: ='RESUMEN TOTAL'!N194 -> 0 | J190: ='RESUMEN TOTAL'!O194 -> 0 | K190: ='RESUMEN TOTAL'!P194 -> 0 | L190: ='RESUMEN TOTAL'!Q194 -> 0 | M190: ='RESUMEN TOTAL'!R194 -> 0 | ... AG190: ='RESUMEN TOTAL'!AL194 -> 0 | AH190: ='RESUMEN TOTAL'!#REF! -> #REF! | AI190: ='RESUMEN TOTAL'!#REF! -> #REF! | AJ190: ='RESUMEN TOTAL'!#REF! -> #REF!
A191: ='RESUMEN TOTAL'!A195 -> MAYOL | B191: ='RESUMEN TOTAL'!B195 -> MAY 03 | C191: ='RESUMEN TOTAL'!D195 -> CHAÑAR Y SAN NICOLAS | D191: ='RESUMEN TOTAL'!E195 -> DOMO | E191: ='RESUMEN TOTAL'!F195 -> PTO A FO | F191: ='RESUMEN TOTAL'!K195 -> 0 | G191: ='RESUMEN TOTAL'!L195 -> 0 | H191: ='RESUMEN TOTAL'!M195 -> 0 | I191: ='RESUMEN TOTAL'!N195 -> 0 | J191: ='RESUMEN TOTAL'!O195 -> 0 | K191: ='RESUMEN TOTAL'!P195 -> 0 | L191: ='RESUMEN TOTAL'!Q195 -> 0 | M191: ='RESUMEN TOTAL'!R195 -> 0 | ... AG191: ='RESUMEN TOTAL'!AL195 -> 0 | AH191: ='RESUMEN TOTAL'!#REF! -> #REF! | AI191: ='RESUMEN TOTAL'!#REF! -> #REF! | AJ191: ='RESUMEN TOTAL'!#REF! -> #REF!
A192: ='RESUMEN TOTAL'!A196 -> MAYOL | B192: ='RESUMEN TOTAL'!B196 -> MAY 04 | C192: ='RESUMEN TOTAL'!D196 -> MAR CHIQUITA Y RIO JACHAL | D192: ='RESUMEN TOTAL'!E196 -> DOMO | E192: ='RESUMEN TOTAL'!F196 -> Radio | F192: ='RESUMEN TOTAL'!K196 -> 0 | G192: ='RESUMEN TOTAL'!L196 -> 0 | H192: ='RESUMEN TOTAL'!M196 -> 0 | I192: ='RESUMEN TOTAL'!N196 -> 0 | J192: ='RESUMEN TOTAL'!O196 -> 0 | K192: ='RESUMEN TOTAL'!P196 -> 0 | L192: ='RESUMEN TOTAL'!Q196 -> 0 | M192: ='RESUMEN TOTAL'!R196 -> 0 | ... AG192: ='RESUMEN TOTAL'!AL196 -> 0 | AH192: ='RESUMEN TOTAL'!#REF! -> #REF! | AI192: ='RESUMEN TOTAL'!#REF! -> #REF! | AJ192: ='RESUMEN TOTAL'!#REF! -> #REF!
A193: ='RESUMEN TOTAL'!A197 -> MARTIN FIERRO | B193: ='RESUMEN TOTAL'!B197 -> MFI 01 | C193: ='RESUMEN TOTAL'!D197 -> Belgrano y Sgto. Cabral | D193: ='RESUMEN TOTAL'!E197 -> Fija | E193: ='RESUMEN TOTAL'!F197 -> Fibra Optica | F193: ='RESUMEN TOTAL'!K197 -> 0 | G193: ='RESUMEN TOTAL'!L197 -> 0 | H193: ='RESUMEN TOTAL'!M197 -> 0 | I193: ='RESUMEN TOTAL'!N197 -> 0 | J193: ='RESUMEN TOTAL'!O197 -> 0 | K193: ='RESUMEN TOTAL'!P197 -> 0 | L193: ='RESUMEN TOTAL'!Q197 -> 0 | M193: ='RESUMEN TOTAL'!R197 -> 0 | ... AG193: ='RESUMEN TOTAL'!AL197 -> 0 | AH193: ='RESUMEN TOTAL'!#REF! -> #REF! | AI193: ='RESUMEN TOTAL'!#REF! -> #REF! | AJ193: ='RESUMEN TOTAL'!#REF! -> #REF!
A194: ='RESUMEN TOTAL'!A198 -> LOPEZ ROMERO | B194: ='RESUMEN TOTAL'!B198 -> MFI02 | C194: ='RESUMEN TOTAL'!D198 -> Calchaqui y Balcarce | D194: ='RESUMEN TOTAL'!E198 -> Fija | E194: ='RESUMEN TOTAL'!F198 -> Fibra Optica | F194: ='RESUMEN TOTAL'!K198 -> 0 | G194: ='RESUMEN TOTAL'!L198 -> 0 | H194: ='RESUMEN TOTAL'!M198 -> 0 | I194: ='RESUMEN TOTAL'!N198 -> 0 | J194: ='RESUMEN TOTAL'!O198 -> 0 | K194: ='RESUMEN TOTAL'!P198 -> 0 | L194: ='RESUMEN TOTAL'!Q198 -> 0 | M194: ='RESUMEN TOTAL'!R198 -> 0 | ... AG194: ='RESUMEN TOTAL'!AL198 -> 0 | AH194: ='RESUMEN TOTAL'!#REF! -> #REF! | AI194: ='RESUMEN TOTAL'!#REF! -> #REF! | AJ194: ='RESUMEN TOTAL'!#REF! -> #REF!
... A435: ='RESUMEN TOTAL'!A439 -> ZEBALLOS | B435: ='RESUMEN TOTAL'!B439 -> ZEB 05 | C435: ='RESUMEN TOTAL'!D439 -> DIAG. GRANADEROS Y 214 BIS | D435: ='RESUMEN TOTAL'!E439 -> Domo | E435: ='RESUMEN TOTAL'!F439 -> Radio | F435: ='RESUMEN TOTAL'!K439 -> 0 | G435: ='RESUMEN TOTAL'!L439 -> 0 | H435: ='RESUMEN TOTAL'!M439 -> 0 | I435: ='RESUMEN TOTAL'!N439 -> 0 | J435: ='RESUMEN TOTAL'!O439 -> 0 | K435: ='RESUMEN TOTAL'!P439 -> 0 | L435: ='RESUMEN TOTAL'!Q439 -> 0 | M435: ='RESUMEN TOTAL'!R439 -> 0 | ... AG435: ='RESUMEN TOTAL'!AL439 -> 0 | AH435: ='RESUMEN TOTAL'!#REF! -> #REF! | AI435: ='RESUMEN TOTAL'!#REF! -> #REF! | AJ435: ='RESUMEN TOTAL'!#REF! -> #REF!
A436: ='RESUMEN TOTAL'!A186 -> LOPEZ ROMERO | B436: ='RESUMEN TOTAL'!B186 -> LRO15 | C436: ='RESUMEN TOTAL'!D186 -> BRAILE Y FINOCCHIETTO | D436: ='RESUMEN TOTAL'!E186 -> DOMO | E436: ='RESUMEN TOTAL'!F186 -> Fibra Optica | F436: ='RESUMEN TOTAL'!K186 -> 0 | G436: ='RESUMEN TOTAL'!L186 -> 0 | H436: ='RESUMEN TOTAL'!M186 -> 0 | I436: ='RESUMEN TOTAL'!N186 -> 0 | J436: ='RESUMEN TOTAL'!O186 -> 0 | K436: ='RESUMEN TOTAL'!P186 -> 0 | L436: ='RESUMEN TOTAL'!Q186 -> 0 | M436: ='RESUMEN TOTAL'!R186 -> 0 | ... AG436: ='RESUMEN TOTAL'!AL186 -> 0 | AH436: ='RESUMEN TOTAL'!#REF! -> #REF! | AI436: ='RESUMEN TOTAL'!#REF! -> #REF! | AJ436: ='RESUMEN TOTAL'!#REF! -> #REF!
A437: ='RESUMEN TOTAL'!B440 -> 0 | B437: ='RESUMEN TOTAL'!#REF! -> #REF! | C437: ='RESUMEN TOTAL'!D440 -> 0 | D437: ='RESUMEN TOTAL'!E440 -> 0 | E437: ='RESUMEN TOTAL'!F440 -> 0 | F437: ='RESUMEN TOTAL'!K440 -> 0 | G437: ='RESUMEN TOTAL'!L440 -> 0 | H437: ='RESUMEN TOTAL'!M440 -> 0 | I437: ='RESUMEN TOTAL'!N440 -> 0 | J437: ='RESUMEN TOTAL'!O440 -> 0 | K437: ='RESUMEN TOTAL'!P440 -> 0 | L437: ='RESUMEN TOTAL'!Q440 -> 0 | M437: ='RESUMEN TOTAL'!R440 -> 0 | ... AG437: ='RESUMEN TOTAL'!AL440 -> 0 | AH437: ='RESUMEN TOTAL'!#REF! -> #REF! | AI437: ='RESUMEN TOTAL'!#REF! -> #REF! | AJ437: ='RESUMEN TOTAL'!#REF! -> #REF!
A438: ='RESUMEN TOTAL'!A441 -> 0 | B438: ='RESUMEN TOTAL'!B441 -> 0 | C438: ='RESUMEN TOTAL'!D441 -> 0 | D438: ='RESUMEN TOTAL'!E441 -> 0 | E438: ='RESUMEN TOTAL'!F441 -> 0 | F438: ='RESUMEN TOTAL'!K441 -> 0 | G438: ='RESUMEN TOTAL'!L441 -> 0 | H438: ='RESUMEN TOTAL'!M441 -> 0 | I438: ='RESUMEN TOTAL'!N441 -> 0 | J438: ='RESUMEN TOTAL'!O441 -> 0 | K438: ='RESUMEN TOTAL'!P441 -> 0 | L438: ='RESUMEN TOTAL'!Q441 -> 0 | M438: ='RESUMEN TOTAL'!R441 -> 0 | ... AG438: ='RESUMEN TOTAL'!AL441 -> 0 | AH438: ='RESUMEN TOTAL'!#REF! -> #REF! | AI438: ='RESUMEN TOTAL'!#REF! -> #REF! | AJ438: ='RESUMEN TOTAL'!#REF! -> #REF!
A439: ='RESUMEN TOTAL'!A442 -> 0 | B439: ='RESUMEN TOTAL'!B442 -> 0 | C439: ='RESUMEN TOTAL'!D442 -> 0 | D439: ='RESUMEN TOTAL'!E442 -> 0 | E439: ='RESUMEN TOTAL'!F442 -> 0 | F439: ='RESUMEN TOTAL'!K442 -> 0 | G439: ='RESUMEN TOTAL'!L442 -> 0 | H439: ='RESUMEN TOTAL'!M442 -> 0 | I439: ='RESUMEN TOTAL'!N442 -> 0 | J439: ='RESUMEN TOTAL'!O442 -> 0 | K439: ='RESUMEN TOTAL'!P442 -> 0 | L439: ='RESUMEN TOTAL'!Q442 -> 0 | M439: ='RESUMEN TOTAL'!R442 -> 0 | ... AG439: ='RESUMEN TOTAL'!AL442 -> 0 | AH439: ='RESUMEN TOTAL'!#REF! -> #REF! | AI439: ='RESUMEN TOTAL'!#REF! -> #REF! | AJ439: ='RESUMEN TOTAL'!#REF! -> #REF!
A440: ='RESUMEN TOTAL'!A443 -> 0 | B440: ='RESUMEN TOTAL'!B443 -> 0 | C440: ='RESUMEN TOTAL'!D443 -> 0 | D440: ='RESUMEN TOTAL'!E443 -> 0 | E440: ='RESUMEN TOTAL'!F443 -> 0 | F440: ='RESUMEN TOTAL'!K443 -> 0 | G440: ='RESUMEN TOTAL'!L443 -> 0 | H440: ='RESUMEN TOTAL'!M443 -> 0 | I440: ='RESUMEN TOTAL'!N443 -> 0 | J440: ='RESUMEN TOTAL'!O443 -> 0 | K440: ='RESUMEN TOTAL'!P443 -> 0 | L440: ='RESUMEN TOTAL'!Q443 -> 0 | M440: ='RESUMEN TOTAL'!R443 -> 0 | ... AG440: ='RESUMEN TOTAL'!AL443 -> 0 | AH440: ='RESUMEN TOTAL'!#REF! -> #REF! | AI440: ='RESUMEN TOTAL'!#REF! -> #REF! | AJ440: ='RESUMEN TOTAL'!#REF! -> #REF!
A441: ='RESUMEN TOTAL'!A444 -> 0 | B441: ='RESUMEN TOTAL'!B444 -> 0 | C441: ='RESUMEN TOTAL'!D444 -> 0 | D441: ='RESUMEN TOTAL'!E444 -> 0 | E441: ='RESUMEN TOTAL'!F444 -> 0 | F441: ='RESUMEN TOTAL'!K444 -> 0 | G441: ='RESUMEN TOTAL'!L444 -> 0 | H441: ='RESUMEN TOTAL'!M444 -> 0 | I441: ='RESUMEN TOTAL'!N444 -> 0 | J441: ='RESUMEN TOTAL'!O444 -> 0 | K441: ='RESUMEN TOTAL'!P444 -> 0 | L441: ='RESUMEN TOTAL'!Q444 -> 0 | M441: ='RESUMEN TOTAL'!R444 -> 0 | ... AG441: ='RESUMEN TOTAL'!AL444 -> 0 | AH441: ='RESUMEN TOTAL'!#REF! -> #REF! | AI441: ='RESUMEN TOTAL'!#REF! -> #REF! | AJ441: ='RESUMEN TOTAL'!#REF! -> #REF!
A442: ='RESUMEN TOTAL'!A445 -> 0 | B442: ='RESUMEN TOTAL'!B445 -> 0 | C442: ='RESUMEN TOTAL'!D445 -> 0 | D442: ='RESUMEN TOTAL'!E445 -> 0 | E442: ='RESUMEN TOTAL'!F445 -> 0 | F442: ='RESUMEN TOTAL'!K445 -> 0 | G442: ='RESUMEN TOTAL'!L445 -> 0 | H442: ='RESUMEN TOTAL'!M445 -> 0 | I442: ='RESUMEN TOTAL'!N445 -> 0 | J442: ='RESUMEN TOTAL'!O445 -> 0 | K442: ='RESUMEN TOTAL'!P445 -> 0 | L442: ='RESUMEN TOTAL'!Q445 -> 0 | M442: ='RESUMEN TOTAL'!R445 -> 0 | ... AG442: ='RESUMEN TOTAL'!AL445 -> 0 | AH442: ='RESUMEN TOTAL'!#REF! -> #REF! | AI442: ='RESUMEN TOTAL'!#REF! -> #REF! | AJ442: ='RESUMEN TOTAL'!#REF! -> #REF!
A443: ='RESUMEN TOTAL'!A446 -> 0 | B443: ='RESUMEN TOTAL'!B446 -> 0 | C443: ='RESUMEN TOTAL'!D446 -> 0 | D443: ='RESUMEN TOTAL'!E446 -> 0 | E443: ='RESUMEN TOTAL'!F446 -> 0 | F443: ='RESUMEN TOTAL'!K446 -> 0 | G443: ='RESUMEN TOTAL'!L446 -> 0 | H443: ='RESUMEN TOTAL'!M446 -> 0 | I443: ='RESUMEN TOTAL'!N446 -> 0 | J443: ='RESUMEN TOTAL'!O446 -> 0 | K443: ='RESUMEN TOTAL'!P446 -> 0 | L443: ='RESUMEN TOTAL'!Q446 -> 0 | M443: ='RESUMEN TOTAL'!R446 -> 0 | ... AG443: ='RESUMEN TOTAL'!AL446 -> 0 | AH443: ='RESUMEN TOTAL'!#REF! -> #REF! | AI443: ='RESUMEN TOTAL'!#REF! -> #REF! | AJ443: ='RESUMEN TOTAL'!#REF! -> #REF!
A444: ='RESUMEN TOTAL'!A447 -> 0 | B444: ='RESUMEN TOTAL'!B447 -> 0 | C444: ='RESUMEN TOTAL'!D447 -> 0 | D444: ='RESUMEN TOTAL'!E447 -> 0 | E444: ='RESUMEN TOTAL'!F447 -> 0 | F444: ='RESUMEN TOTAL'!K447 -> 0 | G444: ='RESUMEN TOTAL'!L447 -> 0 | H444: ='RESUMEN TOTAL'!M447 -> 0 | I444: ='RESUMEN TOTAL'!N447 -> 0 | J444: ='RESUMEN TOTAL'!O447 -> 0 | K444: ='RESUMEN TOTAL'!P447 -> 0 | L444: ='RESUMEN TOTAL'!Q447 -> 0 | M444: ='RESUMEN TOTAL'!R447 -> 0 | ... AG444: ='RESUMEN TOTAL'!AL447 -> 0 | AH444: ='RESUMEN TOTAL'!#REF! -> #REF! | AI444: ='RESUMEN TOTAL'!#REF! -> #REF! | AJ444: ='RESUMEN TOTAL'!#REF! -> #REF!
A445: ='RESUMEN TOTAL'!A448 -> 0 | B445: ='RESUMEN TOTAL'!B448 -> 0 | C445: ='RESUMEN TOTAL'!D448 -> 0 | D445: ='RESUMEN TOTAL'!E448 -> 0 | E445: ='RESUMEN TOTAL'!F448 -> 0 | F445: ='RESUMEN TOTAL'!K448 -> 0 | G445: ='RESUMEN TOTAL'!L448 -> 0 | H445: ='RESUMEN TOTAL'!M448 -> 0 | I445: ='RESUMEN TOTAL'!N448 -> 0 | J445: ='RESUMEN TOTAL'!O448 -> 0 | K445: ='RESUMEN TOTAL'!P448 -> 0 | L445: ='RESUMEN TOTAL'!Q448 -> 0 | M445: ='RESUMEN TOTAL'!R448 -> 0 | ... AG445: ='RESUMEN TOTAL'!AL448 -> 0 | AH445: ='RESUMEN TOTAL'!#REF! -> #REF! | AI445: ='RESUMEN TOTAL'!#REF! -> #REF! | AJ445: ='RESUMEN TOTAL'!#REF! -> #REF!
A446: ='RESUMEN TOTAL'!A449 -> 0 | B446: ='RESUMEN TOTAL'!B449 -> 0 | C446: ='RESUMEN TOTAL'!D449 -> 0 | D446: ='RESUMEN TOTAL'!E449 -> 0 | E446: ='RESUMEN TOTAL'!F449 -> 0 | F446: ='RESUMEN TOTAL'!K449 -> 0 | G446: ='RESUMEN TOTAL'!L449 -> 0 | H446: ='RESUMEN TOTAL'!M449 -> 0 | I446: ='RESUMEN TOTAL'!N449 -> 0 | J446: ='RESUMEN TOTAL'!O449 -> 0 | K446: ='RESUMEN TOTAL'!P449 -> 0 | L446: ='RESUMEN TOTAL'!Q449 -> 0 | M446: ='RESUMEN TOTAL'!R449 -> 0 | ... AG446: ='RESUMEN TOTAL'!AL449 -> 0 | AH446: ='RESUMEN TOTAL'!#REF! -> #REF! | AI446: ='RESUMEN TOTAL'!#REF! -> #REF! | AJ446: ='RESUMEN TOTAL'!#REF! -> #REF!
A447: ='RESUMEN TOTAL'!A450 -> 0 | B447: ='RESUMEN TOTAL'!B450 -> 0 | C447: ='RESUMEN TOTAL'!D450 -> 0 | D447: ='RESUMEN TOTAL'!E450 -> 0 | E447: ='RESUMEN TOTAL'!F450 -> 0 | F447: ='RESUMEN TOTAL'!K450 -> 0 | G447: ='RESUMEN TOTAL'!L450 -> 0 | H447: ='RESUMEN TOTAL'!M450 -> 0 | I447: ='RESUMEN TOTAL'!N450 -> 0 | J447: ='RESUMEN TOTAL'!O450 -> 0 | K447: ='RESUMEN TOTAL'!P450 -> 0 | L447: ='RESUMEN TOTAL'!Q450 -> 0 | M447: ='RESUMEN TOTAL'!R450 -> 0 | ... AG447: ='RESUMEN TOTAL'!AL450 -> 0 | AH447: ='RESUMEN TOTAL'!#REF! -> #REF! | AI447: ='RESUMEN TOTAL'!#REF! -> #REF! | AJ447: ='RESUMEN TOTAL'!#REF! -> #REF!
A448: ='RESUMEN TOTAL'!A451 -> 0 | B448: ='RESUMEN TOTAL'!B451 -> 0 | C448: ='RESUMEN TOTAL'!D451 -> 0 | D448: ='RESUMEN TOTAL'!E451 -> 0 | E448: ='RESUMEN TOTAL'!F451 -> 0 | F448: ='RESUMEN TOTAL'!K451 -> 0 | G448: ='RESUMEN TOTAL'!L451 -> 0 | H448: ='RESUMEN TOTAL'!M451 -> 0 | I448: ='RESUMEN TOTAL'!N451 -> 0 | J448: ='RESUMEN TOTAL'!O451 -> 0 | K448: ='RESUMEN TOTAL'!P451 -> 0 | L448: ='RESUMEN TOTAL'!Q451 -> 0 | M448: ='RESUMEN TOTAL'!R451 -> 0 | ... AG448: ='RESUMEN TOTAL'!AL451 -> 0 | AH448: ='RESUMEN TOTAL'!#REF! -> #REF! | AI448: ='RESUMEN TOTAL'!#REF! -> #REF! | AJ448: ='RESUMEN TOTAL'!#REF! -> #REF!
A449: ='RESUMEN TOTAL'!A452 -> 0 | B449: ='RESUMEN TOTAL'!B452 -> 0 | C449: ='RESUMEN TOTAL'!D452 -> 0 | D449: ='RESUMEN TOTAL'!E452 -> 0 | E449: ='RESUMEN TOTAL'!F452 -> 0 | F449: ='RESUMEN TOTAL'!K452 -> 0 | G449: ='RESUMEN TOTAL'!L452 -> 0 | H449: ='RESUMEN TOTAL'!M452 -> 0 | I449: ='RESUMEN TOTAL'!N452 -> 0 | J449: ='RESUMEN TOTAL'!O452 -> 0 | K449: ='RESUMEN TOTAL'!P452 -> 0 | L449: ='RESUMEN TOTAL'!Q452 -> 0 | M449: ='RESUMEN TOTAL'!R452 -> 0 | ... AG449: ='RESUMEN TOTAL'!AL452 -> 0 | AH449: ='RESUMEN TOTAL'!#REF! -> #REF! | AI449: ='RESUMEN TOTAL'!#REF! -> #REF! | AJ449: ='RESUMEN TOTAL'!#REF! -> #REF!
...

Sheet APAGADOS
E1: APAGADOS | F1: =COUNTIF(F3:F400, "APAGADO") -> 26 | G1: =COUNTIF(G3:G400, "APAGADO") -> 30 | H1: =COUNTIF(H3:H500, "APAGADO") -> 36 | I1: =COUNTIF(I3:I400, "APAGADO") -> 0 | J1: =COUNTIF(J3:J400, "APAGADO") -> 33 | K1: =COUNTIF(K3:K400, "APAGADO") -> 31 | L1: =COUNTIF(L3:L400, "APAGADO") -> 38 | M1: =COUNTIF(M3:M400, "APAGADO") -> 0 | N1: =COUNTIF(N3:N400, "APAGADO") -> 0 | O1: =COUNTIF(O3:O400, "APAGADO") -> 0 | P1: =COUNTIF(P3:P400, "APAGADO") -> 0 | ... AD1: =COUNTIF(AD3:AD400, "APAGADO") -> 0 | AE1: =COUNTIF(AE3:AE500, "APAGADO") -> 0 | AF1: =COUNTIF(AF3:AF400, "APAGADO") -> 0 | AG1: =COUNTIF(AG3:AG400, "APAGADO") -> 0 | AH1: =COUNTIF(AH3:AH400, "APAGADO") -> 0 | AI1: =COUNTIF(AI3:AI400, "APAGADO") -> 0
A2: =ESTADISTICA!A1 -> Barrio | B2: =ESTADISTICA!B1 -> [Denominacion] | C2: =ESTADISTICA!C1 -> [Ubicacion] | D2: =ESTADISTICA!D1 -> [Tipo de Camara] | E2: =ESTADISTICA!E1 -> [Tipo de Conexion] | F2: =ESTADISTICA!F1 -> 44958 | G2: =ESTADISTICA!G1 -> 44959 | H2: =ESTADISTICA!H1 -> 44960 | ... AI2: =ESTADISTICA!AI1 -> #REF!
A3: =ESTADISTICA!A2 -> ALTAMIRA | B3: =ESTADISTICA!B2 -> ALT01 | C3: =ESTADISTICA!C2 -> Calchaqui y Sgto. Cabral | D3: =ESTADISTICA!D2 -> Domo | E3: =ESTADISTICA!E2 -> Fibra Optica | F3: =ESTADISTICA!F2 -> 0 | G3: =ESTADISTICA!G2 -> 0 | H3: =ESTADISTICA!H2 -> 0 | ... AI3: =ESTADISTICA!AI2 -> #REF!
A4: =ESTADISTICA!A3 -> ALTAMIRA | B4: =ESTADISTICA!B3 -> ALT02 | C4: =ESTADISTICA!C3 -> Calchaqui y Lope de Vega | D4: =ESTADISTICA!D3 -> Domo | E4: =ESTADISTICA!E3 -> PTO A FO | F4: =ESTADISTICA!F3 -> 0 | G4: =ESTADISTICA!G3 -> 0 | H4: =ESTADISTICA!H3 -> 0 | ... AI4: =ESTADISTICA!AI3 -> #REF!
A5: =ESTADISTICA!A4 -> ALTAMIRA | B5: =ESTADISTICA!B4 -> ALT 03 | C5: =ESTADISTICA!C4 -> Bombero Galarza y Necochea | D5: =ESTADISTICA!D4 -> Domo | E5: =ESTADISTICA!E4 -> FIBRA OPTICA | F5: =ESTADISTICA!F4 -> 0 | G5: =ESTADISTICA!G4 -> 0 | H5: =ESTADISTICA!H4 -> 0 | ... AI5: =ESTADISTICA!AI4 -> #REF!
A6: =ESTADISTICA!A5 -> ALTAMIRA | B6: =ESTADISTICA!B5 -> ALT 04 | C6: =ESTADISTICA!C5 -> Francia y Necochea | D6: =ESTADISTICA!D5 -> Domo | E6: =ESTADISTICA!E5 -> FIBRA OPTICA | F6: =ESTADISTICA!F5 -> 0 | G6: =ESTADISTICA!G5 -> 0 | H6: =ESTADISTICA!H5 -> 0 | ... AI6: =ESTADISTICA!AI5 -> #REF!
A7: =ESTADISTICA!A6 -> ALTAMIRA | B7: =ESTADISTICA!B6 -> ALT05 | C7: =ESTADISTICA!C6 -> Av. Calchaqui y Bombero Galarza | D7: =ESTADISTICA!D6 -> Domo | E7: =ESTADISTICA!E6 -> PTO A FO | F7: =ESTADISTICA!F6 -> 0 | G7: =ESTADISTICA!G6 -> 0 | H7: =ESTADISTICA!H6 -> 0 | ... AI7: =ESTADISTICA!AI6 -> #REF!
A8: =ESTADISTICA!A7 -> ALTAMIRA | B8: =ESTADISTICA!B7 -> ALT 06 | C8: =ESTADISTICA!C7 -> LOPE DE VEGA Y NECOCHEA | D8: =ESTADISTICA!D7 -> Domo | E8: =ESTADISTICA!E7 -> PTO A FO | F8: =ESTADISTICA!F7 -> 0 | G8: =ESTADISTICA!G7 -> 0 | H8: =ESTADISTICA!H7 -> 0 | ... AI8: =ESTADISTICA!AI7 -> #REF!
A9: =ESTADISTICA!A8 -> ALTAMIRA | B9: =ESTADISTICA!B8 -> ALT07 | C9: =ESTADISTICA!C8 -> AV. CALCHAQUI Y AV. DEL TRABAJO | D9: =ESTADISTICA!D8 -> DOMO | E9: =ESTADISTICA!E8 -> PTO A FO | F9: =ESTADISTICA!F8 -> 0 | G9: =ESTADISTICA!G8 -> 0 | H9: =ESTADISTICA!H8 -> 0 | ... AI9: =ESTADISTICA!AI8 -> #REF!
A10: =ESTADISTICA!A9 -> ALTAMIRA | B10: =ESTADISTICA!B9 -> ALT 08 | C10: =ESTADISTICA!C9 -> HUMAITA Y NECOCHEA | D10: =ESTADISTICA!D9 -> DOMO | E10: =ESTADISTICA!E9 -> Fibra Optica | F10: =ESTADISTICA!F9 -> 0 | G10: =ESTADISTICA!G9 -> 0 | H10: =ESTADISTICA!H9 -> 0 | ... AI10: =ESTADISTICA!AI9 -> #REF!
A11: =ESTADISTICA!A10 -> ALTAMIRA | B11: =ESTADISTICA!B10 -> ALT 09 | C11: =ESTADISTICA!C10 -> NECOCHEA Y CURUPAITY | D11: =ESTADISTICA!D10 -> DOMO | E11: =ESTADISTICA!E10 -> Fibra Optica | F11: =ESTADISTICA!F10 -> 0 | G11: =ESTADISTICA!G10 -> 0 | H11: =ESTADISTICA!H10 -> 0 | ... AI11: =ESTADISTICA!AI10 -> #REF!
A12: =ESTADISTICA!A11 -> ALTAMIRA | B12: =ESTADISTICA!B11 -> ALT 10 | C12: =ESTADISTICA!C11 -> Calchaqui y Francia | D12: =ESTADISTICA!D11 -> Domo | E12: =ESTADISTICA!E11 -> Radio | F12: =ESTADISTICA!F11 -> 0 | G12: =ESTADISTICA!G11 -> 0 | H12: =ESTADISTICA!H11 -> 0 | ... AI12: =ESTADISTICA!AI11 -> #REF!
A13: =ESTADISTICA!A12 -> AGUSTIN RAMIREZ | B13: =ESTADISTICA!B12 -> ARA 01 | C13: =ESTADISTICA!C12 -> Malambo y Tranquera | D13: =ESTADISTICA!D12 -> Domo | E13: =ESTADISTICA!E12 -> FIBRA OPTICA | F13: =ESTADISTICA!F12 -> 0 | G13: =ESTADISTICA!G12 -> 0 | H13: =ESTADISTICA!H12 -> 0 | ... AI13: =ESTADISTICA!AI12 -> #REF!
... A513: =ESTADISTICA!A512 -> 0 | B513: =ESTADISTICA!B512 -> 0 | C513: =ESTADISTICA!C512 -> 0 | D513: =ESTADISTICA!D512 -> 0 | E513: =ESTADISTICA!E512 -> 0 | F513: =ESTADISTICA!F512 -> 0 | G513: =ESTADISTICA!G512 -> 0 | H513: =ESTADISTICA!H512 -> 0 | ... AI513: =ESTADISTICA!AI512 -> #REF!

Sheet APAGADOS FIBRA
C1: TOTAL FIBRA | D1: =COUNTIFS(E4:E400,"=Fibra Optica") -> 266
E2: APAGADOS | F2: =COUNTIFS(F4:F500, "=APAGADO",E4:E500,"=Fibra Optica") -> 23 | G2: =COUNTIFS(G4:G500, "=APAGADO",E4:E500,"=Fibra Optica") -> 22 | H2: =COUNTIFS(H4:H500, "=APAGADO",E4:E500,"=Fibra Optica") -> 29 | I2: =COUNTIFS(I4:I500, "=APAGADO",E4:E500,"=Fibra Optica") -> 0 | J2: =COUNTIFS(J4:J500, "=APAGADO",E4:E500,"=Fibra Optica") -> 26 | K2: =COUNTIFS(K4:K500, "=APAGADO",E4:E500,"=Fibra Optica") -> 27 | L2: =COUNTIFS(L4:L500, "=APAGADO",E4:E500,"=Fibra Optica") -> 27 | M2: =COUNTIFS(M4:M500, "=APAGADO",E4:E500,"=Fibra Optica") -> 0 | N2: =COUNTIFS(N4:N500, "=APAGADO",E4:E500,"=Fibra Optica") -> 0 | O2: =COUNTIFS(O4:O500, "=APAGADO",E4:E500,"=Fibra Optica") -> 0 | P2: =COUNTIFS(P4:P500, "=APAGADO",E4:E500,"=Fibra Optica") -> 0 | Q2: =COUNTIFS(Q4:Q500, "=APAGADO",E4:E500,"=Fibra Optica") -> 0 | R2: =COUNTIFS(R4:R500, "=APAGADO",E4:E500,"=Fibra Optica") -> 0 | S2: =COUNTIFS(S4:S500, "=APAGADO",E4:E500,"=Fibra Optica") -> 0 | T2: =COUNTIFS(T4:T500, "=APAGADO",E4:E500,"=Fibra Optica") -> 0 | U2: =COUNTIFS(U4:U500, "=APAGADO",E4:E500,"=Fibra Optica") -> 0 | V2: =COUNTIFS(V4:V500, "=APAGADO",E4:E500,"=Fibra Optica") -> 0 | W2: =COUNTIFS(W4:W500, "=APAGADO",E4:E500,"=Fibra Optica") -> 0 | X2: =COUNTIFS(X4:X500, "=APAGADO",E4:E500,"=Fibra Optica") -> 0 | Y2: =COUNTIFS(Y4:Y500, "=APAGADO",E4:E500,"=Fibra Optica") -> 0 | Z2: =COUNTIFS(Z4:Z500, "=APAGADO",E4:E500,"=Fibra Optica") -> 0 | AA2: =COUNTIFS(AA4:AA500, "=APAGADO",E4:E500,"=Fibra Optica") -> 0 | AB2: =COUNTIFS(AB4:AB500, "=APAGADO",E4:E500,"=Fibra Optica") -> 0 | AC2: =COUNTIFS(AC4:AC500, "=APAGADO",E4:E500,"=Fibra Optica") -> 0 | AD2: =COUNTIFS(AD4:AD500, "=APAGADO",E4:E500,"=Fibra Optica") -> 0 | AE2: =COUNTIFS(AE4:AE500, "=APAGADO",E4:E500,"=Fibra Optica") -> 0 | AF2: =COUNTIFS(AF4:AF500, "=APAGADO",E4:E500,"=Fibra Optica") -> 0 | AG2: =COUNTIFS(AG4:AG500, "=APAGADO",E4:E500,"=Fibra Optica") -> 0 | AH2: =COUNTIFS(AH4:AH500, "=APAGADO",E4:E500,"=Fibra Optica") -> 0 | AI2: =COUNTIFS(AI4:AI400, "=APAGADO",E4:E400,"=Fibra Optica") -> 0
A3: =ESTADISTICA!A1 -> Barrio | B3: =ESTADISTICA!B1 -> [Denominacion] | C3: =ESTADISTICA!C1 -> [Ubicacion] | D3: =ESTADISTICA!D1 -> [Tipo de Camara] | E3: =ESTADISTICA!E1 -> [Tipo de Conexion] | F3: =ESTADISTICA!F1 -> 44958 | G3: =ESTADISTICA!G1 -> 44959 | H3: =ESTADISTICA!H1 -> 44960 | ... AI3: =ESTADISTICA!AI1 -> #REF!
A4: =ESTADISTICA!A2 -> ALTAMIRA | B4: =ESTADISTICA!B2 -> ALT01 | C4: =ESTADISTICA!C2 -> Calchaqui y Sgto. Cabral | D4: =ESTADISTICA!D2 -> Domo | E4: =ESTADISTICA!E2 -> Fibra Optica | F4: =ESTADISTICA!F2 -> 0 | G4: =ESTADISTICA!G2 -> 0 | H4: =ESTADISTICA!H2 -> 0 | ... AI4: =ESTADISTICA!AI2 -> #REF!
A5: =ESTADISTICA!A3 -> ALTAMIRA | B5: =ESTADISTICA!B3 -> ALT02 | C5: =ESTADISTICA!C3 -> Calchaqui y Lope de Vega | D5: =ESTADISTICA!D3 -> Domo | E5: =ESTADISTICA!E3 -> PTO A FO | F5: =ESTADISTICA!F3 -> 0 | G5: =ESTADISTICA!G3 -> 0 | H5: =ESTADISTICA!H3 -> 0 | ... AI5: =ESTADISTICA!AI3 -> #REF!
A6: =ESTADISTICA!A4 -> ALTAMIRA | B6: =ESTADISTICA!B4 -> ALT 03 | C6: =ESTADISTICA!C4 -> Bombero Galarza y Necochea | D6: =ESTADISTICA!D4 -> Domo | E6: =ESTADISTICA!E4 -> FIBRA OPTICA | F6: =ESTADISTICA!F4 -> 0 | G6: =ESTADISTICA!G4 -> 0 | H6: =ESTADISTICA!H4 -> 0 | ... AI6: =ESTADISTICA!AI4 -> #REF!
A7: =ESTADISTICA!A5 -> ALTAMIRA | B7: =ESTADISTICA!B5 -> ALT 04 | C7: =ESTADISTICA!C5 -> Francia y Necochea | D7: =ESTADISTICA!D5 -> Domo | E7: =ESTADISTICA!E5 -> FIBRA OPTICA | F7: =ESTADISTICA!F5 -> 0 | G7: =ESTADISTICA!G5 -> 0 | H7: =ESTADISTICA!H5 -> 0 | ... AI7: =ESTADISTICA!AI5 -> #REF!
A8: =ESTADISTICA!A6 -> ALTAMIRA | B8: =ESTADISTICA!B6 -> ALT05 | C8: =ESTADISTICA!C6 -> Av. Calchaqui y Bombero Galarza | D8: =ESTADISTICA!D6 -> Domo | E8: =ESTADISTICA!E6 -> PTO A FO | F8: =ESTADISTICA!F6 -> 0 | G8: =ESTADISTICA!G6 -> 0 | H8: =ESTADISTICA!H6 -> 0 | ... AI8: =ESTADISTICA!AI6 -> #REF!
A9: =ESTADISTICA!A7 -> ALTAMIRA | B9: =ESTADISTICA!B7 -> ALT 06 | C9: =ESTADISTICA!C7 -> LOPE DE VEGA Y NECOCHEA | D9: =ESTADISTICA!D7 -> Domo | E9: =ESTADISTICA!E7 -> PTO A FO | F9: =ESTADISTICA!F7 -> 0 | G9: =ESTADISTICA!G7 -> 0 | H9: =ESTADISTICA!H7 -> 0 | ... AI9: =ESTADISTICA!AI7 -> #REF!
A10: =ESTADISTICA!A8 -> ALTAMIRA | B10: =ESTADISTICA!B8 -> ALT07 | C10: =ESTADISTICA!C8 -> AV. CALCHAQUI Y AV. DEL TRABAJO | D10: =ESTADISTICA!D8 -> DOMO | E10: =ESTADISTICA!E8 -> PTO A FO | F10: =ESTADISTICA!F8 -> 0 | G10: =ESTADISTICA!G8 -> 0 | H10: =ESTADISTICA!H8 -> 0 | ... AI10: =ESTADISTICA!AI8 -> #REF!
A11: =ESTADISTICA!A9 -> ALTAMIRA | B11: =ESTADISTICA!B9 -> ALT 08 | C11: =ESTADISTICA!C9 -> HUMAITA Y NECOCHEA | D11: =ESTADISTICA!D9 -> DOMO | E11: =ESTADISTICA!E9 -> Fibra Optica | F11: =ESTADISTICA!F9 -> 0 | G11: =ESTADISTICA!G9 -> 0 | H11: =ESTADISTICA!H9 -> 0 | ... AI11: =ESTADISTICA!AI9 -> #REF!
A12: =ESTADISTICA!A10 -> ALTAMIRA | B12: =ESTADISTICA!B10 -> ALT 09 | C12: =ESTADISTICA!C10 -> NECOCHEA Y CURUPAITY | D12: =ESTADISTICA!D10 -> DOMO | E12: =ESTADISTICA!E10 -> Fibra Optica | F12: =ESTADISTICA!F10 -> 0 | G12: =ESTADISTICA!G10 -> 0 | H12: =ESTADISTICA!H10 -> 0 | ... AI12: =ESTADISTICA!AI10 -> #REF!
A13: =ESTADISTICA!A11 -> ALTAMIRA | B13: =ESTADISTICA!B11 -> ALT 10 | C13: =ESTADISTICA!C11 -> Calchaqui y Francia | D13: =ESTADISTICA!D11 -> Domo | E13: =ESTADISTICA!E11 -> Radio | F13: =ESTADISTICA!F11 -> 0 | G13: =ESTADISTICA!G11 -> 0 | H13: =ESTADISTICA!H11 -> 0 | ... AI13: =ESTADISTICA!AI11 -> #REF!
A14: =ESTADISTICA!A12 -> AGUSTIN RAMIREZ | B14: =ESTADISTICA!B12 -> ARA 01 | C14: =ESTADISTICA!C12 -> Malambo y Tranquera | D14: =ESTADISTICA!D12 -> Domo | E14: =ESTADISTICA!E12 -> FIBRA OPTICA | F14: =ESTADISTICA!F12 -> 0 | G14: =ESTADISTICA!G12 -> 0 | H14: =ESTADISTICA!H12 -> 0 | ... AI14: =ESTADISTICA!AI12 -> #REF!
... A601: =ESTADISTICA!A599 -> 0 | B601: =ESTADISTICA!B599 -> 0 | C601: =ESTADISTICA!C599 -> 0 | D601: =ESTADISTICA!D599 -> 0 | E601: =ESTADISTICA!E599 -> 0 | F601: =ESTADISTICA!F599 -> 0 | G601: =ESTADISTICA!G599 -> 0 | H601: =ESTADISTICA!H599 -> 0 | ... AI601: =ESTADISTICA!AI599 -> #REF!

Sheet APAGADOS ANTENA
C1: TOTAL PTO A FO
E2: APAGADOS | F2: =COUNTIFS(F4:F500, "=APAGADO",E4:E500,"=PTO A FO") -> 0 | G2: =COUNTIFS(G4:G500, "=APAGADO",E4:E500,"=PTO A FO") -> 1 | H2: =COUNTIFS(H4:H500, "=APAGADO",E4:E500,"=PTO A FO") -> 0 | I2: =COUNTIFS(I4:I500, "=APAGADO",E4:E500,"=PTO A FO") -> 0 | J2: =COUNTIFS(J4:J500, "=APAGADO",E4:E500,"=PTO A FO") -> 1 | K2: =COUNTIFS(K4:K500, "=APAGADO",E4:E500,"=PTO A FO") -> 1 | L2: =COUNTIFS(L4:L500, "=APAGADO",E4:E500,"=PTO A FO") -> 1 | M2: =COUNTIFS(M4:M500, "=APAGADO",E4:E500,"=PTO A FO") -> 0 | N2: =COUNTIFS(N4:N500, "=APAGADO",E4:E500,"=PTO A FO") -> 0 | O2: =COUNTIFS(O4:O500, "=APAGADO",E4:E500,"=PTO A FO") -> 0 | P2: =COUNTIFS(P4:P500, "=APAGADO",E4:E500,"=PTO A FO") -> 0 | Q2: =COUNTIFS(Q4:Q500, "=APAGADO",E4:E500,"=PTO A FO") -> 0 | R2: =COUNTIFS(R4:R500, "=APAGADO",E4:E500,"=PTO A FO") -> 0 | S2: =COUNTIFS(S4:S500, "=APAGADO",E4:E500,"=PTO A FO") -> 0 | T2: =COUNTIFS(T4:T500, "=APAGADO",E4:E500,"=PTO A FO") -> 0 | U2: =COUNTIFS(U4:U500, "=APAGADO",E4:E500,"=PTO A FO") -> 0 | V2: =COUNTIFS(V4:V500, "=APAGADO",E4:E500,"=PTO A FO") -> 0 | W2: =COUNTIFS(W4:W500, "=APAGADO",E4:E500,"=PTO A FO") -> 0 | X2: =COUNTIFS(X4:X500, "=APAGADO",E4:E500,"=PTO A FO") -> 0 | Y2: =COUNTIFS(Y4:Y500, "=APAGADO",E4:E500,"=PTO A FO") -> 0 | Z2: =COUNTIFS(Z4:Z500, "=APAGADO",E4:E500,"=PTO A FO") -> 0 | AA2: =COUNTIFS(AA4:AA500, "=APAGADO",E4:E500,"=PTO A FO") -> 0 | AB2: =COUNTIFS(AB4:AB500, "=APAGADO",E4:E500,"=PTO A FO") -> 0 | AC2: =COUNTIFS(AC4:AC500, "=APAGADO",E4:E500,"=PTO A FO") -> 0 | AD2: =COUNTIFS(AD4:AD500, "=APAGADO",E4:E500,"=PTO A FO") -> 0 | AE2: =COUNTIFS(AE4:AE500, "=APAGADO",E4:E500,"=PTO A FO") -> 0 | AF2: =COUNTIFS(AF4:AF500, "=APAGADO",E4:E500,"=PTO A FO") -> 0 | AG2: =COUNTIFS(AG4:AG500, "=APAGADO",E4:E500,"=PTO A FO") -> 0 | AH2: =COUNTIFS(AH4:AH500, "=APAGADO",E4:E500,"=PTO A FO") -> 0 | AI2: =COUNTIFS(AI4:AI500, "=APAGADO",E4:E500,"=PTO A FO") -> 0
A3: =ESTADISTICA!A1 -> Barrio | B3: =ESTADISTICA!B1 -> [Denominacion] | C3: =ESTADISTICA!C1 -> [Ubicacion] | D3: =ESTADISTICA!D1 -> [Tipo de Camara] | E3: =ESTADISTICA!E1 -> [Tipo de Conexion] | F3: =ESTADISTICA!F1 -> 44958 | G3: =ESTADISTICA!G1 -> 44959 | H3: =ESTADISTICA!H1 -> 44960 | ... AI3: =ESTADISTICA!AI1 -> #REF!
A4: =ESTADISTICA!A2 -> ALTAMIRA | B4: =ESTADISTICA!B2 -> ALT01 | C4: =ESTADISTICA!C2 -> Calchaqui y Sgto. Cabral | D4: =ESTADISTICA!D2 -> Domo | E4: =ESTADISTICA!E2 -> Fibra Optica | F4: =ESTADISTICA!F2 -> 0 | G4: =ESTADISTICA!G2 -> 0 | H4: =ESTADISTICA!H2 -> 0 | ... AI4: =ESTADISTICA!AI2 -> #REF!
A5: =ESTADISTICA!A3 -> ALTAMIRA | B5: =ESTADISTICA!B3 -> ALT02 | C5: =ESTADISTICA!C3 -> Calchaqui y Lope de Vega | D5: =ESTADISTICA!D3 -> Domo | E5: =ESTADISTICA!E3 -> PTO A FO | F5: =ESTADISTICA!F3 -> 0 | G5: =ESTADISTICA!G3 -> 0 | H5: =ESTADISTICA!H3 -> 0 | ... AI5: =ESTADISTICA!AI3 -> #REF!
A6: =ESTADISTICA!A4 -> ALTAMIRA | B6: =ESTADISTICA!B4 -> ALT 03 | C6: =ESTADISTICA!C4 -> Bombero Galarza y Necochea | D6: =ESTADISTICA!D4 -> Domo | E6: =ESTADISTICA!E4 -> FIBRA OPTICA | F6: =ESTADISTICA!F4 -> 0 | G6: =ESTADISTICA!G4 -> 0 | H6: =ESTADISTICA!H4 -> 0 | ... AI6: =ESTADISTICA!AI4 -> #REF!
A7: =ESTADISTICA!A5 -> ALTAMIRA | B7: =ESTADISTICA!B5 -> ALT 04 | C7: =ESTADISTICA!C5 -> Francia y Necochea | D7: =ESTADISTICA!D5 -> Domo | E7: =ESTADISTICA!E5 -> FIBRA OPTICA | F7: =ESTADISTICA!F5 -> 0 | G7: =ESTADISTICA!G5 -> 0 | H7: =ESTADISTICA!H5 -> 0 | ... AI7: =ESTADISTICA!AI5 -> #REF!
A8: =ESTADISTICA!A6 -> ALTAMIRA | B8: =ESTADISTICA!B6 -> ALT05 | C8: =ESTADISTICA!C6 -> Av. Calchaqui y Bombero Galarza | D8: =ESTADISTICA!D6 -> Domo | E8: =ESTADISTICA!E6 -> PTO A FO | F8: =ESTADISTICA!F6 -> 0 | G8: =ESTADISTICA!G6 -> 0 | H8: =ESTADISTICA!H6 -> 0 | ... AI8: =ESTADISTICA!AI6 -> #REF!
A9: =ESTADISTICA!A7 -> ALTAMIRA | B9: =ESTADISTICA!B7 -> ALT 06 | C9: =ESTADISTICA!C7 -> LOPE DE VEGA Y NECOCHEA | D9: =ESTADISTICA!D7 -> Domo | E9: =ESTADISTICA!E7 -> PTO A FO | F9: =ESTADISTICA!F7 -> 0 | G9: =ESTADISTICA!G7 -> 0 | H9: =ESTADISTICA!H7 -> 0 | ... AI9: =ESTADISTICA!AI7 -> #REF!
A10: =ESTADISTICA!A8 -> ALTAMIRA | B10: =ESTADISTICA!B8 -> ALT07 | C10: =ESTADISTICA!C8 -> AV. CALCHAQUI Y AV. DEL TRABAJO | D10: =ESTADISTICA!D8 -> DOMO | E10: =ESTADISTICA!E8 -> PTO A FO | F10: =ESTADISTICA!F8 -> 0 | G10: =ESTADISTICA!G8 -> 0 | H10: =ESTADISTICA!H8 -> 0 | ... AI10: =ESTADISTICA!AI8 -> #REF!
A11: =ESTADISTICA!A9 -> ALTAMIRA | B11: =ESTADISTICA!B9 -> ALT 08 | C11: =ESTADISTICA!C9 -> HUMAITA Y NECOCHEA | D11: =ESTADISTICA!D9 -> DOMO | E11: =ESTADISTICA!E9 -> Fibra Optica | F11: =ESTADISTICA!F9 -> 0 | G11: =ESTADISTICA!G9 -> 0 | H11: =ESTADISTICA!H9 -> 0 | ... AI11: =ESTADISTICA!AI9 -> #REF!
A12: =ESTADISTICA!A10 -> ALTAMIRA | B12: =ESTADISTICA!B10 -> ALT 09 | C12: =ESTADISTICA!C10 -> NECOCHEA Y CURUPAITY | D12: =ESTADISTICA!D10 -> DOMO | E12: =ESTADISTICA!E10 -> Fibra Optica | F12: =ESTADISTICA!F10 -> 0 | G12: =ESTADISTICA!G10 -> 0 | H12: =ESTADISTICA!H10 -> 0 | ... AI12: =ESTADISTICA!AI10 -> #REF!
A13: =ESTADISTICA!A11 -> ALTAMIRA | B13: =ESTADISTICA!B11 -> ALT 10 | C13: =ESTADISTICA!C11 -> Calchaqui y Francia | D13: =ESTADISTICA!D11 -> Domo | E13: =ESTADISTICA!E11 -> Radio | F13: =ESTADISTICA!F11 -> 0 | G13: =ESTADISTICA!G11 -> 0 | H13: =ESTADISTICA!H11 -> 0 | ... AI13: =ESTADISTICA!AI11 -> #REF!
A14: =ESTADISTICA!A12 -> AGUSTIN RAMIREZ | B14: =ESTADISTICA!B12 -> ARA 01 | C14: =ESTADISTICA!C12 -> Malambo y Tranquera | D14: =ESTADISTICA!D12 -> Domo | E14: =ESTADISTICA!E12 -> FIBRA OPTICA | F14: =ESTADISTICA!F12 -> 0 | G14: =ESTADISTICA!G12 -> 0 | H14: =ESTADISTICA!H12 -> 0 | ... AI14: =ESTADISTICA!AI12 -> #REF!
... A539: =ESTADISTICA!A537 -> 0 | B539: =ESTADISTICA!B537 -> 0 | C539: =ESTADISTICA!C537 -> 0 | D539: =ESTADISTICA!D537 -> 0 | E539: =ESTADISTICA!E537 -> 0 | F539: =ESTADISTICA!F537 -> 0 | G539: =ESTADISTICA!G537 -> 0 | H539: =ESTADISTICA!H537 -> 0 | ... AI539: =ESTADISTICA!AI537 -> #REF!

Sheet APAGADOS RADIO
C1: TOTAL RADIO | D1: =COUNTIFS(E4:E400,"=radio") -> 94
E2: APAGADOS | F2: =COUNTIFS(F4:F500, "=APAGADO",E4:E500,"=radio") -> 3 | G2: =COUNTIFS(G4:G500, "=APAGADO",E4:E500,"=radio") -> 7 | H2: =COUNTIFS(H4:H500, "=APAGADO",E4:E500,"=radio") -> 7 | I2: =COUNTIFS(I4:I500, "=APAGADO",E4:E500,"=radio") -> 0 | J2: =COUNTIFS(J4:J500, "=APAGADO",E4:E500,"=radio") -> 6 | K2: =COUNTIFS(K4:K500, "=APAGADO",E4:E500,"=radio") -> 3 | L2: =COUNTIFS(L4:L500, "=APAGADO",E4:E500,"=radio") -> 10 | M2: =COUNTIFS(M4:M500, "=APAGADO",E4:E500,"=radio") -> 0 | N2: =COUNTIFS(N4:N500, "=APAGADO",E4:E500,"=radio") -> 0 | O2: =COUNTIFS(O4:O500, "=APAGADO",E4:E500,"=radio") -> 0 | P2: =COUNTIFS(P4:P500, "=APAGADO",E4:E500,"=radio") -> 0 | Q2: =COUNTIFS(Q4:Q367, "=APAGADO",E4:E367,"=radio") -> 0 | R2: =COUNTIFS(R4:R500, "=APAGADO",E4:E500,"=radio") -> 0 | S2: =COUNTIFS(S4:S500, "=APAGADO",E4:E500,"=radio") -> 0 | T2: =COUNTIFS(T4:T500, "=APAGADO",E4:E500,"=radio") -> 0 | U2: =COUNTIFS(U4:U500, "=APAGADO",E4:E500,"=radio") -> 0 | V2: =COUNTIFS(V4:V500, "=APAGADO",E4:E500,"=radio") -> 0 | W2: =COUNTIFS(W4:W500, "=APAGADO",E4:E500,"=radio") -> 0 | X2: =COUNTIFS(X4:X500, "=APAGADO",E4:E500,"=radio") -> 0 | Y2: =COUNTIFS(Y4:Y500, "=APAGADO",E4:E500,"=radio") -> 0 | Z2: =COUNTIFS(Z4:Z500, "=APAGADO",E4:E500,"=radio") -> 0 | AA2: =COUNTIFS(AA4:AA500, "=APAGADO",E4:E500,"=radio") -> 0 | AB2: =COUNTIFS(AB4:AB500, "=APAGADO",E4:E500,"=radio") -> 0 | AC2: =COUNTIFS(AC4:AC500, "=APAGADO",E4:E500,"=radio") -> 0 | AD2: =COUNTIFS(AD4:AD500, "=APAGADO",E4:E500,"=radio") -> 0 | AE2: =COUNTIFS(AE4:AE500, "=APAGADO",E4:E500,"=radio") -> 0 | AF2: =COUNTIFS(AF4:AF500, "=APAGADO",E4:E500,"=radio") -> 0 | AG2: =COUNTIFS(AG4:AG500, "=APAGADO",E4:E500,"=radio") -> 0 | AH2: =COUNTIFS(AH4:AH500, "=APAGADO",E4:E500,"=radio") -> 0 | AI2: =COUNTIFS(AI4:AI500, "=APAGADO",E4:E500,"=radio") -> 0
A3: =ESTADISTICA!A1 -> Barrio | B3: =ESTADISTICA!B1 -> [Denominacion] | C3: =ESTADISTICA!C1 -> [Ubicacion] | D3: =ESTADISTICA!D1 -> [Tipo de Camara] | E3: =ESTADISTICA!E1 -> [Tipo de Conexion] | F3: =ESTADISTICA!F1 -> 44958 | G3: =ESTADISTICA!G1 -> 44959 | H3: =ESTADISTICA!H1 -> 44960 | ... AI3: =ESTADISTICA!AI1 -> #REF!
A4: =ESTADISTICA!A2 -> ALTAMIRA | B4: =ESTADISTICA!B2 -> ALT01 | C4: =ESTADISTICA!C2 -> Calchaqui y Sgto. Cabral | D4: =ESTADISTICA!D2 -> Domo | E4: =ESTADISTICA!E2 -> Fibra Optica | F4: =ESTADISTICA!F2 -> 0 | G4: =ESTADISTICA!G2 -> 0 | H4: =ESTADISTICA!H2 -> 0 | ... AI4: =ESTADISTICA!AI2 -> #REF!
A5: =ESTADISTICA!A3 -> ALTAMIRA | B5: =ESTADISTICA!B3 -> ALT02 | C5: =ESTADISTICA!C3 -> Calchaqui y Lope de Vega | D5: =ESTADISTICA!D3 -> Domo | E5: =ESTADISTICA!E3 -> PTO A FO | F5: =ESTADISTICA!F3 -> 0 | G5: =ESTADISTICA!G3 -> 0 | H5: =ESTADISTICA!H3 -> 0 | ... AI5: =ESTADISTICA!AI3 -> #REF!
A6: =ESTADISTICA!A4 -> ALTAMIRA | B6: =ESTADISTICA!B4 -> ALT 03 | C6: =ESTADISTICA!C4 -> Bombero Galarza y Necochea | D6: =ESTADISTICA!D4 -> Domo | E6: =ESTADISTICA!E4 -> FIBRA OPTICA | F6: =ESTADISTICA!F4 -> 0 | G6: =ESTADISTICA!G4 -> 0 | H6: =ESTADISTICA!H4 -> 0 | ... AI6: =ESTADISTICA!AI4 -> #REF!
A7: =ESTADISTICA!A5 -> ALTAMIRA | B7: =ESTADISTICA!B5 -> ALT 04 | C7: =ESTADISTICA!C5 -> Francia y Necochea | D7: =ESTADISTICA!D5 -> Domo | E7: =ESTADISTICA!E5 -> FIBRA OPTICA | F7: =ESTADISTICA!F5 -> 0 | G7: =ESTADISTICA!G5 -> 0 | H7: =ESTADISTICA!H5 -> 0 | ... AI7: =ESTADISTICA!AI5 -> #REF!
A8: =ESTADISTICA!A6 -> ALTAMIRA | B8: =ESTADISTICA!B6 -> ALT05 | C8: =ESTADISTICA!C6 -> Av. Calchaqui y Bombero Galarza | D8: =ESTADISTICA!D6 -> Domo | E8: =ESTADISTICA!E6 -> PTO A FO | F8: =ESTADISTICA!F6 -> 0 | G8: =ESTADISTICA!G6 -> 0 | H8: =ESTADISTICA!H6 -> 0 | ... AI8: =ESTADISTICA!AI6 -> #REF!
A9: =ESTADISTICA!A7 -> ALTAMIRA | B9: =ESTADISTICA!B7 -> ALT 06 | C9: =ESTADISTICA!C7 -> LOPE DE VEGA Y NECOCHEA | D9: =ESTADISTICA!D7 -> Domo | E9: =ESTADISTICA!E7 -> PTO A FO | F9: =ESTADISTICA!F7 -> 0 | G9: =ESTADISTICA!G7 -> 0 | H9: =ESTADISTICA!H7 -> 0 | ... AI9: =ESTADISTICA!AI7 -> #REF!
A10: =ESTADISTICA!A8 -> ALTAMIRA | B10: =ESTADISTICA!B8 -> ALT07 | C10: =ESTADISTICA!C8 -> AV. CALCHAQUI Y AV. DEL TRABAJO | D10: =ESTADISTICA!D8 -> DOMO | E10: =ESTADISTICA!E8 -> PTO A FO | F10: =ESTADISTICA!F8 -> 0 | G10: =ESTADISTICA!G8 -> 0 | H10: =ESTADISTICA!H8 -> 0 | ... AI10: =ESTADISTICA!AI8 -> #REF!
A11: =ESTADISTICA!A9 -> ALTAMIRA | B11: =ESTADISTICA!B9 -> ALT 08 | C11: =ESTADISTICA!C9 -> HUMAITA Y NECOCHEA | D11: =ESTADISTICA!D9 -> DOMO | E11: =ESTADISTICA!E9 -> Fibra Optica | F11: =ESTADISTICA!F9 -> 0 | G11: =ESTADISTICA!G9 -> 0 | H11: =ESTADISTICA!H9 -> 0 | ... AI11: =ESTADISTICA!AI9 -> #REF!
