Workbook
Name _25_de_agosto: 'RESUMEN TOTAL'!$A$4:$D$352
Name BONOMOcam: Hoja1!$B$2
Name COSEIDIcam: Hoja1!$B$4

Sheet RESUMEN TOTAL
A1: CANTIDAD DE CAMARAS | B1: =COUNTA(B5:B527) -> 395 | D1: PORCIENTO DE CAIDAS | K1: =(K3)/(K2+K3) -> 0.070886076 | L1: =(L3)/(L2+L3) -> 0.13417722 | M1: =(M3)/(M2+M3) -> 0.21772152 | N1: =(N3)/(N2+N3) -> 0.22278481 | O1: =(O3)/(O2+O3) -> 0.096202532 | P1: =(P3)/(P2+P3) -> 0.081012658 | Q1: =(Q3)/(Q2+Q3) -> 0.053164557 | R1: =(R3)/(R2+R3) -> 0 | ... AN1: =(AN3)/(AN2+AN3) -> 0
D2: FUNCIONAN | K2: =COUNTIF(K5:K399, "") -> 367 | L2: =COUNTIF(L5:L399, "") -> 342 | M2: =COUNTIF(M5:M399, "") -> 309 | N2: =COUNTIF(N5:N399, "") -> 307 | O2: =COUNTIF(O5:O399, "") -> 357 | P2: =COUNTIF(P5:P399, "") -> 363 | Q2: =COUNTIF(Q5:Q399, "") -> 374 | R2: =COUNTIF(R5:R399, "") -> 395 | ... AN2: =COUNTIF(AN5:AN399, "") -> 395
D3: CAIDAS | K3: =COUNTIF(K4:K447, "apagado") -> 28 | L3: =COUNTIF(L4:L447, "apagado") -> 53 | M3: =COUNTIF(M4:M447, "apagado") -> 86 | N3: =COUNTIF(N4:N447, "apagado") -> 88 | O3: =COUNTIF(O4:O447, "apagado") -> 38 | P3: =COUNTIF(P4:P447, "apagado") -> 32 | Q3: =COUNTIF(Q4:Q447, "apagado") -> 21 | R3: =COUNTIF(R4:R447, "apagado") -> 0 | ... AN3: =COUNTIF(AN4:AN447, "apagado") -> 0
A4: Barrio | B4: [Denominacion] | C4: [Empresa Mantenimiento] | D4: [Ubicacion] | E4: [Tipo de Camara] | F4: [Tipo de Conexion] | H4: DIAS FUNCIONANDO | I4: DIAS CAIDA | J4: EFECTIVIDAD | K4: 44805 | L4: 44806 | M4: 44807 | N4: 44808 | O4: 44809 | P4: 44810 | Q4: 44811 | R4: 44812 | S4: 44813 | T4: 44814 | U4: 44815 | V4: 44816 | W4: 44817 | X4: 44818 | Y4: 44819 | Z4: 44820 | AA4: 44821 | AB4: 44822 | AC4: 44823 | AD4: 44824 | AE4: 44825 | AF4: 44826 | AG4: 44827 | AH4: 44828 | AI4: 44829 | AJ4: 44830 | AK4: 44831 | AL4: 44832 | AM4: 44833 | AN4: 44834
A5: ALTAMIRA | B5: ALT 03 | C5: BONOMO | D5: Bombero Galarza y Necochea | E5: Domo | F5: FIBRA OPTICA | G5: 172.20.12.54 | H5: =COUNTIF(K5:AN5,"") -> 30 | I5: =COUNTIF(K5:AL5,"APAGADO") -> 0 | J5: =(H5)/(I5+H5) -> 1
A6: ALTAMIRA | B6: ALT 04 | C6: BONOMO | D6: Francia y Necochea | E6: Domo | F6: FIBRA OPTICA | G6: 172.20.12.55 | H6: =COUNTIF(K6:AN6,"") -> 30 | I6: =COUNTIF(K6:AL6,"APAGADO") -> 0 | J6: =(H6)/(I6+H6) -> 1
A7: ALTAMIRA | B7: ALT 06 | C7: BONOMO | D7: LOPE DE VEGA Y NECOCHEA | E7: Domo | F7: PTO A FO | G7: 172.20.12.12 | H7: =COUNTIF(K7:AN7,"") -> 30 | I7: =COUNTIF(K7:AL7,"APAGADO") -> 0 | J7: =(H7)/(I7+H7) -> 1
A8: ALTAMIRA | B8: ALT 08 | C8: BONOMO | D8: HUMAITA Y NECOCHEA | E8: DOMO | F8: Fibra Optica | G8: 172.20.11.215 | H8: =COUNTIF(K8:AN8,"") -> 30 | I8: =COUNTIF(K8:AL8,"APAGADO") -> 0 | J8: =(H8)/(I8+H8) -> 1
A9: ALTAMIRA | B9: ALT 09 | C9: BONOMO | D9: NECOCHEA Y CURUPAITY | E9: DOMO | F9: Fibra Optica | G9: 172.20.11.216 | H9: =COUNTIF(K9:AN9,"") -> 30 | I9: =COUNTIF(K9:AL9,"APAGADO") -> 0 | J9: =(H9)/(I9+H9) -> 1
A10: ALTAMIRA | B10: ALT 10 | C10: BONOMO | D10: Calchaqui y Francia | E10: Domo | F10: Radio | H10: =COUNTIF(K10:AN10,"") -> 23 | I10: =COUNTIF(K10:AL10,"APAGADO") -> 7 | J10: =(H10)/(I10+H10) -> 0.76666667 | K10: APAGADO | L10: APAGADO | M10: APAGADO | N10: APAGADO | O10: APAGADO | P10: APAGADO | Q10: APAGADO
A11: ALTAMIRA | B11: ALT01 | C11: BONOMO | D11: Calchaqui y Sgto. Cabral | E11: Domo | F11: Fibra Optica | G11: 172.20.10.6 | H11: =COUNTIF(K11:AN11,"") -> 30 | I11: =COUNTIF(K11:AL11,"APAGADO") -> 0 | J11: =(H11)/(I11+H11) -> 1
A12: ALTAMIRA | B12: ALT02 | C12: BONOMO | D12: Calchaqui y Lope de Vega | E12: Domo | F12: PTO A FO | G12: 172.20.12.218 | H12: =COUNTIF(K12:AN12,"") -> 30 | I12: =COUNTIF(K12:AL12,"APAGADO") -> 0 | J12: =(H12)/(I12+H12) -> 1
A13: ALTAMIRA | B13: ALT05 | C13: BONOMO | D13: Av. Calchaqui y Bombero Galarza | E13: Domo | F13: PTO A FO | G13: 172.20.12.216 | H13: =COUNTIF(K13:AN13,"") -> 23 | I13: =COUNTIF(K13:AL13,"APAGADO") -> 7 | J13: =(H13)/(I13+H13) -> 0.76666667 | K13: APAGADO | L13: APAGADO | M13: APAGADO | N13: APAGADO | O13: APAGADO | P13: APAGADO | Q13: APAGADO
A14: ALTAMIRA | B14: ALT07 | C14: BONOMO | D14: AV. CALCHAQUI Y AV. DEL TRABAJO | E14: DOMO | F14: PTO A FO | G14: 172.20.10.57 | H14: =COUNTIF(K14:AN14,"") -> 30 | I14: =COUNTIF(K14:AL14,"APAGADO") -> 0 | J14: =(H14)/(I14+H14) -> 1
A15: AGUSTIN RAMIREZ | B15: ARA 01 | C15: COSEIDI | D15: Malambo y Tranquera | E15: Domo | F15: FIBRA OPTICA | G15: 172.20.12.110 | H15: =COUNTIF(K15:AN15,"") -> 30 | I15: =COUNTIF(K15:AL15,"APAGADO") -> 0 | J15: =(H15)/(I15+H15) -> 1
A16: BELGRANO | B16: BEL 01 | C16: BONOMO | D16: San Martin y Dardo Rocha | E16: DOMO | F16: FIBRA OPTICA | G16: 172.20.12.64 | H16: =COUNTIF(K16:AN16,"") -> 25 | I16: =COUNTIF(K16:AL16,"APAGADO") -> 5 | J16: =(H16)/(I16+H16) -> 0.83333333 | K16: APAGADO | L16: APAGADO | O16: APAGADO | P16: APAGADO | Q16: APAGADO
A17: CENTRO | B17: CEN 05 | C17: BONOMO | D17: Bocuzzi e/España y San Martin | E17: DOMO | F17: Fibra Optica | G17: 172.20.10.200 | H17: =COUNTIF(K17:AN17,"") -> 30 | I17: =COUNTIF(K17:AL17,"APAGADO") -> 0 | J17: =(H17)/(I17+H17) -> 1
A18: CENTRO | B18: CEN 12 | C18: BONOMO | D18: Monteagudo y Mitre | E18: Domo | F18: Fibra Optica | G18: 172.20.10.23 | H18: =COUNTIF(K18:AN18,"") -> 30 | I18: =COUNTIF(K18:AL18,"APAGADO") -> 0 | J18: =(H18)/(I18+H18) -> 1
A19: CENTRO | B19: CEN 13 | C19: BONOMO | D19: 25 de Mayo y Maipu | E19: DOMO | F19: Fibra Optica | G19: 172.20.10.20 | H19: =COUNTIF(K19:AN19,"") -> 30 | I19: =COUNTIF(K19:AL19,"APAGADO") -> 0 | J19: =(H19)/(I19+H19) -> 1
A20: CENTRO | B20: CEN 37 | C20: BONOMO | D20: Diagonal Granaderos y Monteagudo | E20: Domo | F20: Fibra Optica | G20: 172.20.12.52 | H20: =COUNTIF(K20:AN20,"") -> 30 | I20: =COUNTIF(K20:AL20,"APAGADO") -> 0 | J20: =(H20)/(I20+H20) -> 1
A21: CENTRO | B21: CEN 50 | C21: BONOMO | D21: Av. San Martin y Newbery | E21: Domo | F21: Radio | G21: 172.20.200.184 | H21: =COUNTIF(K21:AN21,"") -> 28 | I21: =COUNTIF(K21:AL21,"APAGADO") -> 2 | J21: =(H21)/(I21+H21) -> 0.93333333 | M21: APAGADO | N21: APAGADO
A22: CENTRO | B22: CEN 51 | C22: BONOMO | D22: ILLIA Y LAS HERAS | E22: FIJA | F22: Fibra Optica | G22: 172.20.11.29 | H22: =COUNTIF(K22:AN22,"") -> 30 | I22: =COUNTIF(K22:AL22,"APAGADO") -> 0 | J22: =(H22)/(I22+H22) -> 1
A23: CENTRO | B23: CEN 53 | C23: BONOMO | D23: GUTIERREZ Y BROWN | E23: Domo | F23: Radio | G23: 172.20.200.166 | H23: =COUNTIF(K23:AN23,"") -> 30 | I23: =COUNTIF(K23:AL23,"APAGADO") -> 0 | J23: =(H23)/(I23+H23) -> 1
A24: CENTRO | B24: CEN 54 | C24: BONOMO | D24: GUTIERREZ Y PRINGLES | E24: Domo | F24: Radio | G24: 172.20.200.165 | H24: =COUNTIF(K24:AN24,"") -> 30 | I24: =COUNTIF(K24:AL24,"APAGADO") -> 0 | J24: =(H24)/(I24+H24) -> 1
A25: CENTRO | B25: CEN 55 | C25: BONOMO | D25: BOUREL Y URQUIZA | E25: Domo | F25: Radio | G25: 172.20.200.163 | H25: =COUNTIF(K25:AN25,"") -> 29 | I25: =COUNTIF(K25:AL25,"APAGADO") -> 1 | J25: =(H25)/(I25+H25) -> 0.96666667 | M25: APAGADO
A26: CENTRO | B26: CEN 56 | C26: BONOMO | D26: Newbery y Falucho | E26: DOMO | F26: Radio | G26: 172.20.200.161 | H26: =COUNTIF(K26:AN26,"") -> 30 | I26: =COUNTIF(K26:AL26,"APAGADO") -> 0 | J26: =(H26)/(I26+H26) -> 1
A27: CENTRO | B27: CEN 57 | C27: BONOMO | D27: 25 DE MAYO Y DORREGO | E27: DOMO | F27: Radio | G27: 172.20.200.199 | H27: =COUNTIF(K27:AN27,"") -> 30 | I27: =COUNTIF(K27:AL27,"APAGADO") -> 0 | J27: =(H27)/(I27+H27) -> 1
A28: CENTRO | B28: CEN 58 | C28: BONOMO | D28: EEUU Y MORENO | E28: DOMO | F28: FIBRA OPTICA | G28: 172.20.11.84 | H28: =COUNTIF(K28:AN28,"") -> 30 | I28: =COUNTIF(K28:AL28,"APAGADO") -> 0 | J28: =(H28)/(I28+H28) -> 1
A29: CENTRO | B29: CEN 60 | C29: BONOMO | D29: RECONQUISTA Y ILLIA | E29: DOMO | F29: PTO A FO | G29: 172.20.12.67 | H29: =COUNTIF(K29:AN29,"") -> 30 | I29: =COUNTIF(K29:AL29,"APAGADO") -> 0 | J29: =(H29)/(I29+H29) -> 1
A30: CENTRO | B30: CEN 61 | C30: BONOMO | D30: BOUREL Y MAIPU | E30: DOMO | F30: Radio | G30: 172.20.200.159 | H30: =COUNTIF(K30:AN30,"") -> 30 | I30: =COUNTIF(K30:AL30,"APAGADO") -> 0 | J30: =(H30)/(I30+H30) -> 1
A31: CENTRO | B31: CEN 65 | C31: BONOMO | D31: SAN MARTIN Y JUAN PERON | E31: FIJA | F31: Fibra Optica | G31: 172.20.11.135 | H31: =COUNTIF(K31:AN31,"") -> 28 | I31: =COUNTIF(K31:AL31,"APAGADO") -> 2 | J31: =(H31)/(I31+H31) -> 0.93333333 | L31: APAGADO | M31: APAGADO
A32: CENTRO | B32: CEN 70 | C32: BONOMO | D32: RIVADAVIA Y 25 MAYO | E32: Domo | F32: Fibra Optica | G32: 172.20.11.221 | H32: =COUNTIF(K32:AN32,"") -> 30 | I32: =COUNTIF(K32:AL32,"APAGADO") -> 0 | J32: =(H32)/(I32+H32) -> 1
A33: CENTRO | B33: CEN 71 | C33: BONOMO | D33: MORENO Y BOUREL | E33: Domo | F33: Fibra Optica | G33: 172.20.11.220 | H33: =COUNTIF(K33:AN33,"") -> 30 | I33: =COUNTIF(K33:AL33,"APAGADO") -> 0 | J33: =(H33)/(I33+H33) -> 1
A34: CENTRO | B34: CEN 72 | C34: BONOMO | D34: MORENO Y 25 DE MAYO | E34: Domo | F34: Fibra Optica | G34: 172.20.11.219 | H34: =COUNTIF(K34:AN34,"") -> 23 | I34: =COUNTIF(K34:AL34,"APAGADO") -> 7 | J34: =(H34)/(I34+H34) -> 0.76666667 | K34: APAGADO | L34: APAGADO | M34: APAGADO | N34: APAGADO | O34: APAGADO | P34: APAGADO | Q34: APAGADO
A35: CENTRO | B35: CEN 75 | C35: BONOMO | D35: 25 DE MAYO Y CASTELLI | E35: Domo | F35: Fibra Optica | H35: =COUNTIF(K35:AN35,"") -> 30 | I35: =COUNTIF(K35:AL35,"APAGADO") -> 0 | J35: =(H35)/(I35+H35) -> 1
A36: CENTRO | B36: CEN 76 | C36: BONOMO | D36: ESPAÑA E/MITRE Y BOCUZZI | E36: Fija | F36: Fibra Optica | H36: =COUNTIF(K36:AN36,"") -> 30 | I36: =COUNTIF(K36:AL36,"APAGADO") -> 0 | J36: =(H36)/(I36+H36) -> 1
A37: CENTRO | B37: CEN01 | C37: BONOMO | D37: San Martin y 9 de Julio | E37: Fija | F37: Fibra Optica | G37: 172.20.11.10 | H37: =COUNTIF(K37:AN37,"") -> 28 | I37: =COUNTIF(K37:AL37,"APAGADO") -> 2 | J37: =(H37)/(I37+H37) -> 0.93333333 | M37: APAGADO | N37: APAGADO
A38: CENTRO | B38: CEN02 | C38: BONOMO | D38: San Martin y Almafuerte | E38: Fija | F38: Fibra Optica | G38: 172.20.11.11 | H38: =COUNTIF(K38:AN38,"") -> 28 | I38: =COUNTIF(K38:AL38,"APAGADO") -> 2 | J38: =(H38)/(I38+H38) -> 0.93333333 | M38: APAGADO | N38: APAGADO
A39: CENTRO | B39: CEN03 | C39: BONOMO | D39: San Martin y Sallares | E39: Domo | F39: Fibra Optica | G39: 172.20.12.30 | H39: =COUNTIF(K39:AN39,"") -> 30 | I39: =COUNTIF(K39:AL39,"APAGADO") -> 0 | J39: =(H39)/(I39+H39) -> 1
A40: CENTRO | B40: CEN04 | C40: BONOMO | D40: San Martin y Contreras | E40: Domo | F40: Fibra Optica | G40: 172.20.12.29 | H40: =COUNTIF(K40:AN40,"") -> 30 | I40: =COUNTIF(K40:AL40,"APAGADO") -> 0 | J40: =(H40)/(I40+H40) -> 1
...

Sheet ESTADISTICA
A1: ='RESUMEN TOTAL'!A4 -> Barrio | B1: ='RESUMEN TOTAL'!B4 -> [Denominacion] | C1: ='RESUMEN TOTAL'!D4 -> [Ubicacion] | D1: ='RESUMEN TOTAL'!E4 -> [Tipo de Camara] | E1: ='RESUMEN TOTAL'!F4 -> [Tipo de Conexion] | F1: ='RESUMEN TOTAL'!K4 -> 44805 | G1: ='RESUMEN TOTAL'!L4 -> 44806 | H1: ='RESUMEN TOTAL'!M4 -> 44807 | I1: ='RESUMEN TOTAL'!N4 -> 44808 | J1: ='RESUMEN TOTAL'!O4 -> 44809 | K1: ='RESUMEN TOTAL'!P4 -> 44810 | L1: ='RESUMEN TOTAL'!Q4 -> 44811 | M1: ='RESUMEN TOTAL'!R4 -> 44812 | ... AI1: ='RESUMEN TOTAL'!AN4 -> 44834
A2: ='RESUMEN TOTAL'!A5 -> ALTAMIRA | B2: ='RESUMEN TOTAL'!B5 -> ALT 03 | C2: ='RESUMEN TOTAL'!D5 -> Bombero Galarza y Necochea | D2: ='RESUMEN TOTAL'!E5 -> Domo | E2: ='RESUMEN TOTAL'!F5 -> FIBRA OPTICA | F2: ='RESUMEN TOTAL'!K5 -> 0 | G2: ='RESUMEN TOTAL'!L5 -> 0 | H2: ='RESUMEN TOTAL'!M5 -> 0 | I2: ='RESUMEN TOTAL'!N5 -> 0 | J2: ='RESUMEN TOTAL'!O5 -> 0 | K2: ='RESUMEN TOTAL'!P5 -> 0 | L2: ='RESUMEN TOTAL'!Q5 -> 0 | M2: ='RESUMEN TOTAL'!R5 -> 0 | ... AI2: ='RESUMEN TOTAL'!AN5 -> 0
A3: ='RESUMEN TOTAL'!A6 -> ALTAMIRA | B3: ='RESUMEN TOTAL'!B6 -> ALT 04 | C3: ='RESUMEN TOTAL'!D6 -> Francia y Necochea | D3: ='RESUMEN TOTAL'!E6 -> Domo | E3: ='RESUMEN TOTAL'!F6 -> FIBRA OPTICA | F3: ='RESUMEN TOTAL'!K6 -> 0 | G3: ='RESUMEN TOTAL'!L6 -> 0 | H3: ='RESUMEN TOTAL'!M6 -> 0 | I3: ='RESUMEN TOTAL'!N6 -> 0 | J3: ='RESUMEN TOTAL'!O6 -> 0 | K3: ='RESUMEN TOTAL'!P6 -> 0 | L3: ='RESUMEN TOTAL'!Q6 -> 0 | M3: ='RESUMEN TOTAL'!R6 -> 0 | ... AI3: ='RESUMEN TOTAL'!AN6 -> 0
A4: ='RESUMEN TOTAL'!A7 -> ALTAMIRA | B4: ='RESUMEN TOTAL'!B7 -> ALT 06 | C4: ='RESUMEN TOTAL'!D7 -> LOPE DE VEGA Y NECOCHEA | D4: ='RESUMEN TOTAL'!E7 -> Domo | E4: ='RESUMEN TOTAL'!F7 -> PTO A FO | F4: ='RESUMEN TOTAL'!K7 -> 0 | G4: ='RESUMEN TOTAL'!L7 -> 0 | H4: ='RESUMEN TOTAL'!M7 -> 0 | I4: ='RESUMEN TOTAL'!N7 -> 0 | J4: ='RESUMEN TOTAL'!O7 -> 0 | K4: ='RESUMEN TOTAL'!P7 -> 0 | L4: ='RESUMEN TOTAL'!Q7 -> 0 | M4: ='RESUMEN TOTAL'!R7 -> 0 | ... AI4: ='RESUMEN TOTAL'!AN7 -> 0
A5: ='RESUMEN TOTAL'!A8 -> ALTAMIRA | B5: ='RESUMEN TOTAL'!B8 -> ALT 08 | C5: ='RESUMEN TOTAL'!D8 -> HUMAITA Y NECOCHEA | D5: ='RESUMEN TOTAL'!E8 -> DOMO | E5: ='RESUMEN TOTAL'!F8 -> Fibra Optica | F5: ='RESUMEN TOTAL'!K8 -> 0 | G5: ='RESUMEN TOTAL'!L8 -> 0 | H5: ='RESUMEN TOTAL'!M8 -> 0 | I5: ='RESUMEN TOTAL'!N8 -> 0 | J5: ='RESUMEN TOTAL'!O8 -> 0 | K5: ='RESUMEN TOTAL'!P8 -> 0 | L5: ='RESUMEN TOTAL'!Q8 -> 0 | M5: ='RESUMEN TOTAL'!R8 -> 0 | ... AI5: ='RESUMEN TOTAL'!AN8 -> 0
A6: ='RESUMEN TOTAL'!A9 -> ALTAMIRA | B6: ='RESUMEN TOTAL'!B9 -> ALT 09 | C6: ='RESUMEN TOTAL'!D9 -> NECOCHEA Y CURUPAITY | D6: ='RESUMEN TOTAL'!E9 -> DOMO | E6: ='RESUMEN TOTAL'!F9 -> Fibra Optica | F6: ='RESUMEN TOTAL'!K9 -> 0 | G6: ='RESUMEN TOTAL'!L9 -> 0 | H6: ='RESUMEN TOTAL'!M9 -> 0 | I6: ='RESUMEN TOTAL'!N9 -> 0 | J6: ='RESUMEN TOTAL'!O9 -> 0 | K6: ='RESUMEN TOTAL'!P9 -> 0 | L6: ='RESUMEN TOTAL'!Q9 -> 0 | M6: ='RESUMEN TOTAL'!R9 -> 0 | ... AI6: ='RESUMEN TOTAL'!AN9 -> 0
A7: ='RESUMEN TOTAL'!A10 -> ALTAMIRA | B7: ='RESUMEN TOTAL'!B10 -> ALT 10 | C7: ='RESUMEN TOTAL'!D10 -> Calchaqui y Francia | D7: ='RESUMEN TOTAL'!E10 -> Domo | E7: ='RESUMEN TOTAL'!F10 -> Radio | F7: ='RESUMEN TOTAL'!K10 -> APAGADO | G7: ='RESUMEN TOTAL'!L10 -> APAGADO | H7: ='RESUMEN TOTAL'!M10 -> APAGADO | I7: ='RESUMEN TOTAL'!N10 -> APAGADO | J7: ='RESUMEN TOTAL'!O10 -> APAGADO | K7: ='RESUMEN TOTAL'!P10 -> APAGADO | L7: ='RESUMEN TOTAL'!Q10 -> APAGADO | M7: ='RESUMEN TOTAL'!R10 -> 0 | ... AI7: ='RESUMEN TOTAL'!AN10 -> 0
A8: ='RESUMEN TOTAL'!A11 -> ALTAMIRA | B8: ='RESUMEN TOTAL'!B11 -> ALT01 | C8: ='RESUMEN TOTAL'!D11 -> Calchaqui y Sgto. Cabral | D8: ='RESUMEN TOTAL'!E11 -> Domo | E8: ='RESUMEN TOTAL'!F11 -> Fibra Optica | F8: ='RESUMEN TOTAL'!K11 -> 0 | G8: ='RESUMEN TOTAL'!L11 -> 0 | H8: ='RESUMEN TOTAL'!M11 -> 0 | I8: ='RESUMEN TOTAL'!N11 -> 0 | J8: ='RESUMEN TOTAL'!O11 -> 0 | K8: ='RESUMEN TOTAL'!P11 -> 0 | L8: ='RESUMEN TOTAL'!Q11 -> 0 | M8: ='RESUMEN TOTAL'!R11 -> 0 | ... AI8: ='RESUMEN TOTAL'!AN11 -> 0
A9: ='RESUMEN TOTAL'!A12 -> ALTAMIRA | B9: ='RESUMEN TOTAL'!B12 -> ALT02 | C9: ='RESUMEN TOTAL'!D12 -> Calchaqui y Lope de Vega | D9: ='RESUMEN TOTAL'!E12 -> Domo | E9: ='RESUMEN TOTAL'!F12 -> PTO A FO | F9: ='RESUMEN TOTAL'!K12 -> 0 | G9: ='RESUMEN TOTAL'!L12 -> 0 | H9: ='RESUMEN TOTAL'!M12 -> 0 | I9: ='RESUMEN TOTAL'!N12 -> 0 | J9: ='RESUMEN TOTAL'!O12 -> 0 | K9: ='RESUMEN TOTAL'!P12 -> 0 | L9: ='RESUMEN TOTAL'!Q12 -> 0 | M9: ='RESUMEN TOTAL'!R12 -> 0 | ... AI9: ='RESUMEN TOTAL'!AN12 -> 0
A10: ='RESUMEN TOTAL'!A13 -> ALTAMIRA | B10: ='RESUMEN TOTAL'!B13 -> ALT05 | C10: ='RESUMEN TOTAL'!D13 -> Av. Calchaqui y Bombero Galarza | D10: ='RESUMEN TOTAL'!E13 -> Domo | E10: ='RESUMEN TOTAL'!F13 -> PTO A FO | F10: ='RESUMEN TOTAL'!K13 -> APAGADO | G10: ='RESUMEN TOTAL'!L13 -> APAGADO | H10: ='RESUMEN TOTAL'!M13 -> APAGADO | I10: ='RESUMEN TOTAL'!N13 -> APAGADO | J10: ='RESUMEN TOTAL'!O13 -> APAGADO | K10: ='RESUMEN TOTAL'!P13 -> APAGADO | L10: ='RESUMEN TOTAL'!Q13 -> APAGADO | M10: ='RESUMEN TOTAL'!R13 -> 0 | ... AI10: ='RESUMEN TOTAL'!AN13 -> 0
A11: ='RESUMEN TOTAL'!A14 -> ALTAMIRA | B11: ='RESUMEN TOTAL'!B14 -> ALT07 | C11: ='RESUMEN TOTAL'!D14 -> AV. CALCHAQUI Y AV. DEL TRABAJO | D11: ='RESUMEN TOTAL'!E14 -> DOMO | E11: ='RESUMEN TOTAL'!F14 -> PTO A FO | F11: ='RESUMEN TOTAL'!K14 -> 0 | G11: ='RESUMEN TOTAL'!L14 -> 0 | H11: ='RESUMEN TOTAL'!M14 -> 0 | I11: ='RESUMEN TOTAL'!N14 -> 0 | J11: ='RESUMEN TOTAL'!O14 -> 0 | K11: ='RESUMEN TOTAL'!P14 -> 0 | L11: ='RESUMEN TOTAL'!Q14 -> 0 | M11: ='RESUMEN TOTAL'!R14 -> 0 | ... AI11: ='RESUMEN TOTAL'!AN14 -> 0
A12: ='RESUMEN TOTAL'!A15 -> AGUSTIN RAMIREZ | B12: ='RESUMEN TOTAL'!B15 -> ARA 01 | C12: ='RESUMEN TOTAL'!D15 -> Malambo y Tranquera | D12: ='RESUMEN TOTAL'!E15 -> Domo | E12: ='RESUMEN TOTAL'!F15 -> FIBRA OPTICA | F12: ='RESUMEN TOTAL'!K15 -> 0 | G12: ='RESUMEN TOTAL'!L15 -> 0 | H12: ='RESUMEN TOTAL'!M15 -> 0 | I12: ='RESUMEN TOTAL'!N15 -> 0 | J12: ='RESUMEN TOTAL'!O15 -> 0 | K12: ='RESUMEN TOTAL'!P15 -> 0 | L12: ='RESUMEN TOTAL'!Q15 -> 0 | M12: ='RESUMEN TOTAL'!R15 -> 0 | ... AI12: ='RESUMEN TOTAL'!AN15 -> 0
... A330: ='RESUMEN TOTAL'!A333 -> VILLA ARGENTINA | B330: ='RESUMEN TOTAL'!B333 -> VAR11 (fija 2) | C330: ='RESUMEN TOTAL'!D333 -> 532 A Y 523 | D330: ='RESUMEN TOTAL'!E333 -> Fija | E330: ='RESUMEN TOTAL'!F333 -> FIBRA OPTICA | F330: ='RESUMEN TOTAL'!K333 -> 0 | G330: ='RESUMEN TOTAL'!L333 -> 0 | H330: ='RESUMEN TOTAL'!M333 -> 0 | I330: ='RESUMEN TOTAL'!N333 -> 0 | J330: ='RESUMEN TOTAL'!O333 -> 0 | K330: ='RESUMEN TOTAL'!P333 -> 0 | L330: ='RESUMEN TOTAL'!Q333 -> 0 | M330: ='RESUMEN TOTAL'!R333 -> 0 | ... AI330: ='RESUMEN TOTAL'!AN333 -> 0
A331: ='RESUMEN TOTAL'!A337 -> VILLA VATTEONE CENTRO | B331: ='RESUMEN TOTAL'!B337 -> VAT 10 | C331: ='RESUMEN TOTAL'!D337 -> Belgrano y Quintana | D331: ='RESUMEN TOTAL'!E337 -> Domo | E331: ='RESUMEN TOTAL'!F337 -> Fibra Optica | F331: ='RESUMEN TOTAL'!K337 -> 0 | G331: ='RESUMEN TOTAL'!L337 -> 0 | H331: ='RESUMEN TOTAL'!M337 -> 0 | I331: ='RESUMEN TOTAL'!N337 -> APAGADO | J331: ='RESUMEN TOTAL'!O337 -> APAGADO | K331: ='RESUMEN TOTAL'!P337 -> 0 | L331: ='RESUMEN TOTAL'!Q337 -> 0 | M331: ='RESUMEN TOTAL'!R337 -> 0 | ... AI331: ='RESUMEN TOTAL'!AN337 -> 0
A332: ='RESUMEN TOTAL'!A338 -> VILLA VATTEONE | B332: ='RESUMEN TOTAL'!B338 -> VAT 14 | C332: ='RESUMEN TOTAL'!D338 -> FLORIDA Y MONTEVIDEO | D332: ='RESUMEN TOTAL'!E338 -> DOMO | E332: ='RESUMEN TOTAL'!F338 -> FIBRA OPTICA | F332: ='RESUMEN TOTAL'!K338 -> 0 | G332: ='RESUMEN TOTAL'!L338 -> 0 | H332: ='RESUMEN TOTAL'!M338 -> 0 | I332: ='RESUMEN TOTAL'!N338 -> 0 | J332: ='RESUMEN TOTAL'!O338 -> 0 | K332: ='RESUMEN TOTAL'!P338 -> 0 | L332: ='RESUMEN TOTAL'!Q338 -> 0 | M332: ='RESUMEN TOTAL'!R338 -> 0 | ... AI332: ='RESUMEN TOTAL'!AN338 -> 0
A333: ='RESUMEN TOTAL'!A339 -> VILLA VATTEONE | B333: ='RESUMEN TOTAL'!B339 -> VAT 15 | C333: ='RESUMEN TOTAL'!D339 -> CORRIENTES Y VICENTE LOPEZ | D333: ='RESUMEN TOTAL'!E339 -> DOMO | E333: ='RESUMEN TOTAL'!F339 -> PTO A FO | F333: ='RESUMEN TOTAL'!K339 -> 0 | G333: ='RESUMEN TOTAL'!L339 -> 0 | H333: ='RESUMEN TOTAL'!M339 -> APAGADO | I333: ='RESUMEN TOTAL'!N339 -> APAGADO | J333: ='RESUMEN TOTAL'!O339 -> APAGADO | K333: ='RESUMEN TOTAL'!P339 -> 0 | L333: ='RESUMEN TOTAL'!Q339 -> 0 | M333: ='RESUMEN TOTAL'!R339 -> 0 | ... AI333: ='RESUMEN TOTAL'!AN339 -> 0
A334: ='RESUMEN TOTAL'!A340 -> VILLA VATTEONE | B334: ='RESUMEN TOTAL'!B340 -> VAT 16 | C334: ='RESUMEN TOTAL'!D340 -> MONTEVIDEO Y CHACO | D334: ='RESUMEN TOTAL'!E340 -> DOMO | E334: ='RESUMEN TOTAL'!F340 -> PTO A FO | F334: ='RESUMEN TOTAL'!K340 -> 0 | G334: ='RESUMEN TOTAL'!L340 -> 0 | H334: ='RESUMEN TOTAL'!M340 -> APAGADO | I334: ='RESUMEN TOTAL'!N340 -> APAGADO | J334: ='RESUMEN TOTAL'!O340 -> 0 | K334: ='RESUMEN TOTAL'!P340 -> 0 | L334: ='RESUMEN TOTAL'!Q340 -> 0 | M334: ='RESUMEN TOTAL'!R340 -> 0 | ... AI334: ='RESUMEN TOTAL'!AN340 -> 0
A335: ='RESUMEN TOTAL'!A341 -> VILLA VATTEONE | B335: ='RESUMEN TOTAL'!B341 -> VAT 17 | C335: ='RESUMEN TOTAL'!D341 -> CHAÑAR Y URUGUAY | D335: ='RESUMEN TOTAL'!E341 -> DOMO | E335: ='RESUMEN TOTAL'!F341 -> PTO A FO | F335: ='RESUMEN TOTAL'!K341 -> 0 | G335: ='RESUMEN TOTAL'!L341 -> 0 | H335: ='RESUMEN TOTAL'!M341 -> 0 | I335: ='RESUMEN TOTAL'!N341 -> 0 | J335: ='RESUMEN TOTAL'!O341 -> 0 | K335: ='RESUMEN TOTAL'!P341 -> 0 | L335: ='RESUMEN TOTAL'!Q341 -> 0 | M335: ='RESUMEN TOTAL'!R341 -> 0 | ... AI335: ='RESUMEN TOTAL'!AN341 -> 0
A336: ='RESUMEN TOTAL'!A342 -> VILLA VATTEONE | B336: ='RESUMEN TOTAL'!B342 -> VAT 20 | C336: ='RESUMEN TOTAL'!D342 -> URUGUAY Y PILCOMAYO | D336: ='RESUMEN TOTAL'!E342 -> FIJA | E336: ='RESUMEN TOTAL'!F342 -> Radio | F336: ='RESUMEN TOTAL'!K342 -> 0 | G336: ='RESUMEN TOTAL'!L342 -> 0 | H336: ='RESUMEN TOTAL'!M342 -> APAGADO | I336: ='RESUMEN TOTAL'!N342 -> APAGADO | J336: ='RESUMEN TOTAL'!O342 -> 0 | K336: ='RESUMEN TOTAL'!P342 -> 0 | L336: ='RESUMEN TOTAL'!Q342 -> 0 | M336: ='RESUMEN TOTAL'!R342 -> 0 | ... AI336: ='RESUMEN TOTAL'!AN342 -> 0
A337: ='RESUMEN TOTAL'!A343 -> VILLA VATTEONE CENTRO | B337: ='RESUMEN TOTAL'!B343 -> VAT 21 (fija 1) | C337: ='RESUMEN TOTAL'!D343 -> QUINTANA E/ BELGRANO Y FONROUGE | D337: ='RESUMEN TOTAL'!E343 -> Fija | E337: ='RESUMEN TOTAL'!F343 -> Fibra Optica | F337: ='RESUMEN TOTAL'!K343 -> 0 | G337: ='RESUMEN TOTAL'!L343 -> 0 | H337: ='RESUMEN TOTAL'!M343 -> 0 | I337: ='RESUMEN TOTAL'!N343 -> APAGADO | J337: ='RESUMEN TOTAL'!O343 -> APAGADO | K337: ='RESUMEN TOTAL'!P343 -> 0 | L337: ='RESUMEN TOTAL'!Q343 -> 0 | M337: ='RESUMEN TOTAL'!R343 -> 0 | ... AI337: ='RESUMEN TOTAL'!AN343 -> 0
A338: ='RESUMEN TOTAL'!A344 -> VILLA VATTEONE CENTRO | B338: ='RESUMEN TOTAL'!B344 -> VAT 22 (fija 2) | C338: ='RESUMEN TOTAL'!D344 -> QUINTANA E/ BELGRANO Y FONROUGE | D338: ='RESUMEN TOTAL'!E344 -> Fija | E338: ='RESUMEN TOTAL'!F344 -> Fibra Optica | F338: ='RESUMEN TOTAL'!K344 -> 0 | G338: ='RESUMEN TOTAL'!L344 -> 0 | H338: ='RESUMEN TOTAL'!M344 -> 0 | I338: ='RESUMEN TOTAL'!N344 -> APAGADO | J338: ='RESUMEN TOTAL'!O344 -> APAGADO | K338: ='RESUMEN TOTAL'!P344 -> 0 | L338: ='RESUMEN TOTAL'!Q344 -> 0 | M338: ='RESUMEN TOTAL'!R344 -> 0 | ... AI338: ='RESUMEN TOTAL'!AN344 -> 0
A339: ='RESUMEN TOTAL'!A345 -> VILLA VATTEONE | B339: ='RESUMEN TOTAL'!B345 -> VAT01 | C339: ='RESUMEN TOTAL'!D345 -> Montevideo y El ChaÃ±ar | D339: ='RESUMEN TOTAL'!E345 -> Domo | E339: ='RESUMEN TOTAL'!F345 -> Fibra Optica | F339: ='RESUMEN TOTAL'!K345 -> 0 | G339: ='RESUMEN TOTAL'!L345 -> 0 | H339: ='RESUMEN TOTAL'!M345 -> 0 | I339: ='RESUMEN TOTAL'!N345 -> 0 | J339: ='RESUMEN TOTAL'!O345 -> 0 | K339: ='RESUMEN TOTAL'!P345 -> 0 | L339: ='RESUMEN TOTAL'!Q345 -> 0 | M339: ='RESUMEN TOTAL'!R345 -> 0 | ... AI339: ='RESUMEN TOTAL'!AN345 -> 0
A340: ='RESUMEN TOTAL'!A346 -> VILLA VATTEONE CENTRO | B340: ='RESUMEN TOTAL'!B346 -> VAT02 | C340: ='RESUMEN TOTAL'!D346 -> Eva Peron y 12 de Octubre | D340: ='RESUMEN TOTAL'!E346 -> Domo | E340: ='RESUMEN TOTAL'!F346 -> Fibra Optica | F340: ='RESUMEN TOTAL'!K346 -> 0 | G340: ='RESUMEN TOTAL'!L346 -> 0 | H340: ='RESUMEN TOTAL'!M346 -> APAGADO | I340: ='RESUMEN TOTAL'!N346 -> APAGADO | J340: ='RESUMEN TOTAL'!O346 -> 0 | K340: ='RESUMEN TOTAL'!P346 -> 0 | L340: ='RESUMEN TOTAL'!Q346 -> 0 | M340: ='RESUMEN TOTAL'!R346 -> 0 | ... AI340: ='RESUMEN TOTAL'!AN346 -> 0
A341: ='RESUMEN TOTAL'!A347 -> VILLA VATTEONE CENTRO | B341: ='RESUMEN TOTAL'!B347 -> VAT03 | C341: ='RESUMEN TOTAL'!D347 -> Lavalle y Belgrano | D341: ='RESUMEN TOTAL'!E347 -> Domo | E341: ='RESUMEN TOTAL'!F347 -> Fibra Optica | F341: ='RESUMEN TOTAL'!K347 -> 0 | G341: ='RESUMEN TOTAL'!L347 -> 0 | H341: ='RESUMEN TOTAL'!M347 -> 0 | I341: ='RESUMEN TOTAL'!N347 -> APAGADO | J341: ='RESUMEN TOTAL'!O347 -> APAGADO | K341: ='RESUMEN TOTAL'!P347 -> 0 | L341: ='RESUMEN TOTAL'!Q347 -> 0 | M341: ='RESUMEN TOTAL'!R347 -> 0 | ... AI341: ='RESUMEN TOTAL'!AN347 -> 0
A342: ='RESUMEN TOTAL'!A348 -> VILLA VATTEONE CENTRO | B342: ='RESUMEN TOTAL'!B348 -> VAT04 | C342: ='RESUMEN TOTAL'!D348 -> Lavalle y Entre Rios | D342: ='RESUMEN TOTAL'!E348 -> Domo | E342: ='RESUMEN TOTAL'!F348 -> Fibra Optica | F342: ='RESUMEN TOTAL'!K348 -> 0 | G342: ='RESUMEN TOTAL'!L348 -> 0 | H342: ='RESUMEN TOTAL'!M348 -> 0 | I342: ='RESUMEN TOTAL'!N348 -> APAGADO | J342: ='RESUMEN TOTAL'!O348 -> APAGADO | K342: ='RESUMEN TOTAL'!P348 -> 0 | L342: ='RESUMEN TOTAL'!Q348 -> 0 | M342: ='RESUMEN TOTAL'!R348 -> 0 | ... AI342: ='RESUMEN TOTAL'!AN348 -> 0
... A393: ='RESUMEN TOTAL'!A399 -> ZEBALLOS | B393: ='RESUMEN TOTAL'!B399 -> ZEB04 | C393: ='RESUMEN TOTAL'!D399 -> THEVENET Y DIAGONAL GRANADEROS | D393: ='RESUMEN TOTAL'!E399 -> DOMO | E393: ='RESUMEN TOTAL'!F399 -> Radio | F393: ='RESUMEN TOTAL'!K399 -> 0 | G393: ='RESUMEN TOTAL'!L399 -> 0 | H393: ='RESUMEN TOTAL'!M399 -> 0 | I393: ='RESUMEN TOTAL'!N399 -> 0 | J393: ='RESUMEN TOTAL'!O399 -> 0 | K393: ='RESUMEN TOTAL'!P399 -> 0 | L393: ='RESUMEN TOTAL'!Q399 -> 0 | M393: ='RESUMEN TOTAL'!R399 -> 0 | ... AI393: ='RESUMEN TOTAL'!AN399 -> 0
A394: ='RESUMEN TOTAL'!A334 -> VILLA ARGENTINA | B394: ='RESUMEN TOTAL'!B334 -> VAR12 | C394: ='RESUMEN TOTAL'!D334 -> Calle 527 y Portela | D394: ='RESUMEN TOTAL'!E334 -> Domo | E394: ='RESUMEN TOTAL'!F334 -> Fibra Optica | F394: ='RESUMEN TOTAL'!K334 -> 0 | G394: ='RESUMEN TOTAL'!L334 -> 0 | H394: ='RESUMEN TOTAL'!M334 -> 0 | I394: ='RESUMEN TOTAL'!N334 -> 0 | J394: ='RESUMEN TOTAL'!O334 -> 0 | K394: ='RESUMEN TOTAL'!P334 -> 0 | L394: ='RESUMEN TOTAL'!Q334 -> 0 | M394: ='RESUMEN TOTAL'!R334 -> 0 | ... AI394: ='RESUMEN TOTAL'!AN334 -> 0
A395: ='RESUMEN TOTAL'!A335 -> VILLA ARGENTINA | B395: ='RESUMEN TOTAL'!B335 -> VAR13 | C395: ='RESUMEN TOTAL'!D335 -> Calle 527 y 532 | D395: ='RESUMEN TOTAL'!E335 -> Domo | E395: ='RESUMEN TOTAL'!F335 -> Fibra Optica | F395: ='RESUMEN TOTAL'!K335 -> 0 | G395: ='RESUMEN TOTAL'!L335 -> 0 | H395: ='RESUMEN TOTAL'!M335 -> 0 | I395: ='RESUMEN TOTAL'!N335 -> 0 | J395: ='RESUMEN TOTAL'!O335 -> 0 | K395: ='RESUMEN TOTAL'!P335 -> 0 | L395: ='RESUMEN TOTAL'!Q335 -> 0 | M395: ='RESUMEN TOTAL'!R335 -> 0 | ... AI395: ='RESUMEN TOTAL'!AN335 -> 0
A396: ='RESUMEN TOTAL'!A336 -> VILLA ARGENTINA | B396: ='RESUMEN TOTAL'!B336 -> VAR14 | C396: ='RESUMEN TOTAL'!D336 -> Pportela y 517 | D396: ='RESUMEN TOTAL'!E336 -> Domo | E396: ='RESUMEN TOTAL'!F336 -> Fibra Optica | F396: ='RESUMEN TOTAL'!K336 -> 0 | G396: ='RESUMEN TOTAL'!L336 -> 0 | H396: ='RESUMEN TOTAL'!M336 -> 0 | I396: ='RESUMEN TOTAL'!N336 -> 0 | J396: ='RESUMEN TOTAL'!O336 -> 0 | K396: ='RESUMEN TOTAL'!P336 -> 0 | L396: ='RESUMEN TOTAL'!Q336 -> 0 | M396: ='RESUMEN TOTAL'!R336 -> 0 | ... AI396: ='RESUMEN TOTAL'!AN336 -> 0
A397: ='RESUMEN TOTAL'!A400 -> 0 | B397: ='RESUMEN TOTAL'!B400 -> 0 | C397: ='RESUMEN TOTAL'!D400 -> 0 | D397: ='RESUMEN TOTAL'!E400 -> 0 | E397: ='RESUMEN TOTAL'!F400 -> 0 | F397: ='RESUMEN TOTAL'!K400 -> 0 | G397: ='RESUMEN TOTAL'!L400 -> 0 | H397: ='RESUMEN TOTAL'!M400 -> 0 | I397: ='RESUMEN TOTAL'!N400 -> 0 | J397: ='RESUMEN TOTAL'!O400 -> 0 | K397: ='RESUMEN TOTAL'!P400 -> 0 | L397: ='RESUMEN TOTAL'!Q400 -> 0 | M397: ='RESUMEN TOTAL'!R400 -> 0 | ... AI397: ='RESUMEN TOTAL'!AN400 -> 0
A398: ='RESUMEN TOTAL'!A401 -> 0 | B398: ='RESUMEN TOTAL'!B401 -> 0 | C398: ='RESUMEN TOTAL'!D401 -> 0 | D398: ='RESUMEN TOTAL'!E401 -> 0 | E398: ='RESUMEN TOTAL'!F401 -> 0 | F398: ='RESUMEN TOTAL'!K401 -> 0 | G398: ='RESUMEN TOTAL'!L401 -> 0 | H398: ='RESUMEN TOTAL'!M401 -> 0 | I398: ='RESUMEN TOTAL'!N401 -> 0 | J398: ='RESUMEN TOTAL'!O401 -> 0 | K398: ='RESUMEN TOTAL'!P401 -> 0 | L398: ='RESUMEN TOTAL'!Q401 -> 0 | M398: ='RESUMEN TOTAL'!R401 -> 0 | ... AI398: ='RESUMEN TOTAL'!AN401 -> 0
A399: ='RESUMEN TOTAL'!A402 -> 0 | B399: ='RESUMEN TOTAL'!B402 -> 0 | C399: ='RESUMEN TOTAL'!D402 -> 0 | D399: ='RESUMEN TOTAL'!E402 -> 0 | E399: ='RESUMEN TOTAL'!F402 -> 0 | F399: ='RESUMEN TOTAL'!K402 -> 0 | G399: ='RESUMEN TOTAL'!L402 -> 0 | H399: ='RESUMEN TOTAL'!M402 -> 0 | I399: ='RESUMEN TOTAL'!N402 -> 0 | J399: ='RESUMEN TOTAL'!O402 -> 0 | K399: ='RESUMEN TOTAL'!P402 -> 0 | L399: ='RESUMEN TOTAL'!Q402 -> 0 | M399: ='RESUMEN TOTAL'!R402 -> 0 | ... AI399: ='RESUMEN TOTAL'!AN402 -> 0

Sheet APAGADOS
E1: APAGADOS | F1: =COUNTIF(F3:F400, "APAGADO") -> 28 | G1: =COUNTIF(G3:G400, "APAGADO") -> 53 | H1: =COUNTIF(H3:H400, "APAGADO") -> 86 | I1: =COUNTIF(I3:I400, "APAGADO") -> 88 | J1: =COUNTIF(J3:J400, "APAGADO") -> 38 | K1: =COUNTIF(K3:K400, "APAGADO") -> 32 | L1: =COUNTIF(L3:L400, "APAGADO") -> 21 | M1: =COUNTIF(M3:M400, "APAGADO") -> 0 | ... AI1: =COUNTIF(AI3:AI400, "APAGADO") -> 0
A2: =ESTADISTICA!A1 -> Barrio | B2: =ESTADISTICA!B1 -> [Denominacion] | C2: =ESTADISTICA!C1 -> [Ubicacion] | D2: =ESTADISTICA!D1 -> [Tipo de Camara] | E2: =ESTADISTICA!E1 -> [Tipo de Conexion] | F2: =ESTADISTICA!F1 -> 44805 | G2: =ESTADISTICA!G1 -> 44806 | H2: =ESTADISTICA!H1 -> 44807 | ... AI2: =ESTADISTICA!AI1 -> 44834
A3: =ESTADISTICA!A2 -> ALTAMIRA | B3: =ESTADISTICA!B2 -> ALT 03 | C3: =ESTADISTICA!C2 -> Bombero Galarza y Necochea | D3: =ESTADISTICA!D2 -> Domo | E3: =ESTADISTICA!E2 -> FIBRA OPTICA | F3: =ESTADISTICA!F2 -> 0 | G3: =ESTADISTICA!G2 -> 0 | H3: =ESTADISTICA!H2 -> 0 | ... AI3: =ESTADISTICA!AI2 -> 0
A4: =ESTADISTICA!A3 -> ALTAMIRA | B4: =ESTADISTICA!B3 -> ALT 04 | C4: =ESTADISTICA!C3 -> Francia y Necochea | D4: =ESTADISTICA!D3 -> Domo | E4: =ESTADISTICA!E3 -> FIBRA OPTICA | F4: =ESTADISTICA!F3 -> 0 | G4: =ESTADISTICA!G3 -> 0 | H4: =ESTADISTICA!H3 -> 0 | ... AI4: =ESTADISTICA!AI3 -> 0
A5: =ESTADISTICA!A4 -> ALTAMIRA | B5: =ESTADISTICA!B4 -> ALT 06 | C5: =ESTADISTICA!C4 -> LOPE DE VEGA Y NECOCHEA | D5: =ESTADISTICA!D4 -> Domo | E5: =ESTADISTICA!E4 -> PTO A FO | F5: =ESTADISTICA!F4 -> 0 | G5: =ESTADISTICA!G4 -> 0 | H5: =ESTADISTICA!H4 -> 0 | ... AI5: =ESTADISTICA!AI4 -> 0
A6: =ESTADISTICA!A5 -> ALTAMIRA | B6: =ESTADISTICA!B5 -> ALT 08 | C6: =ESTADISTICA!C5 -> HUMAITA Y NECOCHEA | D6: =ESTADISTICA!D5 -> DOMO | E6: =ESTADISTICA!E5 -> Fibra Optica | F6: =ESTADISTICA!F5 -> 0 | G6: =ESTADISTICA!G5 -> 0 | H6: =ESTADISTICA!H5 -> 0 | ... AI6: =ESTADISTICA!AI5 -> 0
A7: =ESTADISTICA!A6 -> ALTAMIRA | B7: =ESTADISTICA!B6 -> ALT 09 | C7: =ESTADISTICA!C6 -> NECOCHEA Y CURUPAITY | D7: =ESTADISTICA!D6 -> DOMO | E7: =ESTADISTICA!E6 -> Fibra Optica | F7: =ESTADISTICA!F6 -> 0 | G7: =ESTADISTICA!G6 -> 0 | H7: =ESTADISTICA!H6 -> 0 | ... AI7: =ESTADISTICA!AI6 -> 0
A8: =ESTADISTICA!A7 -> ALTAMIRA | B8: =ESTADISTICA!B7 -> ALT 10 | C8: =ESTADISTICA!C7 -> Calchaqui y Francia | D8: =ESTADISTICA!D7 -> Domo | E8: =ESTADISTICA!E7 -> Radio | F8: =ESTADISTICA!F7 -> APAGADO | G8: =ESTADISTICA!G7 -> APAGADO | H8: =ESTADISTICA!H7 -> APAGADO | ... AI8: =ESTADISTICA!AI7 -> 0
A9: =ESTADISTICA!A8 -> ALTAMIRA | B9: =ESTADISTICA!B8 -> ALT01 | C9: =ESTADISTICA!C8 -> Calchaqui y Sgto. Cabral | D9: =ESTADISTICA!D8 -> Domo | E9: =ESTADISTICA!E8 -> Fibra Optica | F9: =ESTADISTICA!F8 -> 0 | G9: =ESTADISTICA!G8 -> 0 | H9: =ESTADISTICA!H8 -> 0 | ... AI9: =ESTADISTICA!AI8 -> 0
A10: =ESTADISTICA!A9 -> ALTAMIRA | B10: =ESTADISTICA!B9 -> ALT02 | C10: =ESTADISTICA!C9 -> Calchaqui y Lope de Vega | D10: =ESTADISTICA!D9 -> Domo | E10: =ESTADISTICA!E9 -> PTO A FO | F10: =ESTADISTICA!F9 -> 0 | G10: =ESTADISTICA!G9 -> 0 | H10: =ESTADISTICA!H9 -> 0 | ... AI10: =ESTADISTICA!AI9 -> 0
A11: =ESTADISTICA!A10 -> ALTAMIRA | B11: =ESTADISTICA!B10 -> ALT05 | C11: =ESTADISTICA!C10 -> Av. Calchaqui y Bombero Galarza | D11: =ESTADISTICA!D10 -> Domo | E11: =ESTADISTICA!E10 -> PTO A FO | F11: =ESTADISTICA!F10 -> APAGADO | G11: =ESTADISTICA!G10 -> APAGADO | H11: =ESTADISTICA!H10 -> APAGADO | ... AI11: =ESTADISTICA!AI10 -> 0
A12: =ESTADISTICA!A11 -> ALTAMIRA | B12: =ESTADISTICA!B11 -> ALT07 | C12: =ESTADISTICA!C11 -> AV. CALCHAQUI Y AV. DEL TRABAJO | D12: =ESTADISTICA!D11 -> DOMO | E12: =ESTADISTICA!E11 -> PTO A FO | F12: =ESTADISTICA!F11 -> 0 | G12: =ESTADISTICA!G11 -> 0 | H12: =ESTADISTICA!H11 -> 0 | ... AI12: =ESTADISTICA!AI11 -> 0
A13: =ESTADISTICA!A12 -> AGUSTIN RAMIREZ | B13: =ESTADISTICA!B12 -> ARA 01 | C13: =ESTADISTICA!C12 -> Malambo y Tranquera | D13: =ESTADISTICA!D12 -> Domo | E13: =ESTADISTICA!E12 -> FIBRA OPTICA | F13: =ESTADISTICA!F12 -> 0 | G13: =ESTADISTICA!G12 -> 0 | H13: =ESTADISTICA!H12 -> 0 | ... AI13: =ESTADISTICA!AI12 -> 0
... A401: =ESTADISTICA!A400 -> 0 | B401: =ESTADISTICA!B400 -> 0 | C401: =ESTADISTICA!C400 -> 0 | D401: =ESTADISTICA!D400 -> 0 | E401: =ESTADISTICA!E400 -> 0 | F401: =ESTADISTICA!F400 -> 0 | G401: =ESTADISTICA!G400 -> 0 | H401: =ESTADISTICA!H400 -> 0 | ... AI401: =ESTADISTICA!AI400 -> 0

Sheet APAGADOS FIBRA
C1: TOTAL FIBRA | D1: =COUNTIFS(E4:E400,"=Fibra Optica") -> 264
E2: APAGADOS | F2: =COUNTIFS(F4:F400, "=APAGADO",E4:E400,"=Fibra Optica") -> 22 | G2: =COUNTIFS(G4:G400, "=APAGADO",E4:E400,"=Fibra Optica") -> 49 | H2: =COUNTIFS(H4:H400, "=APAGADO",E4:E400,"=Fibra Optica") -> 55 | I2: =COUNTIFS(I4:I400, "=APAGADO",E4:E400,"=Fibra Optica") -> 54 | J2: =COUNTIFS(J4:J400, "=APAGADO",E4:E400,"=Fibra Optica") -> 32 | K2: =COUNTIFS(K4:K400, "=APAGADO",E4:E400,"=Fibra Optica") -> 29 | L2: =COUNTIFS(L4:L400, "=APAGADO",E4:E400,"=Fibra Optica") -> 17 | M2: =COUNTIFS(M4:M400, "=APAGADO",E4:E400,"=Fibra Optica") -> 0 | N2: =COUNTIFS(N4:N400, "=APAGADO",E4:E400,"=Fibra Optica") -> 0 | O2: =COUNTIFS(O4:O400, "=APAGADO",E4:E400,"=Fibra Optica") -> 0 | P2: =COUNTIFS(P4:P400, "=APAGADO",E4:E400,"=Fibra Optica") -> 0 | Q2: =COUNTIFS(Q4:Q400, "=APAGADO",E4:E400,"=Fibra Optica") -> 0 | R2: =COUNTIFS(R4:R400, "=APAGADO",E4:E400,"=Fibra Optica") -> 0 | S2: =COUNTIFS(S4:S400, "=APAGADO",E4:E400,"=Fibra Optica") -> 0 | T2: =COUNTIFS(T4:T400, "=APAGADO",E4:E400,"=Fibra Optica") -> 0 | U2: =COUNTIFS(U4:U400, "=APAGADO",E4:E400,"=Fibra Optica") -> 0 | V2: =COUNTIFS(V4:V400, "=APAGADO",E4:E400,"=Fibra Optica") -> 0 | W2: =COUNTIFS(W4:W400, "=APAGADO",E4:E400,"=Fibra Optica") -> 0 | X2: =COUNTIFS(X4:X400, "=APAGADO",E4:E400,"=Fibra Optica") -> 0 | Y2: =COUNTIFS(Y4:Y400, "=APAGADO",E4:E400,"=Fibra Optica") -> 0 | Z2: =COUNTIFS(Z4:Z400, "=APAGADO",E4:E400,"=Fibra Optica") -> 0 | AA2: =COUNTIFS(AA4:AA400, "=APAGADO",E4:E400,"=Fibra Optica") -> 0 | AB2: =COUNTIFS(AB4:AB400, "=APAGADO",E4:E400,"=Fibra Optica") -> 0 | AC2: =COUNTIFS(AC4:AC400, "=APAGADO",E4:E400,"=Fibra Optica") -> 0 | AD2: =COUNTIFS(AD4:AD400, "=APAGADO",E4:E400,"=Fibra Optica") -> 0 | AE2: =COUNTIFS(AE4:AE400, "=APAGADO",E4:E400,"=Fibra Optica") -> 0 | AF2: =COUNTIFS(AF4:AF400, "=APAGADO",E4:E400,"=Fibra Optica") -> 0 | AG2: =COUNTIFS(AG4:AG400, "=APAGADO",E4:E400,"=Fibra Optica") -> 0 | AH2: =COUNTIFS(AH4:AH400, "=APAGADO",E4:E400,"=Fibra Optica") -> 0 | AI2: =COUNTIFS(AI4:AI400, "=APAGADO",E4:E400,"=Fibra Optica") -> 0
A3: =ESTADISTICA!A1 -> Barrio | B3: =ESTADISTICA!B1 -> [Denominacion] | C3: =ESTADISTICA!C1 -> [Ubicacion] | D3: =ESTADISTICA!D1 -> [Tipo de Camara] | E3: =ESTADISTICA!E1 -> [Tipo de Conexion] | F3: =ESTADISTICA!F1 -> 44805 | G3: =ESTADISTICA!G1 -> 44806 | H3: =ESTADISTICA!H1 -> 44807 | ... AI3: =ESTADISTICA!AI1 -> 44834
A4: =ESTADISTICA!A2 -> ALTAMIRA | B4: =ESTADISTICA!B2 -> ALT 03 | C4: =ESTADISTICA!C2 -> Bombero Galarza y Necochea | D4: =ESTADISTICA!D2 -> Domo | E4: =ESTADISTICA!E2 -> FIBRA OPTICA | F4: =ESTADISTICA!F2 -> 0 | G4: =ESTADISTICA!G2 -> 0 | H4: =ESTADISTICA!H2 -> 0 | ... AI4: =ESTADISTICA!AI2 -> 0
A5: =ESTADISTICA!A3 -> ALTAMIRA | B5: =ESTADISTICA!B3 -> ALT 04 | C5: =ESTADISTICA!C3 -> Francia y Necochea | D5: =ESTADISTICA!D3 -> Domo | E5: =ESTADISTICA!E3 -> FIBRA OPTICA | F5: =ESTADISTICA!F3 -> 0 | G5: =ESTADISTICA!G3 -> 0 | H5: =ESTADISTICA!H3 -> 0 | ... AI5: =ESTADISTICA!AI3 -> 0
A6: =ESTADISTICA!A4 -> ALTAMIRA | B6: =ESTADISTICA!B4 -> ALT 06 | C6: =ESTADISTICA!C4 -> LOPE DE VEGA Y NECOCHEA | D6: =ESTADISTICA!D4 -> Domo | E6: =ESTADISTICA!E4 -> PTO A FO | F6: =ESTADISTICA!F4 -> 0 | G6: =ESTADISTICA!G4 -> 0 | H6: =ESTADISTICA!H4 -> 0 | ... AI6: =ESTADISTICA!AI4 -> 0
A7: =ESTADISTICA!A5 -> ALTAMIRA | B7: =ESTADISTICA!B5 -> ALT 08 | C7: =ESTADISTICA!C5 -> HUMAITA Y NECOCHEA | D7: =ESTADISTICA!D5 -> DOMO | E7: =ESTADISTICA!E5 -> Fibra Optica | F7: =ESTADISTICA!F5 -> 0 | G7: =ESTADISTICA!G5 -> 0 | H7: =ESTADISTICA!H5 -> 0 | ... AI7: =ESTADISTICA!AI5 -> 0
A8: =ESTADISTICA!A6 -> ALTAMIRA | B8: =ESTADISTICA!B6 -> ALT 09 | C8: =ESTADISTICA!C6 -> NECOCHEA Y CURUPAITY | D8: =ESTADISTICA!D6 -> DOMO | E8: =ESTADISTICA!E6 -> Fibra Optica | F8: =ESTADISTICA!F6 -> 0 | G8: =ESTADISTICA!G6 -> 0 | H8: =ESTADISTICA!H6 -> 0 | ... AI8: =ESTADISTICA!AI6 -> 0
A9: =ESTADISTICA!A7 -> ALTAMIRA | B9: =ESTADISTICA!B7 -> ALT 10 | C9: =ESTADISTICA!C7 -> Calchaqui y Francia | D9: =ESTADISTICA!D7 -> Domo | E9: =ESTADISTICA!E7 -> Radio | F9: =ESTADISTICA!F7 -> APAGADO | G9: =ESTADISTICA!G7 -> APAGADO | H9: =ESTADISTICA!H7 -> APAGADO | ... AI9: =ESTADISTICA!AI7 -> 0
A10: =ESTADISTICA!A8 -> ALTAMIRA | B10: =ESTADISTICA!B8 -> ALT01 | C10: =ESTADISTICA!C8 -> Calchaqui y Sgto. Cabral | D10: =ESTADISTICA!D8 -> Domo | E10: =ESTADISTICA!E8 -> Fibra Optica | F10: =ESTADISTICA!F8 -> 0 | G10: =ESTADISTICA!G8 -> 0 | H10: =ESTADISTICA!H8 -> 0 | ... AI10: =ESTADISTICA!AI8 -> 0
A11: =ESTADISTICA!A9 -> ALTAMIRA | B11: =ESTADISTICA!B9 -> ALT02 | C11: =ESTADISTICA!C9 -> Calchaqui y Lope de Vega | D11: =ESTADISTICA!D9 -> Domo | E11: =ESTADISTICA!E9 -> PTO A FO | F11: =ESTADISTICA!F9 -> 0 | G11: =ESTADISTICA!G9 -> 0 | H11: =ESTADISTICA!H9 -> 0 | ... AI11: =ESTADISTICA!AI9 -> 0
A12: =ESTADISTICA!A10 -> ALTAMIRA | B12: =ESTADISTICA!B10 -> ALT05 | C12: =ESTADISTICA!C10 -> Av. Calchaqui y Bombero Galarza | D12: =ESTADISTICA!D10 -> Domo | E12: =ESTADISTICA!E10 -> PTO A FO | F12: =ESTADISTICA!F10 -> APAGADO | G12: =ESTADISTICA!G10 -> APAGADO | H12: =ESTADISTICA!H10 -> APAGADO | ... AI12: =ESTADISTICA!AI10 -> 0
A13: =ESTADISTICA!A11 -> ALTAMIRA | B13: =ESTADISTICA!B11 -> ALT07 | C13: =ESTADISTICA!C11 -> AV. CALCHAQUI Y AV. DEL TRABAJO | D13: =ESTADISTICA!D11 -> DOMO | E13: =ESTADISTICA!E11 -> PTO A FO | F13: =ESTADISTICA!F11 -> 0 | G13: =ESTADISTICA!G11 -> 0 | H13: =ESTADISTICA!H11 -> 0 | ... AI13: =ESTADISTICA!AI11 -> 0
A14: =ESTADISTICA!A12 -> AGUSTIN RAMIREZ | B14: =ESTADISTICA!B12 -> ARA 01 | C14: =ESTADISTICA!C12 -> Malambo y Tranquera | D14: =ESTADISTICA!D12 -> Domo | E14: =ESTADISTICA!E12 -> FIBRA OPTICA | F14: =ESTADISTICA!F12 -> 0 | G14: =ESTADISTICA!G12 -> 0 | H14: =ESTADISTICA!H12 -> 0 | ... AI14: =ESTADISTICA!AI12 -> 0
... A400: =ESTADISTICA!A398 -> 0 | B400: =ESTADISTICA!B398 -> 0 | C400: =ESTADISTICA!C398 -> 0 | D400: =ESTADISTICA!D398 -> 0 | E400: =ESTADISTICA!E398 -> 0 | F400: =ESTADISTICA!F398 -> 0 | G400: =ESTADISTICA!G398 -> 0 | H400: =ESTADISTICA!H398 -> 0 | ... AI400: =ESTADISTICA!AI398 -> 0

Sheet APAGADOS ANTENA
C1: TOTAL PTO A FO
E2: APAGADOS | F2: =COUNTIFS(F4:F400, "=APAGADO",E4:E400,"=PTO A FO") -> 1 | G2: =COUNTIFS(G4:G400, "=APAGADO",E4:E400,"=PTO A FO") -> 2 | H2: =COUNTIFS(H4:H400, "=APAGADO",E4:E400,"=PTO A FO") -> 10 | I2: =COUNTIFS(I4:I400, "=APAGADO",E4:E400,"=PTO A FO") -> 11 | J2: =COUNTIFS(J4:J400, "=APAGADO",E4:E400,"=PTO A FO") -> 3 | K2: =COUNTIFS(K4:K400, "=APAGADO",E4:E400,"=PTO A FO") -> 1 | L2: =COUNTIFS(L4:L400, "=APAGADO",E4:E400,"=PTO A FO") -> 1 | M2: =COUNTIFS(M4:M400, "=APAGADO",E4:E400,"=PTO A FO") -> 0 | N2: =COUNTIFS(N4:N400, "=APAGADO",E4:E400,"=PTO A FO") -> 0 | O2: =COUNTIFS(O4:O500, "=APAGADO",E4:E500,"=PTO A FO") -> 0 | P2: =COUNTIFS(P4:P400, "=APAGADO",E4:E400,"=PTO A FO") -> 0 | Q2: =COUNTIFS(Q4:Q400, "=APAGADO",E4:E400,"=PTO A FO") -> 0 | R2: =COUNTIFS(R4:R400, "=APAGADO",E4:E400,"=PTO A FO") -> 0 | S2: =COUNTIFS(S4:S400, "=APAGADO",E4:E400,"=PTO A FO") -> 0 | T2: =COUNTIFS(T4:T400, "=APAGADO",E4:E400,"=PTO A FO") -> 0 | U2: =COUNTIFS(U4:U400, "=APAGADO",E4:E400,"=PTO A FO") -> 0 | V2: =COUNTIFS(V4:V400, "=APAGADO",E4:E400,"=PTO A FO") -> 0 | W2: =COUNTIFS(W4:W400, "=APAGADO",E4:E400,"=PTO A FO") -> 0 | X2: =COUNTIFS(X4:X400, "=APAGADO",E4:E400,"=PTO A FO") -> 0 | Y2: =COUNTIFS(Y4:Y400, "=APAGADO",E4:E400,"=PTO A FO") -> 0 | Z2: =COUNTIFS(Z4:Z400, "=APAGADO",E4:E400,"=PTO A FO") -> 0 | AA2: =COUNTIFS(AA4:AA400, "=APAGADO",E4:E400,"=PTO A FO") -> 0 | AB2: =COUNTIFS(AB4:AB400, "=APAGADO",E4:E400,"=PTO A FO") -> 0 | AC2: =COUNTIFS(AC4:AC400, "=APAGADO",E4:E400,"=PTO A FO") -> 0 | AD2: =COUNTIFS(AD4:AD400, "=APAGADO",E4:E400,"=PTO A FO") -> 0 | AE2: =COUNTIFS(AE4:AE400, "=APAGADO",E4:E400,"=PTO A FO") -> 0 | AF2: =COUNTIFS(AF4:AF400, "=APAGADO",E4:E400,"=PTO A FO") -> 0 | AG2: =COUNTIFS(AG4:AG400, "=APAGADO",E4:E400,"=PTO A FO") -> 0 | AH2: =COUNTIFS(AH4:AH400, "=APAGADO",E4:E400,"=PTO A FO") -> 0 | AI2: =COUNTIFS(AI4:AI400, "=APAGADO",E4:E400,"=PTO A FO") -> 0
A3: =ESTADISTICA!A1 -> Barrio | B3: =ESTADISTICA!B1 -> [Denominacion] | C3: =ESTADISTICA!C1 -> [Ubicacion] | D3: =ESTADISTICA!D1 -> [Tipo de Camara] | E3: =ESTADISTICA!E1 -> [Tipo de Conexion] | F3: =ESTADISTICA!F1 -> 44805 | G3: =ESTADISTICA!G1 -> 44806 | H3: =ESTADISTICA!H1 -> 44807 | ... AI3: =ESTADISTICA!AI1 -> 44834
A4: =ESTADISTICA!A2 -> ALTAMIRA | B4: =ESTADISTICA!B2 -> ALT 03 | C4: =ESTADISTICA!C2 -> Bombero Galarza y Necochea | D4: =ESTADISTICA!D2 -> Domo | E4: =ESTADISTICA!E2 -> FIBRA OPTICA | F4: =ESTADISTICA!F2 -> 0 | G4: =ESTADISTICA!G2 -> 0 | H4: =ESTADISTICA!H2 -> 0 | ... AI4: =ESTADISTICA!AI2 -> 0
A5: =ESTADISTICA!A3 -> ALTAMIRA | B5: =ESTADISTICA!B3 -> ALT 04 | C5: =ESTADISTICA!C3 -> Francia y Necochea | D5: =ESTADISTICA!D3 -> Domo | E5: =ESTADISTICA!E3 -> FIBRA OPTICA | F5: =ESTADISTICA!F3 -> 0 | G5: =ESTADISTICA!G3 -> 0 | H5: =ESTADISTICA!H3 -> 0 | ... AI5: =ESTADISTICA!AI3 -> 0
A6: =ESTADISTICA!A4 -> ALTAMIRA | B6: =ESTADISTICA!B4 -> ALT 06 | C6: =ESTADISTICA!C4 -> LOPE DE VEGA Y NECOCHEA | D6: =ESTADISTICA!D4 -> Domo | E6: =ESTADISTICA!E4 -> PTO A FO | F6: =ESTADISTICA!F4 -> 0 | G6: =ESTADISTICA!G4 -> 0 | H6: =ESTADISTICA!H4 -> 0 | ... AI6: =ESTADISTICA!AI4 -> 0
A7: =ESTADISTICA!A5 -> ALTAMIRA | B7: =ESTADISTICA!B5 -> ALT 08 | C7: =ESTADISTICA!C5 -> HUMAITA Y NECOCHEA | D7: =ESTADISTICA!D5 -> DOMO | E7: =ESTADISTICA!E5 -> Fibra Optica | F7: =ESTADISTICA!F5 -> 0 | G7: =ESTADISTICA!G5 -> 0 | H7: =ESTADISTICA!H5 -> 0 | ... AI7: =ESTADISTICA!AI5 -> 0
A8: =ESTADISTICA!A6 -> ALTAMIRA | B8: =ESTADISTICA!B6 -> ALT 09 | C8: =ESTADISTICA!C6 -> NECOCHEA Y CURUPAITY | D8: =ESTADISTICA!D6 -> DOMO | E8: =ESTADISTICA!E6 -> Fibra Optica | F8: =ESTADISTICA!F6 -> 0 | G8: =ESTADISTICA!G6 -> 0 | H8: =ESTADISTICA!H6 -> 0 | ... AI8: =ESTADISTICA!AI6 -> 0
A9: =ESTADISTICA!A7 -> ALTAMIRA | B9: =ESTADISTICA!B7 -> ALT 10 | C9: =ESTADISTICA!C7 -> Calchaqui y Francia | D9: =ESTADISTICA!D7 -> Domo | E9: =ESTADISTICA!E7 -> Radio | F9: =ESTADISTICA!F7 -> APAGADO | G9: =ESTADISTICA!G7 -> APAGADO | H9: =ESTADISTICA!H7 -> APAGADO | ... AI9: =ESTADISTICA!AI7 -> 0
A10: =ESTADISTICA!A8 -> ALTAMIRA | B10: =ESTADISTICA!B8 -> ALT01 | C10: =ESTADISTICA!C8 -> Calchaqui y Sgto. Cabral | D10: =ESTADISTICA!D8 -> Domo | E10: =ESTADISTICA!E8 -> Fibra Optica | F10: =ESTADISTICA!F8 -> 0 | G10: =ESTADISTICA!G8 -> 0 | H10: =ESTADISTICA!H8 -> 0 | ... AI10: =ESTADISTICA!AI8 -> 0
A11: =ESTADISTICA!A9 -> ALTAMIRA | B11: =ESTADISTICA!B9 -> ALT02 | C11: =ESTADISTICA!C9 -> Calchaqui y Lope de Vega | D11: =ESTADISTICA!D9 -> Domo | E11: =ESTADISTICA!E9 -> PTO A FO | F11: =ESTADISTICA!F9 -> 0 | G11: =ESTADISTICA!G9 -> 0 | H11: =ESTADISTICA!H9 -> 0 | ... AI11: =ESTADISTICA!AI9 -> 0
A12: =ESTADISTICA!A10 -> ALTAMIRA | B12: =ESTADISTICA!B10 -> ALT05 | C12: =ESTADISTICA!C10 -> Av. Calchaqui y Bombero Galarza | D12: =ESTADISTICA!D10 -> Domo | E12: =ESTADISTICA!E10 -> PTO A FO | F12: =ESTADISTICA!F10 -> APAGADO | G12: =ESTADISTICA!G10 -> APAGADO | H12: =ESTADISTICA!H10 -> APAGADO | ... AI12: =ESTADISTICA!AI10 -> 0
A13: =ESTADISTICA!A11 -> ALTAMIRA | B13: =ESTADISTICA!B11 -> ALT07 | C13: =ESTADISTICA!C11 -> AV. CALCHAQUI Y AV. DEL TRABAJO | D13: =ESTADISTICA!D11 -> DOMO | E13: =ESTADISTICA!E11 -> PTO A FO | F13: =ESTADISTICA!F11 -> 0 | G13: =ESTADISTICA!G11 -> 0 | H13: =ESTADISTICA!H11 -> 0 | ... AI13: =ESTADISTICA!AI11 -> 0
A14: =ESTADISTICA!A12 -> AGUSTIN RAMIREZ | B14: =ESTADISTICA!B12 -> ARA 01 | C14: =ESTADISTICA!C12 -> Malambo y Tranquera | D14: =ESTADISTICA!D12 -> Domo | E14: =ESTADISTICA!E12 -> FIBRA OPTICA | F14: =ESTADISTICA!F12 -> 0 | G14: =ESTADISTICA!G12 -> 0 | H14: =ESTADISTICA!H12 -> 0 | ... AI14: =ESTADISTICA!AI12 -> 0
... A278: =ESTADISTICA!A276 -> SAN JORGE | B278: =ESTADISTICA!B276 -> SJO07 (fija 1) | C278: =ESTADISTICA!C276 -> 503 Y 556 | D278: =ESTADISTICA!D276 -> Fija | E278: =ESTADISTICA!E276 -> Fibra Optica | F278: =ESTADISTICA!F276 -> 0 | G278: =ESTADISTICA!G276 -> 0 | H278: =ESTADISTICA!H276 -> 0 | ... AI278: =ESTADISTICA!AI276 -> 0
B279: =ESTADISTICA!B277 -> SJO08 (fija 2) | C279: =ESTADISTICA!C277 -> 503 Y 556 | D279: =ESTADISTICA!D277 -> Fija | E279: =ESTADISTICA!E277 -> Fibra Optica | F279: =ESTADISTICA!F277 -> 0 | G279: =ESTADISTICA!G277 -> 0 | H279: =ESTADISTICA!H277 -> 0 | I279: =ESTADISTICA!I277 -> 0 | ... AI279: =ESTADISTICA!AI277 -> 0
A280: =ESTADISTICA!A278 -> SANTO TOMAS | B280: =ESTADISTICA!B278 -> SJU01 | C280: =ESTADISTICA!C278 -> Ruta 36 y Pte.Peron | D280: =ESTADISTICA!D278 -> Domo | E280: =ESTADISTICA!E278 -> Radio | F280: =ESTADISTICA!F278 -> 0 | G280: =ESTADISTICA!G278 -> 0 | H280: =ESTADISTICA!H278 -> APAGADO | ... AI280: =ESTADISTICA!AI278 -> 0
A281: =ESTADISTICA!A279 -> VILLA GENERAL SAN MARTIN | B281: =ESTADISTICA!B279 -> SMA 03 | C281: =ESTADISTICA!C279 -> ROSARIO Y SAN NICOLAS | D281: =ESTADISTICA!D279 -> Domo | E281: =ESTADISTICA!E279 -> Radio | F281: =ESTADISTICA!F279 -> 0 | G281: =ESTADISTICA!G279 -> 0 | H281: =ESTADISTICA!H279 -> 0 | ... AI281: =ESTADISTICA!AI279 -> 0
A282: =ESTADISTICA!A280 -> VILLA GENERAL SAN MARTIN | B282: =ESTADISTICA!B280 -> SMA 04 | C282: =ESTADISTICA!C280 -> HUDSON Y MONTEVIDEO | D282: =ESTADISTICA!D280 -> FIJA | E282: =ESTADISTICA!E280 -> Radio | F282: =ESTADISTICA!F280 -> 0 | G282: =ESTADISTICA!G280 -> 0 | H282: =ESTADISTICA!H280 -> 0 | ... AI282: =ESTADISTICA!AI280 -> 0
A283: =ESTADISTICA!A281 -> VILLA GENERAL SAN MARTIN | B283: =ESTADISTICA!B281 -> SMA 06 | C283: =ESTADISTICA!C281 -> AV. HUDSON Y RIO IGUAZU | D283: =ESTADISTICA!D281 -> DOMO | E283: =ESTADISTICA!E281 -> Fibra Optica | F283: =ESTADISTICA!F281 -> 0 | G283: =ESTADISTICA!G281 -> 0 | H283: =ESTADISTICA!H281 -> 0 | ... AI283: =ESTADISTICA!AI281 -> 0
A284: =ESTADISTICA!A282 -> VILLA GENERAL SAN MARTIN | B284: =ESTADISTICA!B282 -> SMA 07 | C284: =ESTADISTICA!C282 -> AV. HUDSON Y RIO TURBIO | D284: =ESTADISTICA!D282 -> DOMO | E284: =ESTADISTICA!E282 -> Fibra Optica | F284: =ESTADISTICA!F282 -> 0 | G284: =ESTADISTICA!G282 -> 0 | H284: =ESTADISTICA!H282 -> 0 | ... AI284: =ESTADISTICA!AI282 -> 0
A285: =ESTADISTICA!A283 -> VILLA GENERAL SAN MARTIN | B285: =ESTADISTICA!B283 -> SMA01 | C285: =ESTADISTICA!C283 -> Hudson y Montevideo | D285: =ESTADISTICA!D283 -> DOMO | E285: =ESTADISTICA!E283 -> Radio | F285: =ESTADISTICA!F283 -> 0 | G285: =ESTADISTICA!G283 -> 0 | H285: =ESTADISTICA!H283 -> 0 | ... AI285: =ESTADISTICA!AI283 -> 0
A286: =ESTADISTICA!A284 -> VILLA GENERAL SAN MARTIN | B286: =ESTADISTICA!B284 -> SMA02 | C286: =ESTADISTICA!C284 -> Hudson y San Nicolas | D286: =ESTADISTICA!D284 -> Domo | E286: =ESTADISTICA!E284 -> Radio | F286: =ESTADISTICA!F284 -> 0 | G286: =ESTADISTICA!G284 -> 0 | H286: =ESTADISTICA!H284 -> 0 | ... AI286: =ESTADISTICA!AI284 -> 0
A287: =ESTADISTICA!A285 -> VILLA GENERAL SAN MARTIN | B287: =ESTADISTICA!B285 -> SMA05 | C287: =ESTADISTICA!C285 -> MONTEVIDEO Y VILLEGAS | D287: =ESTADISTICA!D285 -> DOMO | E287: =ESTADISTICA!E285 -> PTO A FO | F287: =ESTADISTICA!F285 -> 0 | G287: =ESTADISTICA!G285 -> 0 | H287: =ESTADISTICA!H285 -> 0 | ... AI287: =ESTADISTICA!AI285 -> 0
A288: =ESTADISTICA!A286 -> SAN NICOLAS | B288: =ESTADISTICA!B286 -> SNI 03 (fija 1) | C288: =ESTADISTICA!C286 -> SARRATEA Y LOS TREBOLES | D288: =ESTADISTICA!D286 -> Fija | E288: =ESTADISTICA!E286 -> Fibra Optica | F288: =ESTADISTICA!F286 -> APAGADO | G288: =ESTADISTICA!G286 -> APAGADO | H288: =ESTADISTICA!H286 -> APAGADO | ... AI288: =ESTADISTICA!AI286 -> 0
A289: =ESTADISTICA!A287 -> SAN NICOLAS | B289: =ESTADISTICA!B287 -> SNI 04 (fija 2) | C289: =ESTADISTICA!C287 -> SARRATEA Y LOS TREBOLES | D289: =ESTADISTICA!D287 -> Fija | E289: =ESTADISTICA!E287 -> Fibra Optica | F289: =ESTADISTICA!F287 -> APAGADO | G289: =ESTADISTICA!G287 -> APAGADO | H289: =ESTADISTICA!H287 -> APAGADO | ... AI289: =ESTADISTICA!AI287 -> 0
A290: =ESTADISTICA!A288 -> SAN NICOLAS | B290: =ESTADISTICA!B288 -> SNI01 (fija 1) | C290: =ESTADISTICA!C288 -> SARRATEA E/ EEUU DE A. Y AGRELO | D290: =ESTADISTICA!D288 -> Fija | E290: =ESTADISTICA!E288 -> Fibra Optica | F290: =ESTADISTICA!F288 -> APAGADO | G290: =ESTADISTICA!G288 -> APAGADO | H290: =ESTADISTICA!H288 -> APAGADO | ... AI290: =ESTADISTICA!AI288 -> 0
A291: =ESTADISTICA!A289 -> SAN NICOLAS | B291: =ESTADISTICA!B289 -> SNI02 (fija 2) | C291: =ESTADISTICA!C289 -> SARRATEA E/ EEUU DE A. Y AGRELO | D291: =ESTADISTICA!D289 -> Fija | E291: =ESTADISTICA!E289 -> Fibra Optica | F291: =ESTADISTICA!F289 -> APAGADO | G291: =ESTADISTICA!G289 -> APAGADO | H291: =ESTADISTICA!H289 -> APAGADO | ... AI291: =ESTADISTICA!AI289 -> 0
... A454: =ESTADISTICA!A452 -> 0 | B454: =ESTADISTICA!B452 -> 0 | C454: =ESTADISTICA!C452 -> 0 | D454: =ESTADISTICA!D452 -> 0 | E454: =ESTADISTICA!E452 -> 0 | F454: =ESTADISTICA!F452 -> 0 | G454: =ESTADISTICA!G452 -> 0 | H454: =ESTADISTICA!H452 -> 0 | ... AI454: =ESTADISTICA!AI452 -> 0

Sheet APAGADOS RADIO
C1: TOTAL RADIO | D1: =COUNTIFS(E4:E400,"=radio") -> 94
E2: APAGADOS | F2: =COUNTIFS(F4:F500, "=APAGADO",E4:E500,"=radio") -> 5 | G2: =COUNTIFS(G4:G500, "=APAGADO",E4:E500,"=radio") -> 2 | H2: =COUNTIFS(H4:H500, "=APAGADO",E4:E500,"=radio") -> 21 | I2: =COUNTIFS(I4:I500, "=APAGADO",E4:E500,"=radio") -> 23 | J2: =COUNTIFS(J4:J500, "=APAGADO",E4:E500,"=radio") -> 3 | K2: =COUNTIFS(K4:K500, "=APAGADO",E4:E500,"=radio") -> 2 | L2: =COUNTIFS(L4:L500, "=APAGADO",E4:E500,"=radio") -> 3 | M2: =COUNTIFS(M4:M500, "=APAGADO",E4:E500,"=radio") -> 0 | N2: =COUNTIFS(N4:N500, "=APAGADO",E4:E500,"=radio") -> 0 | O2: =COUNTIFS(O4:O500, "=APAGADO",E4:E500,"=radio") -> 0 | P2: =COUNTIFS(P4:P500, "=APAGADO",E4:E500,"=radio") -> 0 | Q2: =COUNTIFS(Q4:Q367, "=APAGADO",E4:E367,"=radio") -> 0 | R2: =COUNTIFS(R4:R367, "=APAGADO",E4:E367,"=radio") -> 0 | S2: =COUNTIFS(S4:S367, "=APAGADO",E4:E367,"=radio") -> 0 | T2: =COUNTIFS(T4:T367, "=APAGADO",E4:E367,"=radio") -> 0 | U2: =COUNTIFS(U4:U367, "=APAGADO",E4:E367,"=radio") -> 0 | V2: =COUNTIFS(V4:V367, "=APAGADO",E4:E367,"=radio") -> 0 | W2: =COUNTIFS(W4:W367, "=APAGADO",E4:E367,"=radio") -> 0 | X2: =COUNTIFS(X4:X367, "=APAGADO",E4:E367,"=radio") -> 0 | Y2: =COUNTIFS(Y4:Y367, "=APAGADO",E4:E367,"=radio") -> 0 | Z2: =COUNTIFS(Z4:Z367, "=APAGADO",E4:E367,"=radio") -> 0 | AA2: =COUNTIFS(AA4:AA367, "=APAGADO",E4:E367,"=radio") -> 0 | AB2: =COUNTIFS(AB4:AB367, "=APAGADO",E4:E367,"=radio") -> 0 | AC2: =COUNTIFS(AC4:AC367, "=APAGADO",E4:E367,"=radio") -> 0 | AD2: =COUNTIFS(AD4:AD367, "=APAGADO",E4:E367,"=radio") -> 0 | AE2: =COUNTIFS(AE4:AE367, "=APAGADO",E4:E367,"=radio") -> 0 | AF2: =COUNTIFS(AF4:AF367, "=APAGADO",E4:E367,"=radio") -> 0 | AG2: =COUNTIFS(AG4:AG367, "=APAGADO",E4:E367,"=radio") -> 0 | AH2: =COUNTIFS(AH4:AH400, "=APAGADO",E4:E400,"=radio") -> 0 | AI2: =COUNTIFS(AI4:AI367, "=APAGADO",E4:E367,"=radio") -> 0
A3: =ESTADISTICA!A1 -> Barrio | B3: =ESTADISTICA!B1 -> [Denominacion] | C3: =ESTADISTICA!C1 -> [Ubicacion] | D3: =ESTADISTICA!D1 -> [Tipo de Camara] | E3: =ESTADISTICA!E1 -> [Tipo de Conexion] | F3: =ESTADISTICA!F1 -> 44805 | G3: =ESTADISTICA!G1 -> 44806 | H3: =ESTADISTICA!H1 -> 44807 | ... AI3: =ESTADISTICA!AI1 -> 44834
A4: =ESTADISTICA!A2 -> ALTAMIRA | B4: =ESTADISTICA!B2 -> ALT 03 | C4: =ESTADISTICA!C2 -> Bombero Galarza y Necochea | D4: =ESTADISTICA!D2 -> Domo | E4: =ESTADISTICA!E2 -> FIBRA OPTICA | F4: =ESTADISTICA!F2 -> 0 | G4: =ESTADISTICA!G2 -> 0 | H4: =ESTADISTICA!H2 -> 0 | ... AI4: =ESTADISTICA!AI2 -> 0
A5: =ESTADISTICA!A3 -> ALTAMIRA | B5: =ESTADISTICA!B3 -> ALT 04 | C5: =ESTADISTICA!C3 -> Francia y Necochea | D5: =ESTADISTICA!D3 -> Domo | E5: =ESTADISTICA!E3 -> FIBRA OPTICA | F5: =ESTADISTICA!F3 -> 0 | G5: =ESTADISTICA!G3 -> 0 | H5: =ESTADISTICA!H3 -> 0 | ... AI5: =ESTADISTICA!AI3 -> 0
A6: =ESTADISTICA!A4 -> ALTAMIRA | B6: =ESTADISTICA!B4 -> ALT 06 | C6: =ESTADISTICA!C4 -> LOPE DE VEGA Y NECOCHEA | D6: =ESTADISTICA!D4 -> Domo | E6: =ESTADISTICA!E4 -> PTO A FO | F6: =ESTADISTICA!F4 -> 0 | G6: =ESTADISTICA!G4 -> 0 | H6: =ESTADISTICA!H4 -> 0 | ... AI6: =ESTADISTICA!AI4 -> 0
A7: =ESTADISTICA!A5 -> ALTAMIRA | B7: =ESTADISTICA!B5 -> ALT 08 | C7: =ESTADISTICA!C5 -> HUMAITA Y NECOCHEA | D7: =ESTADISTICA!D5 -> DOMO | E7: =ESTADISTICA!E5 -> Fibra Optica | F7: =ESTADISTICA!F5 -> 0 | G7: =ESTADISTICA!G5 -> 0 | H7: =ESTADISTICA!H5 -> 0 | ... AI7: =ESTADISTICA!AI5 -> 0
A8: =ESTADISTICA!A6 -> ALTAMIRA | B8: =ESTADISTICA!B6 -> ALT 09 | C8: =ESTADISTICA!C6 -> NECOCHEA Y CURUPAITY | D8: =ESTADISTICA!D6 -> DOMO | E8: =ESTADISTICA!E6 -> Fibra Optica | F8: =ESTADISTICA!F6 -> 0 | G8: =ESTADISTICA!G6 -> 0 | H8: =ESTADISTICA!H6 -> 0 | ... AI8: =ESTADISTICA!AI6 -> 0
A9: =ESTADISTICA!A7 -> ALTAMIRA | B9: =ESTADISTICA!B7 -> ALT 10 | C9: =ESTADISTICA!C7 -> Calchaqui y Francia | D9: =ESTADISTICA!D7 -> Domo | E9: =ESTADISTICA!E7 -> Radio | F9: =ESTADISTICA!F7 -> APAGADO | G9: =ESTADISTICA!G7 -> APAGADO | H9: =ESTADISTICA!H7 -> APAGADO | ... AI9: =ESTADISTICA!AI7 -> 0
A10: =ESTADISTICA!A8 -> ALTAMIRA | B10: =ESTADISTICA!B8 -> ALT01 | C10: =ESTADISTICA!C8 -> Calchaqui y Sgto. Cabral | D10: =ESTADISTICA!D8 -> Domo | E10: =ESTADISTICA!E8 -> Fibra Optica | F10: =ESTADISTICA!F8 -> 0 | G10: =ESTADISTICA!G8 -> 0 | H10: =ESTADISTICA!H8 -> 0 | ... AI10: =ESTADISTICA!AI8 -> 0
A11: =ESTADISTICA!A9 -> ALTAMIRA | B11: =ESTADISTICA!B9 -> ALT02 | C11: =ESTADISTICA!C9 -> Calchaqui y Lope de Vega | D11: =ESTADISTICA!D9 -> Domo | E11: =ESTADISTICA!E9 -> PTO A FO | F11: =ESTADISTICA!F9 -> 0 | G11: =ESTADISTICA!G9 -> 0 | H11: =ESTADISTICA!H9 -> 0 | ... AI11: =ESTADISTICA!AI9 -> 0
A12: =ESTADISTICA!A10 -> ALTAMIRA | B12: =ESTADISTICA!B10 -> ALT05 | C12: =ESTADISTICA!C10 -> Av. Calchaqui y Bombero Galarza | D12: =ESTADISTICA!D10 -> Domo | E12: =ESTADISTICA!E10 -> PTO A FO | F12: =ESTADISTICA!F10 -> APAGADO | G12: =ESTADISTICA!G10 -> APAGADO | H12: =ESTADISTICA!H10 -> APAGADO | ... AI12: =ESTADISTICA!AI10 -> 0
A13: =ESTADISTICA!A11 -> ALTAMIRA | B13: =ESTADISTICA!B11 -> ALT07 | C13: =ESTADISTICA!C11 -> AV. CALCHAQUI Y AV. DEL TRABAJO | D13: =ESTADISTICA!D11 -> DOMO | E13: =ESTADISTICA!E11 -> PTO A FO | F13: =ESTADISTICA!F11 -> 0 | G13: =ESTADISTICA!G11 -> 0 | H13: =ESTADISTICA!H11 -> 0 | ... AI13: =ESTADISTICA!AI11 -> 0
A14: =ESTADISTICA!A12 -> AGUSTIN RAMIREZ | B14: =ESTADISTICA!B12 -> ARA 01 | C14: =ESTADISTICA!C12 -> Malambo y Tranquera | D14: =ESTADISTICA!D12 -> Domo | E14: =ESTADISTICA!E12 -> FIBRA OPTICA | F14: =ESTADISTICA!F12 -> 0 | G14: =ESTADISTICA!G12 -> 0 | H14: =ESTADISTICA!H12 -> 0 | ... AI14: =ESTADISTICA!AI12 -> 0
... A278: =ESTADISTICA!A276 -> SAN JORGE | B278: =ESTADISTICA!B276 -> SJO07 (fija 1) | C278: =ESTADISTICA!C276 -> 503 Y 556 | D278: =ESTADISTICA!D276 -> Fija | E278: =ESTADISTICA!E276 -> Fibra Optica | F278: =ESTADISTICA!F276 -> 0 | G278: =ESTADISTICA!G276 -> 0 | H278: =ESTADISTICA!H276 -> 0 | ... AI278: =ESTADISTICA!AI276 -> 0
B279: =ESTADISTICA!B277 -> SJO08 (fija 2) | C279: =ESTADISTICA!C277 -> 503 Y 556 | D279: =ESTADISTICA!D277 -> Fija | E279: =ESTADISTICA!E277 -> Fibra Optica | F279: =ESTADISTICA!F277 -> 0 | G279: =ESTADISTICA!G277 -> 0 | H279: =ESTADISTICA!H277 -> 0 | I279: =ESTADISTICA!I277 -> 0 | ... AI279: =ESTADISTICA!AI277 -> 0
A280: =ESTADISTICA!A278 -> SANTO TOMAS | B280: =ESTADISTICA!B278 -> SJU01 | C280: =ESTADISTICA!C278 -> Ruta 36 y Pte.Peron | D280: =ESTADISTICA!D278 -> Domo | E280: =ESTADISTICA!E278 -> Radio | F280: =ESTADISTICA!F278 -> 0 | G280: =ESTADISTICA!G278 -> 0 | H280: =ESTADISTICA!H278 -> APAGADO | ... AI280: =ESTADISTICA!AI278 -> 0
A281: =ESTADISTICA!A279 -> VILLA GENERAL SAN MARTIN | B281: =ESTADISTICA!B279 -> SMA 03 | C281: =ESTADISTICA!C279 -> ROSARIO Y SAN NICOLAS | D281: =ESTADISTICA!D279 -> Domo | E281: =ESTADISTICA!E279 -> Radio | F281: =ESTADISTICA!F279 -> 0 | G281: =ESTADISTICA!G279 -> 0 | H281: =ESTADISTICA!H279 -> 0 | ... AI281: =ESTADISTICA!AI279 -> 0
A282: =ESTADISTICA!A280 -> VILLA GENERAL SAN MARTIN | B282: =ESTADISTICA!B280 -> SMA 04 | C282: =ESTADISTICA!C280 -> HUDSON Y MONTEVIDEO | D282: =ESTADISTICA!D280 -> FIJA | E282: =ESTADISTICA!E280 -> Radio | F282: =ESTADISTICA!F280 -> 0 | G282: =ESTADISTICA!G280 -> 0 | H282: =ESTADISTICA!H280 -> 0 | ... AI282: =ESTADISTICA!AI280 -> 0
A283: =ESTADISTICA!A281 -> VILLA GENERAL SAN MARTIN | B283: =ESTADISTICA!B281 -> SMA 06 | C283: =ESTADISTICA!C281 -> AV. HUDSON Y RIO IGUAZU | D283: =ESTADISTICA!D281 -> DOMO | E283: =ESTADISTICA!E281 -> Fibra Optica | F283: =ESTADISTICA!F281 -> 0 | G283: =ESTADISTICA!G281 -> 0 | H283: =ESTADISTICA!H281 -> 0 | ... AI283: =ESTADISTICA!AI281 -> 0
A284: =ESTADISTICA!A282 -> VILLA GENERAL SAN MARTIN | B284: =ESTADISTICA!B282 -> SMA 07 | C284: =ESTADISTICA!C282 -> AV. HUDSON Y RIO TURBIO | D284: =ESTADISTICA!D282 -> DOMO | E284: =ESTADISTICA!E282 -> Fibra Optica | F284: =ESTADISTICA!F282 -> 0 | G284: =ESTADISTICA!G282 -> 0 | H284: =ESTADISTICA!H282 -> 0 | ... AI284: =ESTADISTICA!AI282 -> 0
A285: =ESTADISTICA!A283 -> VILLA GENERAL SAN MARTIN | B285: =ESTADISTICA!B283 -> SMA01 | C285: =ESTADISTICA!C283 -> Hudson y Montevideo | D285: =ESTADISTICA!D283 -> DOMO | E285: =ESTADISTICA!E283 -> Radio | F285: =ESTADISTICA!F283 -> 0 | G285: =ESTADISTICA!G283 -> 0 | H285: =ESTADISTICA!H283 -> 0 | ... AI285: =ESTADISTICA!AI283 -> 0
A286: =ESTADISTICA!A284 -> VILLA GENERAL SAN MARTIN | B286: =ESTADISTICA!B284 -> SMA02 | C286: =ESTADISTICA!C284 -> Hudson y San Nicolas | D286: =ESTADISTICA!D284 -> Domo | E286: =ESTADISTICA!E284 -> Radio | F286: =ESTADISTICA!F284 -> 0 | G286: =ESTADISTICA!G284 -> 0 | H286: =ESTADISTICA!H284 -> 0 | ... AI286: =ESTADISTICA!AI284 -> 0
A287: =ESTADISTICA!A285 -> VILLA GENERAL SAN MARTIN | B287: =ESTADISTICA!B285 -> SMA05 | C287: =ESTADISTICA!C285 -> MONTEVIDEO Y VILLEGAS | D287: =ESTADISTICA!D285 -> DOMO | E287: =ESTADISTICA!E285 -> PTO A FO | F287: =ESTADISTICA!F285 -> 0 | G287: =ESTADISTICA!G285 -> 0 | H287: =ESTADISTICA!H285 -> 0 | ... AI287: =ESTADISTICA!AI285 -> 0
A288: =ESTADISTICA!A286 -> SAN NICOLAS | B288: =ESTADISTICA!B286 -> SNI 03 (fija 1) | C288: =ESTADISTICA!C286 -> SARRATEA Y LOS TREBOLES | D288: =ESTADISTICA!D286 -> Fija | E288: =ESTADISTICA!E286 -> Fibra Optica | F288: =ESTADISTICA!F286 -> APAGADO | G288: =ESTADISTICA!G286 -> APAGADO | H288: =ESTADISTICA!H286 -> APAGADO | ... AI288: =ESTADISTICA!AI286 -> 0
A289: =ESTADISTICA!A287 -> SAN NICOLAS | B289: =ESTADISTICA!B287 -> SNI 04 (fija 2) | C289: =ESTADISTICA!C287 -> SARRATEA Y LOS TREBOLES | D289: =ESTADISTICA!D287 -> Fija | E289: =ESTADISTICA!E287 -> Fibra Optica | F289: =ESTADISTICA!F287 -> APAGADO | G289: =ESTADISTICA!G287 -> APAGADO | H289: =ESTADISTICA!H287 -> APAGADO | ... AI289: =ESTADISTICA!AI287 -> 0
A290: =ESTADISTICA!A288 -> SAN NICOLAS | B290: =ESTADISTICA!B288 -> SNI01 (fija 1) | C290: =ESTADISTICA!C288 -> SARRATEA E/ EEUU DE A. Y AGRELO | D290: =ESTADISTICA!D288 -> Fija | E290: =ESTADISTICA!E288 -> Fibra Optica | F290: =ESTADISTICA!F288 -> APAGADO | G290: =ESTADISTICA!G288 -> APAGADO | H290: =ESTADISTICA!H288 -> APAGADO | ... AI290: =ESTADISTICA!AI288 -> 0
A291: =ESTADISTICA!A289 -> SAN NICOLAS | B291: =ESTADISTICA!B289 -> SNI02 (fija 2) | C291: =ESTADISTICA!C289 -> SARRATEA E/ EEUU DE A. Y AGRELO | D291: =ESTADISTICA!D289 -> Fija | E291: =ESTADISTICA!E289 -> Fibra Optica | F291: =ESTADISTICA!F289 -> APAGADO | G291: =ESTADISTICA!G289 -> APAGADO | H291: =ESTADISTICA!H289 -> APAGADO | ... AI291: =ESTADISTICA!AI289 -> 0
... A400: =ESTADISTICA!A398 -> 0 | B400: =ESTADISTICA!B398 -> 0 | C400: =ESTADISTICA!C398 -> 0 | D400: =ESTADISTICA!D398 -> 0 | E400: =ESTADISTICA!E398 -> 0 | F400: =ESTADISTICA!F398 -> 0 | G400: =ESTADISTICA!G398 -> 0 | H400: =ESTADISTICA!H398 -> 0 | ... AI400: =ESTADISTICA!AI398 -> 0

Sheet BARRAS

Sheet GRAFICO2

Sheet informe
B1: CANTIDAD | D1: %
A2: TOTAL | B2: 395 | E2: 44805
A3: CAIDAS | B3: 28 | C3: 28 | D3: =C3/B2 -> 0.070886076
A4: LLEGAMOS NOSOTROS | B4: 1 | C4: =B3-B4 -> 27 | D4: =C4/B2 -> 0.06835443
A5: NO ESTA LA CAMARA | B5: 2 | C5: =C4-B5 -> 25 | D5: =C5/B2 -> 0.063291139
A6: RADIO | B6: 5 | C6: =C5-B6 -> 20 | D6: =C6/B2 -> 0.050632911
A7: TOTAL | B7: 395 | E7: 44809
A8: CAIDAS | B8: 38 | C8: 38 | D8: =C8/B7 -> 0.096202532
A9: LLEGAMOS NOSOTROS | B9: 4 | C9: =B8-B9 -> 34 | D9: =C9/B7 -> 0.086075949
A10: NO ESTA LA CAMARA | B10: 2 | C10: =C9-B10 -> 32 | D10: =C10/B7 -> 0.081012658
A11: RADIO | B11: 3 | C11: =C10-B11 -> 29 | D11: =C11/B7 -> 0.073417722
A12: TOTAL | B12: 395 | E12: 44810
A13: CAIDAS | B13: 21 | C13: 21 | D13: =C13/B12 -> 0.053164557
A14: LLEGAMOS NOSOTROS | B14: 2 | C14: =B13-B14 -> 19 | D14: =C14/B12 -> 0.048101266
