Workbook
Name _25_de_agosto: 'RESUMEN TOTAL'!$A$4:$C$347

Sheet RESUMEN TOTAL
A1: CANTIDAD DE CAMARAS | B1: =COUNTA(B5:B525) -> 364 | C1: PORCIENTO DE CAIDAS | J1: DIAS FUNCIONANDO | K1: DIAS CAIDA | L1: EFECTIVIDAD | M1: =(M3)/(M2+M3) -> 0.24450549 | N1: =(N3)/(N2+N3) -> 0.24242424 | O1: =(O3)/(O2+O3) -> 0.21428571 | P1: =(P3)/(P2+P3) -> 0.21428571 | Q1: =(Q3)/(Q2+Q3) -> 0.21428571 | R1: =(R3)/(R2+R3) -> 0.21428571 | S1: =(S3)/(S2+S3) -> 0.23351648 | T1: =(T3)/(T2+T3) -> 0.21978022 | ... AN1: =(AN3)/(AN2+AN3) -> 0
C2: FUNCIONAN | M2: =COUNTIF(M5:M368, "") -> 275 | N2: =COUNTIF(N5:N368, "") -> 275 | O2: =COUNTIF(O5:O368, "") -> 286 | P2: =COUNTIF(P5:P368, "") -> 286 | Q2: =COUNTIF(Q5:Q368, "") -> 286 | R2: =COUNTIF(R5:R368, "") -> 286 | S2: =COUNTIF(S5:S368, "") -> 279 | T2: =COUNTIF(T5:T368, "") -> 284 | ... AN2: =COUNTIF(AN5:AN368, "") -> 364
C3: CAIDAS | M3: =COUNTIF(M4:M445, "apagado") -> 89 | N3: =COUNTIF(N4:N445, "apagado") -> 88 | O3: =COUNTIF(O4:O445, "apagado") -> 78 | P3: =COUNTIF(P4:P445, "apagado") -> 78 | Q3: =COUNTIF(Q4:Q445, "apagado") -> 78 | R3: =COUNTIF(R4:R445, "apagado") -> 78 | S3: =COUNTIF(S4:S445, "apagado") -> 85 | T3: =COUNTIF(T4:T445, "apagado") -> 80 | ... AN3: =COUNTIF(AN4:AN445, "apagado") -> 0
A4: Barrio | B4: [Denominacion] | C4: [Ubicacion] | D4: [Tipo de Camara] | E4: [Tipo de Conexion] | F4: [Fundamento] | G4: [Detalle] | H4: Latitud | I4: Longitud | M4: 44593 | N4: 44594 | O4: 44595 | P4: 44596 | Q4: 44597 | R4: 44598 | S4: 44599 | T4: 44600 | U4: 44601 | V4: 44602 | W4: 44603 | X4: 44604 | Y4: 44605 | Z4: 44606 | AA4: 44607 | AB4: 44608 | AC4: 44609 | AD4: 44610 | AE4: 44611 | AF4: 44612 | AG4: 44613 | AH4: 44614 | AI4: 44615 | AJ4: 44616 | AK4: 44617 | AL4: 44618 | AM4: 44619 | AN4: 44620
A5: PRESIDENTE PERON (PEPSI) | B5: MAR 01 | C5: RP36 Y LA ESMERALDA | D5: DOMO | E5: RADIO | F5: POSIBLE VIA DE ESCAPE. FLUJO VEHICULAR | H5: -348296270000 | I5: -582165860000 | J5: =COUNTIF(M5:AN5,"") -> 23 | K5: =COUNTIF(M5:AN5,"APAGADO") -> 5 | L5: =(J5)/(K5+J5) -> 0.82142857 | M5: APAGADO | O5: APAGADO | P5: APAGADO | Q5: APAGADO | R5: APAGADO
A6: MAYOL | B6: MAY 01 | C6: Eva Peron y Cabildo | D6: Domo | E6: Radio | F6: Flujo Vehicular, Futuro corredor escolar, Zona Comercial | H6: -348239900000 | I6: -582772350000 | J6: =COUNTIF(M6:AN6,"") -> 28 | K6: =COUNTIF(M6:AN6,"APAGADO") -> 0 | L6: =(J6)/(K6+J6) -> 1
B7: MAY 02 | C7: EVA PERON Y MONTEVIDEO | D7: Domo | E7: Radio | H7: -348218190000 | I7: -582771380000 | J7: =COUNTIF(M7:AN7,"") -> 18 | K7: =COUNTIF(M7:AN7,"APAGADO") -> 10 | L7: =(J7)/(K7+J7) -> 0.64285714 | M7: APAGADO | N7: APAGADO | O7: APAGADO | P7: APAGADO | Q7: APAGADO | R7: APAGADO | S7: APAGADO | T7: APAGADO | U7: APAGADO | V7: APAGADO
A8: MAYOL | B8: MAY 03 | C8: CHAÑAR Y SAN NICOLAS | D8: DOMO | E8: Radio | G8: ALTA 29/10/2019 | H8: -348230700000 | I8: -582702540000 | J8: =COUNTIF(M8:AN8,"") -> 25 | K8: =COUNTIF(M8:AN8,"APAGADO") -> 3 | L8: =(J8)/(K8+J8) -> 0.89285714 | P8: APAGADO | Q8: APAGADO | R8: APAGADO
B9: MAY 04 | C9: MAR CHIQUITA Y RIO JACHAL | D9: DOMO | E9: Radio | G9: 08/07/2020 COMIENZA A REPORTAR IMAGEN | H9: -348252070000 | I9: -582711820000 | J9: =COUNTIF(M9:AN9,"") -> 28 | K9: =COUNTIF(M9:AN9,"APAGADO") -> 0 | L9: =(J9)/(K9+J9) -> 1
A10: ALTAMIRA | B10: ALT 06 | C10: LOPE DE VEGA Y NECOCHEA | D10: Domo | E10: Fibra Optica | G10: Instalada sin alta en sistema. ALTA en sistema y en funcionamiento 04/05/2020 | H10: -347738090000 | I10: -582721410000 | J10: =COUNTIF(M10:AN10,"") -> 20 | K10: =COUNTIF(M10:AN10,"APAGADO") -> 8 | L10: =(J10)/(K10+J10) -> 0.71428571 | M10: APAGADO | N10: APAGADO | O10: APAGADO | P10: APAGADO | Q10: APAGADO | R10: APAGADO | S10: APAGADO | T10: APAGADO
A11: ALTAMIRA | B11: ALT01 | C11: Calchaqui y Sgto. Cabral | D11: Domo | E11: Fibra Optica | F11: Universidad, Zona Bancaria, Flujo Vehicular, Posible Via de Escape | H11: -347769580000 | I11: -582650900000 | J11: =COUNTIF(M11:AN11,"") -> 28 | K11: =COUNTIF(M11:AN11,"APAGADO") -> 0 | L11: =(J11)/(K11+J11) -> 1
A12: ALTAMIRA | B12: ALT02 | C12: Calchaqui y Lope de Vega | D12: Domo | E12: Radio | F12: Hospital, Flujo Vehicular, Peatonal | H12: -347718470000 | I12: -582688560000 | J12: =COUNTIF(M12:AN12,"") -> 28 | K12: =COUNTIF(M12:AN12,"APAGADO") -> 0 | L12: =(J12)/(K12+J12) -> 1
A13: ALTAMIRA | B13: ALT03 | C13: Bombero Galarza y Necochea | D13: Domo | E13: Radio | F13: Hospital, Limite del Partido | H13: -347726570000 | I13: -582730620000 | J13: =COUNTIF(M13:AN13,"") -> 21 | K13: =COUNTIF(M13:AN13,"APAGADO") -> 7 | L13: =(J13)/(K13+J13) -> 0.75 | M13: APAGADO | N13: APAGADO | O13: APAGADO | P13: APAGADO | Q13: APAGADO | R13: APAGADO | S13: APAGADO
B14: ALT04 | C14: Francia y Necochea | D14: Domo | E14: Radio | F14: Zona RecreaciÃ³n | H14: -347705420000 | I14: -582748000000 | J14: =COUNTIF(M14:AN14,"") -> 21 | K14: =COUNTIF(M14:AN14,"APAGADO") -> 7 | L14: =(J14)/(K14+J14) -> 0.75 | M14: APAGADO | N14: APAGADO | O14: APAGADO | P14: APAGADO | Q14: APAGADO | R14: APAGADO | S14: APAGADO
A15: ALTAMIRA | B15: ALT05 | C15: Av. Calchaqui y Bombero Galarza | D15: Domo | E15: Radio | F15: Zona Bancaria, Flujo Vehicular, Posible via de escape, Limite del partido | H15: -347708370000 | I15: -582698000000 | J15: =COUNTIF(M15:AN15,"") -> 28 | K15: =COUNTIF(M15:AN15,"APAGADO") -> 0 | L15: =(J15)/(K15+J15) -> 1
A16: ALTAMIRA | B16: ALT07 | C16: AV. CALCHAQUI Y AV. DEL TRABAJO | D16: DOMO | E16: Radio | G16: SE DA DE ALTA EL 17/09/2020 18:51HS | H16: -347737570000 | I16: -582676650000 | J16: =COUNTIF(M16:AN16,"") -> 28 | K16: =COUNTIF(M16:AN16,"APAGADO") -> 0 | L16: =(J16)/(K16+J16) -> 1
A17: ALTAMIRA | B17: ALT08 | C17: HUMAITA Y NECOCHEA | D17: DOMO | E17: Fibra Optica | G17: REPORTA IMAGENES 20/08/2021 | H17: -347749440000 | I17: -582711610000 | J17: =COUNTIF(M17:AN17,"") -> 21 | K17: =COUNTIF(M17:AN17,"APAGADO") -> 7 | L17: =(J17)/(K17+J17) -> 0.75 | M17: APAGADO | N17: APAGADO | O17: APAGADO | P17: APAGADO | Q17: APAGADO | R17: APAGADO | S17: APAGADO
A18: ALTAMIRA | B18: ALT09 | C18: NECOCHEA Y CURUPAITY | D18: DOMO | E18: Fibra Optica | G18: SE DA DE ALTA 25/08/2021 | H18: -347743740000 | I18: -582715650000 | J18: =COUNTIF(M18:AN18,"") -> 21 | K18: =COUNTIF(M18:AN18,"APAGADO") -> 7 | L18: =(J18)/(K18+J18) -> 0.75 | M18: APAGADO | N18: APAGADO | O18: APAGADO | P18: APAGADO | Q18: APAGADO | R18: APAGADO | S18: APAGADO
A19: AGUSTIN RAMIREZ | B19: ARA01 | C19: Malambo y Tranquera | D19: Domo | E19: Radio | F19: Zona Escolar, Flujo Vehicular | H19: -347979380000 | I19: -583160950000 | J19: =COUNTIF(M19:AN19,"") -> 26 | K19: =COUNTIF(M19:AN19,"APAGADO") -> 2 | L19: =(J19)/(K19+J19) -> 0.92857143 | U19: APAGADO | V19: APAGADO
A20: ALTAMIRA | B20: ATL10 | C20: REP. FRANCIA Y CALCHAQUI (RP 36) | D20: DOMO | E20: RADIO | G20: SE DA DE ALTA 10/11/2021 | H20: -347689160000 | I20: -582717100000 | J20: =COUNTIF(M20:AN20,"") -> 28 | K20: =COUNTIF(M20:AN20,"APAGADO") -> 0 | L20: =(J20)/(K20+J20) -> 1
A21: BELGRANO | B21: BEL01 | C21: San Martin y Dardo Rocha | D21: DOMO | E21: Radio | F21: Zona Escolar, Flujo Vehicular | G21: 19/03/2020 SE RETIRO DISPOSITIVO POR RIESGO DE CAIDA. 19/08/2020 comenzo a funcionar. | H21: -347918370000 | I21: -582786080000 | J21: =COUNTIF(M21:AN21,"") -> 28 | K21: =COUNTIF(M21:AN21,"APAGADO") -> 0 | L21: =(J21)/(K21+J21) -> 1
B22: CEN 51 | C22: ILLIA Y LAS HERAS | D22: FIJA | E22: Fibra Optica | F22: POSIBLE VIA DE ESCAPE, Y FLUJO VEHICULAR | H22: -347987830000 | I22: -582840920000 | J22: =COUNTIF(M22:AN22,"") -> 28 | K22: =COUNTIF(M22:AN22,"APAGADO") -> 0 | L22: =(J22)/(K22+J22) -> 1
B23: CEN 53 | C23: GUTIERREZ Y BROWN | D23: Domo | E23: Radio | H23: -348013650000 | I23: -582715700000 | J23: =COUNTIF(M23:AN23,"") -> 28 | K23: =COUNTIF(M23:AN23,"APAGADO") -> 0 | L23: =(J23)/(K23+J23) -> 1
B24: CEN 54 | C24: GUTIERREZ Y PRINGLES | D24: Domo | E24: Radio | H24: -348013470000 | I24: -582698540000 | J24: =COUNTIF(M24:AN24,"") -> 24 | K24: =COUNTIF(M24:AN24,"APAGADO") -> 4 | L24: =(J24)/(K24+J24) -> 0.85714286 | M24: APAGADO | N24: APAGADO | O24: APAGADO | V24: APAGADO
B25: CEN 55 | C25: BOUREL Y URQUIZA | D25: Domo | E25: Radio | H25: -348019110000 | I25: -582819990000 | J25: =COUNTIF(M25:AN25,"") -> 28 | K25: =COUNTIF(M25:AN25,"APAGADO") -> 0 | L25: =(J25)/(K25+J25) -> 1
A26: CENTRO | B26: CEN 56 | C26: Newbery y Falucho | D26: DOMO | E26: Radio | F26: Posible via de escape, Cruce Peligroso | H26: -348073990000 | I26: -582850080000 | J26: =COUNTIF(M26:AN26,"") -> 28 | K26: =COUNTIF(M26:AN26,"APAGADO") -> 0 | L26: =(J26)/(K26+J26) -> 1
B27: CEN 57 | C27: 25 DE MAYO Y DORREGO | D27: DOMO | E27: Radio | H27: -348007360000 | I27: -582804240000 | J27: =COUNTIF(M27:AN27,"") -> 28 | K27: =COUNTIF(M27:AN27,"APAGADO") -> 0 | L27: =(J27)/(K27+J27) -> 1
B28: CEN 58 | C28: EEUU Y MORENO | D28: DOMO | E28: Radio | G28: INSTALADA: 11/06/18. EN FUNCIONAMIENTO: 27/06/18. | H28: -348103030000 | I28: -582835720000 | J28: =COUNTIF(M28:AN28,"") -> 28 | K28: =COUNTIF(M28:AN28,"APAGADO") -> 0 | L28: =(J28)/(K28+J28) -> 1
B29: CEN 59 | C29: CHACABUCO Y BOUREL | D29: DOMO | E29: Radio | G29: INSTALADA:11/06/18EN FUNCIONAMIENTO: 27/06/18 | H29: -348039300000 | I29: -582819780000 | J29: =COUNTIF(M29:AN29,"") -> 28 | K29: =COUNTIF(M29:AN29,"APAGADO") -> 0 | L29: =(J29)/(K29+J29) -> 1
A30: CENTRO | B30: CEN 60 | C30: RECONQUISTA Y ILLIA | D30: DOMO | E30: Radio | G30: ALTA 26/10/2019 | H30: -347999170000 | I30: -582863530000 | J30: =COUNTIF(M30:AN30,"") -> 28 | K30: =COUNTIF(M30:AN30,"APAGADO") -> 0 | L30: =(J30)/(K30+J30) -> 1
A31: CENTRO | B31: CEN 61 | C31: BOUREL Y MAIPU | D31: DOMO | E31: Radio | G31: ALTA EN FUNCIONAMIENTO 12/04/2019 | H31: -348040550000 | I31: -582819380000 | J31: =COUNTIF(M31:AN31,"") -> 26 | K31: =COUNTIF(M31:AN31,"APAGADO") -> 2 | L31: =(J31)/(K31+J31) -> 0.92857143 | M31: APAGADO | N31: APAGADO
A32: CENTRO | B32: CEN 62 | C32: ESPAÑA Y ALEM | D32: DOMO | E32: Radio | G32: ALTA: 16/06/2020 | H32: -348038200000 | I32: -582766160000 | J32: =COUNTIF(M32:AN32,"") -> 28 | K32: =COUNTIF(M32:AN32,"APAGADO") -> 0 | L32: =(J32)/(K32+J32) -> 1
A33: CENTRO | B33: CEN 63 | C33: SAN MARTIN Y URQUIZA | D33: DOMO | E33: Fibra Optica | G33: DADA DE ALTA ABRIL 2021 | H33: -348017700000 | I33: -582785020000 | J33: =COUNTIF(M33:AN33,"") -> 28 | K33: =COUNTIF(M33:AN33,"APAGADO") -> 0 | L33: =(J33)/(K33+J33) -> 1
A34: CENTRO | B34: CEN 70 | C34: RIVADAVIA Y 25 MAYO | D34: Domo | E34: Fibra Optica | G34: alta en sistema 25/11/2021 | H34: -348091950000 | I34: -582800930000 | J34: =COUNTIF(M34:AN34,"") -> 28 | K34: =COUNTIF(M34:AN34,"APAGADO") -> 0 | L34: =(J34)/(K34+J34) -> 1
A35: CENTRO | B35: CEN 71 | C35: MORENO Y BOUREL | D35: Domo | E35: Fibra Optica | G35: alta en sistema 25/11/2021 | H35: -348103130000 | I35: -582818230000 | J35: =COUNTIF(M35:AN35,"") -> 28 | K35: =COUNTIF(M35:AN35,"APAGADO") -> 0 | L35: =(J35)/(K35+J35) -> 1
A36: CENTRO | B36: CEN 72 | C36: MORENO Y 25 DE MAYO | D36: Domo | E36: Fibra Optica | G36: ALTA EN SISTEMA 25/11/2021 | H36: -348102250000 | I36: -582800780000 | J36: =COUNTIF(M36:AN36,"") -> 28 | K36: =COUNTIF(M36:AN36,"APAGADO") -> 0 | L36: =(J36)/(K36+J36) -> 1
A37: CENTRO | B37: CEN01 | C37: San Martin y 9 de Julio | D37: Fija | E37: Fibra Optica | F37: Zona Comercial, Flujo Vehicular | H37: -348028100000 | I37: -582782860000 | J37: =COUNTIF(M37:AN37,"") -> 28 | K37: =COUNTIF(M37:AN37,"APAGADO") -> 0 | L37: =(J37)/(K37+J37) -> 1
A38: CENTRO | B38: CEN02 | C38: San Martin y Almafuerte | D38: Fija | E38: Fibra Optica | F38: Bomberos, Flujo Vehicular, Zona Comercial | H38: -348006070000 | I38: -582784580000 | J38: =COUNTIF(M38:AN38,"") -> 28 | K38: =COUNTIF(M38:AN38,"APAGADO") -> 0 | L38: =(J38)/(K38+J38) -> 1
A39: CENTRO | B39: CEN03 | C39: San Martin y Sallares | D39: Domo | E39: Fibra Optica | F39: Zona Comercial, Flujo Vehicular | G39: 29/03/19 FUNCIONA EN COD 1 | H39: -348080340000 | I39: -582780930000 | J39: =COUNTIF(M39:AN39,"") -> 28 | K39: =COUNTIF(M39:AN39,"APAGADO") -> 0 | L39: =(J39)/(K39+J39) -> 1
A40: CENTRO | B40: CEN04 | C40: San Martin y Contreras | D40: Domo | E40: Fibra Optica | F40: Zona de recreaciÃ³n, Flujo vehicular | H40: -348049240000 | I40: -582781680000 | J40: =COUNTIF(M40:AN40,"") -> 28 | K40: =COUNTIF(M40:AN40,"APAGADO") -> 0 | L40: =(J40)/(K40+J40) -> 1
...

Sheet ESTADISTICA
A1: ='RESUMEN TOTAL'!A4 -> Barrio | B1: ='RESUMEN TOTAL'!B4 -> [Denominacion] | C1: ='RESUMEN TOTAL'!C4 -> [Ubicacion] | D1: ='RESUMEN TOTAL'!D4 -> [Tipo de Camara] | E1: ='RESUMEN TOTAL'!E4 -> [Tipo de Conexion] | F1: ='RESUMEN TOTAL'!M4 -> 44593 | G1: ='RESUMEN TOTAL'!N4 -> 44594 | H1: ='RESUMEN TOTAL'!O4 -> 44595 | I1: ='RESUMEN TOTAL'!P4 -> 44596 | J1: ='RESUMEN TOTAL'!Q4 -> 44597 | K1: ='RESUMEN TOTAL'!R4 -> 44598 | L1: ='RESUMEN TOTAL'!S4 -> 44599 | M1: ='RESUMEN TOTAL'!T4 -> 44600 | ... AG1: ='RESUMEN TOTAL'!AN4 -> 44620
A2: ='RESUMEN TOTAL'!A5 -> PRESIDENTE PERON (PEPSI) | B2: ='RESUMEN TOTAL'!B5 -> MAR 01 | C2: ='RESUMEN TOTAL'!C5 -> RP36 Y LA ESMERALDA | D2: ='RESUMEN TOTAL'!D5 -> DOMO | E2: ='RESUMEN TOTAL'!E5 -> RADIO | F2: ='RESUMEN TOTAL'!M5 -> APAGADO | G2: ='RESUMEN TOTAL'!N5 -> 0 | H2: ='RESUMEN TOTAL'!O5 -> APAGADO | I2: ='RESUMEN TOTAL'!P5 -> APAGADO | J2: ='RESUMEN TOTAL'!Q5 -> APAGADO | K2: ='RESUMEN TOTAL'!R5 -> APAGADO | L2: ='RESUMEN TOTAL'!S5 -> 0 | M2: ='RESUMEN TOTAL'!T5 -> 0 | ... AG2: ='RESUMEN TOTAL'!AN5 -> 0
A3: ='RESUMEN TOTAL'!A6 -> MAYOL | B3: ='RESUMEN TOTAL'!B6 -> MAY 01 | C3: ='RESUMEN TOTAL'!C6 -> Eva Peron y Cabildo | D3: ='RESUMEN TOTAL'!D6 -> Domo | E3: ='RESUMEN TOTAL'!E6 -> Radio | F3: ='RESUMEN TOTAL'!M6 -> 0 | G3: ='RESUMEN TOTAL'!N6 -> 0 | H3: ='RESUMEN TOTAL'!O6 -> 0 | I3: ='RESUMEN TOTAL'!P6 -> 0 | J3: ='RESUMEN TOTAL'!Q6 -> 0 | K3: ='RESUMEN TOTAL'!R6 -> 0 | L3: ='RESUMEN TOTAL'!S6 -> 0 | M3: ='RESUMEN TOTAL'!T6 -> 0 | ... AG3: ='RESUMEN TOTAL'!AN6 -> 0
A4: ='RESUMEN TOTAL'!A7 -> 0 | B4: ='RESUMEN TOTAL'!B7 -> MAY 02 | C4: ='RESUMEN TOTAL'!C7 -> EVA PERON Y MONTEVIDEO | D4: ='RESUMEN TOTAL'!D7 -> Domo | E4: ='RESUMEN TOTAL'!E7 -> Radio | F4: ='RESUMEN TOTAL'!M7 -> APAGADO | G4: ='RESUMEN TOTAL'!N7 -> APAGADO | H4: ='RESUMEN TOTAL'!O7 -> APAGADO | I4: ='RESUMEN TOTAL'!P7 -> APAGADO | J4: ='RESUMEN TOTAL'!Q7 -> APAGADO | K4: ='RESUMEN TOTAL'!R7 -> APAGADO | L4: ='RESUMEN TOTAL'!S7 -> APAGADO | M4: ='RESUMEN TOTAL'!T7 -> APAGADO | ... AG4: ='RESUMEN TOTAL'!AN7 -> 0
A5: ='RESUMEN TOTAL'!A8 -> MAYOL | B5: ='RESUMEN TOTAL'!B8 -> MAY 03 | C5: ='RESUMEN TOTAL'!C8 -> CHAÑAR Y SAN NICOLAS | D5: ='RESUMEN TOTAL'!D8 -> DOMO | E5: ='RESUMEN TOTAL'!E8 -> Radio | F5: ='RESUMEN TOTAL'!M8 -> 0 | G5: ='RESUMEN TOTAL'!N8 -> 0 | H5: ='RESUMEN TOTAL'!O8 -> 0 | I5: ='RESUMEN TOTAL'!P8 -> APAGADO | J5: ='RESUMEN TOTAL'!Q8 -> APAGADO | K5: ='RESUMEN TOTAL'!R8 -> APAGADO | L5: ='RESUMEN TOTAL'!S8 -> 0 | M5: ='RESUMEN TOTAL'!T8 -> 0 | ... AG5: ='RESUMEN TOTAL'!AN8 -> 0
A6: ='RESUMEN TOTAL'!A9 -> 0 | B6: ='RESUMEN TOTAL'!B9 -> MAY 04 | C6: ='RESUMEN TOTAL'!C9 -> MAR CHIQUITA Y RIO JACHAL | D6: ='RESUMEN TOTAL'!D9 -> DOMO | E6: ='RESUMEN TOTAL'!E9 -> Radio | F6: ='RESUMEN TOTAL'!M9 -> 0 | G6: ='RESUMEN TOTAL'!N9 -> 0 | H6: ='RESUMEN TOTAL'!O9 -> 0 | I6: ='RESUMEN TOTAL'!P9 -> 0 | J6: ='RESUMEN TOTAL'!Q9 -> 0 | K6: ='RESUMEN TOTAL'!R9 -> 0 | L6: ='RESUMEN TOTAL'!S9 -> 0 | M6: ='RESUMEN TOTAL'!T9 -> 0 | ... AG6: ='RESUMEN TOTAL'!AN9 -> 0
A7: ='RESUMEN TOTAL'!A10 -> ALTAMIRA | B7: ='RESUMEN TOTAL'!B10 -> ALT 06 | C7: ='RESUMEN TOTAL'!C10 -> LOPE DE VEGA Y NECOCHEA | D7: ='RESUMEN TOTAL'!D10 -> Domo | E7: ='RESUMEN TOTAL'!E10 -> Fibra Optica | F7: ='RESUMEN TOTAL'!M10 -> APAGADO | G7: ='RESUMEN TOTAL'!N10 -> APAGADO | H7: ='RESUMEN TOTAL'!O10 -> APAGADO | I7: ='RESUMEN TOTAL'!P10 -> APAGADO | J7: ='RESUMEN TOTAL'!Q10 -> APAGADO | K7: ='RESUMEN TOTAL'!R10 -> APAGADO | L7: ='RESUMEN TOTAL'!S10 -> APAGADO | M7: ='RESUMEN TOTAL'!T10 -> APAGADO | ... AG7: ='RESUMEN TOTAL'!AN10 -> 0
A8: ='RESUMEN TOTAL'!A11 -> ALTAMIRA | B8: ='RESUMEN TOTAL'!B11 -> ALT01 | C8: ='RESUMEN TOTAL'!C11 -> Calchaqui y Sgto. Cabral | D8: ='RESUMEN TOTAL'!D11 -> Domo | E8: ='RESUMEN TOTAL'!E11 -> Fibra Optica | F8: ='RESUMEN TOTAL'!M11 -> 0 | G8: ='RESUMEN TOTAL'!N11 -> 0 | H8: ='RESUMEN TOTAL'!O11 -> 0 | I8: ='RESUMEN TOTAL'!P11 -> 0 | J8: ='RESUMEN TOTAL'!Q11 -> 0 | K8: ='RESUMEN TOTAL'!R11 -> 0 | L8: ='RESUMEN TOTAL'!S11 -> 0 | M8: ='RESUMEN TOTAL'!T11 -> 0 | ... AG8: ='RESUMEN TOTAL'!AN11 -> 0
A9: ='RESUMEN TOTAL'!A12 -> ALTAMIRA | B9: ='RESUMEN TOTAL'!B12 -> ALT02 | C9: ='RESUMEN TOTAL'!C12 -> Calchaqui y Lope de Vega | D9: ='RESUMEN TOTAL'!D12 -> Domo | E9: ='RESUMEN TOTAL'!E12 -> Radio | F9: ='RESUMEN TOTAL'!M12 -> 0 | G9: ='RESUMEN TOTAL'!N12 -> 0 | H9: ='RESUMEN TOTAL'!O12 -> 0 | I9: ='RESUMEN TOTAL'!P12 -> 0 | J9: ='RESUMEN TOTAL'!Q12 -> 0 | K9: ='RESUMEN TOTAL'!R12 -> 0 | L9: ='RESUMEN TOTAL'!S12 -> 0 | M9: ='RESUMEN TOTAL'!T12 -> 0 | ... AG9: ='RESUMEN TOTAL'!AN12 -> 0
A10: ='RESUMEN TOTAL'!A13 -> ALTAMIRA | B10: ='RESUMEN TOTAL'!B13 -> ALT03 | C10: ='RESUMEN TOTAL'!C13 -> Bombero Galarza y Necochea | D10: ='RESUMEN TOTAL'!D13 -> Domo | E10: ='RESUMEN TOTAL'!E13 -> Radio | F10: ='RESUMEN TOTAL'!M13 -> APAGADO | G10: ='RESUMEN TOTAL'!N13 -> APAGADO | H10: ='RESUMEN TOTAL'!O13 -> APAGADO | I10: ='RESUMEN TOTAL'!P13 -> APAGADO | J10: ='RESUMEN TOTAL'!Q13 -> APAGADO | K10: ='RESUMEN TOTAL'!R13 -> APAGADO | L10: ='RESUMEN TOTAL'!S13 -> APAGADO | M10: ='RESUMEN TOTAL'!T13 -> 0 | ... AG10: ='RESUMEN TOTAL'!AN13 -> 0
A11: ='RESUMEN TOTAL'!A14 -> 0 | B11: ='RESUMEN TOTAL'!B14 -> ALT04 | C11: ='RESUMEN TOTAL'!C14 -> Francia y Necochea | D11: ='RESUMEN TOTAL'!D14 -> Domo | E11: ='RESUMEN TOTAL'!E14 -> Radio | F11: ='RESUMEN TOTAL'!M14 -> APAGADO | G11: ='RESUMEN TOTAL'!N14 -> APAGADO | H11: ='RESUMEN TOTAL'!O14 -> APAGADO | I11: ='RESUMEN TOTAL'!P14 -> APAGADO | J11: ='RESUMEN TOTAL'!Q14 -> APAGADO | K11: ='RESUMEN TOTAL'!R14 -> APAGADO | L11: ='RESUMEN TOTAL'!S14 -> APAGADO | M11: ='RESUMEN TOTAL'!T14 -> 0 | ... AG11: ='RESUMEN TOTAL'!AN14 -> 0
A12: ='RESUMEN TOTAL'!A15 -> ALTAMIRA | B12: ='RESUMEN TOTAL'!B15 -> ALT05 | C12: ='RESUMEN TOTAL'!C15 -> Av. Calchaqui y Bombero Galarza | D12: ='RESUMEN TOTAL'!D15 -> Domo | E12: ='RESUMEN TOTAL'!E15 -> Radio | F12: ='RESUMEN TOTAL'!M15 -> 0 | G12: ='RESUMEN TOTAL'!N15 -> 0 | H12: ='RESUMEN TOTAL'!O15 -> 0 | I12: ='RESUMEN TOTAL'!P15 -> 0 | J12: ='RESUMEN TOTAL'!Q15 -> 0 | K12: ='RESUMEN TOTAL'!R15 -> 0 | L12: ='RESUMEN TOTAL'!S15 -> 0 | M12: ='RESUMEN TOTAL'!T15 -> 0 | ... AG12: ='RESUMEN TOTAL'!AN15 -> 0
... A365: ='RESUMEN TOTAL'!A368 -> 0 | B365: ='RESUMEN TOTAL'!B368 -> ZEB04 | C365: ='RESUMEN TOTAL'!C368 -> THEVENET Y DIAGONAL GRANADEROS | D365: ='RESUMEN TOTAL'!D368 -> DOMO | E365: ='RESUMEN TOTAL'!E368 -> Radio | F365: ='RESUMEN TOTAL'!M368 -> 0 | G365: ='RESUMEN TOTAL'!N368 -> 0 | H365: ='RESUMEN TOTAL'!O368 -> 0 | I365: ='RESUMEN TOTAL'!P368 -> 0 | J365: ='RESUMEN TOTAL'!Q368 -> 0 | K365: ='RESUMEN TOTAL'!R368 -> 0 | L365: ='RESUMEN TOTAL'!S368 -> 0 | M365: ='RESUMEN TOTAL'!T368 -> 0 | ... AG365: ='RESUMEN TOTAL'!AN368 -> 0

Sheet APAGADOS
E1: APAGADOS | F1: =COUNTIF(F3:F366, "APAGADO") -> 89 | G1: =COUNTIF(G3:G366, "APAGADO") -> 88 | H1: =COUNTIF(H3:H366, "APAGADO") -> 78 | I1: =COUNTIF(I3:I366, "APAGADO") -> 78 | J1: =COUNTIF(J3:J366, "APAGADO") -> 78 | K1: =COUNTIF(K3:K366, "APAGADO") -> 78 | L1: =COUNTIF(L3:L366, "APAGADO") -> 85 | M1: =COUNTIF(M3:M366, "APAGADO") -> 80 | ... AG1: =COUNTIF(AG3:AG366, "APAGADO") -> 0
A2: =ESTADISTICA!A1 -> Barrio | B2: =ESTADISTICA!B1 -> [Denominacion] | C2: =ESTADISTICA!C1 -> [Ubicacion] | D2: =ESTADISTICA!D1 -> [Tipo de Camara] | E2: =ESTADISTICA!E1 -> [Tipo de Conexion] | F2: =ESTADISTICA!F1 -> 44593 | G2: =ESTADISTICA!G1 -> 44594 | H2: =ESTADISTICA!H1 -> 44595 | ... AG2: =ESTADISTICA!AG1 -> 44620
A3: =ESTADISTICA!A2 -> PRESIDENTE PERON (PEPSI) | B3: =ESTADISTICA!B2 -> MAR 01 | C3: =ESTADISTICA!C2 -> RP36 Y LA ESMERALDA | D3: =ESTADISTICA!D2 -> DOMO | E3: =ESTADISTICA!E2 -> RADIO | F3: =ESTADISTICA!F2 -> APAGADO | G3: =ESTADISTICA!G2 -> 0 | H3: =ESTADISTICA!H2 -> APAGADO | ... AG3: =ESTADISTICA!AG2 -> 0
A4: =ESTADISTICA!A3 -> MAYOL | B4: =ESTADISTICA!B3 -> MAY 01 | C4: =ESTADISTICA!C3 -> Eva Peron y Cabildo | D4: =ESTADISTICA!D3 -> Domo | E4: =ESTADISTICA!E3 -> Radio | F4: =ESTADISTICA!F3 -> 0 | G4: =ESTADISTICA!G3 -> 0 | H4: =ESTADISTICA!H3 -> 0 | ... AG4: =ESTADISTICA!AG3 -> 0
A5: =ESTADISTICA!A4 -> 0 | B5: =ESTADISTICA!B4 -> MAY 02 | C5: =ESTADISTICA!C4 -> EVA PERON Y MONTEVIDEO | D5: =ESTADISTICA!D4 -> Domo | E5: =ESTADISTICA!E4 -> Radio | F5: =ESTADISTICA!F4 -> APAGADO | G5: =ESTADISTICA!G4 -> APAGADO | H5: =ESTADISTICA!H4 -> APAGADO | ... AG5: =ESTADISTICA!AG4 -> 0
A6: =ESTADISTICA!A5 -> MAYOL | B6: =ESTADISTICA!B5 -> MAY 03 | C6: =ESTADISTICA!C5 -> CHAÑAR Y SAN NICOLAS | D6: =ESTADISTICA!D5 -> DOMO | E6: =ESTADISTICA!E5 -> Radio | F6: =ESTADISTICA!F5 -> 0 | G6: =ESTADISTICA!G5 -> 0 | H6: =ESTADISTICA!H5 -> 0 | ... AG6: =ESTADISTICA!AG5 -> 0
A7: =ESTADISTICA!A6 -> 0 | B7: =ESTADISTICA!B6 -> MAY 04 | C7: =ESTADISTICA!C6 -> MAR CHIQUITA Y RIO JACHAL | D7: =ESTADISTICA!D6 -> DOMO | E7: =ESTADISTICA!E6 -> Radio | F7: =ESTADISTICA!F6 -> 0 | G7: =ESTADISTICA!G6 -> 0 | H7: =ESTADISTICA!H6 -> 0 | ... AG7: =ESTADISTICA!AG6 -> 0
A8: =ESTADISTICA!A7 -> ALTAMIRA | B8: =ESTADISTICA!B7 -> ALT 06 | C8: =ESTADISTICA!C7 -> LOPE DE VEGA Y NECOCHEA | D8: =ESTADISTICA!D7 -> Domo | E8: =ESTADISTICA!E7 -> Fibra Optica | F8: =ESTADISTICA!F7 -> APAGADO | G8: =ESTADISTICA!G7 -> APAGADO | H8: =ESTADISTICA!H7 -> APAGADO | ... AG8: =ESTADISTICA!AG7 -> 0
A9: =ESTADISTICA!A8 -> ALTAMIRA | B9: =ESTADISTICA!B8 -> ALT01 | C9: =ESTADISTICA!C8 -> Calchaqui y Sgto. Cabral | D9: =ESTADISTICA!D8 -> Domo | E9: =ESTADISTICA!E8 -> Fibra Optica | F9: =ESTADISTICA!F8 -> 0 | G9: =ESTADISTICA!G8 -> 0 | H9: =ESTADISTICA!H8 -> 0 | ... AG9: =ESTADISTICA!AG8 -> 0
A10: =ESTADISTICA!A9 -> ALTAMIRA | B10: =ESTADISTICA!B9 -> ALT02 | C10: =ESTADISTICA!C9 -> Calchaqui y Lope de Vega | D10: =ESTADISTICA!D9 -> Domo | E10: =ESTADISTICA!E9 -> Radio | F10: =ESTADISTICA!F9 -> 0 | G10: =ESTADISTICA!G9 -> 0 | H10: =ESTADISTICA!H9 -> 0 | ... AG10: =ESTADISTICA!AG9 -> 0
A11: =ESTADISTICA!A10 -> ALTAMIRA | B11: =ESTADISTICA!B10 -> ALT03 | C11: =ESTADISTICA!C10 -> Bombero Galarza y Necochea | D11: =ESTADISTICA!D10 -> Domo | E11: =ESTADISTICA!E10 -> Radio | F11: =ESTADISTICA!F10 -> APAGADO | G11: =ESTADISTICA!G10 -> APAGADO | H11: =ESTADISTICA!H10 -> APAGADO | ... AG11: =ESTADISTICA!AG10 -> 0
A12: =ESTADISTICA!A11 -> 0 | B12: =ESTADISTICA!B11 -> ALT04 | C12: =ESTADISTICA!C11 -> Francia y Necochea | D12: =ESTADISTICA!D11 -> Domo | E12: =ESTADISTICA!E11 -> Radio | F12: =ESTADISTICA!F11 -> APAGADO | G12: =ESTADISTICA!G11 -> APAGADO | H12: =ESTADISTICA!H11 -> APAGADO | ... AG12: =ESTADISTICA!AG11 -> 0
A13: =ESTADISTICA!A12 -> ALTAMIRA | B13: =ESTADISTICA!B12 -> ALT05 | C13: =ESTADISTICA!C12 -> Av. Calchaqui y Bombero Galarza | D13: =ESTADISTICA!D12 -> Domo | E13: =ESTADISTICA!E12 -> Radio | F13: =ESTADISTICA!F12 -> 0 | G13: =ESTADISTICA!G12 -> 0 | H13: =ESTADISTICA!H12 -> 0 | ... AG13: =ESTADISTICA!AG12 -> 0
... A366: =ESTADISTICA!A365 -> 0 | B366: =ESTADISTICA!B365 -> ZEB04 | C366: =ESTADISTICA!C365 -> THEVENET Y DIAGONAL GRANADEROS | D366: =ESTADISTICA!D365 -> DOMO | E366: =ESTADISTICA!E365 -> Radio | F366: =ESTADISTICA!F365 -> 0 | G366: =ESTADISTICA!G365 -> 0 | H366: =ESTADISTICA!H365 -> 0 | ... AG366: =ESTADISTICA!AG365 -> 0

Sheet APAGADOS FIBRA
E1: APAGADOS | F1: =COUNTIFS(F3:F366, "=APAGADO",E3:E366,"=Fibra Optica") -> 45 | G1: =COUNTIFS(G3:G366, "=APAGADO",E3:E366,"=Fibra Optica") -> 46 | H1: =COUNTIFS(H3:H366, "=APAGADO",E3:E366,"=Fibra Optica") -> 45 | I1: =COUNTIFS(I3:I366, "=APAGADO",E3:E366,"=Fibra Optica") -> 47 | J1: =COUNTIFS(J3:J366, "=APAGADO",E3:E366,"=Fibra Optica") -> 47 | K1: =COUNTIFS(K3:K366, "=APAGADO",E3:E366,"=Fibra Optica") -> 47 | L1: =COUNTIFS(L3:L366, "=APAGADO",E3:E366,"=Fibra Optica") -> 53 | M1: =COUNTIFS(M3:M366, "=APAGADO",E3:E366,"=Fibra Optica") -> 52 | N1: =COUNTIFS(N3:N366, "=APAGADO",E3:E366,"=Fibra Optica") -> 50 | O1: =COUNTIFS(O3:O366, "=APAGADO",E3:E366,"=Fibra Optica") -> 50 | P1: =COUNTIFS(P3:P366, "=APAGADO",E3:E366,"=Fibra Optica") -> 0 | Q1: =COUNTIFS(Q3:Q366, "=APAGADO",E3:E366,"=Fibra Optica") -> 0 | R1: =COUNTIFS(R3:R366, "=APAGADO",E3:E366,"=Fibra Optica") -> 0 | S1: =COUNTIFS(S3:S366, "=APAGADO",E3:E366,"=Fibra Optica") -> 0 | T1: =COUNTIFS(T3:T366, "=APAGADO",E3:E366,"=Fibra Optica") -> 0 | U1: =COUNTIFS(U3:U366, "=APAGADO",E3:E366,"=Fibra Optica") -> 0 | V1: =COUNTIFS(V3:V366, "=APAGADO",E3:E366,"=Fibra Optica") -> 0 | W1: =COUNTIFS(W3:W366, "=APAGADO",E3:E366,"=Fibra Optica") -> 0 | X1: =COUNTIFS(X3:X366, "=APAGADO",E3:E366,"=Fibra Optica") -> 0 | Y1: =COUNTIFS(Y3:Y366, "=APAGADO",E3:E366,"=Fibra Optica") -> 0 | Z1: =COUNTIFS(Z3:Z366, "=APAGADO",E3:E366,"=Fibra Optica") -> 0 | AA1: =COUNTIFS(AA3:AA366, "=APAGADO",Y3:Y366,"=Fibra Optica") -> 0 | AB1: =COUNTIFS(AB3:AB366, "=APAGADO",Y3:Y366,"=Fibra Optica") -> 0 | AC1: =COUNTIFS(AC3:AC366, "=APAGADO",Y3:Y366,"=Fibra Optica") -> 0 | AD1: =COUNTIFS(AD3:AD366, "=APAGADO",AC3:AC366,"=Fibra Optica") -> 0 | AE1: =COUNTIFS(AE3:AE366, "=APAGADO",AC3:AC366,"=Fibra Optica") -> 0 | AF1: =COUNTIFS(AF3:AF366, "=APAGADO",AC3:AC366,"=Fibra Optica") -> 0 | AG1: =COUNTIFS(AG3:AG366, "=APAGADO",AC3:AC366,"=Fibra Optica") -> 0
A2: =ESTADISTICA!A1 -> Barrio | B2: =ESTADISTICA!B1 -> [Denominacion] | C2: =ESTADISTICA!C1 -> [Ubicacion] | D2: =ESTADISTICA!D1 -> [Tipo de Camara] | E2: =ESTADISTICA!E1 -> [Tipo de Conexion] | F2: =ESTADISTICA!F1 -> 44593 | G2: =ESTADISTICA!G1 -> 44594 | H2: =ESTADISTICA!H1 -> 44595 | ... AG2: =ESTADISTICA!AG1 -> 44620
A3: =ESTADISTICA!A2 -> PRESIDENTE PERON (PEPSI) | B3: =ESTADISTICA!B2 -> MAR 01 | C3: =ESTADISTICA!C2 -> RP36 Y LA ESMERALDA | D3: =ESTADISTICA!D2 -> DOMO | E3: =ESTADISTICA!E2 -> RADIO | F3: =ESTADISTICA!F2 -> APAGADO | G3: =ESTADISTICA!G2 -> 0 | H3: =ESTADISTICA!H2 -> APAGADO | ... AG3: =ESTADISTICA!AG2 -> 0
A4: =ESTADISTICA!A3 -> MAYOL | B4: =ESTADISTICA!B3 -> MAY 01 | C4: =ESTADISTICA!C3 -> Eva Peron y Cabildo | D4: =ESTADISTICA!D3 -> Domo | E4: =ESTADISTICA!E3 -> Radio | F4: =ESTADISTICA!F3 -> 0 | G4: =ESTADISTICA!G3 -> 0 | H4: =ESTADISTICA!H3 -> 0 | ... AG4: =ESTADISTICA!AG3 -> 0
A5: =ESTADISTICA!A4 -> 0 | B5: =ESTADISTICA!B4 -> MAY 02 | C5: =ESTADISTICA!C4 -> EVA PERON Y MONTEVIDEO | D5: =ESTADISTICA!D4 -> Domo | E5: =ESTADISTICA!E4 -> Radio | F5: =ESTADISTICA!F4 -> APAGADO | G5: =ESTADISTICA!G4 -> APAGADO | H5: =ESTADISTICA!H4 -> APAGADO | ... AG5: =ESTADISTICA!AG4 -> 0
A6: =ESTADISTICA!A5 -> MAYOL | B6: =ESTADISTICA!B5 -> MAY 03 | C6: =ESTADISTICA!C5 -> CHAÑAR Y SAN NICOLAS | D6: =ESTADISTICA!D5 -> DOMO | E6: =ESTADISTICA!E5 -> Radio | F6: =ESTADISTICA!F5 -> 0 | G6: =ESTADISTICA!G5 -> 0 | H6: =ESTADISTICA!H5 -> 0 | ... AG6: =ESTADISTICA!AG5 -> 0
A7: =ESTADISTICA!A6 -> 0 | B7: =ESTADISTICA!B6 -> MAY 04 | C7: =ESTADISTICA!C6 -> MAR CHIQUITA Y RIO JACHAL | D7: =ESTADISTICA!D6 -> DOMO | E7: =ESTADISTICA!E6 -> Radio | F7: =ESTADISTICA!F6 -> 0 | G7: =ESTADISTICA!G6 -> 0 | H7: =ESTADISTICA!H6 -> 0 | ... AG7: =ESTADISTICA!AG6 -> 0
A8: =ESTADISTICA!A7 -> ALTAMIRA | B8: =ESTADISTICA!B7 -> ALT 06 | C8: =ESTADISTICA!C7 -> LOPE DE VEGA Y NECOCHEA | D8: =ESTADISTICA!D7 -> Domo | E8: =ESTADISTICA!E7 -> Fibra Optica | F8: =ESTADISTICA!F7 -> APAGADO | G8: =ESTADISTICA!G7 -> APAGADO | H8: =ESTADISTICA!H7 -> APAGADO | ... AG8: =ESTADISTICA!AG7 -> 0
A9: =ESTADISTICA!A8 -> ALTAMIRA | B9: =ESTADISTICA!B8 -> ALT01 | C9: =ESTADISTICA!C8 -> Calchaqui y Sgto. Cabral | D9: =ESTADISTICA!D8 -> Domo | E9: =ESTADISTICA!E8 -> Fibra Optica | F9: =ESTADISTICA!F8 -> 0 | G9: =ESTADISTICA!G8 -> 0 | H9: =ESTADISTICA!H8 -> 0 | ... AG9: =ESTADISTICA!AG8 -> 0
A10: =ESTADISTICA!A9 -> ALTAMIRA | B10: =ESTADISTICA!B9 -> ALT02 | C10: =ESTADISTICA!C9 -> Calchaqui y Lope de Vega | D10: =ESTADISTICA!D9 -> Domo | E10: =ESTADISTICA!E9 -> Radio | F10: =ESTADISTICA!F9 -> 0 | G10: =ESTADISTICA!G9 -> 0 | H10: =ESTADISTICA!H9 -> 0 | ... AG10: =ESTADISTICA!AG9 -> 0
A11: =ESTADISTICA!A10 -> ALTAMIRA | B11: =ESTADISTICA!B10 -> ALT03 | C11: =ESTADISTICA!C10 -> Bombero Galarza y Necochea | D11: =ESTADISTICA!D10 -> Domo | E11: =ESTADISTICA!E10 -> Radio | F11: =ESTADISTICA!F10 -> APAGADO | G11: =ESTADISTICA!G10 -> APAGADO | H11: =ESTADISTICA!H10 -> APAGADO | ... AG11: =ESTADISTICA!AG10 -> 0
A12: =ESTADISTICA!A11 -> 0 | B12: =ESTADISTICA!B11 -> ALT04 | C12: =ESTADISTICA!C11 -> Francia y Necochea | D12: =ESTADISTICA!D11 -> Domo | E12: =ESTADISTICA!E11 -> Radio | F12: =ESTADISTICA!F11 -> APAGADO | G12: =ESTADISTICA!G11 -> APAGADO | H12: =ESTADISTICA!H11 -> APAGADO | ... AG12: =ESTADISTICA!AG11 -> 0
A13: =ESTADISTICA!A12 -> ALTAMIRA | B13: =ESTADISTICA!B12 -> ALT05 | C13: =ESTADISTICA!C12 -> Av. Calchaqui y Bombero Galarza | D13: =ESTADISTICA!D12 -> Domo | E13: =ESTADISTICA!E12 -> Radio | F13: =ESTADISTICA!F12 -> 0 | G13: =ESTADISTICA!G12 -> 0 | H13: =ESTADISTICA!H12 -> 0 | ... AG13: =ESTADISTICA!AG12 -> 0
... A366: =ESTADISTICA!A365 -> 0 | B366: =ESTADISTICA!B365 -> ZEB04 | C366: =ESTADISTICA!C365 -> THEVENET Y DIAGONAL GRANADEROS | D366: =ESTADISTICA!D365 -> DOMO | E366: =ESTADISTICA!E365 -> Radio | F366: =ESTADISTICA!F365 -> 0 | G366: =ESTADISTICA!G365 -> 0 | H366: =ESTADISTICA!H365 -> 0 | ... AG366: =ESTADISTICA!AG365 -> 0

Sheet APAGADOS RADIO
E1: APAGADOS | F1: =COUNTIFS(F3:F366, "=APAGADO",E3:E366,"=radio") -> 43 | G1: =COUNTIFS(G3:G366, "=APAGADO",E3:E366,"=radio") -> 41 | H1: =COUNTIFS(H3:H366, "=APAGADO",E3:E366,"=radio") -> 33 | I1: =COUNTIFS(I3:I366, "=APAGADO",E3:E366,"=radio") -> 31 | J1: =COUNTIFS(J3:J366, "=APAGADO",E3:E366,"=radio") -> 31 | K1: =COUNTIFS(K3:K366, "=APAGADO",E3:E366,"=radio") -> 31 | L1: =COUNTIFS(L3:L366, "=APAGADO",E3:E366,"=radio") -> 32 | M1: =COUNTIFS(M3:M366, "=APAGADO",E3:E366,"=radio") -> 28 | N1: =COUNTIFS(N3:N366, "=APAGADO",E3:E366,"=radio") -> 31 | O1: =COUNTIFS(O3:O366, "=APAGADO",E3:E366,"=radio") -> 31 | P1: =COUNTIFS(P3:P366, "=APAGADO",E3:E366,"=radio") -> 0 | Q1: =COUNTIFS(Q3:Q366, "=APAGADO",E3:E366,"=radio") -> 0 | R1: =COUNTIFS(R3:R366, "=APAGADO",E3:E366,"=radio") -> 0 | S1: =COUNTIFS(S3:S366, "=APAGADO",E3:E366,"=radio") -> 0 | T1: =COUNTIFS(T3:T366, "=APAGADO",E3:E366,"=radio") -> 0 | U1: =COUNTIFS(U3:U366, "=APAGADO",E3:E366,"=radio") -> 0 | V1: =COUNTIFS(V3:V366, "=APAGADO",E3:E366,"=radio") -> 0 | W1: =COUNTIFS(W3:W366, "=APAGADO",E3:E366,"=radio") -> 0 | X1: =COUNTIFS(X3:X366, "=APAGADO",E3:E366,"=radio") -> 0 | Y1: =COUNTIFS(Y3:Y366, "=APAGADO",E3:E366,"=radio") -> 0 | Z1: =COUNTIFS(Z3:Z366, "=APAGADO",E3:E366,"=radio") -> 0 | AA1: =COUNTIFS(AA3:AA366, "=APAGADO",E3:E366,"=radio") -> 0 | AB1: =COUNTIFS(AB3:AB366, "=APAGADO",E3:E366,"=radio") -> 0 | AC1: =COUNTIFS(AC3:AC366, "=APAGADO",E3:E366,"=radio") -> 0 | AD1: =COUNTIFS(AD3:AD366, "=APAGADO",E3:E366,"=radio") -> 0 | AE1: =COUNTIFS(AE3:AE366, "=APAGADO",E3:E366,"=radio") -> 0 | AF1: =COUNTIFS(AF3:AF366, "=APAGADO",E3:E366,"=radio") -> 0 | AG1: =COUNTIFS(AG3:AG366, "=APAGADO",E3:E366,"=radio") -> 0
A2: =ESTADISTICA!A1 -> Barrio | B2: =ESTADISTICA!B1 -> [Denominacion] | C2: =ESTADISTICA!C1 -> [Ubicacion] | D2: =ESTADISTICA!D1 -> [Tipo de Camara] | E2: =ESTADISTICA!E1 -> [Tipo de Conexion] | F2: =ESTADISTICA!F1 -> 44593 | G2: =ESTADISTICA!G1 -> 44594 | H2: =ESTADISTICA!H1 -> 44595 | ... AG2: =ESTADISTICA!AG1 -> 44620
A3: =ESTADISTICA!A2 -> PRESIDENTE PERON (PEPSI) | B3: =ESTADISTICA!B2 -> MAR 01 | C3: =ESTADISTICA!C2 -> RP36 Y LA ESMERALDA | D3: =ESTADISTICA!D2 -> DOMO | E3: =ESTADISTICA!E2 -> RADIO | F3: =ESTADISTICA!F2 -> APAGADO | G3: =ESTADISTICA!G2 -> 0 | H3: =ESTADISTICA!H2 -> APAGADO | ... AG3: =ESTADISTICA!AG2 -> 0
A4: =ESTADISTICA!A3 -> MAYOL | B4: =ESTADISTICA!B3 -> MAY 01 | C4: =ESTADISTICA!C3 -> Eva Peron y Cabildo | D4: =ESTADISTICA!D3 -> Domo | E4: =ESTADISTICA!E3 -> Radio | F4: =ESTADISTICA!F3 -> 0 | G4: =ESTADISTICA!G3 -> 0 | H4: =ESTADISTICA!H3 -> 0 | ... AG4: =ESTADISTICA!AG3 -> 0
A5: =ESTADISTICA!A4 -> 0 | B5: =ESTADISTICA!B4 -> MAY 02 | C5: =ESTADISTICA!C4 -> EVA PERON Y MONTEVIDEO | D5: =ESTADISTICA!D4 -> Domo | E5: =ESTADISTICA!E4 -> Radio | F5: =ESTADISTICA!F4 -> APAGADO | G5: =ESTADISTICA!G4 -> APAGADO | H5: =ESTADISTICA!H4 -> APAGADO | ... AG5: =ESTADISTICA!AG4 -> 0
A6: =ESTADISTICA!A5 -> MAYOL | B6: =ESTADISTICA!B5 -> MAY 03 | C6: =ESTADISTICA!C5 -> CHAÑAR Y SAN NICOLAS | D6: =ESTADISTICA!D5 -> DOMO | E6: =ESTADISTICA!E5 -> Radio | F6: =ESTADISTICA!F5 -> 0 | G6: =ESTADISTICA!G5 -> 0 | H6: =ESTADISTICA!H5 -> 0 | ... AG6: =ESTADISTICA!AG5 -> 0
A7: =ESTADISTICA!A6 -> 0 | B7: =ESTADISTICA!B6 -> MAY 04 | C7: =ESTADISTICA!C6 -> MAR CHIQUITA Y RIO JACHAL | D7: =ESTADISTICA!D6 -> DOMO | E7: =ESTADISTICA!E6 -> Radio | F7: =ESTADISTICA!F6 -> 0 | G7: =ESTADISTICA!G6 -> 0 | H7: =ESTADISTICA!H6 -> 0 | ... AG7: =ESTADISTICA!AG6 -> 0
A8: =ESTADISTICA!A7 -> ALTAMIRA | B8: =ESTADISTICA!B7 -> ALT 06 | C8: =ESTADISTICA!C7 -> LOPE DE VEGA Y NECOCHEA | D8: =ESTADISTICA!D7 -> Domo | E8: =ESTADISTICA!E7 -> Fibra Optica | F8: =ESTADISTICA!F7 -> APAGADO | G8: =ESTADISTICA!G7 -> APAGADO | H8: =ESTADISTICA!H7 -> APAGADO | ... AG8: =ESTADISTICA!AG7 -> 0
A9: =ESTADISTICA!A8 -> ALTAMIRA | B9: =ESTADISTICA!B8 -> ALT01 | C9: =ESTADISTICA!C8 -> Calchaqui y Sgto. Cabral | D9: =ESTADISTICA!D8 -> Domo | E9: =ESTADISTICA!E8 -> Fibra Optica | F9: =ESTADISTICA!F8 -> 0 | G9: =ESTADISTICA!G8 -> 0 | H9: =ESTADISTICA!H8 -> 0 | ... AG9: =ESTADISTICA!AG8 -> 0
A10: =ESTADISTICA!A9 -> ALTAMIRA | B10: =ESTADISTICA!B9 -> ALT02 | C10: =ESTADISTICA!C9 -> Calchaqui y Lope de Vega | D10: =ESTADISTICA!D9 -> Domo | E10: =ESTADISTICA!E9 -> Radio | F10: =ESTADISTICA!F9 -> 0 | G10: =ESTADISTICA!G9 -> 0 | H10: =ESTADISTICA!H9 -> 0 | ... AG10: =ESTADISTICA!AG9 -> 0
A11: =ESTADISTICA!A10 -> ALTAMIRA | B11: =ESTADISTICA!B10 -> ALT03 | C11: =ESTADISTICA!C10 -> Bombero Galarza y Necochea | D11: =ESTADISTICA!D10 -> Domo | E11: =ESTADISTICA!E10 -> Radio | F11: =ESTADISTICA!F10 -> APAGADO | G11: =ESTADISTICA!G10 -> APAGADO | H11: =ESTADISTICA!H10 -> APAGADO | ... AG11: =ESTADISTICA!AG10 -> 0
A12: =ESTADISTICA!A11 -> 0 | B12: =ESTADISTICA!B11 -> ALT04 | C12: =ESTADISTICA!C11 -> Francia y Necochea | D12: =ESTADISTICA!D11 -> Domo | E12: =ESTADISTICA!E11 -> Radio | F12: =ESTADISTICA!F11 -> APAGADO | G12: =ESTADISTICA!G11 -> APAGADO | H12: =ESTADISTICA!H11 -> APAGADO | ... AG12: =ESTADISTICA!AG11 -> 0
A13: =ESTADISTICA!A12 -> ALTAMIRA | B13: =ESTADISTICA!B12 -> ALT05 | C13: =ESTADISTICA!C12 -> Av. Calchaqui y Bombero Galarza | D13: =ESTADISTICA!D12 -> Domo | E13: =ESTADISTICA!E12 -> Radio | F13: =ESTADISTICA!F12 -> 0 | G13: =ESTADISTICA!G12 -> 0 | H13: =ESTADISTICA!H12 -> 0 | ... AG13: =ESTADISTICA!AG12 -> 0
... A366: =ESTADISTICA!A365 -> 0 | B366: =ESTADISTICA!B365 -> ZEB04 | C366: =ESTADISTICA!C365 -> THEVENET Y DIAGONAL GRANADEROS | D366: =ESTADISTICA!D365 -> DOMO | E366: =ESTADISTICA!E365 -> Radio | F366: =ESTADISTICA!F365 -> 0 | G366: =ESTADISTICA!G365 -> 0 | H366: =ESTADISTICA!H365 -> 0 | ... AG366: =ESTADISTICA!AG365 -> 0

Sheet GRAFICO

Sheet GRAFICO2

Sheet AUXILIAR
A1: FECHA | B1: RADIO | C1: FIBRA | D1: TOTAL APAGADOS | E1: INSTALADAS
A2: ='APAGADOS RADIO'!F2 -> 44593 | B2: ='APAGADOS RADIO'!F1 -> 43 | C2: ='APAGADOS FIBRA'!F1 -> 45 | D2: =B2+C2 -> 88 | E2: ='RESUMEN TOTAL'!B1 -> 364
A3: ='APAGADOS RADIO'!G2 -> 44594 | B3: ='APAGADOS RADIO'!G1 -> 41 | C3: ='APAGADOS FIBRA'!G1 -> 46 | D3: =B3+C3 -> 87 | E3: ='RESUMEN TOTAL'!B1 -> 364
A4: ='APAGADOS RADIO'!H2 -> 44595 | B4: ='APAGADOS RADIO'!H1 -> 33 | C4: ='APAGADOS FIBRA'!H1 -> 45 | D4: =B4+C4 -> 78 | E4: ='RESUMEN TOTAL'!B1 -> 364
A5: ='APAGADOS RADIO'!I2 -> 44596 | B5: ='APAGADOS RADIO'!I1 -> 31 | C5: ='APAGADOS FIBRA'!I1 -> 47 | D5: =B5+C5 -> 78 | E5: ='RESUMEN TOTAL'!B1 -> 364
A6: ='APAGADOS RADIO'!J2 -> 44597 | B6: ='APAGADOS RADIO'!J1 -> 31 | C6: ='APAGADOS FIBRA'!J1 -> 47 | D6: =B6+C6 -> 78 | E6: ='RESUMEN TOTAL'!B1 -> 364
A7: ='APAGADOS RADIO'!K2 -> 44598 | B7: ='APAGADOS RADIO'!K1 -> 31 | C7: ='APAGADOS FIBRA'!K1 -> 47 | D7: =B7+C7 -> 78 | E7: ='RESUMEN TOTAL'!B1 -> 364
A8: ='APAGADOS RADIO'!L2 -> 44599 | B8: ='APAGADOS RADIO'!L1 -> 32 | C8: ='APAGADOS FIBRA'!L1 -> 53 | D8: =B8+C8 -> 85 | E8: ='RESUMEN TOTAL'!B1 -> 364
A9: ='APAGADOS RADIO'!M2 -> 44600 | B9: ='APAGADOS RADIO'!M1 -> 28 | C9: ='APAGADOS FIBRA'!M1 -> 52 | D9: =B9+C9 -> 80 | E9: ='RESUMEN TOTAL'!B1 -> 364
A10: ='APAGADOS RADIO'!N2 -> 44601 | B10: ='APAGADOS RADIO'!N1 -> 31 | C10: ='APAGADOS FIBRA'!N1 -> 50 | D10: =B10+C10 -> 81 | E10: ='RESUMEN TOTAL'!B1 -> 364
A11: ='APAGADOS RADIO'!O2 -> 44602 | B11: ='APAGADOS RADIO'!O1 -> 31 | C11: ='APAGADOS FIBRA'!O1 -> 50 | D11: =B11+C11 -> 81 | E11: ='RESUMEN TOTAL'!B1 -> 364
A12: ='APAGADOS RADIO'!P2 -> 44603 | B12: ='APAGADOS RADIO'!P1 -> 0 | C12: ='APAGADOS FIBRA'!P1 -> 0 | D12: =B12+C12 -> 0 | E12: ='RESUMEN TOTAL'!B1 -> 364
A13: ='APAGADOS RADIO'!Q2 -> 44604 | B13: ='APAGADOS RADIO'!Q1 -> 0 | C13: ='APAGADOS FIBRA'!Q1 -> 0 | D13: =B13+C13 -> 0 | E13: ='RESUMEN TOTAL'!B1 -> 364
A14: ='APAGADOS RADIO'!R2 -> 44605 | B14: ='APAGADOS RADIO'!R1 -> 0 | C14: ='APAGADOS FIBRA'!R1 -> 0 | D14: =B14+C14 -> 0 | E14: ='RESUMEN TOTAL'!B1 -> 364
A15: ='APAGADOS RADIO'!S2 -> 44606 | B15: ='APAGADOS RADIO'!S1 -> 0 | C15: ='APAGADOS FIBRA'!S1 -> 0 | D15: =B15+C15 -> 0 | E15: ='RESUMEN TOTAL'!B1 -> 364
A16: ='APAGADOS RADIO'!T2 -> 44607 | B16: ='APAGADOS RADIO'!T1 -> 0 | C16: ='APAGADOS FIBRA'!T1 -> 0 | D16: =B16+C16 -> 0 | E16: ='RESUMEN TOTAL'!B1 -> 364
A17: ='APAGADOS RADIO'!U2 -> 44608 | B17: ='APAGADOS RADIO'!U1 -> 0 | C17: ='APAGADOS FIBRA'!U1 -> 0 | D17: =B17+C17 -> 0 | E17: ='RESUMEN TOTAL'!B1 -> 364
A18: ='APAGADOS RADIO'!V2 -> 44609 | B18: ='APAGADOS RADIO'!V1 -> 0 | C18: ='APAGADOS FIBRA'!V1 -> 0 | D18: =B18+C18 -> 0 | E18: ='RESUMEN TOTAL'!B1 -> 364
A19: ='APAGADOS RADIO'!W2 -> 44610 | B19: ='APAGADOS RADIO'!W1 -> 0 | C19: ='APAGADOS FIBRA'!W1 -> 0 | D19: =B19+C19 -> 0 | E19: ='RESUMEN TOTAL'!B1 -> 364
A20: ='APAGADOS RADIO'!X2 -> 44611 | B20: ='APAGADOS RADIO'!X1 -> 0 | C20: ='APAGADOS FIBRA'!X1 -> 0 | D20: =B20+C20 -> 0 | E20: ='RESUMEN TOTAL'!B1 -> 364
A21: ='APAGADOS RADIO'!Y2 -> 44612 | B21: ='APAGADOS RADIO'!Y1 -> 0 | C21: ='APAGADOS FIBRA'!Y1 -> 0 | D21: =B21+C21 -> 0 | E21: ='RESUMEN TOTAL'!B1 -> 364
A22: ='APAGADOS RADIO'!Z2 -> 44613 | B22: ='APAGADOS RADIO'!Z1 -> 0 | C22: ='APAGADOS FIBRA'!Z1 -> 0 | D22: =B22+C22 -> 0 | E22: ='RESUMEN TOTAL'!B1 -> 364
A23: ='APAGADOS RADIO'!AA2 -> 44614 | B23: ='APAGADOS RADIO'!AA1 -> 0 | C23: ='APAGADOS FIBRA'!AA1 -> 0 | D23: =B23+C23 -> 0 | E23: ='RESUMEN TOTAL'!B1 -> 364
A24: ='APAGADOS RADIO'!AB2 -> 44615 | B24: ='APAGADOS RADIO'!AB1 -> 0 | C24: ='APAGADOS FIBRA'!AB1 -> 0 | D24: =B24+C24 -> 0 | E24: ='RESUMEN TOTAL'!B1 -> 364
A25: ='APAGADOS RADIO'!AC2 -> 44616 | B25: ='APAGADOS RADIO'!AC1 -> 0 | C25: ='APAGADOS FIBRA'!AC1 -> 0 | D25: =B25+C25 -> 0 | E25: ='RESUMEN TOTAL'!B1 -> 364
A26: ='APAGADOS RADIO'!AD2 -> 44617 | B26: ='APAGADOS RADIO'!AD1 -> 0 | C26: ='APAGADOS FIBRA'!AD1 -> 0 | D26: =B26+C26 -> 0 | E26: ='RESUMEN TOTAL'!B1 -> 364
A27: ='APAGADOS RADIO'!AE2 -> 44618 | B27: ='APAGADOS RADIO'!AE1 -> 0 | C27: ='APAGADOS FIBRA'!AE1 -> 0 | D27: =B27+C27 -> 0 | E27: ='RESUMEN TOTAL'!B1 -> 364
A28: ='APAGADOS RADIO'!AF2 -> 44619 | B28: ='APAGADOS RADIO'!AF1 -> 0 | C28: ='APAGADOS FIBRA'!AF1 -> 0 | D28: =B28+C28 -> 0 | E28: ='RESUMEN TOTAL'!B1 -> 364
A29: ='APAGADOS RADIO'!AG2 -> 44620 | B29: ='APAGADOS RADIO'!AG1 -> 0 | C29: ='APAGADOS FIBRA'!AG1 -> 0 | D29: =B29+C29 -> 0 | E29: ='RESUMEN TOTAL'!B1 -> 364
