Workbook
Name _25_de_agosto: 'RESUMEN TOTAL'!$A$4:$D$349

Sheet RESUMEN TOTAL
A1: CANTIDAD DE CAMARAS | C1: =COUNTA(C5:C527) -> 373 | D1: PORCIENTO DE CAIDAS | O1: =(O3)/(O2+O3) -> 0.10326087 | P1: =(P3)/(P2+P3) -> 0 | Q1: =(Q3)/(Q2+Q3) -> 0 | R1: =(R3)/(R2+R3) -> 0.097826087 | S1: =(S3)/(S2+S3) -> 0.08719346 | T1: =(T3)/(T2+T3) -> 0.067934783 | U1: =(U3)/(U2+U3) -> 0.092391304 | V1: =(V3)/(V2+V3) -> 0.067934783 | ... AR1: =(AR3)/(AR2+AR3) -> 0
D2: FUNCIONAN | O2: =COUNTIF(O5:O372, "") -> 330 | P2: =COUNTIF(P5:P372, "") -> 368 | Q2: =COUNTIF(Q5:Q372, "") -> 368 | R2: =COUNTIF(R5:R372, "") -> 332 | S2: =COUNTIF(S5:S372, "") -> 335 | T2: =COUNTIF(T5:T372, "") -> 343 | U2: =COUNTIF(U5:U372, "") -> 334 | V2: =COUNTIF(V5:V372, "") -> 343 | ... AR2: =COUNTIF(AR5:AR372, "") -> 368
D3: CAIDAS | O3: =COUNTIF(O4:O447, "apagado") -> 38 | P3: =COUNTIF(P4:P447, "apagado") -> 0 | Q3: =COUNTIF(Q4:Q447, "apagado") -> 0 | R3: =COUNTIF(R4:R447, "apagado") -> 36 | S3: =COUNTIF(S4:S447, "apagado") -> 32 | T3: =COUNTIF(T4:T447, "apagado") -> 25 | U3: =COUNTIF(U4:U447, "apagado") -> 34 | V3: =COUNTIF(V4:V447, "apagado") -> 25 | ... AR3: =COUNTIF(AR4:AR447, "apagado") -> 0
A4: Barrio | B4: a coseidi | C4: [Denominacion] | D4: [Ubicacion] | E4: [Tipo de Camara] | F4: [Tipo de Conexion] | G4: [Fundamento] | H4: [Detalle] | I4: Latitud | J4: Longitud | L4: DIAS FUNCIONANDO | M4: DIAS CAIDA | N4: EFECTIVIDAD | O4: 44652 | P4: 44653 | Q4: 44654 | R4: 44655 | S4: 44656 | T4: 44657 | U4: 44658 | V4: 44659 | W4: 44660 | X4: 44661 | Y4: 44662 | Z4: 44663 | AA4: 44664 | AB4: 44665 | AC4: 44666 | AD4: 44667 | AE4: 44668 | AF4: 44669 | AG4: 44670 | AH4: 44671 | AI4: 44672 | AJ4: 44673 | AK4: 44674 | AL4: 44675 | AM4: 44676 | AN4: 44677 | AO4: 44678 | AP4: 44679 | AQ4: 44680 | AR4: 44681
A5: PRESIDENTE PERON (PEPSI) | B5: 44629 | C5: MAR 01 | D5: RP36 Y LA ESMERALDA | E5: DOMO | F5: Fibra Optica | G5: POSIBLE VIA DE ESCAPE. FLUJO VEHICULAR | I5: -348296270000 | J5: -582165860000 | K5: 172.20.11.101 | L5: =COUNTIF(O5:AP5,"") -> 24 | M5: =COUNTIF(O5:AP5,"APAGADO") -> 4 | N5: =(L5)/(M5+L5) -> 0.85714286 | S5: APAGADO | V5: APAGADO | W5: APAGADO | X5: APAGADO
A6: MAYOL | C6: MAY 01 | D6: Eva Peron y Cabildo | E6: Domo | F6: Radio | G6: Flujo Vehicular, Futuro corredor escolar, Zona Comercial | I6: -348239900000 | J6: -582772350000 | K6: 172.20.200.194 | L6: =COUNTIF(O6:AP6,"") -> 27 | M6: =COUNTIF(O6:AP6,"APAGADO") -> 1 | N6: =(L6)/(M6+L6) -> 0.96428571 | Z6: APAGADO
C7: MAY 02 | D7: EVA PERON Y MONTEVIDEO | E7: Domo | F7: Radio | I7: -348218190000 | J7: -582771380000 | K7: 172.20.200.168 | L7: =COUNTIF(O7:AP7,"") -> 15 | M7: =COUNTIF(O7:AP7,"APAGADO") -> 13 | N7: =(L7)/(M7+L7) -> 0.53571429 | R7: APAGADO | S7: APAGADO | T7: APAGADO | U7: APAGADO | V7: APAGADO | W7: APAGADO | X7: APAGADO | Y7: APAGADO | Z7: APAGADO | AA7: APAGADO | AB7: APAGADO | AC7: APAGADO | AD7: APAGADO
A8: MAYOL | C8: MAY 03 | D8: CHAÑAR Y SAN NICOLAS | E8: DOMO | F8: PTP A FO | H8: ALTA 29/10/2019 | I8: -348230700000 | J8: -582702540000 | K8: 172.20.10.18 | L8: =COUNTIF(O8:AP8,"") -> 28 | M8: =COUNTIF(O8:AP8,"APAGADO") -> 0 | N8: =(L8)/(M8+L8) -> 1
C9: MAY 04 | D9: MAR CHIQUITA Y RIO JACHAL | E9: DOMO | F9: Radio | H9: 08/07/2020 COMIENZA A REPORTAR IMAGEN | I9: -348252070000 | J9: -582711820000 | K9: 10.20.30.34 | L9: =COUNTIF(O9:AP9,"") -> 28 | M9: =COUNTIF(O9:AP9,"APAGADO") -> 0 | N9: =(L9)/(M9+L9) -> 1
A10: ALTAMIRA | C10: ALT06 | D10: LOPE DE VEGA Y NECOCHEA | E10: Domo | F10: PTP A FO | H10: Instalada sin alta en sistema. ALTA en sistema y en funcionamiento 04/05/2020 | I10: -347738090000 | J10: -582721410000 | K10: 172.20.12.12 | L10: =COUNTIF(O10:AP10,"") -> 24 | M10: =COUNTIF(O10:AP10,"APAGADO") -> 4 | N10: =(L10)/(M10+L10) -> 0.85714286 | U10: APAGADO | V10: APAGADO | W10: APAGADO | AB10: APAGADO
A11: ALTAMIRA | C11: ALT01 | D11: Calchaqui y Sgto. Cabral | E11: Domo | F11: Fibra Optica | G11: Universidad, Zona Bancaria, Flujo Vehicular, Posible Via de Escape | I11: -347769580000 | J11: -582650900000 | K11: 172.20.10.6 | L11: =COUNTIF(O11:AP11,"") -> 27 | M11: =COUNTIF(O11:AP11,"APAGADO") -> 1 | N11: =(L11)/(M11+L11) -> 0.96428571 | AB11: APAGADO
A12: ALTAMIRA | C12: ALT02 | D12: Calchaqui y Lope de Vega | E12: Domo | F12: PTP A FO | G12: Hospital, Flujo Vehicular, Peatonal | I12: -347718470000 | J12: -582688560000 | K12: 172.20.12.218 | L12: =COUNTIF(O12:AP12,"") -> 27 | M12: =COUNTIF(O12:AP12,"APAGADO") -> 1 | N12: =(L12)/(M12+L12) -> 0.96428571 | AB12: APAGADO
A13: ALTAMIRA | B13: 44642 | C13: ALT03 | D13: Bombero Galarza y Necochea | E13: Domo | F13: Fibra Optica | G13: Hospital, Limite del Partido | I13: -347726570000 | J13: -582730620000 | K13: 172.20.12.54 | L13: =COUNTIF(O13:AP13,"") -> 27 | M13: =COUNTIF(O13:AP13,"APAGADO") -> 1 | N13: =(L13)/(M13+L13) -> 0.96428571 | AB13: APAGADO
B14: 44642 | C14: ALT04 | D14: Francia y Necochea | E14: Domo | F14: Fibra Optica | G14: Zona RecreaciÃ³n | I14: -347705420000 | J14: -582748000000 | K14: 172.20.12.55 | L14: =COUNTIF(O14:AP14,"") -> 27 | M14: =COUNTIF(O14:AP14,"APAGADO") -> 1 | N14: =(L14)/(M14+L14) -> 0.96428571 | AB14: APAGADO
A15: ALTAMIRA | C15: ALT05 | D15: Av. Calchaqui y Bombero Galarza | E15: Domo | F15: PTP A FO | G15: Zona Bancaria, Flujo Vehicular, Posible via de escape, Limite del partido | I15: -347708370000 | J15: -582698000000 | K15: 172.20.12.216 | L15: =COUNTIF(O15:AP15,"") -> 27 | M15: =COUNTIF(O15:AP15,"APAGADO") -> 1 | N15: =(L15)/(M15+L15) -> 0.96428571 | AB15: APAGADO
A16: ALTAMIRA | C16: ALT07 | D16: AV. CALCHAQUI Y AV. DEL TRABAJO | E16: DOMO | F16: PTP A FO | H16: SE DA DE ALTA EL 17/09/2020 18:51HS | I16: -347737570000 | J16: -582676650000 | K16: 172.20.10.57 | L16: =COUNTIF(O16:AP16,"") -> 27 | M16: =COUNTIF(O16:AP16,"APAGADO") -> 1 | N16: =(L16)/(M16+L16) -> 0.96428571 | AB16: APAGADO
A17: ALTAMIRA | B17: 44642 | C17: ALT08 | D17: HUMAITA Y NECOCHEA | E17: DOMO | F17: Fibra Optica | H17: REPORTA IMAGENES 20/08/2021 | I17: -347749440000 | J17: -582711610000 | K17: 172.20.11.215 | L17: =COUNTIF(O17:AP17,"") -> 27 | M17: =COUNTIF(O17:AP17,"APAGADO") -> 1 | N17: =(L17)/(M17+L17) -> 0.96428571 | AB17: APAGADO
A18: ALTAMIRA | B18: 44642 | C18: ALT09 | D18: NECOCHEA Y CURUPAITY | E18: DOMO | F18: Fibra Optica | H18: SE DA DE ALTA 25/08/2021 | I18: -347743740000 | J18: -582715650000 | K18: 172.20.11.216 | L18: =COUNTIF(O18:AP18,"") -> 27 | M18: =COUNTIF(O18:AP18,"APAGADO") -> 1 | N18: =(L18)/(M18+L18) -> 0.96428571 | AB18: APAGADO
A19: AGUSTIN RAMIREZ | C19: ARA01 | D19: Malambo y Tranquera | E19: Domo | F19: Fibra Optica | G19: Zona Escolar, Flujo Vehicular | I19: -347979380000 | J19: -583160950000 | K19: 172.20.12.110 | L19: =COUNTIF(O19:AP19,"") -> 28 | M19: =COUNTIF(O19:AP19,"APAGADO") -> 0 | N19: =(L19)/(M19+L19) -> 1
A20: ALTAMIRA | C20: ALT10 | D20: REP. FRANCIA Y CALCHAQUI (RP 36) | E20: DOMO | F20: PTP A FO | H20: SE DA DE ALTA 10/11/2021 | I20: -347689160000 | J20: -582717100000 | K20: 172.20.12.156 | L20: =COUNTIF(O20:AP20,"") -> 27 | M20: =COUNTIF(O20:AP20,"APAGADO") -> 1 | N20: =(L20)/(M20+L20) -> 0.96428571 | AB20: APAGADO
A21: BELGRANO | C21: BEL01 | D21: San Martin y Dardo Rocha | E21: DOMO | F21: Fibra Optica | G21: Zona Escolar, Flujo Vehicular | H21: 19/03/2020 SE RETIRO DISPOSITIVO POR RIESGO DE CAIDA. 19/08/2020 comenzo a funcionar. | I21: -347918370000 | J21: -582786080000 | K21: 172.20.12.64 | L21: =COUNTIF(O21:AP21,"") -> 23 | M21: =COUNTIF(O21:AP21,"APAGADO") -> 5 | N21: =(L21)/(M21+L21) -> 0.82142857 | U21: APAGADO | V21: APAGADO | W21: APAGADO | X21: APAGADO | Y21: APAGADO
C22: CEN51 | D22: ILLIA Y LAS HERAS | E22: FIJA | F22: Fibra Optica | G22: POSIBLE VIA DE ESCAPE, Y FLUJO VEHICULAR | I22: -347987830000 | J22: -582840920000 | K22: 172.20.11.29 | L22: =COUNTIF(O22:AP22,"") -> 25 | M22: =COUNTIF(O22:AP22,"APAGADO") -> 3 | N22: =(L22)/(M22+L22) -> 0.89285714 | U22: APAGADO | V22: APAGADO | W22: APAGADO
C23: CEN53 | D23: GUTIERREZ Y BROWN | E23: Domo | F23: Radio | I23: -348013650000 | J23: -582715700000 | K23: 172.20.200.166 | L23: =COUNTIF(O23:AP23,"") -> 28 | M23: =COUNTIF(O23:AP23,"APAGADO") -> 0 | N23: =(L23)/(M23+L23) -> 1
C24: CEN 54 | D24: GUTIERREZ Y PRINGLES | E24: Domo | F24: Radio | I24: -348013470000 | J24: -582698540000 | K24: 172.20.200.165 | L24: =COUNTIF(O24:AP24,"") -> 25 | M24: =COUNTIF(O24:AP24,"APAGADO") -> 3 | N24: =(L24)/(M24+L24) -> 0.89285714 | U24: APAGADO | Y24: APAGADO | AE24: APAGADO
C25: CEN 55 | D25: BOUREL Y URQUIZA | E25: Domo | F25: Radio | I25: -348019110000 | J25: -582819990000 | K25: 172.20.200.163 | L25: =COUNTIF(O25:AP25,"") -> 28 | M25: =COUNTIF(O25:AP25,"APAGADO") -> 0 | N25: =(L25)/(M25+L25) -> 1
A26: CENTRO | C26: CEN 56 | D26: Newbery y Falucho | E26: DOMO | F26: Radio | G26: Posible via de escape, Cruce Peligroso | I26: -348073990000 | J26: -582850080000 | K26: 172.20.200.161 | L26: =COUNTIF(O26:AP26,"") -> 28 | M26: =COUNTIF(O26:AP26,"APAGADO") -> 0 | N26: =(L26)/(M26+L26) -> 1
C27: CEN 57 | D27: 25 DE MAYO Y DORREGO | E27: DOMO | F27: Radio | I27: -348007360000 | J27: -582804240000 | K27: 172.20.200.199 | L27: =COUNTIF(O27:AP27,"") -> 28 | M27: =COUNTIF(O27:AP27,"APAGADO") -> 0 | N27: =(L27)/(M27+L27) -> 1
C28: CEN 58 | D28: EEUU Y MORENO | E28: DOMO | F28: Fibra Optica | H28: INSTALADA: 11/06/18. EN FUNCIONAMIENTO: 27/06/18. | I28: -348103030000 | J28: -582835720000 | K28: 172.20.11.84 | L28: =COUNTIF(O28:AP28,"") -> 28 | M28: =COUNTIF(O28:AP28,"APAGADO") -> 0 | N28: =(L28)/(M28+L28) -> 1
C29: CEN 59 | D29: CHACABUCO Y BOUREL | E29: DOMO | F29: Radio | H29: INSTALADA:11/06/18EN FUNCIONAMIENTO: 27/06/18 | I29: -348039300000 | J29: -582819780000 | K29: 172.20.200.188 | L29: =COUNTIF(O29:AP29,"") -> 28 | M29: =COUNTIF(O29:AP29,"APAGADO") -> 0 | N29: =(L29)/(M29+L29) -> 1
A30: CENTRO | C30: CEN 60 | D30: RECONQUISTA Y ILLIA | E30: DOMO | F30: PTP A FO | H30: ALTA 26/10/2019 | I30: -347999170000 | J30: -582863530000 | K30: 172.20.12.67 | L30: =COUNTIF(O30:AP30,"") -> 23 | M30: =COUNTIF(O30:AP30,"APAGADO") -> 5 | N30: =(L30)/(M30+L30) -> 0.82142857 | O30: APAGADO | R30: APAGADO | S30: APAGADO | T30: APAGADO | Y30: APAGADO
A31: CENTRO | C31: CEN 61 | D31: BOUREL Y MAIPU | E31: DOMO | F31: Radio | H31: ALTA EN FUNCIONAMIENTO 12/04/2019 | I31: -348040550000 | J31: -582819380000 | K31: 172.20.200.159 | L31: =COUNTIF(O31:AP31,"") -> 28 | M31: =COUNTIF(O31:AP31,"APAGADO") -> 0 | N31: =(L31)/(M31+L31) -> 1
A32: CENTRO | C32: CEN 62 | D32: ESPAÑA Y ALEM | E32: DOMO | F32: PTP A FO | H32: ALTA: 16/06/2020 | I32: -348038200000 | J32: -582766160000 | K32: 172.20.12.82 | L32: =COUNTIF(O32:AP32,"") -> 28 | M32: =COUNTIF(O32:AP32,"APAGADO") -> 0 | N32: =(L32)/(M32+L32) -> 1
A33: CENTRO | C33: CEN 63 | D33: SAN MARTIN Y URQUIZA | E33: DOMO | F33: Fibra Optica | H33: DADA DE ALTA ABRIL 2021 | I33: -348017700000 | J33: -582785020000 | K33: 172.20.11.112 | L33: =COUNTIF(O33:AP33,"") -> 28 | M33: =COUNTIF(O33:AP33,"APAGADO") -> 0 | N33: =(L33)/(M33+L33) -> 1
A34: CENTRO | C34: CEN 70 | D34: RIVADAVIA Y 25 MAYO | E34: Domo | F34: Fibra Optica | H34: alta en sistema 25/11/2021 | I34: -348091950000 | J34: -582800930000 | K34: 172.20.11.221 | L34: =COUNTIF(O34:AP34,"") -> 28 | M34: =COUNTIF(O34:AP34,"APAGADO") -> 0 | N34: =(L34)/(M34+L34) -> 1
A35: CENTRO | C35: CEN 71 | D35: MORENO Y BOUREL | E35: Domo | F35: Fibra Optica | H35: alta en sistema 25/11/2021 | I35: -348103130000 | J35: -582818230000 | K35: 172.20.11.220 | L35: =COUNTIF(O35:AP35,"") -> 28 | M35: =COUNTIF(O35:AP35,"APAGADO") -> 0 | N35: =(L35)/(M35+L35) -> 1
A36: CENTRO | C36: CEN 72 | D36: MORENO Y 25 DE MAYO | E36: Domo | F36: Fibra Optica | H36: ALTA EN SISTEMA 25/11/2021 | I36: -348102250000 | J36: -582800780000 | K36: 172.20.11.219 | L36: =COUNTIF(O36:AP36,"") -> 28 | M36: =COUNTIF(O36:AP36,"APAGADO") -> 0 | N36: =(L36)/(M36+L36) -> 1
A37: CENTRO | C37: CEN01 | D37: San Martin y 9 de Julio | E37: Fija | F37: Fibra Optica | G37: Zona Comercial, Flujo Vehicular | I37: -348028100000 | J37: -582782860000 | K37: 172.20.11.10 | L37: =COUNTIF(O37:AP37,"") -> 28 | M37: =COUNTIF(O37:AP37,"APAGADO") -> 0 | N37: =(L37)/(M37+L37) -> 1
A38: CENTRO | C38: CEN02 | D38: San Martin y Almafuerte | E38: Fija | F38: Fibra Optica | G38: Bomberos, Flujo Vehicular, Zona Comercial | I38: -348006070000 | J38: -582784580000 | K38: 172.20.11.11 | L38: =COUNTIF(O38:AP38,"") -> 28 | M38: =COUNTIF(O38:AP38,"APAGADO") -> 0 | N38: =(L38)/(M38+L38) -> 1
A39: CENTRO | C39: CEN03 | D39: San Martin y Sallares | E39: Domo | F39: Fibra Optica | G39: Zona Comercial, Flujo Vehicular | H39: 29/03/19 FUNCIONA EN COD 1 | I39: -348080340000 | J39: -582780930000 | K39: 172.20.12.30 | L39: =COUNTIF(O39:AP39,"") -> 27 | M39: =COUNTIF(O39:AP39,"APAGADO") -> 1 | N39: =(L39)/(M39+L39) -> 0.96428571 | Y39: APAGADO
A40: CENTRO | C40: CEN04 | D40: San Martin y Contreras | E40: Domo | F40: Fibra Optica | G40: Zona de recreaciÃ³n, Flujo vehicular | I40: -348049240000 | J40: -582781680000 | K40: 172.20.12.29 | L40: =COUNTIF(O40:AP40,"") -> 28 | M40: =COUNTIF(O40:AP40,"APAGADO") -> 0 | N40: =(L40)/(M40+L40) -> 1
...

Sheet coseidi
B1: Barrio | C1: [Denominacion] | D1: [Ubicacion] | E1: [Tipo de Camara] | F1: [Tipo de Conexion] | G1: 44651
A2: 1 | B2: LOPEZ ROMERO | C2: LRO05 | D2: Calchaqui y Las Americas | E2: Fija | F2: Fibra Optica | G2: APAGADO | H2: 172.20.10.05
A3: 2 | B3: PRESIDENTE SARMIENTO | C3: LRO02 | D3: H. Irigoyen e Islas Orcadas | E3: Domo | F3: Fibra Optica | G3: APAGADO | H3: 172.20.10.40
A4: 3 | B4: SAN EMILIO | C4: MFI03 | D4: Cno. Gral. Belgrano y Av. del Trabajo | E4: Domo | F4: Fibra Optica | G4: APAGADO | H4: 172.20.10.32
A5: 4 | B5: SAN EMILIO | C5: MFI06 | D5: Con. Gral. Belgrano y Bombero Galarza | E5: DOMO | F5: Fibra Optica | G5: APAGADO | H5: 172.20.10.42
A6: 5 | B6: EL PARQUE | C6: PUNTO SEGURO - EL PARQUE (domo) | D6: CALLE 1282 Y 1201 | E6: DOMO | F6: Fibra Optica | G6: APAGADO | H6: 172.20.12.139
A7: 6 | B7: SAN RUDECINDO | C7: PUNTO SEGURO - SAN RUDECINDO (domo) | D7: SANTA SOFIA Y ALVAR NUÃ‘EZ | E7: DOMO | F7: Fibra Optica | G7: APAGADO | H7: 172.20.12.105
A8: 7 | B8: SAN RUDECINDO | C8: PUNTO SEGURO - SAN RUDECINDO (fija) | D8: SANTA SOFIA Y ALVAR NUÃ‘EZ | E8: Fija | F8: Fibra Optica | G8: APAGADO | H8: 172.20.12.106
A9: 8 | B9: VILLA ANGELICA | C9: VANG04 | D9: Storni e/Thevenet y Calle 158 | E9: DOMO | F9: Fibra Optica | G9: APAGADO | H9: 172.20.12.22
A10: 9 | B10: VILLA ANGELICA | C10: VANG05 | D10: Storni y Thevenet | E10: Domo | F10: Fibra Optica | G10: APAGADO | H10: 172.20.12.21
A11: 10 | B11: VILLA ANGELICA | C11: VANG06 | D11: Arenales e/Thevenet y Calle 158 | E11: DOMO | F11: Fibra Optica | G11: APAGADO | H11: 172.20.12.23
A12: 11 | B12: VILLA ANGELICA | C12: VANG07 | D12: Arenales y Thevenet | E12: Domo | F12: Fibra Optica | G12: APAGADO | H12: 172.20.12.24
A13: 12 | B13: VILLA ANGELICA | C13: VANG08 | D13: Calle 158 al 2200 | E13: Domo | F13: PTP A FO | G13: APAGADO | H13: 172.20.12.220

Sheet REPARACIONES DIARIAS
A1: REPARADOS POR DIA
A3: 44652
A4: 44653
A5: 44654
A6: 44655
A7: 44656
A8: 44657
A9: 44658
A10: 44659
A11: 44660
A12: 44661
A13: 44662
A14: 44663
... A32: 44681

Sheet ESTADISTICA
A1: ='RESUMEN TOTAL'!A4 -> Barrio | B1: ='RESUMEN TOTAL'!C4 -> [Denominacion] | C1: ='RESUMEN TOTAL'!D4 -> [Ubicacion] | D1: ='RESUMEN TOTAL'!E4 -> [Tipo de Camara] | E1: ='RESUMEN TOTAL'!F4 -> [Tipo de Conexion] | F1: ='RESUMEN TOTAL'!O4 -> 44652 | G1: ='RESUMEN TOTAL'!P4 -> 44653 | H1: ='RESUMEN TOTAL'!Q4 -> 44654 | I1: ='RESUMEN TOTAL'!R4 -> 44655 | J1: ='RESUMEN TOTAL'!S4 -> 44656 | K1: ='RESUMEN TOTAL'!T4 -> 44657 | L1: ='RESUMEN TOTAL'!U4 -> 44658 | M1: ='RESUMEN TOTAL'!V4 -> 44659 | ... AI1: ='RESUMEN TOTAL'!AR4 -> 44681 | AJ1: ='RESUMEN TOTAL'!#REF! -> #REF!
A2: ='RESUMEN TOTAL'!A5 -> PRESIDENTE PERON (PEPSI) | B2: ='RESUMEN TOTAL'!C5 -> MAR 01 | C2: ='RESUMEN TOTAL'!D5 -> RP36 Y LA ESMERALDA | D2: ='RESUMEN TOTAL'!E5 -> DOMO | E2: ='RESUMEN TOTAL'!F5 -> Fibra Optica | F2: ='RESUMEN TOTAL'!O5 -> 0 | G2: ='RESUMEN TOTAL'!P5 -> 0 | H2: ='RESUMEN TOTAL'!Q5 -> 0 | I2: ='RESUMEN TOTAL'!R5 -> 0 | J2: ='RESUMEN TOTAL'!S5 -> APAGADO | K2: ='RESUMEN TOTAL'!T5 -> 0 | L2: ='RESUMEN TOTAL'!U5 -> 0 | M2: ='RESUMEN TOTAL'!V5 -> APAGADO | ... AI2: ='RESUMEN TOTAL'!AR5 -> 0 | AJ2: ='RESUMEN TOTAL'!#REF! -> #REF!
A3: ='RESUMEN TOTAL'!A6 -> MAYOL | B3: ='RESUMEN TOTAL'!C6 -> MAY 01 | C3: ='RESUMEN TOTAL'!D6 -> Eva Peron y Cabildo | D3: ='RESUMEN TOTAL'!E6 -> Domo | E3: ='RESUMEN TOTAL'!F6 -> Radio | F3: ='RESUMEN TOTAL'!O6 -> 0 | G3: ='RESUMEN TOTAL'!P6 -> 0 | H3: ='RESUMEN TOTAL'!Q6 -> 0 | I3: ='RESUMEN TOTAL'!R6 -> 0 | J3: ='RESUMEN TOTAL'!S6 -> 0 | K3: ='RESUMEN TOTAL'!T6 -> 0 | L3: ='RESUMEN TOTAL'!U6 -> 0 | M3: ='RESUMEN TOTAL'!V6 -> 0 | ... AI3: ='RESUMEN TOTAL'!AR6 -> 0 | AJ3: ='RESUMEN TOTAL'!#REF! -> #REF!
A4: ='RESUMEN TOTAL'!A7 -> 0 | B4: ='RESUMEN TOTAL'!C7 -> MAY 02 | C4: ='RESUMEN TOTAL'!D7 -> EVA PERON Y MONTEVIDEO | D4: ='RESUMEN TOTAL'!E7 -> Domo | E4: ='RESUMEN TOTAL'!F7 -> Radio | F4: ='RESUMEN TOTAL'!O7 -> 0 | G4: ='RESUMEN TOTAL'!P7 -> 0 | H4: ='RESUMEN TOTAL'!Q7 -> 0 | I4: ='RESUMEN TOTAL'!R7 -> APAGADO | J4: ='RESUMEN TOTAL'!S7 -> APAGADO | K4: ='RESUMEN TOTAL'!T7 -> APAGADO | L4: ='RESUMEN TOTAL'!U7 -> APAGADO | M4: ='RESUMEN TOTAL'!V7 -> APAGADO | ... AI4: ='RESUMEN TOTAL'!AR7 -> 0 | AJ4: ='RESUMEN TOTAL'!#REF! -> #REF!
A5: ='RESUMEN TOTAL'!A8 -> MAYOL | B5: ='RESUMEN TOTAL'!C8 -> MAY 03 | C5: ='RESUMEN TOTAL'!D8 -> CHAÑAR Y SAN NICOLAS | D5: ='RESUMEN TOTAL'!E8 -> DOMO | E5: ='RESUMEN TOTAL'!F8 -> PTP A FO | F5: ='RESUMEN TOTAL'!O8 -> 0 | G5: ='RESUMEN TOTAL'!P8 -> 0 | H5: ='RESUMEN TOTAL'!Q8 -> 0 | I5: ='RESUMEN TOTAL'!R8 -> 0 | J5: ='RESUMEN TOTAL'!S8 -> 0 | K5: ='RESUMEN TOTAL'!T8 -> 0 | L5: ='RESUMEN TOTAL'!U8 -> 0 | M5: ='RESUMEN TOTAL'!V8 -> 0 | ... AI5: ='RESUMEN TOTAL'!AR8 -> 0 | AJ5: ='RESUMEN TOTAL'!#REF! -> #REF!
A6: ='RESUMEN TOTAL'!A9 -> 0 | B6: ='RESUMEN TOTAL'!C9 -> MAY 04 | C6: ='RESUMEN TOTAL'!D9 -> MAR CHIQUITA Y RIO JACHAL | D6: ='RESUMEN TOTAL'!E9 -> DOMO | E6: ='RESUMEN TOTAL'!F9 -> Radio | F6: ='RESUMEN TOTAL'!O9 -> 0 | G6: ='RESUMEN TOTAL'!P9 -> 0 | H6: ='RESUMEN TOTAL'!Q9 -> 0 | I6: ='RESUMEN TOTAL'!R9 -> 0 | J6: ='RESUMEN TOTAL'!S9 -> 0 | K6: ='RESUMEN TOTAL'!T9 -> 0 | L6: ='RESUMEN TOTAL'!U9 -> 0 | M6: ='RESUMEN TOTAL'!V9 -> 0 | ... AI6: ='RESUMEN TOTAL'!AR9 -> 0 | AJ6: ='RESUMEN TOTAL'!#REF! -> #REF!
A7: ='RESUMEN TOTAL'!A10 -> ALTAMIRA | B7: ='RESUMEN TOTAL'!C10 -> ALT06 | C7: ='RESUMEN TOTAL'!D10 -> LOPE DE VEGA Y NECOCHEA | D7: ='RESUMEN TOTAL'!E10 -> Domo | E7: ='RESUMEN TOTAL'!F10 -> PTP A FO | F7: ='RESUMEN TOTAL'!O10 -> 0 | G7: ='RESUMEN TOTAL'!P10 -> 0 | H7: ='RESUMEN TOTAL'!Q10 -> 0 | I7: ='RESUMEN TOTAL'!R10 -> 0 | J7: ='RESUMEN TOTAL'!S10 -> 0 | K7: ='RESUMEN TOTAL'!T10 -> 0 | L7: ='RESUMEN TOTAL'!U10 -> APAGADO | M7: ='RESUMEN TOTAL'!V10 -> APAGADO | ... AI7: ='RESUMEN TOTAL'!AR10 -> 0 | AJ7: ='RESUMEN TOTAL'!#REF! -> #REF!
A8: ='RESUMEN TOTAL'!A11 -> ALTAMIRA | B8: ='RESUMEN TOTAL'!C11 -> ALT01 | C8: ='RESUMEN TOTAL'!D11 -> Calchaqui y Sgto. Cabral | D8: ='RESUMEN TOTAL'!E11 -> Domo | E8: ='RESUMEN TOTAL'!F11 -> Fibra Optica | F8: ='RESUMEN TOTAL'!O11 -> 0 | G8: ='RESUMEN TOTAL'!P11 -> 0 | H8: ='RESUMEN TOTAL'!Q11 -> 0 | I8: ='RESUMEN TOTAL'!R11 -> 0 | J8: ='RESUMEN TOTAL'!S11 -> 0 | K8: ='RESUMEN TOTAL'!T11 -> 0 | L8: ='RESUMEN TOTAL'!U11 -> 0 | M8: ='RESUMEN TOTAL'!V11 -> 0 | ... AI8: ='RESUMEN TOTAL'!AR11 -> 0 | AJ8: ='RESUMEN TOTAL'!#REF! -> #REF!
A9: ='RESUMEN TOTAL'!A12 -> ALTAMIRA | B9: ='RESUMEN TOTAL'!C12 -> ALT02 | C9: ='RESUMEN TOTAL'!D12 -> Calchaqui y Lope de Vega | D9: ='RESUMEN TOTAL'!E12 -> Domo | E9: ='RESUMEN TOTAL'!F12 -> PTP A FO | F9: ='RESUMEN TOTAL'!O12 -> 0 | G9: ='RESUMEN TOTAL'!P12 -> 0 | H9: ='RESUMEN TOTAL'!Q12 -> 0 | I9: ='RESUMEN TOTAL'!R12 -> 0 | J9: ='RESUMEN TOTAL'!S12 -> 0 | K9: ='RESUMEN TOTAL'!T12 -> 0 | L9: ='RESUMEN TOTAL'!U12 -> 0 | M9: ='RESUMEN TOTAL'!V12 -> 0 | ... AI9: ='RESUMEN TOTAL'!AR12 -> 0 | AJ9: ='RESUMEN TOTAL'!#REF! -> #REF!
A10: ='RESUMEN TOTAL'!A13 -> ALTAMIRA | B10: ='RESUMEN TOTAL'!C13 -> ALT03 | C10: ='RESUMEN TOTAL'!D13 -> Bombero Galarza y Necochea | D10: ='RESUMEN TOTAL'!E13 -> Domo | E10: ='RESUMEN TOTAL'!F13 -> Fibra Optica | F10: ='RESUMEN TOTAL'!O13 -> 0 | G10: ='RESUMEN TOTAL'!P13 -> 0 | H10: ='RESUMEN TOTAL'!Q13 -> 0 | I10: ='RESUMEN TOTAL'!R13 -> 0 | J10: ='RESUMEN TOTAL'!S13 -> 0 | K10: ='RESUMEN TOTAL'!T13 -> 0 | L10: ='RESUMEN TOTAL'!U13 -> 0 | M10: ='RESUMEN TOTAL'!V13 -> 0 | ... AI10: ='RESUMEN TOTAL'!AR13 -> 0 | AJ10: ='RESUMEN TOTAL'!#REF! -> #REF!
A11: ='RESUMEN TOTAL'!A14 -> 0 | B11: ='RESUMEN TOTAL'!C14 -> ALT04 | C11: ='RESUMEN TOTAL'!D14 -> Francia y Necochea | D11: ='RESUMEN TOTAL'!E14 -> Domo | E11: ='RESUMEN TOTAL'!F14 -> Fibra Optica | F11: ='RESUMEN TOTAL'!O14 -> 0 | G11: ='RESUMEN TOTAL'!P14 -> 0 | H11: ='RESUMEN TOTAL'!Q14 -> 0 | I11: ='RESUMEN TOTAL'!R14 -> 0 | J11: ='RESUMEN TOTAL'!S14 -> 0 | K11: ='RESUMEN TOTAL'!T14 -> 0 | L11: ='RESUMEN TOTAL'!U14 -> 0 | M11: ='RESUMEN TOTAL'!V14 -> 0 | ... AI11: ='RESUMEN TOTAL'!AR14 -> 0 | AJ11: ='RESUMEN TOTAL'!#REF! -> #REF!
A12: ='RESUMEN TOTAL'!A15 -> ALTAMIRA | B12: ='RESUMEN TOTAL'!C15 -> ALT05 | C12: ='RESUMEN TOTAL'!D15 -> Av. Calchaqui y Bombero Galarza | D12: ='RESUMEN TOTAL'!E15 -> Domo | E12: ='RESUMEN TOTAL'!F15 -> PTP A FO | F12: ='RESUMEN TOTAL'!O15 -> 0 | G12: ='RESUMEN TOTAL'!P15 -> 0 | H12: ='RESUMEN TOTAL'!Q15 -> 0 | I12: ='RESUMEN TOTAL'!R15 -> 0 | J12: ='RESUMEN TOTAL'!S15 -> 0 | K12: ='RESUMEN TOTAL'!T15 -> 0 | L12: ='RESUMEN TOTAL'!U15 -> 0 | M12: ='RESUMEN TOTAL'!V15 -> 0 | ... AI12: ='RESUMEN TOTAL'!AR15 -> 0 | AJ12: ='RESUMEN TOTAL'!#REF! -> #REF!
... A374: ='RESUMEN TOTAL'!A377 -> CENTRO | B374: ='RESUMEN TOTAL'!C377 -> CEN75 | C374: ='RESUMEN TOTAL'!D377 -> CASTELLI Y 25 DE MAYO | D374: ='RESUMEN TOTAL'!E377 -> DOMO | E374: ='RESUMEN TOTAL'!F377 -> Fibra Optica | F374: ='RESUMEN TOTAL'!O377 -> 0 | G374: ='RESUMEN TOTAL'!P377 -> 0 | H374: ='RESUMEN TOTAL'!Q377 -> 0 | I374: ='RESUMEN TOTAL'!R377 -> 0 | J374: ='RESUMEN TOTAL'!S377 -> 0 | K374: ='RESUMEN TOTAL'!T377 -> 0 | L374: ='RESUMEN TOTAL'!U377 -> 0 | M374: ='RESUMEN TOTAL'!V377 -> 0 | ... AI374: ='RESUMEN TOTAL'!AR377 -> 0 | AJ374: ='RESUMEN TOTAL'!#REF! -> #REF!

Sheet APAGADOS
E1: APAGADOS | F1: =COUNTIF(F3:F366, "APAGADO") -> 38 | G1: =COUNTIF(G3:G366, "APAGADO") -> 0 | H1: =COUNTIF(H3:H366, "APAGADO") -> 0 | I1: =COUNTIF(I3:I366, "APAGADO") -> 36 | J1: =COUNTIF(J3:J366, "APAGADO") -> 32 | K1: =COUNTIF(K3:K366, "APAGADO") -> 25 | L1: =COUNTIF(L3:L366, "APAGADO") -> 34 | M1: =COUNTIF(M3:M366, "APAGADO") -> 25 | ... V1: =COUNTIF(V3:V366, "APAGADO") -> 26 | W1: =COUNTIF(W3:W447, "APAGADO") -> 0 | X1: =COUNTIF(X3:X366, "APAGADO") -> 0 | Y1: =COUNTIF(Y3:Y366, "APAGADO") -> 0 | Z1: =COUNTIF(Z3:Z366, "APAGADO") -> 0 | AA1: =COUNTIF(AA3:AA366, "APAGADO") -> 0 | AB1: =COUNTIF(AB3:AB366, "APAGADO") -> 0 | AC1: =COUNTIF(AC3:AC366, "APAGADO") -> 0 | AD1: =COUNTIF(AD3:AD366, "APAGADO") -> 0 | AE1: =COUNTIF(AE3:AE366, "APAGADO") -> 0 | ... AG1: =COUNTIF(AG3:AG366, "APAGADO") -> 0
A2: =ESTADISTICA!A1 -> Barrio | B2: =ESTADISTICA!B1 -> [Denominacion] | C2: =ESTADISTICA!C1 -> [Ubicacion] | D2: =ESTADISTICA!D1 -> [Tipo de Camara] | E2: =ESTADISTICA!E1 -> [Tipo de Conexion] | F2: =ESTADISTICA!F1 -> 44652 | G2: =ESTADISTICA!G1 -> 44653 | H2: =ESTADISTICA!H1 -> 44654 | ... AG2: =ESTADISTICA!AG1 -> 44679
A3: =ESTADISTICA!A2 -> PRESIDENTE PERON (PEPSI) | B3: =ESTADISTICA!B2 -> MAR 01 | C3: =ESTADISTICA!C2 -> RP36 Y LA ESMERALDA | D3: =ESTADISTICA!D2 -> DOMO | E3: =ESTADISTICA!E2 -> Fibra Optica | F3: =ESTADISTICA!F2 -> 0 | G3: =ESTADISTICA!G2 -> 0 | H3: =ESTADISTICA!H2 -> 0 | ... AG3: =ESTADISTICA!AG2 -> 0
A4: =ESTADISTICA!A3 -> MAYOL | B4: =ESTADISTICA!B3 -> MAY 01 | C4: =ESTADISTICA!C3 -> Eva Peron y Cabildo | D4: =ESTADISTICA!D3 -> Domo | E4: =ESTADISTICA!E3 -> Radio | F4: =ESTADISTICA!F3 -> 0 | G4: =ESTADISTICA!G3 -> 0 | H4: =ESTADISTICA!H3 -> 0 | ... AG4: =ESTADISTICA!AG3 -> 0
A5: =ESTADISTICA!A4 -> 0 | B5: =ESTADISTICA!B4 -> MAY 02 | C5: =ESTADISTICA!C4 -> EVA PERON Y MONTEVIDEO | D5: =ESTADISTICA!D4 -> Domo | E5: =ESTADISTICA!E4 -> Radio | F5: =ESTADISTICA!F4 -> 0 | G5: =ESTADISTICA!G4 -> 0 | H5: =ESTADISTICA!H4 -> 0 | ... AG5: =ESTADISTICA!AG4 -> 0
A6: =ESTADISTICA!A5 -> MAYOL | B6: =ESTADISTICA!B5 -> MAY 03 | C6: =ESTADISTICA!C5 -> CHAÑAR Y SAN NICOLAS | D6: =ESTADISTICA!D5 -> DOMO | E6: =ESTADISTICA!E5 -> PTP A FO | F6: =ESTADISTICA!F5 -> 0 | G6: =ESTADISTICA!G5 -> 0 | H6: =ESTADISTICA!H5 -> 0 | ... AG6: =ESTADISTICA!AG5 -> 0
A7: =ESTADISTICA!A6 -> 0 | B7: =ESTADISTICA!B6 -> MAY 04 | C7: =ESTADISTICA!C6 -> MAR CHIQUITA Y RIO JACHAL | D7: =ESTADISTICA!D6 -> DOMO | E7: =ESTADISTICA!E6 -> Radio | F7: =ESTADISTICA!F6 -> 0 | G7: =ESTADISTICA!G6 -> 0 | H7: =ESTADISTICA!H6 -> 0 | ... AG7: =ESTADISTICA!AG6 -> 0
A8: =ESTADISTICA!A7 -> ALTAMIRA | B8: =ESTADISTICA!B7 -> ALT06 | C8: =ESTADISTICA!C7 -> LOPE DE VEGA Y NECOCHEA | D8: =ESTADISTICA!D7 -> Domo | E8: =ESTADISTICA!E7 -> PTP A FO | F8: =ESTADISTICA!F7 -> 0 | G8: =ESTADISTICA!G7 -> 0 | H8: =ESTADISTICA!H7 -> 0 | ... AG8: =ESTADISTICA!AG7 -> 0
A9: =ESTADISTICA!A8 -> ALTAMIRA | B9: =ESTADISTICA!B8 -> ALT01 | C9: =ESTADISTICA!C8 -> Calchaqui y Sgto. Cabral | D9: =ESTADISTICA!D8 -> Domo | E9: =ESTADISTICA!E8 -> Fibra Optica | F9: =ESTADISTICA!F8 -> 0 | G9: =ESTADISTICA!G8 -> 0 | H9: =ESTADISTICA!H8 -> 0 | ... AG9: =ESTADISTICA!AG8 -> 0
A10: =ESTADISTICA!A9 -> ALTAMIRA | B10: =ESTADISTICA!B9 -> ALT02 | C10: =ESTADISTICA!C9 -> Calchaqui y Lope de Vega | D10: =ESTADISTICA!D9 -> Domo | E10: =ESTADISTICA!E9 -> PTP A FO | F10: =ESTADISTICA!F9 -> 0 | G10: =ESTADISTICA!G9 -> 0 | H10: =ESTADISTICA!H9 -> 0 | ... AG10: =ESTADISTICA!AG9 -> 0
A11: =ESTADISTICA!A10 -> ALTAMIRA | B11: =ESTADISTICA!B10 -> ALT03 | C11: =ESTADISTICA!C10 -> Bombero Galarza y Necochea | D11: =ESTADISTICA!D10 -> Domo | E11: =ESTADISTICA!E10 -> Fibra Optica | F11: =ESTADISTICA!F10 -> 0 | G11: =ESTADISTICA!G10 -> 0 | H11: =ESTADISTICA!H10 -> 0 | ... AG11: =ESTADISTICA!AG10 -> 0
A12: =ESTADISTICA!A11 -> 0 | B12: =ESTADISTICA!B11 -> ALT04 | C12: =ESTADISTICA!C11 -> Francia y Necochea | D12: =ESTADISTICA!D11 -> Domo | E12: =ESTADISTICA!E11 -> Fibra Optica | F12: =ESTADISTICA!F11 -> 0 | G12: =ESTADISTICA!G11 -> 0 | H12: =ESTADISTICA!H11 -> 0 | ... AG12: =ESTADISTICA!AG11 -> 0
A13: =ESTADISTICA!A12 -> ALTAMIRA | B13: =ESTADISTICA!B12 -> ALT05 | C13: =ESTADISTICA!C12 -> Av. Calchaqui y Bombero Galarza | D13: =ESTADISTICA!D12 -> Domo | E13: =ESTADISTICA!E12 -> PTP A FO | F13: =ESTADISTICA!F12 -> 0 | G13: =ESTADISTICA!G12 -> 0 | H13: =ESTADISTICA!H12 -> 0 | ... AG13: =ESTADISTICA!AG12 -> 0
... A379: =ESTADISTICA!A378 -> 0 | B379: =ESTADISTICA!B378 -> 0 | C379: =ESTADISTICA!C378 -> 0 | D379: =ESTADISTICA!D378 -> 0 | E379: =ESTADISTICA!E378 -> 0 | F379: =ESTADISTICA!F378 -> 0 | G379: =ESTADISTICA!G378 -> 0 | H379: =ESTADISTICA!H378 -> 0 | ... AG379: =ESTADISTICA!AG378 -> 0

Sheet APAGADOS FIBRA
C1: TOTAL FIBRA | D1: =COUNTIFS(E4:E369,"=Fibra Optica") -> 237
E2: APAGADOS | F2: =COUNTIFS(F4:F367, "=APAGADO",E4:E367,"=Fibra Optica") -> 30 | G2: =COUNTIFS(G4:G367, "=APAGADO",E4:E367,"=Fibra Optica") -> 0 | H2: =COUNTIFS(H4:H367, "=APAGADO",E4:E367,"=Fibra Optica") -> 0 | I2: =COUNTIFS(I4:I367, "=APAGADO",E4:E367,"=Fibra Optica") -> 29 | J2: =COUNTIFS(J4:J367, "=APAGADO",E4:E367,"=Fibra Optica") -> 26 | K2: =COUNTIFS(K4:K367, "=APAGADO",E4:E367,"=Fibra Optica") -> 20 | L2: =COUNTIFS(L4:L367, "=APAGADO",E4:E367,"=Fibra Optica") -> 24 | M2: =COUNTIFS(M4:M367, "=APAGADO",E4:E367,"=Fibra Optica") -> 18 | N2: =COUNTIFS(N4:N367, "=APAGADO",E4:E367,"=Fibra Optica") -> 17 | O2: =COUNTIFS(O4:O367, "=APAGADO",E4:E367,"=Fibra Optica") -> 17 | P2: =COUNTIFS(P4:P367, "=APAGADO",E4:E367,"=Fibra Optica") -> 36 | Q2: =COUNTIFS(Q4:Q367, "=APAGADO",E4:E367,"=Fibra Optica") -> 17 | R2: =COUNTIFS(R4:R367, "=APAGADO",E4:E367,"=Fibra Optica") -> 18 | S2: =COUNTIFS(S4:S367, "=APAGADO",E4:E367,"=Fibra Optica") -> 25 | T2: =COUNTIFS(T4:T367, "=APAGADO",E4:E367,"=Fibra Optica") -> 17 | U2: =COUNTIFS(U4:U367, "=APAGADO",E4:E367,"=Fibra Optica") -> 18 | V2: =COUNTIFS(V4:V367, "=APAGADO",E4:E367,"=Fibra Optica") -> 17 | W2: =COUNTIFS(W4:W367, "=APAGADO",E4:E367,"=Fibra Optica") -> 0 | X2: =COUNTIFS(X4:X367, "=APAGADO",E4:E367,"=Fibra Optica") -> 0 | Y2: =COUNTIFS(Y4:Y367, "=APAGADO",E4:E367,"=Fibra Optica") -> 0 | Z2: =COUNTIFS(Z4:Z367, "=APAGADO",E4:E367,"=Fibra Optica") -> 0 | AA2: =COUNTIFS(AA4:AA367, "=APAGADO",E4:E367,"=Fibra Optica") -> 0 | AB2: =COUNTIFS(AB4:AB367, "=APAGADO",E4:E367,"=Fibra Optica") -> 0 | AC2: =COUNTIFS(AC4:AC367, "=APAGADO",E4:E367,"=Fibra Optica") -> 0 | AD2: =COUNTIFS(AD4:AD367, "=APAGADO",E4:E367,"=Fibra Optica") -> 0 | AE2: =COUNTIFS(AE4:AE367, "=APAGADO",E4:E367,"=Fibra Optica") -> 0 | AF2: =COUNTIFS(AF4:AF367, "=APAGADO",E4:E367,"=Fibra Optica") -> 0 | AG2: =COUNTIFS(AG4:AG367, "=APAGADO",E4:E367,"=Fibra Optica") -> 0 | AH2: =COUNTIFS(AH4:AH367, "=APAGADO",E4:E367,"=Fibra Optica") -> 0 | AI2: =COUNTIFS(AI4:AI367, "=APAGADO",AE4:AE367,"=Fibra Optica") -> 0 | AJ2: =COUNTIFS(AJ4:AJ367, "=APAGADO",AF4:AF367,"=Fibra Optica") -> 0
A3: =ESTADISTICA!A1 -> Barrio | B3: =ESTADISTICA!B1 -> [Denominacion] | C3: =ESTADISTICA!C1 -> [Ubicacion] | D3: =ESTADISTICA!D1 -> [Tipo de Camara] | E3: =ESTADISTICA!E1 -> [Tipo de Conexion] | F3: =ESTADISTICA!F1 -> 44652 | G3: =ESTADISTICA!G1 -> 44653 | H3: =ESTADISTICA!H1 -> 44654 | ... AJ3: =ESTADISTICA!AJ1 -> #REF!
A4: =ESTADISTICA!A2 -> PRESIDENTE PERON (PEPSI) | B4: =ESTADISTICA!B2 -> MAR 01 | C4: =ESTADISTICA!C2 -> RP36 Y LA ESMERALDA | D4: =ESTADISTICA!D2 -> DOMO | E4: =ESTADISTICA!E2 -> Fibra Optica | F4: =ESTADISTICA!F2 -> 0 | G4: =ESTADISTICA!G2 -> 0 | H4: =ESTADISTICA!H2 -> 0 | ... AJ4: =ESTADISTICA!AJ2 -> #REF!
A5: =ESTADISTICA!A3 -> MAYOL | B5: =ESTADISTICA!B3 -> MAY 01 | C5: =ESTADISTICA!C3 -> Eva Peron y Cabildo | D5: =ESTADISTICA!D3 -> Domo | E5: =ESTADISTICA!E3 -> Radio | F5: =ESTADISTICA!F3 -> 0 | G5: =ESTADISTICA!G3 -> 0 | H5: =ESTADISTICA!H3 -> 0 | ... AG5: =ESTADISTICA!AG3 -> 0
A6: =ESTADISTICA!A4 -> 0 | B6: =ESTADISTICA!B4 -> MAY 02 | C6: =ESTADISTICA!C4 -> EVA PERON Y MONTEVIDEO | D6: =ESTADISTICA!D4 -> Domo | E6: =ESTADISTICA!E4 -> Radio | F6: =ESTADISTICA!F4 -> 0 | G6: =ESTADISTICA!G4 -> 0 | H6: =ESTADISTICA!H4 -> 0 | ... AG6: =ESTADISTICA!AG4 -> 0
A7: =ESTADISTICA!A5 -> MAYOL | B7: =ESTADISTICA!B5 -> MAY 03 | C7: =ESTADISTICA!C5 -> CHAÑAR Y SAN NICOLAS | D7: =ESTADISTICA!D5 -> DOMO | E7: =ESTADISTICA!E5 -> PTP A FO | F7: =ESTADISTICA!F5 -> 0 | G7: =ESTADISTICA!G5 -> 0 | H7: =ESTADISTICA!H5 -> 0 | ... AG7: =ESTADISTICA!AG5 -> 0
A8: =ESTADISTICA!A6 -> 0 | B8: =ESTADISTICA!B6 -> MAY 04 | C8: =ESTADISTICA!C6 -> MAR CHIQUITA Y RIO JACHAL | D8: =ESTADISTICA!D6 -> DOMO | E8: =ESTADISTICA!E6 -> Radio | F8: =ESTADISTICA!F6 -> 0 | G8: =ESTADISTICA!G6 -> 0 | H8: =ESTADISTICA!H6 -> 0 | ... AG8: =ESTADISTICA!AG6 -> 0
A9: =ESTADISTICA!A7 -> ALTAMIRA | B9: =ESTADISTICA!B7 -> ALT06 | C9: =ESTADISTICA!C7 -> LOPE DE VEGA Y NECOCHEA | D9: =ESTADISTICA!D7 -> Domo | E9: =ESTADISTICA!E7 -> PTP A FO | F9: =ESTADISTICA!F7 -> 0 | G9: =ESTADISTICA!G7 -> 0 | H9: =ESTADISTICA!H7 -> 0 | ... AG9: =ESTADISTICA!AG7 -> 0
A10: =ESTADISTICA!A8 -> ALTAMIRA | B10: =ESTADISTICA!B8 -> ALT01 | C10: =ESTADISTICA!C8 -> Calchaqui y Sgto. Cabral | D10: =ESTADISTICA!D8 -> Domo | E10: =ESTADISTICA!E8 -> Fibra Optica | F10: =ESTADISTICA!F8 -> 0 | G10: =ESTADISTICA!G8 -> 0 | H10: =ESTADISTICA!H8 -> 0 | ... AJ10: =ESTADISTICA!AJ8 -> #REF!
A11: =ESTADISTICA!A9 -> ALTAMIRA | B11: =ESTADISTICA!B9 -> ALT02 | C11: =ESTADISTICA!C9 -> Calchaqui y Lope de Vega | D11: =ESTADISTICA!D9 -> Domo | E11: =ESTADISTICA!E9 -> PTP A FO | F11: =ESTADISTICA!F9 -> 0 | G11: =ESTADISTICA!G9 -> 0 | H11: =ESTADISTICA!H9 -> 0 | ... AG11: =ESTADISTICA!AG9 -> 0
A12: =ESTADISTICA!A10 -> ALTAMIRA | B12: =ESTADISTICA!B10 -> ALT03 | C12: =ESTADISTICA!C10 -> Bombero Galarza y Necochea | D12: =ESTADISTICA!D10 -> Domo | E12: =ESTADISTICA!E10 -> Fibra Optica | F12: =ESTADISTICA!F10 -> 0 | G12: =ESTADISTICA!G10 -> 0 | H12: =ESTADISTICA!H10 -> 0 | ... AJ12: =ESTADISTICA!AJ10 -> #REF!
A13: =ESTADISTICA!A11 -> 0 | B13: =ESTADISTICA!B11 -> ALT04 | C13: =ESTADISTICA!C11 -> Francia y Necochea | D13: =ESTADISTICA!D11 -> Domo | E13: =ESTADISTICA!E11 -> Fibra Optica | F13: =ESTADISTICA!F11 -> 0 | G13: =ESTADISTICA!G11 -> 0 | H13: =ESTADISTICA!H11 -> 0 | ... AJ13: =ESTADISTICA!AJ11 -> #REF!
A14: =ESTADISTICA!A12 -> ALTAMIRA | B14: =ESTADISTICA!B12 -> ALT05 | C14: =ESTADISTICA!C12 -> Av. Calchaqui y Bombero Galarza | D14: =ESTADISTICA!D12 -> Domo | E14: =ESTADISTICA!E12 -> PTP A FO | F14: =ESTADISTICA!F12 -> 0 | G14: =ESTADISTICA!G12 -> 0 | H14: =ESTADISTICA!H12 -> 0 | ... AG14: =ESTADISTICA!AG12 -> 0
A15: =ESTADISTICA!A13 -> ALTAMIRA | B15: =ESTADISTICA!B13 -> ALT07 | C15: =ESTADISTICA!C13 -> AV. CALCHAQUI Y AV. DEL TRABAJO | D15: =ESTADISTICA!D13 -> DOMO | E15: =ESTADISTICA!E13 -> PTP A FO | F15: =ESTADISTICA!F13 -> 0 | G15: =ESTADISTICA!G13 -> 0 | H15: =ESTADISTICA!H13 -> 0 | ... AG15: =ESTADISTICA!AG13 -> 0
A16: =ESTADISTICA!A14 -> ALTAMIRA | B16: =ESTADISTICA!B14 -> ALT08 | C16: =ESTADISTICA!C14 -> HUMAITA Y NECOCHEA | D16: =ESTADISTICA!D14 -> DOMO | E16: =ESTADISTICA!E14 -> Fibra Optica | F16: =ESTADISTICA!F14 -> 0 | G16: =ESTADISTICA!G14 -> 0 | H16: =ESTADISTICA!H14 -> 0 | ... AJ16: =ESTADISTICA!AJ14 -> #REF!
A17: =ESTADISTICA!A15 -> ALTAMIRA | B17: =ESTADISTICA!B15 -> ALT09 | C17: =ESTADISTICA!C15 -> NECOCHEA Y CURUPAITY | D17: =ESTADISTICA!D15 -> DOMO | E17: =ESTADISTICA!E15 -> Fibra Optica | F17: =ESTADISTICA!F15 -> 0 | G17: =ESTADISTICA!G15 -> 0 | H17: =ESTADISTICA!H15 -> 0 | ... AJ17: =ESTADISTICA!AJ15 -> #REF!
A18: =ESTADISTICA!A16 -> AGUSTIN RAMIREZ | B18: =ESTADISTICA!B16 -> ARA01 | C18: =ESTADISTICA!C16 -> Malambo y Tranquera | D18: =ESTADISTICA!D16 -> Domo | E18: =ESTADISTICA!E16 -> Fibra Optica | F18: =ESTADISTICA!F16 -> 0 | G18: =ESTADISTICA!G16 -> 0 | H18: =ESTADISTICA!H16 -> 0 | ... AJ18: =ESTADISTICA!AJ16 -> #REF!
A19: =ESTADISTICA!A17 -> ALTAMIRA | B19: =ESTADISTICA!B17 -> ALT10 | C19: =ESTADISTICA!C17 -> REP. FRANCIA Y CALCHAQUI (RP 36) | D19: =ESTADISTICA!D17 -> DOMO | E19: =ESTADISTICA!E17 -> PTP A FO | F19: =ESTADISTICA!F17 -> 0 | G19: =ESTADISTICA!G17 -> 0 | H19: =ESTADISTICA!H17 -> 0 | ... AG19: =ESTADISTICA!AG17 -> 0
A20: =ESTADISTICA!A18 -> BELGRANO | B20: =ESTADISTICA!B18 -> BEL01 | C20: =ESTADISTICA!C18 -> San Martin y Dardo Rocha | D20: =ESTADISTICA!D18 -> DOMO | E20: =ESTADISTICA!E18 -> Fibra Optica | F20: =ESTADISTICA!F18 -> 0 | G20: =ESTADISTICA!G18 -> 0 | H20: =ESTADISTICA!H18 -> 0 | ... AJ20: =ESTADISTICA!AJ18 -> #REF!
A21: =ESTADISTICA!A19 -> 0 | B21: =ESTADISTICA!B19 -> CEN51 | C21: =ESTADISTICA!C19 -> ILLIA Y LAS HERAS | D21: =ESTADISTICA!D19 -> FIJA | E21: =ESTADISTICA!E19 -> Fibra Optica | F21: =ESTADISTICA!F19 -> 0 | G21: =ESTADISTICA!G19 -> 0 | H21: =ESTADISTICA!H19 -> 0 | ... AJ21: =ESTADISTICA!AJ19 -> #REF!
A22: =ESTADISTICA!A20 -> 0 | B22: =ESTADISTICA!B20 -> CEN53 | C22: =ESTADISTICA!C20 -> GUTIERREZ Y BROWN | D22: =ESTADISTICA!D20 -> Domo | E22: =ESTADISTICA!E20 -> Radio | F22: =ESTADISTICA!F20 -> 0 | G22: =ESTADISTICA!G20 -> 0 | H22: =ESTADISTICA!H20 -> 0 | ... AG22: =ESTADISTICA!AG20 -> 0
A23: =ESTADISTICA!A21 -> 0 | B23: =ESTADISTICA!B21 -> CEN 54 | C23: =ESTADISTICA!C21 -> GUTIERREZ Y PRINGLES | D23: =ESTADISTICA!D21 -> Domo | E23: =ESTADISTICA!E21 -> Radio | F23: =ESTADISTICA!F21 -> 0 | G23: =ESTADISTICA!G21 -> 0 | H23: =ESTADISTICA!H21 -> 0 | ... AG23: =ESTADISTICA!AG21 -> 0
A24: =ESTADISTICA!A22 -> 0 | B24: =ESTADISTICA!B22 -> CEN 55 | C24: =ESTADISTICA!C22 -> BOUREL Y URQUIZA | D24: =ESTADISTICA!D22 -> Domo | E24: =ESTADISTICA!E22 -> Radio | F24: =ESTADISTICA!F22 -> 0 | G24: =ESTADISTICA!G22 -> 0 | H24: =ESTADISTICA!H22 -> 0 | ... AG24: =ESTADISTICA!AG22 -> 0
A25: =ESTADISTICA!A23 -> CENTRO | B25: =ESTADISTICA!B23 -> CEN 56 | C25: =ESTADISTICA!C23 -> Newbery y Falucho | D25: =ESTADISTICA!D23 -> DOMO | E25: =ESTADISTICA!E23 -> Radio | F25: =ESTADISTICA!F23 -> 0 | G25: =ESTADISTICA!G23 -> 0 | H25: =ESTADISTICA!H23 -> 0 | ... AG25: =ESTADISTICA!AG23 -> 0
A26: =ESTADISTICA!A24 -> 0 | B26: =ESTADISTICA!B24 -> CEN 57 | C26: =ESTADISTICA!C24 -> 25 DE MAYO Y DORREGO | D26: =ESTADISTICA!D24 -> DOMO | E26: =ESTADISTICA!E24 -> Radio | F26: =ESTADISTICA!F24 -> 0 | G26: =ESTADISTICA!G24 -> 0 | H26: =ESTADISTICA!H24 -> 0 | ... AG26: =ESTADISTICA!AG24 -> 0
A27: =ESTADISTICA!A25 -> 0 | B27: =ESTADISTICA!B25 -> CEN 58 | C27: =ESTADISTICA!C25 -> EEUU Y MORENO | D27: =ESTADISTICA!D25 -> DOMO | E27: =ESTADISTICA!E25 -> Fibra Optica | F27: =ESTADISTICA!F25 -> 0 | G27: =ESTADISTICA!G25 -> 0 | H27: =ESTADISTICA!H25 -> 0 | ... AJ27: =ESTADISTICA!AJ25 -> #REF!
A28: =ESTADISTICA!A26 -> 0 | B28: =ESTADISTICA!B26 -> CEN 59 | C28: =ESTADISTICA!C26 -> CHACABUCO Y BOUREL | D28: =ESTADISTICA!D26 -> DOMO | E28: =ESTADISTICA!E26 -> Radio | F28: =ESTADISTICA!F26 -> 0 | G28: =ESTADISTICA!G26 -> 0 | H28: =ESTADISTICA!H26 -> 0 | ... AG28: =ESTADISTICA!AG26 -> 0
A29: =ESTADISTICA!A27 -> CENTRO | B29: =ESTADISTICA!B27 -> CEN 60 | C29: =ESTADISTICA!C27 -> RECONQUISTA Y ILLIA | D29: =ESTADISTICA!D27 -> DOMO | E29: =ESTADISTICA!E27 -> PTP A FO | F29: =ESTADISTICA!F27 -> APAGADO | G29: =ESTADISTICA!G27 -> 0 | H29: =ESTADISTICA!H27 -> 0 | ... AG29: =ESTADISTICA!AG27 -> 0
A30: =ESTADISTICA!A28 -> CENTRO | B30: =ESTADISTICA!B28 -> CEN 61 | C30: =ESTADISTICA!C28 -> BOUREL Y MAIPU | D30: =ESTADISTICA!D28 -> DOMO | E30: =ESTADISTICA!E28 -> Radio | F30: =ESTADISTICA!F28 -> 0 | G30: =ESTADISTICA!G28 -> 0 | H30: =ESTADISTICA!H28 -> 0 | ... AG30: =ESTADISTICA!AG28 -> 0
A31: =ESTADISTICA!A29 -> CENTRO | B31: =ESTADISTICA!B29 -> CEN 62 | C31: =ESTADISTICA!C29 -> ESPAÑA Y ALEM | D31: =ESTADISTICA!D29 -> DOMO | E31: =ESTADISTICA!E29 -> PTP A FO | F31: =ESTADISTICA!F29 -> 0 | G31: =ESTADISTICA!G29 -> 0 | H31: =ESTADISTICA!H29 -> 0 | ... AG31: =ESTADISTICA!AG29 -> 0
A32: =ESTADISTICA!A30 -> CENTRO | B32: =ESTADISTICA!B30 -> CEN 63 | C32: =ESTADISTICA!C30 -> SAN MARTIN Y URQUIZA | D32: =ESTADISTICA!D30 -> DOMO | E32: =ESTADISTICA!E30 -> Fibra Optica | F32: =ESTADISTICA!F30 -> 0 | G32: =ESTADISTICA!G30 -> 0 | H32: =ESTADISTICA!H30 -> 0 | ... AJ32: =ESTADISTICA!AJ30 -> #REF!
A33: =ESTADISTICA!A31 -> CENTRO | B33: =ESTADISTICA!B31 -> CEN 70 | C33: =ESTADISTICA!C31 -> RIVADAVIA Y 25 MAYO | D33: =ESTADISTICA!D31 -> Domo | E33: =ESTADISTICA!E31 -> Fibra Optica | F33: =ESTADISTICA!F31 -> 0 | G33: =ESTADISTICA!G31 -> 0 | H33: =ESTADISTICA!H31 -> 0 | ... AJ33: =ESTADISTICA!AJ31 -> #REF!
A34: =ESTADISTICA!A32 -> CENTRO | B34: =ESTADISTICA!B32 -> CEN 71 | C34: =ESTADISTICA!C32 -> MORENO Y BOUREL | D34: =ESTADISTICA!D32 -> Domo | E34: =ESTADISTICA!E32 -> Fibra Optica | F34: =ESTADISTICA!F32 -> 0 | G34: =ESTADISTICA!G32 -> 0 | H34: =ESTADISTICA!H32 -> 0 | ... AJ34: =ESTADISTICA!AJ32 -> #REF!
A35: =ESTADISTICA!A33 -> CENTRO | B35: =ESTADISTICA!B33 -> CEN 72 | C35: =ESTADISTICA!C33 -> MORENO Y 25 DE MAYO | D35: =ESTADISTICA!D33 -> Domo | E35: =ESTADISTICA!E33 -> Fibra Optica | F35: =ESTADISTICA!F33 -> 0 | G35: =ESTADISTICA!G33 -> 0 | H35: =ESTADISTICA!H33 -> 0 | ... AJ35: =ESTADISTICA!AJ33 -> #REF!
A36: =ESTADISTICA!A34 -> CENTRO | B36: =ESTADISTICA!B34 -> CEN01 | C36: =ESTADISTICA!C34 -> San Martin y 9 de Julio | D36: =ESTADISTICA!D34 -> Fija | E36: =ESTADISTICA!E34 -> Fibra Optica | F36: =ESTADISTICA!F34 -> 0 | G36: =ESTADISTICA!G34 -> 0 | H36: =ESTADISTICA!H34 -> 0 | ... AJ36: =ESTADISTICA!AJ34 -> #REF!
A37: =ESTADISTICA!A35 -> CENTRO | B37: =ESTADISTICA!B35 -> CEN02 | C37: =ESTADISTICA!C35 -> San Martin y Almafuerte | D37: =ESTADISTICA!D35 -> Fija | E37: =ESTADISTICA!E35 -> Fibra Optica | F37: =ESTADISTICA!F35 -> 0 | G37: =ESTADISTICA!G35 -> 0 | H37: =ESTADISTICA!H35 -> 0 | ... AJ37: =ESTADISTICA!AJ35 -> #REF!
A38: =ESTADISTICA!A36 -> CENTRO | B38: =ESTADISTICA!B36 -> CEN03 | C38: =ESTADISTICA!C36 -> San Martin y Sallares | D38: =ESTADISTICA!D36 -> Domo | E38: =ESTADISTICA!E36 -> Fibra Optica | F38: =ESTADISTICA!F36 -> 0 | G38: =ESTADISTICA!G36 -> 0 | H38: =ESTADISTICA!H36 -> 0 | ... AJ38: =ESTADISTICA!AJ36 -> #REF!
A39: =ESTADISTICA!A37 -> CENTRO | B39: =ESTADISTICA!B37 -> CEN04 | C39: =ESTADISTICA!C37 -> San Martin y Contreras | D39: =ESTADISTICA!D37 -> Domo | E39: =ESTADISTICA!E37 -> Fibra Optica | F39: =ESTADISTICA!F37 -> 0 | G39: =ESTADISTICA!G37 -> 0 | H39: =ESTADISTICA!H37 -> 0 | ... AJ39: =ESTADISTICA!AJ37 -> #REF!
A40: =ESTADISTICA!A38 -> CENTRO | B40: =ESTADISTICA!B38 -> CEN05 | C40: =ESTADISTICA!C38 -> Bocuzzi e/España y San Martin | D40: =ESTADISTICA!D38 -> DOMO | E40: =ESTADISTICA!E38 -> Fibra Optica | F40: =ESTADISTICA!F38 -> 0 | G40: =ESTADISTICA!G38 -> 0 | H40: =ESTADISTICA!H38 -> 0 | ... AJ40: =ESTADISTICA!AJ38 -> #REF!
...

Sheet APAGADOS ANTENA
C1: TOTAL PTP A FO | D1: =COUNTIFS(E4:E367,"=PTP A FO") -> 38
E2: APAGADOS | F2: =COUNTIFS(F4:F367, "=APAGADO",E4:E367,"=PTP A FO") -> 4 | G2: =COUNTIFS(G4:G367, "=APAGADO",E4:E367,"=PTP A FO") -> 0 | H2: =COUNTIFS(H4:H367, "=APAGADO",E4:E367,"=PTP A FO") -> 0 | I2: =COUNTIFS(I4:I367, "=APAGADO",E4:E367,"=PTP A FO") -> 3 | J2: =COUNTIFS(J4:J367, "=APAGADO",E4:E367,"=PTP A FO") -> 2 | K2: =COUNTIFS(K4:K367, "=APAGADO",E4:E367,"=PTP A FO") -> 2 | L2: =COUNTIFS(L4:L367, "=APAGADO",E4:E367,"=PTP A FO") -> 4 | M2: =COUNTIFS(M4:M367, "=APAGADO",E4:E367,"=PTP A FO") -> 3 | N2: =COUNTIFS(N4:N367, "=APAGADO",E4:E367,"=PTP A FO") -> 3 | O2: =COUNTIFS(O4:O367,"APAGADO", E4:E367,"=PTP A FO" ) -> 2 | P2: =COUNTIFS(P4:P367, "=APAGADO",E4:E367,"=PTP A FO") -> 3 | Q2: =COUNTIFS(Q4:Q367, "=APAGADO",E4:E367,"=PTP A FO") -> 1 | R2: =COUNTIFS(R4:R367, "=APAGADO",E4:E367,"=PTP A FO") -> 2 | S2: =COUNTIFS(S4:S367, "=APAGADO",E4:E367,"=PTP A FO") -> 7 | T2: =COUNTIFS(T4:T367, "=APAGADO",E4:E367,"=PTP A FO") -> 3 | U2: =COUNTIFS(U4:U367, "=APAGADO",E4:E367,"=PTP A FO") -> 2 | V2: =COUNTIFS(V4:V367, "=APAGADO",E4:E367,"=PTP A FO") -> 3 | W2: =COUNTIFS(W4:W367, "=APAGADO",E4:E367,"=PTP A FO") -> 0 | X2: =COUNTIFS(X4:X367, "=APAGADO",E4:E367,"=PTP A FO") -> 0 | Y2: =COUNTIFS(Y4:Y367, "=APAGADO",E4:E367,"=PTP A FO") -> 0 | Z2: =COUNTIFS(Z4:Z367, "=APAGADO",E4:E367,"=PTP A FO") -> 0 | AA2: =COUNTIFS(AA4:AA367, "=APAGADO",E4:E367,"=PTP A FO") -> 0 | AB2: =COUNTIFS(AB4:AB367, "=APAGADO",E4:E367,"=PTP A FO") -> 0 | AC2: =COUNTIFS(AC4:AC367, "=APAGADO",E4:E367,"=PTP A FO") -> 0 | AD2: =COUNTIFS(AD4:AD367, "=APAGADO",E4:E367,"=PTP A FO") -> 0 | AE2: =COUNTIFS(AE4:AE367, "=APAGADO",E4:E367,"=PTP A FO") -> 0 | AF2: =COUNTIFS(AF4:AF367, "=APAGADO",E4:E367,"=PTP A FO") -> 0 | AG2: =COUNTIFS(AG4:AG367, "=APAGADO",E4:E367,"=PTP A FO") -> 0 | AH2: =COUNTIFS(AH4:AH367, "=APAGADO",E4:E367,"=PTP A FO") -> 0 | AI2: =COUNTIFS(AI4:AI367, "=APAGADO",G4:G367,"=PTP A FO") -> 0 | AJ2: =COUNTIFS(AJ4:AJ367, "=APAGADO",H4:H367,"=PTP A FO") -> 0
A3: =ESTADISTICA!A1 -> Barrio | B3: =ESTADISTICA!B1 -> [Denominacion] | C3: =ESTADISTICA!C1 -> [Ubicacion] | D3: =ESTADISTICA!D1 -> [Tipo de Camara] | E3: =ESTADISTICA!E1 -> [Tipo de Conexion] | F3: =ESTADISTICA!F1 -> 44652 | G3: =ESTADISTICA!G1 -> 44653 | H3: =ESTADISTICA!H1 -> 44654 | ... AJ3: =ESTADISTICA!AJ1 -> #REF!
A4: =ESTADISTICA!A2 -> PRESIDENTE PERON (PEPSI) | B4: =ESTADISTICA!B2 -> MAR 01 | C4: =ESTADISTICA!C2 -> RP36 Y LA ESMERALDA | D4: =ESTADISTICA!D2 -> DOMO | E4: =ESTADISTICA!E2 -> Fibra Optica | F4: =ESTADISTICA!F2 -> 0 | G4: =ESTADISTICA!G2 -> 0 | H4: =ESTADISTICA!H2 -> 0 | ... AJ4: =ESTADISTICA!AJ2 -> #REF!
A5: =ESTADISTICA!A3 -> MAYOL | B5: =ESTADISTICA!B3 -> MAY 01 | C5: =ESTADISTICA!C3 -> Eva Peron y Cabildo | D5: =ESTADISTICA!D3 -> Domo | E5: =ESTADISTICA!E3 -> Radio | F5: =ESTADISTICA!F3 -> 0 | G5: =ESTADISTICA!G3 -> 0 | H5: =ESTADISTICA!H3 -> 0 | ... AJ5: =ESTADISTICA!AJ3 -> #REF!
A6: =ESTADISTICA!A4 -> 0 | B6: =ESTADISTICA!B4 -> MAY 02 | C6: =ESTADISTICA!C4 -> EVA PERON Y MONTEVIDEO | D6: =ESTADISTICA!D4 -> Domo | E6: =ESTADISTICA!E4 -> Radio | F6: =ESTADISTICA!F4 -> 0 | G6: =ESTADISTICA!G4 -> 0 | H6: =ESTADISTICA!H4 -> 0 | ... AJ6: =ESTADISTICA!AJ4 -> #REF!
A7: =ESTADISTICA!A5 -> MAYOL | B7: =ESTADISTICA!B5 -> MAY 03 | C7: =ESTADISTICA!C5 -> CHAÑAR Y SAN NICOLAS | D7: =ESTADISTICA!D5 -> DOMO | E7: =ESTADISTICA!E5 -> PTP A FO | F7: =ESTADISTICA!F5 -> 0 | G7: =ESTADISTICA!G5 -> 0 | H7: =ESTADISTICA!H5 -> 0 | ... AJ7: =ESTADISTICA!AJ5 -> #REF!
A8: =ESTADISTICA!A6 -> 0 | B8: =ESTADISTICA!B6 -> MAY 04 | C8: =ESTADISTICA!C6 -> MAR CHIQUITA Y RIO JACHAL | D8: =ESTADISTICA!D6 -> DOMO | E8: =ESTADISTICA!E6 -> Radio | F8: =ESTADISTICA!F6 -> 0 | G8: =ESTADISTICA!G6 -> 0 | H8: =ESTADISTICA!H6 -> 0 | ... AJ8: =ESTADISTICA!AJ6 -> #REF!
A9: =ESTADISTICA!A7 -> ALTAMIRA | B9: =ESTADISTICA!B7 -> ALT06 | C9: =ESTADISTICA!C7 -> LOPE DE VEGA Y NECOCHEA | D9: =ESTADISTICA!D7 -> Domo | E9: =ESTADISTICA!E7 -> PTP A FO | F9: =ESTADISTICA!F7 -> 0 | G9: =ESTADISTICA!G7 -> 0 | H9: =ESTADISTICA!H7 -> 0 | ... AJ9: =ESTADISTICA!AJ7 -> #REF!
A10: =ESTADISTICA!A8 -> ALTAMIRA | B10: =ESTADISTICA!B8 -> ALT01 | C10: =ESTADISTICA!C8 -> Calchaqui y Sgto. Cabral | D10: =ESTADISTICA!D8 -> Domo | E10: =ESTADISTICA!E8 -> Fibra Optica | F10: =ESTADISTICA!F8 -> 0 | G10: =ESTADISTICA!G8 -> 0 | H10: =ESTADISTICA!H8 -> 0 | ... AJ10: =ESTADISTICA!AJ8 -> #REF!
A11: =ESTADISTICA!A9 -> ALTAMIRA | B11: =ESTADISTICA!B9 -> ALT02 | C11: =ESTADISTICA!C9 -> Calchaqui y Lope de Vega | D11: =ESTADISTICA!D9 -> Domo | E11: =ESTADISTICA!E9 -> PTP A FO | F11: =ESTADISTICA!F9 -> 0 | G11: =ESTADISTICA!G9 -> 0 | H11: =ESTADISTICA!H9 -> 0 | ... AJ11: =ESTADISTICA!AJ9 -> #REF!
A12: =ESTADISTICA!A10 -> ALTAMIRA | B12: =ESTADISTICA!B10 -> ALT03 | C12: =ESTADISTICA!C10 -> Bombero Galarza y Necochea | D12: =ESTADISTICA!D10 -> Domo | E12: =ESTADISTICA!E10 -> Fibra Optica | F12: =ESTADISTICA!F10 -> 0 | G12: =ESTADISTICA!G10 -> 0 | H12: =ESTADISTICA!H10 -> 0 | ... AJ12: =ESTADISTICA!AJ10 -> #REF!
A13: =ESTADISTICA!A11 -> 0 | B13: =ESTADISTICA!B11 -> ALT04 | C13: =ESTADISTICA!C11 -> Francia y Necochea | D13: =ESTADISTICA!D11 -> Domo | E13: =ESTADISTICA!E11 -> Fibra Optica | F13: =ESTADISTICA!F11 -> 0 | G13: =ESTADISTICA!G11 -> 0 | H13: =ESTADISTICA!H11 -> 0 | ... AJ13: =ESTADISTICA!AJ11 -> #REF!
A14: =ESTADISTICA!A12 -> ALTAMIRA | B14: =ESTADISTICA!B12 -> ALT05 | C14: =ESTADISTICA!C12 -> Av. Calchaqui y Bombero Galarza | D14: =ESTADISTICA!D12 -> Domo | E14: =ESTADISTICA!E12 -> PTP A FO | F14: =ESTADISTICA!F12 -> 0 | G14: =ESTADISTICA!G12 -> 0 | H14: =ESTADISTICA!H12 -> 0 | ... AJ14: =ESTADISTICA!AJ12 -> #REF!
... A278: =ESTADISTICA!A276 -> SANTA ROSA | B278: =ESTADISTICA!B276 -> SRO11 | C278: =ESTADISTICA!C276 -> MILAN Y MALLORCA | D278: =ESTADISTICA!D276 -> DOMO | E278: =ESTADISTICA!E276 -> Radio | F278: =ESTADISTICA!F276 -> APAGADO | G278: =ESTADISTICA!G276 -> 0 | H278: =ESTADISTICA!H276 -> 0 | ... AJ278: =ESTADISTICA!AJ276 -> #REF!
B279: =ESTADISTICA!B277 -> SRO12 | C279: =ESTADISTICA!C277 -> YUGOSLAVIA Y PAYSANDU | D279: =ESTADISTICA!D277 -> DOMO | E279: =ESTADISTICA!E277 -> Radio | F279: =ESTADISTICA!F277 -> 0 | G279: =ESTADISTICA!G277 -> 0 | H279: =ESTADISTICA!H277 -> 0 | I279: =ESTADISTICA!I277 -> 0 | ... AJ279: =ESTADISTICA!AJ277 -> #REF!
A280: =ESTADISTICA!A278 -> ZONA RURAL SANTA ROSA | B280: =ESTADISTICA!B278 -> SRO13 (fija 1) | C280: =ESTADISTICA!C278 -> BRUSELAS E/ GRECIA Y CHECOSLOVAQUIA | D280: =ESTADISTICA!D278 -> Fija | E280: =ESTADISTICA!E278 -> RADIO | F280: =ESTADISTICA!F278 -> 0 | G280: =ESTADISTICA!G278 -> 0 | H280: =ESTADISTICA!H278 -> 0 | ... AJ280: =ESTADISTICA!AJ278 -> #REF!
A281: =ESTADISTICA!A279 -> ZONA RURAL SANTA ROSA | B281: =ESTADISTICA!B279 -> SRO14 (fija 2) | C281: =ESTADISTICA!C279 -> BRUSELAS E/ GRECIA Y CHECOSLOVAQUIA | D281: =ESTADISTICA!D279 -> Fija | E281: =ESTADISTICA!E279 -> RADIO | F281: =ESTADISTICA!F279 -> 0 | G281: =ESTADISTICA!G279 -> 0 | H281: =ESTADISTICA!H279 -> 0 | ... AJ281: =ESTADISTICA!AJ279 -> #REF!
A282: =ESTADISTICA!A280 -> SANTA ROSA | B282: =ESTADISTICA!B280 -> SRO15 | C282: =ESTADISTICA!C280 -> NOVAK Y TIRANA (614) | D282: =ESTADISTICA!D280 -> DOMO | E282: =ESTADISTICA!E280 -> Fibra Optica | F282: =ESTADISTICA!F280 -> APAGADO | G282: =ESTADISTICA!G280 -> 0 | H282: =ESTADISTICA!H280 -> 0 | ... AJ282: =ESTADISTICA!AJ280 -> #REF!
A283: =ESTADISTICA!A281 -> SANTA ROSA | B283: =ESTADISTICA!B281 -> SRO18 (fija 1) | C283: =ESTADISTICA!C281 -> GRAN CANARIA Y BUDAPEST | D283: =ESTADISTICA!D281 -> Fija | E283: =ESTADISTICA!E281 -> Fibra Optica | F283: =ESTADISTICA!F281 -> 0 | G283: =ESTADISTICA!G281 -> 0 | H283: =ESTADISTICA!H281 -> 0 | ... AJ283: =ESTADISTICA!AJ281 -> #REF!
A284: =ESTADISTICA!A282 -> SANTA ROSA | B284: =ESTADISTICA!B282 -> SRO19 (fija 2) | C284: =ESTADISTICA!C282 -> GRAN CANARIA Y BUDAPEST | D284: =ESTADISTICA!D282 -> Fija | E284: =ESTADISTICA!E282 -> Fibra Optica | F284: =ESTADISTICA!F282 -> 0 | G284: =ESTADISTICA!G282 -> 0 | H284: =ESTADISTICA!H282 -> 0 | ... AJ284: =ESTADISTICA!AJ282 -> #REF!
A285: =ESTADISTICA!A283 -> SAN RUDECINDO | B285: =ESTADISTICA!B283 -> SRU01 (fija 1) | C285: =ESTADISTICA!C283 -> HERNANDARIAS Y AMBATO | D285: =ESTADISTICA!D283 -> Fija | E285: =ESTADISTICA!E283 -> Fibra Optica | F285: =ESTADISTICA!F283 -> 0 | G285: =ESTADISTICA!G283 -> 0 | H285: =ESTADISTICA!H283 -> 0 | ... AJ285: =ESTADISTICA!AJ283 -> #REF!
A286: =ESTADISTICA!A284 -> SAN RUDECINDO | B286: =ESTADISTICA!B284 -> SRU02 (fija 2) | C286: =ESTADISTICA!C284 -> HERNANDARIAS Y AMBATO | D286: =ESTADISTICA!D284 -> Fija | E286: =ESTADISTICA!E284 -> Fibra Optica | F286: =ESTADISTICA!F284 -> 0 | G286: =ESTADISTICA!G284 -> 0 | H286: =ESTADISTICA!H284 -> 0 | ... AJ286: =ESTADISTICA!AJ284 -> #REF!
A287: =ESTADISTICA!A285 -> VILLA ANGELICA | B287: =ESTADISTICA!B285 -> VANG01 | C287: =ESTADISTICA!C285 -> Senzabello y Necochea | D287: =ESTADISTICA!D285 -> Domo | E287: =ESTADISTICA!E285 -> PTP A FO | F287: =ESTADISTICA!F285 -> 0 | G287: =ESTADISTICA!G285 -> 0 | H287: =ESTADISTICA!H285 -> 0 | ... AJ287: =ESTADISTICA!AJ285 -> #REF!
A288: =ESTADISTICA!A286 -> VILLA ANGELICA | B288: =ESTADISTICA!B286 -> VANG02 | C288: =ESTADISTICA!C286 -> Thevenet y Ruta 36 | D288: =ESTADISTICA!D286 -> Domo | E288: =ESTADISTICA!E286 -> Fibra Optica | F288: =ESTADISTICA!F286 -> 0 | G288: =ESTADISTICA!G286 -> 0 | H288: =ESTADISTICA!H286 -> 0 | ... AJ288: =ESTADISTICA!AJ286 -> #REF!
A289: =ESTADISTICA!A287 -> VILLA DEL PLATA | B289: =ESTADISTICA!B287 -> VANG03 | C289: =ESTADISTICA!C287 -> Thevenet 1950 | D289: =ESTADISTICA!D287 -> Domo | E289: =ESTADISTICA!E287 -> Fibra Optica | F289: =ESTADISTICA!F287 -> 0 | G289: =ESTADISTICA!G287 -> 0 | H289: =ESTADISTICA!H287 -> 0 | ... AJ289: =ESTADISTICA!AJ287 -> #REF!
A290: =ESTADISTICA!A288 -> VILLA ANGELICA | B290: =ESTADISTICA!B288 -> VANG04 | C290: =ESTADISTICA!C288 -> Storni e/Thevenet y Calle 158 | D290: =ESTADISTICA!D288 -> DOMO | E290: =ESTADISTICA!E288 -> Fibra Optica | F290: =ESTADISTICA!F288 -> APAGADO | G290: =ESTADISTICA!G288 -> 0 | H290: =ESTADISTICA!H288 -> 0 | ... AJ290: =ESTADISTICA!AJ288 -> #REF!
A291: =ESTADISTICA!A289 -> VILLA ANGELICA | B291: =ESTADISTICA!B289 -> VANG05 | C291: =ESTADISTICA!C289 -> Storni y Thevenet | D291: =ESTADISTICA!D289 -> Domo | E291: =ESTADISTICA!E289 -> Fibra Optica | F291: =ESTADISTICA!F289 -> APAGADO | G291: =ESTADISTICA!G289 -> 0 | H291: =ESTADISTICA!H289 -> 0 | ... AJ291: =ESTADISTICA!AJ289 -> #REF!
... A369: =ESTADISTICA!A367 -> 0 | B369: =ESTADISTICA!B367 -> ZEB04 | C369: =ESTADISTICA!C367 -> THEVENET Y DIAGONAL GRANADEROS | D369: =ESTADISTICA!D367 -> DOMO | E369: =ESTADISTICA!E367 -> Radio | F369: =ESTADISTICA!F367 -> 0 | G369: =ESTADISTICA!G367 -> 0 | H369: =ESTADISTICA!H367 -> 0 | ... AJ369: =ESTADISTICA!AJ367 -> #REF!

Sheet APAGADOS RADIO
C1: TOTAL RADIO | D1: =COUNTIFS(E4:E367,"=radio") -> 88
E2: APAGADOS | F2: =COUNTIFS(F4:F367, "=APAGADO",E4:E367,"=radio") -> 4 | G2: =COUNTIFS(G4:G367, "=APAGADO",E4:E367,"=radio") -> 0 | H2: =COUNTIFS(H4:H367, "=APAGADO",E4:E367,"=radio") -> 0 | I2: =COUNTIFS(I4:I367, "=APAGADO",E4:E367,"=radio") -> 4 | J2: =COUNTIFS(J4:J367, "=APAGADO",E4:E367,"=radio") -> 4 | K2: =COUNTIFS(K4:K367, "=APAGADO",E4:E367,"=radio") -> 3 | L2: =COUNTIFS(L4:L367, "=APAGADO",E4:E367,"=radio") -> 6 | M2: =COUNTIFS(M4:M367, "=APAGADO",E4:E367,"=radio") -> 4 | N2: =COUNTIFS(N4:N367, "=APAGADO",E4:E367,"=radio") -> 6 | O2: =COUNTIFS(O4:O367, "=APAGADO",E4:E367,"=radio") -> 7 | P2: =COUNTIFS(P4:P367, "=APAGADO",E4:E367,"=radio") -> 4 | Q2: =COUNTIFS(Q4:Q367, "=APAGADO",E4:E367,"=radio") -> 4 | R2: =COUNTIFS(R4:R367, "=APAGADO",E4:E367,"=radio") -> 3 | S2: =COUNTIFS(S4:S367, "=APAGADO",E4:E367,"=radio") -> 3 | T2: =COUNTIFS(T4:T367, "=APAGADO",E4:E367,"=radio") -> 3 | U2: =COUNTIFS(U4:U367, "=APAGADO",E4:E367,"=radio") -> 3 | V2: =COUNTIFS(V4:V367, "=APAGADO",E4:E367,"=radio") -> 5 | W2: =COUNTIFS(W4:W367, "=APAGADO",E4:E367,"=radio") -> 0 | X2: =COUNTIFS(X4:X367, "=APAGADO",E4:E367,"=radio") -> 0 | Y2: =COUNTIFS(Y4:Y367, "=APAGADO",E4:E367,"=radio") -> 0 | Z2: =COUNTIFS(Z4:Z367, "=APAGADO",E4:E367,"=radio") -> 0 | AA2: =COUNTIFS(AA4:AA367, "=APAGADO",E4:E367,"=radio") -> 0 | AB2: =COUNTIFS(AB4:AB367, "=APAGADO",E4:E367,"=radio") -> 0 | AC2: =COUNTIFS(AC4:AC367, "=APAGADO",E4:E367,"=radio") -> 0 | AD2: =COUNTIFS(AD4:AD367, "=APAGADO",E4:E367,"=radio") -> 0 | AE2: =COUNTIFS(AE4:AE367, "=APAGADO",E4:E367,"=radio") -> 0 | AF2: =COUNTIFS(AF4:AF367, "=APAGADO",E4:E367,"=radio") -> 0 | AG2: =COUNTIFS(AG4:AG367, "=APAGADO",E4:E367,"=radio") -> 0 | AH2: =COUNTIFS(AH4:AH367, "=APAGADO",E4:E367,"=radio") -> 0 | AI2: =COUNTIFS(AI4:AI367, "=APAGADO",G4:G367,"=radio") -> 0 | AJ2: =COUNTIFS(AJ4:AJ367, "=APAGADO",H4:H367,"=radio") -> 0
A3: =ESTADISTICA!A1 -> Barrio | B3: =ESTADISTICA!B1 -> [Denominacion] | C3: =ESTADISTICA!C1 -> [Ubicacion] | D3: =ESTADISTICA!D1 -> [Tipo de Camara] | E3: =ESTADISTICA!E1 -> [Tipo de Conexion] | F3: =ESTADISTICA!F1 -> 44652 | G3: =ESTADISTICA!G1 -> 44653 | H3: =ESTADISTICA!H1 -> 44654 | ... AJ3: =ESTADISTICA!AJ1 -> #REF!
A4: =ESTADISTICA!A2 -> PRESIDENTE PERON (PEPSI) | B4: =ESTADISTICA!B2 -> MAR 01 | C4: =ESTADISTICA!C2 -> RP36 Y LA ESMERALDA | D4: =ESTADISTICA!D2 -> DOMO | E4: =ESTADISTICA!E2 -> Fibra Optica | F4: =ESTADISTICA!F2 -> 0 | G4: =ESTADISTICA!G2 -> 0 | H4: =ESTADISTICA!H2 -> 0 | ... AJ4: =ESTADISTICA!AJ2 -> #REF!
A5: =ESTADISTICA!A3 -> MAYOL | B5: =ESTADISTICA!B3 -> MAY 01 | C5: =ESTADISTICA!C3 -> Eva Peron y Cabildo | D5: =ESTADISTICA!D3 -> Domo | E5: =ESTADISTICA!E3 -> Radio | F5: =ESTADISTICA!F3 -> 0 | G5: =ESTADISTICA!G3 -> 0 | H5: =ESTADISTICA!H3 -> 0 | ... AJ5: =ESTADISTICA!AJ3 -> #REF!
A6: =ESTADISTICA!A4 -> 0 | B6: =ESTADISTICA!B4 -> MAY 02 | C6: =ESTADISTICA!C4 -> EVA PERON Y MONTEVIDEO | D6: =ESTADISTICA!D4 -> Domo | E6: =ESTADISTICA!E4 -> Radio | F6: =ESTADISTICA!F4 -> 0 | G6: =ESTADISTICA!G4 -> 0 | H6: =ESTADISTICA!H4 -> 0 | ... AJ6: =ESTADISTICA!AJ4 -> #REF!
A7: =ESTADISTICA!A5 -> MAYOL | B7: =ESTADISTICA!B5 -> MAY 03 | C7: =ESTADISTICA!C5 -> CHAÑAR Y SAN NICOLAS | D7: =ESTADISTICA!D5 -> DOMO | E7: =ESTADISTICA!E5 -> PTP A FO | F7: =ESTADISTICA!F5 -> 0 | G7: =ESTADISTICA!G5 -> 0 | H7: =ESTADISTICA!H5 -> 0 | ... AJ7: =ESTADISTICA!AJ5 -> #REF!
A8: =ESTADISTICA!A6 -> 0 | B8: =ESTADISTICA!B6 -> MAY 04 | C8: =ESTADISTICA!C6 -> MAR CHIQUITA Y RIO JACHAL | D8: =ESTADISTICA!D6 -> DOMO | E8: =ESTADISTICA!E6 -> Radio | F8: =ESTADISTICA!F6 -> 0 | G8: =ESTADISTICA!G6 -> 0 | H8: =ESTADISTICA!H6 -> 0 | ... AJ8: =ESTADISTICA!AJ6 -> #REF!
A9: =ESTADISTICA!A7 -> ALTAMIRA | B9: =ESTADISTICA!B7 -> ALT06 | C9: =ESTADISTICA!C7 -> LOPE DE VEGA Y NECOCHEA | D9: =ESTADISTICA!D7 -> Domo | E9: =ESTADISTICA!E7 -> PTP A FO | F9: =ESTADISTICA!F7 -> 0 | G9: =ESTADISTICA!G7 -> 0 | H9: =ESTADISTICA!H7 -> 0 | ... AJ9: =ESTADISTICA!AJ7 -> #REF!
A10: =ESTADISTICA!A8 -> ALTAMIRA | B10: =ESTADISTICA!B8 -> ALT01 | C10: =ESTADISTICA!C8 -> Calchaqui y Sgto. Cabral | D10: =ESTADISTICA!D8 -> Domo | E10: =ESTADISTICA!E8 -> Fibra Optica | F10: =ESTADISTICA!F8 -> 0 | G10: =ESTADISTICA!G8 -> 0 | H10: =ESTADISTICA!H8 -> 0 | ... AJ10: =ESTADISTICA!AJ8 -> #REF!
A11: =ESTADISTICA!A9 -> ALTAMIRA | B11: =ESTADISTICA!B9 -> ALT02 | C11: =ESTADISTICA!C9 -> Calchaqui y Lope de Vega | D11: =ESTADISTICA!D9 -> Domo | E11: =ESTADISTICA!E9 -> PTP A FO | F11: =ESTADISTICA!F9 -> 0 | G11: =ESTADISTICA!G9 -> 0 | H11: =ESTADISTICA!H9 -> 0 | ... AJ11: =ESTADISTICA!AJ9 -> #REF!
A12: =ESTADISTICA!A10 -> ALTAMIRA | B12: =ESTADISTICA!B10 -> ALT03 | C12: =ESTADISTICA!C10 -> Bombero Galarza y Necochea | D12: =ESTADISTICA!D10 -> Domo | E12: =ESTADISTICA!E10 -> Fibra Optica | F12: =ESTADISTICA!F10 -> 0 | G12: =ESTADISTICA!G10 -> 0 | H12: =ESTADISTICA!H10 -> 0 | ... AJ12: =ESTADISTICA!AJ10 -> #REF!
A13: =ESTADISTICA!A11 -> 0 | B13: =ESTADISTICA!B11 -> ALT04 | C13: =ESTADISTICA!C11 -> Francia y Necochea | D13: =ESTADISTICA!D11 -> Domo | E13: =ESTADISTICA!E11 -> Fibra Optica | F13: =ESTADISTICA!F11 -> 0 | G13: =ESTADISTICA!G11 -> 0 | H13: =ESTADISTICA!H11 -> 0 | ... AJ13: =ESTADISTICA!AJ11 -> #REF!
A14: =ESTADISTICA!A12 -> ALTAMIRA | B14: =ESTADISTICA!B12 -> ALT05 | C14: =ESTADISTICA!C12 -> Av. Calchaqui y Bombero Galarza | D14: =ESTADISTICA!D12 -> Domo | E14: =ESTADISTICA!E12 -> PTP A FO | F14: =ESTADISTICA!F12 -> 0 | G14: =ESTADISTICA!G12 -> 0 | H14: =ESTADISTICA!H12 -> 0 | ... AJ14: =ESTADISTICA!AJ12 -> #REF!
... A278: =ESTADISTICA!A276 -> SANTA ROSA | B278: =ESTADISTICA!B276 -> SRO11 | C278: =ESTADISTICA!C276 -> MILAN Y MALLORCA | D278: =ESTADISTICA!D276 -> DOMO | E278: =ESTADISTICA!E276 -> Radio | F278: =ESTADISTICA!F276 -> APAGADO | G278: =ESTADISTICA!G276 -> 0 | H278: =ESTADISTICA!H276 -> 0 | ... AJ278: =ESTADISTICA!AJ276 -> #REF!
B279: =ESTADISTICA!B277 -> SRO12 | C279: =ESTADISTICA!C277 -> YUGOSLAVIA Y PAYSANDU | D279: =ESTADISTICA!D277 -> DOMO | E279: =ESTADISTICA!E277 -> Radio | F279: =ESTADISTICA!F277 -> 0 | G279: =ESTADISTICA!G277 -> 0 | H279: =ESTADISTICA!H277 -> 0 | I279: =ESTADISTICA!I277 -> 0 | ... AJ279: =ESTADISTICA!AJ277 -> #REF!
A280: =ESTADISTICA!A278 -> ZONA RURAL SANTA ROSA | B280: =ESTADISTICA!B278 -> SRO13 (fija 1) | C280: =ESTADISTICA!C278 -> BRUSELAS E/ GRECIA Y CHECOSLOVAQUIA | D280: =ESTADISTICA!D278 -> Fija | E280: =ESTADISTICA!E278 -> RADIO | F280: =ESTADISTICA!F278 -> 0 | G280: =ESTADISTICA!G278 -> 0 | H280: =ESTADISTICA!H278 -> 0 | ... AJ280: =ESTADISTICA!AJ278 -> #REF!
A281: =ESTADISTICA!A279 -> ZONA RURAL SANTA ROSA | B281: =ESTADISTICA!B279 -> SRO14 (fija 2) | C281: =ESTADISTICA!C279 -> BRUSELAS E/ GRECIA Y CHECOSLOVAQUIA | D281: =ESTADISTICA!D279 -> Fija | E281: =ESTADISTICA!E279 -> RADIO | F281: =ESTADISTICA!F279 -> 0 | G281: =ESTADISTICA!G279 -> 0 | H281: =ESTADISTICA!H279 -> 0 | ... AJ281: =ESTADISTICA!AJ279 -> #REF!
A282: =ESTADISTICA!A280 -> SANTA ROSA | B282: =ESTADISTICA!B280 -> SRO15 | C282: =ESTADISTICA!C280 -> NOVAK Y TIRANA (614) | D282: =ESTADISTICA!D280 -> DOMO | E282: =ESTADISTICA!E280 -> Fibra Optica | F282: =ESTADISTICA!F280 -> APAGADO | G282: =ESTADISTICA!G280 -> 0 | H282: =ESTADISTICA!H280 -> 0 | ... AJ282: =ESTADISTICA!AJ280 -> #REF!
A283: =ESTADISTICA!A281 -> SANTA ROSA | B283: =ESTADISTICA!B281 -> SRO18 (fija 1) | C283: =ESTADISTICA!C281 -> GRAN CANARIA Y BUDAPEST | D283: =ESTADISTICA!D281 -> Fija | E283: =ESTADISTICA!E281 -> Fibra Optica | F283: =ESTADISTICA!F281 -> 0 | G283: =ESTADISTICA!G281 -> 0 | H283: =ESTADISTICA!H281 -> 0 | ... AJ283: =ESTADISTICA!AJ281 -> #REF!
A284: =ESTADISTICA!A282 -> SANTA ROSA | B284: =ESTADISTICA!B282 -> SRO19 (fija 2) | C284: =ESTADISTICA!C282 -> GRAN CANARIA Y BUDAPEST | D284: =ESTADISTICA!D282 -> Fija | E284: =ESTADISTICA!E282 -> Fibra Optica | F284: =ESTADISTICA!F282 -> 0 | G284: =ESTADISTICA!G282 -> 0 | H284: =ESTADISTICA!H282 -> 0 | ... AJ284: =ESTADISTICA!AJ282 -> #REF!
A285: =ESTADISTICA!A283 -> SAN RUDECINDO | B285: =ESTADISTICA!B283 -> SRU01 (fija 1) | C285: =ESTADISTICA!C283 -> HERNANDARIAS Y AMBATO | D285: =ESTADISTICA!D283 -> Fija | E285: =ESTADISTICA!E283 -> Fibra Optica | F285: =ESTADISTICA!F283 -> 0 | G285: =ESTADISTICA!G283 -> 0 | H285: =ESTADISTICA!H283 -> 0 | ... AJ285: =ESTADISTICA!AJ283 -> #REF!
