Workbook
Name _25_de_agosto: 'RESUMEN TOTAL'!$A$4:$D$383
Name _25_de_agosto_3: 'RESUMEN TOTAL'!$A$4:$D$395
Name BONOMOcam: Hoja1!$B$2
Name CANTIDAD_DE_CAMARAS: 'RESUMEN TOTAL'!$B$1
Name COSEIDIcam: Hoja1!$B$4

Sheet RESUMEN TOTAL
A1: CANTIDAD DE CAMARAS | B1: =COUNTA(B5:B600) -> 482 | D1: PORCIENTO DE CAIDAS | L1: =(L3)/(L2+L3) -> 0.070539419 | M1: =(M3)/(M2+M3) -> 0.06846473 | N1: =(N3)/(N2+N3) -> 0.056016598 | O1: =(O3)/(O2+O3) -> 0.13485477 | P1: =(P3)/(P2+P3) -> 0.045643154 | Q1: =(Q3)/(Q2+Q3) -> 0.043568465 | R1: =(R3)/(R2+R3) -> 0.039419087 | S1: =(S3)/(S2+S3) -> 0.053941909 | ... X1: =(X3)/(X2+X3) -> 0.076763485 | Z1: =(Z3)/(Z2+Z3) -> 0.076763485 | AA1: =(AA3)/(AA2+AA3) -> 0.056016598 | AB1: =(AB3)/(AB2+AB3) -> 0.10788382 | AC1: =(AC3)/(AC2+AC3) -> 0 | AD1: =(AD3)/(AD2+AD3) -> 0 | AE1: =(AE3)/(AE2+AE3) -> 0 | AF1: =(AF3)/(AF2+AF3) -> 0 | AG1: =(AG3)/(AG2+AG3) -> 0 | ... AP1: =(AP3)/(AP2+AP3) -> 0
D2: FUNCIONAN | L2: =B1-L3 -> 448 | M2: =CANTIDAD_DE_CAMARAS-M3 -> 449 | N2: =CANTIDAD_DE_CAMARAS-N3 -> 455 | O2: =CANTIDAD_DE_CAMARAS-O3 -> 417 | P2: =CANTIDAD_DE_CAMARAS-P3 -> 460 | Q2: =CANTIDAD_DE_CAMARAS-Q3 -> 461 | R2: =CANTIDAD_DE_CAMARAS-R3 -> 463 | S2: =CANTIDAD_DE_CAMARAS-S3 -> 456 | T2: =CANTIDAD_DE_CAMARAS-T3 -> 432 | ... AP2: =CANTIDAD_DE_CAMARAS-AP3 -> 482
D3: CAIDAS | L3: =COUNTIF(L4:L600, "apagado") -> 34 | M3: =COUNTIF(M4:M600, "apagado") -> 33 | N3: =COUNTIF(N4:N600, "apagado") -> 27 | O3: =COUNTIF(O4:O600, "apagado") -> 65 | P3: =COUNTIF(P4:P600, "apagado") -> 22 | Q3: =COUNTIF(Q4:Q600, "apagado") -> 21 | R3: =COUNTIF(R4:R600, "apagado") -> 19 | S3: =COUNTIF(S4:S600, "apagado") -> 26 | ... W3: =COUNTIF(W4:W600, "apagado") -> 63 | X3: =COUNTIF(X4:X498, "apagado") -> 37 | Y3: =COUNTIF(Y4:Y498, "apagado") -> 33 | Z3: =COUNTIF(Z4:Z600, "apagado") -> 37 | AA3: =COUNTIF(AA4:AA600, "apagado") -> 27 | AB3: =COUNTIF(AB4:AB600, "apagado") -> 52 | AC3: =COUNTIF(AC4:AC600, "apagado") -> 0 | AD3: =COUNTIF(AD4:AD600, "apagado") -> 0 | AE3: =COUNTIF(AE4:AE600, "apagado") -> 0 | AF3: =COUNTIF(AF4:AF600, "apagado") -> 0 | AG3: =COUNTIF(AG4:AG600, "apagado") -> 0 | ... AP3: =COUNTIF(AP4:AP600, "apagado") -> 0
A4: Barrio | B4: [Denominacion] | C4: [Empresa Mantenimiento] | D4: [Ubicacion] | E4: [Tipo de Camara] | F4: [Tipo de Conexion] | G4: Destino | I4: DIAS FUNCIONANDO | J4: DIAS CAIDA | K4: EFECTIVIDAD | L4: 45139 | M4: 45140 | N4: 45141 | O4: 45142 | P4: 45143 | Q4: 45144 | R4: 45145 | S4: 45146 | T4: 45147 | U4: 45148 | V4: 45149 | W4: 45150 | X4: 45151 | Y4: 45152 | Z4: 45153 | AA4: 45154 | AB4: 45155 | AC4: 45156 | AD4: 45157 | AE4: 45158 | AF4: 45159 | AG4: 45160 | AH4: 45161 | AI4: 45162 | AJ4: 45163 | AK4: 45164 | AL4: 45165 | AM4: 45166 | AN4: 45167 | AO4: 45168 | AP4: 45169
A5: ALTAMIRA | B5: ALT01 | C5: BONOMO | D5: Calchaqui y Sgto. Cabral | E5: Domo | F5: Fibra Optica | H5: 172.20.10.6 | I5: =COUNTIF(L5:AM5,"") -> 27 | J5: =COUNTIF(L5:AM5,"APAGADO") -> 1 | K5: =(I5)/(J5+I5) -> 0.96428571 | O5: APAGADO
A6: ALTAMIRA | B6: ALT02 | C6: BONOMO | D6: Calchaqui y Lope de Vega | E6: Domo | F6: PTO A FO | G6: CABRAL Y CALCHAQUI | H6: 172.20.12.218 | I6: =COUNTIF(L6:AM6,"") -> 26 | J6: =COUNTIF(L6:AM6,"APAGADO") -> 2 | K6: =(I6)/(J6+I6) -> 0.92857143 | O6: APAGADO | Q6: APAGADO
A7: ALTAMIRA | B7: ALT 03 | C7: BONOMO | D7: Bombero Galarza y Necochea | E7: Domo | F7: Fibra Optica | H7: 172.20.12.54 | I7: =COUNTIF(L7:AM7,"") -> 27 | J7: =COUNTIF(L7:AM7,"APAGADO") -> 1 | K7: =(I7)/(J7+I7) -> 0.96428571 | O7: APAGADO
A8: ALTAMIRA | B8: ALT 04 | C8: BONOMO | D8: Francia y Necochea | E8: Domo | F8: Fibra Optica | H8: 172.20.12.55 | I8: =COUNTIF(L8:AM8,"") -> 27 | J8: =COUNTIF(L8:AM8,"APAGADO") -> 1 | K8: =(I8)/(J8+I8) -> 0.96428571 | O8: APAGADO
A9: ALTAMIRA | B9: ALT05 | C9: BONOMO | D9: Av. Calchaqui y Bombero Galarza | E9: Domo | F9: PTO A FO | G9: NECOCHEA Y GALARZA | H9: 172.20.12.216 | I9: =COUNTIF(L9:AM9,"") -> 27 | J9: =COUNTIF(L9:AM9,"APAGADO") -> 1 | K9: =(I9)/(J9+I9) -> 0.96428571 | O9: APAGADO
A10: ALTAMIRA | B10: ALT 06 | C10: BONOMO | D10: LOPE DE VEGA Y NECOCHEA | E10: Domo | F10: PTO A FO | G10: NECOCHEA Y GALARZA | H10: 172.20.12.12 | I10: =COUNTIF(L10:AM10,"") -> 27 | J10: =COUNTIF(L10:AM10,"APAGADO") -> 1 | K10: =(I10)/(J10+I10) -> 0.96428571 | O10: APAGADO
A11: ALTAMIRA | B11: ALT07 | C11: BONOMO | D11: AV. CALCHAQUI Y AV. DEL TRABAJO | E11: DOMO | F11: PTO A FO | G11: CABRAL Y CALCHAQUI | H11: 172.20.10.57 | I11: =COUNTIF(L11:AM11,"") -> 27 | J11: =COUNTIF(L11:AM11,"APAGADO") -> 1 | K11: =(I11)/(J11+I11) -> 0.96428571 | O11: APAGADO
A12: ALTAMIRA | B12: ALT 08 | C12: BONOMO | D12: HUMAITA Y NECOCHEA | E12: DOMO | F12: Fibra Optica | H12: 172.20.11.215 | I12: =COUNTIF(L12:AM12,"") -> 27 | J12: =COUNTIF(L12:AM12,"APAGADO") -> 1 | K12: =(I12)/(J12+I12) -> 0.96428571 | O12: APAGADO
A13: ALTAMIRA | B13: ALT 09 | C13: BONOMO | D13: NECOCHEA Y CURUPAITY | E13: DOMO | F13: Fibra Optica | H13: 172.20.11.216 | I13: =COUNTIF(L13:AM13,"") -> 27 | J13: =COUNTIF(L13:AM13,"APAGADO") -> 1 | K13: =(I13)/(J13+I13) -> 0.96428571 | O13: APAGADO
A14: ALTAMIRA | B14: ALT 10 | C14: BONOMO | D14: Calchaqui y Francia | E14: Domo | F14: Radio | H14: 172.20.12.156 | I14: =COUNTIF(L14:AM14,"") -> 27 | J14: =COUNTIF(L14:AM14,"APAGADO") -> 1 | K14: =(I14)/(J14+I14) -> 0.96428571 | O14: APAGADO
A15: AGUSTIN RAMIREZ | B15: ARA 01 | C15: COSEIDI | D15: Malambo y Tranquera | E15: Domo | F15: Fibra Optica | H15: 172.20.12.110 | I15: =COUNTIF(L15:AM15,"") -> 12 | J15: =COUNTIF(L15:AM15,"APAGADO") -> 16 | K15: =(I15)/(J15+I15) -> 0.42857143 | L15: APAGADO | M15: APAGADO | N15: APAGADO | O15: APAGADO | Q15: APAGADO | R15: APAGADO | S15: APAGADO | T15: APAGADO | U15: APAGADO | V15: APAGADO | W15: APAGADO | X15: APAGADO | Y15: APAGADO | Z15: APAGADO | AA15: APAGADO | AB15: APAGADO
A16: BELGRANO | B16: BEL 01 | C16: BONOMO | D16: San Martin y Dardo Rocha | E16: DOMO | F16: Fibra Optica | H16: 172.20.12.64 | I16: =COUNTIF(L16:AM16,"") -> 28 | J16: =COUNTIF(L16:AM16,"APAGADO") -> 0 | K16: =(I16)/(J16+I16) -> 1
A17: BELGRANO | B17: BEL 02 | C17: BONOMO | D17: Guardia vieja y Fronteriz | E17: DOMO | F17: Fibra Optica | I17: =COUNTIF(L17:AM17,"") -> 28 | J17: =COUNTIF(L17:AM17,"APAGADO") -> 0 | K17: =(I17)/(J17+I17) -> 1
A18: BOSQUES CENTRO | B18: BOSQC 01 | C18: COSEIDI | D18: LUIS AGOTE E/DANUNCIO Y CAMPOAMOR | E18: Fija | F18: Radio | H18: 172.20.11.15 | I18: =COUNTIF(L18:AM18,"") -> 27 | J18: =COUNTIF(L18:AM18,"APAGADO") -> 1 | K18: =(I18)/(J18+I18) -> 0.96428571 | W18: APAGADO
A19: BOSQUES CENTRO | B19: BOSQC 02 | C19: COSEIDI | D19: LUIS AGOTE E/DANUNCIO Y CAMPOAMOR | E19: Fija | F19: Radio | H19: 172.20.11.16 | I19: =COUNTIF(L19:AM19,"") -> 27 | J19: =COUNTIF(L19:AM19,"APAGADO") -> 1 | K19: =(I19)/(J19+I19) -> 0.96428571 | W19: APAGADO
A20: BOSQUES CENTRO | B20: BOSQC 03 | C20: COSEIDI | D20: BENAVENTE Y LUIS AGOTE | E20: Fija | F20: Radio | H20: 172.20.11.13 | I20: =COUNTIF(L20:AM20,"") -> 27 | J20: =COUNTIF(L20:AM20,"APAGADO") -> 1 | K20: =(I20)/(J20+I20) -> 0.96428571 | W20: APAGADO
A21: BOSQUES CENTRO | B21: BOSQC 04 | C21: COSEIDI | D21: BENAVENTE Y LUIS AGOTE | E21: Fija | F21: Radio | H21: 172.20.11.113 | I21: =COUNTIF(L21:AM21,"") -> 27 | J21: =COUNTIF(L21:AM21,"APAGADO") -> 1 | K21: =(I21)/(J21+I21) -> 0.96428571 | W21: APAGADO
A22: BOSQUES CENTRO | B22: BOSQC 05 | C22: COSEIDI | D22: LUIS AGOTE Y RUTA 36 | E22: Fija | F22: Radio | H22: 172.20.11.17 | I22: =COUNTIF(L22:AM22,"") -> 27 | J22: =COUNTIF(L22:AM22,"APAGADO") -> 1 | K22: =(I22)/(J22+I22) -> 0.96428571 | W22: APAGADO
A23: BOSQUES CENTRO | B23: BOSQC 06 | C23: COSEIDI | D23: LUIS AGOTE Y RUTA 36 | E23: Fija | F23: Radio | H23: 172.20.11.18 | I23: =COUNTIF(L23:AM23,"") -> 27 | J23: =COUNTIF(L23:AM23,"APAGADO") -> 1 | K23: =(I23)/(J23+I23) -> 0.96428571 | W23: APAGADO
A24: CENTRO | B24: CEN01 | C24: BONOMO | D24: San Martin y 9 de Julio | E24: Fija | F24: Fibra Optica | H24: 172.20.11.10 | I24: =COUNTIF(L24:AM24,"") -> 28 | J24: =COUNTIF(L24:AM24,"APAGADO") -> 0 | K24: =(I24)/(J24+I24) -> 1
A25: CENTRO | B25: CEN02 | C25: BONOMO | D25: San Martin y Almafuerte | E25: Fija | F25: Fibra Optica | H25: 172.20.11.11 | I25: =COUNTIF(L25:AM25,"") -> 28 | J25: =COUNTIF(L25:AM25,"APAGADO") -> 0 | K25: =(I25)/(J25+I25) -> 1
A26: CENTRO | B26: CEN03 | C26: BONOMO | D26: San Martin y Sallares | E26: Domo | F26: Fibra Optica | H26: 172.20.12.30 | I26: =COUNTIF(L26:AM26,"") -> 28 | J26: =COUNTIF(L26:AM26,"APAGADO") -> 0 | K26: =(I26)/(J26+I26) -> 1
A27: CENTRO | B27: CEN04 | C27: BONOMO | D27: San Martin y Contreras | E27: Domo | F27: Fibra Optica | H27: 172.20.12.29 | I27: =COUNTIF(L27:AM27,"") -> 28 | J27: =COUNTIF(L27:AM27,"APAGADO") -> 0 | K27: =(I27)/(J27+I27) -> 1
A28: CENTRO | B28: CEN 05 | C28: BONOMO | D28: Bocuzzi e/España y San Martin | E28: DOMO | F28: Fibra Optica | H28: 172.20.10.200 | I28: =COUNTIF(L28:AM28,"") -> 27 | J28: =COUNTIF(L28:AM28,"APAGADO") -> 1 | K28: =(I28)/(J28+I28) -> 0.96428571 | Z28: APAGADO
A29: CENTRO | B29: CEN06 | C29: BONOMO | D29: Monteagudo y A.del Valle | E29: Fija | F29: Fibra Optica | H29: 172.20.10.02 | I29: =COUNTIF(L29:AM29,"") -> 28 | J29: =COUNTIF(L29:AM29,"APAGADO") -> 0 | K29: =(I29)/(J29+I29) -> 1
A30: CENTRO | B30: CEN07 | C30: BONOMO | D30: San Martin y Guemes | E30: DOMO | F30: Fibra Optica | H30: 172.20.11.20 | I30: =COUNTIF(L30:AM30,"") -> 28 | J30: =COUNTIF(L30:AM30,"APAGADO") -> 0 | K30: =(I30)/(J30+I30) -> 1
A31: CENTRO | B31: CEN08 | C31: BONOMO | D31: San Martin y Pte.Peron | E31: Domo | F31: Fibra Optica | H31: 172.20.11.21 | I31: =COUNTIF(L31:AM31,"") -> 28 | J31: =COUNTIF(L31:AM31,"APAGADO") -> 0 | K31: =(I31)/(J31+I31) -> 1
A32: CENTRO | B32: CEN09 | C32: BONOMO | D32: Chacabuco y 25 de Mayo | E32: Domo | F32: Fibra Optica | H32: 172.20.11.22 | I32: =COUNTIF(L32:AM32,"") -> 28 | J32: =COUNTIF(L32:AM32,"APAGADO") -> 0 | K32: =(I32)/(J32+I32) -> 1
A33: CENTRO | B33: CEN10 | C33: BONOMO | D33: Monteagudo y Pte. Peron | E33: Domo | F33: Fibra Optica | H33: 172.20.11.23 | I33: =COUNTIF(L33:AM33,"") -> 28 | J33: =COUNTIF(L33:AM33,"APAGADO") -> 0 | K33: =(I33)/(J33+I33) -> 1
A34: CENTRO | B34: CEN11 | C34: BONOMO | D34: Monteagudo y Bocuzzi | E34: Domo | F34: Fibra Optica | H34: 172.20.10.24 | I34: =COUNTIF(L34:AM34,"") -> 28 | J34: =COUNTIF(L34:AM34,"APAGADO") -> 0 | K34: =(I34)/(J34+I34) -> 1
A35: CENTRO | B35: CEN 12 | C35: BONOMO | D35: Monteagudo y Mitre | E35: Domo | F35: Fibra Optica | H35: 172.20.10.23 | I35: =COUNTIF(L35:AM35,"") -> 28 | J35: =COUNTIF(L35:AM35,"APAGADO") -> 0 | K35: =(I35)/(J35+I35) -> 1
A36: CENTRO | B36: CEN 13 | C36: BONOMO | D36: 25 de Mayo y Maipu | E36: DOMO | F36: Fibra Optica | H36: 172.20.10.20 | I36: =COUNTIF(L36:AM36,"") -> 28 | J36: =COUNTIF(L36:AM36,"APAGADO") -> 0 | K36: =(I36)/(J36+I36) -> 1
A37: CENTRO | B37: CEN14 | C37: BONOMO | D37: Pte.Peron e/Pringles y Brown | E37: Domo | F37: Fibra Optica | H37: 172.20.10.21 | I37: =COUNTIF(L37:AM37,"") -> 28 | J37: =COUNTIF(L37:AM37,"APAGADO") -> 0 | K37: =(I37)/(J37+I37) -> 1
A38: CENTRO | B38: CEN15 | C38: BONOMO | D38: Alberdi y A.del Valle | E38: Domo | F38: Fibra Optica | H38: 172.20.10.35 | I38: =COUNTIF(L38:AM38,"") -> 28 | J38: =COUNTIF(L38:AM38,"APAGADO") -> 0 | K38: =(I38)/(J38+I38) -> 1
A39: CENTRO | B39: CEN16 | C39: BONOMO | D39: San Martin y Pte. Peron | E39: Fija | F39: Fibra Optica | H39: 172.20.12.36 | I39: =COUNTIF(L39:AM39,"") -> 28 | J39: =COUNTIF(L39:AM39,"APAGADO") -> 0 | K39: =(I39)/(J39+I39) -> 1
A40: CENTRO | B40: CEN17 | C40: BONOMO | D40: San Martin y Mitre | E40: Domo | F40: PTO A FO | G40: SAN MARTIN Y SALLARES | H40: 172.20.12.200 | I40: =COUNTIF(L40:AM40,"") -> 26 | J40: =COUNTIF(L40:AM40,"APAGADO") -> 2 | K40: =(I40)/(J40+I40) -> 0.92857143 | U40: APAGADO | V40: APAGADO
...

Sheet ESTADISTICA
A1: ='RESUMEN TOTAL'!A4 -> Barrio | B1: ='RESUMEN TOTAL'!B4 -> [Denominacion] | C1: ='RESUMEN TOTAL'!D4 -> [Ubicacion] | D1: ='RESUMEN TOTAL'!E4 -> [Tipo de Camara] | E1: ='RESUMEN TOTAL'!F4 -> [Tipo de Conexion] | F1: ='RESUMEN TOTAL'!L4 -> 45139 | G1: ='RESUMEN TOTAL'!M4 -> 45140 | H1: ='RESUMEN TOTAL'!N4 -> 45141 | I1: ='RESUMEN TOTAL'!O4 -> 45142 | J1: ='RESUMEN TOTAL'!P4 -> 45143 | K1: ='RESUMEN TOTAL'!Q4 -> 45144 | L1: ='RESUMEN TOTAL'!R4 -> 45145 | M1: ='RESUMEN TOTAL'!S4 -> 45146 | ... AI1: ='RESUMEN TOTAL'!AO4 -> 45168 | AJ1: ='RESUMEN TOTAL'!#REF! -> #REF!
A2: ='RESUMEN TOTAL'!A5 -> ALTAMIRA | B2: ='RESUMEN TOTAL'!B5 -> ALT01 | C2: ='RESUMEN TOTAL'!D5 -> Calchaqui y Sgto. Cabral | D2: ='RESUMEN TOTAL'!E5 -> Domo | E2: ='RESUMEN TOTAL'!F5 -> Fibra Optica | F2: ='RESUMEN TOTAL'!L5 -> 0 | G2: ='RESUMEN TOTAL'!M5 -> 0 | H2: ='RESUMEN TOTAL'!N5 -> 0 | I2: ='RESUMEN TOTAL'!O5 -> APAGADO | J2: ='RESUMEN TOTAL'!P5 -> 0 | K2: ='RESUMEN TOTAL'!Q5 -> 0 | L2: ='RESUMEN TOTAL'!R5 -> 0 | M2: ='RESUMEN TOTAL'!S5 -> 0 | ... AI2: ='RESUMEN TOTAL'!AO5 -> 0 | AJ2: ='RESUMEN TOTAL'!#REF! -> #REF!
A3: ='RESUMEN TOTAL'!A6 -> ALTAMIRA | B3: ='RESUMEN TOTAL'!B6 -> ALT02 | C3: ='RESUMEN TOTAL'!D6 -> Calchaqui y Lope de Vega | D3: ='RESUMEN TOTAL'!E6 -> Domo | E3: ='RESUMEN TOTAL'!F6 -> PTO A FO | F3: ='RESUMEN TOTAL'!L6 -> 0 | G3: ='RESUMEN TOTAL'!M6 -> 0 | H3: ='RESUMEN TOTAL'!N6 -> 0 | I3: ='RESUMEN TOTAL'!O6 -> APAGADO | J3: ='RESUMEN TOTAL'!P6 -> 0 | K3: ='RESUMEN TOTAL'!Q6 -> APAGADO | L3: ='RESUMEN TOTAL'!R6 -> 0 | M3: ='RESUMEN TOTAL'!S6 -> 0 | ... AI3: ='RESUMEN TOTAL'!AO6 -> 0 | AJ3: ='RESUMEN TOTAL'!#REF! -> #REF!
A4: ='RESUMEN TOTAL'!A7 -> ALTAMIRA | B4: ='RESUMEN TOTAL'!B7 -> ALT 03 | C4: ='RESUMEN TOTAL'!D7 -> Bombero Galarza y Necochea | D4: ='RESUMEN TOTAL'!E7 -> Domo | E4: ='RESUMEN TOTAL'!F7 -> Fibra Optica | F4: ='RESUMEN TOTAL'!L7 -> 0 | G4: ='RESUMEN TOTAL'!M7 -> 0 | H4: ='RESUMEN TOTAL'!N7 -> 0 | I4: ='RESUMEN TOTAL'!O7 -> APAGADO | J4: ='RESUMEN TOTAL'!P7 -> 0 | K4: ='RESUMEN TOTAL'!Q7 -> 0 | L4: ='RESUMEN TOTAL'!R7 -> 0 | M4: ='RESUMEN TOTAL'!S7 -> 0 | ... AI4: ='RESUMEN TOTAL'!AO7 -> 0 | AJ4: ='RESUMEN TOTAL'!#REF! -> #REF!
A5: ='RESUMEN TOTAL'!A8 -> ALTAMIRA | B5: ='RESUMEN TOTAL'!B8 -> ALT 04 | C5: ='RESUMEN TOTAL'!D8 -> Francia y Necochea | D5: ='RESUMEN TOTAL'!E8 -> Domo | E5: ='RESUMEN TOTAL'!F8 -> Fibra Optica | F5: ='RESUMEN TOTAL'!L8 -> 0 | G5: ='RESUMEN TOTAL'!M8 -> 0 | H5: ='RESUMEN TOTAL'!N8 -> 0 | I5: ='RESUMEN TOTAL'!O8 -> APAGADO | J5: ='RESUMEN TOTAL'!P8 -> 0 | K5: ='RESUMEN TOTAL'!Q8 -> 0 | L5: ='RESUMEN TOTAL'!R8 -> 0 | M5: ='RESUMEN TOTAL'!S8 -> 0 | ... AI5: ='RESUMEN TOTAL'!AO8 -> 0 | AJ5: ='RESUMEN TOTAL'!#REF! -> #REF!
A6: ='RESUMEN TOTAL'!A9 -> ALTAMIRA | B6: ='RESUMEN TOTAL'!B9 -> ALT05 | C6: ='RESUMEN TOTAL'!D9 -> Av. Calchaqui y Bombero Galarza | D6: ='RESUMEN TOTAL'!E9 -> Domo | E6: ='RESUMEN TOTAL'!F9 -> PTO A FO | F6: ='RESUMEN TOTAL'!L9 -> 0 | G6: ='RESUMEN TOTAL'!M9 -> 0 | H6: ='RESUMEN TOTAL'!N9 -> 0 | I6: ='RESUMEN TOTAL'!O9 -> APAGADO | J6: ='RESUMEN TOTAL'!P9 -> 0 | K6: ='RESUMEN TOTAL'!Q9 -> 0 | L6: ='RESUMEN TOTAL'!R9 -> 0 | M6: ='RESUMEN TOTAL'!S9 -> 0 | ... AI6: ='RESUMEN TOTAL'!AO9 -> 0 | AJ6: ='RESUMEN TOTAL'!#REF! -> #REF!
A7: ='RESUMEN TOTAL'!A10 -> ALTAMIRA | B7: ='RESUMEN TOTAL'!B10 -> ALT 06 | C7: ='RESUMEN TOTAL'!D10 -> LOPE DE VEGA Y NECOCHEA | D7: ='RESUMEN TOTAL'!E10 -> Domo | E7: ='RESUMEN TOTAL'!F10 -> PTO A FO | F7: ='RESUMEN TOTAL'!L10 -> 0 | G7: ='RESUMEN TOTAL'!M10 -> 0 | H7: ='RESUMEN TOTAL'!N10 -> 0 | I7: ='RESUMEN TOTAL'!O10 -> APAGADO | J7: ='RESUMEN TOTAL'!P10 -> 0 | K7: ='RESUMEN TOTAL'!Q10 -> 0 | L7: ='RESUMEN TOTAL'!R10 -> 0 | M7: ='RESUMEN TOTAL'!S10 -> 0 | ... AI7: ='RESUMEN TOTAL'!AO10 -> 0 | AJ7: ='RESUMEN TOTAL'!#REF! -> #REF!
A8: ='RESUMEN TOTAL'!A11 -> ALTAMIRA | B8: ='RESUMEN TOTAL'!B11 -> ALT07 | C8: ='RESUMEN TOTAL'!D11 -> AV. CALCHAQUI Y AV. DEL TRABAJO | D8: ='RESUMEN TOTAL'!E11 -> DOMO | E8: ='RESUMEN TOTAL'!F11 -> PTO A FO | F8: ='RESUMEN TOTAL'!L11 -> 0 | G8: ='RESUMEN TOTAL'!M11 -> 0 | H8: ='RESUMEN TOTAL'!N11 -> 0 | I8: ='RESUMEN TOTAL'!O11 -> APAGADO | J8: ='RESUMEN TOTAL'!P11 -> 0 | K8: ='RESUMEN TOTAL'!Q11 -> 0 | L8: ='RESUMEN TOTAL'!R11 -> 0 | M8: ='RESUMEN TOTAL'!S11 -> 0 | ... AI8: ='RESUMEN TOTAL'!AO11 -> 0 | AJ8: ='RESUMEN TOTAL'!#REF! -> #REF!
A9: ='RESUMEN TOTAL'!A12 -> ALTAMIRA | B9: ='RESUMEN TOTAL'!B12 -> ALT 08 | C9: ='RESUMEN TOTAL'!D12 -> HUMAITA Y NECOCHEA | D9: ='RESUMEN TOTAL'!E12 -> DOMO | E9: ='RESUMEN TOTAL'!F12 -> Fibra Optica | F9: ='RESUMEN TOTAL'!L12 -> 0 | G9: ='RESUMEN TOTAL'!M12 -> 0 | H9: ='RESUMEN TOTAL'!N12 -> 0 | I9: ='RESUMEN TOTAL'!O12 -> APAGADO | J9: ='RESUMEN TOTAL'!P12 -> 0 | K9: ='RESUMEN TOTAL'!Q12 -> 0 | L9: ='RESUMEN TOTAL'!R12 -> 0 | M9: ='RESUMEN TOTAL'!S12 -> 0 | ... AI9: ='RESUMEN TOTAL'!AO12 -> 0 | AJ9: ='RESUMEN TOTAL'!#REF! -> #REF!
A10: ='RESUMEN TOTAL'!A13 -> ALTAMIRA | B10: ='RESUMEN TOTAL'!B13 -> ALT 09 | C10: ='RESUMEN TOTAL'!D13 -> NECOCHEA Y CURUPAITY | D10: ='RESUMEN TOTAL'!E13 -> DOMO | E10: ='RESUMEN TOTAL'!F13 -> Fibra Optica | F10: ='RESUMEN TOTAL'!L13 -> 0 | G10: ='RESUMEN TOTAL'!M13 -> 0 | H10: ='RESUMEN TOTAL'!N13 -> 0 | I10: ='RESUMEN TOTAL'!O13 -> APAGADO | J10: ='RESUMEN TOTAL'!P13 -> 0 | K10: ='RESUMEN TOTAL'!Q13 -> 0 | L10: ='RESUMEN TOTAL'!R13 -> 0 | M10: ='RESUMEN TOTAL'!S13 -> 0 | ... AI10: ='RESUMEN TOTAL'!AO13 -> 0 | AJ10: ='RESUMEN TOTAL'!#REF! -> #REF!
A11: ='RESUMEN TOTAL'!A14 -> ALTAMIRA | B11: ='RESUMEN TOTAL'!B14 -> ALT 10 | C11: ='RESUMEN TOTAL'!D14 -> Calchaqui y Francia | D11: ='RESUMEN TOTAL'!E14 -> Domo | E11: ='RESUMEN TOTAL'!F14 -> Radio | F11: ='RESUMEN TOTAL'!L14 -> 0 | G11: ='RESUMEN TOTAL'!M14 -> 0 | H11: ='RESUMEN TOTAL'!N14 -> 0 | I11: ='RESUMEN TOTAL'!O14 -> APAGADO | J11: ='RESUMEN TOTAL'!P14 -> 0 | K11: ='RESUMEN TOTAL'!Q14 -> 0 | L11: ='RESUMEN TOTAL'!R14 -> 0 | M11: ='RESUMEN TOTAL'!S14 -> 0 | ... AI11: ='RESUMEN TOTAL'!AO14 -> 0 | AJ11: ='RESUMEN TOTAL'!#REF! -> #REF!
A12: ='RESUMEN TOTAL'!A15 -> AGUSTIN RAMIREZ | B12: ='RESUMEN TOTAL'!B15 -> ARA 01 | C12: ='RESUMEN TOTAL'!D15 -> Malambo y Tranquera | D12: ='RESUMEN TOTAL'!E15 -> Domo | E12: ='RESUMEN TOTAL'!F15 -> Fibra Optica | F12: ='RESUMEN TOTAL'!L15 -> APAGADO | G12: ='RESUMEN TOTAL'!M15 -> APAGADO | H12: ='RESUMEN TOTAL'!N15 -> APAGADO | I12: ='RESUMEN TOTAL'!O15 -> APAGADO | J12: ='RESUMEN TOTAL'!P15 -> 0 | K12: ='RESUMEN TOTAL'!Q15 -> APAGADO | L12: ='RESUMEN TOTAL'!R15 -> APAGADO | M12: ='RESUMEN TOTAL'!S15 -> APAGADO | ... AI12: ='RESUMEN TOTAL'!AO15 -> 0 | AJ12: ='RESUMEN TOTAL'!#REF! -> #REF!
... A464: ='RESUMEN TOTAL'!A467 -> PARADAS SEGURAS | B464: ='RESUMEN TOTAL'!B467 -> 26 | C464: ='RESUMEN TOTAL'!D467 -> HUDSON Y RIO COLORADO OESTE | D464: ='RESUMEN TOTAL'!E467 -> GFIJA | E464: ='RESUMEN TOTAL'!F467 -> GPON | F464: ='RESUMEN TOTAL'!L467 -> 0 | G464: ='RESUMEN TOTAL'!M467 -> 0 | H464: ='RESUMEN TOTAL'!N467 -> 0 | I464: ='RESUMEN TOTAL'!O467 -> 0 | J464: ='RESUMEN TOTAL'!P467 -> 0 | K464: ='RESUMEN TOTAL'!Q467 -> 0 | L464: ='RESUMEN TOTAL'!R467 -> 0 | M464: ='RESUMEN TOTAL'!S467 -> 0 | ... AI464: ='RESUMEN TOTAL'!AO467 -> 0 | AJ464: ='RESUMEN TOTAL'!#REF! -> #REF!
A465: ='RESUMEN TOTAL'!A468 -> PARADAS SEGURAS | B465: ='RESUMEN TOTAL'!B468 -> 26 I | C465: ='RESUMEN TOTAL'!D469 -> HUDON Y 818 ESTE | D465: ='RESUMEN TOTAL'!E468 -> INTERCOMUNICADOR | E465: ='RESUMEN TOTAL'!F468 -> GPON | F465: ='RESUMEN TOTAL'!L468 -> 0 | G465: ='RESUMEN TOTAL'!M468 -> 0 | H465: ='RESUMEN TOTAL'!N468 -> 0 | I465: ='RESUMEN TOTAL'!O468 -> 0 | J465: ='RESUMEN TOTAL'!P468 -> 0 | K465: ='RESUMEN TOTAL'!Q468 -> 0 | L465: ='RESUMEN TOTAL'!R468 -> 0 | M465: ='RESUMEN TOTAL'!S468 -> 0 | ... AI465: ='RESUMEN TOTAL'!AO468 -> 0 | AJ465: ='RESUMEN TOTAL'!#REF! -> #REF!
A466: ='RESUMEN TOTAL'!A469 -> PARADAS SEGURAS | B466: ='RESUMEN TOTAL'!B469 -> 27 | C466: ='RESUMEN TOTAL'!D471 -> HUDSON Y RIO TRAFUL OESTE | D466: ='RESUMEN TOTAL'!E469 -> GFIJA | E466: ='RESUMEN TOTAL'!F469 -> GPON | F466: ='RESUMEN TOTAL'!L469 -> 0 | G466: ='RESUMEN TOTAL'!M469 -> 0 | H466: ='RESUMEN TOTAL'!N469 -> 0 | I466: ='RESUMEN TOTAL'!O469 -> 0 | J466: ='RESUMEN TOTAL'!P469 -> 0 | K466: ='RESUMEN TOTAL'!Q469 -> 0 | L466: ='RESUMEN TOTAL'!R469 -> 0 | M466: ='RESUMEN TOTAL'!S469 -> 0 | ... AI466: ='RESUMEN TOTAL'!AO469 -> 0 | AJ466: ='RESUMEN TOTAL'!#REF! -> #REF!
A467: ='RESUMEN TOTAL'!A470 -> PARADAS SEGURAS | B467: ='RESUMEN TOTAL'!B470 -> 27 I | C467: ='RESUMEN TOTAL'!D473 -> HUDSON Y ESTOMBA ESTE | D467: ='RESUMEN TOTAL'!E470 -> INTERCOMUNICADOR | E467: ='RESUMEN TOTAL'!F470 -> GPON | F467: ='RESUMEN TOTAL'!L470 -> 0 | G467: ='RESUMEN TOTAL'!M470 -> 0 | H467: ='RESUMEN TOTAL'!N470 -> 0 | I467: ='RESUMEN TOTAL'!O470 -> 0 | J467: ='RESUMEN TOTAL'!P470 -> 0 | K467: ='RESUMEN TOTAL'!Q470 -> 0 | L467: ='RESUMEN TOTAL'!R470 -> 0 | M467: ='RESUMEN TOTAL'!S470 -> 0 | ... AI467: ='RESUMEN TOTAL'!AO470 -> 0 | AJ467: ='RESUMEN TOTAL'!#REF! -> #REF!
A468: ='RESUMEN TOTAL'!A471 -> PARADAS SEGURAS | B468: ='RESUMEN TOTAL'!B471 -> 28 | C468: ='RESUMEN TOTAL'!D475 -> HUDSON Y PICHEUTA OESTE | D468: ='RESUMEN TOTAL'!E471 -> GFIJA | E468: ='RESUMEN TOTAL'!F471 -> GPON | F468: ='RESUMEN TOTAL'!L471 -> 0 | G468: ='RESUMEN TOTAL'!M471 -> 0 | H468: ='RESUMEN TOTAL'!N471 -> 0 | I468: ='RESUMEN TOTAL'!O471 -> 0 | J468: ='RESUMEN TOTAL'!P471 -> 0 | K468: ='RESUMEN TOTAL'!Q471 -> 0 | L468: ='RESUMEN TOTAL'!R471 -> 0 | M468: ='RESUMEN TOTAL'!S471 -> 0 | ... AI468: ='RESUMEN TOTAL'!AO471 -> 0 | AJ468: ='RESUMEN TOTAL'!#REF! -> #REF!
A469: ='RESUMEN TOTAL'!A472 -> PARADAS SEGURAS | B469: ='RESUMEN TOTAL'!B472 -> 28 I | C469: ='RESUMEN TOTAL'!D477 -> HUDSON Y 830 ESTE | D469: ='RESUMEN TOTAL'!E472 -> INTERCOMUNICADOR | E469: ='RESUMEN TOTAL'!F472 -> GPON | F469: ='RESUMEN TOTAL'!L472 -> 0 | G469: ='RESUMEN TOTAL'!M472 -> 0 | H469: ='RESUMEN TOTAL'!N472 -> 0 | I469: ='RESUMEN TOTAL'!O472 -> 0 | J469: ='RESUMEN TOTAL'!P472 -> 0 | K469: ='RESUMEN TOTAL'!Q472 -> 0 | L469: ='RESUMEN TOTAL'!R472 -> 0 | M469: ='RESUMEN TOTAL'!S472 -> 0 | ... AI469: ='RESUMEN TOTAL'!AO472 -> 0 | AJ469: ='RESUMEN TOTAL'!#REF! -> #REF!
A470: ='RESUMEN TOTAL'!A473 -> PARADAS SEGURAS | B470: ='RESUMEN TOTAL'!B473 -> 29 | C470: ='RESUMEN TOTAL'!#REF! -> #REF! | D470: ='RESUMEN TOTAL'!E473 -> GFIJA | E470: ='RESUMEN TOTAL'!F473 -> GPON | F470: ='RESUMEN TOTAL'!L473 -> 0 | G470: ='RESUMEN TOTAL'!M473 -> 0 | H470: ='RESUMEN TOTAL'!N473 -> 0 | I470: ='RESUMEN TOTAL'!O473 -> 0 | J470: ='RESUMEN TOTAL'!P473 -> 0 | K470: ='RESUMEN TOTAL'!Q473 -> 0 | L470: ='RESUMEN TOTAL'!R473 -> 0 | M470: ='RESUMEN TOTAL'!S473 -> 0 | ... AI470: ='RESUMEN TOTAL'!AO473 -> 0 | AJ470: ='RESUMEN TOTAL'!#REF! -> #REF!
A471: ='RESUMEN TOTAL'!A474 -> PARADAS SEGURAS | B471: ='RESUMEN TOTAL'!B474 -> 29 I | C471: ='RESUMEN TOTAL'!#REF! -> #REF! | D471: ='RESUMEN TOTAL'!E474 -> INTERCOMUNICADOR | E471: ='RESUMEN TOTAL'!F474 -> GPON | F471: ='RESUMEN TOTAL'!L474 -> 0 | G471: ='RESUMEN TOTAL'!M474 -> 0 | H471: ='RESUMEN TOTAL'!N474 -> 0 | I471: ='RESUMEN TOTAL'!O474 -> 0 | J471: ='RESUMEN TOTAL'!P474 -> 0 | K471: ='RESUMEN TOTAL'!Q474 -> 0 | L471: ='RESUMEN TOTAL'!R474 -> 0 | M471: ='RESUMEN TOTAL'!S474 -> 0 | ... AI471: ='RESUMEN TOTAL'!AO474 -> 0 | AJ471: ='RESUMEN TOTAL'!#REF! -> #REF!
A472: ='RESUMEN TOTAL'!A475 -> PARADAS SEGURAS | B472: ='RESUMEN TOTAL'!B475 -> 30 | C472: ='RESUMEN TOTAL'!#REF! -> #REF! | D472: ='RESUMEN TOTAL'!E475 -> GFIJA | E472: ='RESUMEN TOTAL'!F475 -> GPON | F472: ='RESUMEN TOTAL'!L475 -> 0 | G472: ='RESUMEN TOTAL'!M475 -> 0 | H472: ='RESUMEN TOTAL'!N475 -> 0 | I472: ='RESUMEN TOTAL'!O475 -> 0 | J472: ='RESUMEN TOTAL'!P475 -> 0 | K472: ='RESUMEN TOTAL'!Q475 -> 0 | L472: ='RESUMEN TOTAL'!R475 -> 0 | M472: ='RESUMEN TOTAL'!S475 -> 0 | ... AI472: ='RESUMEN TOTAL'!AO475 -> 0 | AJ472: ='RESUMEN TOTAL'!#REF! -> #REF!
A473: ='RESUMEN TOTAL'!A476 -> PARADAS SEGURAS | B473: ='RESUMEN TOTAL'!B476 -> 30 I | C473: ='RESUMEN TOTAL'!D476 -> HUDSON Y PICHEUTA OESTE | D473: ='RESUMEN TOTAL'!E476 -> INTERCOMUNICADOR | E473: ='RESUMEN TOTAL'!F476 -> GPON | F473: ='RESUMEN TOTAL'!L476 -> 0 | G473: ='RESUMEN TOTAL'!M476 -> 0 | H473: ='RESUMEN TOTAL'!N476 -> 0 | I473: ='RESUMEN TOTAL'!O476 -> 0 | J473: ='RESUMEN TOTAL'!P476 -> 0 | K473: ='RESUMEN TOTAL'!Q476 -> 0 | L473: ='RESUMEN TOTAL'!R476 -> 0 | M473: ='RESUMEN TOTAL'!S476 -> 0 | ... AI473: ='RESUMEN TOTAL'!AO476 -> 0 | AJ473: ='RESUMEN TOTAL'!#REF! -> #REF!
A474: ='RESUMEN TOTAL'!A477 -> PARADAS SEGURAS | B474: ='RESUMEN TOTAL'!B477 -> 31 | C474: ='RESUMEN TOTAL'!#REF! -> #REF! | D474: ='RESUMEN TOTAL'!E477 -> GFIJA | E474: ='RESUMEN TOTAL'!F477 -> GPON | F474: ='RESUMEN TOTAL'!L477 -> 0 | G474: ='RESUMEN TOTAL'!M477 -> 0 | H474: ='RESUMEN TOTAL'!N477 -> 0 | I474: ='RESUMEN TOTAL'!O477 -> 0 | J474: ='RESUMEN TOTAL'!P477 -> 0 | K474: ='RESUMEN TOTAL'!Q477 -> 0 | L474: ='RESUMEN TOTAL'!R477 -> 0 | M474: ='RESUMEN TOTAL'!S477 -> 0 | ... AI474: ='RESUMEN TOTAL'!AO477 -> 0 | AJ474: ='RESUMEN TOTAL'!#REF! -> #REF!
A475: ='RESUMEN TOTAL'!A478 -> PARADAS SEGURAS | B475: ='RESUMEN TOTAL'!B478 -> 31 I | C475: ='RESUMEN TOTAL'!#REF! -> #REF! | D475: ='RESUMEN TOTAL'!E478 -> INTERCOMUNICADOR | E475: ='RESUMEN TOTAL'!F478 -> GPON | F475: ='RESUMEN TOTAL'!L478 -> 0 | G475: ='RESUMEN TOTAL'!M478 -> 0 | H475: ='RESUMEN TOTAL'!N478 -> 0 | I475: ='RESUMEN TOTAL'!O478 -> 0 | J475: ='RESUMEN TOTAL'!P478 -> 0 | K475: ='RESUMEN TOTAL'!Q478 -> 0 | L475: ='RESUMEN TOTAL'!R478 -> 0 | M475: ='RESUMEN TOTAL'!S478 -> 0 | ... AI475: ='RESUMEN TOTAL'!AO478 -> 0 | AJ475: ='RESUMEN TOTAL'!#REF! -> #REF!
A476: ='RESUMEN TOTAL'!A479 -> PARADAS SEGURAS | B476: ='RESUMEN TOTAL'!B479 -> 32 | C476: ='RESUMEN TOTAL'!D479 -> Hudson y 834 oeste | D476: ='RESUMEN TOTAL'!E479 -> GFIJA | E476: ='RESUMEN TOTAL'!F479 -> GPON | F476: ='RESUMEN TOTAL'!L479 -> 0 | G476: ='RESUMEN TOTAL'!M479 -> 0 | H476: ='RESUMEN TOTAL'!N479 -> 0 | I476: ='RESUMEN TOTAL'!O479 -> 0 | J476: ='RESUMEN TOTAL'!P479 -> 0 | K476: ='RESUMEN TOTAL'!Q479 -> 0 | L476: ='RESUMEN TOTAL'!R479 -> 0 | M476: ='RESUMEN TOTAL'!S479 -> 0 | ... AI476: ='RESUMEN TOTAL'!AO479 -> 0 | AJ476: ='RESUMEN TOTAL'!#REF! -> #REF!
A477: ='RESUMEN TOTAL'!A480 -> PARADAS SEGURAS | B477: ='RESUMEN TOTAL'!B480 -> 32 I | C477: ='RESUMEN TOTAL'!D480 -> Hudson y 834 oeste | D477: ='RESUMEN TOTAL'!E480 -> INTERCOMUNICADOR | E477: ='RESUMEN TOTAL'!F480 -> GPON | F477: ='RESUMEN TOTAL'!L480 -> 0 | G477: ='RESUMEN TOTAL'!M480 -> 0 | H477: ='RESUMEN TOTAL'!N480 -> 0 | I477: ='RESUMEN TOTAL'!O480 -> APAGADO | J477: ='RESUMEN TOTAL'!P480 -> APAGADO | K477: ='RESUMEN TOTAL'!Q480 -> APAGADO | L477: ='RESUMEN TOTAL'!R480 -> APAGADO | M477: ='RESUMEN TOTAL'!S480 -> APAGADO | ... AI477: ='RESUMEN TOTAL'!AO480 -> 0 | AJ477: ='RESUMEN TOTAL'!#REF! -> #REF!
A478: ='RESUMEN TOTAL'!A481 -> PARADAS SEGURAS | B478: ='RESUMEN TOTAL'!B481 -> 33 C | C478: ='RESUMEN TOTAL'!D481 -> Hudson y Suipacha este | D478: ='RESUMEN TOTAL'!E481 -> GFIJA | E478: ='RESUMEN TOTAL'!F481 -> GPON | F478: ='RESUMEN TOTAL'!L481 -> 0 | G478: ='RESUMEN TOTAL'!M481 -> 0 | H478: ='RESUMEN TOTAL'!N481 -> 0 | I478: ='RESUMEN TOTAL'!O481 -> APAGADO | J478: ='RESUMEN TOTAL'!P481 -> APAGADO | K478: ='RESUMEN TOTAL'!Q481 -> APAGADO | L478: ='RESUMEN TOTAL'!R481 -> APAGADO | M478: ='RESUMEN TOTAL'!S481 -> APAGADO | ... AI478: ='RESUMEN TOTAL'!AO481 -> 0 | AJ478: ='RESUMEN TOTAL'!#REF! -> #REF!
A479: ='RESUMEN TOTAL'!A482 -> PARADAS SEGURAS | B479: ='RESUMEN TOTAL'!B482 -> 33 I | C479: ='RESUMEN TOTAL'!D482 -> Hudson y Suipacha este | D479: ='RESUMEN TOTAL'!E482 -> INTERCOMUNICADOR | E479: ='RESUMEN TOTAL'!F482 -> GPON | F479: ='RESUMEN TOTAL'!L482 -> 0 | G479: ='RESUMEN TOTAL'!M482 -> 0 | H479: ='RESUMEN TOTAL'!N482 -> 0 | I479: ='RESUMEN TOTAL'!O482 -> APAGADO | J479: ='RESUMEN TOTAL'!P482 -> APAGADO | K479: ='RESUMEN TOTAL'!Q482 -> APAGADO | L479: ='RESUMEN TOTAL'!R482 -> APAGADO | M479: ='RESUMEN TOTAL'!S482 -> APAGADO | ... AI479: ='RESUMEN TOTAL'!AO482 -> 0 | AJ479: ='RESUMEN TOTAL'!#REF! -> #REF!
A480: ='RESUMEN TOTAL'!A483 -> PARADAS SEGURAS | B480: ='RESUMEN TOTAL'!B483 -> 34 C | C480: ='RESUMEN TOTAL'!D483 -> Hudson y Suipacha oeste | D480: ='RESUMEN TOTAL'!E483 -> GFIJA | E480: ='RESUMEN TOTAL'!F483 -> GPON | F480: ='RESUMEN TOTAL'!L483 -> 0 | G480: ='RESUMEN TOTAL'!M483 -> 0 | H480: ='RESUMEN TOTAL'!N483 -> 0 | I480: ='RESUMEN TOTAL'!O483 -> 0 | J480: ='RESUMEN TOTAL'!P483 -> 0 | K480: ='RESUMEN TOTAL'!Q483 -> 0 | L480: ='RESUMEN TOTAL'!R483 -> 0 | M480: ='RESUMEN TOTAL'!S483 -> 0 | ... AI480: ='RESUMEN TOTAL'!AO483 -> 0 | AJ480: ='RESUMEN TOTAL'!#REF! -> #REF!
A481: ='RESUMEN TOTAL'!A484 -> PARADAS SEGURAS | B481: ='RESUMEN TOTAL'!B484 -> 34 I | C481: ='RESUMEN TOTAL'!D484 -> Hudson y Suipacha oeste | D481: ='RESUMEN TOTAL'!E484 -> INTERCOMUNICADOR | E481: ='RESUMEN TOTAL'!F484 -> GPON | F481: ='RESUMEN TOTAL'!L484 -> 0 | G481: ='RESUMEN TOTAL'!M484 -> 0 | H481: ='RESUMEN TOTAL'!N484 -> 0 | I481: ='RESUMEN TOTAL'!O484 -> APAGADO | J481: ='RESUMEN TOTAL'!P484 -> APAGADO | K481: ='RESUMEN TOTAL'!Q484 -> APAGADO | L481: ='RESUMEN TOTAL'!R484 -> APAGADO | M481: ='RESUMEN TOTAL'!S484 -> APAGADO | ... AI481: ='RESUMEN TOTAL'!AO484 -> 0 | AJ481: ='RESUMEN TOTAL'!#REF! -> #REF!
A482: ='RESUMEN TOTAL'!A485 -> PARADAS SEGURAS | B482: ='RESUMEN TOTAL'!B485 -> 35 C | C482: ='RESUMEN TOTAL'!D485 -> Hudson y Suipacha este | D482: ='RESUMEN TOTAL'!E485 -> GFIJA | E482: ='RESUMEN TOTAL'!F485 -> GPON | F482: ='RESUMEN TOTAL'!L485 -> 0 | G482: ='RESUMEN TOTAL'!M485 -> 0 | H482: ='RESUMEN TOTAL'!N485 -> 0 | I482: ='RESUMEN TOTAL'!O485 -> APAGADO | J482: ='RESUMEN TOTAL'!P485 -> APAGADO | K482: ='RESUMEN TOTAL'!Q485 -> APAGADO | L482: ='RESUMEN TOTAL'!R485 -> APAGADO | M482: ='RESUMEN TOTAL'!S485 -> APAGADO | ... AI482: ='RESUMEN TOTAL'!AO485 -> 0 | AJ482: ='RESUMEN TOTAL'!#REF! -> #REF!
A483: ='RESUMEN TOTAL'!A486 -> PARADAS SEGURAS | B483: ='RESUMEN TOTAL'!B486 -> 35 I | C483: ='RESUMEN TOTAL'!D486 -> Hudson y Suipacha este | D483: ='RESUMEN TOTAL'!E486 -> INTERCOMUNICADOR | E483: ='RESUMEN TOTAL'!F486 -> GPON | F483: ='RESUMEN TOTAL'!L486 -> 0 | G483: ='RESUMEN TOTAL'!M486 -> 0 | H483: ='RESUMEN TOTAL'!N486 -> 0 | I483: ='RESUMEN TOTAL'!O486 -> APAGADO | J483: ='RESUMEN TOTAL'!P486 -> APAGADO | K483: ='RESUMEN TOTAL'!Q486 -> APAGADO | L483: ='RESUMEN TOTAL'!R486 -> APAGADO | M483: ='RESUMEN TOTAL'!S486 -> APAGADO | ... AI483: ='RESUMEN TOTAL'!AO486 -> 0 | AJ483: ='RESUMEN TOTAL'!#REF! -> #REF!
A484: ='RESUMEN TOTAL'!A487 -> 0 | B484: ='RESUMEN TOTAL'!B487 -> 0 | C484: ='RESUMEN TOTAL'!D487 -> 0 | D484: ='RESUMEN TOTAL'!E487 -> 0 | E484: ='RESUMEN TOTAL'!F487 -> 0 | F484: ='RESUMEN TOTAL'!L487 -> 0 | G484: ='RESUMEN TOTAL'!M487 -> 0 | H484: ='RESUMEN TOTAL'!N487 -> 0 | I484: ='RESUMEN TOTAL'!O487 -> 0 | J484: ='RESUMEN TOTAL'!P487 -> 0 | K484: ='RESUMEN TOTAL'!Q487 -> 0 | L484: ='RESUMEN TOTAL'!R487 -> 0 | M484: ='RESUMEN TOTAL'!S487 -> 0 | ... AI484: ='RESUMEN TOTAL'!AO487 -> 0 | AJ484: ='RESUMEN TOTAL'!#REF! -> #REF!
A485: ='RESUMEN TOTAL'!A488 -> 0 | B485: ='RESUMEN TOTAL'!B488 -> 0 | C485: ='RESUMEN TOTAL'!D488 -> 0 | D485: ='RESUMEN TOTAL'!E488 -> 0 | E485: ='RESUMEN TOTAL'!F488 -> 0 | F485: ='RESUMEN TOTAL'!L488 -> 0 | G485: ='RESUMEN TOTAL'!M488 -> 0 | H485: ='RESUMEN TOTAL'!N488 -> 0 | I485: ='RESUMEN TOTAL'!O488 -> 0 | J485: ='RESUMEN TOTAL'!P488 -> 0 | K485: ='RESUMEN TOTAL'!Q488 -> 0 | L485: ='RESUMEN TOTAL'!R488 -> 0 | M485: ='RESUMEN TOTAL'!S488 -> 0 | ... AI485: ='RESUMEN TOTAL'!AO488 -> 0 | AJ485: ='RESUMEN TOTAL'!#REF! -> #REF!
A486: ='RESUMEN TOTAL'!A489 -> 0 | B486: ='RESUMEN TOTAL'!B489 -> 0 | C486: ='RESUMEN TOTAL'!D489 -> 0 | D486: ='RESUMEN TOTAL'!E489 -> 0 | E486: ='RESUMEN TOTAL'!F489 -> 0 | F486: ='RESUMEN TOTAL'!L489 -> 0 | G486: ='RESUMEN TOTAL'!M489 -> 0 | H486: ='RESUMEN TOTAL'!N489 -> 0 | I486: ='RESUMEN TOTAL'!O489 -> 0 | J486: ='RESUMEN TOTAL'!P489 -> 0 | K486: ='RESUMEN TOTAL'!Q489 -> 0 | L486: ='RESUMEN TOTAL'!R489 -> 0 | M486: ='RESUMEN TOTAL'!S489 -> 0 | ... AI486: ='RESUMEN TOTAL'!AO489 -> 0 | AJ486: ='RESUMEN TOTAL'!#REF! -> #REF!
A487: ='RESUMEN TOTAL'!A490 -> 0 | B487: ='RESUMEN TOTAL'!B490 -> 0 | C487: ='RESUMEN TOTAL'!D490 -> 0 | D487: ='RESUMEN TOTAL'!E490 -> 0 | E487: ='RESUMEN TOTAL'!F490 -> 0 | F487: ='RESUMEN TOTAL'!L490 -> 0 | G487: ='RESUMEN TOTAL'!M490 -> 0 | H487: ='RESUMEN TOTAL'!N490 -> 0 | I487: ='RESUMEN TOTAL'!O490 -> 0 | J487: ='RESUMEN TOTAL'!P490 -> 0 | K487: ='RESUMEN TOTAL'!Q490 -> 0 | L487: ='RESUMEN TOTAL'!R490 -> 0 | M487: ='RESUMEN TOTAL'!S490 -> 0 | ... AI487: ='RESUMEN TOTAL'!AO490 -> 0 | AJ487: ='RESUMEN TOTAL'!#REF! -> #REF!
... A638: ='RESUMEN TOTAL'!A641 -> 0 | B638: ='RESUMEN TOTAL'!B641 -> 0 | C638: ='RESUMEN TOTAL'!D641 -> 0 | D638: ='RESUMEN TOTAL'!E641 -> 0 | E638: ='RESUMEN TOTAL'!F641 -> 0 | F638: ='RESUMEN TOTAL'!L641 -> 0 | G638: ='RESUMEN TOTAL'!M641 -> 0 | H638: ='RESUMEN TOTAL'!N641 -> 0 | I638: ='RESUMEN TOTAL'!O641 -> 0 | J638: ='RESUMEN TOTAL'!P641 -> 0 | K638: ='RESUMEN TOTAL'!Q641 -> 0 | L638: ='RESUMEN TOTAL'!R641 -> 0 | M638: ='RESUMEN TOTAL'!S641 -> 0 | ... AI638: ='RESUMEN TOTAL'!AO641 -> 0 | AJ638: ='RESUMEN TOTAL'!#REF! -> #REF!

Sheet APAGADOS
E1: APAGADOS | F1: =COUNTIF(F3:F403, "APAGADO") -> 31 | G1: =COUNTIF(G3:G403, "APAGADO") -> 30 | H1: =COUNTIF(H3:H503, "APAGADO") -> 27 | I1: =COUNTIF(I3:I403, "APAGADO") -> 57 | J1: =COUNTIF(J3:J403, "APAGADO") -> 16 | K1: =COUNTIF(K3:K403, "APAGADO") -> 15 | L1: =COUNTIF(L3:L403, "APAGADO") -> 13 | M1: =COUNTIF(M3:M403, "APAGADO") -> 19 | N1: =COUNTIF(N3:N403, "APAGADO") -> 38 | O1: =COUNTIF(O3:O403, "APAGADO") -> 37 | P1: =COUNTIF(P3:P403, "APAGADO") -> 27 | ... AD1: =COUNTIF(AD3:AD403, "APAGADO") -> 0 | AE1: =COUNTIF(AE3:AE503, "APAGADO") -> 0 | AF1: =COUNTIF(AF3:AF403, "APAGADO") -> 0 | AG1: =COUNTIF(AG3:AG403, "APAGADO") -> 0 | AH1: =COUNTIF(AH3:AH403, "APAGADO") -> 0 | AI1: =COUNTIF(AI3:AI403, "APAGADO") -> 0 | AJ1: =COUNTIF(AJ3:AJ403, "APAGADO") -> 0
A2: =ESTADISTICA!A1 -> Barrio | B2: =ESTADISTICA!B1 -> [Denominacion] | C2: =ESTADISTICA!C1 -> [Ubicacion] | D2: =ESTADISTICA!D1 -> [Tipo de Camara] | E2: =ESTADISTICA!E1 -> [Tipo de Conexion] | F2: =ESTADISTICA!F1 -> 45139 | G2: =ESTADISTICA!G1 -> 45140 | H2: =ESTADISTICA!H1 -> 45141 | ... AJ2: =ESTADISTICA!AJ1 -> #REF!
A3: =ESTADISTICA!A2 -> ALTAMIRA | B3: =ESTADISTICA!B2 -> ALT01 | C3: =ESTADISTICA!C2 -> Calchaqui y Sgto. Cabral | D3: =ESTADISTICA!D2 -> Domo | E3: =ESTADISTICA!E2 -> Fibra Optica | F3: =ESTADISTICA!F2 -> 0 | G3: =ESTADISTICA!G2 -> 0 | H3: =ESTADISTICA!H2 -> 0 | ... AJ3: =ESTADISTICA!AJ2 -> #REF!
A4: =ESTADISTICA!A3 -> ALTAMIRA | B4: =ESTADISTICA!B3 -> ALT02 | C4: =ESTADISTICA!C3 -> Calchaqui y Lope de Vega | D4: =ESTADISTICA!D3 -> Domo | E4: =ESTADISTICA!E3 -> PTO A FO | F4: =ESTADISTICA!F3 -> 0 | G4: =ESTADISTICA!G3 -> 0 | H4: =ESTADISTICA!H3 -> 0 | ... AJ4: =ESTADISTICA!AJ3 -> #REF!
A5: =ESTADISTICA!A4 -> ALTAMIRA | B5: =ESTADISTICA!B4 -> ALT 03 | C5: =ESTADISTICA!C4 -> Bombero Galarza y Necochea | D5: =ESTADISTICA!D4 -> Domo | E5: =ESTADISTICA!E4 -> Fibra Optica | F5: =ESTADISTICA!F4 -> 0 | G5: =ESTADISTICA!G4 -> 0 | H5: =ESTADISTICA!H4 -> 0 | ... AJ5: =ESTADISTICA!AJ4 -> #REF!
A6: =ESTADISTICA!A5 -> ALTAMIRA | B6: =ESTADISTICA!B5 -> ALT 04 | C6: =ESTADISTICA!C5 -> Francia y Necochea | D6: =ESTADISTICA!D5 -> Domo | E6: =ESTADISTICA!E5 -> Fibra Optica | F6: =ESTADISTICA!F5 -> 0 | G6: =ESTADISTICA!G5 -> 0 | H6: =ESTADISTICA!H5 -> 0 | ... AJ6: =ESTADISTICA!AJ5 -> #REF!
A7: =ESTADISTICA!A6 -> ALTAMIRA | B7: =ESTADISTICA!B6 -> ALT05 | C7: =ESTADISTICA!C6 -> Av. Calchaqui y Bombero Galarza | D7: =ESTADISTICA!D6 -> Domo | E7: =ESTADISTICA!E6 -> PTO A FO | F7: =ESTADISTICA!F6 -> 0 | G7: =ESTADISTICA!G6 -> 0 | H7: =ESTADISTICA!H6 -> 0 | ... AJ7: =ESTADISTICA!AJ6 -> #REF!
A8: =ESTADISTICA!A7 -> ALTAMIRA | B8: =ESTADISTICA!B7 -> ALT 06 | C8: =ESTADISTICA!C7 -> LOPE DE VEGA Y NECOCHEA | D8: =ESTADISTICA!D7 -> Domo | E8: =ESTADISTICA!E7 -> PTO A FO | F8: =ESTADISTICA!F7 -> 0 | G8: =ESTADISTICA!G7 -> 0 | H8: =ESTADISTICA!H7 -> 0 | ... AJ8: =ESTADISTICA!AJ7 -> #REF!
A9: =ESTADISTICA!A8 -> ALTAMIRA | B9: =ESTADISTICA!B8 -> ALT07 | C9: =ESTADISTICA!C8 -> AV. CALCHAQUI Y AV. DEL TRABAJO | D9: =ESTADISTICA!D8 -> DOMO | E9: =ESTADISTICA!E8 -> PTO A FO | F9: =ESTADISTICA!F8 -> 0 | G9: =ESTADISTICA!G8 -> 0 | H9: =ESTADISTICA!H8 -> 0 | ... AJ9: =ESTADISTICA!AJ8 -> #REF!
A10: =ESTADISTICA!A9 -> ALTAMIRA | B10: =ESTADISTICA!B9 -> ALT 08 | C10: =ESTADISTICA!C9 -> HUMAITA Y NECOCHEA | D10: =ESTADISTICA!D9 -> DOMO | E10: =ESTADISTICA!E9 -> Fibra Optica | F10: =ESTADISTICA!F9 -> 0 | G10: =ESTADISTICA!G9 -> 0 | H10: =ESTADISTICA!H9 -> 0 | ... AJ10: =ESTADISTICA!AJ9 -> #REF!
A11: =ESTADISTICA!A10 -> ALTAMIRA | B11: =ESTADISTICA!B10 -> ALT 09 | C11: =ESTADISTICA!C10 -> NECOCHEA Y CURUPAITY | D11: =ESTADISTICA!D10 -> DOMO | E11: =ESTADISTICA!E10 -> Fibra Optica | F11: =ESTADISTICA!F10 -> 0 | G11: =ESTADISTICA!G10 -> 0 | H11: =ESTADISTICA!H10 -> 0 | ... AJ11: =ESTADISTICA!AJ10 -> #REF!
A12: =ESTADISTICA!A11 -> ALTAMIRA | B12: =ESTADISTICA!B11 -> ALT 10 | C12: =ESTADISTICA!C11 -> Calchaqui y Francia | D12: =ESTADISTICA!D11 -> Domo | E12: =ESTADISTICA!E11 -> Radio | F12: =ESTADISTICA!F11 -> 0 | G12: =ESTADISTICA!G11 -> 0 | H12: =ESTADISTICA!H11 -> 0 | ... AJ12: =ESTADISTICA!AJ11 -> #REF!
A13: =ESTADISTICA!A12 -> AGUSTIN RAMIREZ | B13: =ESTADISTICA!B12 -> ARA 01 | C13: =ESTADISTICA!C12 -> Malambo y Tranquera | D13: =ESTADISTICA!D12 -> Domo | E13: =ESTADISTICA!E12 -> Fibra Optica | F13: =ESTADISTICA!F12 -> APAGADO | G13: =ESTADISTICA!G12 -> APAGADO | H13: =ESTADISTICA!H12 -> APAGADO | ... AJ13: =ESTADISTICA!AJ12 -> #REF!
... A207: =ESTADISTICA!A206 -> SAN EMILIO | B207: =ESTADISTICA!B206 -> MFI06 | C207: =ESTADISTICA!C206 -> Con. Gral. Belgrano y Bombero Galarza | D207: =ESTADISTICA!D206 -> DOMO | E207: =ESTADISTICA!E206 -> Radio | F207: =ESTADISTICA!F206 -> 0 | G207: =ESTADISTICA!G206 -> 0 | H207: =ESTADISTICA!H206 -> 0 | ... AJ207: =ESTADISTICA!AJ206 -> #REF!
A208: =ESTADISTICA!A208 -> MARTIN FIERRO | B208: =ESTADISTICA!B208 -> MFI 08 | C208: =ESTADISTICA!C208 -> Braile y Batalla de Callao | D208: =ESTADISTICA!D208 -> Domo | E208: =ESTADISTICA!E208 -> PTO A FO | F208: =ESTADISTICA!F208 -> 0 | G208: =ESTADISTICA!G208 -> 0 | H208: =ESTADISTICA!H208 -> 0 | ... AJ208: =ESTADISTICA!AJ208 -> #REF!
A209: =ESTADISTICA!A209 -> GOBERNADOR MONTEVERDE | B209: =ESTADISTICA!B209 -> MON01 | C209: =ESTADISTICA!C209 -> San Martin y Patricias Argentinas | D209: =ESTADISTICA!D209 -> Fija | E209: =ESTADISTICA!E209 -> Fibra Optica | F209: =ESTADISTICA!F209 -> 0 | G209: =ESTADISTICA!G209 -> 0 | H209: =ESTADISTICA!H209 -> 0 | ... AJ209: =ESTADISTICA!AJ209 -> #REF!
A210: =ESTADISTICA!A210 -> GOBERNADOR MONTEVERDE | B210: =ESTADISTICA!B210 -> MON02 | C210: =ESTADISTICA!C210 -> Senzabello y Famatina | D210: =ESTADISTICA!D210 -> Domo | E210: =ESTADISTICA!E210 -> Radio | F210: =ESTADISTICA!F210 -> 0 | G210: =ESTADISTICA!G210 -> 0 | H210: =ESTADISTICA!H210 -> 0 | ... AJ210: =ESTADISTICA!AJ210 -> #REF!
A211: =ESTADISTICA!A211 -> GOBERNADOR MONTEVERDE | B211: =ESTADISTICA!B211 -> MON03 | C211: =ESTADISTICA!C211 -> Senzabello y Guemes | D211: =ESTADISTICA!D211 -> Domo | E211: =ESTADISTICA!E211 -> Radio | F211: =ESTADISTICA!F211 -> 0 | G211: =ESTADISTICA!G211 -> 0 | H211: =ESTADISTICA!H211 -> 0 | ... AJ211: =ESTADISTICA!AJ211 -> #REF!
A212: =ESTADISTICA!A212 -> GOBERNADOR MONTEVERDE | B212: =ESTADISTICA!B212 -> MON04 | C212: =ESTADISTICA!C212 -> Av. Yrigoyen y San Lorenzo | D212: =ESTADISTICA!D212 -> Domo | E212: =ESTADISTICA!E212 -> Radio | F212: =ESTADISTICA!F212 -> 0 | G212: =ESTADISTICA!G212 -> 0 | H212: =ESTADISTICA!H212 -> 0 | ... AJ212: =ESTADISTICA!AJ212 -> #REF!
A213: =ESTADISTICA!A213 -> 9 DE JULIO | B213: =ESTADISTICA!B213 -> NJU 01 | C213: =ESTADISTICA!C213 -> Sallares y Parrillo | D213: =ESTADISTICA!D213 -> Domo | E213: =ESTADISTICA!E213 -> Fibra Optica | F213: =ESTADISTICA!F213 -> 0 | G213: =ESTADISTICA!G213 -> 0 | H213: =ESTADISTICA!H213 -> 0 | ... AJ213: =ESTADISTICA!AJ213 -> #REF!
A214: =ESTADISTICA!A214 -> 9 DE JULIO | B214: =ESTADISTICA!B214 -> NJU02 | C214: =ESTADISTICA!C214 -> Ituzaingo y Boccuzzi | D214: =ESTADISTICA!D214 -> Domo | E214: =ESTADISTICA!E214 -> Radio | F214: =ESTADISTICA!F214 -> 0 | G214: =ESTADISTICA!G214 -> 0 | H214: =ESTADISTICA!H214 -> 0 | ... AJ214: =ESTADISTICA!AJ214 -> #REF!
A215: =ESTADISTICA!A215 -> 9 DE JULIO | B215: =ESTADISTICA!B215 -> NJU03 | C215: =ESTADISTICA!C215 -> San Juan y Parrillo | D215: =ESTADISTICA!D215 -> Domo | E215: =ESTADISTICA!E215 -> PTO A FO | F215: =ESTADISTICA!F215 -> 0 | G215: =ESTADISTICA!G215 -> 0 | H215: =ESTADISTICA!H215 -> 0 | ... AJ215: =ESTADISTICA!AJ215 -> #REF!
A216: =ESTADISTICA!A216 -> 9 DE JULIO | B216: =ESTADISTICA!B216 -> NJU04 | C216: =ESTADISTICA!C216 -> Ituzaingo y 214 A | D216: =ESTADISTICA!D216 -> Domo | E216: =ESTADISTICA!E216 -> Radio | F216: =ESTADISTICA!F216 -> 0 | G216: =ESTADISTICA!G216 -> 0 | H216: =ESTADISTICA!H216 -> 0 | ... AJ216: =ESTADISTICA!AJ216 -> #REF!
A217: =ESTADISTICA!A217 -> ZEBALLOS CENTRO | B217: =ESTADISTICA!B217 -> NJU05 | C217: =ESTADISTICA!C217 -> Ituzaingo y Alem | D217: =ESTADISTICA!D217 -> Domo | E217: =ESTADISTICA!E217 -> Radio | F217: =ESTADISTICA!F217 -> 0 | G217: =ESTADISTICA!G217 -> 0 | H217: =ESTADISTICA!H217 -> 0 | ... AJ217: =ESTADISTICA!AJ217 -> #REF!
A218: =ESTADISTICA!A218 -> CENTRO | B218: =ESTADISTICA!B218 -> NJU06 | C218: =ESTADISTICA!C218 -> Sallares y Rodo | D218: =ESTADISTICA!D218 -> Domo | E218: =ESTADISTICA!E218 -> Fibra Optica | F218: =ESTADISTICA!F218 -> 0 | G218: =ESTADISTICA!G218 -> 0 | H218: =ESTADISTICA!H218 -> 0 | ... AJ218: =ESTADISTICA!AJ218 -> #REF!
A219: =ESTADISTICA!A219 -> 9 DE JULIO | B219: =ESTADISTICA!B219 -> NJU07 | C219: =ESTADISTICA!C219 -> Gral. Juan Domingo Peron y Parrillo | D219: =ESTADISTICA!D219 -> Domo | E219: =ESTADISTICA!E219 -> Fibra Optica | F219: =ESTADISTICA!F219 -> 0 | G219: =ESTADISTICA!G219 -> 0 | H219: =ESTADISTICA!H219 -> 0 | ... AJ219: =ESTADISTICA!AJ219 -> #REF!
... A516: =ESTADISTICA!A516 -> 0 | B516: =ESTADISTICA!B516 -> 0 | C516: =ESTADISTICA!C516 -> 0 | D516: =ESTADISTICA!D516 -> 0 | E516: =ESTADISTICA!E516 -> 0 | F516: =ESTADISTICA!F516 -> 0 | G516: =ESTADISTICA!G516 -> 0 | H516: =ESTADISTICA!H516 -> 0 | ... AJ516: =ESTADISTICA!AJ516 -> #REF!

Sheet APAGADOS FIBRA
C1: TOTAL FIBRA | D1: =COUNTIFS(E4:E401,"=Fibra Optica") -> 272
E2: APAGADOS | F2: =COUNTIFS(F4:F501, "=APAGADO",E4:E501,"=Fibra Optica") -> 26 | G2: =COUNTIFS(G4:G501, "=APAGADO",E4:E501,"=Fibra Optica") -> 26 | H2: =COUNTIFS(H4:H501, "=APAGADO",E4:E501,"=Fibra Optica") -> 25 | I2: =COUNTIFS(I4:I501, "=APAGADO",E4:E501,"=Fibra Optica") -> 45 | J2: =COUNTIFS(J4:J501, "=APAGADO",E4:E501,"=Fibra Optica") -> 13 | K2: =COUNTIFS(K4:K501, "=APAGADO",E4:E501,"=Fibra Optica") -> 12 | L2: =COUNTIFS(L4:L501, "=APAGADO",E4:E501,"=Fibra Optica") -> 12 | M2: =COUNTIFS(M4:M501, "=APAGADO",E4:E501,"=Fibra Optica") -> 16 | N2: =COUNTIFS(N4:N501, "=APAGADO",E4:E501,"=Fibra Optica") -> 42 | O2: =COUNTIFS(O4:O501, "=APAGADO",E4:E501,"=Fibra Optica") -> 40 | P2: =COUNTIFS(P4:P501, "=APAGADO",E4:E501,"=Fibra Optica") -> 20 | Q2: =COUNTIFS(Q4:Q501, "=APAGADO",E4:E501,"=Fibra Optica") -> 47 | R2: =COUNTIFS(R4:R501, "=APAGADO",E4:E501,"=Fibra Optica") -> 28 | S2: =COUNTIFS(S4:S501, "=APAGADO",E4:E501,"=Fibra Optica") -> 23 | T2: =COUNTIFS(T4:T501, "=APAGADO",E4:E501,"=Fibra Optica") -> 24 | U2: =COUNTIFS(U4:U501, "=APAGADO",E4:E501,"=Fibra Optica") -> 17 | V2: =COUNTIFS(V4:V501, "=APAGADO",E4:E501,"=Fibra Optica") -> 32 | W2: =COUNTIFS(W4:W501, "=APAGADO",E4:E501,"=Fibra Optica") -> 0 | X2: =COUNTIFS(X4:X501, "=APAGADO",E4:E501,"=Fibra Optica") -> 0 | Y2: =COUNTIFS(Y4:Y501, "=APAGADO",E4:E501,"=Fibra Optica") -> 0 | Z2: =COUNTIFS(Z4:Z501, "=APAGADO",E4:E501,"=Fibra Optica") -> 0 | AA2: =COUNTIFS(AA4:AA501, "=APAGADO",E4:E501,"=Fibra Optica") -> 0 | AB2: =COUNTIFS(AB4:AB501, "=APAGADO",E4:E501,"=Fibra Optica") -> 0 | AC2: =COUNTIFS(AC4:AC601, "=APAGADO",E4:E601,"=Fibra Optica") -> 0 | AD2: =COUNTIFS(AD4:AD501, "=APAGADO",E4:E501,"=Fibra Optica") -> 0 | AE2: =COUNTIFS(AE4:AE501, "=APAGADO",E4:E501,"=Fibra Optica") -> 0 | AF2: =COUNTIFS(AF4:AF501, "=APAGADO",E4:E501,"=Fibra Optica") -> 0 | AG2: =COUNTIFS(AG4:AG501, "=APAGADO",E4:E501,"=Fibra Optica") -> 0 | AH2: =COUNTIFS(AH4:AH501, "=APAGADO",E4:E501,"=Fibra Optica") -> 0 | AI2: =COUNTIFS(AI4:AI401, "=APAGADO",E4:E401,"=Fibra Optica") -> 0 | AJ2: =COUNTIFS(AJ4:AJ401, "=APAGADO",F4:F401,"=Fibra Optica") -> 0
A3: =ESTADISTICA!A1 -> Barrio | B3: =ESTADISTICA!B1 -> [Denominacion] | C3: =ESTADISTICA!C1 -> [Ubicacion] | D3: =ESTADISTICA!D1 -> [Tipo de Camara] | E3: =ESTADISTICA!E1 -> [Tipo de Conexion] | F3: =ESTADISTICA!F1 -> 45139 | G3: =ESTADISTICA!G1 -> 45140 | H3: =ESTADISTICA!H1 -> 45141 | ... AJ3: =ESTADISTICA!AJ1 -> #REF!
A4: ='RESUMEN TOTAL'!A7 -> ALTAMIRA | B4: ='RESUMEN TOTAL'!B7 -> ALT 03 | C4: ='RESUMEN TOTAL'!D7 -> Bombero Galarza y Necochea | D4: ='RESUMEN TOTAL'!E7 -> Domo | E4: ='RESUMEN TOTAL'!F7 -> Fibra Optica | F4: ='RESUMEN TOTAL'!L7 -> 0 | G4: ='RESUMEN TOTAL'!M7 -> 0 | H4: ='RESUMEN TOTAL'!N7 -> 0 | I4: ='RESUMEN TOTAL'!O7 -> APAGADO | J4: ='RESUMEN TOTAL'!P7 -> 0 | K4: ='RESUMEN TOTAL'!Q7 -> 0 | L4: ='RESUMEN TOTAL'!R7 -> 0 | M4: ='RESUMEN TOTAL'!S7 -> 0 | ... AI4: ='RESUMEN TOTAL'!AO7 -> 0 | AJ4: ='RESUMEN TOTAL'!#REF! -> #REF!
A5: ='RESUMEN TOTAL'!A8 -> ALTAMIRA | B5: ='RESUMEN TOTAL'!B8 -> ALT 04 | C5: ='RESUMEN TOTAL'!D8 -> Francia y Necochea | D5: ='RESUMEN TOTAL'!E8 -> Domo | E5: ='RESUMEN TOTAL'!F8 -> Fibra Optica | F5: ='RESUMEN TOTAL'!L8 -> 0 | G5: ='RESUMEN TOTAL'!M8 -> 0 | H5: ='RESUMEN TOTAL'!N8 -> 0 | I5: ='RESUMEN TOTAL'!O8 -> APAGADO | J5: ='RESUMEN TOTAL'!P8 -> 0 | K5: ='RESUMEN TOTAL'!Q8 -> 0 | L5: ='RESUMEN TOTAL'!R8 -> 0 | M5: ='RESUMEN TOTAL'!S8 -> 0 | ... AI5: ='RESUMEN TOTAL'!AO8 -> 0 | AJ5: ='RESUMEN TOTAL'!#REF! -> #REF!
A6: ='RESUMEN TOTAL'!A9 -> ALTAMIRA | B6: ='RESUMEN TOTAL'!B9 -> ALT05 | C6: ='RESUMEN TOTAL'!D9 -> Av. Calchaqui y Bombero Galarza | D6: ='RESUMEN TOTAL'!E9 -> Domo | E6: ='RESUMEN TOTAL'!F9 -> PTO A FO | F6: ='RESUMEN TOTAL'!L9 -> 0 | G6: ='RESUMEN TOTAL'!M9 -> 0 | H6: ='RESUMEN TOTAL'!N9 -> 0 | I6: ='RESUMEN TOTAL'!O9 -> APAGADO | J6: ='RESUMEN TOTAL'!P9 -> 0 | K6: ='RESUMEN TOTAL'!Q9 -> 0 | L6: ='RESUMEN TOTAL'!R9 -> 0 | M6: ='RESUMEN TOTAL'!S9 -> 0 | ... AI6: ='RESUMEN TOTAL'!AO9 -> 0 | AJ6: ='RESUMEN TOTAL'!#REF! -> #REF!
A7: ='RESUMEN TOTAL'!A10 -> ALTAMIRA | B7: ='RESUMEN TOTAL'!B10 -> ALT 06 | C7: ='RESUMEN TOTAL'!D10 -> LOPE DE VEGA Y NECOCHEA | D7: ='RESUMEN TOTAL'!E10 -> Domo | E7: ='RESUMEN TOTAL'!F10 -> PTO A FO | F7: ='RESUMEN TOTAL'!L10 -> 0 | G7: ='RESUMEN TOTAL'!M10 -> 0 | H7: ='RESUMEN TOTAL'!N10 -> 0 | I7: ='RESUMEN TOTAL'!O10 -> APAGADO | J7: ='RESUMEN TOTAL'!P10 -> 0 | K7: ='RESUMEN TOTAL'!Q10 -> 0 | L7: ='RESUMEN TOTAL'!R10 -> 0 | M7: ='RESUMEN TOTAL'!S10 -> 0 | ... AI7: ='RESUMEN TOTAL'!AO10 -> 0 | AJ7: ='RESUMEN TOTAL'!#REF! -> #REF!
A8: ='RESUMEN TOTAL'!A11 -> ALTAMIRA | B8: ='RESUMEN TOTAL'!B11 -> ALT07 | C8: ='RESUMEN TOTAL'!D11 -> AV. CALCHAQUI Y AV. DEL TRABAJO | D8: ='RESUMEN TOTAL'!E11 -> DOMO | E8: ='RESUMEN TOTAL'!F11 -> PTO A FO | F8: ='RESUMEN TOTAL'!L11 -> 0 | G8: ='RESUMEN TOTAL'!M11 -> 0 | H8: ='RESUMEN TOTAL'!N11 -> 0 | I8: ='RESUMEN TOTAL'!O11 -> APAGADO | J8: ='RESUMEN TOTAL'!P11 -> 0 | K8: ='RESUMEN TOTAL'!Q11 -> 0 | L8: ='RESUMEN TOTAL'!R11 -> 0 | M8: ='RESUMEN TOTAL'!S11 -> 0 | ... AI8: ='RESUMEN TOTAL'!AO11 -> 0 | AJ8: ='RESUMEN TOTAL'!#REF! -> #REF!
A9: ='RESUMEN TOTAL'!A12 -> ALTAMIRA | B9: ='RESUMEN TOTAL'!B12 -> ALT 08 | C9: ='RESUMEN TOTAL'!D12 -> HUMAITA Y NECOCHEA | D9: ='RESUMEN TOTAL'!E12 -> DOMO | E9: ='RESUMEN TOTAL'!F12 -> Fibra Optica | F9: ='RESUMEN TOTAL'!L12 -> 0 | G9: ='RESUMEN TOTAL'!M12 -> 0 | H9: ='RESUMEN TOTAL'!N12 -> 0 | I9: ='RESUMEN TOTAL'!O12 -> APAGADO | J9: ='RESUMEN TOTAL'!P12 -> 0 | K9: ='RESUMEN TOTAL'!Q12 -> 0 | L9: ='RESUMEN TOTAL'!R12 -> 0 | M9: ='RESUMEN TOTAL'!S12 -> 0 | ... AI9: ='RESUMEN TOTAL'!AO12 -> 0 | AJ9: ='RESUMEN TOTAL'!#REF! -> #REF!
A10: ='RESUMEN TOTAL'!A13 -> ALTAMIRA | B10: ='RESUMEN TOTAL'!B13 -> ALT 09 | C10: ='RESUMEN TOTAL'!D13 -> NECOCHEA Y CURUPAITY | D10: ='RESUMEN TOTAL'!E13 -> DOMO | E10: ='RESUMEN TOTAL'!F13 -> Fibra Optica | F10: ='RESUMEN TOTAL'!L13 -> 0 | G10: ='RESUMEN TOTAL'!M13 -> 0 | H10: ='RESUMEN TOTAL'!N13 -> 0 | I10: ='RESUMEN TOTAL'!O13 -> APAGADO | J10: ='RESUMEN TOTAL'!P13 -> 0 | K10: ='RESUMEN TOTAL'!Q13 -> 0 | L10: ='RESUMEN TOTAL'!R13 -> 0 | M10: ='RESUMEN TOTAL'!S13 -> 0 | ... AI10: ='RESUMEN TOTAL'!AO13 -> 0 | AJ10: ='RESUMEN TOTAL'!#REF! -> #REF!
A11: ='RESUMEN TOTAL'!A14 -> ALTAMIRA | B11: ='RESUMEN TOTAL'!B14 -> ALT 10 | C11: ='RESUMEN TOTAL'!D14 -> Calchaqui y Francia | D11: ='RESUMEN TOTAL'!E14 -> Domo | E11: ='RESUMEN TOTAL'!F14 -> Radio | F11: ='RESUMEN TOTAL'!L14 -> 0 | G11: ='RESUMEN TOTAL'!M14 -> 0 | H11: ='RESUMEN TOTAL'!N14 -> 0 | I11: ='RESUMEN TOTAL'!O14 -> APAGADO | J11: ='RESUMEN TOTAL'!P14 -> 0 | K11: ='RESUMEN TOTAL'!Q14 -> 0 | L11: ='RESUMEN TOTAL'!R14 -> 0 | M11: ='RESUMEN TOTAL'!S14 -> 0 | ... AI11: ='RESUMEN TOTAL'!AO14 -> 0 | AJ11: ='RESUMEN TOTAL'!#REF! -> #REF!
A12: ='RESUMEN TOTAL'!A15 -> AGUSTIN RAMIREZ | B12: ='RESUMEN TOTAL'!B15 -> ARA 01 | C12: ='RESUMEN TOTAL'!D15 -> Malambo y Tranquera | D12: ='RESUMEN TOTAL'!E15 -> Domo | E12: ='RESUMEN TOTAL'!F15 -> Fibra Optica | F12: ='RESUMEN TOTAL'!L15 -> APAGADO | G12: ='RESUMEN TOTAL'!M15 -> APAGADO | H12: ='RESUMEN TOTAL'!N15 -> APAGADO | I12: ='RESUMEN TOTAL'!O15 -> APAGADO | J12: ='RESUMEN TOTAL'!P15 -> 0 | K12: ='RESUMEN TOTAL'!Q15 -> APAGADO | L12: ='RESUMEN TOTAL'!R15 -> APAGADO | M12: ='RESUMEN TOTAL'!S15 -> APAGADO | ... AI12: ='RESUMEN TOTAL'!AO15 -> 0 | AJ12: ='RESUMEN TOTAL'!#REF! -> #REF!
A13: ='RESUMEN TOTAL'!A16 -> BELGRANO | B13: ='RESUMEN TOTAL'!B16 -> BEL 01 | C13: ='RESUMEN TOTAL'!D16 -> San Martin y Dardo Rocha | D13: ='RESUMEN TOTAL'!E16 -> DOMO | E13: ='RESUMEN TOTAL'!F16 -> Fibra Optica | F13: ='RESUMEN TOTAL'!L16 -> 0 | G13: ='RESUMEN TOTAL'!M16 -> 0 | H13: ='RESUMEN TOTAL'!N16 -> 0 | I13: ='RESUMEN TOTAL'!O16 -> 0 | J13: ='RESUMEN TOTAL'!P16 -> 0 | K13: ='RESUMEN TOTAL'!Q16 -> 0 | L13: ='RESUMEN TOTAL'!R16 -> 0 | M13: ='RESUMEN TOTAL'!S16 -> 0 | ... AI13: ='RESUMEN TOTAL'!AO16 -> 0 | AJ13: ='RESUMEN TOTAL'!#REF! -> #REF!
A14: ='RESUMEN TOTAL'!A17 -> BELGRANO | B14: ='RESUMEN TOTAL'!B17 -> BEL 02 | C14: ='RESUMEN TOTAL'!D17 -> Guardia vieja y Fronteriz | D14: ='RESUMEN TOTAL'!E17 -> DOMO | E14: ='RESUMEN TOTAL'!F17 -> Fibra Optica | F14: ='RESUMEN TOTAL'!L17 -> 0 | G14: ='RESUMEN TOTAL'!M17 -> 0 | H14: ='RESUMEN TOTAL'!N17 -> 0 | I14: ='RESUMEN TOTAL'!O17 -> 0 | J14: ='RESUMEN TOTAL'!P17 -> 0 | K14: ='RESUMEN TOTAL'!Q17 -> 0 | L14: ='RESUMEN TOTAL'!R17 -> 0 | M14: ='RESUMEN TOTAL'!S17 -> 0 | ... AI14: ='RESUMEN TOTAL'!AO17 -> 0 | AJ14: ='RESUMEN TOTAL'!#REF! -> #REF!
A15: ='RESUMEN TOTAL'!A18 -> BOSQUES CENTRO | B15: ='RESUMEN TOTAL'!B18 -> BOSQC 01 | C15: ='RESUMEN TOTAL'!D18 -> LUIS AGOTE E/DANUNCIO Y CAMPOAMOR | D15: ='RESUMEN TOTAL'!E18 -> Fija | E15: ='RESUMEN TOTAL'!F18 -> Radio | F15: ='RESUMEN TOTAL'!L18 -> 0 | G15: ='RESUMEN TOTAL'!M18 -> 0 | H15: ='RESUMEN TOTAL'!N18 -> 0 | I15: ='RESUMEN TOTAL'!O18 -> 0 | J15: ='RESUMEN TOTAL'!P18 -> 0 | K15: ='RESUMEN TOTAL'!Q18 -> 0 | L15: ='RESUMEN TOTAL'!R18 -> 0 | M15: ='RESUMEN TOTAL'!S18 -> 0 | ... AI15: ='RESUMEN TOTAL'!AO18 -> 0 | AJ15: ='RESUMEN TOTAL'!#REF! -> #REF!
... A464: ='RESUMEN TOTAL'!A467 -> PARADAS SEGURAS | B464: ='RESUMEN TOTAL'!B467 -> 26 | C464: ='RESUMEN TOTAL'!D467 -> HUDSON Y RIO COLORADO OESTE | D464: ='RESUMEN TOTAL'!E467 -> GFIJA | E464: ='RESUMEN TOTAL'!F467 -> GPON | F464: ='RESUMEN TOTAL'!L467 -> 0 | G464: ='RESUMEN TOTAL'!M467 -> 0 | H464: ='RESUMEN TOTAL'!N467 -> 0 | I464: ='RESUMEN TOTAL'!O467 -> 0 | J464: ='RESUMEN TOTAL'!P467 -> 0 | K464: ='RESUMEN TOTAL'!Q467 -> 0 | L464: ='RESUMEN TOTAL'!R467 -> 0 | M464: ='RESUMEN TOTAL'!S467 -> 0 | ... AI464: ='RESUMEN TOTAL'!AO467 -> 0 | AJ464: ='RESUMEN TOTAL'!#REF! -> #REF!
A465: ='RESUMEN TOTAL'!A468 -> PARADAS SEGURAS | B465: ='RESUMEN TOTAL'!B468 -> 26 I | C465: ='RESUMEN TOTAL'!D469 -> HUDON Y 818 ESTE | D465: ='RESUMEN TOTAL'!E468 -> INTERCOMUNICADOR | E465: ='RESUMEN TOTAL'!F468 -> GPON | F465: ='RESUMEN TOTAL'!L468 -> 0 | G465: ='RESUMEN TOTAL'!M468 -> 0 | H465: ='RESUMEN TOTAL'!N468 -> 0 | I465: ='RESUMEN TOTAL'!O468 -> 0 | J465: ='RESUMEN TOTAL'!P468 -> 0 | K465: ='RESUMEN TOTAL'!Q468 -> 0 | L465: ='RESUMEN TOTAL'!R468 -> 0 | M465: ='RESUMEN TOTAL'!S468 -> 0 | ... AI465: ='RESUMEN TOTAL'!AO468 -> 0 | AJ465: ='RESUMEN TOTAL'!#REF! -> #REF!
A466: ='RESUMEN TOTAL'!A469 -> PARADAS SEGURAS | B466: ='RESUMEN TOTAL'!B469 -> 27 | C466: ='RESUMEN TOTAL'!D471 -> HUDSON Y RIO TRAFUL OESTE | D466: ='RESUMEN TOTAL'!E469 -> GFIJA | E466: ='RESUMEN TOTAL'!F469 -> GPON | F466: ='RESUMEN TOTAL'!L469 -> 0 | G466: ='RESUMEN TOTAL'!M469 -> 0 | H466: ='RESUMEN TOTAL'!N469 -> 0 | I466: ='RESUMEN TOTAL'!O469 -> 0 | J466: ='RESUMEN TOTAL'!P469 -> 0 | K466: ='RESUMEN TOTAL'!Q469 -> 0 | L466: ='RESUMEN TOTAL'!R469 -> 0 | M466: ='RESUMEN TOTAL'!S469 -> 0 | ... AI466: ='RESUMEN TOTAL'!AO469 -> 0 | AJ466: ='RESUMEN TOTAL'!#REF! -> #REF!
A467: ='RESUMEN TOTAL'!A470 -> PARADAS SEGURAS | B467: ='RESUMEN TOTAL'!B470 -> 27 I | C467: ='RESUMEN TOTAL'!D473 -> HUDSON Y ESTOMBA ESTE | D467: ='RESUMEN TOTAL'!E470 -> INTERCOMUNICADOR | E467: ='RESUMEN TOTAL'!F470 -> GPON | F467: ='RESUMEN TOTAL'!L470 -> 0 | G467: ='RESUMEN TOTAL'!M470 -> 0 | H467: ='RESUMEN TOTAL'!N470 -> 0 | I467: ='RESUMEN TOTAL'!O470 -> 0 | J467: ='RESUMEN TOTAL'!P470 -> 0 | K467: ='RESUMEN TOTAL'!Q470 -> 0 | L467: ='RESUMEN TOTAL'!R470 -> 0 | M467: ='RESUMEN TOTAL'!S470 -> 0 | ... AI467: ='RESUMEN TOTAL'!AO470 -> 0 | AJ467: ='RESUMEN TOTAL'!#REF! -> #REF!
A468: ='RESUMEN TOTAL'!A471 -> PARADAS SEGURAS | B468: ='RESUMEN TOTAL'!B471 -> 28 | C468: ='RESUMEN TOTAL'!D475 -> HUDSON Y PICHEUTA OESTE | D468: ='RESUMEN TOTAL'!E471 -> GFIJA | E468: ='RESUMEN TOTAL'!F471 -> GPON | F468: ='RESUMEN TOTAL'!L471 -> 0 | G468: ='RESUMEN TOTAL'!M471 -> 0 | H468: ='RESUMEN TOTAL'!N471 -> 0 | I468: ='RESUMEN TOTAL'!O471 -> 0 | J468: ='RESUMEN TOTAL'!P471 -> 0 | K468: ='RESUMEN TOTAL'!Q471 -> 0 | L468: ='RESUMEN TOTAL'!R471 -> 0 | M468: ='RESUMEN TOTAL'!S471 -> 0 | ... AI468: ='RESUMEN TOTAL'!AO471 -> 0 | AJ468: ='RESUMEN TOTAL'!#REF! -> #REF!
A469: ='RESUMEN TOTAL'!A472 -> PARADAS SEGURAS | B469: ='RESUMEN TOTAL'!B472 -> 28 I | C469: ='RESUMEN TOTAL'!D477 -> HUDSON Y 830 ESTE | D469: ='RESUMEN TOTAL'!E472 -> INTERCOMUNICADOR | E469: ='RESUMEN TOTAL'!F472 -> GPON | F469: ='RESUMEN TOTAL'!L472 -> 0 | G469: ='RESUMEN TOTAL'!M472 -> 0 | H469: ='RESUMEN TOTAL'!N472 -> 0 | I469: ='RESUMEN TOTAL'!O472 -> 0 | J469: ='RESUMEN TOTAL'!P472 -> 0 | K469: ='RESUMEN TOTAL'!Q472 -> 0 | L469: ='RESUMEN TOTAL'!R472 -> 0 | M469: ='RESUMEN TOTAL'!S472 -> 0 | ... AI469: ='RESUMEN TOTAL'!AO472 -> 0 | AJ469: ='RESUMEN TOTAL'!#REF! -> #REF!
A470: ='RESUMEN TOTAL'!A473 -> PARADAS SEGURAS | B470: ='RESUMEN TOTAL'!B473 -> 29 | C470: ='RESUMEN TOTAL'!#REF! -> #REF! | D470: ='RESUMEN TOTAL'!E473 -> GFIJA | E470: ='RESUMEN TOTAL'!F473 -> GPON | F470: ='RESUMEN TOTAL'!L473 -> 0 | G470: ='RESUMEN TOTAL'!M473 -> 0 | H470: ='RESUMEN TOTAL'!N473 -> 0 | I470: ='RESUMEN TOTAL'!O473 -> 0 | J470: ='RESUMEN TOTAL'!P473 -> 0 | K470: ='RESUMEN TOTAL'!Q473 -> 0 | L470: ='RESUMEN TOTAL'!R473 -> 0 | M470: ='RESUMEN TOTAL'!S473 -> 0 | ... AI470: ='RESUMEN TOTAL'!AO473 -> 0 | AJ470: ='RESUMEN TOTAL'!#REF! -> #REF!
A471: ='RESUMEN TOTAL'!A474 -> PARADAS SEGURAS | B471: ='RESUMEN TOTAL'!B474 -> 29 I | C471: ='RESUMEN TOTAL'!#REF! -> #REF! | D471: ='RESUMEN TOTAL'!E474 -> INTERCOMUNICADOR | E471: ='RESUMEN TOTAL'!F474 -> GPON | F471: ='RESUMEN TOTAL'!L474 -> 0 | G471: ='RESUMEN TOTAL'!M474 -> 0 | H471: ='RESUMEN TOTAL'!N474 -> 0 | I471: ='RESUMEN TOTAL'!O474 -> 0 | J471: ='RESUMEN TOTAL'!P474 -> 0 | K471: ='RESUMEN TOTAL'!Q474 -> 0 | L471: ='RESUMEN TOTAL'!R474 -> 0 | M471: ='RESUMEN TOTAL'!S474 -> 0 | ... AI471: ='RESUMEN TOTAL'!AO474 -> 0 | AJ471: ='RESUMEN TOTAL'!#REF! -> #REF!
A472: ='RESUMEN TOTAL'!A475 -> PARADAS SEGURAS | B472: ='RESUMEN TOTAL'!B475 -> 30 | C472: ='RESUMEN TOTAL'!#REF! -> #REF! | D472: ='RESUMEN TOTAL'!E475 -> GFIJA | E472: ='RESUMEN TOTAL'!F475 -> GPON | F472: ='RESUMEN TOTAL'!L475 -> 0 | G472: ='RESUMEN TOTAL'!M475 -> 0 | H472: ='RESUMEN TOTAL'!N475 -> 0 | I472: ='RESUMEN TOTAL'!O475 -> 0 | J472: ='RESUMEN TOTAL'!P475 -> 0 | K472: ='RESUMEN TOTAL'!Q475 -> 0 | L472: ='RESUMEN TOTAL'!R475 -> 0 | M472: ='RESUMEN TOTAL'!S475 -> 0 | ... AI472: ='RESUMEN TOTAL'!AO475 -> 0 | AJ472: ='RESUMEN TOTAL'!#REF! -> #REF!
A473: ='RESUMEN TOTAL'!A476 -> PARADAS SEGURAS | B473: ='RESUMEN TOTAL'!B476 -> 30 I | C473: ='RESUMEN TOTAL'!D476 -> HUDSON Y PICHEUTA OESTE | D473: ='RESUMEN TOTAL'!E476 -> INTERCOMUNICADOR | E473: ='RESUMEN TOTAL'!F476 -> GPON | F473: ='RESUMEN TOTAL'!L476 -> 0 | G473: ='RESUMEN TOTAL'!M476 -> 0 | H473: ='RESUMEN TOTAL'!N476 -> 0 | I473: ='RESUMEN TOTAL'!O476 -> 0 | J473: ='RESUMEN TOTAL'!P476 -> 0 | K473: ='RESUMEN TOTAL'!Q476 -> 0 | L473: ='RESUMEN TOTAL'!R476 -> 0 | M473: ='RESUMEN TOTAL'!S476 -> 0 | ... AI473: ='RESUMEN TOTAL'!AO476 -> 0 | AJ473: ='RESUMEN TOTAL'!#REF! -> #REF!
A474: ='RESUMEN TOTAL'!A477 -> PARADAS SEGURAS | B474: ='RESUMEN TOTAL'!B477 -> 31 | C474: ='RESUMEN TOTAL'!#REF! -> #REF! | D474: ='RESUMEN TOTAL'!E477 -> GFIJA | E474: ='RESUMEN TOTAL'!F477 -> GPON | F474: ='RESUMEN TOTAL'!L477 -> 0 | G474: ='RESUMEN TOTAL'!M477 -> 0 | H474: ='RESUMEN TOTAL'!N477 -> 0 | I474: ='RESUMEN TOTAL'!O477 -> 0 | J474: ='RESUMEN TOTAL'!P477 -> 0 | K474: ='RESUMEN TOTAL'!Q477 -> 0 | L474: ='RESUMEN TOTAL'!R477 -> 0 | M474: ='RESUMEN TOTAL'!S477 -> 0 | ... AI474: ='RESUMEN TOTAL'!AO477 -> 0 | AJ474: ='RESUMEN TOTAL'!#REF! -> #REF!
A475: ='RESUMEN TOTAL'!A478 -> PARADAS SEGURAS | B475: ='RESUMEN TOTAL'!B478 -> 31 I | C475: ='RESUMEN TOTAL'!#REF! -> #REF! | D475: ='RESUMEN TOTAL'!E478 -> INTERCOMUNICADOR | E475: ='RESUMEN TOTAL'!F478 -> GPON | F475: ='RESUMEN TOTAL'!L478 -> 0 | G475: ='RESUMEN TOTAL'!M478 -> 0 | H475: ='RESUMEN TOTAL'!N478 -> 0 | I475: ='RESUMEN TOTAL'!O478 -> 0 | J475: ='RESUMEN TOTAL'!P478 -> 0 | K475: ='RESUMEN TOTAL'!Q478 -> 0 | L475: ='RESUMEN TOTAL'!R478 -> 0 | M475: ='RESUMEN TOTAL'!S478 -> 0 | ... AI475: ='RESUMEN TOTAL'!AO478 -> 0 | AJ475: ='RESUMEN TOTAL'!#REF! -> #REF!
A476: ='RESUMEN TOTAL'!A479 -> PARADAS SEGURAS | B476: ='RESUMEN TOTAL'!B479 -> 32 | C476: ='RESUMEN TOTAL'!D479 -> Hudson y 834 oeste | D476: ='RESUMEN TOTAL'!E479 -> GFIJA | E476: ='RESUMEN TOTAL'!F479 -> GPON | F476: ='RESUMEN TOTAL'!L479 -> 0 | G476: ='RESUMEN TOTAL'!M479 -> 0 | H476: ='RESUMEN TOTAL'!N479 -> 0 | I476: ='RESUMEN TOTAL'!O479 -> 0 | J476: ='RESUMEN TOTAL'!P479 -> 0 | K476: ='RESUMEN TOTAL'!Q479 -> 0 | L476: ='RESUMEN TOTAL'!R479 -> 0 | M476: ='RESUMEN TOTAL'!S479 -> 0 | ... AI476: ='RESUMEN TOTAL'!AO479 -> 0 | AJ476: ='RESUMEN TOTAL'!#REF! -> #REF!
A477: ='RESUMEN TOTAL'!A480 -> PARADAS SEGURAS | B477: ='RESUMEN TOTAL'!B480 -> 32 I | C477: ='RESUMEN TOTAL'!D480 -> Hudson y 834 oeste | D477: ='RESUMEN TOTAL'!E480 -> INTERCOMUNICADOR | E477: ='RESUMEN TOTAL'!F480 -> GPON | F477: ='RESUMEN TOTAL'!L480 -> 0 | G477: ='RESUMEN TOTAL'!M480 -> 0 | H477: ='RESUMEN TOTAL'!N480 -> 0 | I477: ='RESUMEN TOTAL'!O480 -> APAGADO | J477: ='RESUMEN TOTAL'!P480 -> APAGADO | K477: ='RESUMEN TOTAL'!Q480 -> APAGADO | L477: ='RESUMEN TOTAL'!R480 -> APAGADO | M477: ='RESUMEN TOTAL'!S480 -> APAGADO | ... AI477: ='RESUMEN TOTAL'!AO480 -> 0 | AJ477: ='RESUMEN TOTAL'!#REF! -> #REF!
A478: ='RESUMEN TOTAL'!A481 -> PARADAS SEGURAS | B478: ='RESUMEN TOTAL'!B481 -> 33 C | C478: ='RESUMEN TOTAL'!D481 -> Hudson y Suipacha este | D478: ='RESUMEN TOTAL'!E481 -> GFIJA | E478: ='RESUMEN TOTAL'!F481 -> GPON | F478: ='RESUMEN TOTAL'!L481 -> 0 | G478: ='RESUMEN TOTAL'!M481 -> 0 | H478: ='RESUMEN TOTAL'!N481 -> 0 | I478: ='RESUMEN TOTAL'!O481 -> APAGADO | J478: ='RESUMEN TOTAL'!P481 -> APAGADO | K478: ='RESUMEN TOTAL'!Q481 -> APAGADO | L478: ='RESUMEN TOTAL'!R481 -> APAGADO | M478: ='RESUMEN TOTAL'!S481 -> APAGADO | ... AI478: ='RESUMEN TOTAL'!AO481 -> 0 | AJ478: ='RESUMEN TOTAL'!#REF! -> #REF!
