Workbook
Name _25_de_agosto: 'RESUMEN TOTAL'!$A$4:$D$349

Sheet RESUMEN TOTAL
A1: CANTIDAD DE CAMARAS | C1: =COUNTA(C5:C527) -> 375 | D1: PORCIENTO DE CAIDAS | O1: =(O3)/(O2+O3) -> 0.18933333 | P1: =(P3)/(P2+P3) -> 0.256 | Q1: =(Q3)/(Q2+Q3) -> 0.23733333 | R1: =(R3)/(R2+R3) -> 0.18133333 | S1: =(S3)/(S2+S3) -> 0.17379679 | T1: =(T3)/(T2+T3) -> 0.168 | U1: =(U3)/(U2+U3) -> 0.16533333 | V1: =(V3)/(V2+V3) -> 0.11733333 | ... AR1: =(AR3)/(AR2+AR3) -> 0
D2: FUNCIONAN | O2: =COUNTIF(O5:O379, "") -> 304 | P2: =COUNTIF(P5:P379, "") -> 279 | Q2: =COUNTIF(Q5:Q379, "") -> 286 | R2: =COUNTIF(R5:R379, "") -> 307 | S2: =COUNTIF(S5:S379, "") -> 309 | T2: =COUNTIF(T5:T379, "") -> 312 | U2: =COUNTIF(U5:U379, "") -> 313 | V2: =COUNTIF(V5:V379, "") -> 331 | ... AR2: =COUNTIF(AR5:AR379, "") -> 375
D3: CAIDAS | O3: =COUNTIF(O4:O447, "apagado") -> 71 | P3: =COUNTIF(P4:P447, "apagado") -> 96 | Q3: =COUNTIF(Q4:Q447, "apagado") -> 89 | R3: =COUNTIF(R4:R447, "apagado") -> 68 | S3: =COUNTIF(S4:S447, "apagado") -> 65 | T3: =COUNTIF(T4:T447, "apagado") -> 63 | U3: =COUNTIF(U4:U447, "apagado") -> 62 | V3: =COUNTIF(V4:V447, "apagado") -> 44 | ... AR3: =COUNTIF(AR4:AR447, "apagado") -> 0
A4: Barrio | B4: a coseidi | C4: [Denominacion] | D4: [Ubicacion] | E4: [Tipo de Camara] | F4: [Tipo de Conexion] | G4: [Fundamento] | H4: [Detalle] | I4: Latitud | J4: Longitud | L4: DIAS FUNCIONANDO | M4: DIAS CAIDA | N4: EFECTIVIDAD | O4: 44713 | P4: 44714 | Q4: 44715 | R4: 44716 | S4: 44717 | T4: 44718 | U4: 44719 | V4: 44720 | W4: 44721 | X4: 44722 | Y4: 44723 | Z4: 44724 | AA4: 44725 | AB4: 44726 | AC4: 44727 | AD4: 44728 | AE4: 44729 | AF4: 44730 | AG4: 44731 | AH4: 44732 | AI4: 44733 | AJ4: 44734 | AK4: 44735 | AL4: 44736 | AM4: 44737 | AN4: 44738 | AO4: 44739 | AP4: 44740 | AQ4: 44741 | AR4: 44742
A5: PRESIDENTE PERON (PEPSI) | B5: 44629 | C5: MAR 01 | D5: RP36 Y LA ESMERALDA | E5: DOMO | F5: Fibra Optica | G5: POSIBLE VIA DE ESCAPE. FLUJO VEHICULAR | I5: -348296270000 | J5: -582165860000 | K5: 172.20.11.101 | L5: =COUNTIF(O5:AR5,"") -> 22 | M5: =COUNTIF(O5:AP5,"APAGADO") -> 8 | N5: =(L5)/(M5+L5) -> 0.73333333 | O5: APAGADO | P5: APAGADO | Q5: APAGADO | R5: APAGADO | S5: APAGADO | T5: APAGADO | U5: APAGADO | V5: APAGADO
A6: MAYOL | C6: MAY 01 | D6: Eva Peron y Cabildo | E6: Domo | F6: Radio | G6: Flujo Vehicular, Futuro corredor escolar, Zona Comercial | I6: -348239900000 | J6: -582772350000 | K6: 172.20.200.194 | L6: =COUNTIF(O6:AR6,"") -> 30 | M6: =COUNTIF(O6:AP6,"APAGADO") -> 0 | N6: =(L6)/(M6+L6) -> 1
C7: MAY 02 | D7: EVA PERON Y MONTEVIDEO | E7: Domo | F7: Radio | I7: -348218190000 | J7: -582771380000 | K7: 172.20.200.168 | L7: =COUNTIF(O7:AR7,"") -> 13 | M7: =COUNTIF(O7:AP7,"APAGADO") -> 17 | N7: =(L7)/(M7+L7) -> 0.43333333 | O7: APAGADO | P7: APAGADO | Q7: APAGADO | R7: APAGADO | S7: APAGADO | T7: APAGADO | U7: APAGADO | V7: APAGADO | W7: APAGADO | X7: APAGADO | Y7: APAGADO | Z7: APAGADO | AA7: APAGADO | AB7: APAGADO | AC7: APAGADO | AD7: APAGADO | AF7: APAGADO
A8: MAYOL | C8: MAY 03 | D8: CHAÑAR Y SAN NICOLAS | E8: DOMO | F8: PTP A FO | H8: ALTA 29/10/2019 | I8: -348230700000 | J8: -582702540000 | K8: 172.20.10.18 | L8: =COUNTIF(O8:AR8,"") -> 30 | M8: =COUNTIF(O8:AP8,"APAGADO") -> 0 | N8: =(L8)/(M8+L8) -> 1
C9: MAY 04 | D9: MAR CHIQUITA Y RIO JACHAL | E9: DOMO | F9: Radio | H9: 08/07/2020 COMIENZA A REPORTAR IMAGEN | I9: -348252070000 | J9: -582711820000 | K9: 10.20.30.34 | L9: =COUNTIF(O9:AR9,"") -> 30 | M9: =COUNTIF(O9:AP9,"APAGADO") -> 0 | N9: =(L9)/(M9+L9) -> 1
A10: ALTAMIRA | C10: ALT06 | D10: LOPE DE VEGA Y NECOCHEA | E10: Domo | F10: PTP A FO | H10: Instalada sin alta en sistema. ALTA en sistema y en funcionamiento 04/05/2020 | I10: -347738090000 | J10: -582721410000 | K10: 172.20.12.12 | L10: =COUNTIF(O10:AR10,"") -> 29 | M10: =COUNTIF(O10:AP10,"APAGADO") -> 1 | N10: =(L10)/(M10+L10) -> 0.96666667 | AD10: APAGADO
A11: ALTAMIRA | C11: ALT01 | D11: Calchaqui y Sgto. Cabral | E11: Domo | F11: Fibra Optica | G11: Universidad, Zona Bancaria, Flujo Vehicular, Posible Via de Escape | I11: -347769580000 | J11: -582650900000 | K11: 172.20.10.6 | L11: =COUNTIF(O11:AR11,"") -> 27 | M11: =COUNTIF(O11:AP11,"APAGADO") -> 3 | N11: =(L11)/(M11+L11) -> 0.9 | O11: APAGADO | P11: APAGADO | AD11: APAGADO
A12: ALTAMIRA | C12: ALT02 | D12: Calchaqui y Lope de Vega | E12: Domo | F12: PTP A FO | G12: Hospital, Flujo Vehicular, Peatonal | I12: -347718470000 | J12: -582688560000 | K12: 172.20.12.218 | L12: =COUNTIF(O12:AR12,"") -> 29 | M12: =COUNTIF(O12:AP12,"APAGADO") -> 1 | N12: =(L12)/(M12+L12) -> 0.96666667 | AD12: APAGADO
A13: ALTAMIRA | B13: 44642 | C13: ALT03 | D13: Bombero Galarza y Necochea | E13: Domo | F13: Fibra Optica | G13: Hospital, Limite del Partido | I13: -347726570000 | J13: -582730620000 | K13: 172.20.12.54 | L13: =COUNTIF(O13:AR13,"") -> 27 | M13: =COUNTIF(O13:AP13,"APAGADO") -> 3 | N13: =(L13)/(M13+L13) -> 0.9 | W13: APAGADO | X13: APAGADO | AD13: APAGADO
B14: 44642 | C14: ALT04 | D14: Francia y Necochea | E14: Domo | F14: Fibra Optica | G14: Zona RecreaciÃ³n | I14: -347705420000 | J14: -582748000000 | K14: 172.20.12.55 | L14: =COUNTIF(O14:AR14,"") -> 24 | M14: =COUNTIF(O14:AP14,"APAGADO") -> 6 | N14: =(L14)/(M14+L14) -> 0.8 | O14: APAGADO | P14: APAGADO | Q14: APAGADO | S14: APAGADO | U14: APAGADO | AD14: APAGADO
A15: ALTAMIRA | C15: ALT05 | D15: Av. Calchaqui y Bombero Galarza | E15: Domo | F15: PTP A FO | G15: Zona Bancaria, Flujo Vehicular, Posible via de escape, Limite del partido | I15: -347708370000 | J15: -582698000000 | K15: 172.20.12.216 | L15: =COUNTIF(O15:AR15,"") -> 29 | M15: =COUNTIF(O15:AP15,"APAGADO") -> 1 | N15: =(L15)/(M15+L15) -> 0.96666667 | AD15: APAGADO
A16: ALTAMIRA | C16: ALT07 | D16: AV. CALCHAQUI Y AV. DEL TRABAJO | E16: DOMO | F16: PTP A FO | H16: SE DA DE ALTA EL 17/09/2020 18:51HS | I16: -347737570000 | J16: -582676650000 | K16: 172.20.10.57 | L16: =COUNTIF(O16:AR16,"") -> 29 | M16: =COUNTIF(O16:AP16,"APAGADO") -> 1 | N16: =(L16)/(M16+L16) -> 0.96666667 | AD16: APAGADO
A17: ALTAMIRA | B17: 44642 | C17: ALT08 | D17: HUMAITA Y NECOCHEA | E17: DOMO | F17: Fibra Optica | H17: REPORTA IMAGENES 20/08/2021 | I17: -347749440000 | J17: -582711610000 | K17: 172.20.11.215 | L17: =COUNTIF(O17:AR17,"") -> 29 | M17: =COUNTIF(O17:AP17,"APAGADO") -> 1 | N17: =(L17)/(M17+L17) -> 0.96666667 | AD17: APAGADO
A18: ALTAMIRA | B18: 44642 | C18: ALT09 | D18: NECOCHEA Y CURUPAITY | E18: DOMO | F18: Fibra Optica | H18: SE DA DE ALTA 25/08/2021 | I18: -347743740000 | J18: -582715650000 | K18: 172.20.11.216 | L18: =COUNTIF(O18:AR18,"") -> 29 | M18: =COUNTIF(O18:AP18,"APAGADO") -> 1 | N18: =(L18)/(M18+L18) -> 0.96666667 | AD18: APAGADO
A19: AGUSTIN RAMIREZ | C19: ARA01 | D19: Malambo y Tranquera | E19: Domo | F19: Fibra Optica | G19: Zona Escolar, Flujo Vehicular | I19: -347979380000 | J19: -583160950000 | K19: 172.20.12.110 | L19: =COUNTIF(O19:AR19,"") -> 30 | M19: =COUNTIF(O19:AP19,"APAGADO") -> 0 | N19: =(L19)/(M19+L19) -> 1
A20: ALTAMIRA | C20: ALT10 | D20: REP. FRANCIA Y CALCHAQUI (RP 36) | E20: DOMO | F20: PTP A FO | H20: SE DA DE ALTA 10/11/2021 | I20: -347689160000 | J20: -582717100000 | K20: 172.20.12.156 | L20: =COUNTIF(O20:AR20,"") -> 29 | M20: =COUNTIF(O20:AP20,"APAGADO") -> 1 | N20: =(L20)/(M20+L20) -> 0.96666667 | AD20: APAGADO
A21: BELGRANO | C21: BEL01 | D21: San Martin y Dardo Rocha | E21: DOMO | F21: Fibra Optica | G21: Zona Escolar, Flujo Vehicular | H21: 19/03/2020 SE RETIRO DISPOSITIVO POR RIESGO DE CAIDA. 19/08/2020 comenzo a funcionar. | I21: -347918370000 | J21: -582786080000 | K21: 172.20.12.64 | L21: =COUNTIF(O21:AR21,"") -> 30 | M21: =COUNTIF(O21:AP21,"APAGADO") -> 0 | N21: =(L21)/(M21+L21) -> 1
C22: CEN51 | D22: ILLIA Y LAS HERAS | E22: FIJA | F22: Fibra Optica | G22: POSIBLE VIA DE ESCAPE, Y FLUJO VEHICULAR | I22: -347987830000 | J22: -582840920000 | K22: 172.20.11.29 | L22: =COUNTIF(O22:AR22,"") -> 19 | M22: =COUNTIF(O22:AP22,"APAGADO") -> 11 | N22: =(L22)/(M22+L22) -> 0.63333333 | O22: APAGADO | P22: APAGADO | Q22: APAGADO | R22: APAGADO | S22: APAGADO | T22: APAGADO | U22: APAGADO | X22: APAGADO | Y22: APAGADO | Z22: APAGADO | AA22: APAGADO
C23: CEN53 | D23: GUTIERREZ Y BROWN | E23: Domo | F23: Radio | I23: -348013650000 | J23: -582715700000 | K23: 172.20.200.166 | L23: =COUNTIF(O23:AR23,"") -> 30 | M23: =COUNTIF(O23:AP23,"APAGADO") -> 0 | N23: =(L23)/(M23+L23) -> 1
C24: CEN 54 | D24: GUTIERREZ Y PRINGLES | E24: Domo | F24: Radio | I24: -348013470000 | J24: -582698540000 | K24: 172.20.200.165 | L24: =COUNTIF(O24:AR24,"") -> 30 | M24: =COUNTIF(O24:AP24,"APAGADO") -> 0 | N24: =(L24)/(M24+L24) -> 1
C25: CEN 55 | D25: BOUREL Y URQUIZA | E25: Domo | F25: Radio | I25: -348019110000 | J25: -582819990000 | K25: 172.20.200.163 | L25: =COUNTIF(O25:AR25,"") -> 30 | M25: =COUNTIF(O25:AP25,"APAGADO") -> 0 | N25: =(L25)/(M25+L25) -> 1
A26: CENTRO | C26: CEN 56 | D26: Newbery y Falucho | E26: DOMO | F26: Radio | G26: Posible via de escape, Cruce Peligroso | I26: -348073990000 | J26: -582850080000 | K26: 172.20.200.161 | L26: =COUNTIF(O26:AR26,"") -> 30 | M26: =COUNTIF(O26:AP26,"APAGADO") -> 0 | N26: =(L26)/(M26+L26) -> 1
C27: CEN 57 | D27: 25 DE MAYO Y DORREGO | E27: DOMO | F27: Radio | I27: -348007360000 | J27: -582804240000 | K27: 172.20.200.199 | L27: =COUNTIF(O27:AR27,"") -> 29 | M27: =COUNTIF(O27:AP27,"APAGADO") -> 1 | N27: =(L27)/(M27+L27) -> 0.96666667 | Y27: APAGADO
C28: CEN 58 | D28: EEUU Y MORENO | E28: DOMO | F28: Fibra Optica | H28: INSTALADA: 11/06/18. EN FUNCIONAMIENTO: 27/06/18. | I28: -348103030000 | J28: -582835720000 | K28: 172.20.11.84 | L28: =COUNTIF(O28:AR28,"") -> 30 | M28: =COUNTIF(O28:AP28,"APAGADO") -> 0 | N28: =(L28)/(M28+L28) -> 1
C29: CEN 59 | D29: CHACABUCO Y BOUREL | E29: DOMO | F29: Radio | H29: INSTALADA:11/06/18EN FUNCIONAMIENTO: 27/06/18 | I29: -348039300000 | J29: -582819780000 | K29: 172.20.200.188 | L29: =COUNTIF(O29:AR29,"") -> 30 | M29: =COUNTIF(O29:AP29,"APAGADO") -> 0 | N29: =(L29)/(M29+L29) -> 1
A30: CENTRO | C30: CEN 60 | D30: RECONQUISTA Y ILLIA | E30: DOMO | F30: PTP A FO | H30: ALTA 26/10/2019 | I30: -347999170000 | J30: -582863530000 | K30: 172.20.12.67 | L30: =COUNTIF(O30:AR30,"") -> 19 | M30: =COUNTIF(O30:AP30,"APAGADO") -> 11 | N30: =(L30)/(M30+L30) -> 0.63333333 | O30: APAGADO | P30: APAGADO | Q30: APAGADO | R30: APAGADO | S30: APAGADO | T30: APAGADO | U30: APAGADO | X30: APAGADO | Y30: APAGADO | Z30: APAGADO | AA30: APAGADO
A31: CENTRO | C31: CEN 61 | D31: BOUREL Y MAIPU | E31: DOMO | F31: Radio | H31: ALTA EN FUNCIONAMIENTO 12/04/2019 | I31: -348040550000 | J31: -582819380000 | K31: 172.20.200.159 | L31: =COUNTIF(O31:AR31,"") -> 30 | M31: =COUNTIF(O31:AP31,"APAGADO") -> 0 | N31: =(L31)/(M31+L31) -> 1
A32: CENTRO | C32: CEN 62 | D32: ESPAÑA Y ALEM | E32: DOMO | F32: PTP A FO | H32: ALTA: 16/06/2020 | I32: -348038200000 | J32: -582766160000 | K32: 172.20.12.82 | L32: =COUNTIF(O32:AR32,"") -> 30 | M32: =COUNTIF(O32:AP32,"APAGADO") -> 0 | N32: =(L32)/(M32+L32) -> 1
A33: CENTRO | C33: CEN 63 | D33: SAN MARTIN Y URQUIZA | E33: DOMO | F33: Fibra Optica | H33: DADA DE ALTA ABRIL 2021 | I33: -348017700000 | J33: -582785020000 | K33: 172.20.11.112 | L33: =COUNTIF(O33:AR33,"") -> 30 | M33: =COUNTIF(O33:AP33,"APAGADO") -> 0 | N33: =(L33)/(M33+L33) -> 1
A34: CENTRO | C34: CEN 70 | D34: RIVADAVIA Y 25 MAYO | E34: Domo | F34: Fibra Optica | H34: alta en sistema 25/11/2021 | I34: -348091950000 | J34: -582800930000 | K34: 172.20.11.221 | L34: =COUNTIF(O34:AR34,"") -> 30 | M34: =COUNTIF(O34:AP34,"APAGADO") -> 0 | N34: =(L34)/(M34+L34) -> 1
A35: CENTRO | C35: CEN 71 | D35: MORENO Y BOUREL | E35: Domo | F35: Fibra Optica | H35: alta en sistema 25/11/2021 | I35: -348103130000 | J35: -582818230000 | K35: 172.20.11.220 | L35: =COUNTIF(O35:AR35,"") -> 29 | M35: =COUNTIF(O35:AP35,"APAGADO") -> 1 | N35: =(L35)/(M35+L35) -> 0.96666667 | U35: APAGADO
A36: CENTRO | C36: CEN 72 | D36: MORENO Y 25 DE MAYO | E36: Domo | F36: Fibra Optica | H36: ALTA EN SISTEMA 25/11/2021 | I36: -348102250000 | J36: -582800780000 | K36: 172.20.11.219 | L36: =COUNTIF(O36:AR36,"") -> 28 | M36: =COUNTIF(O36:AP36,"APAGADO") -> 2 | N36: =(L36)/(M36+L36) -> 0.93333333 | U36: APAGADO | V36: APAGADO
A37: CENTRO | C37: CEN01 | D37: San Martin y 9 de Julio | E37: Fija | F37: Fibra Optica | G37: Zona Comercial, Flujo Vehicular | I37: -348028100000 | J37: -582782860000 | K37: 172.20.11.10 | L37: =COUNTIF(O37:AR37,"") -> 30 | M37: =COUNTIF(O37:AP37,"APAGADO") -> 0 | N37: =(L37)/(M37+L37) -> 1
A38: CENTRO | C38: CEN02 | D38: San Martin y Almafuerte | E38: Fija | F38: Fibra Optica | G38: Bomberos, Flujo Vehicular, Zona Comercial | I38: -348006070000 | J38: -582784580000 | K38: 172.20.11.11 | L38: =COUNTIF(O38:AR38,"") -> 30 | M38: =COUNTIF(O38:AP38,"APAGADO") -> 0 | N38: =(L38)/(M38+L38) -> 1
A39: CENTRO | C39: CEN03 | D39: San Martin y Sallares | E39: Domo | F39: Fibra Optica | G39: Zona Comercial, Flujo Vehicular | H39: 29/03/19 FUNCIONA EN COD 1 | I39: -348080340000 | J39: -582780930000 | K39: 172.20.12.30 | L39: =COUNTIF(O39:AR39,"") -> 30 | M39: =COUNTIF(O39:AP39,"APAGADO") -> 0 | N39: =(L39)/(M39+L39) -> 1
A40: CENTRO | C40: CEN04 | D40: San Martin y Contreras | E40: Domo | F40: Fibra Optica | G40: Zona de recreaciÃ³n, Flujo vehicular | I40: -348049240000 | J40: -582781680000 | K40: 172.20.12.29 | L40: =COUNTIF(O40:AR40,"") -> 30 | M40: =COUNTIF(O40:AP40,"APAGADO") -> 0 | N40: =(L40)/(M40+L40) -> 1
...

Sheet ESTADISTICA
A1: ='RESUMEN TOTAL'!A4 -> Barrio | B1: ='RESUMEN TOTAL'!C4 -> [Denominacion] | C1: ='RESUMEN TOTAL'!D4 -> [Ubicacion] | D1: ='RESUMEN TOTAL'!E4 -> [Tipo de Camara] | E1: ='RESUMEN TOTAL'!F4 -> [Tipo de Conexion] | F1: ='RESUMEN TOTAL'!O4 -> 44713 | G1: ='RESUMEN TOTAL'!P4 -> 44714 | H1: ='RESUMEN TOTAL'!Q4 -> 44715 | I1: ='RESUMEN TOTAL'!R4 -> 44716 | J1: ='RESUMEN TOTAL'!S4 -> 44717 | K1: ='RESUMEN TOTAL'!T4 -> 44718 | L1: ='RESUMEN TOTAL'!U4 -> 44719 | M1: ='RESUMEN TOTAL'!V4 -> 44720 | ... AI1: ='RESUMEN TOTAL'!AR4 -> 44742
A2: ='RESUMEN TOTAL'!A5 -> PRESIDENTE PERON (PEPSI) | B2: ='RESUMEN TOTAL'!C5 -> MAR 01 | C2: ='RESUMEN TOTAL'!D5 -> RP36 Y LA ESMERALDA | D2: ='RESUMEN TOTAL'!E5 -> DOMO | E2: ='RESUMEN TOTAL'!F5 -> Fibra Optica | F2: ='RESUMEN TOTAL'!O5 -> APAGADO | G2: ='RESUMEN TOTAL'!P5 -> APAGADO | H2: ='RESUMEN TOTAL'!Q5 -> APAGADO | I2: ='RESUMEN TOTAL'!R5 -> APAGADO | J2: ='RESUMEN TOTAL'!S5 -> APAGADO | K2: ='RESUMEN TOTAL'!T5 -> APAGADO | L2: ='RESUMEN TOTAL'!U5 -> APAGADO | M2: ='RESUMEN TOTAL'!V5 -> APAGADO | ... AI2: ='RESUMEN TOTAL'!AR5 -> 0
A3: ='RESUMEN TOTAL'!A6 -> MAYOL | B3: ='RESUMEN TOTAL'!C6 -> MAY 01 | C3: ='RESUMEN TOTAL'!D6 -> Eva Peron y Cabildo | D3: ='RESUMEN TOTAL'!E6 -> Domo | E3: ='RESUMEN TOTAL'!F6 -> Radio | F3: ='RESUMEN TOTAL'!O6 -> 0 | G3: ='RESUMEN TOTAL'!P6 -> 0 | H3: ='RESUMEN TOTAL'!Q6 -> 0 | I3: ='RESUMEN TOTAL'!R6 -> 0 | J3: ='RESUMEN TOTAL'!S6 -> 0 | K3: ='RESUMEN TOTAL'!T6 -> 0 | L3: ='RESUMEN TOTAL'!U6 -> 0 | M3: ='RESUMEN TOTAL'!V6 -> 0 | ... AI3: ='RESUMEN TOTAL'!AR6 -> 0
A4: ='RESUMEN TOTAL'!A7 -> 0 | B4: ='RESUMEN TOTAL'!C7 -> MAY 02 | C4: ='RESUMEN TOTAL'!D7 -> EVA PERON Y MONTEVIDEO | D4: ='RESUMEN TOTAL'!E7 -> Domo | E4: ='RESUMEN TOTAL'!F7 -> Radio | F4: ='RESUMEN TOTAL'!O7 -> APAGADO | G4: ='RESUMEN TOTAL'!P7 -> APAGADO | H4: ='RESUMEN TOTAL'!Q7 -> APAGADO | I4: ='RESUMEN TOTAL'!R7 -> APAGADO | J4: ='RESUMEN TOTAL'!S7 -> APAGADO | K4: ='RESUMEN TOTAL'!T7 -> APAGADO | L4: ='RESUMEN TOTAL'!U7 -> APAGADO | M4: ='RESUMEN TOTAL'!V7 -> APAGADO | ... AI4: ='RESUMEN TOTAL'!AR7 -> 0
A5: ='RESUMEN TOTAL'!A8 -> MAYOL | B5: ='RESUMEN TOTAL'!C8 -> MAY 03 | C5: ='RESUMEN TOTAL'!D8 -> CHAÑAR Y SAN NICOLAS | D5: ='RESUMEN TOTAL'!E8 -> DOMO | E5: ='RESUMEN TOTAL'!F8 -> PTP A FO | F5: ='RESUMEN TOTAL'!O8 -> 0 | G5: ='RESUMEN TOTAL'!P8 -> 0 | H5: ='RESUMEN TOTAL'!Q8 -> 0 | I5: ='RESUMEN TOTAL'!R8 -> 0 | J5: ='RESUMEN TOTAL'!S8 -> 0 | K5: ='RESUMEN TOTAL'!T8 -> 0 | L5: ='RESUMEN TOTAL'!U8 -> 0 | M5: ='RESUMEN TOTAL'!V8 -> 0 | ... AI5: ='RESUMEN TOTAL'!AR8 -> 0
A6: ='RESUMEN TOTAL'!A9 -> 0 | B6: ='RESUMEN TOTAL'!C9 -> MAY 04 | C6: ='RESUMEN TOTAL'!D9 -> MAR CHIQUITA Y RIO JACHAL | D6: ='RESUMEN TOTAL'!E9 -> DOMO | E6: ='RESUMEN TOTAL'!F9 -> Radio | F6: ='RESUMEN TOTAL'!O9 -> 0 | G6: ='RESUMEN TOTAL'!P9 -> 0 | H6: ='RESUMEN TOTAL'!Q9 -> 0 | I6: ='RESUMEN TOTAL'!R9 -> 0 | J6: ='RESUMEN TOTAL'!S9 -> 0 | K6: ='RESUMEN TOTAL'!T9 -> 0 | L6: ='RESUMEN TOTAL'!U9 -> 0 | M6: ='RESUMEN TOTAL'!V9 -> 0 | ... AI6: ='RESUMEN TOTAL'!AR9 -> 0
A7: ='RESUMEN TOTAL'!A10 -> ALTAMIRA | B7: ='RESUMEN TOTAL'!C10 -> ALT06 | C7: ='RESUMEN TOTAL'!D10 -> LOPE DE VEGA Y NECOCHEA | D7: ='RESUMEN TOTAL'!E10 -> Domo | E7: ='RESUMEN TOTAL'!F10 -> PTP A FO | F7: ='RESUMEN TOTAL'!O10 -> 0 | G7: ='RESUMEN TOTAL'!P10 -> 0 | H7: ='RESUMEN TOTAL'!Q10 -> 0 | I7: ='RESUMEN TOTAL'!R10 -> 0 | J7: ='RESUMEN TOTAL'!S10 -> 0 | K7: ='RESUMEN TOTAL'!T10 -> 0 | L7: ='RESUMEN TOTAL'!U10 -> 0 | M7: ='RESUMEN TOTAL'!V10 -> 0 | ... AI7: ='RESUMEN TOTAL'!AR10 -> 0
A8: ='RESUMEN TOTAL'!A11 -> ALTAMIRA | B8: ='RESUMEN TOTAL'!C11 -> ALT01 | C8: ='RESUMEN TOTAL'!D11 -> Calchaqui y Sgto. Cabral | D8: ='RESUMEN TOTAL'!E11 -> Domo | E8: ='RESUMEN TOTAL'!F11 -> Fibra Optica | F8: ='RESUMEN TOTAL'!O11 -> APAGADO | G8: ='RESUMEN TOTAL'!P11 -> APAGADO | H8: ='RESUMEN TOTAL'!Q11 -> 0 | I8: ='RESUMEN TOTAL'!R11 -> 0 | J8: ='RESUMEN TOTAL'!S11 -> 0 | K8: ='RESUMEN TOTAL'!T11 -> 0 | L8: ='RESUMEN TOTAL'!U11 -> 0 | M8: ='RESUMEN TOTAL'!V11 -> 0 | ... AI8: ='RESUMEN TOTAL'!AR11 -> 0
A9: ='RESUMEN TOTAL'!A12 -> ALTAMIRA | B9: ='RESUMEN TOTAL'!C12 -> ALT02 | C9: ='RESUMEN TOTAL'!D12 -> Calchaqui y Lope de Vega | D9: ='RESUMEN TOTAL'!E12 -> Domo | E9: ='RESUMEN TOTAL'!F12 -> PTP A FO | F9: ='RESUMEN TOTAL'!O12 -> 0 | G9: ='RESUMEN TOTAL'!P12 -> 0 | H9: ='RESUMEN TOTAL'!Q12 -> 0 | I9: ='RESUMEN TOTAL'!R12 -> 0 | J9: ='RESUMEN TOTAL'!S12 -> 0 | K9: ='RESUMEN TOTAL'!T12 -> 0 | L9: ='RESUMEN TOTAL'!U12 -> 0 | M9: ='RESUMEN TOTAL'!V12 -> 0 | ... AI9: ='RESUMEN TOTAL'!AR12 -> 0
A10: ='RESUMEN TOTAL'!A13 -> ALTAMIRA | B10: ='RESUMEN TOTAL'!C13 -> ALT03 | C10: ='RESUMEN TOTAL'!D13 -> Bombero Galarza y Necochea | D10: ='RESUMEN TOTAL'!E13 -> Domo | E10: ='RESUMEN TOTAL'!F13 -> Fibra Optica | F10: ='RESUMEN TOTAL'!O13 -> 0 | G10: ='RESUMEN TOTAL'!P13 -> 0 | H10: ='RESUMEN TOTAL'!Q13 -> 0 | I10: ='RESUMEN TOTAL'!R13 -> 0 | J10: ='RESUMEN TOTAL'!S13 -> 0 | K10: ='RESUMEN TOTAL'!T13 -> 0 | L10: ='RESUMEN TOTAL'!U13 -> 0 | M10: ='RESUMEN TOTAL'!V13 -> 0 | ... AI10: ='RESUMEN TOTAL'!AR13 -> 0
A11: ='RESUMEN TOTAL'!A14 -> 0 | B11: ='RESUMEN TOTAL'!C14 -> ALT04 | C11: ='RESUMEN TOTAL'!D14 -> Francia y Necochea | D11: ='RESUMEN TOTAL'!E14 -> Domo | E11: ='RESUMEN TOTAL'!F14 -> Fibra Optica | F11: ='RESUMEN TOTAL'!O14 -> APAGADO | G11: ='RESUMEN TOTAL'!P14 -> APAGADO | H11: ='RESUMEN TOTAL'!Q14 -> APAGADO | I11: ='RESUMEN TOTAL'!R14 -> 0 | J11: ='RESUMEN TOTAL'!S14 -> APAGADO | K11: ='RESUMEN TOTAL'!T14 -> 0 | L11: ='RESUMEN TOTAL'!U14 -> APAGADO | M11: ='RESUMEN TOTAL'!V14 -> 0 | ... AI11: ='RESUMEN TOTAL'!AR14 -> 0
A12: ='RESUMEN TOTAL'!A15 -> ALTAMIRA | B12: ='RESUMEN TOTAL'!C15 -> ALT05 | C12: ='RESUMEN TOTAL'!D15 -> Av. Calchaqui y Bombero Galarza | D12: ='RESUMEN TOTAL'!E15 -> Domo | E12: ='RESUMEN TOTAL'!F15 -> PTP A FO | F12: ='RESUMEN TOTAL'!O15 -> 0 | G12: ='RESUMEN TOTAL'!P15 -> 0 | H12: ='RESUMEN TOTAL'!Q15 -> 0 | I12: ='RESUMEN TOTAL'!R15 -> 0 | J12: ='RESUMEN TOTAL'!S15 -> 0 | K12: ='RESUMEN TOTAL'!T15 -> 0 | L12: ='RESUMEN TOTAL'!U15 -> 0 | M12: ='RESUMEN TOTAL'!V15 -> 0 | ... AI12: ='RESUMEN TOTAL'!AR15 -> 0
... A374: ='RESUMEN TOTAL'!A377 -> CENTRO | B374: ='RESUMEN TOTAL'!C377 -> CEN75 | C374: ='RESUMEN TOTAL'!D377 -> CASTELLI Y 25 DE MAYO | D374: ='RESUMEN TOTAL'!E377 -> DOMO | E374: ='RESUMEN TOTAL'!F377 -> Fibra Optica | F374: ='RESUMEN TOTAL'!O377 -> 0 | G374: ='RESUMEN TOTAL'!P377 -> 0 | H374: ='RESUMEN TOTAL'!Q377 -> 0 | I374: ='RESUMEN TOTAL'!R377 -> 0 | J374: ='RESUMEN TOTAL'!S377 -> 0 | K374: ='RESUMEN TOTAL'!T377 -> 0 | L374: ='RESUMEN TOTAL'!U377 -> 0 | M374: ='RESUMEN TOTAL'!V377 -> 0 | ... AI374: ='RESUMEN TOTAL'!AR377 -> 0

Sheet APAGADOS
E1: APAGADOS | F1: =COUNTIF(F3:F366, "APAGADO") -> 71 | G1: =COUNTIF(G3:G366, "APAGADO") -> 88 | H1: =COUNTIF(H3:H366, "APAGADO") -> 83 | I1: =COUNTIF(I3:I366, "APAGADO") -> 68 | J1: =COUNTIF(J3:J366, "APAGADO") -> 65 | K1: =COUNTIF(K3:K366, "APAGADO") -> 63 | L1: =COUNTIF(L3:L366, "APAGADO") -> 62 | M1: =COUNTIF(M3:M366, "APAGADO") -> 44 | ... V1: =COUNTIF(V3:V366, "APAGADO") -> 0 | W1: =COUNTIF(W3:W447, "APAGADO") -> 38 | X1: =COUNTIF(X3:X366, "APAGADO") -> 0 | Y1: =COUNTIF(Y3:Y366, "APAGADO") -> 0 | Z1: =COUNTIF(Z3:Z366, "APAGADO") -> 0 | AA1: =COUNTIF(AA3:AA366, "APAGADO") -> 0 | AB1: =COUNTIF(AB3:AB366, "APAGADO") -> 0 | AC1: =COUNTIF(AC3:AC366, "APAGADO") -> 0 | AD1: =COUNTIF(AD3:AD366, "APAGADO") -> 0 | AE1: =COUNTIF(AE3:AE366, "APAGADO") -> 0 | ... AI1: =COUNTIF(AI3:AI366, "APAGADO") -> 0
A2: =ESTADISTICA!A1 -> Barrio | B2: =ESTADISTICA!B1 -> [Denominacion] | C2: =ESTADISTICA!C1 -> [Ubicacion] | D2: =ESTADISTICA!D1 -> [Tipo de Camara] | E2: =ESTADISTICA!E1 -> [Tipo de Conexion] | F2: =ESTADISTICA!F1 -> 44713 | G2: =ESTADISTICA!G1 -> 44714 | H2: =ESTADISTICA!H1 -> 44715 | ... AI2: =ESTADISTICA!AI1 -> 44742
A3: =ESTADISTICA!A2 -> PRESIDENTE PERON (PEPSI) | B3: =ESTADISTICA!B2 -> MAR 01 | C3: =ESTADISTICA!C2 -> RP36 Y LA ESMERALDA | D3: =ESTADISTICA!D2 -> DOMO | E3: =ESTADISTICA!E2 -> Fibra Optica | F3: =ESTADISTICA!F2 -> APAGADO | G3: =ESTADISTICA!G2 -> APAGADO | H3: =ESTADISTICA!H2 -> APAGADO | ... AG3: =ESTADISTICA!AG2 -> 0
A4: =ESTADISTICA!A3 -> MAYOL | B4: =ESTADISTICA!B3 -> MAY 01 | C4: =ESTADISTICA!C3 -> Eva Peron y Cabildo | D4: =ESTADISTICA!D3 -> Domo | E4: =ESTADISTICA!E3 -> Radio | F4: =ESTADISTICA!F3 -> 0 | G4: =ESTADISTICA!G3 -> 0 | H4: =ESTADISTICA!H3 -> 0 | ... AG4: =ESTADISTICA!AG3 -> 0
A5: =ESTADISTICA!A4 -> 0 | B5: =ESTADISTICA!B4 -> MAY 02 | C5: =ESTADISTICA!C4 -> EVA PERON Y MONTEVIDEO | D5: =ESTADISTICA!D4 -> Domo | E5: =ESTADISTICA!E4 -> Radio | F5: =ESTADISTICA!F4 -> APAGADO | G5: =ESTADISTICA!G4 -> APAGADO | H5: =ESTADISTICA!H4 -> APAGADO | ... AG5: =ESTADISTICA!AG4 -> 0
A6: =ESTADISTICA!A5 -> MAYOL | B6: =ESTADISTICA!B5 -> MAY 03 | C6: =ESTADISTICA!C5 -> CHAÑAR Y SAN NICOLAS | D6: =ESTADISTICA!D5 -> DOMO | E6: =ESTADISTICA!E5 -> PTP A FO | F6: =ESTADISTICA!F5 -> 0 | G6: =ESTADISTICA!G5 -> 0 | H6: =ESTADISTICA!H5 -> 0 | ... AG6: =ESTADISTICA!AG5 -> 0
A7: =ESTADISTICA!A6 -> 0 | B7: =ESTADISTICA!B6 -> MAY 04 | C7: =ESTADISTICA!C6 -> MAR CHIQUITA Y RIO JACHAL | D7: =ESTADISTICA!D6 -> DOMO | E7: =ESTADISTICA!E6 -> Radio | F7: =ESTADISTICA!F6 -> 0 | G7: =ESTADISTICA!G6 -> 0 | H7: =ESTADISTICA!H6 -> 0 | ... AG7: =ESTADISTICA!AG6 -> 0
A8: =ESTADISTICA!A7 -> ALTAMIRA | B8: =ESTADISTICA!B7 -> ALT06 | C8: =ESTADISTICA!C7 -> LOPE DE VEGA Y NECOCHEA | D8: =ESTADISTICA!D7 -> Domo | E8: =ESTADISTICA!E7 -> PTP A FO | F8: =ESTADISTICA!F7 -> 0 | G8: =ESTADISTICA!G7 -> 0 | H8: =ESTADISTICA!H7 -> 0 | ... AG8: =ESTADISTICA!AG7 -> 0
A9: =ESTADISTICA!A8 -> ALTAMIRA | B9: =ESTADISTICA!B8 -> ALT01 | C9: =ESTADISTICA!C8 -> Calchaqui y Sgto. Cabral | D9: =ESTADISTICA!D8 -> Domo | E9: =ESTADISTICA!E8 -> Fibra Optica | F9: =ESTADISTICA!F8 -> APAGADO | G9: =ESTADISTICA!G8 -> APAGADO | H9: =ESTADISTICA!H8 -> 0 | ... AG9: =ESTADISTICA!AG8 -> 0
A10: =ESTADISTICA!A9 -> ALTAMIRA | B10: =ESTADISTICA!B9 -> ALT02 | C10: =ESTADISTICA!C9 -> Calchaqui y Lope de Vega | D10: =ESTADISTICA!D9 -> Domo | E10: =ESTADISTICA!E9 -> PTP A FO | F10: =ESTADISTICA!F9 -> 0 | G10: =ESTADISTICA!G9 -> 0 | H10: =ESTADISTICA!H9 -> 0 | ... AG10: =ESTADISTICA!AG9 -> 0
A11: =ESTADISTICA!A10 -> ALTAMIRA | B11: =ESTADISTICA!B10 -> ALT03 | C11: =ESTADISTICA!C10 -> Bombero Galarza y Necochea | D11: =ESTADISTICA!D10 -> Domo | E11: =ESTADISTICA!E10 -> Fibra Optica | F11: =ESTADISTICA!F10 -> 0 | G11: =ESTADISTICA!G10 -> 0 | H11: =ESTADISTICA!H10 -> 0 | ... AG11: =ESTADISTICA!AG10 -> 0
A12: =ESTADISTICA!A11 -> 0 | B12: =ESTADISTICA!B11 -> ALT04 | C12: =ESTADISTICA!C11 -> Francia y Necochea | D12: =ESTADISTICA!D11 -> Domo | E12: =ESTADISTICA!E11 -> Fibra Optica | F12: =ESTADISTICA!F11 -> APAGADO | G12: =ESTADISTICA!G11 -> APAGADO | H12: =ESTADISTICA!H11 -> APAGADO | ... AG12: =ESTADISTICA!AG11 -> 0
A13: =ESTADISTICA!A12 -> ALTAMIRA | B13: =ESTADISTICA!B12 -> ALT05 | C13: =ESTADISTICA!C12 -> Av. Calchaqui y Bombero Galarza | D13: =ESTADISTICA!D12 -> Domo | E13: =ESTADISTICA!E12 -> PTP A FO | F13: =ESTADISTICA!F12 -> 0 | G13: =ESTADISTICA!G12 -> 0 | H13: =ESTADISTICA!H12 -> 0 | ... AG13: =ESTADISTICA!AG12 -> 0
A14: =ESTADISTICA!A13 -> ALTAMIRA | B14: =ESTADISTICA!B13 -> ALT07 | C14: =ESTADISTICA!C13 -> AV. CALCHAQUI Y AV. DEL TRABAJO | D14: =ESTADISTICA!D13 -> DOMO | E14: =ESTADISTICA!E13 -> PTP A FO | F14: =ESTADISTICA!F13 -> 0 | G14: =ESTADISTICA!G13 -> 0 | H14: =ESTADISTICA!H13 -> 0 | ... AG14: =ESTADISTICA!AG13 -> 0
... A77: =ESTADISTICA!A76 -> CENTRO | B77: =ESTADISTICA!B76 -> CEN43 | C77: =ESTADISTICA!C76 -> Sallares y Alberdi | D77: =ESTADISTICA!D76 -> Domo | E77: =ESTADISTICA!E76 -> Fibra Optica | F77: =ESTADISTICA!F76 -> 0 | G77: =ESTADISTICA!G76 -> 0 | H77: =ESTADISTICA!H76 -> 0 | ... AG77: =ESTADISTICA!AG76 -> 0
A78: =ESTADISTICA!A77 -> CENTRO | B78: =ESTADISTICA!B77 -> CEN44 | C78: =ESTADISTICA!C77 -> Mitre y Brown | D78: =ESTADISTICA!D77 -> Domo | E78: =ESTADISTICA!E77 -> Fibra Optica | F78: =ESTADISTICA!F77 -> 0 | G78: =ESTADISTICA!G77 -> APAGADO | H78: =ESTADISTICA!H77 -> APAGADO | ... AI78: =ESTADISTICA!AI77 -> 0
A79: =ESTADISTICA!A78 -> CENTRO | B79: =ESTADISTICA!B78 -> CEN45 (fija 1) | C79: =ESTADISTICA!C78 -> EEUU Y MORENO | D79: =ESTADISTICA!D78 -> Fija | E79: =ESTADISTICA!E78 -> Fibra Optica | F79: =ESTADISTICA!F78 -> 0 | G79: =ESTADISTICA!G78 -> 0 | H79: =ESTADISTICA!H78 -> 0 | ... AG79: =ESTADISTICA!AG78 -> 0
A80: =ESTADISTICA!A79 -> CENTRO | B80: =ESTADISTICA!B79 -> CEN46 (fija 2) | C80: =ESTADISTICA!C79 -> EEUU Y MORENO | D80: =ESTADISTICA!D79 -> Fija | E80: =ESTADISTICA!E79 -> Fibra Optica | F80: =ESTADISTICA!F79 -> 0 | G80: =ESTADISTICA!G79 -> 0 | H80: =ESTADISTICA!H79 -> 0 | ... AG80: =ESTADISTICA!AG79 -> 0
A81: =ESTADISTICA!A80 -> CENTRO | B81: =ESTADISTICA!B80 -> CEN47 | C81: =ESTADISTICA!C80 -> Sallares y Brown | D81: =ESTADISTICA!D80 -> Domo | E81: =ESTADISTICA!E80 -> Fibra Optica | F81: =ESTADISTICA!F80 -> APAGADO | G81: =ESTADISTICA!G80 -> APAGADO | H81: =ESTADISTICA!H80 -> APAGADO | ... AG81: =ESTADISTICA!AG80 -> 0
A82: =ESTADISTICA!A81 -> CENTRO | B82: =ESTADISTICA!B81 -> CEN48 | C82: =ESTADISTICA!C81 -> Velez Sarsfield y Las Heras | D82: =ESTADISTICA!D81 -> Domo | E82: =ESTADISTICA!E81 -> Radio | F82: =ESTADISTICA!F81 -> APAGADO | G82: =ESTADISTICA!G81 -> APAGADO | H82: =ESTADISTICA!H81 -> 0 | ... AG82: =ESTADISTICA!AG81 -> 0
A83: =ESTADISTICA!A82 -> CENTRO | B83: =ESTADISTICA!B82 -> CEN49 | C83: =ESTADISTICA!C82 -> Av. San Martin y Florencio Sanchez | D83: =ESTADISTICA!D82 -> Domo | E83: =ESTADISTICA!E82 -> Radio | F83: =ESTADISTICA!F82 -> 0 | G83: =ESTADISTICA!G82 -> 0 | H83: =ESTADISTICA!H82 -> 0 | ... AG83: =ESTADISTICA!AG82 -> 0
A84: =ESTADISTICA!A83 -> CENTRO | B84: =ESTADISTICA!B83 -> CEN50 | C84: =ESTADISTICA!C83 -> Av. San Martin y Newbery | D84: =ESTADISTICA!D83 -> Domo | E84: =ESTADISTICA!E83 -> Radio | F84: =ESTADISTICA!F83 -> 0 | G84: =ESTADISTICA!G83 -> 0 | H84: =ESTADISTICA!H83 -> 0 | ... AG84: =ESTADISTICA!AG83 -> 0
A85: =ESTADISTICA!A84 -> 0 | B85: =ESTADISTICA!B84 -> CEN52 | C85: =ESTADISTICA!C84 -> San Martin y Almafuerte (ex San Martin y Dorrego) | D85: =ESTADISTICA!D84 -> DOMO | E85: =ESTADISTICA!E84 -> Radio | F85: =ESTADISTICA!F84 -> 0 | G85: =ESTADISTICA!G84 -> 0 | H85: =ESTADISTICA!H84 -> 0 | ... AG85: =ESTADISTICA!AG84 -> 0
A86: =ESTADISTICA!A85 -> CENTRO | B86: =ESTADISTICA!B85 -> CEN64 | C86: =ESTADISTICA!C85 -> SAN MARTIN Y BOCCUZZI | D86: =ESTADISTICA!D85 -> FIJA | E86: =ESTADISTICA!E85 -> Fibra Optica | F86: =ESTADISTICA!F85 -> 0 | G86: =ESTADISTICA!G85 -> 0 | H86: =ESTADISTICA!H85 -> 0 | ... AG86: =ESTADISTICA!AG85 -> 0
A87: =ESTADISTICA!A86 -> CENTRO | B87: =ESTADISTICA!B86 -> CEN65 | C87: =ESTADISTICA!C86 -> SAN MARTIN Y JUAN PERON | D87: =ESTADISTICA!D86 -> FIJA | E87: =ESTADISTICA!E86 -> Fibra Optica | F87: =ESTADISTICA!F86 -> 0 | G87: =ESTADISTICA!G86 -> 0 | H87: =ESTADISTICA!H86 -> 0 | ... AI87: =ESTADISTICA!AI86 -> 0
A88: =ESTADISTICA!A87 -> CENTRO | B88: =ESTADISTICA!B87 -> CEN66 | C88: =ESTADISTICA!C87 -> SAN MARTIN Y JUAN PERON | D88: =ESTADISTICA!D87 -> FIJA | E88: =ESTADISTICA!E87 -> Fibra Optica | F88: =ESTADISTICA!F87 -> APAGADO | G88: =ESTADISTICA!G87 -> 0 | H88: =ESTADISTICA!H87 -> APAGADO | ... AI88: =ESTADISTICA!AI87 -> 0
A89: =ESTADISTICA!A88 -> CENTRO | B89: =ESTADISTICA!B88 -> CEN67 (fija 1) | C89: =ESTADISTICA!C88 -> 9 DE JULIO Y BROWN | D89: =ESTADISTICA!D88 -> Fija | E89: =ESTADISTICA!E88 -> Fibra Optica | F89: =ESTADISTICA!F88 -> 0 | G89: =ESTADISTICA!G88 -> 0 | H89: =ESTADISTICA!H88 -> 0 | ... AI89: =ESTADISTICA!AI88 -> 0
A90: =ESTADISTICA!A89 -> CENTRO | B90: =ESTADISTICA!B89 -> CEN68 (fija 2) | C90: =ESTADISTICA!C89 -> 9 DE JULIO Y BROWN | D90: =ESTADISTICA!D89 -> Fija | E90: =ESTADISTICA!E89 -> Fibra Optica | F90: =ESTADISTICA!F89 -> 0 | G90: =ESTADISTICA!G89 -> 0 | H90: =ESTADISTICA!H89 -> 0 | ... AI90: =ESTADISTICA!AI89 -> 0
A91: =ESTADISTICA!A90 -> CENTRO | B91: =ESTADISTICA!B90 -> CEN69 | C91: =ESTADISTICA!C90 -> RIVADAVIA Y BOUREL | D91: =ESTADISTICA!D90 -> DOMO | E91: =ESTADISTICA!E90 -> Fibra Optica | F91: =ESTADISTICA!F90 -> 0 | G91: =ESTADISTICA!G90 -> 0 | H91: =ESTADISTICA!H90 -> 0 | ... AG91: =ESTADISTICA!AG90 -> 0
A92: =ESTADISTICA!A91 -> CENTRO | B92: =ESTADISTICA!B91 -> CEN73 | C92: =ESTADISTICA!C91 -> BOUREL Y DEFENSA | D92: =ESTADISTICA!D91 -> DOMO | E92: =ESTADISTICA!E91 -> Fibra Optica | F92: =ESTADISTICA!F91 -> APAGADO | G92: =ESTADISTICA!G91 -> APAGADO | H92: =ESTADISTICA!H91 -> APAGADO | ... AG92: =ESTADISTICA!AG91 -> 0
A93: =ESTADISTICA!A92 -> CENTRO | B93: =ESTADISTICA!B92 -> CEN74 | C93: =ESTADISTICA!C92 -> Las Heras y Maipu | D93: =ESTADISTICA!D92 -> Domo | E93: =ESTADISTICA!E92 -> Fibra Optica | F93: =ESTADISTICA!F92 -> 0 | G93: =ESTADISTICA!G92 -> 0 | H93: =ESTADISTICA!H92 -> 0 | ... AG93: =ESTADISTICA!AG92 -> 0
A94: =ESTADISTICA!A93 -> SAN NICOLAS | B94: =ESTADISTICA!B93 -> CHA01 | C94: =ESTADISTICA!C93 -> Novak y Pte Illia | D94: =ESTADISTICA!D93 -> Domo | E94: =ESTADISTICA!E93 -> Radio | F94: =ESTADISTICA!F93 -> 0 | G94: =ESTADISTICA!G93 -> 0 | H94: =ESTADISTICA!H93 -> 0 | ... AG94: =ESTADISTICA!AG93 -> 0
A95: =ESTADISTICA!A94 -> CHACABUCO | B95: =ESTADISTICA!B94 -> CHA02 | C95: =ESTADISTICA!C94 -> Pte. Illia y Posadas | D95: =ESTADISTICA!D94 -> Domo | E95: =ESTADISTICA!E94 -> Radio | F95: =ESTADISTICA!F94 -> 0 | G95: =ESTADISTICA!G94 -> 0 | H95: =ESTADISTICA!H94 -> 0 | ... AG95: =ESTADISTICA!AG94 -> 0
A96: =ESTADISTICA!A95 -> CHACABUCO | B96: =ESTADISTICA!B95 -> CHA03 | C96: =ESTADISTICA!C95 -> MAIPU Y ALVAREZ THOMAS | D96: =ESTADISTICA!D95 -> DOMO | E96: =ESTADISTICA!E95 -> Fibra Optica | F96: =ESTADISTICA!F95 -> 0 | G96: =ESTADISTICA!G95 -> 0 | H96: =ESTADISTICA!H95 -> 0 | ... AG96: =ESTADISTICA!AG95 -> 0
A97: =ESTADISTICA!A96 -> CHACABUCO | B97: =ESTADISTICA!B96 -> CHA04 | C97: =ESTADISTICA!C96 -> ESTADOS UNIDOS DE A. E ILLIA | D97: =ESTADISTICA!D96 -> DOMO | E97: =ESTADISTICA!E96 -> Fibra Optica | F97: =ESTADISTICA!F96 -> APAGADO | G97: =ESTADISTICA!G96 -> APAGADO | H97: =ESTADISTICA!H96 -> APAGADO | ... AG97: =ESTADISTICA!AG96 -> 0
A98: =ESTADISTICA!A97 -> VILLA MONICA NUEVA | B98: =ESTADISTICA!B97 -> COL01 | C98: =ESTADISTICA!C97 -> Eva Peron y Cariboni | D98: =ESTADISTICA!D97 -> Domo | E98: =ESTADISTICA!E97 -> Radio | F98: =ESTADISTICA!F97 -> 0 | G98: =ESTADISTICA!G97 -> 0 | H98: =ESTADISTICA!H97 -> 0 | ... AG98: =ESTADISTICA!AG97 -> 0
A99: =ESTADISTICA!A98 -> LA COLORADA ESTE | B99: =ESTADISTICA!B98 -> COL02 | C99: =ESTADISTICA!C98 -> Av. Eva Peron y Pompeya | D99: =ESTADISTICA!D98 -> Domo | E99: =ESTADISTICA!E98 -> Radio | F99: =ESTADISTICA!F98 -> 0 | G99: =ESTADISTICA!G98 -> 0 | H99: =ESTADISTICA!H98 -> 0 | ... AG99: =ESTADISTICA!AG98 -> 0
A100: =ESTADISTICA!A99 -> LA COLORADA ESTE | B100: =ESTADISTICA!B99 -> COL03 | C100: =ESTADISTICA!C99 -> CARIBONI Y LA ANCIANIDAD | D100: =ESTADISTICA!D99 -> DOMO | E100: =ESTADISTICA!E99 -> Radio | F100: =ESTADISTICA!F99 -> 0 | G100: =ESTADISTICA!G99 -> 0 | H100: =ESTADISTICA!H99 -> 0 | ... AG100: =ESTADISTICA!AG99 -> 0
A101: =ESTADISTICA!A100 -> 0 | B101: =ESTADISTICA!B100 -> DJO01 | C101: =ESTADISTICA!C100 -> Monteverde y Donato Alvarez | D101: =ESTADISTICA!D100 -> Domo | E101: =ESTADISTICA!E100 -> Radio | F101: =ESTADISTICA!F100 -> 0 | G101: =ESTADISTICA!G100 -> 0 | H101: =ESTADISTICA!H100 -> 0 | ... AG101: =ESTADISTICA!AG100 -> 0
A102: =ESTADISTICA!A101 -> DON JOSE | B102: =ESTADISTICA!B101 -> DJO02 (fija 1) | C102: =ESTADISTICA!C101 -> DONATO ALVAREZ Y EL APERO | D102: =ESTADISTICA!D101 -> Fija | E102: =ESTADISTICA!E101 -> PTP A FO | F102: =ESTADISTICA!F101 -> APAGADO | G102: =ESTADISTICA!G101 -> 0 | H102: =ESTADISTICA!H101 -> 0 | ... AI102: =ESTADISTICA!AI101 -> 0
...

Sheet APAGADOS FIBRA
C1: TOTAL FIBRA | D1: =COUNTIFS(E4:E369,"=Fibra Optica") -> 238
E2: APAGADOS | F2: =COUNTIFS(F4:F367, "=APAGADO",E4:E367,"=Fibra Optica") -> 56 | G2: =COUNTIFS(G4:G367, "=APAGADO",E4:E367,"=Fibra Optica") -> 74 | H2: =COUNTIFS(H4:H367, "=APAGADO",E4:E367,"=Fibra Optica") -> 72 | I2: =COUNTIFS(I4:I367, "=APAGADO",E4:E367,"=Fibra Optica") -> 55 | J2: =COUNTIFS(J4:J367, "=APAGADO",E4:E367,"=Fibra Optica") -> 54 | K2: =COUNTIFS(K4:K367, "=APAGADO",E4:E367,"=Fibra Optica") -> 49 | L2: =COUNTIFS(L4:L367, "=APAGADO",E4:E367,"=Fibra Optica") -> 47 | M2: =COUNTIFS(M4:M367, "=APAGADO",E4:E367,"=Fibra Optica") -> 35 | N2: =COUNTIFS(N4:N367, "=APAGADO",E4:E367,"=Fibra Optica") -> 27 | O2: =COUNTIFS(O4:O367, "=APAGADO",E4:E367,"=Fibra Optica") -> 38 | P2: =COUNTIFS(P4:P367, "=APAGADO",E4:E367,"=Fibra Optica") -> 37 | Q2: =COUNTIFS(Q4:Q367, "=APAGADO",E4:E367,"=Fibra Optica") -> 38 | R2: =COUNTIFS(R4:R367, "=APAGADO",E4:E367,"=Fibra Optica") -> 41 | S2: =COUNTIFS(S4:S367, "=APAGADO",E4:E367,"=Fibra Optica") -> 29 | T2: =COUNTIFS(T4:T367, "=APAGADO",E4:E367,"=Fibra Optica") -> 30 | U2: =COUNTIFS(U4:U367, "=APAGADO",E4:E367,"=Fibra Optica") -> 46 | V2: =COUNTIFS(V4:V367, "=APAGADO",E4:E367,"=Fibra Optica") -> 0 | W2: =COUNTIFS(W4:W367, "=APAGADO",E4:E367,"=Fibra Optica") -> 31 | X2: =COUNTIFS(X4:X367, "=APAGADO",E4:E367,"=Fibra Optica") -> 0 | Y2: =COUNTIFS(Y4:Y367, "=APAGADO",E4:E367,"=Fibra Optica") -> 0 | Z2: =COUNTIFS(Z4:Z367, "=APAGADO",E4:E367,"=Fibra Optica") -> 0 | AA2: =COUNTIFS(AA4:AA367, "=APAGADO",E4:E367,"=Fibra Optica") -> 0 | AB2: =COUNTIFS(AB4:AB367, "=APAGADO",E4:E367,"=Fibra Optica") -> 0 | AC2: =COUNTIFS(AC4:AC367, "=APAGADO",E4:E367,"=Fibra Optica") -> 0 | AD2: =COUNTIFS(AD4:AD367, "=APAGADO",E4:E367,"=Fibra Optica") -> 0 | AE2: =COUNTIFS(AE4:AE367, "=APAGADO",E4:E367,"=Fibra Optica") -> 0 | AF2: =COUNTIFS(AF4:AF367, "=APAGADO",E4:E367,"=Fibra Optica") -> 0 | AG2: =COUNTIFS(AG4:AG367, "=APAGADO",E4:E367,"=Fibra Optica") -> 0 | AH2: =COUNTIFS(AH4:AH367, "=APAGADO",E4:E367,"=Fibra Optica") -> 0 | AI2: =COUNTIFS(AI4:AI367, "=APAGADO",E4:E367,"=Fibra Optica") -> 0
A3: =ESTADISTICA!A1 -> Barrio | B3: =ESTADISTICA!B1 -> [Denominacion] | C3: =ESTADISTICA!C1 -> [Ubicacion] | D3: =ESTADISTICA!D1 -> [Tipo de Camara] | E3: =ESTADISTICA!E1 -> [Tipo de Conexion] | F3: =ESTADISTICA!F1 -> 44713 | G3: =ESTADISTICA!G1 -> 44714 | H3: =ESTADISTICA!H1 -> 44715 | ... AI3: =ESTADISTICA!AI1 -> 44742
A4: =ESTADISTICA!A2 -> PRESIDENTE PERON (PEPSI) | B4: =ESTADISTICA!B2 -> MAR 01 | C4: =ESTADISTICA!C2 -> RP36 Y LA ESMERALDA | D4: =ESTADISTICA!D2 -> DOMO | E4: =ESTADISTICA!E2 -> Fibra Optica | F4: =ESTADISTICA!F2 -> APAGADO | G4: =ESTADISTICA!G2 -> APAGADO | H4: =ESTADISTICA!H2 -> APAGADO | ... AI4: =ESTADISTICA!AI2 -> 0
A5: =ESTADISTICA!A3 -> MAYOL | B5: =ESTADISTICA!B3 -> MAY 01 | C5: =ESTADISTICA!C3 -> Eva Peron y Cabildo | D5: =ESTADISTICA!D3 -> Domo | E5: =ESTADISTICA!E3 -> Radio | F5: =ESTADISTICA!F3 -> 0 | G5: =ESTADISTICA!G3 -> 0 | H5: =ESTADISTICA!H3 -> 0 | ... AG5: =ESTADISTICA!AG3 -> 0
A6: =ESTADISTICA!A4 -> 0 | B6: =ESTADISTICA!B4 -> MAY 02 | C6: =ESTADISTICA!C4 -> EVA PERON Y MONTEVIDEO | D6: =ESTADISTICA!D4 -> Domo | E6: =ESTADISTICA!E4 -> Radio | F6: =ESTADISTICA!F4 -> APAGADO | G6: =ESTADISTICA!G4 -> APAGADO | H6: =ESTADISTICA!H4 -> APAGADO | ... AG6: =ESTADISTICA!AG4 -> 0
A7: =ESTADISTICA!A5 -> MAYOL | B7: =ESTADISTICA!B5 -> MAY 03 | C7: =ESTADISTICA!C5 -> CHAÑAR Y SAN NICOLAS | D7: =ESTADISTICA!D5 -> DOMO | E7: =ESTADISTICA!E5 -> PTP A FO | F7: =ESTADISTICA!F5 -> 0 | G7: =ESTADISTICA!G5 -> 0 | H7: =ESTADISTICA!H5 -> 0 | ... AG7: =ESTADISTICA!AG5 -> 0
A8: =ESTADISTICA!A6 -> 0 | B8: =ESTADISTICA!B6 -> MAY 04 | C8: =ESTADISTICA!C6 -> MAR CHIQUITA Y RIO JACHAL | D8: =ESTADISTICA!D6 -> DOMO | E8: =ESTADISTICA!E6 -> Radio | F8: =ESTADISTICA!F6 -> 0 | G8: =ESTADISTICA!G6 -> 0 | H8: =ESTADISTICA!H6 -> 0 | ... AG8: =ESTADISTICA!AG6 -> 0
A9: =ESTADISTICA!A7 -> ALTAMIRA | B9: =ESTADISTICA!B7 -> ALT06 | C9: =ESTADISTICA!C7 -> LOPE DE VEGA Y NECOCHEA | D9: =ESTADISTICA!D7 -> Domo | E9: =ESTADISTICA!E7 -> PTP A FO | F9: =ESTADISTICA!F7 -> 0 | G9: =ESTADISTICA!G7 -> 0 | H9: =ESTADISTICA!H7 -> 0 | ... AG9: =ESTADISTICA!AG7 -> 0
A10: =ESTADISTICA!A8 -> ALTAMIRA | B10: =ESTADISTICA!B8 -> ALT01 | C10: =ESTADISTICA!C8 -> Calchaqui y Sgto. Cabral | D10: =ESTADISTICA!D8 -> Domo | E10: =ESTADISTICA!E8 -> Fibra Optica | F10: =ESTADISTICA!F8 -> APAGADO | G10: =ESTADISTICA!G8 -> APAGADO | H10: =ESTADISTICA!H8 -> 0 | ... AI10: =ESTADISTICA!AI8 -> 0
A11: =ESTADISTICA!A9 -> ALTAMIRA | B11: =ESTADISTICA!B9 -> ALT02 | C11: =ESTADISTICA!C9 -> Calchaqui y Lope de Vega | D11: =ESTADISTICA!D9 -> Domo | E11: =ESTADISTICA!E9 -> PTP A FO | F11: =ESTADISTICA!F9 -> 0 | G11: =ESTADISTICA!G9 -> 0 | H11: =ESTADISTICA!H9 -> 0 | ... AG11: =ESTADISTICA!AG9 -> 0
A12: =ESTADISTICA!A10 -> ALTAMIRA | B12: =ESTADISTICA!B10 -> ALT03 | C12: =ESTADISTICA!C10 -> Bombero Galarza y Necochea | D12: =ESTADISTICA!D10 -> Domo | E12: =ESTADISTICA!E10 -> Fibra Optica | F12: =ESTADISTICA!F10 -> 0 | G12: =ESTADISTICA!G10 -> 0 | H12: =ESTADISTICA!H10 -> 0 | ... AI12: =ESTADISTICA!AI10 -> 0
A13: =ESTADISTICA!A11 -> 0 | B13: =ESTADISTICA!B11 -> ALT04 | C13: =ESTADISTICA!C11 -> Francia y Necochea | D13: =ESTADISTICA!D11 -> Domo | E13: =ESTADISTICA!E11 -> Fibra Optica | F13: =ESTADISTICA!F11 -> APAGADO | G13: =ESTADISTICA!G11 -> APAGADO | H13: =ESTADISTICA!H11 -> APAGADO | ... AI13: =ESTADISTICA!AI11 -> 0
A14: =ESTADISTICA!A12 -> ALTAMIRA | B14: =ESTADISTICA!B12 -> ALT05 | C14: =ESTADISTICA!C12 -> Av. Calchaqui y Bombero Galarza | D14: =ESTADISTICA!D12 -> Domo | E14: =ESTADISTICA!E12 -> PTP A FO | F14: =ESTADISTICA!F12 -> 0 | G14: =ESTADISTICA!G12 -> 0 | H14: =ESTADISTICA!H12 -> 0 | ... AG14: =ESTADISTICA!AG12 -> 0
A15: =ESTADISTICA!A13 -> ALTAMIRA | B15: =ESTADISTICA!B13 -> ALT07 | C15: =ESTADISTICA!C13 -> AV. CALCHAQUI Y AV. DEL TRABAJO | D15: =ESTADISTICA!D13 -> DOMO | E15: =ESTADISTICA!E13 -> PTP A FO | F15: =ESTADISTICA!F13 -> 0 | G15: =ESTADISTICA!G13 -> 0 | H15: =ESTADISTICA!H13 -> 0 | ... AG15: =ESTADISTICA!AG13 -> 0
A16: =ESTADISTICA!A14 -> ALTAMIRA | B16: =ESTADISTICA!B14 -> ALT08 | C16: =ESTADISTICA!C14 -> HUMAITA Y NECOCHEA | D16: =ESTADISTICA!D14 -> DOMO | E16: =ESTADISTICA!E14 -> Fibra Optica | F16: =ESTADISTICA!F14 -> 0 | G16: =ESTADISTICA!G14 -> 0 | H16: =ESTADISTICA!H14 -> 0 | ... AI16: =ESTADISTICA!AI14 -> 0
A17: =ESTADISTICA!A15 -> ALTAMIRA | B17: =ESTADISTICA!B15 -> ALT09 | C17: =ESTADISTICA!C15 -> NECOCHEA Y CURUPAITY | D17: =ESTADISTICA!D15 -> DOMO | E17: =ESTADISTICA!E15 -> Fibra Optica | F17: =ESTADISTICA!F15 -> 0 | G17: =ESTADISTICA!G15 -> 0 | H17: =ESTADISTICA!H15 -> 0 | ... AI17: =ESTADISTICA!AI15 -> 0
A18: =ESTADISTICA!A16 -> AGUSTIN RAMIREZ | B18: =ESTADISTICA!B16 -> ARA01 | C18: =ESTADISTICA!C16 -> Malambo y Tranquera | D18: =ESTADISTICA!D16 -> Domo | E18: =ESTADISTICA!E16 -> Fibra Optica | F18: =ESTADISTICA!F16 -> 0 | G18: =ESTADISTICA!G16 -> 0 | H18: =ESTADISTICA!H16 -> 0 | ... AI18: =ESTADISTICA!AI16 -> 0
A19: =ESTADISTICA!A17 -> ALTAMIRA | B19: =ESTADISTICA!B17 -> ALT10 | C19: =ESTADISTICA!C17 -> REP. FRANCIA Y CALCHAQUI (RP 36) | D19: =ESTADISTICA!D17 -> DOMO | E19: =ESTADISTICA!E17 -> PTP A FO | F19: =ESTADISTICA!F17 -> 0 | G19: =ESTADISTICA!G17 -> 0 | H19: =ESTADISTICA!H17 -> 0 | ... AG19: =ESTADISTICA!AG17 -> 0
A20: =ESTADISTICA!A18 -> BELGRANO | B20: =ESTADISTICA!B18 -> BEL01 | C20: =ESTADISTICA!C18 -> San Martin y Dardo Rocha | D20: =ESTADISTICA!D18 -> DOMO | E20: =ESTADISTICA!E18 -> Fibra Optica | F20: =ESTADISTICA!F18 -> 0 | G20: =ESTADISTICA!G18 -> 0 | H20: =ESTADISTICA!H18 -> 0 | ... AI20: =ESTADISTICA!AI18 -> 0
A21: =ESTADISTICA!A19 -> 0 | B21: =ESTADISTICA!B19 -> CEN51 | C21: =ESTADISTICA!C19 -> ILLIA Y LAS HERAS | D21: =ESTADISTICA!D19 -> FIJA | E21: =ESTADISTICA!E19 -> Fibra Optica | F21: =ESTADISTICA!F19 -> APAGADO | G21: =ESTADISTICA!G19 -> APAGADO | H21: =ESTADISTICA!H19 -> APAGADO | ... AI21: =ESTADISTICA!AI19 -> 0
A22: =ESTADISTICA!A20 -> 0 | B22: =ESTADISTICA!B20 -> CEN53 | C22: =ESTADISTICA!C20 -> GUTIERREZ Y BROWN | D22: =ESTADISTICA!D20 -> Domo | E22: =ESTADISTICA!E20 -> Radio | F22: =ESTADISTICA!F20 -> 0 | G22: =ESTADISTICA!G20 -> 0 | H22: =ESTADISTICA!H20 -> 0 | ... AG22: =ESTADISTICA!AG20 -> 0
A23: =ESTADISTICA!A21 -> 0 | B23: =ESTADISTICA!B21 -> CEN 54 | C23: =ESTADISTICA!C21 -> GUTIERREZ Y PRINGLES | D23: =ESTADISTICA!D21 -> Domo | E23: =ESTADISTICA!E21 -> Radio | F23: =ESTADISTICA!F21 -> 0 | G23: =ESTADISTICA!G21 -> 0 | H23: =ESTADISTICA!H21 -> 0 | ... AG23: =ESTADISTICA!AG21 -> 0
A24: =ESTADISTICA!A22 -> 0 | B24: =ESTADISTICA!B22 -> CEN 55 | C24: =ESTADISTICA!C22 -> BOUREL Y URQUIZA | D24: =ESTADISTICA!D22 -> Domo | E24: =ESTADISTICA!E22 -> Radio | F24: =ESTADISTICA!F22 -> 0 | G24: =ESTADISTICA!G22 -> 0 | H24: =ESTADISTICA!H22 -> 0 | ... AG24: =ESTADISTICA!AG22 -> 0
A25: =ESTADISTICA!A23 -> CENTRO | B25: =ESTADISTICA!B23 -> CEN 56 | C25: =ESTADISTICA!C23 -> Newbery y Falucho | D25: =ESTADISTICA!D23 -> DOMO | E25: =ESTADISTICA!E23 -> Radio | F25: =ESTADISTICA!F23 -> 0 | G25: =ESTADISTICA!G23 -> 0 | H25: =ESTADISTICA!H23 -> 0 | ... AG25: =ESTADISTICA!AG23 -> 0
A26: =ESTADISTICA!A24 -> 0 | B26: =ESTADISTICA!B24 -> CEN 57 | C26: =ESTADISTICA!C24 -> 25 DE MAYO Y DORREGO | D26: =ESTADISTICA!D24 -> DOMO | E26: =ESTADISTICA!E24 -> Radio | F26: =ESTADISTICA!F24 -> 0 | G26: =ESTADISTICA!G24 -> 0 | H26: =ESTADISTICA!H24 -> 0 | ... AG26: =ESTADISTICA!AG24 -> 0
A27: =ESTADISTICA!A25 -> 0 | B27: =ESTADISTICA!B25 -> CEN 58 | C27: =ESTADISTICA!C25 -> EEUU Y MORENO | D27: =ESTADISTICA!D25 -> DOMO | E27: =ESTADISTICA!E25 -> Fibra Optica | F27: =ESTADISTICA!F25 -> 0 | G27: =ESTADISTICA!G25 -> 0 | H27: =ESTADISTICA!H25 -> 0 | ... AI27: =ESTADISTICA!AI25 -> 0
A28: =ESTADISTICA!A26 -> 0 | B28: =ESTADISTICA!B26 -> CEN 59 | C28: =ESTADISTICA!C26 -> CHACABUCO Y BOUREL | D28: =ESTADISTICA!D26 -> DOMO | E28: =ESTADISTICA!E26 -> Radio | F28: =ESTADISTICA!F26 -> 0 | G28: =ESTADISTICA!G26 -> 0 | H28: =ESTADISTICA!H26 -> 0 | ... AG28: =ESTADISTICA!AG26 -> 0
A29: =ESTADISTICA!A27 -> CENTRO | B29: =ESTADISTICA!B27 -> CEN 60 | C29: =ESTADISTICA!C27 -> RECONQUISTA Y ILLIA | D29: =ESTADISTICA!D27 -> DOMO | E29: =ESTADISTICA!E27 -> PTP A FO | F29: =ESTADISTICA!F27 -> APAGADO | G29: =ESTADISTICA!G27 -> APAGADO | H29: =ESTADISTICA!H27 -> APAGADO | ... AG29: =ESTADISTICA!AG27 -> 0
A30: =ESTADISTICA!A28 -> CENTRO | B30: =ESTADISTICA!B28 -> CEN 61 | C30: =ESTADISTICA!C28 -> BOUREL Y MAIPU | D30: =ESTADISTICA!D28 -> DOMO | E30: =ESTADISTICA!E28 -> Radio | F30: =ESTADISTICA!F28 -> 0 | G30: =ESTADISTICA!G28 -> 0 | H30: =ESTADISTICA!H28 -> 0 | ... AG30: =ESTADISTICA!AG28 -> 0
A31: =ESTADISTICA!A29 -> CENTRO | B31: =ESTADISTICA!B29 -> CEN 62 | C31: =ESTADISTICA!C29 -> ESPAÑA Y ALEM | D31: =ESTADISTICA!D29 -> DOMO | E31: =ESTADISTICA!E29 -> PTP A FO | F31: =ESTADISTICA!F29 -> 0 | G31: =ESTADISTICA!G29 -> 0 | H31: =ESTADISTICA!H29 -> 0 | ... AG31: =ESTADISTICA!AG29 -> 0
A32: =ESTADISTICA!A30 -> CENTRO | B32: =ESTADISTICA!B30 -> CEN 63 | C32: =ESTADISTICA!C30 -> SAN MARTIN Y URQUIZA | D32: =ESTADISTICA!D30 -> DOMO | E32: =ESTADISTICA!E30 -> Fibra Optica | F32: =ESTADISTICA!F30 -> 0 | G32: =ESTADISTICA!G30 -> 0 | H32: =ESTADISTICA!H30 -> 0 | ... AI32: =ESTADISTICA!AI30 -> 0
A33: =ESTADISTICA!A31 -> CENTRO | B33: =ESTADISTICA!B31 -> CEN 70 | C33: =ESTADISTICA!C31 -> RIVADAVIA Y 25 MAYO | D33: =ESTADISTICA!D31 -> Domo | E33: =ESTADISTICA!E31 -> Fibra Optica | F33: =ESTADISTICA!F31 -> 0 | G33: =ESTADISTICA!G31 -> 0 | H33: =ESTADISTICA!H31 -> 0 | ... AI33: =ESTADISTICA!AI31 -> 0
A34: =ESTADISTICA!A32 -> CENTRO | B34: =ESTADISTICA!B32 -> CEN 71 | C34: =ESTADISTICA!C32 -> MORENO Y BOUREL | D34: =ESTADISTICA!D32 -> Domo | E34: =ESTADISTICA!E32 -> Fibra Optica | F34: =ESTADISTICA!F32 -> 0 | G34: =ESTADISTICA!G32 -> 0 | H34: =ESTADISTICA!H32 -> 0 | ... AI34: =ESTADISTICA!AI32 -> 0
A35: =ESTADISTICA!A33 -> CENTRO | B35: =ESTADISTICA!B33 -> CEN 72 | C35: =ESTADISTICA!C33 -> MORENO Y 25 DE MAYO | D35: =ESTADISTICA!D33 -> Domo | E35: =ESTADISTICA!E33 -> Fibra Optica | F35: =ESTADISTICA!F33 -> 0 | G35: =ESTADISTICA!G33 -> 0 | H35: =ESTADISTICA!H33 -> 0 | ... AI35: =ESTADISTICA!AI33 -> 0
A36: =ESTADISTICA!A34 -> CENTRO | B36: =ESTADISTICA!B34 -> CEN01 | C36: =ESTADISTICA!C34 -> San Martin y 9 de Julio | D36: =ESTADISTICA!D34 -> Fija | E36: =ESTADISTICA!E34 -> Fibra Optica | F36: =ESTADISTICA!F34 -> 0 | G36: =ESTADISTICA!G34 -> 0 | H36: =ESTADISTICA!H34 -> 0 | ... AI36: =ESTADISTICA!AI34 -> 0
A37: =ESTADISTICA!A35 -> CENTRO | B37: =ESTADISTICA!B35 -> CEN02 | C37: =ESTADISTICA!C35 -> San Martin y Almafuerte | D37: =ESTADISTICA!D35 -> Fija | E37: =ESTADISTICA!E35 -> Fibra Optica | F37: =ESTADISTICA!F35 -> 0 | G37: =ESTADISTICA!G35 -> 0 | H37: =ESTADISTICA!H35 -> 0 | ... AI37: =ESTADISTICA!AI35 -> 0
A38: =ESTADISTICA!A36 -> CENTRO | B38: =ESTADISTICA!B36 -> CEN03 | C38: =ESTADISTICA!C36 -> San Martin y Sallares | D38: =ESTADISTICA!D36 -> Domo | E38: =ESTADISTICA!E36 -> Fibra Optica | F38: =ESTADISTICA!F36 -> 0 | G38: =ESTADISTICA!G36 -> 0 | H38: =ESTADISTICA!H36 -> 0 | ... AI38: =ESTADISTICA!AI36 -> 0
A39: =ESTADISTICA!A37 -> CENTRO | B39: =ESTADISTICA!B37 -> CEN04 | C39: =ESTADISTICA!C37 -> San Martin y Contreras | D39: =ESTADISTICA!D37 -> Domo | E39: =ESTADISTICA!E37 -> Fibra Optica | F39: =ESTADISTICA!F37 -> 0 | G39: =ESTADISTICA!G37 -> 0 | H39: =ESTADISTICA!H37 -> 0 | ... AI39: =ESTADISTICA!AI37 -> 0
A40: =ESTADISTICA!A38 -> CENTRO | B40: =ESTADISTICA!B38 -> CEN05 | C40: =ESTADISTICA!C38 -> Bocuzzi e/España y San Martin | D40: =ESTADISTICA!D38 -> DOMO | E40: =ESTADISTICA!E38 -> Fibra Optica | F40: =ESTADISTICA!F38 -> 0 | G40: =ESTADISTICA!G38 -> 0 | H40: =ESTADISTICA!H38 -> 0 | ... AI40: =ESTADISTICA!AI38 -> 0
...

Sheet APAGADOS ANTENA
C1: TOTAL PTP A FO | D1: =COUNTIFS(E4:E367,"=PTP A FO") -> 38
E2: APAGADOS | F2: =COUNTIFS(F4:F367, "=APAGADO",E4:E367,"=PTP A FO") -> 8 | G2: =COUNTIFS(G4:G367, "=APAGADO",E4:E367,"=PTP A FO") -> 6 | H2: =COUNTIFS(H4:H367, "=APAGADO",E4:E367,"=PTP A FO") -> 6 | I2: =COUNTIFS(I4:I367, "=APAGADO",E4:E367,"=PTP A FO") -> 6 | J2: =COUNTIFS(J4:J367, "=APAGADO",E4:E367,"=PTP A FO") -> 5 | K2: =COUNTIFS(K4:K367, "=APAGADO",E4:E367,"=PTP A FO") -> 5 | L2: =COUNTIFS(L4:L367, "=APAGADO",E4:E367,"=PTP A FO") -> 6 | M2: =COUNTIFS(M4:M367, "=APAGADO",E4:E367,"=PTP A FO") -> 2 | N2: =COUNTIFS(N4:N367, "=APAGADO",E4:E367,"=PTP A FO") -> 2 | O2: =COUNTIFS(O4:O367,"APAGADO", E4:E367,"=PTP A FO" ) -> 6 | P2: =COUNTIFS(P4:P367, "=APAGADO",E4:E367,"=PTP A FO") -> 6 | Q2: =COUNTIFS(Q4:Q367, "=APAGADO",E4:E367,"=PTP A FO") -> 6 | R2: =COUNTIFS(R4:R367, "=APAGADO",E4:E367,"=PTP A FO") -> 6 | S2: =COUNTIFS(S4:S367, "=APAGADO",E4:E367,"=PTP A FO") -> 2 | T2: =COUNTIFS(T4:T367, "=APAGADO",E4:E367,"=PTP A FO") -> 2 | U2: =COUNTIFS(U4:U367, "=APAGADO",E4:E367,"=PTP A FO") -> 8 | V2: =COUNTIFS(V4:V367, "=APAGADO",E4:E367,"=PTP A FO") -> 0 | W2: =COUNTIFS(W4:W367, "=APAGADO",E4:E367,"=PTP A FO") -> 2 | X2: =COUNTIFS(X4:X367, "=APAGADO",E4:E367,"=PTP A FO") -> 0 | Y2: =COUNTIFS(Y4:Y367, "=APAGADO",E4:E367,"=PTP A FO") -> 0 | Z2: =COUNTIFS(Z4:Z367, "=APAGADO",E4:E367,"=PTP A FO") -> 0 | AA2: =COUNTIFS(AA4:AA367, "=APAGADO",E4:E367,"=PTP A FO") -> 0 | AB2: =COUNTIFS(AB4:AB367, "=APAGADO",E4:E367,"=PTP A FO") -> 0 | AC2: =COUNTIFS(AC4:AC367, "=APAGADO",E4:E367,"=PTP A FO") -> 0 | AD2: =COUNTIFS(AD4:AD367, "=APAGADO",E4:E367,"=PTP A FO") -> 0 | AE2: =COUNTIFS(AE4:AE367, "=APAGADO",E4:E367,"=PTP A FO") -> 0 | AF2: =COUNTIFS(AF4:AF367, "=APAGADO",E4:E367,"=PTP A FO") -> 0 | AG2: =COUNTIFS(AG4:AG367, "=APAGADO",E4:E367,"=PTP A FO") -> 0 | AH2: =COUNTIFS(AH4:AH367, "=APAGADO",E4:E367,"=PTP A FO") -> 0 | AI2: =COUNTIFS(AI4:AI367, "=APAGADO",E4:E367,"=PTP A FO") -> 0
A3: =ESTADISTICA!A1 -> Barrio | B3: =ESTADISTICA!B1 -> [Denominacion] | C3: =ESTADISTICA!C1 -> [Ubicacion] | D3: =ESTADISTICA!D1 -> [Tipo de Camara] | E3: =ESTADISTICA!E1 -> [Tipo de Conexion] | F3: =ESTADISTICA!F1 -> 44713 | G3: =ESTADISTICA!G1 -> 44714 | H3: =ESTADISTICA!H1 -> 44715 | ... AI3: =ESTADISTICA!AI1 -> 44742
A4: =ESTADISTICA!A2 -> PRESIDENTE PERON (PEPSI) | B4: =ESTADISTICA!B2 -> MAR 01 | C4: =ESTADISTICA!C2 -> RP36 Y LA ESMERALDA | D4: =ESTADISTICA!D2 -> DOMO | E4: =ESTADISTICA!E2 -> Fibra Optica | F4: =ESTADISTICA!F2 -> APAGADO | G4: =ESTADISTICA!G2 -> APAGADO | H4: =ESTADISTICA!H2 -> APAGADO | ... AI4: =ESTADISTICA!AI2 -> 0
A5: =ESTADISTICA!A3 -> MAYOL | B5: =ESTADISTICA!B3 -> MAY 01 | C5: =ESTADISTICA!C3 -> Eva Peron y Cabildo | D5: =ESTADISTICA!D3 -> Domo | E5: =ESTADISTICA!E3 -> Radio | F5: =ESTADISTICA!F3 -> 0 | G5: =ESTADISTICA!G3 -> 0 | H5: =ESTADISTICA!H3 -> 0 | ... AI5: =ESTADISTICA!AI3 -> 0
A6: =ESTADISTICA!A4 -> 0 | B6: =ESTADISTICA!B4 -> MAY 02 | C6: =ESTADISTICA!C4 -> EVA PERON Y MONTEVIDEO | D6: =ESTADISTICA!D4 -> Domo | E6: =ESTADISTICA!E4 -> Radio | F6: =ESTADISTICA!F4 -> APAGADO | G6: =ESTADISTICA!G4 -> APAGADO | H6: =ESTADISTICA!H4 -> APAGADO | ... AI6: =ESTADISTICA!AI4 -> 0
A7: =ESTADISTICA!A5 -> MAYOL | B7: =ESTADISTICA!B5 -> MAY 03 | C7: =ESTADISTICA!C5 -> CHAÑAR Y SAN NICOLAS | D7: =ESTADISTICA!D5 -> DOMO | E7: =ESTADISTICA!E5 -> PTP A FO | F7: =ESTADISTICA!F5 -> 0 | G7: =ESTADISTICA!G5 -> 0 | H7: =ESTADISTICA!H5 -> 0 | ... AI7: =ESTADISTICA!AI5 -> 0
A8: =ESTADISTICA!A6 -> 0 | B8: =ESTADISTICA!B6 -> MAY 04 | C8: =ESTADISTICA!C6 -> MAR CHIQUITA Y RIO JACHAL | D8: =ESTADISTICA!D6 -> DOMO | E8: =ESTADISTICA!E6 -> Radio | F8: =ESTADISTICA!F6 -> 0 | G8: =ESTADISTICA!G6 -> 0 | H8: =ESTADISTICA!H6 -> 0 | ... AI8: =ESTADISTICA!AI6 -> 0
A9: =ESTADISTICA!A7 -> ALTAMIRA | B9: =ESTADISTICA!B7 -> ALT06 | C9: =ESTADISTICA!C7 -> LOPE DE VEGA Y NECOCHEA | D9: =ESTADISTICA!D7 -> Domo | E9: =ESTADISTICA!E7 -> PTP A FO | F9: =ESTADISTICA!F7 -> 0 | G9: =ESTADISTICA!G7 -> 0 | H9: =ESTADISTICA!H7 -> 0 | ... AI9: =ESTADISTICA!AI7 -> 0
A10: =ESTADISTICA!A8 -> ALTAMIRA | B10: =ESTADISTICA!B8 -> ALT01 | C10: =ESTADISTICA!C8 -> Calchaqui y Sgto. Cabral | D10: =ESTADISTICA!D8 -> Domo | E10: =ESTADISTICA!E8 -> Fibra Optica | F10: =ESTADISTICA!F8 -> APAGADO | G10: =ESTADISTICA!G8 -> APAGADO | H10: =ESTADISTICA!H8 -> 0 | ... AI10: =ESTADISTICA!AI8 -> 0
A11: =ESTADISTICA!A9 -> ALTAMIRA | B11: =ESTADISTICA!B9 -> ALT02 | C11: =ESTADISTICA!C9 -> Calchaqui y Lope de Vega | D11: =ESTADISTICA!D9 -> Domo | E11: =ESTADISTICA!E9 -> PTP A FO | F11: =ESTADISTICA!F9 -> 0 | G11: =ESTADISTICA!G9 -> 0 | H11: =ESTADISTICA!H9 -> 0 | ... AI11: =ESTADISTICA!AI9 -> 0
A12: =ESTADISTICA!A10 -> ALTAMIRA | B12: =ESTADISTICA!B10 -> ALT03 | C12: =ESTADISTICA!C10 -> Bombero Galarza y Necochea | D12: =ESTADISTICA!D10 -> Domo | E12: =ESTADISTICA!E10 -> Fibra Optica | F12: =ESTADISTICA!F10 -> 0 | G12: =ESTADISTICA!G10 -> 0 | H12: =ESTADISTICA!H10 -> 0 | ... AI12: =ESTADISTICA!AI10 -> 0
A13: =ESTADISTICA!A11 -> 0 | B13: =ESTADISTICA!B11 -> ALT04 | C13: =ESTADISTICA!C11 -> Francia y Necochea | D13: =ESTADISTICA!D11 -> Domo | E13: =ESTADISTICA!E11 -> Fibra Optica | F13: =ESTADISTICA!F11 -> APAGADO | G13: =ESTADISTICA!G11 -> APAGADO | H13: =ESTADISTICA!H11 -> APAGADO | ... AI13: =ESTADISTICA!AI11 -> 0
A14: =ESTADISTICA!A12 -> ALTAMIRA | B14: =ESTADISTICA!B12 -> ALT05 | C14: =ESTADISTICA!C12 -> Av. Calchaqui y Bombero Galarza | D14: =ESTADISTICA!D12 -> Domo | E14: =ESTADISTICA!E12 -> PTP A FO | F14: =ESTADISTICA!F12 -> 0 | G14: =ESTADISTICA!G12 -> 0 | H14: =ESTADISTICA!H12 -> 0 | ... AI14: =ESTADISTICA!AI12 -> 0
... A278: =ESTADISTICA!A276 -> SANTA ROSA | B278: =ESTADISTICA!B276 -> SRO11 | C278: =ESTADISTICA!C276 -> MILAN Y MALLORCA | D278: =ESTADISTICA!D276 -> DOMO | E278: =ESTADISTICA!E276 -> Radio | F278: =ESTADISTICA!F276 -> 0 | G278: =ESTADISTICA!G276 -> 0 | H278: =ESTADISTICA!H276 -> 0 | ... AI278: =ESTADISTICA!AI276 -> 0
B279: =ESTADISTICA!B277 -> SRO12 | C279: =ESTADISTICA!C277 -> YUGOSLAVIA Y PAYSANDU | D279: =ESTADISTICA!D277 -> DOMO | E279: =ESTADISTICA!E277 -> Radio | F279: =ESTADISTICA!F277 -> 0 | G279: =ESTADISTICA!G277 -> 0 | H279: =ESTADISTICA!H277 -> 0 | I279: =ESTADISTICA!I277 -> 0 | ... AI279: =ESTADISTICA!AI277 -> 0
A280: =ESTADISTICA!A278 -> ZONA RURAL SANTA ROSA | B280: =ESTADISTICA!B278 -> SRO13 (fija 1) | C280: =ESTADISTICA!C278 -> BRUSELAS E/ GRECIA Y CHECOSLOVAQUIA | D280: =ESTADISTICA!D278 -> Fija | E280: =ESTADISTICA!E278 -> RADIO | F280: =ESTADISTICA!F278 -> 0 | G280: =ESTADISTICA!G278 -> 0 | H280: =ESTADISTICA!H278 -> 0 | ... AI280: =ESTADISTICA!AI278 -> 0
A281: =ESTADISTICA!A279 -> ZONA RURAL SANTA ROSA | B281: =ESTADISTICA!B279 -> SRO14 (fija 2) | C281: =ESTADISTICA!C279 -> BRUSELAS E/ GRECIA Y CHECOSLOVAQUIA | D281: =ESTADISTICA!D279 -> Fija | E281: =ESTADISTICA!E279 -> RADIO | F281: =ESTADISTICA!F279 -> 0 | G281: =ESTADISTICA!G279 -> APAGADO | H281: =ESTADISTICA!H279 -> 0 | ... AI281: =ESTADISTICA!AI279 -> 0
A282: =ESTADISTICA!A280 -> SANTA ROSA | B282: =ESTADISTICA!B280 -> SRO15 | C282: =ESTADISTICA!C280 -> NOVAK Y TIRANA (614) | D282: =ESTADISTICA!D280 -> DOMO | E282: =ESTADISTICA!E280 -> Fibra Optica | F282: =ESTADISTICA!F280 -> 0 | G282: =ESTADISTICA!G280 -> 0 | H282: =ESTADISTICA!H280 -> 0 | ... AI282: =ESTADISTICA!AI280 -> 0
A283: =ESTADISTICA!A281 -> SANTA ROSA | B283: =ESTADISTICA!B281 -> SRO18 (fija 1) | C283: =ESTADISTICA!C281 -> GRAN CANARIA Y BUDAPEST | D283: =ESTADISTICA!D281 -> Fija | E283: =ESTADISTICA!E281 -> Fibra Optica | F283: =ESTADISTICA!F281 -> 0 | G283: =ESTADISTICA!G281 -> 0 | H283: =ESTADISTICA!H281 -> 0 | ... AI283: =ESTADISTICA!AI281 -> 0
A284: =ESTADISTICA!A282 -> SANTA ROSA | B284: =ESTADISTICA!B282 -> SRO19 (fija 2) | C284: =ESTADISTICA!C282 -> GRAN CANARIA Y BUDAPEST | D284: =ESTADISTICA!D282 -> Fija | E284: =ESTADISTICA!E282 -> Fibra Optica | F284: =ESTADISTICA!F282 -> 0 | G284: =ESTADISTICA!G282 -> 0 | H284: =ESTADISTICA!H282 -> 0 | ... AI284: =ESTADISTICA!AI282 -> 0
A285: =ESTADISTICA!A283 -> SAN RUDECINDO | B285: =ESTADISTICA!B283 -> SRU01 (fija 1) | C285: =ESTADISTICA!C283 -> HERNANDARIAS Y AMBATO | D285: =ESTADISTICA!D283 -> Fija | E285: =ESTADISTICA!E283 -> Fibra Optica | F285: =ESTADISTICA!F283 -> 0 | G285: =ESTADISTICA!G283 -> APAGADO | H285: =ESTADISTICA!H283 -> APAGADO | ... AI285: =ESTADISTICA!AI283 -> 0
A286: =ESTADISTICA!A284 -> SAN RUDECINDO | B286: =ESTADISTICA!B284 -> SRU02 (fija 2) | C286: =ESTADISTICA!C284 -> HERNANDARIAS Y AMBATO | D286: =ESTADISTICA!D284 -> Fija | E286: =ESTADISTICA!E284 -> Fibra Optica | F286: =ESTADISTICA!F284 -> 0 | G286: =ESTADISTICA!G284 -> APAGADO | H286: =ESTADISTICA!H284 -> APAGADO | ... AI286: =ESTADISTICA!AI284 -> 0
A287: =ESTADISTICA!A285 -> VILLA ANGELICA | B287: =ESTADISTICA!B285 -> VANG01 | C287: =ESTADISTICA!C285 -> Senzabello y Necochea | D287: =ESTADISTICA!D285 -> Domo | E287: =ESTADISTICA!E285 -> PTP A FO | F287: =ESTADISTICA!F285 -> 0 | G287: =ESTADISTICA!G285 -> 0 | H287: =ESTADISTICA!H285 -> 0 | ... AI287: =ESTADISTICA!AI285 -> 0
A288: =ESTADISTICA!A286 -> VILLA ANGELICA | B288: =ESTADISTICA!B286 -> VANG02 | C288: =ESTADISTICA!C286 -> Thevenet y Ruta 36 | D288: =ESTADISTICA!D286 -> Domo | E288: =ESTADISTICA!E286 -> Fibra Optica | F288: =ESTADISTICA!F286 -> 0 | G288: =ESTADISTICA!G286 -> 0 | H288: =ESTADISTICA!H286 -> 0 | ... AI288: =ESTADISTICA!AI286 -> 0
A289: =ESTADISTICA!A287 -> VILLA DEL PLATA | B289: =ESTADISTICA!B287 -> VANG03 | C289: =ESTADISTICA!C287 -> Thevenet 1950 | D289: =ESTADISTICA!D287 -> Domo | E289: =ESTADISTICA!E287 -> Fibra Optica | F289: =ESTADISTICA!F287 -> 0 | G289: =ESTADISTICA!G287 -> 0 | H289: =ESTADISTICA!H287 -> 0 | ... AI289: =ESTADISTICA!AI287 -> 0
A290: =ESTADISTICA!A288 -> VILLA ANGELICA | B290: =ESTADISTICA!B288 -> VANG04 | C290: =ESTADISTICA!C288 -> Storni e/Thevenet y Calle 158 | D290: =ESTADISTICA!D288 -> DOMO | E290: =ESTADISTICA!E288 -> Fibra Optica | F290: =ESTADISTICA!F288 -> 0 | G290: =ESTADISTICA!G288 -> 0 | H290: =ESTADISTICA!H288 -> 0 | ... AI290: =ESTADISTICA!AI288 -> 0
A291: =ESTADISTICA!A289 -> VILLA ANGELICA | B291: =ESTADISTICA!B289 -> VANG05 | C291: =ESTADISTICA!C289 -> Storni y Thevenet | D291: =ESTADISTICA!D289 -> Domo | E291: =ESTADISTICA!E289 -> Fibra Optica | F291: =ESTADISTICA!F289 -> 0 | G291: =ESTADISTICA!G289 -> 0 | H291: =ESTADISTICA!H289 -> 0 | ... AI291: =ESTADISTICA!AI289 -> 0
... A369: =ESTADISTICA!A367 -> 0 | B369: =ESTADISTICA!B367 -> ZEB04 | C369: =ESTADISTICA!C367 -> THEVENET Y DIAGONAL GRANADEROS | D369: =ESTADISTICA!D367 -> DOMO | E369: =ESTADISTICA!E367 -> Radio | F369: =ESTADISTICA!F367 -> 0 | G369: =ESTADISTICA!G367 -> 0 | H369: =ESTADISTICA!H367 -> 0 | ... AI369: =ESTADISTICA!AI367 -> 0

Sheet APAGADOS RADIO
C1: TOTAL RADIO | D1: =COUNTIFS(E4:E367,"=radio") -> 88
E2: APAGADOS | F2: =COUNTIFS(F4:F367, "=APAGADO",E4:E367,"=radio") -> 7 | G2: =COUNTIFS(G4:G367, "=APAGADO",E4:E367,"=radio") -> 8 | H2: =COUNTIFS(H4:H367, "=APAGADO",E4:E367,"=radio") -> 5 | I2: =COUNTIFS(I4:I367, "=APAGADO",E4:E367,"=radio") -> 7 | J2: =COUNTIFS(J4:J367, "=APAGADO",E4:E367,"=radio") -> 6 | K2: =COUNTIFS(K4:K367, "=APAGADO",E4:E367,"=radio") -> 9 | L2: =COUNTIFS(L4:L367, "=APAGADO",E4:E367,"=radio") -> 9 | M2: =COUNTIFS(M4:M367, "=APAGADO",E4:E367,"=radio") -> 7 | N2: =COUNTIFS(N4:N367, "=APAGADO",E4:E367,"=radio") -> 6 | O2: =COUNTIFS(O4:O367, "=APAGADO",E4:E367,"=radio") -> 7 | P2: =COUNTIFS(P4:P367, "=APAGADO",E4:E367,"=radio") -> 10 | Q2: =COUNTIFS(Q4:Q367, "=APAGADO",E4:E367,"=radio") -> 8 | R2: =COUNTIFS(R4:R367, "=APAGADO",E4:E367,"=radio") -> 8 | S2: =COUNTIFS(S4:S367, "=APAGADO",E4:E367,"=radio") -> 8 | T2: =COUNTIFS(T4:T367, "=APAGADO",E4:E367,"=radio") -> 8 | U2: =COUNTIFS(U4:U367, "=APAGADO",E4:E367,"=radio") -> 5 | V2: =COUNTIFS(V4:V367, "=APAGADO",E4:E367,"=radio") -> 0 | W2: =COUNTIFS(W4:W367, "=APAGADO",E4:E367,"=radio") -> 4 | X2: =COUNTIFS(X4:X367, "=APAGADO",E4:E367,"=radio") -> 0 | Y2: =COUNTIFS(Y4:Y367, "=APAGADO",E4:E367,"=radio") -> 0 | Z2: =COUNTIFS(Z4:Z367, "=APAGADO",E4:E367,"=radio") -> 0 | AA2: =COUNTIFS(AA4:AA367, "=APAGADO",E4:E367,"=radio") -> 0 | AB2: =COUNTIFS(AB4:AB367, "=APAGADO",E4:E367,"=radio") -> 0 | AC2: =COUNTIFS(AC4:AC367, "=APAGADO",E4:E367,"=radio") -> 0 | AD2: =COUNTIFS(AD4:AD367, "=APAGADO",E4:E367,"=radio") -> 0 | AE2: =COUNTIFS(AE4:AE367, "=APAGADO",E4:E367,"=radio") -> 0 | AF2: =COUNTIFS(AF4:AF367, "=APAGADO",E4:E367,"=radio") -> 0 | AG2: =COUNTIFS(AG4:AG367, "=APAGADO",E4:E367,"=radio") -> 0 | AH2: =COUNTIFS(AH4:AH367, "=APAGADO",E4:E367,"=radio") -> 0 | AI2: =COUNTIFS(AI4:AI367, "=APAGADO",E4:E367,"=radio") -> 0
A3: =ESTADISTICA!A1 -> Barrio | B3: =ESTADISTICA!B1 -> [Denominacion] | C3: =ESTADISTICA!C1 -> [Ubicacion] | D3: =ESTADISTICA!D1 -> [Tipo de Camara] | E3: =ESTADISTICA!E1 -> [Tipo de Conexion] | F3: =ESTADISTICA!F1 -> 44713 | G3: =ESTADISTICA!G1 -> 44714 | H3: =ESTADISTICA!H1 -> 44715 | ... AI3: =ESTADISTICA!AI1 -> 44742
A4: =ESTADISTICA!A2 -> PRESIDENTE PERON (PEPSI) | B4: =ESTADISTICA!B2 -> MAR 01 | C4: =ESTADISTICA!C2 -> RP36 Y LA ESMERALDA | D4: =ESTADISTICA!D2 -> DOMO | E4: =ESTADISTICA!E2 -> Fibra Optica | F4: =ESTADISTICA!F2 -> APAGADO | G4: =ESTADISTICA!G2 -> APAGADO | H4: =ESTADISTICA!H2 -> APAGADO | ... AI4: =ESTADISTICA!AI2 -> 0
