Workbook
Name _25_de_agosto: 'RESUMEN TOTAL'!$A$4:$D$365
Name _25_de_agosto_3: 'RESUMEN TOTAL'!$A$4:$D$377
Name BONOMOcam: Hoja1!$B$2
Name CANTIDAD_DE_CAMARAS: 'RESUMEN TOTAL'!$B$1
Name COSEIDIcam: Hoja1!$B$4

Sheet RESUMEN TOTAL
A1: CANTIDAD DE CAMARAS | B1: =COUNTA(B5:B533) -> 435 | D1: PORCIENTO DE CAIDAS | K1: =(K3)/(K2+K3) -> 0.31034483 | L1: =(L3)/(L2+L3) -> 0.25977011 | M1: =(M3)/(M2+M3) -> 0.22298851 | N1: =(N3)/(N2+N3) -> 0.2183908 | O1: =(O3)/(O2+O3) -> 0.22528736 | P1: =(P3)/(P2+P3) -> 0.1862069 | Q1: =(Q3)/(Q2+Q3) -> 0.18850575 | R1: =(R3)/(R2+R3) -> 0.18850575 | ... AN1: =(AN3)/(AN2+AN3) -> 0
D2: FUNCIONAN | K2: =B1-K3 -> 300 | L2: =CANTIDAD_DE_CAMARAS-L3 -> 322 | M2: =CANTIDAD_DE_CAMARAS-M3 -> 338 | N2: =CANTIDAD_DE_CAMARAS-N3 -> 340 | O2: =CANTIDAD_DE_CAMARAS-O3 -> 337 | P2: =CANTIDAD_DE_CAMARAS-P3 -> 354 | Q2: =CANTIDAD_DE_CAMARAS-Q3 -> 353 | R2: =CANTIDAD_DE_CAMARAS-R3 -> 353 | S2: =CANTIDAD_DE_CAMARAS-S3 -> 343 | ... AN2: =CANTIDAD_DE_CAMARAS-AN3 -> 435
D3: CAIDAS | K3: =COUNTIF(K4:K453, "apagado") -> 135 | L3: =COUNTIF(L4:L453, "apagado") -> 113 | M3: =COUNTIF(M4:M453, "apagado") -> 97 | N3: =COUNTIF(N4:N453, "apagado") -> 95 | O3: =COUNTIF(O4:O453, "apagado") -> 98 | P3: =COUNTIF(P4:P453, "apagado") -> 81 | Q3: =COUNTIF(Q4:Q453, "apagado") -> 82 | R3: =COUNTIF(R4:R453, "apagado") -> 82 | ... AN3: =COUNTIF(AN4:AN453, "apagado") -> 0
A4: Barrio | B4: [Denominacion] | C4: [Empresa Mantenimiento] | D4: [Ubicacion] | E4: [Tipo de Camara] | F4: [Tipo de Conexion] | H4: DIAS FUNCIONANDO | I4: DIAS CAIDA | J4: EFECTIVIDAD | K4: 44896 | L4: 44897 | M4: 44898 | N4: 44899 | O4: 44900 | P4: 44901 | Q4: 44902 | R4: 44903 | S4: 44904 | T4: 44905 | U4: 44906 | V4: 44907 | W4: 44908 | X4: 44909 | Y4: 44910 | Z4: 44911 | AA4: 44912 | AB4: 44913 | AC4: 44914 | AD4: 44915 | AE4: 44916 | AF4: 44917 | AG4: 44918 | AH4: 44919 | AI4: 44920 | AJ4: 44921 | AK4: 44922 | AL4: 44923 | AM4: 44924 | AN4: 44925 | AO4: 44926
A5: ALTAMIRA | B5: ALT01 | C5: BONOMO | D5: Calchaqui y Sgto. Cabral | E5: Domo | F5: Fibra Optica | G5: 172.20.10.6 | H5: =COUNTIF(K5:AO5,"") -> 16 | I5: =COUNTIF(K5:AL5,"APAGADO") -> 15 | J5: =(H5)/(I5+H5) -> 0.51612903 | K5: APAGADO | L5: APAGADO | M5: APAGADO | N5: APAGADO | O5: APAGADO | P5: APAGADO | Q5: APAGADO | R5: APAGADO | S5: APAGADO | T5: APAGADO | U5: APAGADO | V5: APAGADO | W5: APAGADO | X5: APAGADO | Y5: APAGADO
A6: ALTAMIRA | B6: ALT02 | C6: BONOMO | D6: Calchaqui y Lope de Vega | E6: Domo | F6: PTO A FO | G6: 172.20.12.218 | H6: =COUNTIF(K6:AO6,"") -> 16 | I6: =COUNTIF(K6:AL6,"APAGADO") -> 15 | J6: =(H6)/(I6+H6) -> 0.51612903 | K6: APAGADO | L6: APAGADO | M6: APAGADO | N6: APAGADO | O6: APAGADO | P6: APAGADO | Q6: APAGADO | R6: APAGADO | S6: APAGADO | T6: APAGADO | U6: APAGADO | V6: APAGADO | W6: APAGADO | X6: APAGADO | Y6: APAGADO
A7: ALTAMIRA | B7: ALT 03 | C7: BONOMO | D7: Bombero Galarza y Necochea | E7: Domo | F7: FIBRA OPTICA | G7: 172.20.12.54 | H7: =COUNTIF(K7:AO7,"") -> 16 | I7: =COUNTIF(K7:AL7,"APAGADO") -> 15 | J7: =(H7)/(I7+H7) -> 0.51612903 | K7: APAGADO | L7: APAGADO | M7: APAGADO | N7: APAGADO | O7: APAGADO | P7: APAGADO | Q7: APAGADO | R7: APAGADO | S7: APAGADO | T7: APAGADO | U7: APAGADO | V7: APAGADO | W7: APAGADO | X7: APAGADO | Y7: APAGADO
A8: ALTAMIRA | B8: ALT 04 | C8: BONOMO | D8: Francia y Necochea | E8: Domo | F8: FIBRA OPTICA | G8: 172.20.12.55 | H8: =COUNTIF(K8:AO8,"") -> 16 | I8: =COUNTIF(K8:AL8,"APAGADO") -> 15 | J8: =(H8)/(I8+H8) -> 0.51612903 | K8: APAGADO | L8: APAGADO | M8: APAGADO | N8: APAGADO | O8: APAGADO | P8: APAGADO | Q8: APAGADO | R8: APAGADO | S8: APAGADO | T8: APAGADO | U8: APAGADO | V8: APAGADO | W8: APAGADO | X8: APAGADO | Y8: APAGADO
A9: ALTAMIRA | B9: ALT05 | C9: BONOMO | D9: Av. Calchaqui y Bombero Galarza | E9: Domo | F9: PTO A FO | G9: 172.20.12.216 | H9: =COUNTIF(K9:AO9,"") -> 16 | I9: =COUNTIF(K9:AL9,"APAGADO") -> 15 | J9: =(H9)/(I9+H9) -> 0.51612903 | K9: APAGADO | L9: APAGADO | M9: APAGADO | N9: APAGADO | O9: APAGADO | P9: APAGADO | Q9: APAGADO | R9: APAGADO | S9: APAGADO | T9: APAGADO | U9: APAGADO | V9: APAGADO | W9: APAGADO | X9: APAGADO | Y9: APAGADO
A10: ALTAMIRA | B10: ALT 06 | C10: BONOMO | D10: LOPE DE VEGA Y NECOCHEA | E10: Domo | F10: PTO A FO | G10: 172.20.12.12 | H10: =COUNTIF(K10:AO10,"") -> 16 | I10: =COUNTIF(K10:AL10,"APAGADO") -> 15 | J10: =(H10)/(I10+H10) -> 0.51612903 | K10: APAGADO | L10: APAGADO | M10: APAGADO | N10: APAGADO | O10: APAGADO | P10: APAGADO | Q10: APAGADO | R10: APAGADO | S10: APAGADO | T10: APAGADO | U10: APAGADO | V10: APAGADO | W10: APAGADO | X10: APAGADO | Y10: APAGADO
A11: ALTAMIRA | B11: ALT07 | C11: BONOMO | D11: AV. CALCHAQUI Y AV. DEL TRABAJO | E11: DOMO | F11: PTO A FO | G11: 172.20.10.57 | H11: =COUNTIF(K11:AO11,"") -> 16 | I11: =COUNTIF(K11:AL11,"APAGADO") -> 15 | J11: =(H11)/(I11+H11) -> 0.51612903 | K11: APAGADO | L11: APAGADO | M11: APAGADO | N11: APAGADO | O11: APAGADO | P11: APAGADO | Q11: APAGADO | R11: APAGADO | S11: APAGADO | T11: APAGADO | U11: APAGADO | V11: APAGADO | W11: APAGADO | X11: APAGADO | Y11: APAGADO
A12: ALTAMIRA | B12: ALT 08 | C12: BONOMO | D12: HUMAITA Y NECOCHEA | E12: DOMO | F12: Fibra Optica | G12: 172.20.11.215 | H12: =COUNTIF(K12:AO12,"") -> 16 | I12: =COUNTIF(K12:AL12,"APAGADO") -> 15 | J12: =(H12)/(I12+H12) -> 0.51612903 | K12: APAGADO | L12: APAGADO | M12: APAGADO | N12: APAGADO | O12: APAGADO | P12: APAGADO | Q12: APAGADO | R12: APAGADO | S12: APAGADO | T12: APAGADO | U12: APAGADO | V12: APAGADO | W12: APAGADO | X12: APAGADO | Y12: APAGADO
A13: ALTAMIRA | B13: ALT 09 | C13: BONOMO | D13: NECOCHEA Y CURUPAITY | E13: DOMO | F13: Fibra Optica | G13: 172.20.11.216 | H13: =COUNTIF(K13:AO13,"") -> 16 | I13: =COUNTIF(K13:AL13,"APAGADO") -> 15 | J13: =(H13)/(I13+H13) -> 0.51612903 | K13: APAGADO | L13: APAGADO | M13: APAGADO | N13: APAGADO | O13: APAGADO | P13: APAGADO | Q13: APAGADO | R13: APAGADO | S13: APAGADO | T13: APAGADO | U13: APAGADO | V13: APAGADO | W13: APAGADO | X13: APAGADO | Y13: APAGADO
A14: ALTAMIRA | B14: ALT 10 | C14: BONOMO | D14: Calchaqui y Francia | E14: Domo | F14: Radio | H14: =COUNTIF(K14:AO14,"") -> 16 | I14: =COUNTIF(K14:AL14,"APAGADO") -> 15 | J14: =(H14)/(I14+H14) -> 0.51612903 | K14: APAGADO | L14: APAGADO | M14: APAGADO | N14: APAGADO | O14: APAGADO | P14: APAGADO | Q14: APAGADO | R14: APAGADO | S14: APAGADO | T14: APAGADO | U14: APAGADO | V14: APAGADO | W14: APAGADO | X14: APAGADO | Y14: APAGADO
A15: AGUSTIN RAMIREZ | B15: ARA 01 | C15: COSEIDI | D15: Malambo y Tranquera | E15: Domo | F15: FIBRA OPTICA | G15: 172.20.12.110 | H15: =COUNTIF(K15:AO15,"") -> 31 | I15: =COUNTIF(K15:AL15,"APAGADO") -> 0 | J15: =(H15)/(I15+H15) -> 1
A16: BELGRANO | B16: BEL 01 | C16: BONOMO | D16: San Martin y Dardo Rocha | E16: DOMO | F16: FIBRA OPTICA | G16: 172.20.12.64 | H16: =COUNTIF(K16:AO16,"") -> 12 | I16: =COUNTIF(K16:AL16,"APAGADO") -> 18 | J16: =(H16)/(I16+H16) -> 0.4 | K16: APAGADO | L16: APAGADO | M16: APAGADO | O16: APAGADO | P16: APAGADO | Q16: APAGADO | R16: APAGADO | S16: APAGADO | T16: APAGADO | U16: APAGADO | V16: X | W16: APAGADO | X16: APAGADO | Y16: APAGADO | Z16: APAGADO | AA16: APAGADO | AB16: APAGADO | AC16: APAGADO | AD16: APAGADO
A17: BOSQUES CENTRO | B17: BOSQC 01 | C17: COSEIDI | D17: LUIS AGOTE E/DANUNCIO Y CAMPOAMOR | E17: Fija | F17: Radio | G17: 172.20.11.15 | H17: =COUNTIF(K17:AO17,"") -> 23 | I17: =COUNTIF(K17:AL17,"APAGADO") -> 8 | J17: =(H17)/(I17+H17) -> 0.74193548 | K17: APAGADO | L17: APAGADO | M17: APAGADO | N17: APAGADO | O17: APAGADO | Y17: APAGADO | Z17: APAGADO | AA17: APAGADO
A18: BOSQUES CENTRO | B18: BOSQC 02 | C18: COSEIDI | D18: LUIS AGOTE E/DANUNCIO Y CAMPOAMOR | E18: Fija | F18: Radio | G18: 172.20.11.16 | H18: =COUNTIF(K18:AO18,"") -> 23 | I18: =COUNTIF(K18:AL18,"APAGADO") -> 8 | J18: =(H18)/(I18+H18) -> 0.74193548 | K18: APAGADO | L18: APAGADO | M18: APAGADO | N18: APAGADO | O18: APAGADO | Y18: APAGADO | Z18: APAGADO | AA18: APAGADO
A19: BOSQUES CENTRO | B19: BOSQC 03 | C19: COSEIDI | D19: BENAVENTE Y LUIS AGOTE | E19: Fija | F19: Radio | G19: 172.20.11.13 | H19: =COUNTIF(K19:AO19,"") -> 23 | I19: =COUNTIF(K19:AL19,"APAGADO") -> 8 | J19: =(H19)/(I19+H19) -> 0.74193548 | K19: APAGADO | L19: APAGADO | M19: APAGADO | N19: APAGADO | O19: APAGADO | Y19: APAGADO | Z19: APAGADO | AA19: APAGADO
A20: BOSQUES CENTRO | B20: BOSQC 04 | C20: COSEIDI | D20: BENAVENTE Y LUIS AGOTE | E20: Fija | F20: Radio | G20: 172.20.11.113 | H20: =COUNTIF(K20:AO20,"") -> 23 | I20: =COUNTIF(K20:AL20,"APAGADO") -> 8 | J20: =(H20)/(I20+H20) -> 0.74193548 | K20: APAGADO | L20: APAGADO | M20: APAGADO | N20: APAGADO | O20: APAGADO | Y20: APAGADO | Z20: APAGADO | AA20: APAGADO
A21: BOSQUES CENTRO | B21: BOSQC 05 | C21: COSEIDI | D21: LUIS AGOTE Y RUTA 36 | E21: Fija | F21: Radio | G21: 172.20.11.17 | H21: =COUNTIF(K21:AO21,"") -> 25 | I21: =COUNTIF(K21:AL21,"APAGADO") -> 6 | J21: =(H21)/(I21+H21) -> 0.80645161 | K21: APAGADO | L21: APAGADO | M21: APAGADO | N21: APAGADO | O21: APAGADO | AA21: APAGADO
A22: BOSQUES CENTRO | B22: BOSQC 06 | C22: COSEIDI | D22: LUIS AGOTE Y RUTA 36 | E22: Fija | F22: Radio | G22: 172.20.11.18 | H22: =COUNTIF(K22:AO22,"") -> 25 | I22: =COUNTIF(K22:AL22,"APAGADO") -> 6 | J22: =(H22)/(I22+H22) -> 0.80645161 | K22: APAGADO | L22: APAGADO | M22: APAGADO | N22: APAGADO | O22: APAGADO | AA22: APAGADO
A23: CENTRO | B23: CEN01 | C23: BONOMO | D23: San Martin y 9 de Julio | E23: Fija | F23: Fibra Optica | G23: 172.20.11.10 | H23: =COUNTIF(K23:AO23,"") -> 30 | I23: =COUNTIF(K23:AL23,"APAGADO") -> 1 | J23: =(H23)/(I23+H23) -> 0.96774194 | AA23: APAGADO
A24: CENTRO | B24: CEN02 | C24: BONOMO | D24: San Martin y Almafuerte | E24: Fija | F24: Fibra Optica | G24: 172.20.11.11 | H24: =COUNTIF(K24:AO24,"") -> 29 | I24: =COUNTIF(K24:AL24,"APAGADO") -> 2 | J24: =(H24)/(I24+H24) -> 0.93548387 | Y24: APAGADO | Z24: APAGADO
A25: CENTRO | B25: CEN03 | C25: BONOMO | D25: San Martin y Sallares | E25: Domo | F25: Fibra Optica | G25: 172.20.12.30 | H25: =COUNTIF(K25:AO25,"") -> 31 | I25: =COUNTIF(K25:AL25,"APAGADO") -> 0 | J25: =(H25)/(I25+H25) -> 1
A26: CENTRO | B26: CEN04 | C26: BONOMO | D26: San Martin y Contreras | E26: Domo | F26: Fibra Optica | G26: 172.20.12.29 | H26: =COUNTIF(K26:AO26,"") -> 31 | I26: =COUNTIF(K26:AL26,"APAGADO") -> 0 | J26: =(H26)/(I26+H26) -> 1
A27: CENTRO | B27: CEN 05 | C27: BONOMO | D27: Bocuzzi e/España y San Martin | E27: DOMO | F27: Fibra Optica | G27: 172.20.10.200 | H27: =COUNTIF(K27:AO27,"") -> 29 | I27: =COUNTIF(K27:AL27,"APAGADO") -> 2 | J27: =(H27)/(I27+H27) -> 0.93548387 | K27: APAGADO | L27: APAGADO
A28: CENTRO | B28: CEN06 | C28: BONOMO | D28: Monteagudo y A.del Valle | E28: Fija | F28: Fibra Optica | G28: 172.20.10.02 | H28: =COUNTIF(K28:AO28,"") -> 31 | I28: =COUNTIF(K28:AL28,"APAGADO") -> 0 | J28: =(H28)/(I28+H28) -> 1
A29: CENTRO | B29: CEN07 | C29: BONOMO | D29: San Martin y Guemes | E29: DOMO | F29: Fibra Optica | G29: 172.20.11.20 | H29: =COUNTIF(K29:AO29,"") -> 31 | I29: =COUNTIF(K29:AL29,"APAGADO") -> 0 | J29: =(H29)/(I29+H29) -> 1
A30: CENTRO | B30: CEN08 | C30: BONOMO | D30: San Martin y Pte.Peron | E30: Domo | F30: Fibra Optica | G30: 172.20.11.21 | H30: =COUNTIF(K30:AO30,"") -> 31 | I30: =COUNTIF(K30:AL30,"APAGADO") -> 0 | J30: =(H30)/(I30+H30) -> 1
A31: CENTRO | B31: CEN09 | C31: BONOMO | D31: Chacabuco y 25 de Mayo | E31: Domo | F31: Fibra Optica | G31: 172.20.11.22 | H31: =COUNTIF(K31:AO31,"") -> 31 | I31: =COUNTIF(K31:AL31,"APAGADO") -> 0 | J31: =(H31)/(I31+H31) -> 1
A32: CENTRO | B32: CEN10 | C32: BONOMO | D32: Monteagudo y Pte. Peron | E32: Domo | F32: Fibra Optica | G32: 172.20.11.23 | H32: =COUNTIF(K32:AO32,"") -> 31 | I32: =COUNTIF(K32:AL32,"APAGADO") -> 0 | J32: =(H32)/(I32+H32) -> 1
A33: CENTRO | B33: CEN11 | C33: BONOMO | D33: Monteagudo y Bocuzzi | E33: Domo | F33: Fibra Optica | G33: 172.20.10.24 | H33: =COUNTIF(K33:AO33,"") -> 31 | I33: =COUNTIF(K33:AL33,"APAGADO") -> 0 | J33: =(H33)/(I33+H33) -> 1
A34: CENTRO | B34: CEN 12 | C34: BONOMO | D34: Monteagudo y Mitre | E34: Domo | F34: Fibra Optica | G34: 172.20.10.23 | H34: =COUNTIF(K34:AO34,"") -> 14 | I34: =COUNTIF(K34:AL34,"APAGADO") -> 17 | J34: =(H34)/(I34+H34) -> 0.4516129 | K34: APAGADO | L34: APAGADO | M34: APAGADO | N34: APAGADO | O34: APAGADO | P34: APAGADO | Q34: APAGADO | R34: APAGADO | S34: APAGADO | T34: APAGADO | U34: APAGADO | V34: APAGADO | W34: APAGADO | X34: APAGADO | Y34: APAGADO | Z34: APAGADO | AA34: APAGADO
A35: CENTRO | B35: CEN 13 | C35: BONOMO | D35: 25 de Mayo y Maipu | E35: DOMO | F35: Fibra Optica | G35: 172.20.10.20 | H35: =COUNTIF(K35:AO35,"") -> 31 | I35: =COUNTIF(K35:AL35,"APAGADO") -> 0 | J35: =(H35)/(I35+H35) -> 1
A36: CENTRO | B36: CEN14 | C36: BONOMO | D36: Pte.Peron e/Pringles y Brown | E36: Domo | F36: Fibra Optica | G36: 172.20.10.21 | H36: =COUNTIF(K36:AO36,"") -> 31 | I36: =COUNTIF(K36:AL36,"APAGADO") -> 0 | J36: =(H36)/(I36+H36) -> 1
A37: CENTRO | B37: CEN15 | C37: BONOMO | D37: Alberdi y A.del Valle | E37: Domo | F37: Fibra Optica | G37: 172.20.10.35 | H37: =COUNTIF(K37:AO37,"") -> 31 | I37: =COUNTIF(K37:AL37,"APAGADO") -> 0 | J37: =(H37)/(I37+H37) -> 1
A38: CENTRO | B38: CEN16 | C38: BONOMO | D38: San Martin y Pte. Peron | E38: Fija | F38: Fibra Optica | G38: 172.20.12.36 | H38: =COUNTIF(K38:AO38,"") -> 31 | I38: =COUNTIF(K38:AL38,"APAGADO") -> 0 | J38: =(H38)/(I38+H38) -> 1
A39: CENTRO | B39: CEN17 | C39: BONOMO | D39: San Martin y Mitre | E39: Domo | F39: PTO A FO | G39: 172.20.12.200 | H39: =COUNTIF(K39:AO39,"") -> 31 | I39: =COUNTIF(K39:AL39,"APAGADO") -> 0 | J39: =(H39)/(I39+H39) -> 1
A40: CENTRO | B40: CEN18 | C40: BONOMO | D40: Monteagudo e/Mitre y Sallares | E40: Fija | F40: Fibra Optica | G40: 172.20.10.26 | H40: =COUNTIF(K40:AO40,"") -> 11 | I40: =COUNTIF(K40:AL40,"APAGADO") -> 20 | J40: =(H40)/(I40+H40) -> 0.35483871 | K40: APAGADO | L40: APAGADO | M40: APAGADO | N40: APAGADO | O40: APAGADO | P40: APAGADO | Q40: APAGADO | R40: APAGADO | S40: APAGADO | T40: APAGADO | U40: APAGADO | V40: APAGADO | W40: APAGADO | X40: APAGADO | Y40: APAGADO | Z40: APAGADO | AA40: APAGADO | AB40: APAGADO | AC40: APAGADO | AD40: APAGADO
...

Sheet Hoja4

Sheet Hoja5

Sheet ESTADISTICA
A1: ='RESUMEN TOTAL'!A4 -> Barrio | B1: ='RESUMEN TOTAL'!B4 -> [Denominacion] | C1: ='RESUMEN TOTAL'!D4 -> [Ubicacion] | D1: ='RESUMEN TOTAL'!E4 -> [Tipo de Camara] | E1: ='RESUMEN TOTAL'!F4 -> [Tipo de Conexion] | F1: ='RESUMEN TOTAL'!K4 -> 44896 | G1: ='RESUMEN TOTAL'!L4 -> 44897 | H1: ='RESUMEN TOTAL'!M4 -> 44898 | I1: ='RESUMEN TOTAL'!N4 -> 44899 | J1: ='RESUMEN TOTAL'!O4 -> 44900 | K1: ='RESUMEN TOTAL'!P4 -> 44901 | L1: ='RESUMEN TOTAL'!Q4 -> 44902 | M1: ='RESUMEN TOTAL'!R4 -> 44903 | ... AI1: ='RESUMEN TOTAL'!AN4 -> 44925
A2: ='RESUMEN TOTAL'!A5 -> ALTAMIRA | B2: ='RESUMEN TOTAL'!B5 -> ALT01 | C2: ='RESUMEN TOTAL'!D5 -> Calchaqui y Sgto. Cabral | D2: ='RESUMEN TOTAL'!E5 -> Domo | E2: ='RESUMEN TOTAL'!F5 -> Fibra Optica | F2: ='RESUMEN TOTAL'!K5 -> APAGADO | G2: ='RESUMEN TOTAL'!L5 -> APAGADO | H2: ='RESUMEN TOTAL'!M5 -> APAGADO | I2: ='RESUMEN TOTAL'!N5 -> APAGADO | J2: ='RESUMEN TOTAL'!O5 -> APAGADO | K2: ='RESUMEN TOTAL'!P5 -> APAGADO | L2: ='RESUMEN TOTAL'!Q5 -> APAGADO | M2: ='RESUMEN TOTAL'!R5 -> APAGADO | ... AI2: ='RESUMEN TOTAL'!AN5 -> 0
A3: ='RESUMEN TOTAL'!A6 -> ALTAMIRA | B3: ='RESUMEN TOTAL'!B6 -> ALT02 | C3: ='RESUMEN TOTAL'!D6 -> Calchaqui y Lope de Vega | D3: ='RESUMEN TOTAL'!E6 -> Domo | E3: ='RESUMEN TOTAL'!F6 -> PTO A FO | F3: ='RESUMEN TOTAL'!K6 -> APAGADO | G3: ='RESUMEN TOTAL'!L6 -> APAGADO | H3: ='RESUMEN TOTAL'!M6 -> APAGADO | I3: ='RESUMEN TOTAL'!N6 -> APAGADO | J3: ='RESUMEN TOTAL'!O6 -> APAGADO | K3: ='RESUMEN TOTAL'!P6 -> APAGADO | L3: ='RESUMEN TOTAL'!Q6 -> APAGADO | M3: ='RESUMEN TOTAL'!R6 -> APAGADO | ... AI3: ='RESUMEN TOTAL'!AN6 -> 0
A4: ='RESUMEN TOTAL'!A7 -> ALTAMIRA | B4: ='RESUMEN TOTAL'!B7 -> ALT 03 | C4: ='RESUMEN TOTAL'!D7 -> Bombero Galarza y Necochea | D4: ='RESUMEN TOTAL'!E7 -> Domo | E4: ='RESUMEN TOTAL'!F7 -> FIBRA OPTICA | F4: ='RESUMEN TOTAL'!K7 -> APAGADO | G4: ='RESUMEN TOTAL'!L7 -> APAGADO | H4: ='RESUMEN TOTAL'!M7 -> APAGADO | I4: ='RESUMEN TOTAL'!N7 -> APAGADO | J4: ='RESUMEN TOTAL'!O7 -> APAGADO | K4: ='RESUMEN TOTAL'!P7 -> APAGADO | L4: ='RESUMEN TOTAL'!Q7 -> APAGADO | M4: ='RESUMEN TOTAL'!R7 -> APAGADO | ... AI4: ='RESUMEN TOTAL'!AN7 -> 0
A5: ='RESUMEN TOTAL'!A8 -> ALTAMIRA | B5: ='RESUMEN TOTAL'!B8 -> ALT 04 | C5: ='RESUMEN TOTAL'!D8 -> Francia y Necochea | D5: ='RESUMEN TOTAL'!E8 -> Domo | E5: ='RESUMEN TOTAL'!F8 -> FIBRA OPTICA | F5: ='RESUMEN TOTAL'!K8 -> APAGADO | G5: ='RESUMEN TOTAL'!L8 -> APAGADO | H5: ='RESUMEN TOTAL'!M8 -> APAGADO | I5: ='RESUMEN TOTAL'!N8 -> APAGADO | J5: ='RESUMEN TOTAL'!O8 -> APAGADO | K5: ='RESUMEN TOTAL'!P8 -> APAGADO | L5: ='RESUMEN TOTAL'!Q8 -> APAGADO | M5: ='RESUMEN TOTAL'!R8 -> APAGADO | ... AI5: ='RESUMEN TOTAL'!AN8 -> 0
A6: ='RESUMEN TOTAL'!A9 -> ALTAMIRA | B6: ='RESUMEN TOTAL'!B9 -> ALT05 | C6: ='RESUMEN TOTAL'!D9 -> Av. Calchaqui y Bombero Galarza | D6: ='RESUMEN TOTAL'!E9 -> Domo | E6: ='RESUMEN TOTAL'!F9 -> PTO A FO | F6: ='RESUMEN TOTAL'!K9 -> APAGADO | G6: ='RESUMEN TOTAL'!L9 -> APAGADO | H6: ='RESUMEN TOTAL'!M9 -> APAGADO | I6: ='RESUMEN TOTAL'!N9 -> APAGADO | J6: ='RESUMEN TOTAL'!O9 -> APAGADO | K6: ='RESUMEN TOTAL'!P9 -> APAGADO | L6: ='RESUMEN TOTAL'!Q9 -> APAGADO | M6: ='RESUMEN TOTAL'!R9 -> APAGADO | ... AI6: ='RESUMEN TOTAL'!AN9 -> 0
A7: ='RESUMEN TOTAL'!A10 -> ALTAMIRA | B7: ='RESUMEN TOTAL'!B10 -> ALT 06 | C7: ='RESUMEN TOTAL'!D10 -> LOPE DE VEGA Y NECOCHEA | D7: ='RESUMEN TOTAL'!E10 -> Domo | E7: ='RESUMEN TOTAL'!F10 -> PTO A FO | F7: ='RESUMEN TOTAL'!K10 -> APAGADO | G7: ='RESUMEN TOTAL'!L10 -> APAGADO | H7: ='RESUMEN TOTAL'!M10 -> APAGADO | I7: ='RESUMEN TOTAL'!N10 -> APAGADO | J7: ='RESUMEN TOTAL'!O10 -> APAGADO | K7: ='RESUMEN TOTAL'!P10 -> APAGADO | L7: ='RESUMEN TOTAL'!Q10 -> APAGADO | M7: ='RESUMEN TOTAL'!R10 -> APAGADO | ... AI7: ='RESUMEN TOTAL'!AN10 -> 0
A8: ='RESUMEN TOTAL'!A11 -> ALTAMIRA | B8: ='RESUMEN TOTAL'!B11 -> ALT07 | C8: ='RESUMEN TOTAL'!D11 -> AV. CALCHAQUI Y AV. DEL TRABAJO | D8: ='RESUMEN TOTAL'!E11 -> DOMO | E8: ='RESUMEN TOTAL'!F11 -> PTO A FO | F8: ='RESUMEN TOTAL'!K11 -> APAGADO | G8: ='RESUMEN TOTAL'!L11 -> APAGADO | H8: ='RESUMEN TOTAL'!M11 -> APAGADO | I8: ='RESUMEN TOTAL'!N11 -> APAGADO | J8: ='RESUMEN TOTAL'!O11 -> APAGADO | K8: ='RESUMEN TOTAL'!P11 -> APAGADO | L8: ='RESUMEN TOTAL'!Q11 -> APAGADO | M8: ='RESUMEN TOTAL'!R11 -> APAGADO | ... AI8: ='RESUMEN TOTAL'!AN11 -> 0
A9: ='RESUMEN TOTAL'!A12 -> ALTAMIRA | B9: ='RESUMEN TOTAL'!B12 -> ALT 08 | C9: ='RESUMEN TOTAL'!D12 -> HUMAITA Y NECOCHEA | D9: ='RESUMEN TOTAL'!E12 -> DOMO | E9: ='RESUMEN TOTAL'!F12 -> Fibra Optica | F9: ='RESUMEN TOTAL'!K12 -> APAGADO | G9: ='RESUMEN TOTAL'!L12 -> APAGADO | H9: ='RESUMEN TOTAL'!M12 -> APAGADO | I9: ='RESUMEN TOTAL'!N12 -> APAGADO | J9: ='RESUMEN TOTAL'!O12 -> APAGADO | K9: ='RESUMEN TOTAL'!P12 -> APAGADO | L9: ='RESUMEN TOTAL'!Q12 -> APAGADO | M9: ='RESUMEN TOTAL'!R12 -> APAGADO | ... AI9: ='RESUMEN TOTAL'!AN12 -> 0
A10: ='RESUMEN TOTAL'!A13 -> ALTAMIRA | B10: ='RESUMEN TOTAL'!B13 -> ALT 09 | C10: ='RESUMEN TOTAL'!D13 -> NECOCHEA Y CURUPAITY | D10: ='RESUMEN TOTAL'!E13 -> DOMO | E10: ='RESUMEN TOTAL'!F13 -> Fibra Optica | F10: ='RESUMEN TOTAL'!K13 -> APAGADO | G10: ='RESUMEN TOTAL'!L13 -> APAGADO | H10: ='RESUMEN TOTAL'!M13 -> APAGADO | I10: ='RESUMEN TOTAL'!N13 -> APAGADO | J10: ='RESUMEN TOTAL'!O13 -> APAGADO | K10: ='RESUMEN TOTAL'!P13 -> APAGADO | L10: ='RESUMEN TOTAL'!Q13 -> APAGADO | M10: ='RESUMEN TOTAL'!R13 -> APAGADO | ... AI10: ='RESUMEN TOTAL'!AN13 -> 0
A11: ='RESUMEN TOTAL'!A14 -> ALTAMIRA | B11: ='RESUMEN TOTAL'!B14 -> ALT 10 | C11: ='RESUMEN TOTAL'!D14 -> Calchaqui y Francia | D11: ='RESUMEN TOTAL'!E14 -> Domo | E11: ='RESUMEN TOTAL'!F14 -> Radio | F11: ='RESUMEN TOTAL'!K14 -> APAGADO | G11: ='RESUMEN TOTAL'!L14 -> APAGADO | H11: ='RESUMEN TOTAL'!M14 -> APAGADO | I11: ='RESUMEN TOTAL'!N14 -> APAGADO | J11: ='RESUMEN TOTAL'!O14 -> APAGADO | K11: ='RESUMEN TOTAL'!P14 -> APAGADO | L11: ='RESUMEN TOTAL'!Q14 -> APAGADO | M11: ='RESUMEN TOTAL'!R14 -> APAGADO | ... AI11: ='RESUMEN TOTAL'!AN14 -> 0
A12: ='RESUMEN TOTAL'!A15 -> AGUSTIN RAMIREZ | B12: ='RESUMEN TOTAL'!B15 -> ARA 01 | C12: ='RESUMEN TOTAL'!D15 -> Malambo y Tranquera | D12: ='RESUMEN TOTAL'!E15 -> Domo | E12: ='RESUMEN TOTAL'!F15 -> FIBRA OPTICA | F12: ='RESUMEN TOTAL'!K15 -> 0 | G12: ='RESUMEN TOTAL'!L15 -> 0 | H12: ='RESUMEN TOTAL'!M15 -> 0 | I12: ='RESUMEN TOTAL'!N15 -> 0 | J12: ='RESUMEN TOTAL'!O15 -> 0 | K12: ='RESUMEN TOTAL'!P15 -> 0 | L12: ='RESUMEN TOTAL'!Q15 -> 0 | M12: ='RESUMEN TOTAL'!R15 -> 0 | ... AI12: ='RESUMEN TOTAL'!AN15 -> 0
... A19: ='RESUMEN TOTAL'!A22 -> BOSQUES CENTRO | B19: ='RESUMEN TOTAL'!B22 -> BOSQC 06 | C19: ='RESUMEN TOTAL'!D22 -> LUIS AGOTE Y RUTA 36 | D19: ='RESUMEN TOTAL'!E22 -> Fija | E19: ='RESUMEN TOTAL'!F22 -> Radio | F19: ='RESUMEN TOTAL'!K22 -> APAGADO | G19: ='RESUMEN TOTAL'!L22 -> APAGADO | H19: ='RESUMEN TOTAL'!M22 -> APAGADO | I19: ='RESUMEN TOTAL'!N22 -> APAGADO | J19: ='RESUMEN TOTAL'!O22 -> APAGADO | K19: ='RESUMEN TOTAL'!P22 -> 0 | L19: ='RESUMEN TOTAL'!Q22 -> 0 | M19: ='RESUMEN TOTAL'!R22 -> 0 | ... AI19: ='RESUMEN TOTAL'!AN22 -> 0
A20: ='RESUMEN TOTAL'!A265 -> RICARDO ROJAS | B20: ='RESUMEN TOTAL'!B265 -> RRJ 12 | C20: ='RESUMEN TOTAL'!D265 -> FADER Y DIAGONAL LOS POETAS | D20: ='RESUMEN TOTAL'!E265 -> Fija | E20: ='RESUMEN TOTAL'!F265 -> Fibra Optica | F20: ='RESUMEN TOTAL'!K265 -> APAGADO | G20: ='RESUMEN TOTAL'!L265 -> APAGADO | H20: ='RESUMEN TOTAL'!M265 -> APAGADO | I20: ='RESUMEN TOTAL'!N265 -> APAGADO | J20: ='RESUMEN TOTAL'!O265 -> APAGADO | K20: ='RESUMEN TOTAL'!P265 -> 0 | L20: ='RESUMEN TOTAL'!Q265 -> 0 | M20: ='RESUMEN TOTAL'!R265 -> 0 | ... AI20: ='RESUMEN TOTAL'!AN265 -> 0
A21: ='RESUMEN TOTAL'!A23 -> CENTRO | B21: ='RESUMEN TOTAL'!B23 -> CEN01 | C21: ='RESUMEN TOTAL'!D23 -> San Martin y 9 de Julio | D21: ='RESUMEN TOTAL'!E23 -> Fija | E21: ='RESUMEN TOTAL'!F23 -> Fibra Optica | F21: ='RESUMEN TOTAL'!K23 -> 0 | G21: ='RESUMEN TOTAL'!L23 -> 0 | H21: ='RESUMEN TOTAL'!M23 -> 0 | I21: ='RESUMEN TOTAL'!N23 -> 0 | J21: ='RESUMEN TOTAL'!O23 -> 0 | K21: ='RESUMEN TOTAL'!P23 -> 0 | L21: ='RESUMEN TOTAL'!Q23 -> 0 | M21: ='RESUMEN TOTAL'!R23 -> 0 | ... AI21: ='RESUMEN TOTAL'!AN23 -> 0
A22: ='RESUMEN TOTAL'!A24 -> CENTRO | B22: ='RESUMEN TOTAL'!B24 -> CEN02 | C22: ='RESUMEN TOTAL'!D24 -> San Martin y Almafuerte | D22: ='RESUMEN TOTAL'!E24 -> Fija | E22: ='RESUMEN TOTAL'!F24 -> Fibra Optica | F22: ='RESUMEN TOTAL'!K24 -> 0 | G22: ='RESUMEN TOTAL'!L24 -> 0 | H22: ='RESUMEN TOTAL'!M24 -> 0 | I22: ='RESUMEN TOTAL'!N24 -> 0 | J22: ='RESUMEN TOTAL'!O24 -> 0 | K22: ='RESUMEN TOTAL'!P24 -> 0 | L22: ='RESUMEN TOTAL'!Q24 -> 0 | M22: ='RESUMEN TOTAL'!R24 -> 0 | ... AI22: ='RESUMEN TOTAL'!AN24 -> 0
A23: ='RESUMEN TOTAL'!A25 -> CENTRO | B23: ='RESUMEN TOTAL'!B25 -> CEN03 | C23: ='RESUMEN TOTAL'!D25 -> San Martin y Sallares | D23: ='RESUMEN TOTAL'!E25 -> Domo | E23: ='RESUMEN TOTAL'!F25 -> Fibra Optica | F23: ='RESUMEN TOTAL'!K25 -> 0 | G23: ='RESUMEN TOTAL'!L25 -> 0 | H23: ='RESUMEN TOTAL'!M25 -> 0 | I23: ='RESUMEN TOTAL'!N25 -> 0 | J23: ='RESUMEN TOTAL'!O25 -> 0 | K23: ='RESUMEN TOTAL'!P25 -> 0 | L23: ='RESUMEN TOTAL'!Q25 -> 0 | M23: ='RESUMEN TOTAL'!R25 -> 0 | ... AI23: ='RESUMEN TOTAL'!AN25 -> 0
A24: ='RESUMEN TOTAL'!A26 -> CENTRO | B24: ='RESUMEN TOTAL'!B26 -> CEN04 | C24: ='RESUMEN TOTAL'!D26 -> San Martin y Contreras | D24: ='RESUMEN TOTAL'!E26 -> Domo | E24: ='RESUMEN TOTAL'!F26 -> Fibra Optica | F24: ='RESUMEN TOTAL'!K26 -> 0 | G24: ='RESUMEN TOTAL'!L26 -> 0 | H24: ='RESUMEN TOTAL'!M26 -> 0 | I24: ='RESUMEN TOTAL'!N26 -> 0 | J24: ='RESUMEN TOTAL'!O26 -> 0 | K24: ='RESUMEN TOTAL'!P26 -> 0 | L24: ='RESUMEN TOTAL'!Q26 -> 0 | M24: ='RESUMEN TOTAL'!R26 -> 0 | ... AI24: ='RESUMEN TOTAL'!AN26 -> 0
A25: ='RESUMEN TOTAL'!A27 -> CENTRO | B25: ='RESUMEN TOTAL'!B27 -> CEN 05 | C25: ='RESUMEN TOTAL'!D27 -> Bocuzzi e/España y San Martin | D25: ='RESUMEN TOTAL'!E27 -> DOMO | E25: ='RESUMEN TOTAL'!F27 -> Fibra Optica | F25: ='RESUMEN TOTAL'!K27 -> APAGADO | G25: ='RESUMEN TOTAL'!L27 -> APAGADO | H25: ='RESUMEN TOTAL'!M27 -> 0 | I25: ='RESUMEN TOTAL'!N27 -> 0 | J25: ='RESUMEN TOTAL'!O27 -> 0 | K25: ='RESUMEN TOTAL'!P27 -> 0 | L25: ='RESUMEN TOTAL'!Q27 -> 0 | M25: ='RESUMEN TOTAL'!R27 -> 0 | ... AI25: ='RESUMEN TOTAL'!AN27 -> 0
A26: ='RESUMEN TOTAL'!A28 -> CENTRO | B26: ='RESUMEN TOTAL'!B28 -> CEN06 | C26: ='RESUMEN TOTAL'!D28 -> Monteagudo y A.del Valle | D26: ='RESUMEN TOTAL'!E28 -> Fija | E26: ='RESUMEN TOTAL'!F28 -> Fibra Optica | F26: ='RESUMEN TOTAL'!K28 -> 0 | G26: ='RESUMEN TOTAL'!L28 -> 0 | H26: ='RESUMEN TOTAL'!M28 -> 0 | I26: ='RESUMEN TOTAL'!N28 -> 0 | J26: ='RESUMEN TOTAL'!O28 -> 0 | K26: ='RESUMEN TOTAL'!P28 -> 0 | L26: ='RESUMEN TOTAL'!Q28 -> 0 | M26: ='RESUMEN TOTAL'!R28 -> 0 | ... AI26: ='RESUMEN TOTAL'!AN28 -> 0
A27: ='RESUMEN TOTAL'!A29 -> CENTRO | B27: ='RESUMEN TOTAL'!B29 -> CEN07 | C27: ='RESUMEN TOTAL'!D29 -> San Martin y Guemes | D27: ='RESUMEN TOTAL'!E29 -> DOMO | E27: ='RESUMEN TOTAL'!F29 -> Fibra Optica | F27: ='RESUMEN TOTAL'!K29 -> 0 | G27: ='RESUMEN TOTAL'!L29 -> 0 | H27: ='RESUMEN TOTAL'!M29 -> 0 | I27: ='RESUMEN TOTAL'!N29 -> 0 | J27: ='RESUMEN TOTAL'!O29 -> 0 | K27: ='RESUMEN TOTAL'!P29 -> 0 | L27: ='RESUMEN TOTAL'!Q29 -> 0 | M27: ='RESUMEN TOTAL'!R29 -> 0 | ... AI27: ='RESUMEN TOTAL'!AN29 -> 0
A28: ='RESUMEN TOTAL'!A30 -> CENTRO | B28: ='RESUMEN TOTAL'!B30 -> CEN08 | C28: ='RESUMEN TOTAL'!D30 -> San Martin y Pte.Peron | D28: ='RESUMEN TOTAL'!E30 -> Domo | E28: ='RESUMEN TOTAL'!F30 -> Fibra Optica | F28: ='RESUMEN TOTAL'!K30 -> 0 | G28: ='RESUMEN TOTAL'!L30 -> 0 | H28: ='RESUMEN TOTAL'!M30 -> 0 | I28: ='RESUMEN TOTAL'!N30 -> 0 | J28: ='RESUMEN TOTAL'!O30 -> 0 | K28: ='RESUMEN TOTAL'!P30 -> 0 | L28: ='RESUMEN TOTAL'!Q30 -> 0 | M28: ='RESUMEN TOTAL'!R30 -> 0 | ... AI28: ='RESUMEN TOTAL'!AN30 -> 0
A29: ='RESUMEN TOTAL'!A31 -> CENTRO | B29: ='RESUMEN TOTAL'!B31 -> CEN09 | C29: ='RESUMEN TOTAL'!D31 -> Chacabuco y 25 de Mayo | D29: ='RESUMEN TOTAL'!E31 -> Domo | E29: ='RESUMEN TOTAL'!F31 -> Fibra Optica | F29: ='RESUMEN TOTAL'!K31 -> 0 | G29: ='RESUMEN TOTAL'!L31 -> 0 | H29: ='RESUMEN TOTAL'!M31 -> 0 | I29: ='RESUMEN TOTAL'!N31 -> 0 | J29: ='RESUMEN TOTAL'!O31 -> 0 | K29: ='RESUMEN TOTAL'!P31 -> 0 | L29: ='RESUMEN TOTAL'!Q31 -> 0 | M29: ='RESUMEN TOTAL'!R31 -> 0 | ... AI29: ='RESUMEN TOTAL'!AN31 -> 0
A30: ='RESUMEN TOTAL'!A32 -> CENTRO | B30: ='RESUMEN TOTAL'!B32 -> CEN10 | C30: ='RESUMEN TOTAL'!D32 -> Monteagudo y Pte. Peron | D30: ='RESUMEN TOTAL'!E32 -> Domo | E30: ='RESUMEN TOTAL'!F32 -> Fibra Optica | F30: ='RESUMEN TOTAL'!K32 -> 0 | G30: ='RESUMEN TOTAL'!L32 -> 0 | H30: ='RESUMEN TOTAL'!M32 -> 0 | I30: ='RESUMEN TOTAL'!N32 -> 0 | J30: ='RESUMEN TOTAL'!O32 -> 0 | K30: ='RESUMEN TOTAL'!P32 -> 0 | L30: ='RESUMEN TOTAL'!Q32 -> 0 | M30: ='RESUMEN TOTAL'!R32 -> 0 | ... AI30: ='RESUMEN TOTAL'!AN32 -> 0
A31: ='RESUMEN TOTAL'!A33 -> CENTRO | B31: ='RESUMEN TOTAL'!B33 -> CEN11 | C31: ='RESUMEN TOTAL'!D33 -> Monteagudo y Bocuzzi | D31: ='RESUMEN TOTAL'!E33 -> Domo | E31: ='RESUMEN TOTAL'!F33 -> Fibra Optica | F31: ='RESUMEN TOTAL'!K33 -> 0 | G31: ='RESUMEN TOTAL'!L33 -> 0 | H31: ='RESUMEN TOTAL'!M33 -> 0 | I31: ='RESUMEN TOTAL'!N33 -> 0 | J31: ='RESUMEN TOTAL'!O33 -> 0 | K31: ='RESUMEN TOTAL'!P33 -> 0 | L31: ='RESUMEN TOTAL'!Q33 -> 0 | M31: ='RESUMEN TOTAL'!R33 -> 0 | ... AI31: ='RESUMEN TOTAL'!AN33 -> 0
A32: ='RESUMEN TOTAL'!A34 -> CENTRO | B32: ='RESUMEN TOTAL'!B34 -> CEN 12 | C32: ='RESUMEN TOTAL'!D34 -> Monteagudo y Mitre | D32: ='RESUMEN TOTAL'!E34 -> Domo | E32: ='RESUMEN TOTAL'!F34 -> Fibra Optica | F32: ='RESUMEN TOTAL'!K34 -> APAGADO | G32: ='RESUMEN TOTAL'!L34 -> APAGADO | H32: ='RESUMEN TOTAL'!M34 -> APAGADO | I32: ='RESUMEN TOTAL'!N34 -> APAGADO | J32: ='RESUMEN TOTAL'!O34 -> APAGADO | K32: ='RESUMEN TOTAL'!P34 -> APAGADO | L32: ='RESUMEN TOTAL'!Q34 -> APAGADO | M32: ='RESUMEN TOTAL'!R34 -> APAGADO | ... AI32: ='RESUMEN TOTAL'!AN34 -> 0
... A101: ='RESUMEN TOTAL'!A103 -> CENTRO | B101: ='RESUMEN TOTAL'!B103 -> CEN 81 | C101: ='RESUMEN TOTAL'!D103 -> Alberdi y A.del Valle | D101: ='RESUMEN TOTAL'!E103 -> Fija | E101: ='RESUMEN TOTAL'!F103 -> Fibra Optica | F101: ='RESUMEN TOTAL'!K103 -> 0 | G101: ='RESUMEN TOTAL'!L103 -> 0 | H101: ='RESUMEN TOTAL'!M103 -> 0 | I101: ='RESUMEN TOTAL'!N103 -> 0 | J101: ='RESUMEN TOTAL'!O103 -> 0 | K101: ='RESUMEN TOTAL'!P103 -> 0 | L101: ='RESUMEN TOTAL'!Q103 -> 0 | M101: ='RESUMEN TOTAL'!R103 -> 0 | ... AI101: ='RESUMEN TOTAL'!AN103 -> 0
A102: ='RESUMEN TOTAL'!A106 -> SAN NICOLAS | B102: ='RESUMEN TOTAL'!B106 -> CHA01 | C102: ='RESUMEN TOTAL'!D106 -> Novak y Pte Illia | D102: ='RESUMEN TOTAL'!E106 -> Domo | E102: ='RESUMEN TOTAL'!F106 -> Radio | F102: ='RESUMEN TOTAL'!K106 -> 0 | G102: ='RESUMEN TOTAL'!L106 -> 0 | H102: ='RESUMEN TOTAL'!M106 -> 0 | I102: ='RESUMEN TOTAL'!N106 -> 0 | J102: ='RESUMEN TOTAL'!O106 -> 0 | K102: ='RESUMEN TOTAL'!P106 -> 0 | L102: ='RESUMEN TOTAL'!Q106 -> 0 | M102: ='RESUMEN TOTAL'!R106 -> 0 | ... AI102: ='RESUMEN TOTAL'!AN106 -> 0
A103: ='RESUMEN TOTAL'!A107 -> CHACABUCO | B103: ='RESUMEN TOTAL'!B107 -> CHA02 | C103: ='RESUMEN TOTAL'!D107 -> Pte. Illia y Posadas | D103: ='RESUMEN TOTAL'!E107 -> Domo | E103: ='RESUMEN TOTAL'!F107 -> Radio | F103: ='RESUMEN TOTAL'!K107 -> 0 | G103: ='RESUMEN TOTAL'!L107 -> 0 | H103: ='RESUMEN TOTAL'!M107 -> APAGADO | I103: ='RESUMEN TOTAL'!N107 -> APAGADO | J103: ='RESUMEN TOTAL'!O107 -> APAGADO | K103: ='RESUMEN TOTAL'!P107 -> APAGADO | L103: ='RESUMEN TOTAL'!Q107 -> APAGADO | M103: ='RESUMEN TOTAL'!R107 -> 0 | ... AI103: ='RESUMEN TOTAL'!AN107 -> 0
A104: ='RESUMEN TOTAL'!A108 -> CHACABUCO | B104: ='RESUMEN TOTAL'!B108 -> CHA03 | C104: ='RESUMEN TOTAL'!D108 -> MAIPU Y ALVAREZ THOMAS | D104: ='RESUMEN TOTAL'!E108 -> DOMO | E104: ='RESUMEN TOTAL'!F108 -> Fibra Optica | F104: ='RESUMEN TOTAL'!K108 -> 0 | G104: ='RESUMEN TOTAL'!L108 -> 0 | H104: ='RESUMEN TOTAL'!M108 -> 0 | I104: ='RESUMEN TOTAL'!N108 -> 0 | J104: ='RESUMEN TOTAL'!O108 -> 0 | K104: ='RESUMEN TOTAL'!P108 -> 0 | L104: ='RESUMEN TOTAL'!Q108 -> 0 | M104: ='RESUMEN TOTAL'!R108 -> 0 | ... AI104: ='RESUMEN TOTAL'!AN108 -> 0
A105: ='RESUMEN TOTAL'!A109 -> CHACABUCO | B105: ='RESUMEN TOTAL'!B109 -> CHA04 | C105: ='RESUMEN TOTAL'!D109 -> ESTADOS UNIDOS DE A. E ILLIA | D105: ='RESUMEN TOTAL'!E109 -> DOMO | E105: ='RESUMEN TOTAL'!F109 -> Fibra Optica | F105: ='RESUMEN TOTAL'!K109 -> 0 | G105: ='RESUMEN TOTAL'!L109 -> 0 | H105: ='RESUMEN TOTAL'!M109 -> 0 | I105: ='RESUMEN TOTAL'!N109 -> 0 | J105: ='RESUMEN TOTAL'!O109 -> 0 | K105: ='RESUMEN TOTAL'!P109 -> 0 | L105: ='RESUMEN TOTAL'!Q109 -> 0 | M105: ='RESUMEN TOTAL'!R109 -> 0 | ... AI105: ='RESUMEN TOTAL'!AN109 -> 0
A106: ='RESUMEN TOTAL'!A110 -> LA COLORADA ESTE | B106: ='RESUMEN TOTAL'!B110 -> COL 03 | C106: ='RESUMEN TOTAL'!D110 -> CARIBONI Y LA ANCIANIDAD | D106: ='RESUMEN TOTAL'!E110 -> DOMO | E106: ='RESUMEN TOTAL'!F110 -> Radio | F106: ='RESUMEN TOTAL'!K110 -> 0 | G106: ='RESUMEN TOTAL'!L110 -> 0 | H106: ='RESUMEN TOTAL'!M110 -> 0 | I106: ='RESUMEN TOTAL'!N110 -> 0 | J106: ='RESUMEN TOTAL'!O110 -> 0 | K106: ='RESUMEN TOTAL'!P110 -> 0 | L106: ='RESUMEN TOTAL'!Q110 -> 0 | M106: ='RESUMEN TOTAL'!R110 -> 0 | ... AI106: ='RESUMEN TOTAL'!AN110 -> 0
A107: ='RESUMEN TOTAL'!A111 -> VILLA MONICA NUEVA | B107: ='RESUMEN TOTAL'!B111 -> COL01 | C107: ='RESUMEN TOTAL'!D111 -> Eva Peron y Cariboni | D107: ='RESUMEN TOTAL'!E111 -> Domo | E107: ='RESUMEN TOTAL'!F111 -> Radio | F107: ='RESUMEN TOTAL'!K111 -> 0 | G107: ='RESUMEN TOTAL'!L111 -> 0 | H107: ='RESUMEN TOTAL'!M111 -> 0 | I107: ='RESUMEN TOTAL'!N111 -> 0 | J107: ='RESUMEN TOTAL'!O111 -> 0 | K107: ='RESUMEN TOTAL'!P111 -> 0 | L107: ='RESUMEN TOTAL'!Q111 -> 0 | M107: ='RESUMEN TOTAL'!R111 -> 0 | ... AI107: ='RESUMEN TOTAL'!AN111 -> 0
A108: ='RESUMEN TOTAL'!A112 -> LA COLORADA ESTE | B108: ='RESUMEN TOTAL'!B112 -> COL02 | C108: ='RESUMEN TOTAL'!D112 -> Av. Eva Peron y Pompeya | D108: ='RESUMEN TOTAL'!E112 -> Domo | E108: ='RESUMEN TOTAL'!F112 -> Radio | F108: ='RESUMEN TOTAL'!K112 -> 0 | G108: ='RESUMEN TOTAL'!L112 -> 0 | H108: ='RESUMEN TOTAL'!M112 -> 0 | I108: ='RESUMEN TOTAL'!N112 -> 0 | J108: ='RESUMEN TOTAL'!O112 -> 0 | K108: ='RESUMEN TOTAL'!P112 -> 0 | L108: ='RESUMEN TOTAL'!Q112 -> 0 | M108: ='RESUMEN TOTAL'!R112 -> 0 | ... AI108: ='RESUMEN TOTAL'!AN112 -> 0
A109: ='RESUMEN TOTAL'!A113 -> DON JOSE | B109: ='RESUMEN TOTAL'!B113 -> DJO01 | C109: ='RESUMEN TOTAL'!D113 -> Monteverde y Donato Alvarez | D109: ='RESUMEN TOTAL'!E113 -> Domo | E109: ='RESUMEN TOTAL'!F113 -> RADIO | F109: ='RESUMEN TOTAL'!K113 -> 0 | G109: ='RESUMEN TOTAL'!L113 -> 0 | H109: ='RESUMEN TOTAL'!M113 -> 0 | I109: ='RESUMEN TOTAL'!N113 -> 0 | J109: ='RESUMEN TOTAL'!O113 -> 0 | K109: ='RESUMEN TOTAL'!P113 -> 0 | L109: ='RESUMEN TOTAL'!Q113 -> 0 | M109: ='RESUMEN TOTAL'!R113 -> 0 | ... AI109: ='RESUMEN TOTAL'!AN113 -> 0
A110: ='RESUMEN TOTAL'!A114 -> DON JOSE | B110: ='RESUMEN TOTAL'!B114 -> DJO 02 (fija 1) | C110: ='RESUMEN TOTAL'!D114 -> DONATO ALVAREZ Y EL APERO | D110: ='RESUMEN TOTAL'!E114 -> Fija | E110: ='RESUMEN TOTAL'!F114 -> PTO A FO | F110: ='RESUMEN TOTAL'!K114 -> 0 | G110: ='RESUMEN TOTAL'!L114 -> 0 | H110: ='RESUMEN TOTAL'!M114 -> 0 | I110: ='RESUMEN TOTAL'!N114 -> 0 | J110: ='RESUMEN TOTAL'!O114 -> 0 | K110: ='RESUMEN TOTAL'!P114 -> 0 | L110: ='RESUMEN TOTAL'!Q114 -> 0 | M110: ='RESUMEN TOTAL'!R114 -> 0 | ... AI110: ='RESUMEN TOTAL'!AN114 -> 0
A111: ='RESUMEN TOTAL'!A115 -> DON JOSE | B111: ='RESUMEN TOTAL'!B115 -> DJO 03 (fija 2) | C111: ='RESUMEN TOTAL'!D115 -> DONATO ALVAREZ Y EL APERO | D111: ='RESUMEN TOTAL'!E115 -> Fija | E111: ='RESUMEN TOTAL'!F115 -> PTO A FO | F111: ='RESUMEN TOTAL'!K115 -> 0 | G111: ='RESUMEN TOTAL'!L115 -> 0 | H111: ='RESUMEN TOTAL'!M115 -> 0 | I111: ='RESUMEN TOTAL'!N115 -> 0 | J111: ='RESUMEN TOTAL'!O115 -> 0 | K111: ='RESUMEN TOTAL'!P115 -> 0 | L111: ='RESUMEN TOTAL'!Q115 -> 0 | M111: ='RESUMEN TOTAL'!R115 -> 0 | ... AI111: ='RESUMEN TOTAL'!AN115 -> 0
A112: ='RESUMEN TOTAL'!A116 -> DON JOSE | B112: ='RESUMEN TOTAL'!B116 -> DJO 04 (Fija 1) | C112: ='RESUMEN TOTAL'!D116 -> MONTEVERDE Y EL INDIO | D112: ='RESUMEN TOTAL'!E116 -> Fija | E112: ='RESUMEN TOTAL'!F116 -> Radio | F112: ='RESUMEN TOTAL'!K116 -> APAGADO | G112: ='RESUMEN TOTAL'!L116 -> APAGADO | H112: ='RESUMEN TOTAL'!M116 -> 0 | I112: ='RESUMEN TOTAL'!N116 -> 0 | J112: ='RESUMEN TOTAL'!O116 -> 0 | K112: ='RESUMEN TOTAL'!P116 -> 0 | L112: ='RESUMEN TOTAL'!Q116 -> 0 | M112: ='RESUMEN TOTAL'!R116 -> 0 | ... AI112: ='RESUMEN TOTAL'!AN116 -> 0
A113: ='RESUMEN TOTAL'!A117 -> DON JOSE | B113: ='RESUMEN TOTAL'!B117 -> DJO 05 (Fija 2) | C113: ='RESUMEN TOTAL'!D117 -> MONTEVERDE Y EL INDIO | D113: ='RESUMEN TOTAL'!E117 -> Fija | E113: ='RESUMEN TOTAL'!F117 -> Radio | F113: ='RESUMEN TOTAL'!K117 -> APAGADO | G113: ='RESUMEN TOTAL'!L117 -> APAGADO | H113: ='RESUMEN TOTAL'!M117 -> APAGADO | I113: ='RESUMEN TOTAL'!N117 -> 0 | J113: ='RESUMEN TOTAL'!O117 -> 0 | K113: ='RESUMEN TOTAL'!P117 -> 0 | L113: ='RESUMEN TOTAL'!Q117 -> 0 | M113: ='RESUMEN TOTAL'!R117 -> 0 | ... AI113: ='RESUMEN TOTAL'!AN117 -> 0
... A119: ='RESUMEN TOTAL'!A123 -> EL PARQUE | B119: ='RESUMEN TOTAL'!B123 -> EPQ 04 | C119: ='RESUMEN TOTAL'!D123 -> 1282 Y MORENO | D119: ='RESUMEN TOTAL'!E123 -> DOMO | E119: ='RESUMEN TOTAL'!F123 -> Fibra Optica | F119: ='RESUMEN TOTAL'!K123 -> APAGADO | G119: ='RESUMEN TOTAL'!L123 -> 0 | H119: ='RESUMEN TOTAL'!M123 -> 0 | I119: ='RESUMEN TOTAL'!N123 -> 0 | J119: ='RESUMEN TOTAL'!O123 -> 0 | K119: ='RESUMEN TOTAL'!P123 -> 0 | L119: ='RESUMEN TOTAL'!Q123 -> 0 | M119: ='RESUMEN TOTAL'!R123 -> 0 | ... AI119: ='RESUMEN TOTAL'!AN123 -> 0
...

Sheet APAGADOS
E1: APAGADOS | F1: =COUNTIF(F3:F400, "APAGADO") -> 133 | G1: =COUNTIF(G3:G400, "APAGADO") -> 111 | H1: =COUNTIF(H3:H500, "APAGADO") -> 97 | I1: =COUNTIF(I3:I400, "APAGADO") -> 93 | J1: =COUNTIF(J3:J400, "APAGADO") -> 97 | K1: =COUNTIF(K3:K400, "APAGADO") -> 79 | L1: =COUNTIF(L3:L400, "APAGADO") -> 79 | M1: =COUNTIF(M3:M400, "APAGADO") -> 80 | N1: =COUNTIF(N3:N400, "APAGADO") -> 90 | O1: =COUNTIF(O3:O400, "APAGADO") -> 97 | P1: =COUNTIF(P3:P400, "APAGADO") -> 89 | ... AI1: =COUNTIF(AI3:AI400, "APAGADO") -> 0
A2: =ESTADISTICA!A1 -> Barrio | B2: =ESTADISTICA!B1 -> [Denominacion] | C2: =ESTADISTICA!C1 -> [Ubicacion] | D2: =ESTADISTICA!D1 -> [Tipo de Camara] | E2: =ESTADISTICA!E1 -> [Tipo de Conexion] | F2: =ESTADISTICA!F1 -> 44896 | G2: =ESTADISTICA!G1 -> 44897 | H2: =ESTADISTICA!H1 -> 44898 | ... AI2: =ESTADISTICA!AI1 -> 44925
A3: =ESTADISTICA!A2 -> ALTAMIRA | B3: =ESTADISTICA!B2 -> ALT01 | C3: =ESTADISTICA!C2 -> Calchaqui y Sgto. Cabral | D3: =ESTADISTICA!D2 -> Domo | E3: =ESTADISTICA!E2 -> Fibra Optica | F3: =ESTADISTICA!F2 -> APAGADO | G3: =ESTADISTICA!G2 -> APAGADO | H3: =ESTADISTICA!H2 -> APAGADO | ... AI3: =ESTADISTICA!AI2 -> 0
A4: =ESTADISTICA!A3 -> ALTAMIRA | B4: =ESTADISTICA!B3 -> ALT02 | C4: =ESTADISTICA!C3 -> Calchaqui y Lope de Vega | D4: =ESTADISTICA!D3 -> Domo | E4: =ESTADISTICA!E3 -> PTO A FO | F4: =ESTADISTICA!F3 -> APAGADO | G4: =ESTADISTICA!G3 -> APAGADO | H4: =ESTADISTICA!H3 -> APAGADO | ... AI4: =ESTADISTICA!AI3 -> 0
A5: =ESTADISTICA!A4 -> ALTAMIRA | B5: =ESTADISTICA!B4 -> ALT 03 | C5: =ESTADISTICA!C4 -> Bombero Galarza y Necochea | D5: =ESTADISTICA!D4 -> Domo | E5: =ESTADISTICA!E4 -> FIBRA OPTICA | F5: =ESTADISTICA!F4 -> APAGADO | G5: =ESTADISTICA!G4 -> APAGADO | H5: =ESTADISTICA!H4 -> APAGADO | ... AI5: =ESTADISTICA!AI4 -> 0
A6: =ESTADISTICA!A5 -> ALTAMIRA | B6: =ESTADISTICA!B5 -> ALT 04 | C6: =ESTADISTICA!C5 -> Francia y Necochea | D6: =ESTADISTICA!D5 -> Domo | E6: =ESTADISTICA!E5 -> FIBRA OPTICA | F6: =ESTADISTICA!F5 -> APAGADO | G6: =ESTADISTICA!G5 -> APAGADO | H6: =ESTADISTICA!H5 -> APAGADO | ... AI6: =ESTADISTICA!AI5 -> 0
A7: =ESTADISTICA!A6 -> ALTAMIRA | B7: =ESTADISTICA!B6 -> ALT05 | C7: =ESTADISTICA!C6 -> Av. Calchaqui y Bombero Galarza | D7: =ESTADISTICA!D6 -> Domo | E7: =ESTADISTICA!E6 -> PTO A FO | F7: =ESTADISTICA!F6 -> APAGADO | G7: =ESTADISTICA!G6 -> APAGADO | H7: =ESTADISTICA!H6 -> APAGADO | ... AI7: =ESTADISTICA!AI6 -> 0
A8: =ESTADISTICA!A7 -> ALTAMIRA | B8: =ESTADISTICA!B7 -> ALT 06 | C8: =ESTADISTICA!C7 -> LOPE DE VEGA Y NECOCHEA | D8: =ESTADISTICA!D7 -> Domo | E8: =ESTADISTICA!E7 -> PTO A FO | F8: =ESTADISTICA!F7 -> APAGADO | G8: =ESTADISTICA!G7 -> APAGADO | H8: =ESTADISTICA!H7 -> APAGADO | ... AI8: =ESTADISTICA!AI7 -> 0
A9: =ESTADISTICA!A8 -> ALTAMIRA | B9: =ESTADISTICA!B8 -> ALT07 | C9: =ESTADISTICA!C8 -> AV. CALCHAQUI Y AV. DEL TRABAJO | D9: =ESTADISTICA!D8 -> DOMO | E9: =ESTADISTICA!E8 -> PTO A FO | F9: =ESTADISTICA!F8 -> APAGADO | G9: =ESTADISTICA!G8 -> APAGADO | H9: =ESTADISTICA!H8 -> APAGADO | ... AI9: =ESTADISTICA!AI8 -> 0
A10: =ESTADISTICA!A9 -> ALTAMIRA | B10: =ESTADISTICA!B9 -> ALT 08 | C10: =ESTADISTICA!C9 -> HUMAITA Y NECOCHEA | D10: =ESTADISTICA!D9 -> DOMO | E10: =ESTADISTICA!E9 -> Fibra Optica | F10: =ESTADISTICA!F9 -> APAGADO | G10: =ESTADISTICA!G9 -> APAGADO | H10: =ESTADISTICA!H9 -> APAGADO | ... AI10: =ESTADISTICA!AI9 -> 0
A11: =ESTADISTICA!A10 -> ALTAMIRA | B11: =ESTADISTICA!B10 -> ALT 09 | C11: =ESTADISTICA!C10 -> NECOCHEA Y CURUPAITY | D11: =ESTADISTICA!D10 -> DOMO | E11: =ESTADISTICA!E10 -> Fibra Optica | F11: =ESTADISTICA!F10 -> APAGADO | G11: =ESTADISTICA!G10 -> APAGADO | H11: =ESTADISTICA!H10 -> APAGADO | ... AI11: =ESTADISTICA!AI10 -> 0
A12: =ESTADISTICA!A11 -> ALTAMIRA | B12: =ESTADISTICA!B11 -> ALT 10 | C12: =ESTADISTICA!C11 -> Calchaqui y Francia | D12: =ESTADISTICA!D11 -> Domo | E12: =ESTADISTICA!E11 -> Radio | F12: =ESTADISTICA!F11 -> APAGADO | G12: =ESTADISTICA!G11 -> APAGADO | H12: =ESTADISTICA!H11 -> APAGADO | ... AI12: =ESTADISTICA!AI11 -> 0
A13: =ESTADISTICA!A12 -> AGUSTIN RAMIREZ | B13: =ESTADISTICA!B12 -> ARA 01 | C13: =ESTADISTICA!C12 -> Malambo y Tranquera | D13: =ESTADISTICA!D12 -> Domo | E13: =ESTADISTICA!E12 -> FIBRA OPTICA | F13: =ESTADISTICA!F12 -> 0 | G13: =ESTADISTICA!G12 -> 0 | H13: =ESTADISTICA!H12 -> 0 | ... AI13: =ESTADISTICA!AI12 -> 0
... A509: =ESTADISTICA!A508 -> 0 | B509: =ESTADISTICA!B508 -> 0 | C509: =ESTADISTICA!C508 -> 0 | D509: =ESTADISTICA!D508 -> 0 | E509: =ESTADISTICA!E508 -> 0 | F509: =ESTADISTICA!F508 -> 0 | G509: =ESTADISTICA!G508 -> 0 | H509: =ESTADISTICA!H508 -> 0 | ... AI509: =ESTADISTICA!AI508 -> 0

Sheet APAGADOS FIBRA
C1: TOTAL FIBRA | D1: =COUNTIFS(E4:E400,"=Fibra Optica") -> 268
E2: APAGADOS | F2: =COUNTIFS(F4:F500, "=APAGADO",E4:E500,"=Fibra Optica") -> 100 | G2: =COUNTIFS(G4:G500, "=APAGADO",E4:E500,"=Fibra Optica") -> 81 | H2: =COUNTIFS(H4:H500, "=APAGADO",E4:E500,"=Fibra Optica") -> 65 | I2: =COUNTIFS(I4:I500, "=APAGADO",E4:E500,"=Fibra Optica") -> 64 | J2: =COUNTIFS(J4:J500, "=APAGADO",E4:E500,"=Fibra Optica") -> 70 | K2: =COUNTIFS(K4:K500, "=APAGADO",E4:E500,"=Fibra Optica") -> 55 | L2: =COUNTIFS(L4:L500, "=APAGADO",E4:E500,"=Fibra Optica") -> 59 | M2: =COUNTIFS(M4:M500, "=APAGADO",E4:E500,"=Fibra Optica") -> 63 | N2: =COUNTIFS(N4:N500, "=APAGADO",E4:E500,"=Fibra Optica") -> 73 | O2: =COUNTIFS(O4:O500, "=APAGADO",E4:E500,"=Fibra Optica") -> 76 | P2: =COUNTIFS(P4:P500, "=APAGADO",E4:E500,"=Fibra Optica") -> 70 | Q2: =COUNTIFS(Q4:Q500, "=APAGADO",E4:E500,"=Fibra Optica") -> 57 | R2: =COUNTIFS(R4:R500, "=APAGADO",E4:E500,"=Fibra Optica") -> 61 | S2: =COUNTIFS(S4:S500, "=APAGADO",E4:E500,"=Fibra Optica") -> 63 | T2: =COUNTIFS(T4:T500, "=APAGADO",E4:E500,"=Fibra Optica") -> 52 | U2: =COUNTIFS(U4:U500, "=APAGADO",E4:E500,"=Fibra Optica") -> 36 | V2: =COUNTIFS(V4:V500, "=APAGADO",E4:E500,"=Fibra Optica") -> 63 | W2: =COUNTIFS(W4:W500, "=APAGADO",E4:E500,"=Fibra Optica") -> 33 | X2: =COUNTIFS(X4:X500, "=APAGADO",E4:E500,"=Fibra Optica") -> 27 | Y2: =COUNTIFS(Y4:Y500, "=APAGADO",E4:E500,"=Fibra Optica") -> 29 | Z2: =COUNTIFS(Z4:Z500, "=APAGADO",E4:E500,"=Fibra Optica") -> 0 | AA2: =COUNTIFS(AA4:AA500, "=APAGADO",E4:E500,"=Fibra Optica") -> 0 | AB2: =COUNTIFS(AB4:AB500, "=APAGADO",E4:E500,"=Fibra Optica") -> 0 | AC2: =COUNTIFS(AC4:AC500, "=APAGADO",E4:E500,"=Fibra Optica") -> 0 | AD2: =COUNTIFS(AD4:AD500, "=APAGADO",E4:E500,"=Fibra Optica") -> 0 | AE2: =COUNTIFS(AE4:AE500, "=APAGADO",E4:E500,"=Fibra Optica") -> 0 | AF2: =COUNTIFS(AF4:AF500, "=APAGADO",E4:E500,"=Fibra Optica") -> 0 | AG2: =COUNTIFS(AG4:AG500, "=APAGADO",E4:E500,"=Fibra Optica") -> 0 | AH2: =COUNTIFS(AH4:AH500, "=APAGADO",E4:E500,"=Fibra Optica") -> 0 | AI2: =COUNTIFS(AI4:AI400, "=APAGADO",E4:E400,"=Fibra Optica") -> 0
A3: =ESTADISTICA!A1 -> Barrio | B3: =ESTADISTICA!B1 -> [Denominacion] | C3: =ESTADISTICA!C1 -> [Ubicacion] | D3: =ESTADISTICA!D1 -> [Tipo de Camara] | E3: =ESTADISTICA!E1 -> [Tipo de Conexion] | F3: =ESTADISTICA!F1 -> 44896 | G3: =ESTADISTICA!G1 -> 44897 | H3: =ESTADISTICA!H1 -> 44898 | ... AI3: =ESTADISTICA!AI1 -> 44925
A4: =ESTADISTICA!A2 -> ALTAMIRA | B4: =ESTADISTICA!B2 -> ALT01 | C4: =ESTADISTICA!C2 -> Calchaqui y Sgto. Cabral | D4: =ESTADISTICA!D2 -> Domo | E4: =ESTADISTICA!E2 -> Fibra Optica | F4: =ESTADISTICA!F2 -> APAGADO | G4: =ESTADISTICA!G2 -> APAGADO | H4: =ESTADISTICA!H2 -> APAGADO | ... AI4: =ESTADISTICA!AI2 -> 0
A5: =ESTADISTICA!A3 -> ALTAMIRA | B5: =ESTADISTICA!B3 -> ALT02 | C5: =ESTADISTICA!C3 -> Calchaqui y Lope de Vega | D5: =ESTADISTICA!D3 -> Domo | E5: =ESTADISTICA!E3 -> PTO A FO | F5: =ESTADISTICA!F3 -> APAGADO | G5: =ESTADISTICA!G3 -> APAGADO | H5: =ESTADISTICA!H3 -> APAGADO | ... AI5: =ESTADISTICA!AI3 -> 0
A6: =ESTADISTICA!A4 -> ALTAMIRA | B6: =ESTADISTICA!B4 -> ALT 03 | C6: =ESTADISTICA!C4 -> Bombero Galarza y Necochea | D6: =ESTADISTICA!D4 -> Domo | E6: =ESTADISTICA!E4 -> FIBRA OPTICA | F6: =ESTADISTICA!F4 -> APAGADO | G6: =ESTADISTICA!G4 -> APAGADO | H6: =ESTADISTICA!H4 -> APAGADO | ... AI6: =ESTADISTICA!AI4 -> 0
A7: =ESTADISTICA!A5 -> ALTAMIRA | B7: =ESTADISTICA!B5 -> ALT 04 | C7: =ESTADISTICA!C5 -> Francia y Necochea | D7: =ESTADISTICA!D5 -> Domo | E7: =ESTADISTICA!E5 -> FIBRA OPTICA | F7: =ESTADISTICA!F5 -> APAGADO | G7: =ESTADISTICA!G5 -> APAGADO | H7: =ESTADISTICA!H5 -> APAGADO | ... AI7: =ESTADISTICA!AI5 -> 0
A8: =ESTADISTICA!A6 -> ALTAMIRA | B8: =ESTADISTICA!B6 -> ALT05 | C8: =ESTADISTICA!C6 -> Av. Calchaqui y Bombero Galarza | D8: =ESTADISTICA!D6 -> Domo | E8: =ESTADISTICA!E6 -> PTO A FO | F8: =ESTADISTICA!F6 -> APAGADO | G8: =ESTADISTICA!G6 -> APAGADO | H8: =ESTADISTICA!H6 -> APAGADO | ... AI8: =ESTADISTICA!AI6 -> 0
A9: =ESTADISTICA!A7 -> ALTAMIRA | B9: =ESTADISTICA!B7 -> ALT 06 | C9: =ESTADISTICA!C7 -> LOPE DE VEGA Y NECOCHEA | D9: =ESTADISTICA!D7 -> Domo | E9: =ESTADISTICA!E7 -> PTO A FO | F9: =ESTADISTICA!F7 -> APAGADO | G9: =ESTADISTICA!G7 -> APAGADO | H9: =ESTADISTICA!H7 -> APAGADO | ... AI9: =ESTADISTICA!AI7 -> 0
A10: =ESTADISTICA!A8 -> ALTAMIRA | B10: =ESTADISTICA!B8 -> ALT07 | C10: =ESTADISTICA!C8 -> AV. CALCHAQUI Y AV. DEL TRABAJO | D10: =ESTADISTICA!D8 -> DOMO | E10: =ESTADISTICA!E8 -> PTO A FO | F10: =ESTADISTICA!F8 -> APAGADO | G10: =ESTADISTICA!G8 -> APAGADO | H10: =ESTADISTICA!H8 -> APAGADO | ... AI10: =ESTADISTICA!AI8 -> 0
A11: =ESTADISTICA!A9 -> ALTAMIRA | B11: =ESTADISTICA!B9 -> ALT 08 | C11: =ESTADISTICA!C9 -> HUMAITA Y NECOCHEA | D11: =ESTADISTICA!D9 -> DOMO | E11: =ESTADISTICA!E9 -> Fibra Optica | F11: =ESTADISTICA!F9 -> APAGADO | G11: =ESTADISTICA!G9 -> APAGADO | H11: =ESTADISTICA!H9 -> APAGADO | ... AI11: =ESTADISTICA!AI9 -> 0
A12: =ESTADISTICA!A10 -> ALTAMIRA | B12: =ESTADISTICA!B10 -> ALT 09 | C12: =ESTADISTICA!C10 -> NECOCHEA Y CURUPAITY | D12: =ESTADISTICA!D10 -> DOMO | E12: =ESTADISTICA!E10 -> Fibra Optica | F12: =ESTADISTICA!F10 -> APAGADO | G12: =ESTADISTICA!G10 -> APAGADO | H12: =ESTADISTICA!H10 -> APAGADO | ... AI12: =ESTADISTICA!AI10 -> 0
A13: =ESTADISTICA!A11 -> ALTAMIRA | B13: =ESTADISTICA!B11 -> ALT 10 | C13: =ESTADISTICA!C11 -> Calchaqui y Francia | D13: =ESTADISTICA!D11 -> Domo | E13: =ESTADISTICA!E11 -> Radio | F13: =ESTADISTICA!F11 -> APAGADO | G13: =ESTADISTICA!G11 -> APAGADO | H13: =ESTADISTICA!H11 -> APAGADO | ... AI13: =ESTADISTICA!AI11 -> 0
A14: =ESTADISTICA!A12 -> AGUSTIN RAMIREZ | B14: =ESTADISTICA!B12 -> ARA 01 | C14: =ESTADISTICA!C12 -> Malambo y Tranquera | D14: =ESTADISTICA!D12 -> Domo | E14: =ESTADISTICA!E12 -> FIBRA OPTICA | F14: =ESTADISTICA!F12 -> 0 | G14: =ESTADISTICA!G12 -> 0 | H14: =ESTADISTICA!H12 -> 0 | ... AI14: =ESTADISTICA!AI12 -> 0
... A435: =ESTADISTICA!A433 -> 0 | B435: =ESTADISTICA!B433 -> X | C435: =ESTADISTICA!C433 -> BRAILE Y FINOCCHIETTO | D435: =ESTADISTICA!D433 -> DOMO | E435: =ESTADISTICA!E433 -> Fibra Optica | F435: =ESTADISTICA!F433 -> 0 | G435: =ESTADISTICA!G433 -> 0 | H435: =ESTADISTICA!H433 -> 0 | ... AI435: =ESTADISTICA!AI433 -> 0

Sheet APAGADOS ANTENA
C1: TOTAL PTO A FO
E2: APAGADOS | F2: =COUNTIFS(F4:F500, "=APAGADO",E4:E500,"=PTO A FO") -> 11 | G2: =COUNTIFS(G4:G500, "=APAGADO",E4:E500,"=PTO A FO") -> 11 | H2: =COUNTIFS(H4:H500, "=APAGADO",E4:E500,"=PTO A FO") -> 9 | I2: =COUNTIFS(I4:I500, "=APAGADO",E4:E500,"=PTO A FO") -> 11 | J2: =COUNTIFS(J4:J500, "=APAGADO",E4:E500,"=PTO A FO") -> 12 | K2: =COUNTIFS(K4:K500, "=APAGADO",E4:E500,"=PTO A FO") -> 11 | L2: =COUNTIFS(L4:L500, "=APAGADO",E4:E500,"=PTO A FO") -> 11 | M2: =COUNTIFS(M4:M500, "=APAGADO",E4:E500,"=PTO A FO") -> 8 | N2: =COUNTIFS(N4:N500, "=APAGADO",E4:E500,"=PTO A FO") -> 9 | O2: =COUNTIFS(O4:O500, "=APAGADO",E4:E500,"=PTO A FO") -> 9 | P2: =COUNTIFS(P4:P500, "=APAGADO",E4:E500,"=PTO A FO") -> 9 | Q2: =COUNTIFS(Q4:Q500, "=APAGADO",E4:E500,"=PTO A FO") -> 8 | R2: =COUNTIFS(R4:R500, "=APAGADO",E4:E500,"=PTO A FO") -> 7 | S2: =COUNTIFS(S4:S500, "=APAGADO",E4:E500,"=PTO A FO") -> 8 | T2: =COUNTIFS(T4:T500, "=APAGADO",E4:E500,"=PTO A FO") -> 10 | U2: =COUNTIFS(U4:U500, "=APAGADO",E4:E500,"=PTO A FO") -> 3 | V2: =COUNTIFS(V4:V500, "=APAGADO",E4:E500,"=PTO A FO") -> 2 | W2: =COUNTIFS(W4:W500, "=APAGADO",E4:E500,"=PTO A FO") -> 3 | X2: =COUNTIFS(X4:X500, "=APAGADO",E4:E500,"=PTO A FO") -> 2 | Y2: =COUNTIFS(Y4:Y500, "=APAGADO",E4:E500,"=PTO A FO") -> 2 | Z2: =COUNTIFS(Z4:Z500, "=APAGADO",E4:E500,"=PTO A FO") -> 0 | AA2: =COUNTIFS(AA4:AA500, "=APAGADO",E4:E500,"=PTO A FO") -> 0 | AB2: =COUNTIFS(AB4:AB500, "=APAGADO",E4:E500,"=PTO A FO") -> 0 | AC2: =COUNTIFS(AC4:AC500, "=APAGADO",E4:E500,"=PTO A FO") -> 0 | AD2: =COUNTIFS(AD4:AD500, "=APAGADO",E4:E500,"=PTO A FO") -> 0 | AE2: =COUNTIFS(AE4:AE500, "=APAGADO",E4:E500,"=PTO A FO") -> 0 | AF2: =COUNTIFS(AF4:AF500, "=APAGADO",E4:E500,"=PTO A FO") -> 0 | AG2: =COUNTIFS(AG4:AG500, "=APAGADO",E4:E500,"=PTO A FO") -> 0 | AH2: =COUNTIFS(AH4:AH500, "=APAGADO",E4:E500,"=PTO A FO") -> 0 | AI2: =COUNTIFS(AI4:AI500, "=APAGADO",E4:E500,"=PTO A FO") -> 0
A3: =ESTADISTICA!A1 -> Barrio | B3: =ESTADISTICA!B1 -> [Denominacion] | C3: =ESTADISTICA!C1 -> [Ubicacion] | D3: =ESTADISTICA!D1 -> [Tipo de Camara] | E3: =ESTADISTICA!E1 -> [Tipo de Conexion] | F3: =ESTADISTICA!F1 -> 44896 | G3: =ESTADISTICA!G1 -> 44897 | H3: =ESTADISTICA!H1 -> 44898 | ... AI3: =ESTADISTICA!AI1 -> 44925
A4: =ESTADISTICA!A2 -> ALTAMIRA | B4: =ESTADISTICA!B2 -> ALT01 | C4: =ESTADISTICA!C2 -> Calchaqui y Sgto. Cabral | D4: =ESTADISTICA!D2 -> Domo | E4: =ESTADISTICA!E2 -> Fibra Optica | F4: =ESTADISTICA!F2 -> APAGADO | G4: =ESTADISTICA!G2 -> APAGADO | H4: =ESTADISTICA!H2 -> APAGADO | ... AI4: =ESTADISTICA!AI2 -> 0
A5: =ESTADISTICA!A3 -> ALTAMIRA | B5: =ESTADISTICA!B3 -> ALT02 | C5: =ESTADISTICA!C3 -> Calchaqui y Lope de Vega | D5: =ESTADISTICA!D3 -> Domo | E5: =ESTADISTICA!E3 -> PTO A FO | F5: =ESTADISTICA!F3 -> APAGADO | G5: =ESTADISTICA!G3 -> APAGADO | H5: =ESTADISTICA!H3 -> APAGADO | ... AI5: =ESTADISTICA!AI3 -> 0
A6: =ESTADISTICA!A4 -> ALTAMIRA | B6: =ESTADISTICA!B4 -> ALT 03 | C6: =ESTADISTICA!C4 -> Bombero Galarza y Necochea | D6: =ESTADISTICA!D4 -> Domo | E6: =ESTADISTICA!E4 -> FIBRA OPTICA | F6: =ESTADISTICA!F4 -> APAGADO | G6: =ESTADISTICA!G4 -> APAGADO | H6: =ESTADISTICA!H4 -> APAGADO | ... AI6: =ESTADISTICA!AI4 -> 0
A7: =ESTADISTICA!A5 -> ALTAMIRA | B7: =ESTADISTICA!B5 -> ALT 04 | C7: =ESTADISTICA!C5 -> Francia y Necochea | D7: =ESTADISTICA!D5 -> Domo | E7: =ESTADISTICA!E5 -> FIBRA OPTICA | F7: =ESTADISTICA!F5 -> APAGADO | G7: =ESTADISTICA!G5 -> APAGADO | H7: =ESTADISTICA!H5 -> APAGADO | ... AI7: =ESTADISTICA!AI5 -> 0
A8: =ESTADISTICA!A6 -> ALTAMIRA | B8: =ESTADISTICA!B6 -> ALT05 | C8: =ESTADISTICA!C6 -> Av. Calchaqui y Bombero Galarza | D8: =ESTADISTICA!D6 -> Domo | E8: =ESTADISTICA!E6 -> PTO A FO | F8: =ESTADISTICA!F6 -> APAGADO | G8: =ESTADISTICA!G6 -> APAGADO | H8: =ESTADISTICA!H6 -> APAGADO | ... AI8: =ESTADISTICA!AI6 -> 0
A9: =ESTADISTICA!A7 -> ALTAMIRA | B9: =ESTADISTICA!B7 -> ALT 06 | C9: =ESTADISTICA!C7 -> LOPE DE VEGA Y NECOCHEA | D9: =ESTADISTICA!D7 -> Domo | E9: =ESTADISTICA!E7 -> PTO A FO | F9: =ESTADISTICA!F7 -> APAGADO | G9: =ESTADISTICA!G7 -> APAGADO | H9: =ESTADISTICA!H7 -> APAGADO | ... AI9: =ESTADISTICA!AI7 -> 0
A10: =ESTADISTICA!A8 -> ALTAMIRA | B10: =ESTADISTICA!B8 -> ALT07 | C10: =ESTADISTICA!C8 -> AV. CALCHAQUI Y AV. DEL TRABAJO | D10: =ESTADISTICA!D8 -> DOMO | E10: =ESTADISTICA!E8 -> PTO A FO | F10: =ESTADISTICA!F8 -> APAGADO | G10: =ESTADISTICA!G8 -> APAGADO | H10: =ESTADISTICA!H8 -> APAGADO | ... AI10: =ESTADISTICA!AI8 -> 0
A11: =ESTADISTICA!A9 -> ALTAMIRA | B11: =ESTADISTICA!B9 -> ALT 08 | C11: =ESTADISTICA!C9 -> HUMAITA Y NECOCHEA | D11: =ESTADISTICA!D9 -> DOMO | E11: =ESTADISTICA!E9 -> Fibra Optica | F11: =ESTADISTICA!F9 -> APAGADO | G11: =ESTADISTICA!G9 -> APAGADO | H11: =ESTADISTICA!H9 -> APAGADO | ... AI11: =ESTADISTICA!AI9 -> 0
A12: =ESTADISTICA!A10 -> ALTAMIRA | B12: =ESTADISTICA!B10 -> ALT 09 | C12: =ESTADISTICA!C10 -> NECOCHEA Y CURUPAITY | D12: =ESTADISTICA!D10 -> DOMO | E12: =ESTADISTICA!E10 -> Fibra Optica | F12: =ESTADISTICA!F10 -> APAGADO | G12: =ESTADISTICA!G10 -> APAGADO | H12: =ESTADISTICA!H10 -> APAGADO | ... AI12: =ESTADISTICA!AI10 -> 0
A13: =ESTADISTICA!A11 -> ALTAMIRA | B13: =ESTADISTICA!B11 -> ALT 10 | C13: =ESTADISTICA!C11 -> Calchaqui y Francia | D13: =ESTADISTICA!D11 -> Domo | E13: =ESTADISTICA!E11 -> Radio | F13: =ESTADISTICA!F11 -> APAGADO | G13: =ESTADISTICA!G11 -> APAGADO | H13: =ESTADISTICA!H11 -> APAGADO | ... AI13: =ESTADISTICA!AI11 -> 0
A14: =ESTADISTICA!A12 -> AGUSTIN RAMIREZ | B14: =ESTADISTICA!B12 -> ARA 01 | C14: =ESTADISTICA!C12 -> Malambo y Tranquera | D14: =ESTADISTICA!D12 -> Domo | E14: =ESTADISTICA!E12 -> FIBRA OPTICA | F14: =ESTADISTICA!F12 -> 0 | G14: =ESTADISTICA!G12 -> 0 | H14: =ESTADISTICA!H12 -> 0 | ... AI14: =ESTADISTICA!AI12 -> 0
... A278: =ESTADISTICA!A276 -> SAN EMILIO | B278: =ESTADISTICA!B276 -> SEMI 02 | C278: =ESTADISTICA!C276 -> Cno. Gral. Belgrano y Francia | D278: =ESTADISTICA!D276 -> Domo | E278: =ESTADISTICA!E276 -> FIBRA OPTICA | F278: =ESTADISTICA!F276 -> APAGADO | G278: =ESTADISTICA!G276 -> APAGADO | H278: =ESTADISTICA!H276 -> APAGADO | ... AI278: =ESTADISTICA!AI276 -> 0
B279: =ESTADISTICA!B277 -> SEMI03 (fija 1) | C279: =ESTADISTICA!C277 -> GORRITI E/ GALARZA Y LOPE DE VEGA | D279: =ESTADISTICA!D277 -> Fija | E279: =ESTADISTICA!E277 -> Fibra Optica | F279: =ESTADISTICA!F277 -> 0 | G279: =ESTADISTICA!G277 -> 0 | H279: =ESTADISTICA!H277 -> 0 | I279: =ESTADISTICA!I277 -> 0 | ... AI279: =ESTADISTICA!AI277 -> 0
A280: =ESTADISTICA!A278 -> SAN EMILIO | B280: =ESTADISTICA!B278 -> SEMI04 (fija 2) | C280: =ESTADISTICA!C278 -> GORRITI E/ GALARZA Y LOPE DE VEGA | D280: =ESTADISTICA!D278 -> Fija | E280: =ESTADISTICA!E278 -> Fibra Optica | F280: =ESTADISTICA!F278 -> 0 | G280: =ESTADISTICA!G278 -> 0 | H280: =ESTADISTICA!H278 -> 0 | ... AI280: =ESTADISTICA!AI278 -> 0
A281: =ESTADISTICA!A279 -> LA SIRENA | B281: =ESTADISTICA!B279 -> SIR01 | C281: =ESTADISTICA!C279 -> Moran y Calle 14 | D281: =ESTADISTICA!D279 -> DOMO | E281: =ESTADISTICA!E279 -> Radio | F281: =ESTADISTICA!F279 -> 0 | G281: =ESTADISTICA!G279 -> 0 | H281: =ESTADISTICA!H279 -> 0 | ... AI281: =ESTADISTICA!AI279 -> 0
A282: =ESTADISTICA!A280 -> SAN EDUARDO | B282: =ESTADISTICA!B280 -> SIR 02 | C282: =ESTADISTICA!C280 -> Victorino de la Plaza y Argentina | D282: =ESTADISTICA!D280 -> Domo | E282: =ESTADISTICA!E280 -> Radio | F282: =ESTADISTICA!F280 -> 0 | G282: =ESTADISTICA!G280 -> APAGADO | H282: =ESTADISTICA!H280 -> 0 | ... AI282: =ESTADISTICA!AI280 -> 0
A283: =ESTADISTICA!A281 -> SAN EDUARDO | B283: =ESTADISTICA!B281 -> SIR 03 | C283: =ESTADISTICA!C281 -> MONTES Y LONARDI | D283: =ESTADISTICA!D281 -> DOMO | E283: =ESTADISTICA!E281 -> Radio | F283: =ESTADISTICA!F281 -> 0 | G283: =ESTADISTICA!G281 -> 0 | H283: =ESTADISTICA!H281 -> 0 | ... AI283: =ESTADISTICA!AI281 -> 0
A284: =ESTADISTICA!A282 -> LA SIRENA | B284: =ESTADISTICA!B282 -> SIR 04 | C284: =ESTADISTICA!C282 -> AV. MONTEVERDE Y MORAN | D284: =ESTADISTICA!D282 -> Domo | E284: =ESTADISTICA!E282 -> Fibra Optica | F284: =ESTADISTICA!F282 -> 0 | G284: =ESTADISTICA!G282 -> 0 | H284: =ESTADISTICA!H282 -> 0 | ... AI284: =ESTADISTICA!AI282 -> 0
A285: =ESTADISTICA!A283 -> LA SIRENA | B285: =ESTADISTICA!B283 -> SIR 05 (FIJA 01) | C285: =ESTADISTICA!C283 -> AV. MONTEVERDE Y MORAN | D285: =ESTADISTICA!D283 -> Fija | E285: =ESTADISTICA!E283 -> Fibra Optica | F285: =ESTADISTICA!F283 -> 0 | G285: =ESTADISTICA!G283 -> 0 | H285: =ESTADISTICA!H283 -> 0 | ... AI285: =ESTADISTICA!AI283 -> 0
A286: =ESTADISTICA!A284 -> LA SIRENA | B286: =ESTADISTICA!B284 -> SIR 06 (FIJA 02) | C286: =ESTADISTICA!C284 -> AV. MONTEVERDE Y MORAN | D286: =ESTADISTICA!D284 -> Fija | E286: =ESTADISTICA!E284 -> Fibra Optica | F286: =ESTADISTICA!F284 -> 0 | G286: =ESTADISTICA!G284 -> 0 | H286: =ESTADISTICA!H284 -> 0 | ... AI286: =ESTADISTICA!AI284 -> 0
A287: =ESTADISTICA!A285 -> VILLA AURORA | B287: =ESTADISTICA!B285 -> SIR07 (fija 1) | C287: =ESTADISTICA!C285 -> MONTEVERDE Y URIBURU | D287: =ESTADISTICA!D285 -> Fija | E287: =ESTADISTICA!E285 -> Fibra Optica | F287: =ESTADISTICA!F285 -> 0 | G287: =ESTADISTICA!G285 -> 0 | H287: =ESTADISTICA!H285 -> 0 | ... AI287: =ESTADISTICA!AI285 -> 0
A288: =ESTADISTICA!A286 -> VILLA AURORA | B288: =ESTADISTICA!B286 -> SIR08 (fija 2) | C288: =ESTADISTICA!C286 -> MONTEVERDE Y URIBURU | D288: =ESTADISTICA!D286 -> Fija | E288: =ESTADISTICA!E286 -> Fibra Optica | F288: =ESTADISTICA!F286 -> 0 | G288: =ESTADISTICA!G286 -> 0 | H288: =ESTADISTICA!H286 -> 0 | ... AI288: =ESTADISTICA!AI286 -> 0
A289: =ESTADISTICA!A287 -> LA SIRENA | B289: =ESTADISTICA!B287 -> SIR09 (fija 1) | C289: =ESTADISTICA!C287 -> GUIDO SPANO Y MORAN | D289: =ESTADISTICA!D287 -> Fija | E289: =ESTADISTICA!E287 -> Fibra Optica | F289: =ESTADISTICA!F287 -> 0 | G289: =ESTADISTICA!G287 -> 0 | H289: =ESTADISTICA!H287 -> 0 | ... AI289: =ESTADISTICA!AI287 -> 0
A290: =ESTADISTICA!A288 -> LA SIRENA | B290: =ESTADISTICA!B288 -> SIR10 (fija 2) | C290: =ESTADISTICA!C288 -> GUIDO SPANO Y MORAN | D290: =ESTADISTICA!D288 -> Fija | E290: =ESTADISTICA!E288 -> Fibra Optica | F290: =ESTADISTICA!F288 -> 0 | G290: =ESTADISTICA!G288 -> 0 | H290: =ESTADISTICA!H288 -> 0 | ... AI290: =ESTADISTICA!AI288 -> 0
A291: =ESTADISTICA!A289 -> LA SIRENA | B291: =ESTADISTICA!B289 -> SIR11 (fija 1) | C291: =ESTADISTICA!C289 -> LARREA Y GUARDIA NACIONAL | D291: =ESTADISTICA!D289 -> Fija | E291: =ESTADISTICA!E289 -> Fibra Optica | F291: =ESTADISTICA!F289 -> 0 | G291: =ESTADISTICA!G289 -> 0 | H291: =ESTADISTICA!H289 -> 0 | ... AI291: =ESTADISTICA!AI289 -> 0
... A454: =ESTADISTICA!A452 -> 0 | B454: =ESTADISTICA!B452 -> 0 | C454: =ESTADISTICA!C452 -> 0 | D454: =ESTADISTICA!D452 -> 0 | E454: =ESTADISTICA!E452 -> 0 | F454: =ESTADISTICA!F452 -> 0 | G454: =ESTADISTICA!G452 -> 0 | H454: =ESTADISTICA!H452 -> 0 | ... AI454: =ESTADISTICA!AI452 -> 0

Sheet APAGADOS RADIO
C1: TOTAL RADIO | D1: =COUNTIFS(E4:E400,"=radio") -> 93
E2: APAGADOS | F2: =COUNTIFS(F4:F500, "=APAGADO",E4:E500,"=radio") -> 24 | G2: =COUNTIFS(G4:G500, "=APAGADO",E4:E500,"=radio") -> 21 | H2: =COUNTIFS(H4:H500, "=APAGADO",E4:E500,"=radio") -> 23 | I2: =COUNTIFS(I4:I500, "=APAGADO",E4:E500,"=radio") -> 20 | J2: =COUNTIFS(J4:J500, "=APAGADO",E4:E500,"=radio") -> 16 | K2: =COUNTIFS(K4:K500, "=APAGADO",E4:E500,"=radio") -> 15 | L2: =COUNTIFS(L4:L500, "=APAGADO",E4:E500,"=radio") -> 12 | M2: =COUNTIFS(M4:M500, "=APAGADO",E4:E500,"=radio") -> 11 | N2: =COUNTIFS(N4:N500, "=APAGADO",E4:E500,"=radio") -> 10 | O2: =COUNTIFS(O4:O500, "=APAGADO",E4:E500,"=radio") -> 14 | P2: =COUNTIFS(P4:P500, "=APAGADO",E4:E500,"=radio") -> 12 | Q2: =COUNTIFS(Q4:Q367, "=APAGADO",E4:E367,"=radio") -> 10 | R2: =COUNTIFS(R4:R500, "=APAGADO",E4:E500,"=radio") -> 10 | S2: =COUNTIFS(S4:S500, "=APAGADO",E4:E500,"=radio") -> 11 | T2: =COUNTIFS(T4:T500, "=APAGADO",E4:E500,"=radio") -> 13 | U2: =COUNTIFS(U4:U500, "=APAGADO",E4:E500,"=radio") -> 12 | V2: =COUNTIFS(V4:V500, "=APAGADO",E4:E500,"=radio") -> 16 | W2: =COUNTIFS(W4:W500, "=APAGADO",E4:E500,"=radio") -> 9 | X2: =COUNTIFS(X4:X500, "=APAGADO",E4:E500,"=radio") -> 9 | Y2: =COUNTIFS(Y4:Y500, "=APAGADO",E4:E500,"=radio") -> 6 | Z2: =COUNTIFS(Z4:Z500, "=APAGADO",E4:E500,"=radio") -> 0 | AA2: =COUNTIFS(AA4:AA500, "=APAGADO",E4:E500,"=radio") -> 0 | AB2: =COUNTIFS(AB4:AB500, "=APAGADO",E4:E500,"=radio") -> 0 | AC2: =COUNTIFS(AC4:AC500, "=APAGADO",E4:E500,"=radio") -> 0 | AD2: =COUNTIFS(AD4:AD500, "=APAGADO",E4:E500,"=radio") -> 0 | AE2: =COUNTIFS(AE4:AE500, "=APAGADO",E4:E500,"=radio") -> 0 | AF2: =COUNTIFS(AF4:AF500, "=APAGADO",E4:E500,"=radio") -> 0 | AG2: =COUNTIFS(AG4:AG500, "=APAGADO",E4:E500,"=radio") -> 0 | AH2: =COUNTIFS(AH4:AH500, "=APAGADO",E4:E500,"=radio") -> 0 | AI2: =COUNTIFS(AI4:AI500, "=APAGADO",E4:E500,"=radio") -> 0
A3: =ESTADISTICA!A1 -> Barrio | B3: =ESTADISTICA!B1 -> [Denominacion] | C3: =ESTADISTICA!C1 -> [Ubicacion] | D3: =ESTADISTICA!D1 -> [Tipo de Camara] | E3: =ESTADISTICA!E1 -> [Tipo de Conexion] | F3: =ESTADISTICA!F1 -> 44896 | G3: =ESTADISTICA!G1 -> 44897 | H3: =ESTADISTICA!H1 -> 44898 | ... AI3: =ESTADISTICA!AI1 -> 44925
A4: =ESTADISTICA!A2 -> ALTAMIRA | B4: =ESTADISTICA!B2 -> ALT01 | C4: =ESTADISTICA!C2 -> Calchaqui y Sgto. Cabral | D4: =ESTADISTICA!D2 -> Domo | E4: =ESTADISTICA!E2 -> Fibra Optica | F4: =ESTADISTICA!F2 -> APAGADO | G4: =ESTADISTICA!G2 -> APAGADO | H4: =ESTADISTICA!H2 -> APAGADO | ... AI4: =ESTADISTICA!AI2 -> 0
A5: =ESTADISTICA!A3 -> ALTAMIRA | B5: =ESTADISTICA!B3 -> ALT02 | C5: =ESTADISTICA!C3 -> Calchaqui y Lope de Vega | D5: =ESTADISTICA!D3 -> Domo | E5: =ESTADISTICA!E3 -> PTO A FO | F5: =ESTADISTICA!F3 -> APAGADO | G5: =ESTADISTICA!G3 -> APAGADO | H5: =ESTADISTICA!H3 -> APAGADO | ... AI5: =ESTADISTICA!AI3 -> 0
