Workbook
Name _25_de_agosto: 'RESUMEN TOTAL'!$A$4:$D$365
Name _25_de_agosto_3: 'RESUMEN TOTAL'!$A$4:$D$377
Name BONOMOcam: Hoja1!$B$2
Name CANTIDAD_DE_CAMARAS: 'RESUMEN TOTAL'!$B$1
Name COSEIDIcam: Hoja1!$B$4

Sheet RESUMEN TOTAL
A1: CANTIDAD DE CAMARAS | B1: =COUNTA(B5:B533) -> 435 | D1: PORCIENTO DE CAIDAS | K1: =(K3)/(K2+K3) -> 0.082758621 | L1: =(L3)/(L2+L3) -> 0.052873563 | M1: =(M3)/(M2+M3) -> 0.087356322 | N1: =(N3)/(N2+N3) -> 0.10804598 | O1: =(O3)/(O2+O3) -> 0.057471264 | P1: =(P3)/(P2+P3) -> 0.082758621 | Q1: =(Q3)/(Q2+Q3) -> 0.050574713 | R1: =(R3)/(R2+R3) -> 0.064367816 | ... AN1: =(AN3)/(AN2+AN3) -> 0
D2: FUNCIONAN | K2: =B1-K3 -> 399 | L2: =CANTIDAD_DE_CAMARAS-L3 -> 412 | M2: =CANTIDAD_DE_CAMARAS-M3 -> 397 | N2: =CANTIDAD_DE_CAMARAS-N3 -> 388 | O2: =CANTIDAD_DE_CAMARAS-O3 -> 410 | P2: =CANTIDAD_DE_CAMARAS-P3 -> 399 | Q2: =CANTIDAD_DE_CAMARAS-Q3 -> 413 | R2: =CANTIDAD_DE_CAMARAS-R3 -> 407 | S2: =CANTIDAD_DE_CAMARAS-S3 -> 414 | ... AN2: =CANTIDAD_DE_CAMARAS-AN3 -> 435
D3: CAIDAS | K3: =COUNTIF(K4:K453, "apagado") -> 36 | L3: =COUNTIF(L4:L453, "apagado") -> 23 | M3: =COUNTIF(M4:M453, "apagado") -> 38 | N3: =COUNTIF(N4:N453, "apagado") -> 47 | O3: =COUNTIF(O4:O453, "apagado") -> 25 | P3: =COUNTIF(P4:P453, "apagado") -> 36 | Q3: =COUNTIF(Q4:Q453, "apagado") -> 22 | R3: =COUNTIF(R4:R453, "apagado") -> 28 | ... AN3: =COUNTIF(AN4:AN453, "apagado") -> 0
A4: Barrio | B4: [Denominacion] | C4: [Empresa Mantenimiento] | D4: [Ubicacion] | E4: [Tipo de Camara] | F4: [Tipo de Conexion] | H4: DIAS FUNCIONANDO | I4: DIAS CAIDA | J4: EFECTIVIDAD | K4: 44927 | L4: 44928 | M4: 44929 | N4: 44930 | O4: 44931 | P4: 44932 | Q4: 44933 | R4: 44934 | S4: 44935 | T4: 44936 | U4: 44937 | V4: 44938 | W4: 44939 | X4: 44940 | Y4: 44941 | Z4: 44942 | AA4: 44943 | AB4: 44944 | AC4: 44945 | AD4: 44946 | AE4: 44947 | AF4: 44948 | AG4: 44949 | AH4: 44950 | AI4: 44951 | AJ4: 44952 | AK4: 44953 | AL4: 44954 | AM4: 44955 | AN4: 44956 | AO4: 44957
A5: ALTAMIRA | B5: ALT01 | C5: BONOMO | D5: Calchaqui y Sgto. Cabral | E5: Domo | F5: Fibra Optica | G5: 172.20.10.6 | H5: =COUNTIF(K5:AO5,"") -> 31 | I5: =COUNTIF(K5:AL5,"APAGADO") -> 0 | J5: =(H5)/(I5+H5) -> 1
A6: ALTAMIRA | B6: ALT02 | C6: BONOMO | D6: Calchaqui y Lope de Vega | E6: Domo | F6: PTO A FO | G6: 172.20.12.218 | H6: =COUNTIF(K6:AO6,"") -> 31 | I6: =COUNTIF(K6:AL6,"APAGADO") -> 0 | J6: =(H6)/(I6+H6) -> 1
A7: ALTAMIRA | B7: ALT 03 | C7: BONOMO | D7: Bombero Galarza y Necochea | E7: Domo | F7: FIBRA OPTICA | G7: 172.20.12.54 | H7: =COUNTIF(K7:AO7,"") -> 31 | I7: =COUNTIF(K7:AL7,"APAGADO") -> 0 | J7: =(H7)/(I7+H7) -> 1
A8: ALTAMIRA | B8: ALT 04 | C8: BONOMO | D8: Francia y Necochea | E8: Domo | F8: FIBRA OPTICA | G8: 172.20.12.55 | H8: =COUNTIF(K8:AO8,"") -> 31 | I8: =COUNTIF(K8:AL8,"APAGADO") -> 0 | J8: =(H8)/(I8+H8) -> 1
A9: ALTAMIRA | B9: ALT05 | C9: BONOMO | D9: Av. Calchaqui y Bombero Galarza | E9: Domo | F9: PTO A FO | G9: 172.20.12.216 | H9: =COUNTIF(K9:AO9,"") -> 31 | I9: =COUNTIF(K9:AL9,"APAGADO") -> 0 | J9: =(H9)/(I9+H9) -> 1
A10: ALTAMIRA | B10: ALT 06 | C10: BONOMO | D10: LOPE DE VEGA Y NECOCHEA | E10: Domo | F10: PTO A FO | G10: 172.20.12.12 | H10: =COUNTIF(K10:AO10,"") -> 31 | I10: =COUNTIF(K10:AL10,"APAGADO") -> 0 | J10: =(H10)/(I10+H10) -> 1
A11: ALTAMIRA | B11: ALT07 | C11: BONOMO | D11: AV. CALCHAQUI Y AV. DEL TRABAJO | E11: DOMO | F11: PTO A FO | G11: 172.20.10.57 | H11: =COUNTIF(K11:AO11,"") -> 31 | I11: =COUNTIF(K11:AL11,"APAGADO") -> 0 | J11: =(H11)/(I11+H11) -> 1
A12: ALTAMIRA | B12: ALT 08 | C12: BONOMO | D12: HUMAITA Y NECOCHEA | E12: DOMO | F12: Fibra Optica | G12: 172.20.11.215 | H12: =COUNTIF(K12:AO12,"") -> 31 | I12: =COUNTIF(K12:AL12,"APAGADO") -> 0 | J12: =(H12)/(I12+H12) -> 1
A13: ALTAMIRA | B13: ALT 09 | C13: BONOMO | D13: NECOCHEA Y CURUPAITY | E13: DOMO | F13: Fibra Optica | G13: 172.20.11.216 | H13: =COUNTIF(K13:AO13,"") -> 31 | I13: =COUNTIF(K13:AL13,"APAGADO") -> 0 | J13: =(H13)/(I13+H13) -> 1
A14: ALTAMIRA | B14: ALT 10 | C14: BONOMO | D14: Calchaqui y Francia | E14: Domo | F14: Radio | H14: =COUNTIF(K14:AO14,"") -> 31 | I14: =COUNTIF(K14:AL14,"APAGADO") -> 0 | J14: =(H14)/(I14+H14) -> 1
A15: AGUSTIN RAMIREZ | B15: ARA 01 | C15: COSEIDI | D15: Malambo y Tranquera | E15: Domo | F15: FIBRA OPTICA | G15: 172.20.12.110 | H15: =COUNTIF(K15:AO15,"") -> 31 | I15: =COUNTIF(K15:AL15,"APAGADO") -> 0 | J15: =(H15)/(I15+H15) -> 1
A16: BELGRANO | B16: BEL 01 | C16: BONOMO | D16: San Martin y Dardo Rocha | E16: DOMO | F16: FIBRA OPTICA | G16: 172.20.12.64 | H16: =COUNTIF(K16:AO16,"") -> 25 | I16: =COUNTIF(K16:AL16,"APAGADO") -> 6 | J16: =(H16)/(I16+H16) -> 0.80645161 | K16: APAGADO | L16: APAGADO | M16: APAGADO | N16: APAGADO | O16: APAGADO | P16: APAGADO
A17: BOSQUES CENTRO | B17: BOSQC 01 | C17: COSEIDI | D17: LUIS AGOTE E/DANUNCIO Y CAMPOAMOR | E17: Fija | F17: Radio | G17: 172.20.11.15 | H17: =COUNTIF(K17:AO17,"") -> 31 | I17: =COUNTIF(K17:AL17,"APAGADO") -> 0 | J17: =(H17)/(I17+H17) -> 1
A18: BOSQUES CENTRO | B18: BOSQC 02 | C18: COSEIDI | D18: LUIS AGOTE E/DANUNCIO Y CAMPOAMOR | E18: Fija | F18: Radio | G18: 172.20.11.16 | H18: =COUNTIF(K18:AO18,"") -> 31 | I18: =COUNTIF(K18:AL18,"APAGADO") -> 0 | J18: =(H18)/(I18+H18) -> 1
A19: BOSQUES CENTRO | B19: BOSQC 03 | C19: COSEIDI | D19: BENAVENTE Y LUIS AGOTE | E19: Fija | F19: Radio | G19: 172.20.11.13 | H19: =COUNTIF(K19:AO19,"") -> 31 | I19: =COUNTIF(K19:AL19,"APAGADO") -> 0 | J19: =(H19)/(I19+H19) -> 1
A20: BOSQUES CENTRO | B20: BOSQC 04 | C20: COSEIDI | D20: BENAVENTE Y LUIS AGOTE | E20: Fija | F20: Radio | G20: 172.20.11.113 | H20: =COUNTIF(K20:AO20,"") -> 31 | I20: =COUNTIF(K20:AL20,"APAGADO") -> 0 | J20: =(H20)/(I20+H20) -> 1
A21: BOSQUES CENTRO | B21: BOSQC 05 | C21: COSEIDI | D21: LUIS AGOTE Y RUTA 36 | E21: Fija | F21: Radio | G21: 172.20.11.17 | H21: =COUNTIF(K21:AO21,"") -> 31 | I21: =COUNTIF(K21:AL21,"APAGADO") -> 0 | J21: =(H21)/(I21+H21) -> 1
A22: BOSQUES CENTRO | B22: BOSQC 06 | C22: COSEIDI | D22: LUIS AGOTE Y RUTA 36 | E22: Fija | F22: Radio | G22: 172.20.11.18 | H22: =COUNTIF(K22:AO22,"") -> 31 | I22: =COUNTIF(K22:AL22,"APAGADO") -> 0 | J22: =(H22)/(I22+H22) -> 1
A23: CENTRO | B23: CEN01 | C23: BONOMO | D23: San Martin y 9 de Julio | E23: Fija | F23: Fibra Optica | G23: 172.20.11.10 | H23: =COUNTIF(K23:AO23,"") -> 31 | I23: =COUNTIF(K23:AL23,"APAGADO") -> 0 | J23: =(H23)/(I23+H23) -> 1
A24: CENTRO | B24: CEN02 | C24: BONOMO | D24: San Martin y Almafuerte | E24: Fija | F24: Fibra Optica | G24: 172.20.11.11 | H24: =COUNTIF(K24:AO24,"") -> 31 | I24: =COUNTIF(K24:AL24,"APAGADO") -> 0 | J24: =(H24)/(I24+H24) -> 1
A25: CENTRO | B25: CEN03 | C25: BONOMO | D25: San Martin y Sallares | E25: Domo | F25: Fibra Optica | G25: 172.20.12.30 | H25: =COUNTIF(K25:AO25,"") -> 31 | I25: =COUNTIF(K25:AL25,"APAGADO") -> 0 | J25: =(H25)/(I25+H25) -> 1
A26: CENTRO | B26: CEN04 | C26: BONOMO | D26: San Martin y Contreras | E26: Domo | F26: Fibra Optica | G26: 172.20.12.29 | H26: =COUNTIF(K26:AO26,"") -> 31 | I26: =COUNTIF(K26:AL26,"APAGADO") -> 0 | J26: =(H26)/(I26+H26) -> 1
A27: CENTRO | B27: CEN 05 | C27: BONOMO | D27: Bocuzzi e/España y San Martin | E27: DOMO | F27: Fibra Optica | G27: 172.20.10.200 | H27: =COUNTIF(K27:AO27,"") -> 31 | I27: =COUNTIF(K27:AL27,"APAGADO") -> 0 | J27: =(H27)/(I27+H27) -> 1
A28: CENTRO | B28: CEN06 | C28: BONOMO | D28: Monteagudo y A.del Valle | E28: Fija | F28: Fibra Optica | G28: 172.20.10.02 | H28: =COUNTIF(K28:AO28,"") -> 31 | I28: =COUNTIF(K28:AL28,"APAGADO") -> 0 | J28: =(H28)/(I28+H28) -> 1
... A39: CENTRO | B39: CEN17 | C39: BONOMO | D39: San Martin y Mitre | E39: Domo | F39: PTO A FO | G39: 172.20.12.200 | H39: =COUNTIF(K39:AO39,"") -> 31 | I39: =COUNTIF(K39:AL39,"APAGADO") -> 0 | J39: =(H39)/(I39+H39) -> 1
A40: CENTRO | B40: CEN18 | C40: BONOMO | D40: Monteagudo e/Mitre y Sallares | E40: Fija | F40: Fibra Optica | G40: 172.20.10.26 | H40: =COUNTIF(K40:AO40,"") -> 27 | I40: =COUNTIF(K40:AL40,"APAGADO") -> 4 | J40: =(H40)/(I40+H40) -> 0.87096774 | K40: APAGADO | M40: APAGADO | N40: APAGADO | O40: APAGADO
A41: CENTRO | B41: CEN19 | C41: BONOMO | D41: Chacabuco y 25 de Mayo | E41: Fija | F41: Fibra Optica | G41: 172.20.10.27 | H41: =COUNTIF(K41:AO41,"") -> 31 | I41: =COUNTIF(K41:AL41,"APAGADO") -> 0 | J41: =(H41)/(I41+H41) -> 1
A42: LOMAS DE MONTEVERDE | B42: CEN20 | C42: BONOMO | D42: Pte. Illia y Las Heras | E42: Domo | F42: Fibra Optica | G42: 172.20.10.33 | H42: =COUNTIF(K42:AO42,"") -> 31 | I42: =COUNTIF(K42:AL42,"APAGADO") -> 0 | J42: =(H42)/(I42+H42) -> 1
A43: CENTRO | B43: CEN21 | C43: BONOMO | D43: Misiones y Urquiza | E43: Fija | F43: Radio | G43: 172.20.200.132 | H43: =COUNTIF(K43:AO43,"") -> 30 | I43: =COUNTIF(K43:AL43,"APAGADO") -> 1 | J43: =(H43)/(I43+H43) -> 0.96774194 | T43: APAGADO
A44: CENTRO | B44: CEN22 | C44: BONOMO | D44: Las Heras y Chacabuco | E44: Domo | F44: Radio | G44: 172.20.200.125 | H44: =COUNTIF(K44:AO44,"") -> 31 | I44: =COUNTIF(K44:AL44,"APAGADO") -> 0 | J44: =(H44)/(I44+H44) -> 1
A45: CENTRO | B45: CEN23 | C45: BONOMO | D45: Sallares y Monteagudo | E45: Domo | F45: Fibra Optica | G45: 172.20.12.05 | H45: =COUNTIF(K45:AO45,"") -> 31 | I45: =COUNTIF(K45:AL45,"APAGADO") -> 0 | J45: =(H45)/(I45+H45) -> 1
A46: CENTRO | B46: CEN24 | C46: BONOMO | D46: Sallares y España | E46: Domo | F46: Fibra Optica | G46: 172.20.12.04 | H46: =COUNTIF(K46:AO46,"") -> 31 | I46: =COUNTIF(K46:AL46,"APAGADO") -> 0 | J46: =(H46)/(I46+H46) -> 1
A47: CENTRO | B47: CEN25 | C47: BONOMO | D47: SAN MARTIN Y 9 DE JULIO | E47: Domo | F47: Fibra Optica | G47: 172.20.12.02 | H47: =COUNTIF(K47:AO47,"") -> 31 | I47: =COUNTIF(K47:AL47,"APAGADO") -> 0 | J47: =(H47)/(I47+H47) -> 1
A48: CENTRO | B48: CEN26 | C48: BONOMO | D48: Mitre y España | E48: Domo | F48: Fibra Optica | G48: 172.20.12.06 | H48: =COUNTIF(K48:AO48,"") -> 25 | I48: =COUNTIF(K48:AL48,"APAGADO") -> 6 | J48: =(H48)/(I48+H48) -> 0.80645161 | K48: APAGADO | L48: APAGADO | M48: APAGADO | N48: APAGADO | O48: APAGADO | P48: APAGADO
A49: CENTRO | B49: CEN27 | C49: BONOMO | D49: San Juan y España | E49: Domo | F49: Fibra Optica | G49: 172.20.12.37 | H49: =COUNTIF(K49:AO49,"") -> 31 | I49: =COUNTIF(K49:AL49,"APAGADO") -> 0 | J49: =(H49)/(I49+H49) -> 1
A50: CENTRO | B50: CEN28 | C50: BONOMO | D50: Mitre y Alberdi | E50: Domo | F50: Fibra Optica | G50: 172.20.12.38 | H50: =COUNTIF(K50:AO50,"") -> 31 | I50: =COUNTIF(K50:AL50,"APAGADO") -> 0 | J50: =(H50)/(I50+H50) -> 1
...

Sheet Hoja4
A10: Barrio | B10: [Denominacion] | C10: [Empresa Mantenimiento] | D10: [Ubicacion] | E10: [Tipo de Camara] | F10: [Tipo de Conexion]
A11: CENTRO | B11: CEN 65 | C11: BONOMO | D11: SAN MARTIN Y JUAN PERON | E11: FIJA | F11: Fibra Optica | G11: 172.20.11.135
A12: CENTRO | B12: CEN66 | C12: BONOMO | D12: SAN MARTIN Y JUAN PERON | E12: FIJA | F12: Fibra Optica | G12: 172.20.11.136
A13: CENTRO | B13: CEN 77 | C13: BONOMO | D13: Monteagudo e/ Mitre y Boccuzzi | E13: Fija | F13: Fibra Optica | G13: 172.20.11.241
A14: DON JOSE | B14: DJO 04 (Fija 1) | C14: BONOMO | D14: MONTEVERDE Y EL INDIO | E14: Fija | F14: Radio
A15: DON JOSE | B15: DJO 05 (Fija 2) | C15: BONOMO | D15: MONTEVERDE Y EL INDIO | E15: Fija | F15: Radio
A16: PRESIDENTE SARMIENTO | B16: LRO02 | C16: BONOMO | D16: H. Irigoyen e Islas Orcadas | E16: Domo | F16: FIBRA OPTICA | G16: 172.20.10.40
A17: 9 DE JULIO | B17: NJU09 | C17: BONOMO | D17: PARRILLO Y CONTRERAS | E17: DOMO | F17: Fibra Optica | G17: 172.20.11.190
A18: DON JOSE | B18: PUNTO SEGURO AGUSTIN RAMIREZ INTERCOMUNICADOR | C18: BONOMO | D18: MALAMBO Y LA TRANQUERA | E18: Fija | F18: Fibra Optica
A19: PRESIDENTE SARMIENTO | B19: SAR 02 (fija 1) | C19: BONOMO | D19: DARDO ROCHA Y GABRIELA MISTRAL | E19: Fija | F19: Fibra Optica | G19: 172.20.11.184
A20: PRESIDENTE SARMIENTO | B20: SAR 03 (fija 2) | C20: BONOMO | D20: DARDO ROCHA Y GABRIELA MISTRAL | E20: Fija | F20: Fibra Optica | G20: 172.20.11.185
A21: SAN EDUARDO | B21: SEDU01 | C21: BONOMO | D21: San Martin y Sperandio | E21: Domo | F21: Fibra Optica | G21: 172.20.10.10
A22: VILLA VATTEONE CENTRO | B22: VAT07 | C22: BONOMO | D22: Eva Peron y Lavalle | F22: PTO A FO | G22: 172.20.11.26
A23: VILLA VATTEONE CENTRO | B23: VAT23 (fija 1) | C23: BONOMO | D23: EVA PERON Y "EL TUNEL" (BAJO NIVEL) | E23: Fija | F23: Fibra Optica | G23: 172.20.11.139
A24: VILLA VATTEONE CENTRO | B24: VAT24 (fija 2) | C24: BONOMO | D24: EVA PERON Y "EL TUNEL" (BAJO NIVEL) | E24: Fija | F24: Fibra Optica | G24: 172.20.11.140
A35: CAMARAS SIN FUNCIONAMIENTO DEL DIA 20 DE ENERO DE 2023
A37: RECIBIDO:
A39: EMPRESA: BONOMO SISTEMAS | D39: FIRMA:
D41: ACALARCION:

Sheet ESTADISTICA
A1: ='RESUMEN TOTAL'!A4 -> Barrio | B1: ='RESUMEN TOTAL'!B4 -> [Denominacion] | C1: ='RESUMEN TOTAL'!D4 -> [Ubicacion] | D1: ='RESUMEN TOTAL'!E4 -> [Tipo de Camara] | E1: ='RESUMEN TOTAL'!F4 -> [Tipo de Conexion] | F1: ='RESUMEN TOTAL'!K4 -> 44927 | G1: ='RESUMEN TOTAL'!L4 -> 44928 | H1: ='RESUMEN TOTAL'!M4 -> 44929 | I1: ='RESUMEN TOTAL'!N4 -> 44930 | J1: ='RESUMEN TOTAL'!O4 -> 44931 | K1: ='RESUMEN TOTAL'!P4 -> 44932 | L1: ='RESUMEN TOTAL'!Q4 -> 44933 | M1: ='RESUMEN TOTAL'!R4 -> 44934 | ... AJ1: ='RESUMEN TOTAL'!AO4 -> 44957
A2: ='RESUMEN TOTAL'!A5 -> ALTAMIRA | B2: ='RESUMEN TOTAL'!B5 -> ALT01 | C2: ='RESUMEN TOTAL'!D5 -> Calchaqui y Sgto. Cabral | D2: ='RESUMEN TOTAL'!E5 -> Domo | E2: ='RESUMEN TOTAL'!F5 -> Fibra Optica | F2: ='RESUMEN TOTAL'!K5 -> 0 | G2: ='RESUMEN TOTAL'!L5 -> 0 | H2: ='RESUMEN TOTAL'!M5 -> 0 | I2: ='RESUMEN TOTAL'!N5 -> 0 | J2: ='RESUMEN TOTAL'!O5 -> 0 | K2: ='RESUMEN TOTAL'!P5 -> 0 | L2: ='RESUMEN TOTAL'!Q5 -> 0 | M2: ='RESUMEN TOTAL'!R5 -> 0 | ... AJ2: ='RESUMEN TOTAL'!AO5 -> 0
A3: ='RESUMEN TOTAL'!A6 -> ALTAMIRA | B3: ='RESUMEN TOTAL'!B6 -> ALT02 | C3: ='RESUMEN TOTAL'!D6 -> Calchaqui y Lope de Vega | D3: ='RESUMEN TOTAL'!E6 -> Domo | E3: ='RESUMEN TOTAL'!F6 -> PTO A FO | F3: ='RESUMEN TOTAL'!K6 -> 0 | G3: ='RESUMEN TOTAL'!L6 -> 0 | H3: ='RESUMEN TOTAL'!M6 -> 0 | I3: ='RESUMEN TOTAL'!N6 -> 0 | J3: ='RESUMEN TOTAL'!O6 -> 0 | K3: ='RESUMEN TOTAL'!P6 -> 0 | L3: ='RESUMEN TOTAL'!Q6 -> 0 | M3: ='RESUMEN TOTAL'!R6 -> 0 | ... AJ3: ='RESUMEN TOTAL'!AO6 -> 0
A4: ='RESUMEN TOTAL'!A7 -> ALTAMIRA | B4: ='RESUMEN TOTAL'!B7 -> ALT 03 | C4: ='RESUMEN TOTAL'!D7 -> Bombero Galarza y Necochea | D4: ='RESUMEN TOTAL'!E7 -> Domo | E4: ='RESUMEN TOTAL'!F7 -> FIBRA OPTICA | F4: ='RESUMEN TOTAL'!K7 -> 0 | G4: ='RESUMEN TOTAL'!L7 -> 0 | H4: ='RESUMEN TOTAL'!M7 -> 0 | I4: ='RESUMEN TOTAL'!N7 -> 0 | J4: ='RESUMEN TOTAL'!O7 -> 0 | K4: ='RESUMEN TOTAL'!P7 -> 0 | L4: ='RESUMEN TOTAL'!Q7 -> 0 | M4: ='RESUMEN TOTAL'!R7 -> 0 | ... AJ4: ='RESUMEN TOTAL'!AO7 -> 0
A5: ='RESUMEN TOTAL'!A8 -> ALTAMIRA | B5: ='RESUMEN TOTAL'!B8 -> ALT 04 | C5: ='RESUMEN TOTAL'!D8 -> Francia y Necochea | D5: ='RESUMEN TOTAL'!E8 -> Domo | E5: ='RESUMEN TOTAL'!F8 -> FIBRA OPTICA | F5: ='RESUMEN TOTAL'!K8 -> 0 | G5: ='RESUMEN TOTAL'!L8 -> 0 | H5: ='RESUMEN TOTAL'!M8 -> 0 | I5: ='RESUMEN TOTAL'!N8 -> 0 | J5: ='RESUMEN TOTAL'!O8 -> 0 | K5: ='RESUMEN TOTAL'!P8 -> 0 | L5: ='RESUMEN TOTAL'!Q8 -> 0 | M5: ='RESUMEN TOTAL'!R8 -> 0 | ... AJ5: ='RESUMEN TOTAL'!AO8 -> 0
A6: ='RESUMEN TOTAL'!A9 -> ALTAMIRA | B6: ='RESUMEN TOTAL'!B9 -> ALT05 | C6: ='RESUMEN TOTAL'!D9 -> Av. Calchaqui y Bombero Galarza | D6: ='RESUMEN TOTAL'!E9 -> Domo | E6: ='RESUMEN TOTAL'!F9 -> PTO A FO | F6: ='RESUMEN TOTAL'!K9 -> 0 | G6: ='RESUMEN TOTAL'!L9 -> 0 | H6: ='RESUMEN TOTAL'!M9 -> 0 | I6: ='RESUMEN TOTAL'!N9 -> 0 | J6: ='RESUMEN TOTAL'!O9 -> 0 | K6: ='RESUMEN TOTAL'!P9 -> 0 | L6: ='RESUMEN TOTAL'!Q9 -> 0 | M6: ='RESUMEN TOTAL'!R9 -> 0 | ... AJ6: ='RESUMEN TOTAL'!AO9 -> 0
A7: ='RESUMEN TOTAL'!A10 -> ALTAMIRA | B7: ='RESUMEN TOTAL'!B10 -> ALT 06 | C7: ='RESUMEN TOTAL'!D10 -> LOPE DE VEGA Y NECOCHEA | D7: ='RESUMEN TOTAL'!E10 -> Domo | E7: ='RESUMEN TOTAL'!F10 -> PTO A FO | F7: ='RESUMEN TOTAL'!K10 -> 0 | G7: ='RESUMEN TOTAL'!L10 -> 0 | H7: ='RESUMEN TOTAL'!M10 -> 0 | I7: ='RESUMEN TOTAL'!N10 -> 0 | J7: ='RESUMEN TOTAL'!O10 -> 0 | K7: ='RESUMEN TOTAL'!P10 -> 0 | L7: ='RESUMEN TOTAL'!Q10 -> 0 | M7: ='RESUMEN TOTAL'!R10 -> 0 | ... AJ7: ='RESUMEN TOTAL'!AO10 -> 0
A8: ='RESUMEN TOTAL'!A11 -> ALTAMIRA | B8: ='RESUMEN TOTAL'!B11 -> ALT07 | C8: ='RESUMEN TOTAL'!D11 -> AV. CALCHAQUI Y AV. DEL TRABAJO | D8: ='RESUMEN TOTAL'!E11 -> DOMO | E8: ='RESUMEN TOTAL'!F11 -> PTO A FO | F8: ='RESUMEN TOTAL'!K11 -> 0 | G8: ='RESUMEN TOTAL'!L11 -> 0 | H8: ='RESUMEN TOTAL'!M11 -> 0 | I8: ='RESUMEN TOTAL'!N11 -> 0 | J8: ='RESUMEN TOTAL'!O11 -> 0 | K8: ='RESUMEN TOTAL'!P11 -> 0 | L8: ='RESUMEN TOTAL'!Q11 -> 0 | M8: ='RESUMEN TOTAL'!R11 -> 0 | ... AJ8: ='RESUMEN TOTAL'!AO11 -> 0
A9: ='RESUMEN TOTAL'!A12 -> ALTAMIRA | B9: ='RESUMEN TOTAL'!B12 -> ALT 08 | C9: ='RESUMEN TOTAL'!D12 -> HUMAITA Y NECOCHEA | D9: ='RESUMEN TOTAL'!E12 -> DOMO | E9: ='RESUMEN TOTAL'!F12 -> Fibra Optica | F9: ='RESUMEN TOTAL'!K12 -> 0 | G9: ='RESUMEN TOTAL'!L12 -> 0 | H9: ='RESUMEN TOTAL'!M12 -> 0 | I9: ='RESUMEN TOTAL'!N12 -> 0 | J9: ='RESUMEN TOTAL'!O12 -> 0 | K9: ='RESUMEN TOTAL'!P12 -> 0 | L9: ='RESUMEN TOTAL'!Q12 -> 0 | M9: ='RESUMEN TOTAL'!R12 -> 0 | ... AJ9: ='RESUMEN TOTAL'!AO12 -> 0
A10: ='RESUMEN TOTAL'!A13 -> ALTAMIRA | B10: ='RESUMEN TOTAL'!B13 -> ALT 09 | C10: ='RESUMEN TOTAL'!D13 -> NECOCHEA Y CURUPAITY | D10: ='RESUMEN TOTAL'!E13 -> DOMO | E10: ='RESUMEN TOTAL'!F13 -> Fibra Optica | F10: ='RESUMEN TOTAL'!K13 -> 0 | G10: ='RESUMEN TOTAL'!L13 -> 0 | H10: ='RESUMEN TOTAL'!M13 -> 0 | I10: ='RESUMEN TOTAL'!N13 -> 0 | J10: ='RESUMEN TOTAL'!O13 -> 0 | K10: ='RESUMEN TOTAL'!P13 -> 0 | L10: ='RESUMEN TOTAL'!Q13 -> 0 | M10: ='RESUMEN TOTAL'!R13 -> 0 | ... AJ10: ='RESUMEN TOTAL'!AO13 -> 0
A11: ='RESUMEN TOTAL'!A14 -> ALTAMIRA | B11: ='RESUMEN TOTAL'!B14 -> ALT 10 | C11: ='RESUMEN TOTAL'!D14 -> Calchaqui y Francia | D11: ='RESUMEN TOTAL'!E14 -> Domo | E11: ='RESUMEN TOTAL'!F14 -> Radio | F11: ='RESUMEN TOTAL'!K14 -> 0 | G11: ='RESUMEN TOTAL'!L14 -> 0 | H11: ='RESUMEN TOTAL'!M14 -> 0 | I11: ='RESUMEN TOTAL'!N14 -> 0 | J11: ='RESUMEN TOTAL'!O14 -> 0 | K11: ='RESUMEN TOTAL'!P14 -> 0 | L11: ='RESUMEN TOTAL'!Q14 -> 0 | M11: ='RESUMEN TOTAL'!R14 -> 0 | ... AJ11: ='RESUMEN TOTAL'!AO14 -> 0
A12: ='RESUMEN TOTAL'!A15 -> AGUSTIN RAMIREZ | B12: ='RESUMEN TOTAL'!B15 -> ARA 01 | C12: ='RESUMEN TOTAL'!D15 -> Malambo y Tranquera | D12: ='RESUMEN TOTAL'!E15 -> Domo | E12: ='RESUMEN TOTAL'!F15 -> FIBRA OPTICA | F12: ='RESUMEN TOTAL'!K15 -> 0 | G12: ='RESUMEN TOTAL'!L15 -> 0 | H12: ='RESUMEN TOTAL'!M15 -> 0 | I12: ='RESUMEN TOTAL'!N15 -> 0 | J12: ='RESUMEN TOTAL'!O15 -> 0 | K12: ='RESUMEN TOTAL'!P15 -> 0 | L12: ='RESUMEN TOTAL'!Q15 -> 0 | M12: ='RESUMEN TOTAL'!R15 -> 0 | ... AJ12: ='RESUMEN TOTAL'!AO15 -> 0
... A461: ='RESUMEN TOTAL'!A464 -> 0 | B461: ='RESUMEN TOTAL'!B464 -> 0 | C461: ='RESUMEN TOTAL'!D464 -> 0 | D461: ='RESUMEN TOTAL'!E464 -> 0 | E461: ='RESUMEN TOTAL'!F464 -> 0 | F461: ='RESUMEN TOTAL'!K464 -> 0 | G461: ='RESUMEN TOTAL'!L464 -> 0 | H461: ='RESUMEN TOTAL'!M464 -> 0 | I461: ='RESUMEN TOTAL'!N464 -> 0 | J461: ='RESUMEN TOTAL'!O464 -> 0 | K461: ='RESUMEN TOTAL'!P464 -> 0 | L461: ='RESUMEN TOTAL'!Q464 -> 0 | M461: ='RESUMEN TOTAL'!R464 -> 0 | ... AJ461: ='RESUMEN TOTAL'!AO464 -> 0
A462: ='RESUMEN TOTAL'!A465 -> 0 | B462: ='RESUMEN TOTAL'!B465 -> 0 | F462: ='RESUMEN TOTAL'!K465 -> 0 | G462: ='RESUMEN TOTAL'!L465 -> 0 | H462: ='RESUMEN TOTAL'!M465 -> 0 | I462: ='RESUMEN TOTAL'!N465 -> 0 | J462: ='RESUMEN TOTAL'!O465 -> 0 | K462: ='RESUMEN TOTAL'!P465 -> 0 | L462: ='RESUMEN TOTAL'!Q465 -> 0 | M462: ='RESUMEN TOTAL'!R465 -> 0 | ... AJ462: ='RESUMEN TOTAL'!AO465 -> 0
A463: ='RESUMEN TOTAL'!A466 -> 0 | B463: ='RESUMEN TOTAL'!B466 -> 0 | F463: ='RESUMEN TOTAL'!K466 -> 0 | G463: ='RESUMEN TOTAL'!L466 -> 0 | H463: ='RESUMEN TOTAL'!M466 -> 0 | I463: ='RESUMEN TOTAL'!N466 -> 0 | J463: ='RESUMEN TOTAL'!O466 -> 0 | K463: ='RESUMEN TOTAL'!P466 -> 0 | L463: ='RESUMEN TOTAL'!Q466 -> 0 | M463: ='RESUMEN TOTAL'!R466 -> 0 | ... AJ463: ='RESUMEN TOTAL'!AO466 -> 0
A464: ='RESUMEN TOTAL'!A467 -> 0 | B464: ='RESUMEN TOTAL'!B467 -> 0 | F464: ='RESUMEN TOTAL'!K467 -> 0 | G464: ='RESUMEN TOTAL'!L467 -> 0 | H464: ='RESUMEN TOTAL'!M467 -> 0 | I464: ='RESUMEN TOTAL'!N467 -> 0 | J464: ='RESUMEN TOTAL'!O467 -> 0 | K464: ='RESUMEN TOTAL'!P467 -> 0 | L464: ='RESUMEN TOTAL'!Q467 -> 0 | M464: ='RESUMEN TOTAL'!R467 -> 0 | ... AJ464: ='RESUMEN TOTAL'!AO467 -> 0
A465: ='RESUMEN TOTAL'!A468 -> 0 | B465: ='RESUMEN TOTAL'!B468 -> 0 | F465: ='RESUMEN TOTAL'!K468 -> 0 | G465: ='RESUMEN TOTAL'!L468 -> 0 | H465: ='RESUMEN TOTAL'!M468 -> 0 | I465: ='RESUMEN TOTAL'!N468 -> 0 | J465: ='RESUMEN TOTAL'!O468 -> 0 | K465: ='RESUMEN TOTAL'!P468 -> 0 | L465: ='RESUMEN TOTAL'!Q468 -> 0 | M465: ='RESUMEN TOTAL'!R468 -> 0 | ... AJ465: ='RESUMEN TOTAL'!AO468 -> 0
A466: ='RESUMEN TOTAL'!A469 -> 0 | B466: ='RESUMEN TOTAL'!B469 -> 0 | F466: ='RESUMEN TOTAL'!K469 -> 0 | G466: ='RESUMEN TOTAL'!L469 -> 0 | H466: ='RESUMEN TOTAL'!M469 -> 0 | I466: ='RESUMEN TOTAL'!N469 -> 0 | J466: ='RESUMEN TOTAL'!O469 -> 0 | K466: ='RESUMEN TOTAL'!P469 -> 0 | L466: ='RESUMEN TOTAL'!Q469 -> 0 | M466: ='RESUMEN TOTAL'!R469 -> 0 | ... AJ466: ='RESUMEN TOTAL'!AO469 -> 0
A467: ='RESUMEN TOTAL'!A470 -> 0 | B467: ='RESUMEN TOTAL'!B470 -> 0 | F467: ='RESUMEN TOTAL'!K470 -> 0 | G467: ='RESUMEN TOTAL'!L470 -> 0 | H467: ='RESUMEN TOTAL'!M470 -> 0 | I467: ='RESUMEN TOTAL'!N470 -> 0 | J467: ='RESUMEN TOTAL'!O470 -> 0 | K467: ='RESUMEN TOTAL'!P470 -> 0 | L467: ='RESUMEN TOTAL'!Q470 -> 0 | M467: ='RESUMEN TOTAL'!R470 -> 0 | ... AJ467: ='RESUMEN TOTAL'!AO470 -> 0
A468: ='RESUMEN TOTAL'!A471 -> 0 | B468: ='RESUMEN TOTAL'!B471 -> 0 | F468: ='RESUMEN TOTAL'!K471 -> 0 | G468: ='RESUMEN TOTAL'!L471 -> 0 | H468: ='RESUMEN TOTAL'!M471 -> 0 | I468: ='RESUMEN TOTAL'!N471 -> 0 | J468: ='RESUMEN TOTAL'!O471 -> 0 | K468: ='RESUMEN TOTAL'!P471 -> 0 | L468: ='RESUMEN TOTAL'!Q471 -> 0 | M468: ='RESUMEN TOTAL'!R471 -> 0 | ... AJ468: ='RESUMEN TOTAL'!AO471 -> 0
A469: ='RESUMEN TOTAL'!A472 -> 0 | B469: ='RESUMEN TOTAL'!B472 -> 0 | F469: ='RESUMEN TOTAL'!K472 -> 0 | G469: ='RESUMEN TOTAL'!L472 -> 0 | H469: ='RESUMEN TOTAL'!M472 -> 0 | I469: ='RESUMEN TOTAL'!N472 -> 0 | J469: ='RESUMEN TOTAL'!O472 -> 0 | K469: ='RESUMEN TOTAL'!P472 -> 0 | L469: ='RESUMEN TOTAL'!Q472 -> 0 | M469: ='RESUMEN TOTAL'!R472 -> 0 | ... AJ469: ='RESUMEN TOTAL'!AO472 -> 0
F470: ='RESUMEN TOTAL'!K473 -> 0 | G470: ='RESUMEN TOTAL'!L473 -> 0 | H470: ='RESUMEN TOTAL'!M473 -> 0 | I470: ='RESUMEN TOTAL'!N473 -> 0 | J470: ='RESUMEN TOTAL'!O473 -> 0 | K470: ='RESUMEN TOTAL'!P473 -> 0 | L470: ='RESUMEN TOTAL'!Q473 -> 0 | M470: ='RESUMEN TOTAL'!R473 -> 0 | ... AJ470: ='RESUMEN TOTAL'!AO473 -> 0
F471: ='RESUMEN TOTAL'!K474 -> 0 | G471: ='RESUMEN TOTAL'!L474 -> 0 | H471: ='RESUMEN TOTAL'!M474 -> 0 | I471: ='RESUMEN TOTAL'!N474 -> 0 | J471: ='RESUMEN TOTAL'!O474 -> 0 | K471: ='RESUMEN TOTAL'!P474 -> 0 | L471: ='RESUMEN TOTAL'!Q474 -> 0 | M471: ='RESUMEN TOTAL'!R474 -> 0 | ... AJ471: ='RESUMEN TOTAL'!AO474 -> 0
F472: ='RESUMEN TOTAL'!K475 -> 0 | G472: ='RESUMEN TOTAL'!L475 -> 0 | H472: ='RESUMEN TOTAL'!M475 -> 0 | I472: ='RESUMEN TOTAL'!N475 -> 0 | J472: ='RESUMEN TOTAL'!O475 -> 0 | K472: ='RESUMEN TOTAL'!P475 -> 0 | L472: ='RESUMEN TOTAL'!Q475 -> 0 | M472: ='RESUMEN TOTAL'!R475 -> 0 | ... AJ472: ='RESUMEN TOTAL'!AO475 -> 0
F473: ='RESUMEN TOTAL'!K476 -> 0 | G473: ='RESUMEN TOTAL'!L476 -> 0 | H473: ='RESUMEN TOTAL'!M476 -> 0 | I473: ='RESUMEN TOTAL'!N476 -> 0 | J473: ='RESUMEN TOTAL'!O476 -> 0 | K473: ='RESUMEN TOTAL'!P476 -> 0 | L473: ='RESUMEN TOTAL'!Q476 -> 0 | M473: ='RESUMEN TOTAL'!R476 -> 0 | ... AJ473: ='RESUMEN TOTAL'!AO476 -> 0
F474: ='RESUMEN TOTAL'!K477 -> 0 | G474: ='RESUMEN TOTAL'!L477 -> 0 | H474: ='RESUMEN TOTAL'!M477 -> 0 | I474: ='RESUMEN TOTAL'!N477 -> 0 | J474: ='RESUMEN TOTAL'!O477 -> 0 | K474: ='RESUMEN TOTAL'!P477 -> 0 | L474: ='RESUMEN TOTAL'!Q477 -> 0 | M474: ='RESUMEN TOTAL'!R477 -> 0 | ... AJ474: ='RESUMEN TOTAL'!AO477 -> 0
F475: ='RESUMEN TOTAL'!K478 -> 0 | G475: ='RESUMEN TOTAL'!L478 -> 0 | H475: ='RESUMEN TOTAL'!M478 -> 0 | I475: ='RESUMEN TOTAL'!N478 -> 0 | J475: ='RESUMEN TOTAL'!O478 -> 0 | K475: ='RESUMEN TOTAL'!P478 -> 0 | L475: ='RESUMEN TOTAL'!Q478 -> 0 | M475: ='RESUMEN TOTAL'!R478 -> 0 | ... AJ475: ='RESUMEN TOTAL'!AO478 -> 0
F476: ='RESUMEN TOTAL'!K479 -> 0 | G476: ='RESUMEN TOTAL'!L479 -> 0 | H476: ='RESUMEN TOTAL'!M479 -> 0 | I476: ='RESUMEN TOTAL'!N479 -> 0 | J476: ='RESUMEN TOTAL'!O479 -> 0 | K476: ='RESUMEN TOTAL'!P479 -> 0 | L476: ='RESUMEN TOTAL'!Q479 -> 0 | M476: ='RESUMEN TOTAL'!R479 -> 0 | ... AJ476: ='RESUMEN TOTAL'!AO479 -> 0
F477: ='RESUMEN TOTAL'!K480 -> 0 | G477: ='RESUMEN TOTAL'!L480 -> 0 | H477: ='RESUMEN TOTAL'!M480 -> 0 | I477: ='RESUMEN TOTAL'!N480 -> 0 | J477: ='RESUMEN TOTAL'!O480 -> 0 | K477: ='RESUMEN TOTAL'!P480 -> 0 | L477: ='RESUMEN TOTAL'!Q480 -> 0 | M477: ='RESUMEN TOTAL'!R480 -> 0 | ... AJ477: ='RESUMEN TOTAL'!AO480 -> 0
F478: ='RESUMEN TOTAL'!K481 -> 0 | G478: ='RESUMEN TOTAL'!L481 -> 0 | H478: ='RESUMEN TOTAL'!M481 -> 0 | I478: ='RESUMEN TOTAL'!N481 -> 0 | J478: ='RESUMEN TOTAL'!O481 -> 0 | K478: ='RESUMEN TOTAL'!P481 -> 0 | L478: ='RESUMEN TOTAL'!Q481 -> 0 | M478: ='RESUMEN TOTAL'!R481 -> 0 | ... AJ478: ='RESUMEN TOTAL'!AO481 -> 0
F479: ='RESUMEN TOTAL'!K482 -> 0 | G479: ='RESUMEN TOTAL'!L482 -> 0 | H479: ='RESUMEN TOTAL'!M482 -> 0 | I479: ='RESUMEN TOTAL'!N482 -> 0 | J479: ='RESUMEN TOTAL'!O482 -> 0 | K479: ='RESUMEN TOTAL'!P482 -> 0 | L479: ='RESUMEN TOTAL'!Q482 -> 0 | M479: ='RESUMEN TOTAL'!R482 -> 0 | ... AJ479: ='RESUMEN TOTAL'!AO482 -> 0
F480: ='RESUMEN TOTAL'!K483 -> 0 | G480: ='RESUMEN TOTAL'!L483 -> 0 | H480: ='RESUMEN TOTAL'!M483 -> 0 | I480: ='RESUMEN TOTAL'!N483 -> 0 | J480: ='RESUMEN TOTAL'!O483 -> 0 | K480: ='RESUMEN TOTAL'!P483 -> 0 | L480: ='RESUMEN TOTAL'!Q483 -> 0 | M480: ='RESUMEN TOTAL'!R483 -> 0 | ... AJ480: ='RESUMEN TOTAL'!AO483 -> 0
F481: ='RESUMEN TOTAL'!K484 -> 0 | G481: ='RESUMEN TOTAL'!L484 -> 0 | H481: ='RESUMEN TOTAL'!M484 -> 0 | I481: ='RESUMEN TOTAL'!N484 -> 0 | J481: ='RESUMEN TOTAL'!O484 -> 0 | K481: ='RESUMEN TOTAL'!P484 -> 0 | L481: ='RESUMEN TOTAL'!Q484 -> 0 | M481: ='RESUMEN TOTAL'!R484 -> 0 | ... AJ481: ='RESUMEN TOTAL'!AO484 -> 0
... F634: ='RESUMEN TOTAL'!K637 -> 0 | G634: ='RESUMEN TOTAL'!L637 -> 0 | H634: ='RESUMEN TOTAL'!M637 -> 0 | I634: ='RESUMEN TOTAL'!N637 -> 0 | J634: ='RESUMEN TOTAL'!O637 -> 0 | K634: ='RESUMEN TOTAL'!P637 -> 0 | L634: ='RESUMEN TOTAL'!Q637 -> 0 | M634: ='RESUMEN TOTAL'!R637 -> 0 | ... AJ634: ='RESUMEN TOTAL'!AO637 -> 0

Sheet APAGADOS
E1: APAGADOS | F1: =COUNTIF(F3:F400, "APAGADO") -> 36 | G1: =COUNTIF(G3:G400, "APAGADO") -> 23 | H1: =COUNTIF(H3:H500, "APAGADO") -> 38 | I1: =COUNTIF(I3:I400, "APAGADO") -> 46 | J1: =COUNTIF(J3:J400, "APAGADO") -> 25 | K1: =COUNTIF(K3:K400, "APAGADO") -> 36 | L1: =COUNTIF(L3:L400, "APAGADO") -> 22 | M1: =COUNTIF(M3:M400, "APAGADO") -> 28 | N1: =COUNTIF(N3:N400, "APAGADO") -> 21 | O1: =COUNTIF(O3:O400, "APAGADO") -> 21 | P1: =COUNTIF(P3:P400, "APAGADO") -> 18 | ... AD1: =COUNTIF(AD3:AD400, "APAGADO") -> 0 | AE1: =COUNTIF(AE3:AE500, "APAGADO") -> 0 | AF1: =COUNTIF(AF3:AF400, "APAGADO") -> 0 | AG1: =COUNTIF(AG3:AG400, "APAGADO") -> 0 | AH1: =COUNTIF(AH3:AH400, "APAGADO") -> 0 | AI1: =COUNTIF(AI3:AI400, "APAGADO") -> 0
A2: =ESTADISTICA!A1 -> Barrio | B2: =ESTADISTICA!B1 -> [Denominacion] | C2: =ESTADISTICA!C1 -> [Ubicacion] | D2: =ESTADISTICA!D1 -> [Tipo de Camara] | E2: =ESTADISTICA!E1 -> [Tipo de Conexion] | F2: =ESTADISTICA!F1 -> 44927 | G2: =ESTADISTICA!G1 -> 44928 | H2: =ESTADISTICA!H1 -> 44929 | ... AI2: =ESTADISTICA!AI1 -> 44956
A3: =ESTADISTICA!A2 -> ALTAMIRA | B3: =ESTADISTICA!B2 -> ALT01 | C3: =ESTADISTICA!C2 -> Calchaqui y Sgto. Cabral | D3: =ESTADISTICA!D2 -> Domo | E3: =ESTADISTICA!E2 -> Fibra Optica | F3: =ESTADISTICA!F2 -> 0 | G3: =ESTADISTICA!G2 -> 0 | H3: =ESTADISTICA!H2 -> 0 | ... AI3: =ESTADISTICA!AI2 -> 0
A4: =ESTADISTICA!A3 -> ALTAMIRA | B4: =ESTADISTICA!B3 -> ALT02 | C4: =ESTADISTICA!C3 -> Calchaqui y Lope de Vega | D4: =ESTADISTICA!D3 -> Domo | E4: =ESTADISTICA!E3 -> PTO A FO | F4: =ESTADISTICA!F3 -> 0 | G4: =ESTADISTICA!G3 -> 0 | H4: =ESTADISTICA!H3 -> 0 | ... AI4: =ESTADISTICA!AI3 -> 0
A5: =ESTADISTICA!A4 -> ALTAMIRA | B5: =ESTADISTICA!B4 -> ALT 03 | C5: =ESTADISTICA!C4 -> Bombero Galarza y Necochea | D5: =ESTADISTICA!D4 -> Domo | E5: =ESTADISTICA!E4 -> FIBRA OPTICA | F5: =ESTADISTICA!F4 -> 0 | G5: =ESTADISTICA!G4 -> 0 | H5: =ESTADISTICA!H4 -> 0 | ... AI5: =ESTADISTICA!AI4 -> 0
A6: =ESTADISTICA!A5 -> ALTAMIRA | B6: =ESTADISTICA!B5 -> ALT 04 | C6: =ESTADISTICA!C5 -> Francia y Necochea | D6: =ESTADISTICA!D5 -> Domo | E6: =ESTADISTICA!E5 -> FIBRA OPTICA | F6: =ESTADISTICA!F5 -> 0 | G6: =ESTADISTICA!G5 -> 0 | H6: =ESTADISTICA!H5 -> 0 | ... AI6: =ESTADISTICA!AI5 -> 0
A7: =ESTADISTICA!A6 -> ALTAMIRA | B7: =ESTADISTICA!B6 -> ALT05 | C7: =ESTADISTICA!C6 -> Av. Calchaqui y Bombero Galarza | D7: =ESTADISTICA!D6 -> Domo | E7: =ESTADISTICA!E6 -> PTO A FO | F7: =ESTADISTICA!F6 -> 0 | G7: =ESTADISTICA!G6 -> 0 | H7: =ESTADISTICA!H6 -> 0 | ... AI7: =ESTADISTICA!AI6 -> 0
A8: =ESTADISTICA!A7 -> ALTAMIRA | B8: =ESTADISTICA!B7 -> ALT 06 | C8: =ESTADISTICA!C7 -> LOPE DE VEGA Y NECOCHEA | D8: =ESTADISTICA!D7 -> Domo | E8: =ESTADISTICA!E7 -> PTO A FO | F8: =ESTADISTICA!F7 -> 0 | G8: =ESTADISTICA!G7 -> 0 | H8: =ESTADISTICA!H7 -> 0 | ... AI8: =ESTADISTICA!AI7 -> 0
A9: =ESTADISTICA!A8 -> ALTAMIRA | B9: =ESTADISTICA!B8 -> ALT07 | C9: =ESTADISTICA!C8 -> AV. CALCHAQUI Y AV. DEL TRABAJO | D9: =ESTADISTICA!D8 -> DOMO | E9: =ESTADISTICA!E8 -> PTO A FO | F9: =ESTADISTICA!F8 -> 0 | G9: =ESTADISTICA!G8 -> 0 | H9: =ESTADISTICA!H8 -> 0 | ... AI9: =ESTADISTICA!AI8 -> 0
A10: =ESTADISTICA!A9 -> ALTAMIRA | B10: =ESTADISTICA!B9 -> ALT 08 | C10: =ESTADISTICA!C9 -> HUMAITA Y NECOCHEA | D10: =ESTADISTICA!D9 -> DOMO | E10: =ESTADISTICA!E9 -> Fibra Optica | F10: =ESTADISTICA!F9 -> 0 | G10: =ESTADISTICA!G9 -> 0 | H10: =ESTADISTICA!H9 -> 0 | ... AI10: =ESTADISTICA!AI9 -> 0
A11: =ESTADISTICA!A10 -> ALTAMIRA | B11: =ESTADISTICA!B10 -> ALT 09 | C11: =ESTADISTICA!C10 -> NECOCHEA Y CURUPAITY | D11: =ESTADISTICA!D10 -> DOMO | E11: =ESTADISTICA!E10 -> Fibra Optica | F11: =ESTADISTICA!F10 -> 0 | G11: =ESTADISTICA!G10 -> 0 | H11: =ESTADISTICA!H10 -> 0 | ... AI11: =ESTADISTICA!AI10 -> 0
A12: =ESTADISTICA!A11 -> ALTAMIRA | B12: =ESTADISTICA!B11 -> ALT 10 | C12: =ESTADISTICA!C11 -> Calchaqui y Francia | D12: =ESTADISTICA!D11 -> Domo | E12: =ESTADISTICA!E11 -> Radio | F12: =ESTADISTICA!F11 -> 0 | G12: =ESTADISTICA!G11 -> 0 | H12: =ESTADISTICA!H11 -> 0 | ... AI12: =ESTADISTICA!AI11 -> 0
A13: =ESTADISTICA!A12 -> AGUSTIN RAMIREZ | B13: =ESTADISTICA!B12 -> ARA 01 | C13: =ESTADISTICA!C12 -> Malambo y Tranquera | D13: =ESTADISTICA!D12 -> Domo | E13: =ESTADISTICA!E12 -> FIBRA OPTICA | F13: =ESTADISTICA!F12 -> 0 | G13: =ESTADISTICA!G12 -> 0 | H13: =ESTADISTICA!H12 -> 0 | ... AI13: =ESTADISTICA!AI12 -> 0
... A513: =ESTADISTICA!A512 -> 0 | B513: =ESTADISTICA!B512 -> 0 | C513: =ESTADISTICA!C512 -> 0 | D513: =ESTADISTICA!D512 -> 0 | E513: =ESTADISTICA!E512 -> 0 | F513: =ESTADISTICA!F512 -> 0 | G513: =ESTADISTICA!G512 -> 0 | H513: =ESTADISTICA!H512 -> 0 | ... AI513: =ESTADISTICA!AI512 -> 0

Sheet APAGADOS FIBRA
C1: TOTAL FIBRA | D1: =COUNTIFS(E4:E400,"=Fibra Optica") -> 267
E2: APAGADOS | F2: =COUNTIFS(F4:F500, "=APAGADO",E4:E500,"=Fibra Optica") -> 28 | G2: =COUNTIFS(G4:G500, "=APAGADO",E4:E500,"=Fibra Optica") -> 20 | H2: =COUNTIFS(H4:H500, "=APAGADO",E4:E500,"=Fibra Optica") -> 29 | I2: =COUNTIFS(I4:I500, "=APAGADO",E4:E500,"=Fibra Optica") -> 39 | J2: =COUNTIFS(J4:J500, "=APAGADO",E4:E500,"=Fibra Optica") -> 17 | K2: =COUNTIFS(K4:K500, "=APAGADO",E4:E500,"=Fibra Optica") -> 29 | L2: =COUNTIFS(L4:L500, "=APAGADO",E4:E500,"=Fibra Optica") -> 13 | M2: =COUNTIFS(M4:M500, "=APAGADO",E4:E500,"=Fibra Optica") -> 17 | N2: =COUNTIFS(N4:N500, "=APAGADO",E4:E500,"=Fibra Optica") -> 14 | O2: =COUNTIFS(O4:O500, "=APAGADO",E4:E500,"=Fibra Optica") -> 14 | P2: =COUNTIFS(P4:P500, "=APAGADO",E4:E500,"=Fibra Optica") -> 12 | Q2: =COUNTIFS(Q4:Q500, "=APAGADO",E4:E500,"=Fibra Optica") -> 7 | R2: =COUNTIFS(R4:R500, "=APAGADO",E4:E500,"=Fibra Optica") -> 7 | S2: =COUNTIFS(S4:S500, "=APAGADO",E4:E500,"=Fibra Optica") -> 10 | T2: =COUNTIFS(T4:T500, "=APAGADO",E4:E500,"=Fibra Optica") -> 19 | U2: =COUNTIFS(U4:U500, "=APAGADO",E4:E500,"=Fibra Optica") -> 21 | V2: =COUNTIFS(V4:V500, "=APAGADO",E4:E500,"=Fibra Optica") -> 20 | W2: =COUNTIFS(W4:W500, "=APAGADO",E4:E500,"=Fibra Optica") -> 16 | X2: =COUNTIFS(X4:X500, "=APAGADO",E4:E500,"=Fibra Optica") -> 21 | Y2: =COUNTIFS(Y4:Y500, "=APAGADO",E4:E500,"=Fibra Optica") -> 21 | Z2: =COUNTIFS(Z4:Z500, "=APAGADO",E4:E500,"=Fibra Optica") -> 0 | AA2: =COUNTIFS(AA4:AA500, "=APAGADO",E4:E500,"=Fibra Optica") -> 0 | AB2: =COUNTIFS(AB4:AB500, "=APAGADO",E4:E500,"=Fibra Optica") -> 0 | AC2: =COUNTIFS(AC4:AC500, "=APAGADO",E4:E500,"=Fibra Optica") -> 0 | AD2: =COUNTIFS(AD4:AD500, "=APAGADO",E4:E500,"=Fibra Optica") -> 0 | AE2: =COUNTIFS(AE4:AE500, "=APAGADO",E4:E500,"=Fibra Optica") -> 0 | AF2: =COUNTIFS(AF4:AF500, "=APAGADO",E4:E500,"=Fibra Optica") -> 0 | AG2: =COUNTIFS(AG4:AG500, "=APAGADO",E4:E500,"=Fibra Optica") -> 0 | AH2: =COUNTIFS(AH4:AH500, "=APAGADO",E4:E500,"=Fibra Optica") -> 0 | AI2: =COUNTIFS(AI4:AI400, "=APAGADO",E4:E400,"=Fibra Optica") -> 0
A3: =ESTADISTICA!A1 -> Barrio | B3: =ESTADISTICA!B1 -> [Denominacion] | C3: =ESTADISTICA!C1 -> [Ubicacion] | D3: =ESTADISTICA!D1 -> [Tipo de Camara] | E3: =ESTADISTICA!E1 -> [Tipo de Conexion] | F3: =ESTADISTICA!F1 -> 44927 | G3: =ESTADISTICA!G1 -> 44928 | H3: =ESTADISTICA!H1 -> 44929 | ... AI3: =ESTADISTICA!AI1 -> 44956
A4: =ESTADISTICA!A2 -> ALTAMIRA | B4: =ESTADISTICA!B2 -> ALT01 | C4: =ESTADISTICA!C2 -> Calchaqui y Sgto. Cabral | D4: =ESTADISTICA!D2 -> Domo | E4: =ESTADISTICA!E2 -> Fibra Optica | F4: =ESTADISTICA!F2 -> 0 | G4: =ESTADISTICA!G2 -> 0 | H4: =ESTADISTICA!H2 -> 0 | ... AI4: =ESTADISTICA!AI2 -> 0
A5: =ESTADISTICA!A3 -> ALTAMIRA | B5: =ESTADISTICA!B3 -> ALT02 | C5: =ESTADISTICA!C3 -> Calchaqui y Lope de Vega | D5: =ESTADISTICA!D3 -> Domo | E5: =ESTADISTICA!E3 -> PTO A FO | F5: =ESTADISTICA!F3 -> 0 | G5: =ESTADISTICA!G3 -> 0 | H5: =ESTADISTICA!H3 -> 0 | ... AI5: =ESTADISTICA!AI3 -> 0
A6: =ESTADISTICA!A4 -> ALTAMIRA | B6: =ESTADISTICA!B4 -> ALT 03 | C6: =ESTADISTICA!C4 -> Bombero Galarza y Necochea | D6: =ESTADISTICA!D4 -> Domo | E6: =ESTADISTICA!E4 -> FIBRA OPTICA | F6: =ESTADISTICA!F4 -> 0 | G6: =ESTADISTICA!G4 -> 0 | H6: =ESTADISTICA!H4 -> 0 | ... AI6: =ESTADISTICA!AI4 -> 0
A7: =ESTADISTICA!A5 -> ALTAMIRA | B7: =ESTADISTICA!B5 -> ALT 04 | C7: =ESTADISTICA!C5 -> Francia y Necochea | D7: =ESTADISTICA!D5 -> Domo | E7: =ESTADISTICA!E5 -> FIBRA OPTICA | F7: =ESTADISTICA!F5 -> 0 | G7: =ESTADISTICA!G5 -> 0 | H7: =ESTADISTICA!H5 -> 0 | ... AI7: =ESTADISTICA!AI5 -> 0
A8: =ESTADISTICA!A6 -> ALTAMIRA | B8: =ESTADISTICA!B6 -> ALT05 | C8: =ESTADISTICA!C6 -> Av. Calchaqui y Bombero Galarza | D8: =ESTADISTICA!D6 -> Domo | E8: =ESTADISTICA!E6 -> PTO A FO | F8: =ESTADISTICA!F6 -> 0 | G8: =ESTADISTICA!G6 -> 0 | H8: =ESTADISTICA!H6 -> 0 | ... AI8: =ESTADISTICA!AI6 -> 0
A9: =ESTADISTICA!A7 -> ALTAMIRA | B9: =ESTADISTICA!B7 -> ALT 06 | C9: =ESTADISTICA!C7 -> LOPE DE VEGA Y NECOCHEA | D9: =ESTADISTICA!D7 -> Domo | E9: =ESTADISTICA!E7 -> PTO A FO | F9: =ESTADISTICA!F7 -> 0 | G9: =ESTADISTICA!G7 -> 0 | H9: =ESTADISTICA!H7 -> 0 | ... AI9: =ESTADISTICA!AI7 -> 0
A10: =ESTADISTICA!A8 -> ALTAMIRA | B10: =ESTADISTICA!B8 -> ALT07 | C10: =ESTADISTICA!C8 -> AV. CALCHAQUI Y AV. DEL TRABAJO | D10: =ESTADISTICA!D8 -> DOMO | E10: =ESTADISTICA!E8 -> PTO A FO | F10: =ESTADISTICA!F8 -> 0 | G10: =ESTADISTICA!G8 -> 0 | H10: =ESTADISTICA!H8 -> 0 | ... AI10: =ESTADISTICA!AI8 -> 0
A11: =ESTADISTICA!A9 -> ALTAMIRA | B11: =ESTADISTICA!B9 -> ALT 08 | C11: =ESTADISTICA!C9 -> HUMAITA Y NECOCHEA | D11: =ESTADISTICA!D9 -> DOMO | E11: =ESTADISTICA!E9 -> Fibra Optica | F11: =ESTADISTICA!F9 -> 0 | G11: =ESTADISTICA!G9 -> 0 | H11: =ESTADISTICA!H9 -> 0 | ... AI11: =ESTADISTICA!AI9 -> 0
A12: =ESTADISTICA!A10 -> ALTAMIRA | B12: =ESTADISTICA!B10 -> ALT 09 | C12: =ESTADISTICA!C10 -> NECOCHEA Y CURUPAITY | D12: =ESTADISTICA!D10 -> DOMO | E12: =ESTADISTICA!E10 -> Fibra Optica | F12: =ESTADISTICA!F10 -> 0 | G12: =ESTADISTICA!G10 -> 0 | H12: =ESTADISTICA!H10 -> 0 | ... AI12: =ESTADISTICA!AI10 -> 0
A13: =ESTADISTICA!A11 -> ALTAMIRA | B13: =ESTADISTICA!B11 -> ALT 10 | C13: =ESTADISTICA!C11 -> Calchaqui y Francia | D13: =ESTADISTICA!D11 -> Domo | E13: =ESTADISTICA!E11 -> Radio | F13: =ESTADISTICA!F11 -> 0 | G13: =ESTADISTICA!G11 -> 0 | H13: =ESTADISTICA!H11 -> 0 | ... AI13: =ESTADISTICA!AI11 -> 0
A14: =ESTADISTICA!A12 -> AGUSTIN RAMIREZ | B14: =ESTADISTICA!B12 -> ARA 01 | C14: =ESTADISTICA!C12 -> Malambo y Tranquera | D14: =ESTADISTICA!D12 -> Domo | E14: =ESTADISTICA!E12 -> FIBRA OPTICA | F14: =ESTADISTICA!F12 -> 0 | G14: =ESTADISTICA!G12 -> 0 | H14: =ESTADISTICA!H12 -> 0 | ... AI14: =ESTADISTICA!AI12 -> 0
... A601: =ESTADISTICA!A599 -> 0 | B601: =ESTADISTICA!B599 -> 0 | C601: =ESTADISTICA!C599 -> 0 | D601: =ESTADISTICA!D599 -> 0 | E601: =ESTADISTICA!E599 -> 0 | F601: =ESTADISTICA!F599 -> 0 | G601: =ESTADISTICA!G599 -> 0 | H601: =ESTADISTICA!H599 -> 0 | ... AI601: =ESTADISTICA!AI599 -> 0

Sheet APAGADOS ANTENA
C1: TOTAL PTO A FO
E2: APAGADOS | F2: =COUNTIFS(F4:F500, "=APAGADO",E4:E500,"=PTO A FO") -> 3 | G2: =COUNTIFS(G4:G500, "=APAGADO",E4:E500,"=PTO A FO") -> 0 | H2: =COUNTIFS(H4:H500, "=APAGADO",E4:E500,"=PTO A FO") -> 1 | I2: =COUNTIFS(I4:I500, "=APAGADO",E4:E500,"=PTO A FO") -> 0 | J2: =COUNTIFS(J4:J500, "=APAGADO",E4:E500,"=PTO A FO") -> 0 | K2: =COUNTIFS(K4:K500, "=APAGADO",E4:E500,"=PTO A FO") -> 1 | L2: =COUNTIFS(L4:L500, "=APAGADO",E4:E500,"=PTO A FO") -> 2 | M2: =COUNTIFS(M4:M500, "=APAGADO",E4:E500,"=PTO A FO") -> 2 | N2: =COUNTIFS(N4:N500, "=APAGADO",E4:E500,"=PTO A FO") -> 1 | O2: =COUNTIFS(O4:O500, "=APAGADO",E4:E500,"=PTO A FO") -> 2 | P2: =COUNTIFS(P4:P500, "=APAGADO",E4:E500,"=PTO A FO") -> 1 | Q2: =COUNTIFS(Q4:Q500, "=APAGADO",E4:E500,"=PTO A FO") -> 0 | R2: =COUNTIFS(R4:R500, "=APAGADO",E4:E500,"=PTO A FO") -> 1 | S2: =COUNTIFS(S4:S500, "=APAGADO",E4:E500,"=PTO A FO") -> 0 | T2: =COUNTIFS(T4:T500, "=APAGADO",E4:E500,"=PTO A FO") -> 3 | U2: =COUNTIFS(U4:U500, "=APAGADO",E4:E500,"=PTO A FO") -> 1 | V2: =COUNTIFS(V4:V500, "=APAGADO",E4:E500,"=PTO A FO") -> 0 | W2: =COUNTIFS(W4:W500, "=APAGADO",E4:E500,"=PTO A FO") -> 1 | X2: =COUNTIFS(X4:X500, "=APAGADO",E4:E500,"=PTO A FO") -> 2 | Y2: =COUNTIFS(Y4:Y500, "=APAGADO",E4:E500,"=PTO A FO") -> 1 | Z2: =COUNTIFS(Z4:Z500, "=APAGADO",E4:E500,"=PTO A FO") -> 0 | AA2: =COUNTIFS(AA4:AA500, "=APAGADO",E4:E500,"=PTO A FO") -> 0 | AB2: =COUNTIFS(AB4:AB500, "=APAGADO",E4:E500,"=PTO A FO") -> 0 | AC2: =COUNTIFS(AC4:AC500, "=APAGADO",E4:E500,"=PTO A FO") -> 0 | AD2: =COUNTIFS(AD4:AD500, "=APAGADO",E4:E500,"=PTO A FO") -> 0 | AE2: =COUNTIFS(AE4:AE500, "=APAGADO",E4:E500,"=PTO A FO") -> 0 | AF2: =COUNTIFS(AF4:AF500, "=APAGADO",E4:E500,"=PTO A FO") -> 0 | AG2: =COUNTIFS(AG4:AG500, "=APAGADO",E4:E500,"=PTO A FO") -> 0 | AH2: =COUNTIFS(AH4:AH500, "=APAGADO",E4:E500,"=PTO A FO") -> 0 | AI2: =COUNTIFS(AI4:AI500, "=APAGADO",E4:E500,"=PTO A FO") -> 0
A3: =ESTADISTICA!A1 -> Barrio | B3: =ESTADISTICA!B1 -> [Denominacion] | C3: =ESTADISTICA!C1 -> [Ubicacion] | D3: =ESTADISTICA!D1 -> [Tipo de Camara] | E3: =ESTADISTICA!E1 -> [Tipo de Conexion] | F3: =ESTADISTICA!F1 -> 44927 | G3: =ESTADISTICA!G1 -> 44928 | H3: =ESTADISTICA!H1 -> 44929 | ... AI3: =ESTADISTICA!AI1 -> 44956
A4: =ESTADISTICA!A2 -> ALTAMIRA | B4: =ESTADISTICA!B2 -> ALT01 | C4: =ESTADISTICA!C2 -> Calchaqui y Sgto. Cabral | D4: =ESTADISTICA!D2 -> Domo | E4: =ESTADISTICA!E2 -> Fibra Optica | F4: =ESTADISTICA!F2 -> 0 | G4: =ESTADISTICA!G2 -> 0 | H4: =ESTADISTICA!H2 -> 0 | ... AI4: =ESTADISTICA!AI2 -> 0
A5: =ESTADISTICA!A3 -> ALTAMIRA | B5: =ESTADISTICA!B3 -> ALT02 | C5: =ESTADISTICA!C3 -> Calchaqui y Lope de Vega | D5: =ESTADISTICA!D3 -> Domo | E5: =ESTADISTICA!E3 -> PTO A FO | F5: =ESTADISTICA!F3 -> 0 | G5: =ESTADISTICA!G3 -> 0 | H5: =ESTADISTICA!H3 -> 0 | ... AI5: =ESTADISTICA!AI3 -> 0
A6: =ESTADISTICA!A4 -> ALTAMIRA | B6: =ESTADISTICA!B4 -> ALT 03 | C6: =ESTADISTICA!C4 -> Bombero Galarza y Necochea | D6: =ESTADISTICA!D4 -> Domo | E6: =ESTADISTICA!E4 -> FIBRA OPTICA | F6: =ESTADISTICA!F4 -> 0 | G6: =ESTADISTICA!G4 -> 0 | H6: =ESTADISTICA!H4 -> 0 | ... AI6: =ESTADISTICA!AI4 -> 0
A7: =ESTADISTICA!A5 -> ALTAMIRA | B7: =ESTADISTICA!B5 -> ALT 04 | C7: =ESTADISTICA!C5 -> Francia y Necochea | D7: =ESTADISTICA!D5 -> Domo | E7: =ESTADISTICA!E5 -> FIBRA OPTICA | F7: =ESTADISTICA!F5 -> 0 | G7: =ESTADISTICA!G5 -> 0 | H7: =ESTADISTICA!H5 -> 0 | ... AI7: =ESTADISTICA!AI5 -> 0
A8: =ESTADISTICA!A6 -> ALTAMIRA | B8: =ESTADISTICA!B6 -> ALT05 | C8: =ESTADISTICA!C6 -> Av. Calchaqui y Bombero Galarza | D8: =ESTADISTICA!D6 -> Domo | E8: =ESTADISTICA!E6 -> PTO A FO | F8: =ESTADISTICA!F6 -> 0 | G8: =ESTADISTICA!G6 -> 0 | H8: =ESTADISTICA!H6 -> 0 | ... AI8: =ESTADISTICA!AI6 -> 0
A9: =ESTADISTICA!A7 -> ALTAMIRA | B9: =ESTADISTICA!B7 -> ALT 06 | C9: =ESTADISTICA!C7 -> LOPE DE VEGA Y NECOCHEA | D9: =ESTADISTICA!D7 -> Domo | E9: =ESTADISTICA!E7 -> PTO A FO | F9: =ESTADISTICA!F7 -> 0 | G9: =ESTADISTICA!G7 -> 0 | H9: =ESTADISTICA!H7 -> 0 | ... AI9: =ESTADISTICA!AI7 -> 0
A10: =ESTADISTICA!A8 -> ALTAMIRA | B10: =ESTADISTICA!B8 -> ALT07 | C10: =ESTADISTICA!C8 -> AV. CALCHAQUI Y AV. DEL TRABAJO | D10: =ESTADISTICA!D8 -> DOMO | E10: =ESTADISTICA!E8 -> PTO A FO | F10: =ESTADISTICA!F8 -> 0 | G10: =ESTADISTICA!G8 -> 0 | H10: =ESTADISTICA!H8 -> 0 | ... AI10: =ESTADISTICA!AI8 -> 0
A11: =ESTADISTICA!A9 -> ALTAMIRA | B11: =ESTADISTICA!B9 -> ALT 08 | C11: =ESTADISTICA!C9 -> HUMAITA Y NECOCHEA | D11: =ESTADISTICA!D9 -> DOMO | E11: =ESTADISTICA!E9 -> Fibra Optica | F11: =ESTADISTICA!F9 -> 0 | G11: =ESTADISTICA!G9 -> 0 | H11: =ESTADISTICA!H9 -> 0 | ... AI11: =ESTADISTICA!AI9 -> 0
A12: =ESTADISTICA!A10 -> ALTAMIRA | B12: =ESTADISTICA!B10 -> ALT 09 | C12: =ESTADISTICA!C10 -> NECOCHEA Y CURUPAITY | D12: =ESTADISTICA!D10 -> DOMO | E12: =ESTADISTICA!E10 -> Fibra Optica | F12: =ESTADISTICA!F10 -> 0 | G12: =ESTADISTICA!G10 -> 0 | H12: =ESTADISTICA!H10 -> 0 | ... AI12: =ESTADISTICA!AI10 -> 0
A13: =ESTADISTICA!A11 -> ALTAMIRA | B13: =ESTADISTICA!B11 -> ALT 10 | C13: =ESTADISTICA!C11 -> Calchaqui y Francia | D13: =ESTADISTICA!D11 -> Domo | E13: =ESTADISTICA!E11 -> Radio | F13: =ESTADISTICA!F11 -> 0 | G13: =ESTADISTICA!G11 -> 0 | H13: =ESTADISTICA!H11 -> 0 | ... AI13: =ESTADISTICA!AI11 -> 0
A14: =ESTADISTICA!A12 -> AGUSTIN RAMIREZ | B14: =ESTADISTICA!B12 -> ARA 01 | C14: =ESTADISTICA!C12 -> Malambo y Tranquera | D14: =ESTADISTICA!D12 -> Domo | E14: =ESTADISTICA!E12 -> FIBRA OPTICA | F14: =ESTADISTICA!F12 -> 0 | G14: =ESTADISTICA!G12 -> 0 | H14: =ESTADISTICA!H12 -> 0 | ... AI14: =ESTADISTICA!AI12 -> 0
... A539: =ESTADISTICA!A537 -> 0 | B539: =ESTADISTICA!B537 -> 0 | C539: =ESTADISTICA!C537 -> 0 | D539: =ESTADISTICA!D537 -> 0 | E539: =ESTADISTICA!E537 -> 0 | F539: =ESTADISTICA!F537 -> 0 | G539: =ESTADISTICA!G537 -> 0 | H539: =ESTADISTICA!H537 -> 0 | ... AI539: =ESTADISTICA!AI537 -> 0

Sheet APAGADOS RADIO
C1: TOTAL RADIO | D1: =COUNTIFS(E4:E400,"=radio") -> 94
E2: APAGADOS | F2: =COUNTIFS(F4:F500, "=APAGADO",E4:E500,"=radio") -> 5 | G2: =COUNTIFS(G4:G500, "=APAGADO",E4:E500,"=radio") -> 3 | H2: =COUNTIFS(H4:H500, "=APAGADO",E4:E500,"=radio") -> 8 | I2: =COUNTIFS(I4:I500, "=APAGADO",E4:E500,"=radio") -> 8 | J2: =COUNTIFS(J4:J500, "=APAGADO",E4:E500,"=radio") -> 8 | K2: =COUNTIFS(K4:K500, "=APAGADO",E4:E500,"=radio") -> 6 | L2: =COUNTIFS(L4:L500, "=APAGADO",E4:E500,"=radio") -> 7 | M2: =COUNTIFS(M4:M500, "=APAGADO",E4:E500,"=radio") -> 9 | N2: =COUNTIFS(N4:N500, "=APAGADO",E4:E500,"=radio") -> 6 | O2: =COUNTIFS(O4:O500, "=APAGADO",E4:E500,"=radio") -> 6 | P2: =COUNTIFS(P4:P500, "=APAGADO",E4:E500,"=radio") -> 6 | Q2: =COUNTIFS(Q4:Q367, "=APAGADO",E4:E367,"=radio") -> 6 | R2: =COUNTIFS(R4:R500, "=APAGADO",E4:E500,"=radio") -> 6 | S2: =COUNTIFS(S4:S500, "=APAGADO",E4:E500,"=radio") -> 6 | T2: =COUNTIFS(T4:T500, "=APAGADO",E4:E500,"=radio") -> 7 | U2: =COUNTIFS(U4:U500, "=APAGADO",E4:E500,"=radio") -> 9 | V2: =COUNTIFS(V4:V500, "=APAGADO",E4:E500,"=radio") -> 7 | W2: =COUNTIFS(W4:W500, "=APAGADO",E4:E500,"=radio") -> 8 | X2: =COUNTIFS(X4:X500, "=APAGADO",E4:E500,"=radio") -> 6 | Y2: =COUNTIFS(Y4:Y500, "=APAGADO",E4:E500,"=radio") -> 5 | Z2: =COUNTIFS(Z4:Z500, "=APAGADO",E4:E500,"=radio") -> 0 | AA2: =COUNTIFS(AA4:AA500, "=APAGADO",E4:E500,"=radio") -> 0 | AB2: =COUNTIFS(AB4:AB500, "=APAGADO",E4:E500,"=radio") -> 0 | AC2: =COUNTIFS(AC4:AC500, "=APAGADO",E4:E500,"=radio") -> 0 | AD2: =COUNTIFS(AD4:AD500, "=APAGADO",E4:E500,"=radio") -> 0 | AE2: =COUNTIFS(AE4:AE500, "=APAGADO",E4:E500,"=radio") -> 0 | AF2: =COUNTIFS(AF4:AF500, "=APAGADO",E4:E500,"=radio") -> 0 | AG2: =COUNTIFS(AG4:AG500, "=APAGADO",E4:E500,"=radio") -> 0 | AH2: =COUNTIFS(AH4:AH500, "=APAGADO",E4:E500,"=radio") -> 0 | AI2: =COUNTIFS(AI4:AI500, "=APAGADO",E4:E500,"=radio") -> 0
A3: =ESTADISTICA!A1 -> Barrio | B3: =ESTADISTICA!B1 -> [Denominacion] | C3: =ESTADISTICA!C1 -> [Ubicacion] | D3: =ESTADISTICA!D1 -> [Tipo de Camara] | E3: =ESTADISTICA!E1 -> [Tipo de Conexion] | F3: =ESTADISTICA!F1 -> 44927 | G3: =ESTADISTICA!G1 -> 44928 | H3: =ESTADISTICA!H1 -> 44929 | ... AI3: =ESTADISTICA!AI1 -> 44956
A4: =ESTADISTICA!A2 -> ALTAMIRA | B4: =ESTADISTICA!B2 -> ALT01 | C4: =ESTADISTICA!C2 -> Calchaqui y Sgto. Cabral | D4: =ESTADISTICA!D2 -> Domo | E4: =ESTADISTICA!E2 -> Fibra Optica | F4: =ESTADISTICA!F2 -> 0 | G4: =ESTADISTICA!G2 -> 0 | H4: =ESTADISTICA!H2 -> 0 | ... AI4: =ESTADISTICA!AI2 -> 0
A5: =ESTADISTICA!A3 -> ALTAMIRA | B5: =ESTADISTICA!B3 -> ALT02 | C5: =ESTADISTICA!C3 -> Calchaqui y Lope de Vega | D5: =ESTADISTICA!D3 -> Domo | E5: =ESTADISTICA!E3 -> PTO A FO | F5: =ESTADISTICA!F3 -> 0 | G5: =ESTADISTICA!G3 -> 0 | H5: =ESTADISTICA!H3 -> 0 | ... AI5: =ESTADISTICA!AI3 -> 0
A6: =ESTADISTICA!A4 -> ALTAMIRA | B6: =ESTADISTICA!B4 -> ALT 03 | C6: =ESTADISTICA!C4 -> Bombero Galarza y Necochea | D6: =ESTADISTICA!D4 -> Domo | E6: =ESTADISTICA!E4 -> FIBRA OPTICA | F6: =ESTADISTICA!F4 -> 0 | G6: =ESTADISTICA!G4 -> 0 | H6: =ESTADISTICA!H4 -> 0 | ... AI6: =ESTADISTICA!AI4 -> 0
A7: =ESTADISTICA!A5 -> ALTAMIRA | B7: =ESTADISTICA!B5 -> ALT 04 | C7: =ESTADISTICA!C5 -> Francia y Necochea | D7: =ESTADISTICA!D5 -> Domo | E7: =ESTADISTICA!E5 -> FIBRA OPTICA | F7: =ESTADISTICA!F5 -> 0 | G7: =ESTADISTICA!G5 -> 0 | H7: =ESTADISTICA!H5 -> 0 | ... AI7: =ESTADISTICA!AI5 -> 0
A8: =ESTADISTICA!A6 -> ALTAMIRA | B8: =ESTADISTICA!B6 -> ALT05 | C8: =ESTADISTICA!C6 -> Av. Calchaqui y Bombero Galarza | D8: =ESTADISTICA!D6 -> Domo | E8: =ESTADISTICA!E6 -> PTO A FO | F8: =ESTADISTICA!F6 -> 0 | G8: =ESTADISTICA!G6 -> 0 | H8: =ESTADISTICA!H6 -> 0 | ... AI8: =ESTADISTICA!AI6 -> 0
A9: =ESTADISTICA!A7 -> ALTAMIRA | B9: =ESTADISTICA!B7 -> ALT 06 | C9: =ESTADISTICA!C7 -> LOPE DE VEGA Y NECOCHEA | D9: =ESTADISTICA!D7 -> Domo | E9: =ESTADISTICA!E7 -> PTO A FO | F9: =ESTADISTICA!F7 -> 0 | G9: =ESTADISTICA!G7 -> 0 | H9: =ESTADISTICA!H7 -> 0 | ... AI9: =ESTADISTICA!AI7 -> 0
A10: =ESTADISTICA!A8 -> ALTAMIRA | B10: =ESTADISTICA!B8 -> ALT07 | C10: =ESTADISTICA!C8 -> AV. CALCHAQUI Y AV. DEL TRABAJO | D10: =ESTADISTICA!D8 -> DOMO | E10: =ESTADISTICA!E8 -> PTO A FO | F10: =ESTADISTICA!F8 -> 0 | G10: =ESTADISTICA!G8 -> 0 | H10: =ESTADISTICA!H8 -> 0 | ... AI10: =ESTADISTICA!AI8 -> 0
A11: =ESTADISTICA!A9 -> ALTAMIRA | B11: =ESTADISTICA!B9 -> ALT 08 | C11: =ESTADISTICA!C9 -> HUMAITA Y NECOCHEA | D11: =ESTADISTICA!D9 -> DOMO | E11: =ESTADISTICA!E9 -> Fibra Optica | F11: =ESTADISTICA!F9 -> 0 | G11: =ESTADISTICA!G9 -> 0 | H11: =ESTADISTICA!H9 -> 0 | ... AI11: =ESTADISTICA!AI9 -> 0
A12: =ESTADISTICA!A10 -> ALTAMIRA | B12: =ESTADISTICA!B10 -> ALT 09 | C12: =ESTADISTICA!C10 -> NECOCHEA Y CURUPAITY | D12: =ESTADISTICA!D10 -> DOMO | E12: =ESTADISTICA!E10 -> Fibra Optica | F12: =ESTADISTICA!F10 -> 0 | G12: =ESTADISTICA!G10 -> 0 | H12: =ESTADISTICA!H10 -> 0 | ... AI12: =ESTADISTICA!AI10 -> 0
A13: =ESTADISTICA!A11 -> ALTAMIRA | B13: =ESTADISTICA!B11 -> ALT 10 | C13: =ESTADISTICA!C11 -> Calchaqui y Francia | D13: =ESTADISTICA!D11 -> Domo | E13: =ESTADISTICA!E11 -> Radio | F13: =ESTADISTICA!F11 -> 0 | G13: =ESTADISTICA!G11 -> 0 | H13: =ESTADISTICA!H11 -> 0 | ... AI13: =ESTADISTICA!AI11 -> 0
A14: =ESTADISTICA!A12 -> AGUSTIN RAMIREZ | B14: =ESTADISTICA!B12 -> ARA 01 | C14: =ESTADISTICA!C12 -> Malambo y Tranquera | D14: =ESTADISTICA!D12 -> Domo | E14: =ESTADISTICA!E12 -> FIBRA OPTICA | F14: =ESTADISTICA!F12 -> 0 | G14: =ESTADISTICA!G12 -> 0 | H14: =ESTADISTICA!H12 -> 0 | ... AI14: =ESTADISTICA!AI12 -> 0
... A686: =ESTADISTICA!A684 -> 0 | B686: =ESTADISTICA!B684 -> 0 | C686: =ESTADISTICA!C684 -> 0 | D686: =ESTADISTICA!D684 -> 0 | E686: =ESTADISTICA!E684 -> 0 | F686: =ESTADISTICA!F684 -> 0 | G686: =ESTADISTICA!G684 -> 0 | H686: =ESTADISTICA!H684 -> 0 | ... AI686: =ESTADISTICA!AI684 -> 0

Sheet BARRAS

Sheet PORCENTAJE

Sheet informe
B1: CANTIDAD | D1: %
A2: TOTAL | B2: 436
A3: CAIDAS | B3: 23 | C3: 23 | D3: =C3/B2 -> 0.052752294
A4: LLEGAMOS NOSOTROS | B4: 0 | C4: =C3-B4 -> 23 | D4: =C4/B2 -> 0.052752294
A5: NO ESTA LA CAMARA | B5: 4 | C5: =C4-B5 -> 19 | D5: =C5/B2 -> 0.043577982
A6: RADIO | B6: 3 | C6: =C5-B6 -> 16 | D6: =C6/B2 -> 0.036697248
A7: TOTAL | B7: 436 | E7: 44929
A8: CAIDAS | B8: 38 | C8: 38 | D8: =C8/B7 -> 0.087155963
A9: LLEGAMOS NOSOTROS | B9: 0 | C9: =C8-B9 -> 38 | D9: =C9/B7 -> 0.087155963
A10: NO ESTA LA CAMARA | B10: 4 | C10: =C9-B10 -> 34 | D10: =C10/B7 -> 0.077981651
A11: RADIO | B11: 8 | C11: =C10-B11 -> 26 | D11: =C11/B7 -> 0.059633028
A12: TOTAL | B12: 436 | E12: 44930
A13: CAIDAS | B13: 47 | C13: 47 | D13: =C13/B12 -> 0.10779817
A14: LLEGAMOS NOSOTROS | B14: 2 | C14: =C13-B14 -> 45 | D14: =C14/B12 -> 0.10321101
A15: NO ESTA LA CAMARA | B15: 4 | C15: =C14-B15 -> 41 | D15: =C15/B12 -> 0.094036697
A16: RADIO | B16: 9 | C16: =C15-B16 -> 32 | D16: =C16/B12 -> 0.073394495
A17: TOTAL | B17: 436 | E17: 44931
A18: CAIDAS | B18: 25 | C18: 25 | D18: =C18/B17 -> 0.05733945
A19: LLEGAMOS NOSOTROS | B19: 1 | C19: =C18-B19 -> 24 | D19: =C19/B17 -> 0.055045872
A20: NO ESTA LA CAMARA | B20: 1 | C20: =C19-B20 -> 23 | D20: =C20/B17 -> 0.052752294
A21: RADIO | B21: 4 | C21: =C20-B21 -> 19 | D21: =C21/B17 -> 0.043577982
A22: TOTAL | B22: 436 | E22: 44932
A23: CAIDAS | B23: 38 | C23: 38 | D23: =C23/B22 -> 0.087155963
A24: LLEGAMOS NOSOTROS | B24: 6 | C24: =C23-B24 -> 32 | D24: =C24/B22 -> 0.073394495
A25: NO ESTA LA CAMARA | B25: 1 | C25: =C24-B25 -> 31 | D25: =C25/B22 -> 0.071100917
A26: RADIO | B26: 6 | C26: =C25-B26 -> 25 | D26: =C26/B22 -> 0.05733945
A27: TOTAL | B27: 436 | E27: 44935
A28: CAIDAS | B28: 21 | C28: 21 | D28: =C28/B27 -> 0.048165138
A29: LLEGAMOS NOSOTROS | B29: 1 | C29: =C28-B29 -> 20 | D29: =C29/B27 -> 0.04587156
A30: NO ESTA LA CAMARA | B30: 1 | C30: =C29-B30 -> 19 | D30: =C30/B27 -> 0.043577982
A31: RADIO | B31: 6 | C31: =C30-B31 -> 13 | D31: =C31/B27 -> 0.029816514
A32: TOTAL | B32: 436 | E32: 44936
A33: CAIDAS | B33: ='RESUMEN TOTAL'!T3 -> 22 | C33: =B33 -> 22 | D33: =C33/B32 -> 0.050458716
A34: LLEGAMOS NOSOTROS | B34: 0 | C34: =C33-B34 -> 22 | D34: =C34/B32 -> 0.050458716
A35: NO ESTA LA CAMARA | B35: 1 | C35: =C34-B35 -> 21 | D35: =C35/B32 -> 0.048165138
A36: RADIO | B36: ='APAGADOS RADIO'!O2 -> 6 | C36: =C35-B36 -> 15 | D36: =C36/B32 -> 0.03440367
A37: TOTAL | B37: 436 | E37: 44937
A38: CAIDAS | B38: ='RESUMEN TOTAL'!U3 -> 19 | C38: =B38 -> 19 | D38: =C38/B37 -> 0.043577982
A39: LLEGAMOS NOSOTROS | B39: 1 | C39: =C38-B39 -> 18 | D39: =C39/B37 -> 0.041284404
A40: NO ESTA LA CAMARA | B40: 1 | C40: =C39-B40 -> 17 | D40: =C40/B37 -> 0.038990826
...

Sheet Hoja2
C3: CAMARAS | D3: 44931 | H3: CAMARAS | I3: 44928
B4: BONOMO | C4: =COUNTIFS('RESUMEN TOTAL'!C5:C504,"=BONOMO") -> 228 | D4: 16 | F4: 6 de radio | G4: BONOMO | H4: 228 | I4: 10
D5: 0.070175439 | I5: =I4/H4 -> 0.043859649
B6: COSEIDI | C6: =COUNTIFS('RESUMEN TOTAL'!C5:C504,"=COSEIDI") -> 207 | D6: 9 | E6: 1 no esta la camara | F6: 2 de radio | G6: COSEIDI | H6: 207 | I6: 6
D7: 0.043478261 | I7: =I6/H6 -> 0.028985507

Sheet GRAFICO2

Sheet AUXILIAR
A1: FECHA | B1: RADIO | C1: FIBRA | D1: ANTENA | E1: TOTAL APAGADOS | F1: INSTALADAS | G1: % APAGADOS
A2: ='APAGADOS RADIO'!F3 -> 44927 | B2: ='APAGADOS RADIO'!F2+D2 -> 8 | C2: ='APAGADOS FIBRA'!F2 -> 28 | D2: ='APAGADOS ANTENA'!F2 -> 3 | E2: =B2+C2 -> 36 | F2: ='RESUMEN TOTAL'!B1 -> 435 | G2: =E2/F2 -> 0.082758621
A3: ='APAGADOS RADIO'!G3 -> 44928 | B3: ='APAGADOS RADIO'!G2+D3 -> 3 | C3: ='APAGADOS FIBRA'!G2 -> 20 | D3: ='APAGADOS ANTENA'!G2 -> 0 | E3: =B3+C3 -> 23 | F3: ='RESUMEN TOTAL'!B1 -> 435 | G3: =E3/F3 -> 0.052873563
A4: ='APAGADOS RADIO'!H3 -> 44929 | B4: ='APAGADOS RADIO'!H2+D4 -> 9 | C4: ='APAGADOS FIBRA'!H2 -> 29 | D4: ='APAGADOS ANTENA'!H2 -> 1 | E4: =B4+C4 -> 38 | F4: ='RESUMEN TOTAL'!B1 -> 435 | G4: =E4/F4 -> 0.087356322
A5: ='APAGADOS RADIO'!I3 -> 44930 | B5: ='APAGADOS RADIO'!I2+D5 -> 8 | C5: ='APAGADOS FIBRA'!I2 -> 39 | D5: ='APAGADOS ANTENA'!I2 -> 0 | E5: =B5+C5 -> 47 | F5: ='RESUMEN TOTAL'!B1 -> 435 | G5: =E5/F5 -> 0.10804598
A6: ='APAGADOS RADIO'!J3 -> 44931 | B6: ='APAGADOS RADIO'!J2+D6 -> 8 | C6: ='APAGADOS FIBRA'!J2 -> 17 | D6: ='APAGADOS ANTENA'!J2 -> 0 | E6: =B6+C6 -> 25 | F6: ='RESUMEN TOTAL'!B1 -> 435 | G6: =E6/F6 -> 0.057471264
A7: ='APAGADOS RADIO'!K3 -> 44932 | B7: ='APAGADOS RADIO'!K2+D7 -> 7 | C7: ='APAGADOS FIBRA'!K2 -> 29 | D7: ='APAGADOS ANTENA'!K2 -> 1 | E7: =B7+C7 -> 36 | F7: ='RESUMEN TOTAL'!B1 -> 435 | G7: =E7/F7 -> 0.082758621
A8: ='APAGADOS RADIO'!L3 -> 44933
A9: ='APAGADOS RADIO'!M3 -> 44934
A10: ='APAGADOS RADIO'!N3 -> 44935
A11: ='APAGADOS RADIO'!O3 -> 44936
A12: ='APAGADOS RADIO'!P3 -> 44937
A13: ='APAGADOS RADIO'!Q3 -> 44938
A14: ='APAGADOS RADIO'!R3 -> 44939
A15: ='APAGADOS RADIO'!S3 -> 44940
A16: ='APAGADOS RADIO'!T3 -> 44941
A17: ='APAGADOS RADIO'!U3 -> 44942
A18: ='APAGADOS RADIO'!V3 -> 44943
A19: ='APAGADOS RADIO'!W3 -> 44944
A20: ='APAGADOS RADIO'!X3 -> 44945
A21: ='APAGADOS RADIO'!Y3 -> 44946
A22: ='APAGADOS RADIO'!Z3 -> 44947
A23: ='APAGADOS RADIO'!AA3 -> 44948
A24: ='APAGADOS RADIO'!AB3 -> 44949
A25: ='APAGADOS RADIO'!AC3 -> 44950
A26: ='APAGADOS RADIO'!AD3 -> 44951
A27: ='APAGADOS RADIO'!AE3 -> 44952
A28: ='APAGADOS RADIO'!AF3 -> 44953
A29: ='APAGADOS RADIO'!AG3 -> 44954
A30: ='APAGADOS RADIO'!AH3 -> 44955
A31: ='APAGADOS RADIO'!AI3 -> 44956

Sheet Hoja1
B1: CAMARAS
A2: BONOMO | B2: =COUNTIFS('RESUMEN TOTAL'!C5:C503,"=BONOMO") -> 228 | F2: 44927 | G2: 44928 | H2: 44929 | I2: 44930 | J2: 44931 | K2: 44932 | L2: 44933 | M2: 44934 | N2: 44935 | O2: 44936 | P2: 44937 | Q2: 44938 | R2: 44939 | S2: 44940 | T2: 44941 | U2: 44942 | V2: 44943 | W2: 44944 | X2: 44945 | Y2: 44946 | Z2: 44947 | AA2: 44948 | AB2: 44949 | AC2: 44950 | AD2: 44951 | AE2: 44952 | AF2: 44953 | AG2: 44954 | AH2: 44955 | AI2: 44956 | AJ2: 44957
D3: BONOMO | E3: APAGADAS BONOMO | F3: =COUNTIFS('RESUMEN TOTAL'!C7:C504, "=BONOMO",'RESUMEN TOTAL'!K7:K504,"=APAGADO") -> 23 | G3: =COUNTIFS('RESUMEN TOTAL'!C7:C504, "=BONOMO",'RESUMEN TOTAL'!L7:L504,"=APAGADO") -> 15 | H3: =COUNTIFS('RESUMEN TOTAL'!C7:C504, "=BONOMO",'RESUMEN TOTAL'!M7:M504,"=APAGADO") -> 23 | I3: =COUNTIFS('RESUMEN TOTAL'!C7:C504, "=BONOMO",'RESUMEN TOTAL'!N7:N504,"=APAGADO") -> 21 | J3: =COUNTIFS('RESUMEN TOTAL'!C7:C504, "=BONOMO",'RESUMEN TOTAL'!O7:O504,"=APAGADO") -> 16 | K3: =COUNTIFS('RESUMEN TOTAL'!C7:C504, "=BONOMO",'RESUMEN TOTAL'!P7:P504,"=APAGADO") -> 18 | L3: =COUNTIFS('RESUMEN TOTAL'!C7:C504, "=BONOMO",'RESUMEN TOTAL'!Q7:Q504,"=APAGADO") -> 16 | M3: =COUNTIFS('RESUMEN TOTAL'!C7:C504, "=BONOMO",'RESUMEN TOTAL'!R7:R504,"=APAGADO") -> 15 | N3: =COUNTIFS('RESUMEN TOTAL'!C7:C504, "=BONOMO",'RESUMEN TOTAL'!S7:S504,"=APAGADO") -> 14 | O3: =COUNTIFS('RESUMEN TOTAL'!C7:C504, "=BONOMO",'RESUMEN TOTAL'!T7:T504,"=APAGADO") -> 15 | P3: =COUNTIFS('RESUMEN TOTAL'!C7:C504, "=BONOMO",'RESUMEN TOTAL'!U7:U504,"=APAGADO") -> 14 | Q3: =COUNTIFS('RESUMEN TOTAL'!C7:C504, "=BONOMO",'RESUMEN TOTAL'!V7:V504,"=APAGADO") -> 9 | R3: =COUNTIFS('RESUMEN TOTAL'!C7:C504, "=BONOMO",'RESUMEN TOTAL'!W7:W504,"=APAGADO") -> 9 | S3: =COUNTIFS('RESUMEN TOTAL'!C7:C504, "=BONOMO",'RESUMEN TOTAL'!X7:X504,"=APAGADO") -> 9 | T3: =COUNTIFS('RESUMEN TOTAL'!C7:C504, "=BONOMO",'RESUMEN TOTAL'!Y7:Y504,"=APAGADO") -> 17 | U3: =COUNTIFS('RESUMEN TOTAL'!C7:C504, "=BONOMO",'RESUMEN TOTAL'!Z7:Z504,"=APAGADO") -> 16 | V3: =COUNTIFS('RESUMEN TOTAL'!C7:C504, "=BONOMO",'RESUMEN TOTAL'!AA7:AA504,"=APAGADO") -> 12 | W3: =COUNTIFS('RESUMEN TOTAL'!C7:C504, "=BONOMO",'RESUMEN TOTAL'!AB7:AB504,"=APAGADO") -> 11 | X3: =COUNTIFS('RESUMEN TOTAL'!C7:C504, "=BONOMO",'RESUMEN TOTAL'!AC7:AC504,"=APAGADO") -> 16 | Y3: =COUNTIFS('RESUMEN TOTAL'!C7:C504, "=BONOMO",'RESUMEN TOTAL'!AD7:AD504,"=APAGADO") -> 14 | Z3: =COUNTIFS('RESUMEN TOTAL'!C7:C504, "=BONOMO",'RESUMEN TOTAL'!AE7:AE504,"=APAGADO") -> 0 | AA3: =COUNTIFS('RESUMEN TOTAL'!C7:C504, "=BONOMO",'RESUMEN TOTAL'!AF7:AF504,"=APAGADO") -> 0 | AB3: =COUNTIFS('RESUMEN TOTAL'!C7:C504, "=BONOMO",'RESUMEN TOTAL'!AG7:AG504,"=APAGADO") -> 0 | AC3: =COUNTIFS('RESUMEN TOTAL'!C7:C504, "=BONOMO",'RESUMEN TOTAL'!AH7:AH504,"=APAGADO") -> 0 | AD3: =COUNTIFS('RESUMEN TOTAL'!C7:C504, "=BONOMO",'RESUMEN TOTAL'!AI7:AI504,"=APAGADO") -> 0 | AE3: =COUNTIFS('RESUMEN TOTAL'!C7:C504, "=BONOMO",'RESUMEN TOTAL'!AJ7:AJ504,"=APAGADO") -> 0 | AF3: =COUNTIFS('RESUMEN TOTAL'!C7:C504, "=BONOMO",'RESUMEN TOTAL'!AK7:AK504,"=APAGADO") -> 0 | AG3: =COUNTIFS('RESUMEN TOTAL'!C7:C504, "=BONOMO",'RESUMEN TOTAL'!AL7:AL504,"=APAGADO") -> 0 | AH3: =COUNTIFS('RESUMEN TOTAL'!C7:C504, "=BONOMO",'RESUMEN TOTAL'!AM7:AM504,"=APAGADO") -> 0 | AI3: =COUNTIFS('RESUMEN TOTAL'!C7:C504, "=BONOMO",'RESUMEN TOTAL'!AN7:AN504,"=APAGADO") -> 0 | AJ3: =COUNTIFS('RESUMEN TOTAL'!D7:D504, "=BONOMO",'RESUMEN TOTAL'!AO7:AO504,"=APAGADO") -> 0
A4: COSEIDI | B4: =COUNTIFS('RESUMEN TOTAL'!C5:C503,"=COSEIDI") -> 207 | E4: % BONOMO | F4: =F3/BONOMOcam -> 0.10087719 | G4: =G3/BONOMOcam -> 0.065789474 | H4: =H3/BONOMOcam -> 0.10087719 | I4: =I3/BONOMOcam -> 0.092105263 | J4: =J3/BONOMOcam -> 0.070175439 | K4: =K3/BONOMOcam -> 0.078947368 | L4: =L3/BONOMOcam -> 0.070175439 | M4: =M3/BONOMOcam -> 0.065789474 | ... AJ4: =AJ3/BONOMOcam -> 0
