Workbook
Name _25_de_agosto: 'RESUMEN TOTAL'!$A$4:$D$363
Name BONOMOcam: Hoja1!$B$2
Name COSEIDIcam: Hoja1!$B$4

Sheet RESUMEN TOTAL
A1: CANTIDAD DE CAMARAS | B1: =COUNTA(B5:B528) -> 427 | D1: PORCIENTO DE CAIDAS | K1: =(K3)/(K2+K3) -> 0.093975904 | L1: =(L3)/(L2+L3) -> 0.093975904 | M1: =(M3)/(M2+M3) -> 0.39328537 | N1: =(N3)/(N2+N3) -> 0.10361446 | O1: =(O3)/(O2+O3) -> 0.089156627 | P1: =(P3)/(P2+P3) -> 0 | Q1: =(Q3)/(Q2+Q3) -> 0.084337349 | R1: =(R3)/(R2+R3) -> 0 | ... AO1: =(AO3)/(AO2+AO3) -> 0
D2: FUNCIONAN | K2: =COUNTIF(K7:K421, "") -> 376 | L2: =COUNTIF(L7:L421, "") -> 376 | M2: =COUNTIF(M7:M421, "") -> 253 | N2: =COUNTIF(N7:N421, "") -> 372 | O2: =COUNTIF(O7:O421, "") -> 378 | P2: =COUNTIF(P7:P421, "") -> 415 | Q2: =COUNTIF(Q7:Q421, "") -> 380 | R2: =COUNTIF(R7:R421, "") -> 415 | ... AE2: =COUNTIF(AE7:AE421, "") -> 373 | AF2: =COUNTIF(AF5:AF422, "") -> 373 | AG2: =COUNTIF(AG5:AG422, "") -> 362 | AH2: =COUNTIF(AH5:AH422, "") -> 418 | AI2: =COUNTIF(AI5:AI422, "") -> 418 | AJ2: =COUNTIF(AJ5:AJ422, "") -> 418 | AK2: =COUNTIF(AK5:AK422, "") -> 418 | AL2: =COUNTIF(AL5:AL422, "") -> 418 | AM2: =COUNTIF(AM5:AM422, "") -> 418 | ... AO2: =COUNTIF(AO5:AO422, "") -> 418
D3: CAIDAS | K3: =COUNTIF(K4:K448, "apagado") -> 39 | L3: =COUNTIF(L4:L448, "apagado") -> 39 | M3: =COUNTIF(M4:M448, "apagado") -> 164 | N3: =COUNTIF(N4:N448, "apagado") -> 43 | O3: =COUNTIF(O4:O448, "apagado") -> 37 | P3: =COUNTIF(P4:P448, "apagado") -> 0 | Q3: =COUNTIF(Q4:Q448, "apagado") -> 35 | R3: =COUNTIF(R4:R448, "apagado") -> 0 | ... AO3: =COUNTIF(AO4:AO448, "apagado") -> 0
A4: Barrio | B4: [Denominacion] | C4: [Empresa Mantenimiento] | D4: [Ubicacion] | E4: [Tipo de Camara] | F4: [Tipo de Conexion] | H4: DIAS FUNCIONANDO | I4: DIAS CAIDA | J4: EFECTIVIDAD | K4: 44835 | L4: 44836 | M4: 44837 | N4: 44838 | O4: 44839 | P4: 44840 | Q4: 44841 | R4: 44842 | S4: 44843 | T4: 44844 | U4: 44845 | V4: 44846 | W4: 44847 | X4: 44848 | Y4: 44849 | Z4: 44850 | AA4: 44851 | AB4: 44852 | AC4: 44853 | AD4: 44854 | AE4: 44855 | AF4: 44856 | AG4: 44857 | AH4: 44858 | AI4: 44859 | AJ4: 44860 | AK4: 44861 | AL4: 44862 | AM4: 44863 | AN4: 44864 | AO4: 44865
A5: ALTAMIRA | B5: ALT01 | C5: BONOMO | D5: Calchaqui y Sgto. Cabral | E5: Domo | F5: Fibra Optica | G5: 172.20.10.6 | H5: =COUNTIF(K5:AN5,"") -> 29 | I5: =COUNTIF(K5:AL5,"APAGADO") -> 1 | J5: =(H5)/(I5+H5) -> 0.96666667 | M5: APAGADO
A6: ALTAMIRA | B6: ALT02 | C6: BONOMO | D6: Calchaqui y Lope de Vega | E6: Domo | F6: PTO A FO | G6: 172.20.12.218 | H6: =COUNTIF(K6:AN6,"") -> 29 | I6: =COUNTIF(K6:AL6,"APAGADO") -> 1 | J6: =(H6)/(I6+H6) -> 0.96666667 | M6: APAGADO
A7: ALTAMIRA | B7: ALT 03 | C7: BONOMO | D7: Bombero Galarza y Necochea | E7: Domo | F7: FIBRA OPTICA | G7: 172.20.12.54 | H7: =COUNTIF(K7:AN7,"") -> 30 | I7: =COUNTIF(K7:AL7,"APAGADO") -> 0 | J7: =(H7)/(I7+H7) -> 1
A8: ALTAMIRA | B8: ALT 04 | C8: BONOMO | D8: Francia y Necochea | E8: Domo | F8: FIBRA OPTICA | G8: 172.20.12.55 | H8: =COUNTIF(K8:AN8,"") -> 25 | I8: =COUNTIF(K8:AL8,"APAGADO") -> 5 | J8: =(H8)/(I8+H8) -> 0.83333333 | K8: APAGADO | L8: APAGADO | M8: APAGADO | N8: APAGADO | O8: APAGADO
A9: ALTAMIRA | B9: ALT05 | C9: BONOMO | D9: Av. Calchaqui y Bombero Galarza | E9: Domo | F9: PTO A FO | G9: 172.20.12.216 | H9: =COUNTIF(K9:AN9,"") -> 10 | I9: =COUNTIF(K9:AL9,"APAGADO") -> 20 | J9: =(H9)/(I9+H9) -> 0.33333333 | K9: APAGADO | L9: APAGADO | M9: APAGADO | N9: APAGADO | O9: APAGADO | Q9: APAGADO | S9: APAGADO | T9: APAGADO | U9: APAGADO | V9: APAGADO | W9: APAGADO | X9: APAGADO | Y9: APAGADO | Z9: APAGADO | AB9: APAGADO | AC9: APAGADO | AD9: APAGADO | AE9: APAGADO | AF9: APAGADO | AG9: APAGADO
A10: ALTAMIRA | B10: ALT 06 | C10: BONOMO | D10: LOPE DE VEGA Y NECOCHEA | E10: Domo | F10: PTO A FO | G10: 172.20.12.12 | H10: =COUNTIF(K10:AN10,"") -> 28 | I10: =COUNTIF(K10:AL10,"APAGADO") -> 2 | J10: =(H10)/(I10+H10) -> 0.93333333 | M10: APAGADO | N10: APAGADO
A11: ALTAMIRA | B11: ALT07 | C11: BONOMO | D11: AV. CALCHAQUI Y AV. DEL TRABAJO | E11: DOMO | F11: PTO A FO | G11: 172.20.10.57 | H11: =COUNTIF(K11:AN11,"") -> 30 | I11: =COUNTIF(K11:AL11,"APAGADO") -> 0 | J11: =(H11)/(I11+H11) -> 1
A12: ALTAMIRA | B12: ALT 08 | C12: BONOMO | D12: HUMAITA Y NECOCHEA | E12: DOMO | F12: Fibra Optica | G12: 172.20.11.215 | H12: =COUNTIF(K12:AN12,"") -> 30 | I12: =COUNTIF(K12:AL12,"APAGADO") -> 0 | J12: =(H12)/(I12+H12) -> 1
A13: ALTAMIRA | B13: ALT 09 | C13: BONOMO | D13: NECOCHEA Y CURUPAITY | E13: DOMO | F13: Fibra Optica | G13: 172.20.11.216 | H13: =COUNTIF(K13:AN13,"") -> 30 | I13: =COUNTIF(K13:AL13,"APAGADO") -> 0 | J13: =(H13)/(I13+H13) -> 1
A14: ALTAMIRA | B14: ALT 10 | C14: BONOMO | D14: Calchaqui y Francia | E14: Domo | F14: Radio | H14: =COUNTIF(K14:AN14,"") -> 10 | I14: =COUNTIF(K14:AL14,"APAGADO") -> 20 | J14: =(H14)/(I14+H14) -> 0.33333333 | K14: APAGADO | L14: APAGADO | M14: APAGADO | N14: APAGADO | O14: APAGADO | Q14: APAGADO | S14: APAGADO | T14: APAGADO | U14: APAGADO | V14: APAGADO | W14: APAGADO | X14: APAGADO | Y14: APAGADO | Z14: APAGADO | AB14: APAGADO | AC14: APAGADO | AD14: APAGADO | AE14: APAGADO | AF14: APAGADO | AG14: APAGADO
A15: AGUSTIN RAMIREZ | B15: ARA 01 | C15: COSEIDI | D15: Malambo y Tranquera | E15: Domo | F15: FIBRA OPTICA | G15: 172.20.12.110 | H15: =COUNTIF(K15:AN15,"") -> 28 | I15: =COUNTIF(K15:AL15,"APAGADO") -> 2 | J15: =(H15)/(I15+H15) -> 0.93333333 | M15: APAGADO | AC15: APAGADO
A16: BELGRANO | B16: BEL 01 | C16: BONOMO | D16: San Martin y Dardo Rocha | E16: DOMO | F16: FIBRA OPTICA | G16: 172.20.12.64 | H16: =COUNTIF(K16:AN16,"") -> 11 | I16: =COUNTIF(K16:AL16,"APAGADO") -> 19 | J16: =(H16)/(I16+H16) -> 0.36666667 | K16: APAGADO | L16: APAGADO | M16: APAGADO | N16: APAGADO | O16: APAGADO | Q16: APAGADO | T16: APAGADO | U16: APAGADO | V16: APAGADO | W16: APAGADO | X16: APAGADO | Y16: APAGADO | Z16: APAGADO | AB16: APAGADO | AC16: APAGADO | AD16: APAGADO | AE16: APAGADO | AF16: APAGADO | AG16: APAGADO
A17: CENTRO | B17: CEN01 | C17: BONOMO | D17: San Martin y 9 de Julio | E17: Fija | F17: Fibra Optica | G17: 172.20.11.10 | H17: =COUNTIF(K17:AN17,"") -> 29 | I17: =COUNTIF(K17:AL17,"APAGADO") -> 1 | J17: =(H17)/(I17+H17) -> 0.96666667 | M17: APAGADO
A18: CENTRO | B18: CEN02 | C18: BONOMO | D18: San Martin y Almafuerte | E18: Fija | F18: Fibra Optica | G18: 172.20.11.11 | H18: =COUNTIF(K18:AN18,"") -> 29 | I18: =COUNTIF(K18:AL18,"APAGADO") -> 1 | J18: =(H18)/(I18+H18) -> 0.96666667 | M18: APAGADO
A19: CENTRO | B19: CEN03 | C19: BONOMO | D19: San Martin y Sallares | E19: Domo | F19: Fibra Optica | G19: 172.20.12.30 | H19: =COUNTIF(K19:AN19,"") -> 29 | I19: =COUNTIF(K19:AL19,"APAGADO") -> 1 | J19: =(H19)/(I19+H19) -> 0.96666667 | M19: APAGADO
A20: CENTRO | B20: CEN04 | C20: BONOMO | D20: San Martin y Contreras | E20: Domo | F20: Fibra Optica | G20: 172.20.12.29 | H20: =COUNTIF(K20:AN20,"") -> 30 | I20: =COUNTIF(K20:AL20,"APAGADO") -> 0 | J20: =(H20)/(I20+H20) -> 1
A21: CENTRO | B21: CEN 05 | C21: BONOMO | D21: Bocuzzi e/España y San Martin | E21: DOMO | F21: Fibra Optica | G21: 172.20.10.200 | H21: =COUNTIF(K21:AN21,"") -> 29 | I21: =COUNTIF(K21:AL21,"APAGADO") -> 1 | J21: =(H21)/(I21+H21) -> 0.96666667 | M21: APAGADO
A22: CENTRO | B22: CEN06 | C22: BONOMO | D22: Monteagudo y A.del Valle | E22: Fija | F22: Fibra Optica | G22: 172.20.10.02 | H22: =COUNTIF(K22:AN22,"") -> 29 | I22: =COUNTIF(K22:AL22,"APAGADO") -> 1 | J22: =(H22)/(I22+H22) -> 0.96666667 | M22: APAGADO
A23: CENTRO | B23: CEN07 | C23: BONOMO | D23: San Martin y Guemes | E23: DOMO | F23: Fibra Optica | G23: 172.20.11.20 | H23: =COUNTIF(K23:AN23,"") -> 29 | I23: =COUNTIF(K23:AL23,"APAGADO") -> 1 | J23: =(H23)/(I23+H23) -> 0.96666667 | M23: APAGADO
A24: CENTRO | B24: CEN08 | C24: BONOMO | D24: San Martin y Pte.Peron | E24: Domo | F24: Fibra Optica | G24: 172.20.11.21 | H24: =COUNTIF(K24:AN24,"") -> 30 | I24: =COUNTIF(K24:AL24,"APAGADO") -> 0 | J24: =(H24)/(I24+H24) -> 1
A25: CENTRO | B25: CEN09 | C25: BONOMO | D25: Chacabuco y 25 de Mayo | E25: Domo | F25: Fibra Optica | G25: 172.20.11.22 | H25: =COUNTIF(K25:AN25,"") -> 30 | I25: =COUNTIF(K25:AL25,"APAGADO") -> 0 | J25: =(H25)/(I25+H25) -> 1
A26: CENTRO | B26: CEN10 | C26: BONOMO | D26: Monteagudo y Pte. Peron | E26: Domo | F26: Fibra Optica | G26: 172.20.11.23 | H26: =COUNTIF(K26:AN26,"") -> 29 | I26: =COUNTIF(K26:AL26,"APAGADO") -> 1 | J26: =(H26)/(I26+H26) -> 0.96666667 | M26: APAGADO
A27: CENTRO | B27: CEN11 | C27: BONOMO | D27: Monteagudo y Bocuzzi | E27: Domo | F27: Fibra Optica | G27: 172.20.10.24 | H27: =COUNTIF(K27:AN27,"") -> 30 | I27: =COUNTIF(K27:AL27,"APAGADO") -> 0 | J27: =(H27)/(I27+H27) -> 1
A28: CENTRO | B28: CEN 12 | C28: BONOMO | D28: Monteagudo y Mitre | E28: Domo | F28: Fibra Optica | G28: 172.20.10.23 | H28: =COUNTIF(K28:AN28,"") -> 18 | I28: =COUNTIF(K28:AL28,"APAGADO") -> 12 | J28: =(H28)/(I28+H28) -> 0.6 | N28: APAGADO | O28: APAGADO | W28: APAGADO | X28: APAGADO | Y28: APAGADO | Z28: APAGADO | AB28: APAGADO | AC28: APAGADO | AD28: APAGADO | AE28: APAGADO | AF28: APAGADO | AG28: APAGADO
A29: CENTRO | B29: CEN 13 | C29: BONOMO | D29: 25 de Mayo y Maipu | E29: DOMO | F29: Fibra Optica | G29: 172.20.10.20 | H29: =COUNTIF(K29:AN29,"") -> 28 | I29: =COUNTIF(K29:AL29,"APAGADO") -> 2 | J29: =(H29)/(I29+H29) -> 0.93333333 | M29: APAGADO | Q29: APAGADO
A30: CENTRO | B30: CEN14 | C30: BONOMO | D30: Pte.Peron e/Pringles y Brown | E30: Domo | F30: Fibra Optica | G30: 172.20.10.21 | H30: =COUNTIF(K30:AN30,"") -> 30 | I30: =COUNTIF(K30:AL30,"APAGADO") -> 0 | J30: =(H30)/(I30+H30) -> 1
A31: CENTRO | B31: CEN15 | C31: BONOMO | D31: Alberdi y A.del Valle | E31: Domo | F31: Fibra Optica | G31: 172.20.10.35 | H31: =COUNTIF(K31:AN31,"") -> 11 | I31: =COUNTIF(K31:AL31,"APAGADO") -> 19 | J31: =(H31)/(I31+H31) -> 0.36666667 | K31: APAGADO | L31: APAGADO | M31: APAGADO | N31: APAGADO | O31: APAGADO | S31: APAGADO | T31: APAGADO | U31: APAGADO | V31: APAGADO | W31: APAGADO | X31: APAGADO | Y31: APAGADO | Z31: APAGADO | AB31: APAGADO | AC31: APAGADO | AD31: APAGADO | AE31: APAGADO | AF31: APAGADO | AG31: APAGADO
A32: CENTRO | B32: CEN16 | C32: BONOMO | D32: San Martin y Pte. Peron | E32: Fija | F32: Fibra Optica | G32: 172.20.12.36 | H32: =COUNTIF(K32:AN32,"") -> 29 | I32: =COUNTIF(K32:AL32,"APAGADO") -> 1 | J32: =(H32)/(I32+H32) -> 0.96666667 | M32: APAGADO
A33: CENTRO | B33: CEN17 | C33: BONOMO | D33: San Martin y Mitre | E33: Domo | F33: PTO A FO | G33: 172.20.12.200 | H33: =COUNTIF(K33:AN33,"") -> 29 | I33: =COUNTIF(K33:AL33,"APAGADO") -> 1 | J33: =(H33)/(I33+H33) -> 0.96666667 | M33: APAGADO
A34: CENTRO | B34: CEN18 | C34: BONOMO | D34: Monteagudo e/Mitre y Sallares | E34: Fija | F34: Fibra Optica | G34: 172.20.10.26 | H34: =COUNTIF(K34:AN34,"") -> 10 | I34: =COUNTIF(K34:AL34,"APAGADO") -> 20 | J34: =(H34)/(I34+H34) -> 0.33333333 | K34: APAGADO | L34: APAGADO | M34: APAGADO | N34: APAGADO | O34: APAGADO | Q34: APAGADO | S34: APAGADO | T34: APAGADO | U34: APAGADO | V34: APAGADO | W34: APAGADO | X34: APAGADO | Y34: APAGADO | Z34: APAGADO | AB34: APAGADO | AC34: APAGADO | AD34: APAGADO | AE34: APAGADO | AF34: APAGADO | AG34: APAGADO
A35: CENTRO | B35: CEN19 | C35: BONOMO | D35: Chacabuco y 25 de Mayo | E35: Fija | F35: Fibra Optica | G35: 172.20.10.27 | H35: =COUNTIF(K35:AN35,"") -> 30 | I35: =COUNTIF(K35:AL35,"APAGADO") -> 0 | J35: =(H35)/(I35+H35) -> 1
A36: LOMAS DE MONTEVERDE | B36: CEN20 | C36: BONOMO | D36: Pte. Illia y Las Heras | E36: Domo | F36: Fibra Optica | G36: 172.20.10.33 | H36: =COUNTIF(K36:AN36,"") -> 26 | I36: =COUNTIF(K36:AL36,"APAGADO") -> 4 | J36: =(H36)/(I36+H36) -> 0.86666667 | K36: APAGADO | L36: APAGADO | M36: APAGADO | N36: APAGADO
A37: CENTRO | B37: CEN21 | C37: BONOMO | D37: Misiones y Urquiza | E37: Fija | F37: Radio | G37: 172.20.200.132 | H37: =COUNTIF(K37:AN37,"") -> 29 | I37: =COUNTIF(K37:AL37,"APAGADO") -> 1 | J37: =(H37)/(I37+H37) -> 0.96666667 | M37: APAGADO
A38: CENTRO | B38: CEN22 | C38: BONOMO | D38: Las Heras y Chacabuco | E38: Domo | F38: Radio | G38: 172.20.200.125 | H38: =COUNTIF(K38:AN38,"") -> 30 | I38: =COUNTIF(K38:AL38,"APAGADO") -> 0 | J38: =(H38)/(I38+H38) -> 1
A39: CENTRO | B39: CEN23 | C39: BONOMO | D39: Sallares y Monteagudo | E39: Domo | F39: Fibra Optica | G39: 172.20.12.05 | H39: =COUNTIF(K39:AN39,"") -> 29 | I39: =COUNTIF(K39:AL39,"APAGADO") -> 1 | J39: =(H39)/(I39+H39) -> 0.96666667 | M39: APAGADO
A40: CENTRO | B40: CEN24 | C40: BONOMO | D40: Sallares y España | E40: Domo | F40: Fibra Optica | G40: 172.20.12.04 | H40: =COUNTIF(K40:AN40,"") -> 28 | I40: =COUNTIF(K40:AL40,"APAGADO") -> 2 | J40: =(H40)/(I40+H40) -> 0.93333333 | L40: APAGADO | N40: APAGADO
...

Sheet ESTADISTICA
A1: ='RESUMEN TOTAL'!A4 -> Barrio | B1: ='RESUMEN TOTAL'!B4 -> [Denominacion] | C1: ='RESUMEN TOTAL'!D4 -> [Ubicacion] | D1: ='RESUMEN TOTAL'!E4 -> [Tipo de Camara] | E1: ='RESUMEN TOTAL'!F4 -> [Tipo de Conexion] | F1: ='RESUMEN TOTAL'!K4 -> 44835 | G1: ='RESUMEN TOTAL'!L4 -> 44836 | H1: ='RESUMEN TOTAL'!M4 -> 44837 | I1: ='RESUMEN TOTAL'!N4 -> 44838 | J1: ='RESUMEN TOTAL'!O4 -> 44839 | K1: ='RESUMEN TOTAL'!P4 -> 44840 | L1: ='RESUMEN TOTAL'!Q4 -> 44841 | M1: ='RESUMEN TOTAL'!R4 -> 44842 | ... AI1: ='RESUMEN TOTAL'!AN4 -> 44864
A2: ='RESUMEN TOTAL'!A5 -> ALTAMIRA | B2: ='RESUMEN TOTAL'!B5 -> ALT01 | C2: ='RESUMEN TOTAL'!D5 -> Calchaqui y Sgto. Cabral | D2: ='RESUMEN TOTAL'!E5 -> Domo | E2: ='RESUMEN TOTAL'!F5 -> Fibra Optica | F2: ='RESUMEN TOTAL'!K5 -> 0 | G2: ='RESUMEN TOTAL'!L5 -> 0 | H2: ='RESUMEN TOTAL'!M5 -> APAGADO | I2: ='RESUMEN TOTAL'!N5 -> 0 | J2: ='RESUMEN TOTAL'!O5 -> 0 | K2: ='RESUMEN TOTAL'!P5 -> 0 | L2: ='RESUMEN TOTAL'!Q5 -> 0 | M2: ='RESUMEN TOTAL'!R5 -> 0 | ... AI2: ='RESUMEN TOTAL'!AN5 -> 0
A3: ='RESUMEN TOTAL'!A6 -> ALTAMIRA | B3: ='RESUMEN TOTAL'!B6 -> ALT02 | C3: ='RESUMEN TOTAL'!D6 -> Calchaqui y Lope de Vega | D3: ='RESUMEN TOTAL'!E6 -> Domo | E3: ='RESUMEN TOTAL'!F6 -> PTO A FO | F3: ='RESUMEN TOTAL'!K6 -> 0 | G3: ='RESUMEN TOTAL'!L6 -> 0 | H3: ='RESUMEN TOTAL'!M6 -> APAGADO | I3: ='RESUMEN TOTAL'!N6 -> 0 | J3: ='RESUMEN TOTAL'!O6 -> 0 | K3: ='RESUMEN TOTAL'!P6 -> 0 | L3: ='RESUMEN TOTAL'!Q6 -> 0 | M3: ='RESUMEN TOTAL'!R6 -> 0 | ... AI3: ='RESUMEN TOTAL'!AN6 -> 0
A4: ='RESUMEN TOTAL'!A7 -> ALTAMIRA | B4: ='RESUMEN TOTAL'!B7 -> ALT 03 | C4: ='RESUMEN TOTAL'!D7 -> Bombero Galarza y Necochea | D4: ='RESUMEN TOTAL'!E7 -> Domo | E4: ='RESUMEN TOTAL'!F7 -> FIBRA OPTICA | F4: ='RESUMEN TOTAL'!K7 -> 0 | G4: ='RESUMEN TOTAL'!L7 -> 0 | H4: ='RESUMEN TOTAL'!M7 -> 0 | I4: ='RESUMEN TOTAL'!N7 -> 0 | J4: ='RESUMEN TOTAL'!O7 -> 0 | K4: ='RESUMEN TOTAL'!P7 -> 0 | L4: ='RESUMEN TOTAL'!Q7 -> 0 | M4: ='RESUMEN TOTAL'!R7 -> 0 | ... AI4: ='RESUMEN TOTAL'!AN7 -> 0
A5: ='RESUMEN TOTAL'!A8 -> ALTAMIRA | B5: ='RESUMEN TOTAL'!B8 -> ALT 04 | C5: ='RESUMEN TOTAL'!D8 -> Francia y Necochea | D5: ='RESUMEN TOTAL'!E8 -> Domo | E5: ='RESUMEN TOTAL'!F8 -> FIBRA OPTICA | F5: ='RESUMEN TOTAL'!K8 -> APAGADO | G5: ='RESUMEN TOTAL'!L8 -> APAGADO | H5: ='RESUMEN TOTAL'!M8 -> APAGADO | I5: ='RESUMEN TOTAL'!N8 -> APAGADO | J5: ='RESUMEN TOTAL'!O8 -> APAGADO | K5: ='RESUMEN TOTAL'!P8 -> 0 | L5: ='RESUMEN TOTAL'!Q8 -> 0 | M5: ='RESUMEN TOTAL'!R8 -> 0 | ... AI5: ='RESUMEN TOTAL'!AN8 -> 0
A6: ='RESUMEN TOTAL'!A9 -> ALTAMIRA | B6: ='RESUMEN TOTAL'!B9 -> ALT05 | C6: ='RESUMEN TOTAL'!D9 -> Av. Calchaqui y Bombero Galarza | D6: ='RESUMEN TOTAL'!E9 -> Domo | E6: ='RESUMEN TOTAL'!F9 -> PTO A FO | F6: ='RESUMEN TOTAL'!K9 -> APAGADO | G6: ='RESUMEN TOTAL'!L9 -> APAGADO | H6: ='RESUMEN TOTAL'!M9 -> APAGADO | I6: ='RESUMEN TOTAL'!N9 -> APAGADO | J6: ='RESUMEN TOTAL'!O9 -> APAGADO | K6: ='RESUMEN TOTAL'!P9 -> 0 | L6: ='RESUMEN TOTAL'!Q9 -> APAGADO | M6: ='RESUMEN TOTAL'!R9 -> 0 | ... AI6: ='RESUMEN TOTAL'!AN9 -> 0
A7: ='RESUMEN TOTAL'!A10 -> ALTAMIRA | B7: ='RESUMEN TOTAL'!B10 -> ALT 06 | C7: ='RESUMEN TOTAL'!D10 -> LOPE DE VEGA Y NECOCHEA | D7: ='RESUMEN TOTAL'!E10 -> Domo | E7: ='RESUMEN TOTAL'!F10 -> PTO A FO | F7: ='RESUMEN TOTAL'!K10 -> 0 | G7: ='RESUMEN TOTAL'!L10 -> 0 | H7: ='RESUMEN TOTAL'!M10 -> APAGADO | I7: ='RESUMEN TOTAL'!N10 -> APAGADO | J7: ='RESUMEN TOTAL'!O10 -> 0 | K7: ='RESUMEN TOTAL'!P10 -> 0 | L7: ='RESUMEN TOTAL'!Q10 -> 0 | M7: ='RESUMEN TOTAL'!R10 -> 0 | ... AI7: ='RESUMEN TOTAL'!AN10 -> 0
A8: ='RESUMEN TOTAL'!A11 -> ALTAMIRA | B8: ='RESUMEN TOTAL'!B11 -> ALT07 | C8: ='RESUMEN TOTAL'!D11 -> AV. CALCHAQUI Y AV. DEL TRABAJO | D8: ='RESUMEN TOTAL'!E11 -> DOMO | E8: ='RESUMEN TOTAL'!F11 -> PTO A FO | F8: ='RESUMEN TOTAL'!K11 -> 0 | G8: ='RESUMEN TOTAL'!L11 -> 0 | H8: ='RESUMEN TOTAL'!M11 -> 0 | I8: ='RESUMEN TOTAL'!N11 -> 0 | J8: ='RESUMEN TOTAL'!O11 -> 0 | K8: ='RESUMEN TOTAL'!P11 -> 0 | L8: ='RESUMEN TOTAL'!Q11 -> 0 | M8: ='RESUMEN TOTAL'!R11 -> 0 | ... AI8: ='RESUMEN TOTAL'!AN11 -> 0
A9: ='RESUMEN TOTAL'!A12 -> ALTAMIRA | B9: ='RESUMEN TOTAL'!B12 -> ALT 08 | C9: ='RESUMEN TOTAL'!D12 -> HUMAITA Y NECOCHEA | D9: ='RESUMEN TOTAL'!E12 -> DOMO | E9: ='RESUMEN TOTAL'!F12 -> Fibra Optica | F9: ='RESUMEN TOTAL'!K12 -> 0 | G9: ='RESUMEN TOTAL'!L12 -> 0 | H9: ='RESUMEN TOTAL'!M12 -> 0 | I9: ='RESUMEN TOTAL'!N12 -> 0 | J9: ='RESUMEN TOTAL'!O12 -> 0 | K9: ='RESUMEN TOTAL'!P12 -> 0 | L9: ='RESUMEN TOTAL'!Q12 -> 0 | M9: ='RESUMEN TOTAL'!R12 -> 0 | ... AI9: ='RESUMEN TOTAL'!AN12 -> 0
A10: ='RESUMEN TOTAL'!A13 -> ALTAMIRA | B10: ='RESUMEN TOTAL'!B13 -> ALT 09 | C10: ='RESUMEN TOTAL'!D13 -> NECOCHEA Y CURUPAITY | D10: ='RESUMEN TOTAL'!E13 -> DOMO | E10: ='RESUMEN TOTAL'!F13 -> Fibra Optica | F10: ='RESUMEN TOTAL'!K13 -> 0 | G10: ='RESUMEN TOTAL'!L13 -> 0 | H10: ='RESUMEN TOTAL'!M13 -> 0 | I10: ='RESUMEN TOTAL'!N13 -> 0 | J10: ='RESUMEN TOTAL'!O13 -> 0 | K10: ='RESUMEN TOTAL'!P13 -> 0 | L10: ='RESUMEN TOTAL'!Q13 -> 0 | M10: ='RESUMEN TOTAL'!R13 -> 0 | ... AE10: ='RESUMEN TOTAL'!AJ13 -> 0 | AF10: ='RESUMEN TOTAL'!#REF! -> #REF! | AG10: ='RESUMEN TOTAL'!AL13 -> 0 | AH10: ='RESUMEN TOTAL'!AM13 -> 0 | AI10: ='RESUMEN TOTAL'!AN13 -> 0
A11: ='RESUMEN TOTAL'!A14 -> ALTAMIRA | B11: ='RESUMEN TOTAL'!B14 -> ALT 10 | C11: ='RESUMEN TOTAL'!D14 -> Calchaqui y Francia | D11: ='RESUMEN TOTAL'!E14 -> Domo | E11: ='RESUMEN TOTAL'!F14 -> Radio | F11: ='RESUMEN TOTAL'!K14 -> APAGADO | G11: ='RESUMEN TOTAL'!L14 -> APAGADO | H11: ='RESUMEN TOTAL'!M14 -> APAGADO | I11: ='RESUMEN TOTAL'!N14 -> APAGADO | J11: ='RESUMEN TOTAL'!O14 -> APAGADO | K11: ='RESUMEN TOTAL'!P14 -> 0 | L11: ='RESUMEN TOTAL'!Q14 -> APAGADO | M11: ='RESUMEN TOTAL'!R14 -> 0 | ... AD11: ='RESUMEN TOTAL'!AI14 -> 0 | AE11: ='RESUMEN TOTAL'!AK13 -> 0 | AF11: ='RESUMEN TOTAL'!AK14 -> 0 | AG11: ='RESUMEN TOTAL'!AL14 -> 0 | AH11: ='RESUMEN TOTAL'!AM14 -> 0 | AI11: ='RESUMEN TOTAL'!AN14 -> 0
A12: ='RESUMEN TOTAL'!A15 -> AGUSTIN RAMIREZ | B12: ='RESUMEN TOTAL'!B15 -> ARA 01 | C12: ='RESUMEN TOTAL'!D15 -> Malambo y Tranquera | D12: ='RESUMEN TOTAL'!E15 -> Domo | E12: ='RESUMEN TOTAL'!F15 -> FIBRA OPTICA | F12: ='RESUMEN TOTAL'!K15 -> 0 | G12: ='RESUMEN TOTAL'!L15 -> 0 | H12: ='RESUMEN TOTAL'!M15 -> APAGADO | I12: ='RESUMEN TOTAL'!N15 -> 0 | J12: ='RESUMEN TOTAL'!O15 -> 0 | K12: ='RESUMEN TOTAL'!P15 -> 0 | L12: ='RESUMEN TOTAL'!Q15 -> 0 | M12: ='RESUMEN TOTAL'!R15 -> 0 | ... AI12: ='RESUMEN TOTAL'!AN15 -> 0
A13: ='RESUMEN TOTAL'!A16 -> BELGRANO | B13: ='RESUMEN TOTAL'!B16 -> BEL 01 | C13: ='RESUMEN TOTAL'!D16 -> San Martin y Dardo Rocha | D13: ='RESUMEN TOTAL'!E16 -> DOMO | E13: ='RESUMEN TOTAL'!F16 -> FIBRA OPTICA | F13: ='RESUMEN TOTAL'!K16 -> APAGADO | G13: ='RESUMEN TOTAL'!L16 -> APAGADO | H13: ='RESUMEN TOTAL'!M16 -> APAGADO | I13: ='RESUMEN TOTAL'!N16 -> APAGADO | J13: ='RESUMEN TOTAL'!O16 -> APAGADO | K13: ='RESUMEN TOTAL'!P16 -> 0 | L13: ='RESUMEN TOTAL'!Q16 -> APAGADO | M13: ='RESUMEN TOTAL'!R16 -> 0 | ... AI13: ='RESUMEN TOTAL'!AN16 -> 0
A14: ='RESUMEN TOTAL'!A17 -> CENTRO | B14: ='RESUMEN TOTAL'!B17 -> CEN01 | C14: ='RESUMEN TOTAL'!D17 -> San Martin y 9 de Julio | D14: ='RESUMEN TOTAL'!E17 -> Fija | E14: ='RESUMEN TOTAL'!F17 -> Fibra Optica | F14: ='RESUMEN TOTAL'!K17 -> 0 | G14: ='RESUMEN TOTAL'!L17 -> 0 | H14: ='RESUMEN TOTAL'!M17 -> APAGADO | I14: ='RESUMEN TOTAL'!N17 -> 0 | J14: ='RESUMEN TOTAL'!O17 -> 0 | K14: ='RESUMEN TOTAL'!P17 -> 0 | L14: ='RESUMEN TOTAL'!Q17 -> 0 | M14: ='RESUMEN TOTAL'!R17 -> 0 | ... AI14: ='RESUMEN TOTAL'!AN17 -> 0
A15: ='RESUMEN TOTAL'!A18 -> CENTRO | B15: ='RESUMEN TOTAL'!B18 -> CEN02 | C15: ='RESUMEN TOTAL'!D18 -> San Martin y Almafuerte | D15: ='RESUMEN TOTAL'!E18 -> Fija | E15: ='RESUMEN TOTAL'!F18 -> Fibra Optica | F15: ='RESUMEN TOTAL'!K18 -> 0 | G15: ='RESUMEN TOTAL'!L18 -> 0 | H15: ='RESUMEN TOTAL'!M18 -> APAGADO | I15: ='RESUMEN TOTAL'!N18 -> 0 | J15: ='RESUMEN TOTAL'!O18 -> 0 | K15: ='RESUMEN TOTAL'!P18 -> 0 | L15: ='RESUMEN TOTAL'!Q18 -> 0 | M15: ='RESUMEN TOTAL'!R18 -> 0 | ... AI15: ='RESUMEN TOTAL'!AN18 -> 0
A16: ='RESUMEN TOTAL'!A19 -> CENTRO | B16: ='RESUMEN TOTAL'!B19 -> CEN03 | C16: ='RESUMEN TOTAL'!D19 -> San Martin y Sallares | D16: ='RESUMEN TOTAL'!E19 -> Domo | E16: ='RESUMEN TOTAL'!F19 -> Fibra Optica | F16: ='RESUMEN TOTAL'!K19 -> 0 | G16: ='RESUMEN TOTAL'!L19 -> 0 | H16: ='RESUMEN TOTAL'!M19 -> APAGADO | I16: ='RESUMEN TOTAL'!N19 -> 0 | J16: ='RESUMEN TOTAL'!O19 -> 0 | K16: ='RESUMEN TOTAL'!P19 -> 0 | L16: ='RESUMEN TOTAL'!Q19 -> 0 | M16: ='RESUMEN TOTAL'!R19 -> 0 | ... AI16: ='RESUMEN TOTAL'!AN19 -> 0
A17: ='RESUMEN TOTAL'!A20 -> CENTRO | B17: ='RESUMEN TOTAL'!B20 -> CEN04 | C17: ='RESUMEN TOTAL'!D20 -> San Martin y Contreras | D17: ='RESUMEN TOTAL'!E20 -> Domo | E17: ='RESUMEN TOTAL'!F20 -> Fibra Optica | F17: ='RESUMEN TOTAL'!K20 -> 0 | G17: ='RESUMEN TOTAL'!L20 -> 0 | H17: ='RESUMEN TOTAL'!M20 -> 0 | I17: ='RESUMEN TOTAL'!N20 -> 0 | J17: ='RESUMEN TOTAL'!O20 -> 0 | K17: ='RESUMEN TOTAL'!P20 -> 0 | L17: ='RESUMEN TOTAL'!Q20 -> 0 | M17: ='RESUMEN TOTAL'!R20 -> 0 | ... AI17: ='RESUMEN TOTAL'!AN20 -> 0
A18: ='RESUMEN TOTAL'!A21 -> CENTRO | B18: ='RESUMEN TOTAL'!B21 -> CEN 05 | C18: ='RESUMEN TOTAL'!D21 -> Bocuzzi e/España y San Martin | D18: ='RESUMEN TOTAL'!E21 -> DOMO | E18: ='RESUMEN TOTAL'!F21 -> Fibra Optica | F18: ='RESUMEN TOTAL'!K21 -> 0 | G18: ='RESUMEN TOTAL'!L21 -> 0 | H18: ='RESUMEN TOTAL'!M21 -> APAGADO | I18: ='RESUMEN TOTAL'!N21 -> 0 | J18: ='RESUMEN TOTAL'!O21 -> 0 | K18: ='RESUMEN TOTAL'!P21 -> 0 | L18: ='RESUMEN TOTAL'!Q21 -> 0 | M18: ='RESUMEN TOTAL'!R21 -> 0 | ... AI18: ='RESUMEN TOTAL'!AN21 -> 0
A19: ='RESUMEN TOTAL'!A22 -> CENTRO | B19: ='RESUMEN TOTAL'!B22 -> CEN06 | C19: ='RESUMEN TOTAL'!D22 -> Monteagudo y A.del Valle | D19: ='RESUMEN TOTAL'!E22 -> Fija | E19: ='RESUMEN TOTAL'!F22 -> Fibra Optica | F19: ='RESUMEN TOTAL'!K22 -> 0 | G19: ='RESUMEN TOTAL'!L22 -> 0 | H19: ='RESUMEN TOTAL'!M22 -> APAGADO | I19: ='RESUMEN TOTAL'!N22 -> 0 | J19: ='RESUMEN TOTAL'!O22 -> 0 | K19: ='RESUMEN TOTAL'!P22 -> 0 | L19: ='RESUMEN TOTAL'!Q22 -> 0 | M19: ='RESUMEN TOTAL'!R22 -> 0 | ... AI19: ='RESUMEN TOTAL'!AN22 -> 0
A20: ='RESUMEN TOTAL'!A23 -> CENTRO | B20: ='RESUMEN TOTAL'!B23 -> CEN07 | C20: ='RESUMEN TOTAL'!D23 -> San Martin y Guemes | D20: ='RESUMEN TOTAL'!E23 -> DOMO | E20: ='RESUMEN TOTAL'!F23 -> Fibra Optica | F20: ='RESUMEN TOTAL'!K23 -> 0 | G20: ='RESUMEN TOTAL'!L23 -> 0 | H20: ='RESUMEN TOTAL'!M23 -> APAGADO | I20: ='RESUMEN TOTAL'!N23 -> 0 | J20: ='RESUMEN TOTAL'!O23 -> 0 | K20: ='RESUMEN TOTAL'!P23 -> 0 | L20: ='RESUMEN TOTAL'!Q23 -> 0 | M20: ='RESUMEN TOTAL'!R23 -> 0 | ... AI20: ='RESUMEN TOTAL'!AN23 -> 0
A21: ='RESUMEN TOTAL'!A24 -> CENTRO | B21: ='RESUMEN TOTAL'!B24 -> CEN08 | C21: ='RESUMEN TOTAL'!D24 -> San Martin y Pte.Peron | D21: ='RESUMEN TOTAL'!E24 -> Domo | E21: ='RESUMEN TOTAL'!F24 -> Fibra Optica | F21: ='RESUMEN TOTAL'!K24 -> 0 | G21: ='RESUMEN TOTAL'!L24 -> 0 | H21: ='RESUMEN TOTAL'!M24 -> 0 | I21: ='RESUMEN TOTAL'!N24 -> 0 | J21: ='RESUMEN TOTAL'!O24 -> 0 | K21: ='RESUMEN TOTAL'!P24 -> 0 | L21: ='RESUMEN TOTAL'!Q24 -> 0 | M21: ='RESUMEN TOTAL'!R24 -> 0 | ... AI21: ='RESUMEN TOTAL'!AN24 -> 0
A22: ='RESUMEN TOTAL'!A25 -> CENTRO | B22: ='RESUMEN TOTAL'!B25 -> CEN09 | C22: ='RESUMEN TOTAL'!D25 -> Chacabuco y 25 de Mayo | D22: ='RESUMEN TOTAL'!E25 -> Domo | E22: ='RESUMEN TOTAL'!F25 -> Fibra Optica | F22: ='RESUMEN TOTAL'!K25 -> 0 | G22: ='RESUMEN TOTAL'!L25 -> 0 | H22: ='RESUMEN TOTAL'!M25 -> 0 | I22: ='RESUMEN TOTAL'!N25 -> 0 | J22: ='RESUMEN TOTAL'!O25 -> 0 | K22: ='RESUMEN TOTAL'!P25 -> 0 | L22: ='RESUMEN TOTAL'!Q25 -> 0 | M22: ='RESUMEN TOTAL'!R25 -> 0 | ... AI22: ='RESUMEN TOTAL'!AN25 -> 0
A23: ='RESUMEN TOTAL'!A26 -> CENTRO | B23: ='RESUMEN TOTAL'!B26 -> CEN10 | C23: ='RESUMEN TOTAL'!D26 -> Monteagudo y Pte. Peron | D23: ='RESUMEN TOTAL'!E26 -> Domo | E23: ='RESUMEN TOTAL'!F26 -> Fibra Optica | F23: ='RESUMEN TOTAL'!K26 -> 0 | G23: ='RESUMEN TOTAL'!L26 -> 0 | H23: ='RESUMEN TOTAL'!M26 -> APAGADO | I23: ='RESUMEN TOTAL'!N26 -> 0 | J23: ='RESUMEN TOTAL'!O26 -> 0 | K23: ='RESUMEN TOTAL'!P26 -> 0 | L23: ='RESUMEN TOTAL'!Q26 -> 0 | M23: ='RESUMEN TOTAL'!R26 -> 0 | ... AI23: ='RESUMEN TOTAL'!AN26 -> 0
... A39: ='RESUMEN TOTAL'!A42 -> CENTRO | B39: ='RESUMEN TOTAL'!B42 -> CEN26 | C39: ='RESUMEN TOTAL'!D42 -> Mitre y España | D39: ='RESUMEN TOTAL'!E42 -> Domo | E39: ='RESUMEN TOTAL'!F42 -> Fibra Optica | F39: ='RESUMEN TOTAL'!K42 -> APAGADO | G39: ='RESUMEN TOTAL'!L42 -> APAGADO | H39: ='RESUMEN TOTAL'!M42 -> APAGADO | I39: ='RESUMEN TOTAL'!N42 -> APAGADO | J39: ='RESUMEN TOTAL'!O42 -> APAGADO | K39: ='RESUMEN TOTAL'!P42 -> 0 | L39: ='RESUMEN TOTAL'!Q42 -> APAGADO | M39: ='RESUMEN TOTAL'!R42 -> 0 | ... AI39: ='RESUMEN TOTAL'!AN42 -> 0
A40: ='RESUMEN TOTAL'!A43 -> CENTRO | B40: ='RESUMEN TOTAL'!B43 -> CEN27 | C40: ='RESUMEN TOTAL'!D43 -> San Juan y España | D40: ='RESUMEN TOTAL'!E43 -> Domo | E40: ='RESUMEN TOTAL'!F43 -> Fibra Optica | F40: ='RESUMEN TOTAL'!K43 -> 0 | G40: ='RESUMEN TOTAL'!L43 -> 0 | H40: ='RESUMEN TOTAL'!M43 -> 0 | I40: ='RESUMEN TOTAL'!N43 -> 0 | J40: ='RESUMEN TOTAL'!O43 -> 0 | K40: ='RESUMEN TOTAL'!P43 -> 0 | L40: ='RESUMEN TOTAL'!Q43 -> 0 | M40: ='RESUMEN TOTAL'!R43 -> 0 | ... V40: ='RESUMEN TOTAL'!AA43 -> 0 | W40: ='RESUMEN TOTAL'!AB44 -> 0 | X40: ='RESUMEN TOTAL'!AC43 -> APAGADO | Y40: ='RESUMEN TOTAL'!AD43 -> APAGADO | Z40: ='RESUMEN TOTAL'!AE43 -> APAGADO | AA40: ='RESUMEN TOTAL'!AF43 -> APAGADO | AB40: ='RESUMEN TOTAL'!AG43 -> APAGADO | AC40: ='RESUMEN TOTAL'!AH43 -> 0 | AD40: ='RESUMEN TOTAL'!AI43 -> 0 | AE40: ='RESUMEN TOTAL'!AJ43 -> 0 | ... AI40: ='RESUMEN TOTAL'!AN43 -> 0
A41: ='RESUMEN TOTAL'!A44 -> CENTRO | B41: ='RESUMEN TOTAL'!B44 -> CEN28 | C41: ='RESUMEN TOTAL'!D44 -> Mitre y Alberdi | D41: ='RESUMEN TOTAL'!E44 -> Domo | E41: ='RESUMEN TOTAL'!F44 -> Fibra Optica | F41: ='RESUMEN TOTAL'!K44 -> 0 | G41: ='RESUMEN TOTAL'!L44 -> 0 | H41: ='RESUMEN TOTAL'!M44 -> APAGADO | I41: ='RESUMEN TOTAL'!N44 -> 0 | J41: ='RESUMEN TOTAL'!O44 -> 0 | K41: ='RESUMEN TOTAL'!P44 -> 0 | L41: ='RESUMEN TOTAL'!Q44 -> 0 | M41: ='RESUMEN TOTAL'!R44 -> 0 | ... V41: ='RESUMEN TOTAL'!AA44 -> 0 | W41: ='RESUMEN TOTAL'!AB45 -> APAGADO | X41: ='RESUMEN TOTAL'!AC44 -> 0 | Y41: ='RESUMEN TOTAL'!AD44 -> 0 | Z41: ='RESUMEN TOTAL'!AE44 -> 0 | AA41: ='RESUMEN TOTAL'!AF44 -> 0 | AB41: ='RESUMEN TOTAL'!AG44 -> 0 | AC41: ='RESUMEN TOTAL'!AH44 -> 0 | AD41: ='RESUMEN TOTAL'!AI44 -> 0 | AE41: ='RESUMEN TOTAL'!AJ44 -> 0 | ... AI41: ='RESUMEN TOTAL'!AN44 -> 0
A42: ='RESUMEN TOTAL'!A45 -> CENTRO | B42: ='RESUMEN TOTAL'!B45 -> CEN29 | C42: ='RESUMEN TOTAL'!D45 -> Alberdi y San Juan | D42: ='RESUMEN TOTAL'!E45 -> Domo | E42: ='RESUMEN TOTAL'!F45 -> Fibra Optica | F42: ='RESUMEN TOTAL'!K45 -> 0 | G42: ='RESUMEN TOTAL'!L45 -> 0 | H42: ='RESUMEN TOTAL'!M45 -> APAGADO | I42: ='RESUMEN TOTAL'!N45 -> 0 | J42: ='RESUMEN TOTAL'!O45 -> 0 | K42: ='RESUMEN TOTAL'!P45 -> 0 | L42: ='RESUMEN TOTAL'!Q45 -> 0 | M42: ='RESUMEN TOTAL'!R45 -> 0 | ... V42: ='RESUMEN TOTAL'!AA45 -> 0 | W42: ='RESUMEN TOTAL'!#REF! -> #REF! | X42: ='RESUMEN TOTAL'!AC45 -> APAGADO | Y42: ='RESUMEN TOTAL'!AD45 -> APAGADO | Z42: ='RESUMEN TOTAL'!AE45 -> APAGADO | AA42: ='RESUMEN TOTAL'!AF45 -> APAGADO | AB42: ='RESUMEN TOTAL'!AG45 -> APAGADO | AC42: ='RESUMEN TOTAL'!AH45 -> 0 | AD42: ='RESUMEN TOTAL'!AI45 -> 0 | AE42: ='RESUMEN TOTAL'!AJ45 -> 0 | ... AI42: ='RESUMEN TOTAL'!AN45 -> 0
A43: ='RESUMEN TOTAL'!A46 -> CENTRO | B43: ='RESUMEN TOTAL'!B46 -> CEN30 | C43: ='RESUMEN TOTAL'!D46 -> Mitre y Pringles | D43: ='RESUMEN TOTAL'!E46 -> Domo | E43: ='RESUMEN TOTAL'!F46 -> Fibra Optica | F43: ='RESUMEN TOTAL'!K46 -> 0 | G43: ='RESUMEN TOTAL'!L46 -> 0 | H43: ='RESUMEN TOTAL'!M46 -> APAGADO | I43: ='RESUMEN TOTAL'!N46 -> 0 | J43: ='RESUMEN TOTAL'!O46 -> 0 | K43: ='RESUMEN TOTAL'!P46 -> 0 | L43: ='RESUMEN TOTAL'!Q46 -> 0 | M43: ='RESUMEN TOTAL'!R46 -> 0 | ... AI43: ='RESUMEN TOTAL'!AN46 -> 0
A44: ='RESUMEN TOTAL'!A47 -> CENTRO | B44: ='RESUMEN TOTAL'!B47 -> CEN31 | C44: ='RESUMEN TOTAL'!D47 -> Mitre e/Monteagudo y Alberdi | D44: ='RESUMEN TOTAL'!E47 -> Domo | E44: ='RESUMEN TOTAL'!F47 -> Fibra Optica | F44: ='RESUMEN TOTAL'!K47 -> 0 | G44: ='RESUMEN TOTAL'!L47 -> 0 | H44: ='RESUMEN TOTAL'!M47 -> APAGADO | I44: ='RESUMEN TOTAL'!N47 -> 0 | J44: ='RESUMEN TOTAL'!O47 -> 0 | K44: ='RESUMEN TOTAL'!P47 -> 0 | L44: ='RESUMEN TOTAL'!Q47 -> 0 | M44: ='RESUMEN TOTAL'!R47 -> 0 | ... AI44: ='RESUMEN TOTAL'!AN47 -> 0
A45: ='RESUMEN TOTAL'!A48 -> CENTRO | B45: ='RESUMEN TOTAL'!B48 -> CEN32 | C45: ='RESUMEN TOTAL'!D48 -> Aristobulo del Valle y España | D45: ='RESUMEN TOTAL'!E48 -> Domo | E45: ='RESUMEN TOTAL'!F48 -> Fibra Optica | F45: ='RESUMEN TOTAL'!K48 -> 0 | G45: ='RESUMEN TOTAL'!L48 -> 0 | H45: ='RESUMEN TOTAL'!M48 -> APAGADO | I45: ='RESUMEN TOTAL'!N48 -> 0 | J45: ='RESUMEN TOTAL'!O48 -> 0 | K45: ='RESUMEN TOTAL'!P48 -> 0 | L45: ='RESUMEN TOTAL'!Q48 -> 0 | M45: ='RESUMEN TOTAL'!R48 -> 0 | ... AI45: ='RESUMEN TOTAL'!AN48 -> 0
A46: ='RESUMEN TOTAL'!A49 -> CENTRO | B46: ='RESUMEN TOTAL'!B49 -> CEN33 | C46: ='RESUMEN TOTAL'!D49 -> Peron y Alberdi | D46: ='RESUMEN TOTAL'!E49 -> Domo | E46: ='RESUMEN TOTAL'!F49 -> Fibra Optica | F46: ='RESUMEN TOTAL'!K49 -> 0 | G46: ='RESUMEN TOTAL'!L49 -> 0 | H46: ='RESUMEN TOTAL'!M49 -> APAGADO | I46: ='RESUMEN TOTAL'!N49 -> 0 | J46: ='RESUMEN TOTAL'!O49 -> 0 | K46: ='RESUMEN TOTAL'!P49 -> 0 | L46: ='RESUMEN TOTAL'!Q49 -> 0 | M46: ='RESUMEN TOTAL'!R49 -> 0 | ... AI46: ='RESUMEN TOTAL'!AN49 -> 0
A47: ='RESUMEN TOTAL'!A50 -> CENTRO | B47: ='RESUMEN TOTAL'!B50 -> CEN34 | C47: ='RESUMEN TOTAL'!D50 -> Peron y España | D47: ='RESUMEN TOTAL'!E50 -> Domo | E47: ='RESUMEN TOTAL'!F50 -> Fibra Optica | F47: ='RESUMEN TOTAL'!K50 -> 0 | G47: ='RESUMEN TOTAL'!L50 -> 0 | H47: ='RESUMEN TOTAL'!M50 -> APAGADO | I47: ='RESUMEN TOTAL'!N50 -> APAGADO | J47: ='RESUMEN TOTAL'!O50 -> APAGADO | K47: ='RESUMEN TOTAL'!P50 -> 0 | L47: ='RESUMEN TOTAL'!Q50 -> APAGADO | M47: ='RESUMEN TOTAL'!R50 -> 0 | ... AI47: ='RESUMEN TOTAL'!AN50 -> 0
A48: ='RESUMEN TOTAL'!A51 -> CENTRO | B48: ='RESUMEN TOTAL'!B51 -> CEN35 | C48: ='RESUMEN TOTAL'!D51 -> España y Marmol | D48: ='RESUMEN TOTAL'!E51 -> Domo | E48: ='RESUMEN TOTAL'!F51 -> Fibra Optica | F48: ='RESUMEN TOTAL'!K51 -> 0 | G48: ='RESUMEN TOTAL'!L51 -> 0 | H48: ='RESUMEN TOTAL'!M51 -> APAGADO | I48: ='RESUMEN TOTAL'!N51 -> 0 | J48: ='RESUMEN TOTAL'!O51 -> 0 | K48: ='RESUMEN TOTAL'!P51 -> 0 | L48: ='RESUMEN TOTAL'!Q51 -> 0 | M48: ='RESUMEN TOTAL'!R51 -> 0 | ... AI48: ='RESUMEN TOTAL'!AN51 -> 0
A49: ='RESUMEN TOTAL'!A52 -> CENTRO | B49: ='RESUMEN TOTAL'!B52 -> CEN36 | C49: ='RESUMEN TOTAL'!D52 -> España y 9 de Julio | D49: ='RESUMEN TOTAL'!E52 -> Domo | E49: ='RESUMEN TOTAL'!F52 -> Fibra Optica | F49: ='RESUMEN TOTAL'!K52 -> 0 | G49: ='RESUMEN TOTAL'!L52 -> 0 | H49: ='RESUMEN TOTAL'!M52 -> 0 | I49: ='RESUMEN TOTAL'!N52 -> 0 | J49: ='RESUMEN TOTAL'!O52 -> 0 | K49: ='RESUMEN TOTAL'!P52 -> 0 | L49: ='RESUMEN TOTAL'!Q52 -> 0 | M49: ='RESUMEN TOTAL'!R52 -> 0 | ... AI49: ='RESUMEN TOTAL'!AN52 -> 0
A50: ='RESUMEN TOTAL'!A53 -> CENTRO | B50: ='RESUMEN TOTAL'!B53 -> CEN 37 | C50: ='RESUMEN TOTAL'!D53 -> Diagonal Granaderos y Monteagudo | D50: ='RESUMEN TOTAL'!E53 -> Domo | E50: ='RESUMEN TOTAL'!F53 -> Fibra Optica | F50: ='RESUMEN TOTAL'!K53 -> 0 | G50: ='RESUMEN TOTAL'!L53 -> 0 | H50: ='RESUMEN TOTAL'!M53 -> APAGADO | I50: ='RESUMEN TOTAL'!N53 -> 0 | J50: ='RESUMEN TOTAL'!O53 -> 0 | K50: ='RESUMEN TOTAL'!P53 -> 0 | L50: ='RESUMEN TOTAL'!Q53 -> 0 | M50: ='RESUMEN TOTAL'!R53 -> 0 | ... AI50: ='RESUMEN TOTAL'!AN53 -> 0
A51: ='RESUMEN TOTAL'!A54 -> CENTRO | B51: ='RESUMEN TOTAL'!B54 -> CEN38 | C51: ='RESUMEN TOTAL'!D54 -> Diagonal Constituyentes y Almafuerte | D51: ='RESUMEN TOTAL'!E54 -> Domo | E51: ='RESUMEN TOTAL'!F54 -> Fibra Optica | F51: ='RESUMEN TOTAL'!K54 -> 0 | G51: ='RESUMEN TOTAL'!L54 -> 0 | H51: ='RESUMEN TOTAL'!M54 -> 0 | I51: ='RESUMEN TOTAL'!N54 -> 0 | J51: ='RESUMEN TOTAL'!O54 -> 0 | K51: ='RESUMEN TOTAL'!P54 -> 0 | L51: ='RESUMEN TOTAL'!Q54 -> 0 | M51: ='RESUMEN TOTAL'!R54 -> 0 | ... AI51: ='RESUMEN TOTAL'!AN54 -> 0
A52: ='RESUMEN TOTAL'!A55 -> CENTRO | B52: ='RESUMEN TOTAL'!B55 -> CEN39 | C52: ='RESUMEN TOTAL'!D55 -> San Martin y Alem | D52: ='RESUMEN TOTAL'!E55 -> Domo | E52: ='RESUMEN TOTAL'!F55 -> Fibra Optica | F52: ='RESUMEN TOTAL'!K55 -> 0 | G52: ='RESUMEN TOTAL'!L55 -> 0 | H52: ='RESUMEN TOTAL'!M55 -> APAGADO | I52: ='RESUMEN TOTAL'!N55 -> 0 | J52: ='RESUMEN TOTAL'!O55 -> 0 | K52: ='RESUMEN TOTAL'!P55 -> 0 | L52: ='RESUMEN TOTAL'!Q55 -> 0 | M52: ='RESUMEN TOTAL'!R55 -> 0 | ... AI52: ='RESUMEN TOTAL'!AN55 -> 0
A53: ='RESUMEN TOTAL'!A56 -> CENTRO | B53: ='RESUMEN TOTAL'!B56 -> CEN40 | C53: ='RESUMEN TOTAL'!D56 -> Contreras y Monteagudo | D53: ='RESUMEN TOTAL'!E56 -> Domo | E53: ='RESUMEN TOTAL'!F56 -> Fibra Optica | F53: ='RESUMEN TOTAL'!K56 -> 0 | G53: ='RESUMEN TOTAL'!L56 -> 0 | H53: ='RESUMEN TOTAL'!M56 -> 0 | I53: ='RESUMEN TOTAL'!N56 -> 0 | J53: ='RESUMEN TOTAL'!O56 -> 0 | K53: ='RESUMEN TOTAL'!P56 -> 0 | L53: ='RESUMEN TOTAL'!Q56 -> 0 | M53: ='RESUMEN TOTAL'!R56 -> 0 | ... AI53: ='RESUMEN TOTAL'!AN56 -> 0
A54: ='RESUMEN TOTAL'!A57 -> CENTRO | B54: ='RESUMEN TOTAL'!B57 -> CEN41 | C54: ='RESUMEN TOTAL'!D57 -> Contreras y Alberdi | D54: ='RESUMEN TOTAL'!E57 -> Domo | E54: ='RESUMEN TOTAL'!F57 -> Fibra Optica | F54: ='RESUMEN TOTAL'!K57 -> 0 | G54: ='RESUMEN TOTAL'!L57 -> 0 | H54: ='RESUMEN TOTAL'!M57 -> 0 | I54: ='RESUMEN TOTAL'!N57 -> 0 | J54: ='RESUMEN TOTAL'!O57 -> 0 | K54: ='RESUMEN TOTAL'!P57 -> 0 | L54: ='RESUMEN TOTAL'!Q57 -> 0 | M54: ='RESUMEN TOTAL'!R57 -> 0 | ... AI54: ='RESUMEN TOTAL'!AN57 -> 0
... A123: ='RESUMEN TOTAL'!A126 -> LA ESMERALDA | B123: ='RESUMEN TOTAL'!B126 -> ESM12 (fija 2) | C123: ='RESUMEN TOTAL'!D126 -> NOVAK Y LAMBARDI | D123: ='RESUMEN TOTAL'!E126 -> Fija | E123: ='RESUMEN TOTAL'!F126 -> Fibra Optica | F123: ='RESUMEN TOTAL'!K126 -> 0 | G123: ='RESUMEN TOTAL'!L126 -> 0 | H123: ='RESUMEN TOTAL'!M126 -> 0 | I123: ='RESUMEN TOTAL'!N126 -> 0 | J123: ='RESUMEN TOTAL'!O126 -> 0 | K123: ='RESUMEN TOTAL'!P126 -> 0 | L123: ='RESUMEN TOTAL'!Q126 -> 0 | M123: ='RESUMEN TOTAL'!R126 -> 0 | ... AI123: ='RESUMEN TOTAL'!AN126 -> 0
...

Sheet APAGADOS
E1: APAGADOS | F1: =COUNTIF(F3:F400, "APAGADO") -> 39 | G1: =COUNTIF(G3:G400, "APAGADO") -> 39 | H1: =COUNTIF(H3:H400, "APAGADO") -> 153 | I1: =COUNTIF(I3:I400, "APAGADO") -> 43 | J1: =COUNTIF(J3:J400, "APAGADO") -> 37 | K1: =COUNTIF(K3:K400, "APAGADO") -> 0 | L1: =COUNTIF(L3:L400, "APAGADO") -> 35 | M1: =COUNTIF(M3:M400, "APAGADO") -> 0 | ... AI1: =COUNTIF(AI3:AI400, "APAGADO") -> 0
A2: =ESTADISTICA!A1 -> Barrio | B2: =ESTADISTICA!B1 -> [Denominacion] | C2: =ESTADISTICA!C1 -> [Ubicacion] | D2: =ESTADISTICA!D1 -> [Tipo de Camara] | E2: =ESTADISTICA!E1 -> [Tipo de Conexion] | F2: =ESTADISTICA!F1 -> 44835 | G2: =ESTADISTICA!G1 -> 44836 | H2: =ESTADISTICA!H1 -> 44837 | ... AI2: =ESTADISTICA!AI1 -> 44864
A3: =ESTADISTICA!A2 -> ALTAMIRA | B3: =ESTADISTICA!B2 -> ALT01 | C3: =ESTADISTICA!C2 -> Calchaqui y Sgto. Cabral | D3: =ESTADISTICA!D2 -> Domo | E3: =ESTADISTICA!E2 -> Fibra Optica | F3: =ESTADISTICA!F2 -> 0 | G3: =ESTADISTICA!G2 -> 0 | H3: =ESTADISTICA!H2 -> APAGADO | ... AI3: =ESTADISTICA!AI2 -> 0
A4: =ESTADISTICA!A3 -> ALTAMIRA | B4: =ESTADISTICA!B3 -> ALT02 | C4: =ESTADISTICA!C3 -> Calchaqui y Lope de Vega | D4: =ESTADISTICA!D3 -> Domo | E4: =ESTADISTICA!E3 -> PTO A FO | F4: =ESTADISTICA!F3 -> 0 | G4: =ESTADISTICA!G3 -> 0 | H4: =ESTADISTICA!H3 -> APAGADO | ... AI4: =ESTADISTICA!AI3 -> 0
A5: =ESTADISTICA!A4 -> ALTAMIRA | B5: =ESTADISTICA!B4 -> ALT 03 | C5: =ESTADISTICA!C4 -> Bombero Galarza y Necochea | D5: =ESTADISTICA!D4 -> Domo | E5: =ESTADISTICA!E4 -> FIBRA OPTICA | F5: =ESTADISTICA!F4 -> 0 | G5: =ESTADISTICA!G4 -> 0 | H5: =ESTADISTICA!H4 -> 0 | ... AI5: =ESTADISTICA!AI4 -> 0
A6: =ESTADISTICA!A5 -> ALTAMIRA | B6: =ESTADISTICA!B5 -> ALT 04 | C6: =ESTADISTICA!C5 -> Francia y Necochea | D6: =ESTADISTICA!D5 -> Domo | E6: =ESTADISTICA!E5 -> FIBRA OPTICA | F6: =ESTADISTICA!F5 -> APAGADO | G6: =ESTADISTICA!G5 -> APAGADO | H6: =ESTADISTICA!H5 -> APAGADO | ... AI6: =ESTADISTICA!AI5 -> 0
A7: =ESTADISTICA!A6 -> ALTAMIRA | B7: =ESTADISTICA!B6 -> ALT05 | C7: =ESTADISTICA!C6 -> Av. Calchaqui y Bombero Galarza | D7: =ESTADISTICA!D6 -> Domo | E7: =ESTADISTICA!E6 -> PTO A FO | F7: =ESTADISTICA!F6 -> APAGADO | G7: =ESTADISTICA!G6 -> APAGADO | H7: =ESTADISTICA!H6 -> APAGADO | ... AI7: =ESTADISTICA!AI6 -> 0
A8: =ESTADISTICA!A7 -> ALTAMIRA | B8: =ESTADISTICA!B7 -> ALT 06 | C8: =ESTADISTICA!C7 -> LOPE DE VEGA Y NECOCHEA | D8: =ESTADISTICA!D7 -> Domo | E8: =ESTADISTICA!E7 -> PTO A FO | F8: =ESTADISTICA!F7 -> 0 | G8: =ESTADISTICA!G7 -> 0 | H8: =ESTADISTICA!H7 -> APAGADO | ... AI8: =ESTADISTICA!AI7 -> 0
A9: =ESTADISTICA!A8 -> ALTAMIRA | B9: =ESTADISTICA!B8 -> ALT07 | C9: =ESTADISTICA!C8 -> AV. CALCHAQUI Y AV. DEL TRABAJO | D9: =ESTADISTICA!D8 -> DOMO | E9: =ESTADISTICA!E8 -> PTO A FO | F9: =ESTADISTICA!F8 -> 0 | G9: =ESTADISTICA!G8 -> 0 | H9: =ESTADISTICA!H8 -> 0 | ... AI9: =ESTADISTICA!AI8 -> 0
A10: =ESTADISTICA!A9 -> ALTAMIRA | B10: =ESTADISTICA!B9 -> ALT 08 | C10: =ESTADISTICA!C9 -> HUMAITA Y NECOCHEA | D10: =ESTADISTICA!D9 -> DOMO | E10: =ESTADISTICA!E9 -> Fibra Optica | F10: =ESTADISTICA!F9 -> 0 | G10: =ESTADISTICA!G9 -> 0 | H10: =ESTADISTICA!H9 -> 0 | ... AI10: =ESTADISTICA!AI9 -> 0
A11: =ESTADISTICA!A10 -> ALTAMIRA | B11: =ESTADISTICA!B10 -> ALT 09 | C11: =ESTADISTICA!C10 -> NECOCHEA Y CURUPAITY | D11: =ESTADISTICA!D10 -> DOMO | E11: =ESTADISTICA!E10 -> Fibra Optica | F11: =ESTADISTICA!F10 -> 0 | G11: =ESTADISTICA!G10 -> 0 | H11: =ESTADISTICA!H10 -> 0 | ... AI11: =ESTADISTICA!AI10 -> 0
A12: =ESTADISTICA!A11 -> ALTAMIRA | B12: =ESTADISTICA!B11 -> ALT 10 | C12: =ESTADISTICA!C11 -> Calchaqui y Francia | D12: =ESTADISTICA!D11 -> Domo | E12: =ESTADISTICA!E11 -> Radio | F12: =ESTADISTICA!F11 -> APAGADO | G12: =ESTADISTICA!G11 -> APAGADO | H12: =ESTADISTICA!H11 -> APAGADO | ... AI12: =ESTADISTICA!AI11 -> 0
A13: =ESTADISTICA!A12 -> AGUSTIN RAMIREZ | B13: =ESTADISTICA!B12 -> ARA 01 | C13: =ESTADISTICA!C12 -> Malambo y Tranquera | D13: =ESTADISTICA!D12 -> Domo | E13: =ESTADISTICA!E12 -> FIBRA OPTICA | F13: =ESTADISTICA!F12 -> 0 | G13: =ESTADISTICA!G12 -> 0 | H13: =ESTADISTICA!H12 -> APAGADO | ... AI13: =ESTADISTICA!AI12 -> 0
... A401: =ESTADISTICA!A400 -> VILLA MONICA VIEJA | B401: =ESTADISTICA!B400 -> VMOV 03 (fija 1) | C401: =ESTADISTICA!C400 -> ROMA E/ HOLANDA Y CAFFERATA | D401: =ESTADISTICA!D400 -> Fija | E401: =ESTADISTICA!E400 -> Fibra Optica | F401: =ESTADISTICA!F400 -> 0 | G401: =ESTADISTICA!G400 -> 0 | H401: =ESTADISTICA!H400 -> 0 | ... AI401: =ESTADISTICA!AI400 -> 0

Sheet APAGADOS FIBRA
C1: TOTAL FIBRA | D1: =COUNTIFS(E4:E400,"=Fibra Optica") -> 271
E2: APAGADOS | F2: =COUNTIFS(F4:F400, "=APAGADO",E4:E400,"=Fibra Optica") -> 32 | G2: =COUNTIFS(G4:G400, "=APAGADO",E4:E400,"=Fibra Optica") -> 34 | H2: =COUNTIFS(H4:H400, "=APAGADO",E4:E400,"=Fibra Optica") -> 95 | I2: =COUNTIFS(I4:I400, "=APAGADO",E4:E400,"=Fibra Optica") -> 34 | J2: =COUNTIFS(J4:J400, "=APAGADO",E4:E400,"=Fibra Optica") -> 31 | K2: =COUNTIFS(K4:K400, "=APAGADO",E4:E400,"=Fibra Optica") -> 0 | L2: =COUNTIFS(L4:L400, "=APAGADO",E4:E400,"=Fibra Optica") -> 30 | M2: =COUNTIFS(M4:M400, "=APAGADO",E4:E400,"=Fibra Optica") -> 0 | N2: =COUNTIFS(N4:N400, "=APAGADO",E4:E400,"=Fibra Optica") -> 38 | O2: =COUNTIFS(O4:O400, "=APAGADO",E4:E400,"=Fibra Optica") -> 35 | P2: =COUNTIFS(P4:P400, "=APAGADO",E4:E400,"=Fibra Optica") -> 35 | Q2: =COUNTIFS(Q4:Q400, "=APAGADO",E4:E400,"=Fibra Optica") -> 30 | R2: =COUNTIFS(R4:R400, "=APAGADO",E4:E400,"=Fibra Optica") -> 41 | S2: =COUNTIFS(S4:S400, "=APAGADO",E4:E400,"=Fibra Optica") -> 28 | T2: =COUNTIFS(T4:T400, "=APAGADO",E4:E400,"=Fibra Optica") -> 25 | U2: =COUNTIFS(U4:U400, "=APAGADO",E4:E400,"=Fibra Optica") -> 47 | V2: =COUNTIFS(V4:V400, "=APAGADO",E4:E400,"=Fibra Optica") -> 0 | W2: =COUNTIFS(W4:W400, "=APAGADO",E4:E400,"=Fibra Optica") -> 39 | X2: =COUNTIFS(X4:X400, "=APAGADO",E4:E400,"=Fibra Optica") -> 76 | Y2: =COUNTIFS(Y4:Y400, "=APAGADO",E4:E400,"=Fibra Optica") -> 41 | Z2: =COUNTIFS(Z4:Z400, "=APAGADO",E4:E400,"=Fibra Optica") -> 36 | AA2: =COUNTIFS(AA4:AA400, "=APAGADO",E4:E400,"=Fibra Optica") -> 34 | AB2: =COUNTIFS(AB4:AB400, "=APAGADO",E4:E400,"=Fibra Optica") -> 41 | AC2: =COUNTIFS(AC4:AC400, "=APAGADO",E4:E400,"=Fibra Optica") -> 0 | AD2: =COUNTIFS(AD4:AD400, "=APAGADO",E4:E400,"=Fibra Optica") -> 0 | AE2: =COUNTIFS(AE4:AE400, "=APAGADO",E4:E400,"=Fibra Optica") -> 0 | AF2: =COUNTIFS(AF4:AF400, "=APAGADO",E4:E400,"=Fibra Optica") -> 0 | AG2: =COUNTIFS(AG4:AG400, "=APAGADO",E4:E400,"=Fibra Optica") -> 0 | AH2: =COUNTIFS(AH4:AH400, "=APAGADO",E4:E400,"=Fibra Optica") -> 0 | AI2: =COUNTIFS(AI4:AI400, "=APAGADO",E4:E400,"=Fibra Optica") -> 0
A3: =ESTADISTICA!A1 -> Barrio | B3: =ESTADISTICA!B1 -> [Denominacion] | C3: =ESTADISTICA!C1 -> [Ubicacion] | D3: =ESTADISTICA!D1 -> [Tipo de Camara] | E3: =ESTADISTICA!E1 -> [Tipo de Conexion] | F3: =ESTADISTICA!F1 -> 44835 | G3: =ESTADISTICA!G1 -> 44836 | H3: =ESTADISTICA!H1 -> 44837 | ... AI3: =ESTADISTICA!AI1 -> 44864
A4: =ESTADISTICA!A2 -> ALTAMIRA | B4: =ESTADISTICA!B2 -> ALT01 | C4: =ESTADISTICA!C2 -> Calchaqui y Sgto. Cabral | D4: =ESTADISTICA!D2 -> Domo | E4: =ESTADISTICA!E2 -> Fibra Optica | F4: =ESTADISTICA!F2 -> 0 | G4: =ESTADISTICA!G2 -> 0 | H4: =ESTADISTICA!H2 -> APAGADO | ... AI4: =ESTADISTICA!AI2 -> 0
A5: =ESTADISTICA!A3 -> ALTAMIRA | B5: =ESTADISTICA!B3 -> ALT02 | C5: =ESTADISTICA!C3 -> Calchaqui y Lope de Vega | D5: =ESTADISTICA!D3 -> Domo | E5: =ESTADISTICA!E3 -> PTO A FO | F5: =ESTADISTICA!F3 -> 0 | G5: =ESTADISTICA!G3 -> 0 | H5: =ESTADISTICA!H3 -> APAGADO | ... AI5: =ESTADISTICA!AI3 -> 0
A6: =ESTADISTICA!A4 -> ALTAMIRA | B6: =ESTADISTICA!B4 -> ALT 03 | C6: =ESTADISTICA!C4 -> Bombero Galarza y Necochea | D6: =ESTADISTICA!D4 -> Domo | E6: =ESTADISTICA!E4 -> FIBRA OPTICA | F6: =ESTADISTICA!F4 -> 0 | G6: =ESTADISTICA!G4 -> 0 | H6: =ESTADISTICA!H4 -> 0 | ... AI6: =ESTADISTICA!AI4 -> 0
A7: =ESTADISTICA!A5 -> ALTAMIRA | B7: =ESTADISTICA!B5 -> ALT 04 | C7: =ESTADISTICA!C5 -> Francia y Necochea | D7: =ESTADISTICA!D5 -> Domo | E7: =ESTADISTICA!E5 -> FIBRA OPTICA | F7: =ESTADISTICA!F5 -> APAGADO | G7: =ESTADISTICA!G5 -> APAGADO | H7: =ESTADISTICA!H5 -> APAGADO | ... AI7: =ESTADISTICA!AI5 -> 0
A8: =ESTADISTICA!A6 -> ALTAMIRA | B8: =ESTADISTICA!B6 -> ALT05 | C8: =ESTADISTICA!C6 -> Av. Calchaqui y Bombero Galarza | D8: =ESTADISTICA!D6 -> Domo | E8: =ESTADISTICA!E6 -> PTO A FO | F8: =ESTADISTICA!F6 -> APAGADO | G8: =ESTADISTICA!G6 -> APAGADO | H8: =ESTADISTICA!H6 -> APAGADO | ... AI8: =ESTADISTICA!AI6 -> 0
A9: =ESTADISTICA!A7 -> ALTAMIRA | B9: =ESTADISTICA!B7 -> ALT 06 | C9: =ESTADISTICA!C7 -> LOPE DE VEGA Y NECOCHEA | D9: =ESTADISTICA!D7 -> Domo | E9: =ESTADISTICA!E7 -> PTO A FO | F9: =ESTADISTICA!F7 -> 0 | G9: =ESTADISTICA!G7 -> 0 | H9: =ESTADISTICA!H7 -> APAGADO | ... AI9: =ESTADISTICA!AI7 -> 0
A10: =ESTADISTICA!A8 -> ALTAMIRA | B10: =ESTADISTICA!B8 -> ALT07 | C10: =ESTADISTICA!C8 -> AV. CALCHAQUI Y AV. DEL TRABAJO | D10: =ESTADISTICA!D8 -> DOMO | E10: =ESTADISTICA!E8 -> PTO A FO | F10: =ESTADISTICA!F8 -> 0 | G10: =ESTADISTICA!G8 -> 0 | H10: =ESTADISTICA!H8 -> 0 | ... AI10: =ESTADISTICA!AI8 -> 0
A11: =ESTADISTICA!A9 -> ALTAMIRA | B11: =ESTADISTICA!B9 -> ALT 08 | C11: =ESTADISTICA!C9 -> HUMAITA Y NECOCHEA | D11: =ESTADISTICA!D9 -> DOMO | E11: =ESTADISTICA!E9 -> Fibra Optica | F11: =ESTADISTICA!F9 -> 0 | G11: =ESTADISTICA!G9 -> 0 | H11: =ESTADISTICA!H9 -> 0 | ... AI11: =ESTADISTICA!AI9 -> 0
A12: =ESTADISTICA!A10 -> ALTAMIRA | B12: =ESTADISTICA!B10 -> ALT 09 | C12: =ESTADISTICA!C10 -> NECOCHEA Y CURUPAITY | D12: =ESTADISTICA!D10 -> DOMO | E12: =ESTADISTICA!E10 -> Fibra Optica | F12: =ESTADISTICA!F10 -> 0 | G12: =ESTADISTICA!G10 -> 0 | H12: =ESTADISTICA!H10 -> 0 | ... AI12: =ESTADISTICA!AI10 -> 0
A13: =ESTADISTICA!A11 -> ALTAMIRA | B13: =ESTADISTICA!B11 -> ALT 10 | C13: =ESTADISTICA!C11 -> Calchaqui y Francia | D13: =ESTADISTICA!D11 -> Domo | E13: =ESTADISTICA!E11 -> Radio | F13: =ESTADISTICA!F11 -> APAGADO | G13: =ESTADISTICA!G11 -> APAGADO | H13: =ESTADISTICA!H11 -> APAGADO | ... AI13: =ESTADISTICA!AI11 -> 0
A14: =ESTADISTICA!A12 -> AGUSTIN RAMIREZ | B14: =ESTADISTICA!B12 -> ARA 01 | C14: =ESTADISTICA!C12 -> Malambo y Tranquera | D14: =ESTADISTICA!D12 -> Domo | E14: =ESTADISTICA!E12 -> FIBRA OPTICA | F14: =ESTADISTICA!F12 -> 0 | G14: =ESTADISTICA!G12 -> 0 | H14: =ESTADISTICA!H12 -> APAGADO | ... AI14: =ESTADISTICA!AI12 -> 0
... A400: =ESTADISTICA!A398 -> VILLA MONICA VIEJA | B400: =ESTADISTICA!B398 -> VMOV01 (fija 1) | C400: =ESTADISTICA!C398 -> ATENAS E/ CAFFERATA Y ALEMANIA | D400: =ESTADISTICA!D398 -> Fija | E400: =ESTADISTICA!E398 -> Fibra Optica | F400: =ESTADISTICA!F398 -> 0 | G400: =ESTADISTICA!G398 -> 0 | H400: =ESTADISTICA!H398 -> 0 | ... AI400: =ESTADISTICA!AI398 -> 0

Sheet APAGADOS ANTENA
C1: TOTAL PTO A FO
E2: APAGADOS | F2: =COUNTIFS(F4:F400, "=APAGADO",E4:E400,"=PTO A FO") -> 3 | G2: =COUNTIFS(G4:G400, "=APAGADO",E4:E400,"=PTO A FO") -> 4 | H2: =COUNTIFS(H4:H400, "=APAGADO",E4:E400,"=PTO A FO") -> 17 | I2: =COUNTIFS(I4:I400, "=APAGADO",E4:E400,"=PTO A FO") -> 5 | J2: =COUNTIFS(J4:J400, "=APAGADO",E4:E400,"=PTO A FO") -> 4 | K2: =COUNTIFS(K4:K400, "=APAGADO",E4:E400,"=PTO A FO") -> 0 | L2: =COUNTIFS(L4:L400, "=APAGADO",E4:E400,"=PTO A FO") -> 4 | M2: =COUNTIFS(M4:M400, "=APAGADO",E4:E400,"=PTO A FO") -> 0 | N2: =COUNTIFS(N4:N400, "=APAGADO",E4:E400,"=PTO A FO") -> 5 | O2: =COUNTIFS(O4:O500, "=APAGADO",E4:E500,"=PTO A FO") -> 5 | P2: =COUNTIFS(P4:P400, "=APAGADO",E4:E400,"=PTO A FO") -> 4 | Q2: =COUNTIFS(Q4:Q400, "=APAGADO",E4:E400,"=PTO A FO") -> 4 | R2: =COUNTIFS(R4:R400, "=APAGADO",E4:E400,"=PTO A FO") -> 4 | S2: =COUNTIFS(S4:S400, "=APAGADO",E4:E400,"=PTO A FO") -> 4 | T2: =COUNTIFS(T4:T400, "=APAGADO",E4:E400,"=PTO A FO") -> 5 | U2: =COUNTIFS(U4:U400, "=APAGADO",E4:E400,"=PTO A FO") -> 7 | V2: =COUNTIFS(V4:V400, "=APAGADO",E4:E400,"=PTO A FO") -> 0 | W2: =COUNTIFS(W4:W400, "=APAGADO",E4:E400,"=PTO A FO") -> 3 | X2: =COUNTIFS(X4:X400, "=APAGADO",E4:E400,"=PTO A FO") -> 12 | Y2: =COUNTIFS(Y4:Y400, "=APAGADO",E4:E400,"=PTO A FO") -> 4 | Z2: =COUNTIFS(Z4:Z400, "=APAGADO",E4:E400,"=PTO A FO") -> 4 | AA2: =COUNTIFS(AA4:AA400, "=APAGADO",E4:E400,"=PTO A FO") -> 6 | AB2: =COUNTIFS(AB4:AB400, "=APAGADO",E4:E400,"=PTO A FO") -> 6 | AC2: =COUNTIFS(AC4:AC400, "=APAGADO",E4:E400,"=PTO A FO") -> 0 | AD2: =COUNTIFS(AD4:AD400, "=APAGADO",E4:E400,"=PTO A FO") -> 0 | AE2: =COUNTIFS(AE4:AE400, "=APAGADO",E4:E400,"=PTO A FO") -> 0 | AF2: =COUNTIFS(AF4:AF400, "=APAGADO",E4:E400,"=PTO A FO") -> 0 | AG2: =COUNTIFS(AG4:AG400, "=APAGADO",E4:E400,"=PTO A FO") -> 0 | AH2: =COUNTIFS(AH4:AH400, "=APAGADO",E4:E400,"=PTO A FO") -> 0 | AI2: =COUNTIFS(AI4:AI400, "=APAGADO",E4:E400,"=PTO A FO") -> 0
A3: =ESTADISTICA!A1 -> Barrio | B3: =ESTADISTICA!B1 -> [Denominacion] | C3: =ESTADISTICA!C1 -> [Ubicacion] | D3: =ESTADISTICA!D1 -> [Tipo de Camara] | E3: =ESTADISTICA!E1 -> [Tipo de Conexion] | F3: =ESTADISTICA!F1 -> 44835 | G3: =ESTADISTICA!G1 -> 44836 | H3: =ESTADISTICA!H1 -> 44837 | ... AI3: =ESTADISTICA!AI1 -> 44864
A4: =ESTADISTICA!A2 -> ALTAMIRA | B4: =ESTADISTICA!B2 -> ALT01 | C4: =ESTADISTICA!C2 -> Calchaqui y Sgto. Cabral | D4: =ESTADISTICA!D2 -> Domo | E4: =ESTADISTICA!E2 -> Fibra Optica | F4: =ESTADISTICA!F2 -> 0 | G4: =ESTADISTICA!G2 -> 0 | H4: =ESTADISTICA!H2 -> APAGADO | ... AI4: =ESTADISTICA!AI2 -> 0
A5: =ESTADISTICA!A3 -> ALTAMIRA | B5: =ESTADISTICA!B3 -> ALT02 | C5: =ESTADISTICA!C3 -> Calchaqui y Lope de Vega | D5: =ESTADISTICA!D3 -> Domo | E5: =ESTADISTICA!E3 -> PTO A FO | F5: =ESTADISTICA!F3 -> 0 | G5: =ESTADISTICA!G3 -> 0 | H5: =ESTADISTICA!H3 -> APAGADO | ... AI5: =ESTADISTICA!AI3 -> 0
A6: =ESTADISTICA!A4 -> ALTAMIRA | B6: =ESTADISTICA!B4 -> ALT 03 | C6: =ESTADISTICA!C4 -> Bombero Galarza y Necochea | D6: =ESTADISTICA!D4 -> Domo | E6: =ESTADISTICA!E4 -> FIBRA OPTICA | F6: =ESTADISTICA!F4 -> 0 | G6: =ESTADISTICA!G4 -> 0 | H6: =ESTADISTICA!H4 -> 0 | ... AI6: =ESTADISTICA!AI4 -> 0
A7: =ESTADISTICA!A5 -> ALTAMIRA | B7: =ESTADISTICA!B5 -> ALT 04 | C7: =ESTADISTICA!C5 -> Francia y Necochea | D7: =ESTADISTICA!D5 -> Domo | E7: =ESTADISTICA!E5 -> FIBRA OPTICA | F7: =ESTADISTICA!F5 -> APAGADO | G7: =ESTADISTICA!G5 -> APAGADO | H7: =ESTADISTICA!H5 -> APAGADO | ... AI7: =ESTADISTICA!AI5 -> 0
A8: =ESTADISTICA!A6 -> ALTAMIRA | B8: =ESTADISTICA!B6 -> ALT05 | C8: =ESTADISTICA!C6 -> Av. Calchaqui y Bombero Galarza | D8: =ESTADISTICA!D6 -> Domo | E8: =ESTADISTICA!E6 -> PTO A FO | F8: =ESTADISTICA!F6 -> APAGADO | G8: =ESTADISTICA!G6 -> APAGADO | H8: =ESTADISTICA!H6 -> APAGADO | ... AI8: =ESTADISTICA!AI6 -> 0
A9: =ESTADISTICA!A7 -> ALTAMIRA | B9: =ESTADISTICA!B7 -> ALT 06 | C9: =ESTADISTICA!C7 -> LOPE DE VEGA Y NECOCHEA | D9: =ESTADISTICA!D7 -> Domo | E9: =ESTADISTICA!E7 -> PTO A FO | F9: =ESTADISTICA!F7 -> 0 | G9: =ESTADISTICA!G7 -> 0 | H9: =ESTADISTICA!H7 -> APAGADO | ... AI9: =ESTADISTICA!AI7 -> 0
A10: =ESTADISTICA!A8 -> ALTAMIRA | B10: =ESTADISTICA!B8 -> ALT07 | C10: =ESTADISTICA!C8 -> AV. CALCHAQUI Y AV. DEL TRABAJO | D10: =ESTADISTICA!D8 -> DOMO | E10: =ESTADISTICA!E8 -> PTO A FO | F10: =ESTADISTICA!F8 -> 0 | G10: =ESTADISTICA!G8 -> 0 | H10: =ESTADISTICA!H8 -> 0 | ... AI10: =ESTADISTICA!AI8 -> 0
A11: =ESTADISTICA!A9 -> ALTAMIRA | B11: =ESTADISTICA!B9 -> ALT 08 | C11: =ESTADISTICA!C9 -> HUMAITA Y NECOCHEA | D11: =ESTADISTICA!D9 -> DOMO | E11: =ESTADISTICA!E9 -> Fibra Optica | F11: =ESTADISTICA!F9 -> 0 | G11: =ESTADISTICA!G9 -> 0 | H11: =ESTADISTICA!H9 -> 0 | ... AI11: =ESTADISTICA!AI9 -> 0
A12: =ESTADISTICA!A10 -> ALTAMIRA | B12: =ESTADISTICA!B10 -> ALT 09 | C12: =ESTADISTICA!C10 -> NECOCHEA Y CURUPAITY | D12: =ESTADISTICA!D10 -> DOMO | E12: =ESTADISTICA!E10 -> Fibra Optica | F12: =ESTADISTICA!F10 -> 0 | G12: =ESTADISTICA!G10 -> 0 | H12: =ESTADISTICA!H10 -> 0 | ... AI12: =ESTADISTICA!AI10 -> 0
A13: =ESTADISTICA!A11 -> ALTAMIRA | B13: =ESTADISTICA!B11 -> ALT 10 | C13: =ESTADISTICA!C11 -> Calchaqui y Francia | D13: =ESTADISTICA!D11 -> Domo | E13: =ESTADISTICA!E11 -> Radio | F13: =ESTADISTICA!F11 -> APAGADO | G13: =ESTADISTICA!G11 -> APAGADO | H13: =ESTADISTICA!H11 -> APAGADO | ... AI13: =ESTADISTICA!AI11 -> 0
A14: =ESTADISTICA!A12 -> AGUSTIN RAMIREZ | B14: =ESTADISTICA!B12 -> ARA 01 | C14: =ESTADISTICA!C12 -> Malambo y Tranquera | D14: =ESTADISTICA!D12 -> Domo | E14: =ESTADISTICA!E12 -> FIBRA OPTICA | F14: =ESTADISTICA!F12 -> 0 | G14: =ESTADISTICA!G12 -> 0 | H14: =ESTADISTICA!H12 -> APAGADO | ... AI14: =ESTADISTICA!AI12 -> 0
... A278: =ESTADISTICA!A276 -> LA SIRENA | B278: =ESTADISTICA!B276 -> SIR 14 | C278: =ESTADISTICA!C276 -> MANUEL IGLESIAS Y PEDRAZA | D278: =ESTADISTICA!D276 -> Domo | E278: =ESTADISTICA!E276 -> Fibra Optica | F278: =ESTADISTICA!F276 -> 0 | G278: =ESTADISTICA!G276 -> 0 | H278: =ESTADISTICA!H276 -> 0 | ... AI278: =ESTADISTICA!AI276 -> 0
B279: =ESTADISTICA!B277 -> SIR 15 | C279: =ESTADISTICA!C277 -> Monteverde y Azara | D279: =ESTADISTICA!D277 -> Domo | E279: =ESTADISTICA!E277 -> Fibra Optica | F279: =ESTADISTICA!F277 -> 0 | G279: =ESTADISTICA!G277 -> 0 | H279: =ESTADISTICA!H277 -> APAGADO | I279: =ESTADISTICA!I277 -> 0 | ... AI279: =ESTADISTICA!AI277 -> 0
A280: =ESTADISTICA!A278 -> SAN JORGE | B280: =ESTADISTICA!B278 -> SJO 03 | C280: =ESTADISTICA!C278 -> 517 Y 580 | D280: =ESTADISTICA!D278 -> DOMO | E280: =ESTADISTICA!E278 -> Radio | F280: =ESTADISTICA!F278 -> 0 | G280: =ESTADISTICA!G278 -> 0 | H280: =ESTADISTICA!H278 -> APAGADO | ... AI280: =ESTADISTICA!AI278 -> 0
A281: =ESTADISTICA!A279 -> SAN JORGE | B281: =ESTADISTICA!B279 -> SJO 04 | C281: =ESTADISTICA!C279 -> 552 Y 519 | D281: =ESTADISTICA!D279 -> DOMO | E281: =ESTADISTICA!E279 -> Radio | F281: =ESTADISTICA!F279 -> 0 | G281: =ESTADISTICA!G279 -> 0 | H281: =ESTADISTICA!H279 -> APAGADO | ... AI281: =ESTADISTICA!AI279 -> 0
A282: =ESTADISTICA!A280 -> SAN JORGE | B282: =ESTADISTICA!B280 -> SJO 09 (FIJA 1) | C282: =ESTADISTICA!C280 -> 515 Y 566 | D282: =ESTADISTICA!D280 -> Fija | E282: =ESTADISTICA!E280 -> Radio | F282: =ESTADISTICA!F280 -> 0 | G282: =ESTADISTICA!G280 -> 0 | H282: =ESTADISTICA!H280 -> APAGADO | ... AI282: =ESTADISTICA!AI280 -> 0
A283: =ESTADISTICA!A281 -> SAN JORGE | B283: =ESTADISTICA!B281 -> SJO 10 (FIJA 2) | C283: =ESTADISTICA!C281 -> 515 Y 566 | D283: =ESTADISTICA!D281 -> Fija | E283: =ESTADISTICA!E281 -> Radio | F283: =ESTADISTICA!F281 -> 0 | G283: =ESTADISTICA!G281 -> 0 | H283: =ESTADISTICA!H281 -> APAGADO | ... AI283: =ESTADISTICA!AI281 -> 0
A284: =ESTADISTICA!A282 -> SAN JORGE | B284: =ESTADISTICA!B282 -> SJO01 | C284: =ESTADISTICA!C282 -> Calle 554 y 527 | D284: =ESTADISTICA!D282 -> Domo | E284: =ESTADISTICA!E282 -> Radio | F284: =ESTADISTICA!F282 -> APAGADO | G284: =ESTADISTICA!G282 -> 0 | H284: =ESTADISTICA!H282 -> APAGADO | ... AI284: =ESTADISTICA!AI282 -> 0
A285: =ESTADISTICA!A283 -> SAN JORGE | B285: =ESTADISTICA!B283 -> SJO02 | C285: =ESTADISTICA!C283 -> Calle 554 y 511 | D285: =ESTADISTICA!D283 -> Domo | E285: =ESTADISTICA!E283 -> Radio | F285: =ESTADISTICA!F283 -> 0 | G285: =ESTADISTICA!G283 -> 0 | H285: =ESTADISTICA!H283 -> APAGADO | ... AI285: =ESTADISTICA!AI283 -> 0
A286: =ESTADISTICA!A284 -> SAN JORGE | B286: =ESTADISTICA!B284 -> SJO05 (fija 1) | C286: =ESTADISTICA!C284 -> 511 Y 560 | D286: =ESTADISTICA!D284 -> Fija | E286: =ESTADISTICA!E284 -> Fibra Optica | F286: =ESTADISTICA!F284 -> 0 | G286: =ESTADISTICA!G284 -> 0 | H286: =ESTADISTICA!H284 -> 0 | ... AI286: =ESTADISTICA!AI284 -> 0
A287: =ESTADISTICA!A285 -> SAN JORGE | B287: =ESTADISTICA!B285 -> SJO06 (fija 2) | C287: =ESTADISTICA!C285 -> 511 Y 560 | D287: =ESTADISTICA!D285 -> Fija | E287: =ESTADISTICA!E285 -> Fibra Optica | F287: =ESTADISTICA!F285 -> 0 | G287: =ESTADISTICA!G285 -> 0 | H287: =ESTADISTICA!H285 -> 0 | ... AI287: =ESTADISTICA!AI285 -> 0
A288: =ESTADISTICA!A286 -> SAN JORGE | B288: =ESTADISTICA!B286 -> SJO07 (fija 1) | C288: =ESTADISTICA!C286 -> 503 Y 556 | D288: =ESTADISTICA!D286 -> Fija | E288: =ESTADISTICA!E286 -> Fibra Optica | F288: =ESTADISTICA!F286 -> 0 | G288: =ESTADISTICA!G286 -> 0 | H288: =ESTADISTICA!H286 -> 0 | ... AI288: =ESTADISTICA!AI286 -> 0
A289: =ESTADISTICA!A287 -> SAN JORGE | B289: =ESTADISTICA!B287 -> SJO08 (fija 2) | C289: =ESTADISTICA!C287 -> 503 Y 556 | D289: =ESTADISTICA!D287 -> Fija | E289: =ESTADISTICA!E287 -> Fibra Optica | F289: =ESTADISTICA!F287 -> 0 | G289: =ESTADISTICA!G287 -> 0 | H289: =ESTADISTICA!H287 -> 0 | ... AI289: =ESTADISTICA!AI287 -> 0
A290: =ESTADISTICA!A288 -> SANTO TOMAS | B290: =ESTADISTICA!B288 -> SJU01 | C290: =ESTADISTICA!C288 -> Ruta 36 y Pte.Peron | D290: =ESTADISTICA!D288 -> Domo | E290: =ESTADISTICA!E288 -> Radio | F290: =ESTADISTICA!F288 -> 0 | G290: =ESTADISTICA!G288 -> 0 | H290: =ESTADISTICA!H288 -> APAGADO | ... AI290: =ESTADISTICA!AI288 -> 0
A291: =ESTADISTICA!A289 -> VILLA GENERAL SAN MARTIN | B291: =ESTADISTICA!B289 -> SMA01 | C291: =ESTADISTICA!C289 -> Hudson y Montevideo | D291: =ESTADISTICA!D289 -> DOMO | E291: =ESTADISTICA!E289 -> Radio | F291: =ESTADISTICA!F289 -> 0 | G291: =ESTADISTICA!G289 -> 0 | H291: =ESTADISTICA!H289 -> APAGADO | ... AI291: =ESTADISTICA!AI289 -> 0
... A454: =ESTADISTICA!A452 -> 0 | B454: =ESTADISTICA!B452 -> 0 | C454: =ESTADISTICA!C452 -> 0 | D454: =ESTADISTICA!D452 -> 0 | E454: =ESTADISTICA!E452 -> 0 | F454: =ESTADISTICA!F452 -> 0 | G454: =ESTADISTICA!G452 -> 0 | H454: =ESTADISTICA!H452 -> 0 | ... AI454: =ESTADISTICA!AI452 -> 0

Sheet APAGADOS RADIO
C1: TOTAL RADIO | D1: =COUNTIFS(E4:E400,"=radio") -> 89
E2: APAGADOS | F2: =COUNTIFS(F4:F500, "=APAGADO",E4:E500,"=radio") -> 4 | G2: =COUNTIFS(G4:G500, "=APAGADO",E4:E500,"=radio") -> 1 | H2: =COUNTIFS(H4:H500, "=APAGADO",E4:E500,"=radio") -> 41 | I2: =COUNTIFS(I4:I500, "=APAGADO",E4:E500,"=radio") -> 4 | J2: =COUNTIFS(J4:J500, "=APAGADO",E4:E500,"=radio") -> 2 | K2: =COUNTIFS(K4:K500, "=APAGADO",E4:E500,"=radio") -> 0 | L2: =COUNTIFS(L4:L500, "=APAGADO",E4:E500,"=radio") -> 1 | M2: =COUNTIFS(M4:M500, "=APAGADO",E4:E500,"=radio") -> 0 | N2: =COUNTIFS(N4:N500, "=APAGADO",E4:E500,"=radio") -> 4 | O2: =COUNTIFS(O4:O500, "=APAGADO",E4:E500,"=radio") -> 3 | P2: =COUNTIFS(P4:P500, "=APAGADO",E4:E500,"=radio") -> 4 | Q2: =COUNTIFS(Q4:Q367, "=APAGADO",E4:E367,"=radio") -> 3 | R2: =COUNTIFS(R4:R367, "=APAGADO",E4:E367,"=radio") -> 8 | S2: =COUNTIFS(S4:S367, "=APAGADO",E4:E367,"=radio") -> 1 | T2: =COUNTIFS(T4:T367, "=APAGADO",E4:E367,"=radio") -> 2 | U2: =COUNTIFS(U4:U367, "=APAGADO",E4:E367,"=radio") -> 3 | V2: =COUNTIFS(V4:V367, "=APAGADO",E4:E367,"=radio") -> 0 | W2: =COUNTIFS(W4:W367, "=APAGADO",E4:E367,"=radio") -> 3 | X2: =COUNTIFS(X4:X367, "=APAGADO",E4:E367,"=radio") -> 5 | Y2: =COUNTIFS(Y4:Y367, "=APAGADO",E4:E367,"=radio") -> 7 | Z2: =COUNTIFS(Z4:Z367, "=APAGADO",E4:E367,"=radio") -> 2 | AA2: =COUNTIFS(AA4:AA367, "=APAGADO",E4:E367,"=radio") -> 4 | AB2: =COUNTIFS(AB4:AB367, "=APAGADO",E4:E367,"=radio") -> 8 | AC2: =COUNTIFS(AC4:AC367, "=APAGADO",E4:E367,"=radio") -> 0 | AD2: =COUNTIFS(AD4:AD367, "=APAGADO",E4:E367,"=radio") -> 0 | AE2: =COUNTIFS(AE4:AE367, "=APAGADO",E4:E367,"=radio") -> 0 | AF2: =COUNTIFS(AF4:AF367, "=APAGADO",E4:E367,"=radio") -> 0 | AG2: =COUNTIFS(AG4:AG367, "=APAGADO",E4:E367,"=radio") -> 0 | AH2: =COUNTIFS(AH4:AH400, "=APAGADO",E4:E400,"=radio") -> 0 | AI2: =COUNTIFS(AI4:AI367, "=APAGADO",E4:E367,"=radio") -> 0
A3: =ESTADISTICA!A1 -> Barrio | B3: =ESTADISTICA!B1 -> [Denominacion] | C3: =ESTADISTICA!C1 -> [Ubicacion] | D3: =ESTADISTICA!D1 -> [Tipo de Camara] | E3: =ESTADISTICA!E1 -> [Tipo de Conexion] | F3: =ESTADISTICA!F1 -> 44835 | G3: =ESTADISTICA!G1 -> 44836 | H3: =ESTADISTICA!H1 -> 44837 | ... AI3: =ESTADISTICA!AI1 -> 44864
A4: =ESTADISTICA!A2 -> ALTAMIRA | B4: =ESTADISTICA!B2 -> ALT01 | C4: =ESTADISTICA!C2 -> Calchaqui y Sgto. Cabral | D4: =ESTADISTICA!D2 -> Domo | E4: =ESTADISTICA!E2 -> Fibra Optica | F4: =ESTADISTICA!F2 -> 0 | G4: =ESTADISTICA!G2 -> 0 | H4: =ESTADISTICA!H2 -> APAGADO | ... AI4: =ESTADISTICA!AI2 -> 0
A5: =ESTADISTICA!A3 -> ALTAMIRA | B5: =ESTADISTICA!B3 -> ALT02 | C5: =ESTADISTICA!C3 -> Calchaqui y Lope de Vega | D5: =ESTADISTICA!D3 -> Domo | E5: =ESTADISTICA!E3 -> PTO A FO | F5: =ESTADISTICA!F3 -> 0 | G5: =ESTADISTICA!G3 -> 0 | H5: =ESTADISTICA!H3 -> APAGADO | ... AI5: =ESTADISTICA!AI3 -> 0
A6: =ESTADISTICA!A4 -> ALTAMIRA | B6: =ESTADISTICA!B4 -> ALT 03 | C6: =ESTADISTICA!C4 -> Bombero Galarza y Necochea | D6: =ESTADISTICA!D4 -> Domo | E6: =ESTADISTICA!E4 -> FIBRA OPTICA | F6: =ESTADISTICA!F4 -> 0 | G6: =ESTADISTICA!G4 -> 0 | H6: =ESTADISTICA!H4 -> 0 | ... AI6: =ESTADISTICA!AI4 -> 0
A7: =ESTADISTICA!A5 -> ALTAMIRA | B7: =ESTADISTICA!B5 -> ALT 04 | C7: =ESTADISTICA!C5 -> Francia y Necochea | D7: =ESTADISTICA!D5 -> Domo | E7: =ESTADISTICA!E5 -> FIBRA OPTICA | F7: =ESTADISTICA!F5 -> APAGADO | G7: =ESTADISTICA!G5 -> APAGADO | H7: =ESTADISTICA!H5 -> APAGADO | ... AI7: =ESTADISTICA!AI5 -> 0
A8: =ESTADISTICA!A6 -> ALTAMIRA | B8: =ESTADISTICA!B6 -> ALT05 | C8: =ESTADISTICA!C6 -> Av. Calchaqui y Bombero Galarza | D8: =ESTADISTICA!D6 -> Domo | E8: =ESTADISTICA!E6 -> PTO A FO | F8: =ESTADISTICA!F6 -> APAGADO | G8: =ESTADISTICA!G6 -> APAGADO | H8: =ESTADISTICA!H6 -> APAGADO | ... AI8: =ESTADISTICA!AI6 -> 0
A9: =ESTADISTICA!A7 -> ALTAMIRA | B9: =ESTADISTICA!B7 -> ALT 06 | C9: =ESTADISTICA!C7 -> LOPE DE VEGA Y NECOCHEA | D9: =ESTADISTICA!D7 -> Domo | E9: =ESTADISTICA!E7 -> PTO A FO | F9: =ESTADISTICA!F7 -> 0 | G9: =ESTADISTICA!G7 -> 0 | H9: =ESTADISTICA!H7 -> APAGADO | ... AI9: =ESTADISTICA!AI7 -> 0
