Workbook
Name _25_de_agosto: 'RESUMEN TOTAL'!$A$4:$D$357
Name BONOMOcam: Hoja1!$B$2
Name COSEIDIcam: Hoja1!$B$4

Sheet RESUMEN TOTAL
A1: CANTIDAD DE CAMARAS | B1: =COUNTA(B5:B528) -> 412 | D1: PORCIENTO DE CAIDAS | K1: =(K3)/(K2+K3) -> 0.068459658 | L1: =(L3)/(L2+L3) -> 0.12958435 | M1: =(M3)/(M2+M3) -> 0.21026895 | N1: =(N3)/(N2+N3) -> 0.2200489 | O1: =(O3)/(O2+O3) -> 0.092909535 | P1: =(P3)/(P2+P3) -> 0.078239609 | Q1: =(Q3)/(Q2+Q3) -> 0.051344743 | R1: =(R3)/(R2+R3) -> 0.051344743 | ... AN1: =(AN3)/(AN2+AN3) -> 0
D2: FUNCIONAN | K2: =COUNTIF(K7:K415, "") -> 381 | L2: =COUNTIF(L7:L415, "") -> 356 | M2: =COUNTIF(M7:M415, "") -> 323 | N2: =COUNTIF(N7:N415, "") -> 319 | O2: =COUNTIF(O7:O415, "") -> 371 | P2: =COUNTIF(P7:P415, "") -> 377 | Q2: =COUNTIF(Q7:Q415, "") -> 388 | R2: =COUNTIF(R7:R415, "") -> 388 | ... AE2: =COUNTIF(AE7:AE415, "") -> 371 | AF2: =COUNTIF(AF5:AF416, "") -> 371 | AG2: =COUNTIF(AG5:AG416, "") -> 365 | AH2: =COUNTIF(AH5:AH416, "") -> 369 | AI2: =COUNTIF(AI5:AI416, "") -> 371 | AJ2: =COUNTIF(AJ5:AJ416, "") -> 412 | AK2: =COUNTIF(AK5:AK416, "") -> 412 | AL2: =COUNTIF(AL5:AL416, "") -> 412 | AM2: =COUNTIF(AM5:AM416, "") -> 412 | AN2: =COUNTIF(AN5:AN416, "") -> 412
D3: CAIDAS | K3: =COUNTIF(K4:K448, "apagado") -> 28 | L3: =COUNTIF(L4:L448, "apagado") -> 53 | M3: =COUNTIF(M4:M448, "apagado") -> 86 | N3: =COUNTIF(N4:N448, "apagado") -> 90 | O3: =COUNTIF(O4:O448, "apagado") -> 38 | P3: =COUNTIF(P4:P448, "apagado") -> 32 | Q3: =COUNTIF(Q4:Q448, "apagado") -> 21 | R3: =COUNTIF(R4:R448, "apagado") -> 21 | ... AN3: =COUNTIF(AN4:AN448, "apagado") -> 0
A4: Barrio | B4: [Denominacion] | C4: [Empresa Mantenimiento] | D4: [Ubicacion] | E4: [Tipo de Camara] | F4: [Tipo de Conexion] | H4: DIAS FUNCIONANDO | I4: DIAS CAIDA | J4: EFECTIVIDAD | K4: 44805 | L4: 44806 | M4: 44807 | N4: 44808 | O4: 44809 | P4: 44810 | Q4: 44811 | R4: 44812 | S4: 44813 | T4: 44814 | U4: 44815 | V4: 44816 | W4: 44817 | X4: 44818 | Y4: 44819 | Z4: 44820 | AA4: 44821 | AB4: 44822 | AC4: 44823 | AD4: 44824 | AE4: 44825 | AF4: 44826 | AG4: 44827 | AH4: 44828 | AI4: 44829 | AJ4: 44830 | AK4: 44831 | AL4: 44832 | AM4: 44833 | AN4: 44834
A5: ALTAMIRA | B5: ALT01 | C5: BONOMO | D5: Calchaqui y Sgto. Cabral | E5: Domo | F5: Fibra Optica | G5: 172.20.10.6 | H5: =COUNTIF(K5:AN5,"") -> 30 | I5: =COUNTIF(K5:AL5,"APAGADO") -> 0 | J5: =(H5)/(I5+H5) -> 1
A6: ALTAMIRA | B6: ALT02 | C6: BONOMO | D6: Calchaqui y Lope de Vega | E6: Domo | F6: PTO A FO | G6: 172.20.12.218 | H6: =COUNTIF(K6:AN6,"") -> 30 | I6: =COUNTIF(K6:AL6,"APAGADO") -> 0 | J6: =(H6)/(I6+H6) -> 1
A7: ALTAMIRA | B7: ALT 03 | C7: BONOMO | D7: Bombero Galarza y Necochea | E7: Domo | F7: FIBRA OPTICA | G7: 172.20.12.54 | H7: =COUNTIF(K7:AN7,"") -> 27 | I7: =COUNTIF(K7:AL7,"APAGADO") -> 3 | J7: =(H7)/(I7+H7) -> 0.9 | AG7: APAGADO | AH7: APAGADO | AI7: APAGADO
A8: ALTAMIRA | B8: ALT 04 | C8: BONOMO | D8: Francia y Necochea | E8: Domo | F8: FIBRA OPTICA | G8: 172.20.12.55 | H8: =COUNTIF(K8:AN8,"") -> 12 | I8: =COUNTIF(K8:AL8,"APAGADO") -> 18 | J8: =(H8)/(I8+H8) -> 0.4 | R8: APAGADO | S8: APAGADO | T8: APAGADO | U8: APAGADO | V8: APAGADO | W8: APAGADO | X8: APAGADO | Y8: APAGADO | Z8: APAGADO | AA8: APAGADO | AB8: APAGADO | AC8: APAGADO | AD8: APAGADO | AE8: APAGADO | AF8: APAGADO | AG8: APAGADO | AH8: APAGADO | AI8: APAGADO
A9: ALTAMIRA | B9: ALT05 | C9: BONOMO | D9: Av. Calchaqui y Bombero Galarza | E9: Domo | F9: PTO A FO | G9: 172.20.12.216 | H9: =COUNTIF(K9:AN9,"") -> 5 | I9: =COUNTIF(K9:AL9,"APAGADO") -> 25 | J9: =(H9)/(I9+H9) -> 0.16666667 | K9: APAGADO | L9: APAGADO | M9: APAGADO | N9: APAGADO | O9: APAGADO | P9: APAGADO | Q9: APAGADO | R9: APAGADO | S9: APAGADO | T9: APAGADO | U9: APAGADO | V9: APAGADO | W9: APAGADO | X9: APAGADO | Y9: APAGADO | Z9: APAGADO | AA9: APAGADO | AB9: APAGADO | AC9: APAGADO | AD9: APAGADO | AE9: APAGADO | AF9: APAGADO | AG9: APAGADO | AH9: APAGADO | AI9: APAGADO
A10: ALTAMIRA | B10: ALT 06 | C10: BONOMO | D10: LOPE DE VEGA Y NECOCHEA | E10: Domo | F10: PTO A FO | G10: 172.20.12.12 | H10: =COUNTIF(K10:AN10,"") -> 27 | I10: =COUNTIF(K10:AL10,"APAGADO") -> 3 | J10: =(H10)/(I10+H10) -> 0.9 | AG10: APAGADO | AH10: APAGADO | AI10: APAGADO
A11: ALTAMIRA | B11: ALT07 | C11: BONOMO | D11: AV. CALCHAQUI Y AV. DEL TRABAJO | E11: DOMO | F11: PTO A FO | G11: 172.20.10.57 | H11: =COUNTIF(K11:AN11,"") -> 30 | I11: =COUNTIF(K11:AL11,"APAGADO") -> 0 | J11: =(H11)/(I11+H11) -> 1
A12: ALTAMIRA | B12: ALT 08 | C12: BONOMO | D12: HUMAITA Y NECOCHEA | E12: DOMO | F12: Fibra Optica | G12: 172.20.11.215 | H12: =COUNTIF(K12:AN12,"") -> 27 | I12: =COUNTIF(K12:AL12,"APAGADO") -> 3 | J12: =(H12)/(I12+H12) -> 0.9 | AG12: APAGADO | AH12: APAGADO | AI12: APAGADO
A13: ALTAMIRA | B13: ALT 09 | C13: BONOMO | D13: NECOCHEA Y CURUPAITY | E13: DOMO | F13: Fibra Optica | G13: 172.20.11.216 | H13: =COUNTIF(K13:AN13,"") -> 27 | I13: =COUNTIF(K13:AL13,"APAGADO") -> 3 | J13: =(H13)/(I13+H13) -> 0.9 | AG13: APAGADO | AH13: APAGADO | AI13: APAGADO
A14: ALTAMIRA | B14: ALT 10 | C14: BONOMO | D14: Calchaqui y Francia | E14: Domo | F14: Radio | H14: =COUNTIF(K14:AN14,"") -> 5 | I14: =COUNTIF(K14:AL14,"APAGADO") -> 25 | J14: =(H14)/(I14+H14) -> 0.16666667 | K14: APAGADO | L14: APAGADO | M14: APAGADO | N14: APAGADO | O14: APAGADO | P14: APAGADO | Q14: APAGADO | R14: APAGADO | S14: APAGADO | T14: APAGADO | U14: APAGADO | V14: APAGADO | W14: APAGADO | X14: APAGADO | Y14: APAGADO | Z14: APAGADO | AA14: APAGADO | AB14: APAGADO | AC14: APAGADO | AD14: APAGADO | AE14: APAGADO | AF14: APAGADO | AG14: APAGADO | AH14: APAGADO | AI14: APAGADO
A15: AGUSTIN RAMIREZ | B15: ARA 01 | C15: COSEIDI | D15: Malambo y Tranquera | E15: Domo | F15: FIBRA OPTICA | G15: 172.20.12.110 | H15: =COUNTIF(K15:AN15,"") -> 30 | I15: =COUNTIF(K15:AL15,"APAGADO") -> 0 | J15: =(H15)/(I15+H15) -> 1
A16: BELGRANO | B16: BEL 01 | C16: BONOMO | D16: San Martin y Dardo Rocha | E16: DOMO | F16: FIBRA OPTICA | G16: 172.20.12.64 | H16: =COUNTIF(K16:AN16,"") -> 11 | I16: =COUNTIF(K16:AL16,"APAGADO") -> 19 | J16: =(H16)/(I16+H16) -> 0.36666667 | K16: APAGADO | L16: APAGADO | O16: APAGADO | P16: APAGADO | Q16: APAGADO | R16: APAGADO | S16: APAGADO | T16: APAGADO | V16: APAGADO | X16: APAGADO | Y16: APAGADO | Z16: APAGADO | AA16: APAGADO | AB16: APAGADO | AC16: APAGADO | AE16: APAGADO | AF16: APAGADO | AH16: APAGADO | AI16: APAGADO
A17: CENTRO | B17: CEN01 | C17: BONOMO | D17: San Martin y 9 de Julio | E17: Fija | F17: Fibra Optica | G17: 172.20.11.10 | H17: =COUNTIF(K17:AN17,"") -> 28 | I17: =COUNTIF(K17:AL17,"APAGADO") -> 2 | J17: =(H17)/(I17+H17) -> 0.93333333 | M17: APAGADO | N17: APAGADO
A18: CENTRO | B18: CEN02 | C18: BONOMO | D18: San Martin y Almafuerte | E18: Fija | F18: Fibra Optica | G18: 172.20.11.11 | H18: =COUNTIF(K18:AN18,"") -> 28 | I18: =COUNTIF(K18:AL18,"APAGADO") -> 2 | J18: =(H18)/(I18+H18) -> 0.93333333 | M18: APAGADO | N18: APAGADO
A19: CENTRO | B19: CEN03 | C19: BONOMO | D19: San Martin y Sallares | E19: Domo | F19: Fibra Optica | G19: 172.20.12.30 | H19: =COUNTIF(K19:AN19,"") -> 30 | I19: =COUNTIF(K19:AL19,"APAGADO") -> 0 | J19: =(H19)/(I19+H19) -> 1
A20: CENTRO | B20: CEN04 | C20: BONOMO | D20: San Martin y Contreras | E20: Domo | F20: Fibra Optica | G20: 172.20.12.29 | H20: =COUNTIF(K20:AN20,"") -> 30 | I20: =COUNTIF(K20:AL20,"APAGADO") -> 0 | J20: =(H20)/(I20+H20) -> 1
A21: CENTRO | B21: CEN 05 | C21: BONOMO | D21: Bocuzzi e/España y San Martin | E21: DOMO | F21: Fibra Optica | G21: 172.20.10.200 | H21: =COUNTIF(K21:AN21,"") -> 30 | I21: =COUNTIF(K21:AL21,"APAGADO") -> 0 | J21: =(H21)/(I21+H21) -> 1
A22: CENTRO | B22: CEN06 | C22: BONOMO | D22: Monteagudo y A.del Valle | E22: Fija | F22: Fibra Optica | G22: 172.20.10.02 | H22: =COUNTIF(K22:AN22,"") -> 30 | I22: =COUNTIF(K22:AL22,"APAGADO") -> 0 | J22: =(H22)/(I22+H22) -> 1
A23: CENTRO | B23: CEN07 | C23: BONOMO | D23: San Martin y Guemes | E23: DOMO | F23: Fibra Optica | G23: 172.20.11.20 | H23: =COUNTIF(K23:AN23,"") -> 26 | I23: =COUNTIF(K23:AL23,"APAGADO") -> 4 | J23: =(H23)/(I23+H23) -> 0.86666667 | M23: APAGADO | N23: APAGADO | S23: APAGADO | T23: APAGADO
A24: CENTRO | B24: CEN08 | C24: BONOMO | D24: San Martin y Pte.Peron | E24: Domo | F24: Fibra Optica | G24: 172.20.11.21 | H24: =COUNTIF(K24:AN24,"") -> 30 | I24: =COUNTIF(K24:AL24,"APAGADO") -> 0 | J24: =(H24)/(I24+H24) -> 1
A25: CENTRO | B25: CEN09 | C25: BONOMO | D25: Chacabuco y 25 de Mayo | E25: Domo | F25: Fibra Optica | G25: 172.20.11.22 | H25: =COUNTIF(K25:AN25,"") -> 30 | I25: =COUNTIF(K25:AL25,"APAGADO") -> 0 | J25: =(H25)/(I25+H25) -> 1
A26: CENTRO | B26: CEN10 | C26: BONOMO | D26: Monteagudo y Pte. Peron | E26: Domo | F26: Fibra Optica | G26: 172.20.11.23 | H26: =COUNTIF(K26:AN26,"") -> 30 | I26: =COUNTIF(K26:AL26,"APAGADO") -> 0 | J26: =(H26)/(I26+H26) -> 1
A27: CENTRO | B27: CEN11 | C27: BONOMO | D27: Monteagudo y Bocuzzi | E27: Domo | F27: Fibra Optica | G27: 172.20.10.24 | H27: =COUNTIF(K27:AN27,"") -> 30 | I27: =COUNTIF(K27:AL27,"APAGADO") -> 0 | J27: =(H27)/(I27+H27) -> 1
A28: CENTRO | B28: CEN 12 | C28: BONOMO | D28: Monteagudo y Mitre | E28: Domo | F28: Fibra Optica | G28: 172.20.10.23 | H28: =COUNTIF(K28:AN28,"") -> 30 | I28: =COUNTIF(K28:AL28,"APAGADO") -> 0 | J28: =(H28)/(I28+H28) -> 1
A29: CENTRO | B29: CEN 13 | C29: BONOMO | D29: 25 de Mayo y Maipu | E29: DOMO | F29: Fibra Optica | G29: 172.20.10.20 | H29: =COUNTIF(K29:AN29,"") -> 30 | I29: =COUNTIF(K29:AL29,"APAGADO") -> 0 | J29: =(H29)/(I29+H29) -> 1
A30: CENTRO | B30: CEN14 | C30: BONOMO | D30: Pte.Peron e/Pringles y Brown | E30: Domo | F30: Fibra Optica | G30: 172.20.10.21 | H30: =COUNTIF(K30:AN30,"") -> 30 | I30: =COUNTIF(K30:AL30,"APAGADO") -> 0 | J30: =(H30)/(I30+H30) -> 1
A31: CENTRO | B31: CEN15 | C31: BONOMO | D31: Alberdi y A.del Valle | E31: Domo | F31: Fibra Optica | G31: 172.20.10.35 | H31: =COUNTIF(K31:AN31,"") -> 30 | I31: =COUNTIF(K31:AL31,"APAGADO") -> 0 | J31: =(H31)/(I31+H31) -> 1
A32: CENTRO | B32: CEN16 | C32: BONOMO | D32: San Martin y Pte. Peron | E32: Fija | F32: Fibra Optica | G32: 172.20.12.36 | H32: =COUNTIF(K32:AN32,"") -> 30 | I32: =COUNTIF(K32:AL32,"APAGADO") -> 0 | J32: =(H32)/(I32+H32) -> 1
A33: CENTRO | B33: CEN17 | C33: BONOMO | D33: San Martin y Mitre | E33: Domo | F33: PTO A FO | G33: 172.20.12.200 | H33: =COUNTIF(K33:AN33,"") -> 28 | I33: =COUNTIF(K33:AL33,"APAGADO") -> 2 | J33: =(H33)/(I33+H33) -> 0.93333333 | M33: APAGADO | N33: APAGADO
A34: CENTRO | B34: CEN18 | C34: BONOMO | D34: Monteagudo e/Mitre y Sallares | E34: Fija | F34: Fibra Optica | G34: 172.20.10.26 | H34: =COUNTIF(K34:AN34,"") -> 30 | I34: =COUNTIF(K34:AL34,"APAGADO") -> 0 | J34: =(H34)/(I34+H34) -> 1
A35: CENTRO | B35: CEN19 | C35: BONOMO | D35: Chacabuco y 25 de Mayo | E35: Fija | F35: Fibra Optica | G35: 172.20.10.27 | H35: =COUNTIF(K35:AN35,"") -> 29 | I35: =COUNTIF(K35:AL35,"APAGADO") -> 1 | J35: =(H35)/(I35+H35) -> 0.96666667 | U35: APAGADO
A36: LOMAS DE MONTEVERDE | B36: CEN20 | C36: BONOMO | D36: Pte. Illia y Las Heras | E36: Domo | F36: Fibra Optica | G36: 172.20.10.33 | H36: =COUNTIF(K36:AN36,"") -> 30 | I36: =COUNTIF(K36:AL36,"APAGADO") -> 0 | J36: =(H36)/(I36+H36) -> 1
A37: CENTRO | B37: CEN21 | C37: BONOMO | D37: Misiones y Urquiza | E37: Fija | F37: Radio | G37: 172.20.200.132 | H37: =COUNTIF(K37:AN37,"") -> 29 | I37: =COUNTIF(K37:AL37,"APAGADO") -> 1 | J37: =(H37)/(I37+H37) -> 0.96666667 | N37: APAGADO
A38: CENTRO | B38: CEN22 | C38: BONOMO | D38: Las Heras y Chacabuco | E38: Domo | F38: Radio | G38: 172.20.200.125 | H38: =COUNTIF(K38:AN38,"") -> 30 | I38: =COUNTIF(K38:AL38,"APAGADO") -> 0 | J38: =(H38)/(I38+H38) -> 1
A39: CENTRO | B39: CEN23 | C39: BONOMO | D39: Sallares y Monteagudo | E39: Domo | F39: Fibra Optica | G39: 172.20.12.05 | H39: =COUNTIF(K39:AN39,"") -> 30 | I39: =COUNTIF(K39:AL39,"APAGADO") -> 0 | J39: =(H39)/(I39+H39) -> 1
A40: CENTRO | B40: CEN24 | C40: BONOMO | D40: Sallares y España | E40: Domo | F40: Fibra Optica | G40: 172.20.12.04 | H40: =COUNTIF(K40:AN40,"") -> 24 | I40: =COUNTIF(K40:AL40,"APAGADO") -> 6 | J40: =(H40)/(I40+H40) -> 0.8 | R40: APAGADO | Z40: APAGADO | AA40: APAGADO | AF40: APAGADO | AH40: APAGADO | AI40: APAGADO
...

Sheet ESTADISTICA
A1: ='RESUMEN TOTAL'!A4 -> Barrio | B1: ='RESUMEN TOTAL'!B4 -> [Denominacion] | C1: ='RESUMEN TOTAL'!D4 -> [Ubicacion] | D1: ='RESUMEN TOTAL'!E4 -> [Tipo de Camara] | E1: ='RESUMEN TOTAL'!F4 -> [Tipo de Conexion] | F1: ='RESUMEN TOTAL'!K4 -> 44805 | G1: ='RESUMEN TOTAL'!L4 -> 44806 | H1: ='RESUMEN TOTAL'!M4 -> 44807 | I1: ='RESUMEN TOTAL'!N4 -> 44808 | J1: ='RESUMEN TOTAL'!O4 -> 44809 | K1: ='RESUMEN TOTAL'!P4 -> 44810 | L1: ='RESUMEN TOTAL'!Q4 -> 44811 | M1: ='RESUMEN TOTAL'!R4 -> 44812 | ... AI1: ='RESUMEN TOTAL'!AN4 -> 44834
A2: ='RESUMEN TOTAL'!A5 -> ALTAMIRA | B2: ='RESUMEN TOTAL'!B5 -> ALT01 | C2: ='RESUMEN TOTAL'!D5 -> Calchaqui y Sgto. Cabral | D2: ='RESUMEN TOTAL'!E5 -> Domo | E2: ='RESUMEN TOTAL'!F5 -> Fibra Optica | F2: ='RESUMEN TOTAL'!K5 -> 0 | G2: ='RESUMEN TOTAL'!L5 -> 0 | H2: ='RESUMEN TOTAL'!M5 -> 0 | I2: ='RESUMEN TOTAL'!N5 -> 0 | J2: ='RESUMEN TOTAL'!O5 -> 0 | K2: ='RESUMEN TOTAL'!P5 -> 0 | L2: ='RESUMEN TOTAL'!Q5 -> 0 | M2: ='RESUMEN TOTAL'!R5 -> 0 | ... AI2: ='RESUMEN TOTAL'!AN5 -> 0
A3: ='RESUMEN TOTAL'!A6 -> ALTAMIRA | B3: ='RESUMEN TOTAL'!B6 -> ALT02 | C3: ='RESUMEN TOTAL'!D6 -> Calchaqui y Lope de Vega | D3: ='RESUMEN TOTAL'!E6 -> Domo | E3: ='RESUMEN TOTAL'!F6 -> PTO A FO | F3: ='RESUMEN TOTAL'!K6 -> 0 | G3: ='RESUMEN TOTAL'!L6 -> 0 | H3: ='RESUMEN TOTAL'!M6 -> 0 | I3: ='RESUMEN TOTAL'!N6 -> 0 | J3: ='RESUMEN TOTAL'!O6 -> 0 | K3: ='RESUMEN TOTAL'!P6 -> 0 | L3: ='RESUMEN TOTAL'!Q6 -> 0 | M3: ='RESUMEN TOTAL'!R6 -> 0 | ... AI3: ='RESUMEN TOTAL'!AN6 -> 0
A4: ='RESUMEN TOTAL'!A7 -> ALTAMIRA | B4: ='RESUMEN TOTAL'!B7 -> ALT 03 | C4: ='RESUMEN TOTAL'!D7 -> Bombero Galarza y Necochea | D4: ='RESUMEN TOTAL'!E7 -> Domo | E4: ='RESUMEN TOTAL'!F7 -> FIBRA OPTICA | F4: ='RESUMEN TOTAL'!K7 -> 0 | G4: ='RESUMEN TOTAL'!L7 -> 0 | H4: ='RESUMEN TOTAL'!M7 -> 0 | I4: ='RESUMEN TOTAL'!N7 -> 0 | J4: ='RESUMEN TOTAL'!O7 -> 0 | K4: ='RESUMEN TOTAL'!P7 -> 0 | L4: ='RESUMEN TOTAL'!Q7 -> 0 | M4: ='RESUMEN TOTAL'!R7 -> 0 | ... AI4: ='RESUMEN TOTAL'!AN7 -> 0
A5: ='RESUMEN TOTAL'!A8 -> ALTAMIRA | B5: ='RESUMEN TOTAL'!B8 -> ALT 04 | C5: ='RESUMEN TOTAL'!D8 -> Francia y Necochea | D5: ='RESUMEN TOTAL'!E8 -> Domo | E5: ='RESUMEN TOTAL'!F8 -> FIBRA OPTICA | F5: ='RESUMEN TOTAL'!K8 -> 0 | G5: ='RESUMEN TOTAL'!L8 -> 0 | H5: ='RESUMEN TOTAL'!M8 -> 0 | I5: ='RESUMEN TOTAL'!N8 -> 0 | J5: ='RESUMEN TOTAL'!O8 -> 0 | K5: ='RESUMEN TOTAL'!P8 -> 0 | L5: ='RESUMEN TOTAL'!Q8 -> 0 | M5: ='RESUMEN TOTAL'!R8 -> APAGADO | ... AI5: ='RESUMEN TOTAL'!AN8 -> 0
A6: ='RESUMEN TOTAL'!A9 -> ALTAMIRA | B6: ='RESUMEN TOTAL'!B9 -> ALT05 | C6: ='RESUMEN TOTAL'!D9 -> Av. Calchaqui y Bombero Galarza | D6: ='RESUMEN TOTAL'!E9 -> Domo | E6: ='RESUMEN TOTAL'!F9 -> PTO A FO | F6: ='RESUMEN TOTAL'!K9 -> APAGADO | G6: ='RESUMEN TOTAL'!L9 -> APAGADO | H6: ='RESUMEN TOTAL'!M9 -> APAGADO | I6: ='RESUMEN TOTAL'!N9 -> APAGADO | J6: ='RESUMEN TOTAL'!O9 -> APAGADO | K6: ='RESUMEN TOTAL'!P9 -> APAGADO | L6: ='RESUMEN TOTAL'!Q9 -> APAGADO | M6: ='RESUMEN TOTAL'!R9 -> APAGADO | ... AI6: ='RESUMEN TOTAL'!AN9 -> 0
A7: ='RESUMEN TOTAL'!A10 -> ALTAMIRA | B7: ='RESUMEN TOTAL'!B10 -> ALT 06 | C7: ='RESUMEN TOTAL'!D10 -> LOPE DE VEGA Y NECOCHEA | D7: ='RESUMEN TOTAL'!E10 -> Domo | E7: ='RESUMEN TOTAL'!F10 -> PTO A FO | F7: ='RESUMEN TOTAL'!K10 -> 0 | G7: ='RESUMEN TOTAL'!L10 -> 0 | H7: ='RESUMEN TOTAL'!M10 -> 0 | I7: ='RESUMEN TOTAL'!N10 -> 0 | J7: ='RESUMEN TOTAL'!O10 -> 0 | K7: ='RESUMEN TOTAL'!P10 -> 0 | L7: ='RESUMEN TOTAL'!Q10 -> 0 | M7: ='RESUMEN TOTAL'!R10 -> 0 | ... AI7: ='RESUMEN TOTAL'!AN10 -> 0
A8: ='RESUMEN TOTAL'!A11 -> ALTAMIRA | B8: ='RESUMEN TOTAL'!B11 -> ALT07 | C8: ='RESUMEN TOTAL'!D11 -> AV. CALCHAQUI Y AV. DEL TRABAJO | D8: ='RESUMEN TOTAL'!E11 -> DOMO | E8: ='RESUMEN TOTAL'!F11 -> PTO A FO | F8: ='RESUMEN TOTAL'!K11 -> 0 | G8: ='RESUMEN TOTAL'!L11 -> 0 | H8: ='RESUMEN TOTAL'!M11 -> 0 | I8: ='RESUMEN TOTAL'!N11 -> 0 | J8: ='RESUMEN TOTAL'!O11 -> 0 | K8: ='RESUMEN TOTAL'!P11 -> 0 | L8: ='RESUMEN TOTAL'!Q11 -> 0 | M8: ='RESUMEN TOTAL'!R11 -> 0 | ... AI8: ='RESUMEN TOTAL'!AN11 -> 0
A9: ='RESUMEN TOTAL'!A12 -> ALTAMIRA | B9: ='RESUMEN TOTAL'!B12 -> ALT 08 | C9: ='RESUMEN TOTAL'!D12 -> HUMAITA Y NECOCHEA | D9: ='RESUMEN TOTAL'!E12 -> DOMO | E9: ='RESUMEN TOTAL'!F12 -> Fibra Optica | F9: ='RESUMEN TOTAL'!K12 -> 0 | G9: ='RESUMEN TOTAL'!L12 -> 0 | H9: ='RESUMEN TOTAL'!M12 -> 0 | I9: ='RESUMEN TOTAL'!N12 -> 0 | J9: ='RESUMEN TOTAL'!O12 -> 0 | K9: ='RESUMEN TOTAL'!P12 -> 0 | L9: ='RESUMEN TOTAL'!Q12 -> 0 | M9: ='RESUMEN TOTAL'!R12 -> 0 | ... AI9: ='RESUMEN TOTAL'!AN12 -> 0
A10: ='RESUMEN TOTAL'!A13 -> ALTAMIRA | B10: ='RESUMEN TOTAL'!B13 -> ALT 09 | C10: ='RESUMEN TOTAL'!D13 -> NECOCHEA Y CURUPAITY | D10: ='RESUMEN TOTAL'!E13 -> DOMO | E10: ='RESUMEN TOTAL'!F13 -> Fibra Optica | F10: ='RESUMEN TOTAL'!K13 -> 0 | G10: ='RESUMEN TOTAL'!L13 -> 0 | H10: ='RESUMEN TOTAL'!M13 -> 0 | I10: ='RESUMEN TOTAL'!N13 -> 0 | J10: ='RESUMEN TOTAL'!O13 -> 0 | K10: ='RESUMEN TOTAL'!P13 -> 0 | L10: ='RESUMEN TOTAL'!Q13 -> 0 | M10: ='RESUMEN TOTAL'!R13 -> 0 | ... AI10: ='RESUMEN TOTAL'!AN13 -> 0
A11: ='RESUMEN TOTAL'!A14 -> ALTAMIRA | B11: ='RESUMEN TOTAL'!B14 -> ALT 10 | C11: ='RESUMEN TOTAL'!D14 -> Calchaqui y Francia | D11: ='RESUMEN TOTAL'!E14 -> Domo | E11: ='RESUMEN TOTAL'!F14 -> Radio | F11: ='RESUMEN TOTAL'!K14 -> APAGADO | G11: ='RESUMEN TOTAL'!L14 -> APAGADO | H11: ='RESUMEN TOTAL'!M14 -> APAGADO | I11: ='RESUMEN TOTAL'!N14 -> APAGADO | J11: ='RESUMEN TOTAL'!O14 -> APAGADO | K11: ='RESUMEN TOTAL'!P14 -> APAGADO | L11: ='RESUMEN TOTAL'!Q14 -> APAGADO | M11: ='RESUMEN TOTAL'!R14 -> APAGADO | ... AI11: ='RESUMEN TOTAL'!AN14 -> 0
A12: ='RESUMEN TOTAL'!A15 -> AGUSTIN RAMIREZ | B12: ='RESUMEN TOTAL'!B15 -> ARA 01 | C12: ='RESUMEN TOTAL'!D15 -> Malambo y Tranquera | D12: ='RESUMEN TOTAL'!E15 -> Domo | E12: ='RESUMEN TOTAL'!F15 -> FIBRA OPTICA | F12: ='RESUMEN TOTAL'!K15 -> 0 | G12: ='RESUMEN TOTAL'!L15 -> 0 | H12: ='RESUMEN TOTAL'!M15 -> 0 | I12: ='RESUMEN TOTAL'!N15 -> 0 | J12: ='RESUMEN TOTAL'!O15 -> 0 | K12: ='RESUMEN TOTAL'!P15 -> 0 | L12: ='RESUMEN TOTAL'!Q15 -> 0 | M12: ='RESUMEN TOTAL'!R15 -> 0 | ... AI12: ='RESUMEN TOTAL'!AN15 -> 0
... A370: ='RESUMEN TOTAL'!A373 -> VILLA VATTEONE CENTRO | B370: ='RESUMEN TOTAL'!B373 -> VAT24 (fija 2) | C370: ='RESUMEN TOTAL'!D373 -> EVA PERON Y "EL TUNEL" (BAJO NIVEL) | D370: ='RESUMEN TOTAL'!E373 -> Fija | E370: ='RESUMEN TOTAL'!F373 -> Fibra Optica | F370: ='RESUMEN TOTAL'!K373 -> 0 | G370: ='RESUMEN TOTAL'!L373 -> APAGADO | H370: ='RESUMEN TOTAL'!M373 -> APAGADO | I370: ='RESUMEN TOTAL'!N373 -> 0 | J370: ='RESUMEN TOTAL'!O373 -> 0 | K370: ='RESUMEN TOTAL'!P373 -> 0 | L370: ='RESUMEN TOTAL'!Q373 -> 0 | M370: ='RESUMEN TOTAL'!R373 -> 0 | ... AI370: ='RESUMEN TOTAL'!AN373 -> 0
A371: ='RESUMEN TOTAL'!A376 -> VILLA AURORA | B371: ='RESUMEN TOTAL'!B376 -> VAU 01 | C371: ='RESUMEN TOTAL'!D376 -> San Martin y Monteverde | D371: ='RESUMEN TOTAL'!E376 -> Domo | E371: ='RESUMEN TOTAL'!F376 -> Fibra Optica | F371: ='RESUMEN TOTAL'!K376 -> 0 | G371: ='RESUMEN TOTAL'!L376 -> APAGADO | H371: ='RESUMEN TOTAL'!M376 -> APAGADO | I371: ='RESUMEN TOTAL'!N376 -> APAGADO | J371: ='RESUMEN TOTAL'!O376 -> 0 | K371: ='RESUMEN TOTAL'!P376 -> 0 | L371: ='RESUMEN TOTAL'!Q376 -> 0 | M371: ='RESUMEN TOTAL'!R376 -> 0 | ... AI371: ='RESUMEN TOTAL'!AN376 -> 0
A372: ='RESUMEN TOTAL'!A377 -> SAN EMILIO | B372: ='RESUMEN TOTAL'!B377 -> VAU 02 | C372: ='RESUMEN TOTAL'!D377 -> San Martin y Lope de Vega | D372: ='RESUMEN TOTAL'!E377 -> Domo | E372: ='RESUMEN TOTAL'!F377 -> Fibra Optica | F372: ='RESUMEN TOTAL'!K377 -> 0 | G372: ='RESUMEN TOTAL'!L377 -> APAGADO | H372: ='RESUMEN TOTAL'!M377 -> 0 | I372: ='RESUMEN TOTAL'!N377 -> APAGADO | J372: ='RESUMEN TOTAL'!O377 -> 0 | K372: ='RESUMEN TOTAL'!P377 -> 0 | L372: ='RESUMEN TOTAL'!Q377 -> 0 | M372: ='RESUMEN TOTAL'!R377 -> 0 | ... AI372: ='RESUMEN TOTAL'!AN377 -> 0
A373: ='RESUMEN TOTAL'!A378 -> VILLA AURORA | B373: ='RESUMEN TOTAL'!B378 -> VAU03 (fija 1) | C373: ='RESUMEN TOTAL'!D378 -> PIZZURNO Y NUESTRAS MALVINAS | D373: ='RESUMEN TOTAL'!E378 -> Fija | E373: ='RESUMEN TOTAL'!F378 -> Fibra Optica | F373: ='RESUMEN TOTAL'!K378 -> 0 | G373: ='RESUMEN TOTAL'!L378 -> APAGADO | H373: ='RESUMEN TOTAL'!M378 -> APAGADO | I373: ='RESUMEN TOTAL'!N378 -> APAGADO | J373: ='RESUMEN TOTAL'!O378 -> APAGADO | K373: ='RESUMEN TOTAL'!P378 -> APAGADO | L373: ='RESUMEN TOTAL'!Q378 -> APAGADO | M373: ='RESUMEN TOTAL'!R378 -> APAGADO | ... AI373: ='RESUMEN TOTAL'!AN378 -> 0
A374: ='RESUMEN TOTAL'!A379 -> VILLA AURORA | B374: ='RESUMEN TOTAL'!B379 -> VAU04 (fija 2) | C374: ='RESUMEN TOTAL'!D379 -> PIZZURNO Y NUESTRAS MALVINAS | D374: ='RESUMEN TOTAL'!E379 -> Fija | E374: ='RESUMEN TOTAL'!F379 -> Fibra Optica | F374: ='RESUMEN TOTAL'!K379 -> 0 | G374: ='RESUMEN TOTAL'!L379 -> APAGADO | H374: ='RESUMEN TOTAL'!M379 -> APAGADO | I374: ='RESUMEN TOTAL'!N379 -> APAGADO | J374: ='RESUMEN TOTAL'!O379 -> APAGADO | K374: ='RESUMEN TOTAL'!P379 -> APAGADO | L374: ='RESUMEN TOTAL'!Q379 -> APAGADO | M374: ='RESUMEN TOTAL'!R379 -> APAGADO | ... AI374: ='RESUMEN TOTAL'!AN379 -> 0
A375: ='RESUMEN TOTAL'!A380 -> VILLA AURORA | B375: ='RESUMEN TOTAL'!B380 -> VAU05 (fija 1) | C375: ='RESUMEN TOTAL'!D380 -> GUIDO SPANO Y VICTORINO DE LA PLAZA | D375: ='RESUMEN TOTAL'!E380 -> Fija | E375: ='RESUMEN TOTAL'!F380 -> Fibra Optica | F375: ='RESUMEN TOTAL'!K380 -> 0 | G375: ='RESUMEN TOTAL'!L380 -> APAGADO | H375: ='RESUMEN TOTAL'!M380 -> 0 | I375: ='RESUMEN TOTAL'!N380 -> 0 | J375: ='RESUMEN TOTAL'!O380 -> 0 | K375: ='RESUMEN TOTAL'!P380 -> 0 | L375: ='RESUMEN TOTAL'!Q380 -> 0 | M375: ='RESUMEN TOTAL'!R380 -> 0 | ... AI375: ='RESUMEN TOTAL'!AN380 -> 0
A376: ='RESUMEN TOTAL'!A381 -> VILLA AURORA | B376: ='RESUMEN TOTAL'!B381 -> VAU06 (fija 2) | C376: ='RESUMEN TOTAL'!D381 -> GUIDO SPANO Y VICTORINO DE LA PLAZA | D376: ='RESUMEN TOTAL'!E381 -> Fija | E376: ='RESUMEN TOTAL'!F381 -> Fibra Optica | F376: ='RESUMEN TOTAL'!K381 -> 0 | G376: ='RESUMEN TOTAL'!L381 -> APAGADO | H376: ='RESUMEN TOTAL'!M381 -> 0 | I376: ='RESUMEN TOTAL'!N381 -> 0 | J376: ='RESUMEN TOTAL'!O381 -> 0 | K376: ='RESUMEN TOTAL'!P381 -> 0 | L376: ='RESUMEN TOTAL'!Q381 -> 0 | M376: ='RESUMEN TOTAL'!R381 -> 0 | ... AI376: ='RESUMEN TOTAL'!AN381 -> 0
A377: ='RESUMEN TOTAL'!A382 -> VILLA AURORA | B377: ='RESUMEN TOTAL'!B382 -> VAU 07 | C377: ='RESUMEN TOTAL'!D382 -> VICTORINO DE LA PLAZA Y MONTEVERDE | D377: ='RESUMEN TOTAL'!E382 -> Domo | E377: ='RESUMEN TOTAL'!F382 -> Fibra Optica | F377: ='RESUMEN TOTAL'!K382 -> 0 | G377: ='RESUMEN TOTAL'!L382 -> APAGADO | H377: ='RESUMEN TOTAL'!M382 -> 0 | I377: ='RESUMEN TOTAL'!N382 -> 0 | J377: ='RESUMEN TOTAL'!O382 -> 0 | K377: ='RESUMEN TOTAL'!P382 -> 0 | L377: ='RESUMEN TOTAL'!Q382 -> 0 | M377: ='RESUMEN TOTAL'!R382 -> 0 | ... AI377: ='RESUMEN TOTAL'!AN382 -> 0
A378: ='RESUMEN TOTAL'!A383 -> VILLA AURORA | B378: ='RESUMEN TOTAL'!B383 -> VAU08 | C378: ='RESUMEN TOTAL'!D383 -> MONTEVERDE Y WASHINGTON | D378: ='RESUMEN TOTAL'!E383 -> DOMO | E378: ='RESUMEN TOTAL'!F383 -> Fibra Optica | F378: ='RESUMEN TOTAL'!K383 -> 0 | G378: ='RESUMEN TOTAL'!L383 -> APAGADO | H378: ='RESUMEN TOTAL'!M383 -> 0 | I378: ='RESUMEN TOTAL'!N383 -> 0 | J378: ='RESUMEN TOTAL'!O383 -> 0 | K378: ='RESUMEN TOTAL'!P383 -> 0 | L378: ='RESUMEN TOTAL'!Q383 -> 0 | M378: ='RESUMEN TOTAL'!R383 -> 0 | ... AI378: ='RESUMEN TOTAL'!AN383 -> 0
A379: ='RESUMEN TOTAL'!A384 -> VILLA DEL PLATA | B379: ='RESUMEN TOTAL'!B384 -> VDPL02 | C379: ='RESUMEN TOTAL'!D384 -> Thevenet y Berutti | D379: ='RESUMEN TOTAL'!E384 -> Domo | E379: ='RESUMEN TOTAL'!F384 -> Fibra Optica | F379: ='RESUMEN TOTAL'!K384 -> 0 | G379: ='RESUMEN TOTAL'!L384 -> 0 | H379: ='RESUMEN TOTAL'!M384 -> 0 | I379: ='RESUMEN TOTAL'!N384 -> 0 | J379: ='RESUMEN TOTAL'!O384 -> 0 | K379: ='RESUMEN TOTAL'!P384 -> 0 | L379: ='RESUMEN TOTAL'!Q384 -> 0 | M379: ='RESUMEN TOTAL'!R384 -> 0 | ... AI379: ='RESUMEN TOTAL'!AN384 -> 0
A380: ='RESUMEN TOTAL'!A385 -> VILLA DEL PLATA | B380: ='RESUMEN TOTAL'!B385 -> VDPL03 | C380: ='RESUMEN TOTAL'!D385 -> Neuquen y Alvarado | D380: ='RESUMEN TOTAL'!E385 -> Domo | E380: ='RESUMEN TOTAL'!F385 -> Radio | F380: ='RESUMEN TOTAL'!K385 -> 0 | G380: ='RESUMEN TOTAL'!L385 -> 0 | H380: ='RESUMEN TOTAL'!M385 -> 0 | I380: ='RESUMEN TOTAL'!N385 -> 0 | J380: ='RESUMEN TOTAL'!O385 -> 0 | K380: ='RESUMEN TOTAL'!P385 -> 0 | L380: ='RESUMEN TOTAL'!Q385 -> 0 | M380: ='RESUMEN TOTAL'!R385 -> 0 | ... AI380: ='RESUMEN TOTAL'!AN385 -> 0
A381: ='RESUMEN TOTAL'!A386 -> VILLA DEL PLATA | B381: ='RESUMEN TOTAL'!B386 -> VDPL04 | C381: ='RESUMEN TOTAL'!D386 -> Neuquen y Diagonal Guemes | D381: ='RESUMEN TOTAL'!E386 -> Domo | E381: ='RESUMEN TOTAL'!F386 -> Radio | F381: ='RESUMEN TOTAL'!K386 -> 0 | G381: ='RESUMEN TOTAL'!L386 -> 0 | H381: ='RESUMEN TOTAL'!M386 -> 0 | I381: ='RESUMEN TOTAL'!N386 -> 0 | J381: ='RESUMEN TOTAL'!O386 -> 0 | K381: ='RESUMEN TOTAL'!P386 -> 0 | L381: ='RESUMEN TOTAL'!Q386 -> 0 | M381: ='RESUMEN TOTAL'!R386 -> 0 | ... AI381: ='RESUMEN TOTAL'!AN386 -> 0
A382: ='RESUMEN TOTAL'!A387 -> VILLA DEL PLATA | B382: ='RESUMEN TOTAL'!B387 -> VDPL05 | C382: ='RESUMEN TOTAL'!D387 -> Ruta 36 y Abraham | D382: ='RESUMEN TOTAL'!E387 -> Domo | E382: ='RESUMEN TOTAL'!F387 -> PTO A FO | F382: ='RESUMEN TOTAL'!K387 -> 0 | G382: ='RESUMEN TOTAL'!L387 -> 0 | H382: ='RESUMEN TOTAL'!M387 -> 0 | I382: ='RESUMEN TOTAL'!N387 -> 0 | J382: ='RESUMEN TOTAL'!O387 -> 0 | K382: ='RESUMEN TOTAL'!P387 -> 0 | L382: ='RESUMEN TOTAL'!Q387 -> 0 | M382: ='RESUMEN TOTAL'!R387 -> 0 | ... AI382: ='RESUMEN TOTAL'!AN387 -> 0
... A411: ='RESUMEN TOTAL'!A416 -> ZEBALLOS | B411: ='RESUMEN TOTAL'!B416 -> ZEB 05 | C411: ='RESUMEN TOTAL'!D416 -> DIAG. GRANADEROS Y 214 BIS | D411: ='RESUMEN TOTAL'!E416 -> Domo | E411: ='RESUMEN TOTAL'!F416 -> Radio | F411: ='RESUMEN TOTAL'!K416 -> 0 | G411: ='RESUMEN TOTAL'!L416 -> 0 | H411: ='RESUMEN TOTAL'!M416 -> 0 | I411: ='RESUMEN TOTAL'!N416 -> 0 | J411: ='RESUMEN TOTAL'!O416 -> 0 | K411: ='RESUMEN TOTAL'!P416 -> 0 | L411: ='RESUMEN TOTAL'!Q416 -> 0 | M411: ='RESUMEN TOTAL'!R416 -> 0 | ... AI411: ='RESUMEN TOTAL'!AN416 -> 0
A412: ='RESUMEN TOTAL'!#REF! -> #REF! | B412: ='RESUMEN TOTAL'!#REF! -> #REF! | C412: ='RESUMEN TOTAL'!#REF! -> #REF! | D412: ='RESUMEN TOTAL'!#REF! -> #REF! | E412: ='RESUMEN TOTAL'!#REF! -> #REF! | F412: ='RESUMEN TOTAL'!#REF! -> #REF! | G412: ='RESUMEN TOTAL'!#REF! -> #REF! | H412: ='RESUMEN TOTAL'!#REF! -> #REF! | ... AI412: ='RESUMEN TOTAL'!#REF! -> #REF!
A413: ='RESUMEN TOTAL'!#REF! -> #REF! | B413: ='RESUMEN TOTAL'!#REF! -> #REF! | C413: ='RESUMEN TOTAL'!#REF! -> #REF! | D413: ='RESUMEN TOTAL'!#REF! -> #REF! | E413: ='RESUMEN TOTAL'!#REF! -> #REF! | F413: ='RESUMEN TOTAL'!#REF! -> #REF! | G413: ='RESUMEN TOTAL'!#REF! -> #REF! | H413: ='RESUMEN TOTAL'!#REF! -> #REF! | ... AI413: ='RESUMEN TOTAL'!#REF! -> #REF!
A414: ='RESUMEN TOTAL'!A417 -> 0 | B414: ='RESUMEN TOTAL'!B417 -> 0 | C414: ='RESUMEN TOTAL'!D417 -> 0 | D414: ='RESUMEN TOTAL'!E417 -> 0 | E414: ='RESUMEN TOTAL'!F417 -> 0 | F414: ='RESUMEN TOTAL'!K417 -> 0 | G414: ='RESUMEN TOTAL'!L417 -> 0 | H414: ='RESUMEN TOTAL'!M417 -> 0 | I414: ='RESUMEN TOTAL'!N417 -> 0 | J414: ='RESUMEN TOTAL'!O417 -> 0 | K414: ='RESUMEN TOTAL'!P417 -> 0 | L414: ='RESUMEN TOTAL'!Q417 -> 0 | M414: ='RESUMEN TOTAL'!R417 -> 0 | ... AI414: ='RESUMEN TOTAL'!AN417 -> 0
A415: ='RESUMEN TOTAL'!A418 -> 0 | B415: ='RESUMEN TOTAL'!B418 -> 0 | C415: ='RESUMEN TOTAL'!D418 -> 0 | D415: ='RESUMEN TOTAL'!E418 -> 0 | E415: ='RESUMEN TOTAL'!F418 -> 0 | F415: ='RESUMEN TOTAL'!K418 -> 0 | G415: ='RESUMEN TOTAL'!L418 -> 0 | H415: ='RESUMEN TOTAL'!M418 -> 0 | I415: ='RESUMEN TOTAL'!N418 -> 0 | J415: ='RESUMEN TOTAL'!O418 -> 0 | K415: ='RESUMEN TOTAL'!P418 -> 0 | L415: ='RESUMEN TOTAL'!Q418 -> 0 | M415: ='RESUMEN TOTAL'!R418 -> 0 | ... AI415: ='RESUMEN TOTAL'!AN418 -> 0
A416: ='RESUMEN TOTAL'!A419 -> 0 | B416: ='RESUMEN TOTAL'!B419 -> 0 | C416: ='RESUMEN TOTAL'!D419 -> 0 | D416: ='RESUMEN TOTAL'!E419 -> 0 | E416: ='RESUMEN TOTAL'!F419 -> 0 | F416: ='RESUMEN TOTAL'!K419 -> 0 | G416: ='RESUMEN TOTAL'!L419 -> 0 | H416: ='RESUMEN TOTAL'!M419 -> 0 | I416: ='RESUMEN TOTAL'!N419 -> 0 | J416: ='RESUMEN TOTAL'!O419 -> 0 | K416: ='RESUMEN TOTAL'!P419 -> 0 | L416: ='RESUMEN TOTAL'!Q419 -> 0 | M416: ='RESUMEN TOTAL'!R419 -> 0 | ... AI416: ='RESUMEN TOTAL'!AN419 -> 0
A417: ='RESUMEN TOTAL'!A420 -> 0 | B417: ='RESUMEN TOTAL'!B420 -> 0 | C417: ='RESUMEN TOTAL'!D420 -> 0 | D417: ='RESUMEN TOTAL'!E420 -> 0 | E417: ='RESUMEN TOTAL'!F420 -> 0 | F417: ='RESUMEN TOTAL'!K420 -> 0 | G417: ='RESUMEN TOTAL'!L420 -> 0 | H417: ='RESUMEN TOTAL'!M420 -> 0 | I417: ='RESUMEN TOTAL'!N420 -> 0 | J417: ='RESUMEN TOTAL'!O420 -> 0 | K417: ='RESUMEN TOTAL'!P420 -> 0 | L417: ='RESUMEN TOTAL'!Q420 -> 0 | M417: ='RESUMEN TOTAL'!R420 -> 0 | ... AI417: ='RESUMEN TOTAL'!AN420 -> 0
A418: ='RESUMEN TOTAL'!A421 -> 0 | B418: ='RESUMEN TOTAL'!B421 -> 0 | C418: ='RESUMEN TOTAL'!D421 -> 0 | D418: ='RESUMEN TOTAL'!E421 -> 0 | E418: ='RESUMEN TOTAL'!F421 -> 0 | F418: ='RESUMEN TOTAL'!K421 -> 0 | G418: ='RESUMEN TOTAL'!L421 -> 0 | H418: ='RESUMEN TOTAL'!M421 -> 0 | I418: ='RESUMEN TOTAL'!N421 -> 0 | J418: ='RESUMEN TOTAL'!O421 -> 0 | K418: ='RESUMEN TOTAL'!P421 -> 0 | L418: ='RESUMEN TOTAL'!Q421 -> 0 | M418: ='RESUMEN TOTAL'!R421 -> 0 | ... AI418: ='RESUMEN TOTAL'!AN421 -> 0
A419: ='RESUMEN TOTAL'!A422 -> 0 | B419: ='RESUMEN TOTAL'!B422 -> 0 | C419: ='RESUMEN TOTAL'!D422 -> 0 | D419: ='RESUMEN TOTAL'!E422 -> 0 | E419: ='RESUMEN TOTAL'!F422 -> 0 | F419: ='RESUMEN TOTAL'!K422 -> 0 | G419: ='RESUMEN TOTAL'!L422 -> 0 | H419: ='RESUMEN TOTAL'!M422 -> 0 | I419: ='RESUMEN TOTAL'!N422 -> 0 | J419: ='RESUMEN TOTAL'!O422 -> 0 | K419: ='RESUMEN TOTAL'!P422 -> 0 | L419: ='RESUMEN TOTAL'!Q422 -> 0 | M419: ='RESUMEN TOTAL'!R422 -> 0 | ... AI419: ='RESUMEN TOTAL'!AN422 -> 0
A420: ='RESUMEN TOTAL'!A423 -> 0 | B420: ='RESUMEN TOTAL'!B423 -> 0 | C420: ='RESUMEN TOTAL'!D423 -> 0 | D420: ='RESUMEN TOTAL'!E423 -> 0 | E420: ='RESUMEN TOTAL'!F423 -> 0 | F420: ='RESUMEN TOTAL'!K423 -> 0 | G420: ='RESUMEN TOTAL'!L423 -> 0 | H420: ='RESUMEN TOTAL'!M423 -> 0 | I420: ='RESUMEN TOTAL'!N423 -> 0 | J420: ='RESUMEN TOTAL'!O423 -> 0 | K420: ='RESUMEN TOTAL'!P423 -> 0 | L420: ='RESUMEN TOTAL'!Q423 -> 0 | M420: ='RESUMEN TOTAL'!R423 -> 0 | ... AI420: ='RESUMEN TOTAL'!AN423 -> 0
A421: ='RESUMEN TOTAL'!A424 -> 0 | B421: ='RESUMEN TOTAL'!B424 -> 0 | C421: ='RESUMEN TOTAL'!D424 -> 0 | D421: ='RESUMEN TOTAL'!E424 -> 0 | E421: ='RESUMEN TOTAL'!F424 -> 0 | F421: ='RESUMEN TOTAL'!K424 -> 0 | G421: ='RESUMEN TOTAL'!L424 -> 0 | H421: ='RESUMEN TOTAL'!M424 -> 0 | I421: ='RESUMEN TOTAL'!N424 -> 0 | J421: ='RESUMEN TOTAL'!O424 -> 0 | K421: ='RESUMEN TOTAL'!P424 -> 0 | L421: ='RESUMEN TOTAL'!Q424 -> 0 | M421: ='RESUMEN TOTAL'!R424 -> 0 | ... AI421: ='RESUMEN TOTAL'!AN424 -> 0
A422: ='RESUMEN TOTAL'!A425 -> 0 | B422: ='RESUMEN TOTAL'!B425 -> 0 | C422: ='RESUMEN TOTAL'!D425 -> 0 | D422: ='RESUMEN TOTAL'!E425 -> 0 | E422: ='RESUMEN TOTAL'!F425 -> 0 | F422: ='RESUMEN TOTAL'!K425 -> 0 | G422: ='RESUMEN TOTAL'!L425 -> 0 | H422: ='RESUMEN TOTAL'!M425 -> 0 | I422: ='RESUMEN TOTAL'!N425 -> 0 | J422: ='RESUMEN TOTAL'!O425 -> 0 | K422: ='RESUMEN TOTAL'!P425 -> 0 | L422: ='RESUMEN TOTAL'!Q425 -> 0 | M422: ='RESUMEN TOTAL'!R425 -> 0 | ... AI422: ='RESUMEN TOTAL'!AN425 -> 0
A423: ='RESUMEN TOTAL'!A426 -> 0 | B423: ='RESUMEN TOTAL'!B426 -> 0 | C423: ='RESUMEN TOTAL'!D426 -> 0 | D423: ='RESUMEN TOTAL'!E426 -> 0 | E423: ='RESUMEN TOTAL'!F426 -> 0 | F423: ='RESUMEN TOTAL'!K426 -> 0 | G423: ='RESUMEN TOTAL'!L426 -> 0 | H423: ='RESUMEN TOTAL'!M426 -> 0 | I423: ='RESUMEN TOTAL'!N426 -> 0 | J423: ='RESUMEN TOTAL'!O426 -> 0 | K423: ='RESUMEN TOTAL'!P426 -> 0 | L423: ='RESUMEN TOTAL'!Q426 -> 0 | M423: ='RESUMEN TOTAL'!R426 -> 0 | ... AI423: ='RESUMEN TOTAL'!AN426 -> 0
A424: ='RESUMEN TOTAL'!A427 -> 0 | B424: ='RESUMEN TOTAL'!B427 -> 0 | C424: ='RESUMEN TOTAL'!D427 -> 0 | D424: ='RESUMEN TOTAL'!E427 -> 0 | E424: ='RESUMEN TOTAL'!F427 -> 0 | F424: ='RESUMEN TOTAL'!K427 -> 0 | G424: ='RESUMEN TOTAL'!L427 -> 0 | H424: ='RESUMEN TOTAL'!M427 -> 0 | I424: ='RESUMEN TOTAL'!N427 -> 0 | J424: ='RESUMEN TOTAL'!O427 -> 0 | K424: ='RESUMEN TOTAL'!P427 -> 0 | L424: ='RESUMEN TOTAL'!Q427 -> 0 | M424: ='RESUMEN TOTAL'!R427 -> 0 | ... AI424: ='RESUMEN TOTAL'!AN427 -> 0
A425: ='RESUMEN TOTAL'!A428 -> 0 | B425: ='RESUMEN TOTAL'!B428 -> 0 | C425: ='RESUMEN TOTAL'!D428 -> 0 | D425: ='RESUMEN TOTAL'!E428 -> 0 | E425: ='RESUMEN TOTAL'!F428 -> 0 | F425: ='RESUMEN TOTAL'!K428 -> 0 | G425: ='RESUMEN TOTAL'!L428 -> 0 | H425: ='RESUMEN TOTAL'!M428 -> 0 | I425: ='RESUMEN TOTAL'!N428 -> 0 | J425: ='RESUMEN TOTAL'!O428 -> 0 | K425: ='RESUMEN TOTAL'!P428 -> 0 | L425: ='RESUMEN TOTAL'!Q428 -> 0 | M425: ='RESUMEN TOTAL'!R428 -> 0 | ... AI425: ='RESUMEN TOTAL'!AN428 -> 0
...

Sheet APAGADOS
E1: APAGADOS | F1: =COUNTIF(F3:F400, "APAGADO") -> 28 | G1: =COUNTIF(G3:G400, "APAGADO") -> 53 | H1: =COUNTIF(H3:H400, "APAGADO") -> 85 | I1: =COUNTIF(I3:I400, "APAGADO") -> 86 | J1: =COUNTIF(J3:J400, "APAGADO") -> 38 | K1: =COUNTIF(K3:K400, "APAGADO") -> 32 | L1: =COUNTIF(L3:L400, "APAGADO") -> 21 | M1: =COUNTIF(M3:M400, "APAGADO") -> 21 | ... AI1: =COUNTIF(AI3:AI400, "APAGADO") -> 0
A2: =ESTADISTICA!A1 -> Barrio | B2: =ESTADISTICA!B1 -> [Denominacion] | C2: =ESTADISTICA!C1 -> [Ubicacion] | D2: =ESTADISTICA!D1 -> [Tipo de Camara] | E2: =ESTADISTICA!E1 -> [Tipo de Conexion] | F2: =ESTADISTICA!F1 -> 44805 | G2: =ESTADISTICA!G1 -> 44806 | H2: =ESTADISTICA!H1 -> 44807 | ... AI2: =ESTADISTICA!AI1 -> 44834
A3: =ESTADISTICA!A2 -> ALTAMIRA | B3: =ESTADISTICA!B2 -> ALT01 | C3: =ESTADISTICA!C2 -> Calchaqui y Sgto. Cabral | D3: =ESTADISTICA!D2 -> Domo | E3: =ESTADISTICA!E2 -> Fibra Optica | F3: =ESTADISTICA!F2 -> 0 | G3: =ESTADISTICA!G2 -> 0 | H3: =ESTADISTICA!H2 -> 0 | ... AI3: =ESTADISTICA!AI2 -> 0
A4: =ESTADISTICA!A3 -> ALTAMIRA | B4: =ESTADISTICA!B3 -> ALT02 | C4: =ESTADISTICA!C3 -> Calchaqui y Lope de Vega | D4: =ESTADISTICA!D3 -> Domo | E4: =ESTADISTICA!E3 -> PTO A FO | F4: =ESTADISTICA!F3 -> 0 | G4: =ESTADISTICA!G3 -> 0 | H4: =ESTADISTICA!H3 -> 0 | ... AI4: =ESTADISTICA!AI3 -> 0
A5: =ESTADISTICA!A4 -> ALTAMIRA | B5: =ESTADISTICA!B4 -> ALT 03 | C5: =ESTADISTICA!C4 -> Bombero Galarza y Necochea | D5: =ESTADISTICA!D4 -> Domo | E5: =ESTADISTICA!E4 -> FIBRA OPTICA | F5: =ESTADISTICA!F4 -> 0 | G5: =ESTADISTICA!G4 -> 0 | H5: =ESTADISTICA!H4 -> 0 | ... AI5: =ESTADISTICA!AI4 -> 0
A6: =ESTADISTICA!A5 -> ALTAMIRA | B6: =ESTADISTICA!B5 -> ALT 04 | C6: =ESTADISTICA!C5 -> Francia y Necochea | D6: =ESTADISTICA!D5 -> Domo | E6: =ESTADISTICA!E5 -> FIBRA OPTICA | F6: =ESTADISTICA!F5 -> 0 | G6: =ESTADISTICA!G5 -> 0 | H6: =ESTADISTICA!H5 -> 0 | ... AI6: =ESTADISTICA!AI5 -> 0
A7: =ESTADISTICA!A6 -> ALTAMIRA | B7: =ESTADISTICA!B6 -> ALT05 | C7: =ESTADISTICA!C6 -> Av. Calchaqui y Bombero Galarza | D7: =ESTADISTICA!D6 -> Domo | E7: =ESTADISTICA!E6 -> PTO A FO | F7: =ESTADISTICA!F6 -> APAGADO | G7: =ESTADISTICA!G6 -> APAGADO | H7: =ESTADISTICA!H6 -> APAGADO | ... AI7: =ESTADISTICA!AI6 -> 0
A8: =ESTADISTICA!A7 -> ALTAMIRA | B8: =ESTADISTICA!B7 -> ALT 06 | C8: =ESTADISTICA!C7 -> LOPE DE VEGA Y NECOCHEA | D8: =ESTADISTICA!D7 -> Domo | E8: =ESTADISTICA!E7 -> PTO A FO | F8: =ESTADISTICA!F7 -> 0 | G8: =ESTADISTICA!G7 -> 0 | H8: =ESTADISTICA!H7 -> 0 | ... AI8: =ESTADISTICA!AI7 -> 0
A9: =ESTADISTICA!A8 -> ALTAMIRA | B9: =ESTADISTICA!B8 -> ALT07 | C9: =ESTADISTICA!C8 -> AV. CALCHAQUI Y AV. DEL TRABAJO | D9: =ESTADISTICA!D8 -> DOMO | E9: =ESTADISTICA!E8 -> PTO A FO | F9: =ESTADISTICA!F8 -> 0 | G9: =ESTADISTICA!G8 -> 0 | H9: =ESTADISTICA!H8 -> 0 | ... AI9: =ESTADISTICA!AI8 -> 0
A10: =ESTADISTICA!A9 -> ALTAMIRA | B10: =ESTADISTICA!B9 -> ALT 08 | C10: =ESTADISTICA!C9 -> HUMAITA Y NECOCHEA | D10: =ESTADISTICA!D9 -> DOMO | E10: =ESTADISTICA!E9 -> Fibra Optica | F10: =ESTADISTICA!F9 -> 0 | G10: =ESTADISTICA!G9 -> 0 | H10: =ESTADISTICA!H9 -> 0 | ... AI10: =ESTADISTICA!AI9 -> 0
A11: =ESTADISTICA!A10 -> ALTAMIRA | B11: =ESTADISTICA!B10 -> ALT 09 | C11: =ESTADISTICA!C10 -> NECOCHEA Y CURUPAITY | D11: =ESTADISTICA!D10 -> DOMO | E11: =ESTADISTICA!E10 -> Fibra Optica | F11: =ESTADISTICA!F10 -> 0 | G11: =ESTADISTICA!G10 -> 0 | H11: =ESTADISTICA!H10 -> 0 | ... AI11: =ESTADISTICA!AI10 -> 0
A12: =ESTADISTICA!A11 -> ALTAMIRA | B12: =ESTADISTICA!B11 -> ALT 10 | C12: =ESTADISTICA!C11 -> Calchaqui y Francia | D12: =ESTADISTICA!D11 -> Domo | E12: =ESTADISTICA!E11 -> Radio | F12: =ESTADISTICA!F11 -> APAGADO | G12: =ESTADISTICA!G11 -> APAGADO | H12: =ESTADISTICA!H11 -> APAGADO | ... AI12: =ESTADISTICA!AI11 -> 0
A13: =ESTADISTICA!A12 -> AGUSTIN RAMIREZ | B13: =ESTADISTICA!B12 -> ARA 01 | C13: =ESTADISTICA!C12 -> Malambo y Tranquera | D13: =ESTADISTICA!D12 -> Domo | E13: =ESTADISTICA!E12 -> FIBRA OPTICA | F13: =ESTADISTICA!F12 -> 0 | G13: =ESTADISTICA!G12 -> 0 | H13: =ESTADISTICA!H12 -> 0 | ... AI13: =ESTADISTICA!AI12 -> 0
... A401: =ESTADISTICA!A400 -> VILLA MONICA VIEJA | B401: =ESTADISTICA!B400 -> VMOV 03 (fija 1) | C401: =ESTADISTICA!C400 -> ROMA E/ HOLANDA Y CAFFERATA | D401: =ESTADISTICA!D400 -> Fija | E401: =ESTADISTICA!E400 -> Fibra Optica | F401: =ESTADISTICA!F400 -> 0 | G401: =ESTADISTICA!G400 -> 0 | H401: =ESTADISTICA!H400 -> 0 | ... AI401: =ESTADISTICA!AI400 -> 0

Sheet APAGADOS FIBRA
C1: TOTAL FIBRA | D1: =COUNTIFS(E4:E400,"=Fibra Optica") -> 271
E2: APAGADOS | F2: =COUNTIFS(F4:F400, "=APAGADO",E4:E400,"=Fibra Optica") -> 22 | G2: =COUNTIFS(G4:G400, "=APAGADO",E4:E400,"=Fibra Optica") -> 49 | H2: =COUNTIFS(H4:H400, "=APAGADO",E4:E400,"=Fibra Optica") -> 55 | I2: =COUNTIFS(I4:I400, "=APAGADO",E4:E400,"=Fibra Optica") -> 54 | J2: =COUNTIFS(J4:J400, "=APAGADO",E4:E400,"=Fibra Optica") -> 32 | K2: =COUNTIFS(K4:K400, "=APAGADO",E4:E400,"=Fibra Optica") -> 29 | L2: =COUNTIFS(L4:L400, "=APAGADO",E4:E400,"=Fibra Optica") -> 17 | M2: =COUNTIFS(M4:M400, "=APAGADO",E4:E400,"=Fibra Optica") -> 16 | N2: =COUNTIFS(N4:N400, "=APAGADO",E4:E400,"=Fibra Optica") -> 30 | O2: =COUNTIFS(O4:O400, "=APAGADO",E4:E400,"=Fibra Optica") -> 22 | P2: =COUNTIFS(P4:P400, "=APAGADO",E4:E400,"=Fibra Optica") -> 23 | Q2: =COUNTIFS(Q4:Q400, "=APAGADO",E4:E400,"=Fibra Optica") -> 21 | R2: =COUNTIFS(R4:R400, "=APAGADO",E4:E400,"=Fibra Optica") -> 22 | S2: =COUNTIFS(S4:S400, "=APAGADO",E4:E400,"=Fibra Optica") -> 26 | T2: =COUNTIFS(T4:T400, "=APAGADO",E4:E400,"=Fibra Optica") -> 33 | U2: =COUNTIFS(U4:U400, "=APAGADO",E4:E400,"=Fibra Optica") -> 29 | V2: =COUNTIFS(V4:V400, "=APAGADO",E4:E400,"=Fibra Optica") -> 31 | W2: =COUNTIFS(W4:W400, "=APAGADO",E4:E400,"=Fibra Optica") -> 31 | X2: =COUNTIFS(X4:X400, "=APAGADO",E4:E400,"=Fibra Optica") -> 29 | Y2: =COUNTIFS(Y4:Y400, "=APAGADO",E4:E400,"=Fibra Optica") -> 33 | Z2: =COUNTIFS(Z4:Z400, "=APAGADO",E4:E400,"=Fibra Optica") -> 33 | AA2: =COUNTIFS(AA4:AA400, "=APAGADO",E4:E400,"=Fibra Optica") -> 34 | AB2: =COUNTIFS(AB4:AB400, "=APAGADO",E4:E400,"=Fibra Optica") -> 40 | AC2: =COUNTIFS(AC4:AC400, "=APAGADO",E4:E400,"=Fibra Optica") -> 34 | AD2: =COUNTIFS(AD4:AD400, "=APAGADO",E4:E400,"=Fibra Optica") -> 35 | AE2: =COUNTIFS(AE4:AE400, "=APAGADO",E4:E400,"=Fibra Optica") -> 0 | AF2: =COUNTIFS(AF4:AF400, "=APAGADO",E4:E400,"=Fibra Optica") -> 0 | AG2: =COUNTIFS(AG4:AG400, "=APAGADO",E4:E400,"=Fibra Optica") -> 0 | AH2: =COUNTIFS(AH4:AH400, "=APAGADO",E4:E400,"=Fibra Optica") -> 0 | AI2: =COUNTIFS(AI4:AI400, "=APAGADO",E4:E400,"=Fibra Optica") -> 0
A3: =ESTADISTICA!A1 -> Barrio | B3: =ESTADISTICA!B1 -> [Denominacion] | C3: =ESTADISTICA!C1 -> [Ubicacion] | D3: =ESTADISTICA!D1 -> [Tipo de Camara] | E3: =ESTADISTICA!E1 -> [Tipo de Conexion] | F3: =ESTADISTICA!F1 -> 44805 | G3: =ESTADISTICA!G1 -> 44806 | H3: =ESTADISTICA!H1 -> 44807 | ... AI3: =ESTADISTICA!AI1 -> 44834
A4: =ESTADISTICA!A2 -> ALTAMIRA | B4: =ESTADISTICA!B2 -> ALT01 | C4: =ESTADISTICA!C2 -> Calchaqui y Sgto. Cabral | D4: =ESTADISTICA!D2 -> Domo | E4: =ESTADISTICA!E2 -> Fibra Optica | F4: =ESTADISTICA!F2 -> 0 | G4: =ESTADISTICA!G2 -> 0 | H4: =ESTADISTICA!H2 -> 0 | ... AI4: =ESTADISTICA!AI2 -> 0
A5: =ESTADISTICA!A3 -> ALTAMIRA | B5: =ESTADISTICA!B3 -> ALT02 | C5: =ESTADISTICA!C3 -> Calchaqui y Lope de Vega | D5: =ESTADISTICA!D3 -> Domo | E5: =ESTADISTICA!E3 -> PTO A FO | F5: =ESTADISTICA!F3 -> 0 | G5: =ESTADISTICA!G3 -> 0 | H5: =ESTADISTICA!H3 -> 0 | ... AI5: =ESTADISTICA!AI3 -> 0
A6: =ESTADISTICA!A4 -> ALTAMIRA | B6: =ESTADISTICA!B4 -> ALT 03 | C6: =ESTADISTICA!C4 -> Bombero Galarza y Necochea | D6: =ESTADISTICA!D4 -> Domo | E6: =ESTADISTICA!E4 -> FIBRA OPTICA | F6: =ESTADISTICA!F4 -> 0 | G6: =ESTADISTICA!G4 -> 0 | H6: =ESTADISTICA!H4 -> 0 | ... AI6: =ESTADISTICA!AI4 -> 0
A7: =ESTADISTICA!A5 -> ALTAMIRA | B7: =ESTADISTICA!B5 -> ALT 04 | C7: =ESTADISTICA!C5 -> Francia y Necochea | D7: =ESTADISTICA!D5 -> Domo | E7: =ESTADISTICA!E5 -> FIBRA OPTICA | F7: =ESTADISTICA!F5 -> 0 | G7: =ESTADISTICA!G5 -> 0 | H7: =ESTADISTICA!H5 -> 0 | ... AI7: =ESTADISTICA!AI5 -> 0
A8: =ESTADISTICA!A6 -> ALTAMIRA | B8: =ESTADISTICA!B6 -> ALT05 | C8: =ESTADISTICA!C6 -> Av. Calchaqui y Bombero Galarza | D8: =ESTADISTICA!D6 -> Domo | E8: =ESTADISTICA!E6 -> PTO A FO | F8: =ESTADISTICA!F6 -> APAGADO | G8: =ESTADISTICA!G6 -> APAGADO | H8: =ESTADISTICA!H6 -> APAGADO | ... AI8: =ESTADISTICA!AI6 -> 0
A9: =ESTADISTICA!A7 -> ALTAMIRA | B9: =ESTADISTICA!B7 -> ALT 06 | C9: =ESTADISTICA!C7 -> LOPE DE VEGA Y NECOCHEA | D9: =ESTADISTICA!D7 -> Domo | E9: =ESTADISTICA!E7 -> PTO A FO | F9: =ESTADISTICA!F7 -> 0 | G9: =ESTADISTICA!G7 -> 0 | H9: =ESTADISTICA!H7 -> 0 | ... AI9: =ESTADISTICA!AI7 -> 0
A10: =ESTADISTICA!A8 -> ALTAMIRA | B10: =ESTADISTICA!B8 -> ALT07 | C10: =ESTADISTICA!C8 -> AV. CALCHAQUI Y AV. DEL TRABAJO | D10: =ESTADISTICA!D8 -> DOMO | E10: =ESTADISTICA!E8 -> PTO A FO | F10: =ESTADISTICA!F8 -> 0 | G10: =ESTADISTICA!G8 -> 0 | H10: =ESTADISTICA!H8 -> 0 | ... AI10: =ESTADISTICA!AI8 -> 0
A11: =ESTADISTICA!A9 -> ALTAMIRA | B11: =ESTADISTICA!B9 -> ALT 08 | C11: =ESTADISTICA!C9 -> HUMAITA Y NECOCHEA | D11: =ESTADISTICA!D9 -> DOMO | E11: =ESTADISTICA!E9 -> Fibra Optica | F11: =ESTADISTICA!F9 -> 0 | G11: =ESTADISTICA!G9 -> 0 | H11: =ESTADISTICA!H9 -> 0 | ... AI11: =ESTADISTICA!AI9 -> 0
A12: =ESTADISTICA!A10 -> ALTAMIRA | B12: =ESTADISTICA!B10 -> ALT 09 | C12: =ESTADISTICA!C10 -> NECOCHEA Y CURUPAITY | D12: =ESTADISTICA!D10 -> DOMO | E12: =ESTADISTICA!E10 -> Fibra Optica | F12: =ESTADISTICA!F10 -> 0 | G12: =ESTADISTICA!G10 -> 0 | H12: =ESTADISTICA!H10 -> 0 | ... AI12: =ESTADISTICA!AI10 -> 0
A13: =ESTADISTICA!A11 -> ALTAMIRA | B13: =ESTADISTICA!B11 -> ALT 10 | C13: =ESTADISTICA!C11 -> Calchaqui y Francia | D13: =ESTADISTICA!D11 -> Domo | E13: =ESTADISTICA!E11 -> Radio | F13: =ESTADISTICA!F11 -> APAGADO | G13: =ESTADISTICA!G11 -> APAGADO | H13: =ESTADISTICA!H11 -> APAGADO | ... AI13: =ESTADISTICA!AI11 -> 0
A14: =ESTADISTICA!A12 -> AGUSTIN RAMIREZ | B14: =ESTADISTICA!B12 -> ARA 01 | C14: =ESTADISTICA!C12 -> Malambo y Tranquera | D14: =ESTADISTICA!D12 -> Domo | E14: =ESTADISTICA!E12 -> FIBRA OPTICA | F14: =ESTADISTICA!F12 -> 0 | G14: =ESTADISTICA!G12 -> 0 | H14: =ESTADISTICA!H12 -> 0 | ... AI14: =ESTADISTICA!AI12 -> 0
... A400: =ESTADISTICA!A398 -> VILLA MONICA VIEJA | B400: =ESTADISTICA!B398 -> VMOV01 (fija 1) | C400: =ESTADISTICA!C398 -> ATENAS E/ CAFFERATA Y ALEMANIA | D400: =ESTADISTICA!D398 -> Fija | E400: =ESTADISTICA!E398 -> Fibra Optica | F400: =ESTADISTICA!F398 -> 0 | G400: =ESTADISTICA!G398 -> 0 | H400: =ESTADISTICA!H398 -> 0 | ... AI400: =ESTADISTICA!AI398 -> 0

Sheet APAGADOS ANTENA
C1: TOTAL PTO A FO
E2: APAGADOS | F2: =COUNTIFS(F4:F400, "=APAGADO",E4:E400,"=PTO A FO") -> 1 | G2: =COUNTIFS(G4:G400, "=APAGADO",E4:E400,"=PTO A FO") -> 2 | H2: =COUNTIFS(H4:H400, "=APAGADO",E4:E400,"=PTO A FO") -> 10 | I2: =COUNTIFS(I4:I400, "=APAGADO",E4:E400,"=PTO A FO") -> 11 | J2: =COUNTIFS(J4:J400, "=APAGADO",E4:E400,"=PTO A FO") -> 3 | K2: =COUNTIFS(K4:K400, "=APAGADO",E4:E400,"=PTO A FO") -> 1 | L2: =COUNTIFS(L4:L400, "=APAGADO",E4:E400,"=PTO A FO") -> 1 | M2: =COUNTIFS(M4:M400, "=APAGADO",E4:E400,"=PTO A FO") -> 1 | N2: =COUNTIFS(N4:N400, "=APAGADO",E4:E400,"=PTO A FO") -> 2 | O2: =COUNTIFS(O4:O500, "=APAGADO",E4:E500,"=PTO A FO") -> 2 | P2: =COUNTIFS(P4:P400, "=APAGADO",E4:E400,"=PTO A FO") -> 3 | Q2: =COUNTIFS(Q4:Q400, "=APAGADO",E4:E400,"=PTO A FO") -> 2 | R2: =COUNTIFS(R4:R400, "=APAGADO",E4:E400,"=PTO A FO") -> 3 | S2: =COUNTIFS(S4:S400, "=APAGADO",E4:E400,"=PTO A FO") -> 3 | T2: =COUNTIFS(T4:T400, "=APAGADO",E4:E400,"=PTO A FO") -> 4 | U2: =COUNTIFS(U4:U400, "=APAGADO",E4:E400,"=PTO A FO") -> 4 | V2: =COUNTIFS(V4:V400, "=APAGADO",E4:E400,"=PTO A FO") -> 4 | W2: =COUNTIFS(W4:W400, "=APAGADO",E4:E400,"=PTO A FO") -> 4 | X2: =COUNTIFS(X4:X400, "=APAGADO",E4:E400,"=PTO A FO") -> 4 | Y2: =COUNTIFS(Y4:Y400, "=APAGADO",E4:E400,"=PTO A FO") -> 6 | Z2: =COUNTIFS(Z4:Z400, "=APAGADO",E4:E400,"=PTO A FO") -> 4 | AA2: =COUNTIFS(AA4:AA400, "=APAGADO",E4:E400,"=PTO A FO") -> 3 | AB2: =COUNTIFS(AB4:AB400, "=APAGADO",E4:E400,"=PTO A FO") -> 5 | AC2: =COUNTIFS(AC4:AC400, "=APAGADO",E4:E400,"=PTO A FO") -> 3 | AD2: =COUNTIFS(AD4:AD400, "=APAGADO",E4:E400,"=PTO A FO") -> 4 | AE2: =COUNTIFS(AE4:AE400, "=APAGADO",E4:E400,"=PTO A FO") -> 0 | AF2: =COUNTIFS(AF4:AF400, "=APAGADO",E4:E400,"=PTO A FO") -> 0 | AG2: =COUNTIFS(AG4:AG400, "=APAGADO",E4:E400,"=PTO A FO") -> 0 | AH2: =COUNTIFS(AH4:AH400, "=APAGADO",E4:E400,"=PTO A FO") -> 0 | AI2: =COUNTIFS(AI4:AI400, "=APAGADO",E4:E400,"=PTO A FO") -> 0
A3: =ESTADISTICA!A1 -> Barrio | B3: =ESTADISTICA!B1 -> [Denominacion] | C3: =ESTADISTICA!C1 -> [Ubicacion] | D3: =ESTADISTICA!D1 -> [Tipo de Camara] | E3: =ESTADISTICA!E1 -> [Tipo de Conexion] | F3: =ESTADISTICA!F1 -> 44805 | G3: =ESTADISTICA!G1 -> 44806 | H3: =ESTADISTICA!H1 -> 44807 | ... AI3: =ESTADISTICA!AI1 -> 44834
A4: =ESTADISTICA!A2 -> ALTAMIRA | B4: =ESTADISTICA!B2 -> ALT01 | C4: =ESTADISTICA!C2 -> Calchaqui y Sgto. Cabral | D4: =ESTADISTICA!D2 -> Domo | E4: =ESTADISTICA!E2 -> Fibra Optica | F4: =ESTADISTICA!F2 -> 0 | G4: =ESTADISTICA!G2 -> 0 | H4: =ESTADISTICA!H2 -> 0 | ... AI4: =ESTADISTICA!AI2 -> 0
A5: =ESTADISTICA!A3 -> ALTAMIRA | B5: =ESTADISTICA!B3 -> ALT02 | C5: =ESTADISTICA!C3 -> Calchaqui y Lope de Vega | D5: =ESTADISTICA!D3 -> Domo | E5: =ESTADISTICA!E3 -> PTO A FO | F5: =ESTADISTICA!F3 -> 0 | G5: =ESTADISTICA!G3 -> 0 | H5: =ESTADISTICA!H3 -> 0 | ... AI5: =ESTADISTICA!AI3 -> 0
A6: =ESTADISTICA!A4 -> ALTAMIRA | B6: =ESTADISTICA!B4 -> ALT 03 | C6: =ESTADISTICA!C4 -> Bombero Galarza y Necochea | D6: =ESTADISTICA!D4 -> Domo | E6: =ESTADISTICA!E4 -> FIBRA OPTICA | F6: =ESTADISTICA!F4 -> 0 | G6: =ESTADISTICA!G4 -> 0 | H6: =ESTADISTICA!H4 -> 0 | ... AI6: =ESTADISTICA!AI4 -> 0
A7: =ESTADISTICA!A5 -> ALTAMIRA | B7: =ESTADISTICA!B5 -> ALT 04 | C7: =ESTADISTICA!C5 -> Francia y Necochea | D7: =ESTADISTICA!D5 -> Domo | E7: =ESTADISTICA!E5 -> FIBRA OPTICA | F7: =ESTADISTICA!F5 -> 0 | G7: =ESTADISTICA!G5 -> 0 | H7: =ESTADISTICA!H5 -> 0 | ... AI7: =ESTADISTICA!AI5 -> 0
A8: =ESTADISTICA!A6 -> ALTAMIRA | B8: =ESTADISTICA!B6 -> ALT05 | C8: =ESTADISTICA!C6 -> Av. Calchaqui y Bombero Galarza | D8: =ESTADISTICA!D6 -> Domo | E8: =ESTADISTICA!E6 -> PTO A FO | F8: =ESTADISTICA!F6 -> APAGADO | G8: =ESTADISTICA!G6 -> APAGADO | H8: =ESTADISTICA!H6 -> APAGADO | ... AI8: =ESTADISTICA!AI6 -> 0
A9: =ESTADISTICA!A7 -> ALTAMIRA | B9: =ESTADISTICA!B7 -> ALT 06 | C9: =ESTADISTICA!C7 -> LOPE DE VEGA Y NECOCHEA | D9: =ESTADISTICA!D7 -> Domo | E9: =ESTADISTICA!E7 -> PTO A FO | F9: =ESTADISTICA!F7 -> 0 | G9: =ESTADISTICA!G7 -> 0 | H9: =ESTADISTICA!H7 -> 0 | ... AI9: =ESTADISTICA!AI7 -> 0
A10: =ESTADISTICA!A8 -> ALTAMIRA | B10: =ESTADISTICA!B8 -> ALT07 | C10: =ESTADISTICA!C8 -> AV. CALCHAQUI Y AV. DEL TRABAJO | D10: =ESTADISTICA!D8 -> DOMO | E10: =ESTADISTICA!E8 -> PTO A FO | F10: =ESTADISTICA!F8 -> 0 | G10: =ESTADISTICA!G8 -> 0 | H10: =ESTADISTICA!H8 -> 0 | ... AI10: =ESTADISTICA!AI8 -> 0
A11: =ESTADISTICA!A9 -> ALTAMIRA | B11: =ESTADISTICA!B9 -> ALT 08 | C11: =ESTADISTICA!C9 -> HUMAITA Y NECOCHEA | D11: =ESTADISTICA!D9 -> DOMO | E11: =ESTADISTICA!E9 -> Fibra Optica | F11: =ESTADISTICA!F9 -> 0 | G11: =ESTADISTICA!G9 -> 0 | H11: =ESTADISTICA!H9 -> 0 | ... AI11: =ESTADISTICA!AI9 -> 0
A12: =ESTADISTICA!A10 -> ALTAMIRA | B12: =ESTADISTICA!B10 -> ALT 09 | C12: =ESTADISTICA!C10 -> NECOCHEA Y CURUPAITY | D12: =ESTADISTICA!D10 -> DOMO | E12: =ESTADISTICA!E10 -> Fibra Optica | F12: =ESTADISTICA!F10 -> 0 | G12: =ESTADISTICA!G10 -> 0 | H12: =ESTADISTICA!H10 -> 0 | ... AI12: =ESTADISTICA!AI10 -> 0
A13: =ESTADISTICA!A11 -> ALTAMIRA | B13: =ESTADISTICA!B11 -> ALT 10 | C13: =ESTADISTICA!C11 -> Calchaqui y Francia | D13: =ESTADISTICA!D11 -> Domo | E13: =ESTADISTICA!E11 -> Radio | F13: =ESTADISTICA!F11 -> APAGADO | G13: =ESTADISTICA!G11 -> APAGADO | H13: =ESTADISTICA!H11 -> APAGADO | ... AI13: =ESTADISTICA!AI11 -> 0
A14: =ESTADISTICA!A12 -> AGUSTIN RAMIREZ | B14: =ESTADISTICA!B12 -> ARA 01 | C14: =ESTADISTICA!C12 -> Malambo y Tranquera | D14: =ESTADISTICA!D12 -> Domo | E14: =ESTADISTICA!E12 -> FIBRA OPTICA | F14: =ESTADISTICA!F12 -> 0 | G14: =ESTADISTICA!G12 -> 0 | H14: =ESTADISTICA!H12 -> 0 | ... AI14: =ESTADISTICA!AI12 -> 0
... A278: =ESTADISTICA!A276 -> LA SIRENA | B278: =ESTADISTICA!B276 -> SIR 14 | C278: =ESTADISTICA!C276 -> MANUEL IGLESIAS Y PEDRAZA | D278: =ESTADISTICA!D276 -> Domo | E278: =ESTADISTICA!E276 -> Fibra Optica | F278: =ESTADISTICA!F276 -> 0 | G278: =ESTADISTICA!G276 -> APAGADO | H278: =ESTADISTICA!H276 -> 0 | ... AI278: =ESTADISTICA!AI276 -> 0
B279: =ESTADISTICA!B277 -> SIR 15 | C279: =ESTADISTICA!C277 -> Monteverde y Azara | D279: =ESTADISTICA!D277 -> Domo | E279: =ESTADISTICA!E277 -> Fibra Optica | F279: =ESTADISTICA!F277 -> 0 | G279: =ESTADISTICA!G277 -> APAGADO | H279: =ESTADISTICA!H277 -> APAGADO | I279: =ESTADISTICA!I277 -> APAGADO | ... AI279: =ESTADISTICA!AI277 -> 0
A280: =ESTADISTICA!A278 -> SAN JORGE | B280: =ESTADISTICA!B278 -> SJO 03 | C280: =ESTADISTICA!C278 -> 517 Y 580 | D280: =ESTADISTICA!D278 -> DOMO | E280: =ESTADISTICA!E278 -> Radio | F280: =ESTADISTICA!F278 -> 0 | G280: =ESTADISTICA!G278 -> 0 | H280: =ESTADISTICA!H278 -> APAGADO | ... AI280: =ESTADISTICA!AI278 -> 0
A281: =ESTADISTICA!A279 -> SAN JORGE | B281: =ESTADISTICA!B279 -> SJO 04 | C281: =ESTADISTICA!C279 -> 552 Y 519 | D281: =ESTADISTICA!D279 -> DOMO | E281: =ESTADISTICA!E279 -> Radio | F281: =ESTADISTICA!F279 -> 0 | G281: =ESTADISTICA!G279 -> 0 | H281: =ESTADISTICA!H279 -> APAGADO | ... AI281: =ESTADISTICA!AI279 -> 0
A282: =ESTADISTICA!A280 -> SAN JORGE | B282: =ESTADISTICA!B280 -> SJO 09 (FIJA 1) | C282: =ESTADISTICA!C280 -> 515 Y 566 | D282: =ESTADISTICA!D280 -> Fija | E282: =ESTADISTICA!E280 -> Radio | F282: =ESTADISTICA!F280 -> 0 | G282: =ESTADISTICA!G280 -> 0 | H282: =ESTADISTICA!H280 -> 0 | ... AI282: =ESTADISTICA!AI280 -> 0
A283: =ESTADISTICA!A281 -> SAN JORGE | B283: =ESTADISTICA!B281 -> SJO 10 (FIJA 2) | C283: =ESTADISTICA!C281 -> 515 Y 566 | D283: =ESTADISTICA!D281 -> Fija | E283: =ESTADISTICA!E281 -> Radio | F283: =ESTADISTICA!F281 -> 0 | G283: =ESTADISTICA!G281 -> 0 | H283: =ESTADISTICA!H281 -> 0 | ... AI283: =ESTADISTICA!AI281 -> 0
A284: =ESTADISTICA!A282 -> SAN JORGE | B284: =ESTADISTICA!B282 -> SJO01 | C284: =ESTADISTICA!C282 -> Calle 554 y 527 | D284: =ESTADISTICA!D282 -> Domo | E284: =ESTADISTICA!E282 -> Radio | F284: =ESTADISTICA!F282 -> 0 | G284: =ESTADISTICA!G282 -> 0 | H284: =ESTADISTICA!H282 -> 0 | ... AI284: =ESTADISTICA!AI282 -> 0
A285: =ESTADISTICA!A283 -> SAN JORGE | B285: =ESTADISTICA!B283 -> SJO02 | C285: =ESTADISTICA!C283 -> Calle 554 y 511 | D285: =ESTADISTICA!D283 -> Domo | E285: =ESTADISTICA!E283 -> Radio | F285: =ESTADISTICA!F283 -> 0 | G285: =ESTADISTICA!G283 -> 0 | H285: =ESTADISTICA!H283 -> APAGADO | ... AI285: =ESTADISTICA!AI283 -> 0
A286: =ESTADISTICA!A284 -> SAN JORGE | B286: =ESTADISTICA!B284 -> SJO05 (fija 1) | C286: =ESTADISTICA!C284 -> 511 Y 560 | D286: =ESTADISTICA!D284 -> Fija | E286: =ESTADISTICA!E284 -> Fibra Optica | F286: =ESTADISTICA!F284 -> 0 | G286: =ESTADISTICA!G284 -> 0 | H286: =ESTADISTICA!H284 -> 0 | ... AI286: =ESTADISTICA!AI284 -> 0
A287: =ESTADISTICA!A285 -> SAN JORGE | B287: =ESTADISTICA!B285 -> SJO06 (fija 2) | C287: =ESTADISTICA!C285 -> 511 Y 560 | D287: =ESTADISTICA!D285 -> Fija | E287: =ESTADISTICA!E285 -> Fibra Optica | F287: =ESTADISTICA!F285 -> 0 | G287: =ESTADISTICA!G285 -> 0 | H287: =ESTADISTICA!H285 -> 0 | ... AI287: =ESTADISTICA!AI285 -> 0
A288: =ESTADISTICA!A286 -> SAN JORGE | B288: =ESTADISTICA!B286 -> SJO07 (fija 1) | C288: =ESTADISTICA!C286 -> 503 Y 556 | D288: =ESTADISTICA!D286 -> Fija | E288: =ESTADISTICA!E286 -> Fibra Optica | F288: =ESTADISTICA!F286 -> 0 | G288: =ESTADISTICA!G286 -> 0 | H288: =ESTADISTICA!H286 -> 0 | ... AI288: =ESTADISTICA!AI286 -> 0
A289: =ESTADISTICA!A287 -> SAN JORGE | B289: =ESTADISTICA!B287 -> SJO08 (fija 2) | C289: =ESTADISTICA!C287 -> 503 Y 556 | D289: =ESTADISTICA!D287 -> Fija | E289: =ESTADISTICA!E287 -> Fibra Optica | F289: =ESTADISTICA!F287 -> 0 | G289: =ESTADISTICA!G287 -> 0 | H289: =ESTADISTICA!H287 -> 0 | ... AI289: =ESTADISTICA!AI287 -> 0
A290: =ESTADISTICA!A288 -> SANTO TOMAS | B290: =ESTADISTICA!B288 -> SJU01 | C290: =ESTADISTICA!C288 -> Ruta 36 y Pte.Peron | D290: =ESTADISTICA!D288 -> Domo | E290: =ESTADISTICA!E288 -> Radio | F290: =ESTADISTICA!F288 -> 0 | G290: =ESTADISTICA!G288 -> 0 | H290: =ESTADISTICA!H288 -> APAGADO | ... AI290: =ESTADISTICA!AI288 -> 0
A291: =ESTADISTICA!A289 -> VILLA GENERAL SAN MARTIN | B291: =ESTADISTICA!B289 -> SMA01 | C291: =ESTADISTICA!C289 -> Hudson y Montevideo | D291: =ESTADISTICA!D289 -> DOMO | E291: =ESTADISTICA!E289 -> Radio | F291: =ESTADISTICA!F289 -> 0 | G291: =ESTADISTICA!G289 -> 0 | H291: =ESTADISTICA!H289 -> 0 | ... AI291: =ESTADISTICA!AI289 -> 0
... A454: =ESTADISTICA!A452 -> 0 | B454: =ESTADISTICA!B452 -> 0 | C454: =ESTADISTICA!C452 -> 0 | D454: =ESTADISTICA!D452 -> 0 | E454: =ESTADISTICA!E452 -> 0 | F454: =ESTADISTICA!F452 -> 0 | G454: =ESTADISTICA!G452 -> 0 | H454: =ESTADISTICA!H452 -> 0 | ... AI454: =ESTADISTICA!AI452 -> 0

Sheet APAGADOS RADIO
C1: TOTAL RADIO | D1: =COUNTIFS(E4:E400,"=radio") -> 89
E2: APAGADOS | F2: =COUNTIFS(F4:F500, "=APAGADO",E4:E500,"=radio") -> 5 | G2: =COUNTIFS(G4:G500, "=APAGADO",E4:E500,"=radio") -> 2 | H2: =COUNTIFS(H4:H500, "=APAGADO",E4:E500,"=radio") -> 20 | I2: =COUNTIFS(I4:I500, "=APAGADO",E4:E500,"=radio") -> 21 | J2: =COUNTIFS(J4:J500, "=APAGADO",E4:E500,"=radio") -> 3 | K2: =COUNTIFS(K4:K500, "=APAGADO",E4:E500,"=radio") -> 2 | L2: =COUNTIFS(L4:L500, "=APAGADO",E4:E500,"=radio") -> 3 | M2: =COUNTIFS(M4:M500, "=APAGADO",E4:E500,"=radio") -> 4 | N2: =COUNTIFS(N4:N500, "=APAGADO",E4:E500,"=radio") -> 5 | O2: =COUNTIFS(O4:O500, "=APAGADO",E4:E500,"=radio") -> 3 | P2: =COUNTIFS(P4:P500, "=APAGADO",E4:E500,"=radio") -> 6 | Q2: =COUNTIFS(Q4:Q367, "=APAGADO",E4:E367,"=radio") -> 3 | R2: =COUNTIFS(R4:R367, "=APAGADO",E4:E367,"=radio") -> 4 | S2: =COUNTIFS(S4:S367, "=APAGADO",E4:E367,"=radio") -> 5 | T2: =COUNTIFS(T4:T367, "=APAGADO",E4:E367,"=radio") -> 6 | U2: =COUNTIFS(U4:U367, "=APAGADO",E4:E367,"=radio") -> 3 | V2: =COUNTIFS(V4:V367, "=APAGADO",E4:E367,"=radio") -> 5 | W2: =COUNTIFS(W4:W367, "=APAGADO",E4:E367,"=radio") -> 4 | X2: =COUNTIFS(X4:X367, "=APAGADO",E4:E367,"=radio") -> 4 | Y2: =COUNTIFS(Y4:Y367, "=APAGADO",E4:E367,"=radio") -> 3 | Z2: =COUNTIFS(Z4:Z367, "=APAGADO",E4:E367,"=radio") -> 1 | AA2: =COUNTIFS(AA4:AA367, "=APAGADO",E4:E367,"=radio") -> 4 | AB2: =COUNTIFS(AB4:AB367, "=APAGADO",E4:E367,"=radio") -> 2 | AC2: =COUNTIFS(AC4:AC367, "=APAGADO",E4:E367,"=radio") -> 6 | AD2: =COUNTIFS(AD4:AD367, "=APAGADO",E4:E367,"=radio") -> 2 | AE2: =COUNTIFS(AE4:AE367, "=APAGADO",E4:E367,"=radio") -> 0 | AF2: =COUNTIFS(AF4:AF367, "=APAGADO",E4:E367,"=radio") -> 0 | AG2: =COUNTIFS(AG4:AG367, "=APAGADO",E4:E367,"=radio") -> 0 | AH2: =COUNTIFS(AH4:AH400, "=APAGADO",E4:E400,"=radio") -> 0 | AI2: =COUNTIFS(AI4:AI367, "=APAGADO",E4:E367,"=radio") -> 0
A3: =ESTADISTICA!A1 -> Barrio | B3: =ESTADISTICA!B1 -> [Denominacion] | C3: =ESTADISTICA!C1 -> [Ubicacion] | D3: =ESTADISTICA!D1 -> [Tipo de Camara] | E3: =ESTADISTICA!E1 -> [Tipo de Conexion] | F3: =ESTADISTICA!F1 -> 44805 | G3: =ESTADISTICA!G1 -> 44806 | H3: =ESTADISTICA!H1 -> 44807 | ... AI3: =ESTADISTICA!AI1 -> 44834
A4: =ESTADISTICA!A2 -> ALTAMIRA | B4: =ESTADISTICA!B2 -> ALT01 | C4: =ESTADISTICA!C2 -> Calchaqui y Sgto. Cabral | D4: =ESTADISTICA!D2 -> Domo | E4: =ESTADISTICA!E2 -> Fibra Optica | F4: =ESTADISTICA!F2 -> 0 | G4: =ESTADISTICA!G2 -> 0 | H4: =ESTADISTICA!H2 -> 0 | ... AI4: =ESTADISTICA!AI2 -> 0
A5: =ESTADISTICA!A3 -> ALTAMIRA | B5: =ESTADISTICA!B3 -> ALT02 | C5: =ESTADISTICA!C3 -> Calchaqui y Lope de Vega | D5: =ESTADISTICA!D3 -> Domo | E5: =ESTADISTICA!E3 -> PTO A FO | F5: =ESTADISTICA!F3 -> 0 | G5: =ESTADISTICA!G3 -> 0 | H5: =ESTADISTICA!H3 -> 0 | ... AI5: =ESTADISTICA!AI3 -> 0
A6: =ESTADISTICA!A4 -> ALTAMIRA | B6: =ESTADISTICA!B4 -> ALT 03 | C6: =ESTADISTICA!C4 -> Bombero Galarza y Necochea | D6: =ESTADISTICA!D4 -> Domo | E6: =ESTADISTICA!E4 -> FIBRA OPTICA | F6: =ESTADISTICA!F4 -> 0 | G6: =ESTADISTICA!G4 -> 0 | H6: =ESTADISTICA!H4 -> 0 | ... AI6: =ESTADISTICA!AI4 -> 0
A7: =ESTADISTICA!A5 -> ALTAMIRA | B7: =ESTADISTICA!B5 -> ALT 04 | C7: =ESTADISTICA!C5 -> Francia y Necochea | D7: =ESTADISTICA!D5 -> Domo | E7: =ESTADISTICA!E5 -> FIBRA OPTICA | F7: =ESTADISTICA!F5 -> 0 | G7: =ESTADISTICA!G5 -> 0 | H7: =ESTADISTICA!H5 -> 0 | ... AI7: =ESTADISTICA!AI5 -> 0
A8: =ESTADISTICA!A6 -> ALTAMIRA | B8: =ESTADISTICA!B6 -> ALT05 | C8: =ESTADISTICA!C6 -> Av. Calchaqui y Bombero Galarza | D8: =ESTADISTICA!D6 -> Domo | E8: =ESTADISTICA!E6 -> PTO A FO | F8: =ESTADISTICA!F6 -> APAGADO | G8: =ESTADISTICA!G6 -> APAGADO | H8: =ESTADISTICA!H6 -> APAGADO | ... AI8: =ESTADISTICA!AI6 -> 0
A9: =ESTADISTICA!A7 -> ALTAMIRA | B9: =ESTADISTICA!B7 -> ALT 06 | C9: =ESTADISTICA!C7 -> LOPE DE VEGA Y NECOCHEA | D9: =ESTADISTICA!D7 -> Domo | E9: =ESTADISTICA!E7 -> PTO A FO | F9: =ESTADISTICA!F7 -> 0 | G9: =ESTADISTICA!G7 -> 0 | H9: =ESTADISTICA!H7 -> 0 | ... AI9: =ESTADISTICA!AI7 -> 0
A10: =ESTADISTICA!A8 -> ALTAMIRA | B10: =ESTADISTICA!B8 -> ALT07 | C10: =ESTADISTICA!C8 -> AV. CALCHAQUI Y AV. DEL TRABAJO | D10: =ESTADISTICA!D8 -> DOMO | E10: =ESTADISTICA!E8 -> PTO A FO | F10: =ESTADISTICA!F8 -> 0 | G10: =ESTADISTICA!G8 -> 0 | H10: =ESTADISTICA!H8 -> 0 | ... AI10: =ESTADISTICA!AI8 -> 0
A11: =ESTADISTICA!A9 -> ALTAMIRA | B11: =ESTADISTICA!B9 -> ALT 08 | C11: =ESTADISTICA!C9 -> HUMAITA Y NECOCHEA | D11: =ESTADISTICA!D9 -> DOMO | E11: =ESTADISTICA!E9 -> Fibra Optica | F11: =ESTADISTICA!F9 -> 0 | G11: =ESTADISTICA!G9 -> 0 | H11: =ESTADISTICA!H9 -> 0 | ... AI11: =ESTADISTICA!AI9 -> 0
A12: =ESTADISTICA!A10 -> ALTAMIRA | B12: =ESTADISTICA!B10 -> ALT 09 | C12: =ESTADISTICA!C10 -> NECOCHEA Y CURUPAITY | D12: =ESTADISTICA!D10 -> DOMO | E12: =ESTADISTICA!E10 -> Fibra Optica | F12: =ESTADISTICA!F10 -> 0 | G12: =ESTADISTICA!G10 -> 0 | H12: =ESTADISTICA!H10 -> 0 | ... AI12: =ESTADISTICA!AI10 -> 0
A13: =ESTADISTICA!A11 -> ALTAMIRA | B13: =ESTADISTICA!B11 -> ALT 10 | C13: =ESTADISTICA!C11 -> Calchaqui y Francia | D13: =ESTADISTICA!D11 -> Domo | E13: =ESTADISTICA!E11 -> Radio | F13: =ESTADISTICA!F11 -> APAGADO | G13: =ESTADISTICA!G11 -> APAGADO | H13: =ESTADISTICA!H11 -> APAGADO | ... AI13: =ESTADISTICA!AI11 -> 0
A14: =ESTADISTICA!A12 -> AGUSTIN RAMIREZ | B14: =ESTADISTICA!B12 -> ARA 01 | C14: =ESTADISTICA!C12 -> Malambo y Tranquera | D14: =ESTADISTICA!D12 -> Domo | E14: =ESTADISTICA!E12 -> FIBRA OPTICA | F14: =ESTADISTICA!F12 -> 0 | G14: =ESTADISTICA!G12 -> 0 | H14: =ESTADISTICA!H12 -> 0 | ... AI14: =ESTADISTICA!AI12 -> 0
... A278: =ESTADISTICA!A276 -> LA SIRENA | B278: =ESTADISTICA!B276 -> SIR 14 | C278: =ESTADISTICA!C276 -> MANUEL IGLESIAS Y PEDRAZA | D278: =ESTADISTICA!D276 -> Domo | E278: =ESTADISTICA!E276 -> Fibra Optica | F278: =ESTADISTICA!F276 -> 0 | G278: =ESTADISTICA!G276 -> APAGADO | H278: =ESTADISTICA!H276 -> 0 | ... AI278: =ESTADISTICA!AI276 -> 0
B279: =ESTADISTICA!B277 -> SIR 15 | C279: =ESTADISTICA!C277 -> Monteverde y Azara | D279: =ESTADISTICA!D277 -> Domo | E279: =ESTADISTICA!E277 -> Fibra Optica | F279: =ESTADISTICA!F277 -> 0 | G279: =ESTADISTICA!G277 -> APAGADO | H279: =ESTADISTICA!H277 -> APAGADO | I279: =ESTADISTICA!I277 -> APAGADO | ... AI279: =ESTADISTICA!AI277 -> 0
