Workbook
Name _25_de_agosto: 'RESUMEN TOTAL'!$A$4:$D$349

Sheet RESUMEN TOTAL
A1: CANTIDAD DE CAMARAS | C1: =COUNTA(C5:C527) -> 368 | D1: PORCIENTO DE CAIDAS | O1: =(O3)/(O2+O3) -> 0.16847826 | P1: =(P3)/(P2+P3) -> 0.2173913 | Q1: =(Q3)/(Q2+Q3) -> 0.20923913 | R1: =(R3)/(R2+R3) -> 0.19021739 | S1: =(S3)/(S2+S3) -> 0.19021739 | T1: =(T3)/(T2+T3) -> 0.1875 | U1: =(U3)/(U2+U3) -> 0.19346049 | V1: =(V3)/(V2+V3) -> 0.18206522 | ... AS1: =(AS3)/(AS2+AS3) -> 0
D2: FUNCIONAN | O2: =COUNTIF(O5:O372, "") -> 306 | P2: =COUNTIF(P5:P372, "") -> 288 | Q2: =COUNTIF(Q5:Q372, "") -> 291 | R2: =COUNTIF(R5:R372, "") -> 298 | S2: =COUNTIF(S5:S372, "") -> 298 | T2: =COUNTIF(T5:T372, "") -> 299 | U2: =COUNTIF(U5:U372, "") -> 296 | V2: =COUNTIF(V5:V372, "") -> 301 | ... AS2: =COUNTIF(AS5:AS372, "") -> 368
D3: CAIDAS | O3: =COUNTIF(O4:O447, "apagado") -> 62 | P3: =COUNTIF(P4:P447, "apagado") -> 80 | Q3: =COUNTIF(Q4:Q447, "apagado") -> 77 | R3: =COUNTIF(R4:R447, "apagado") -> 70 | S3: =COUNTIF(S4:S447, "apagado") -> 70 | T3: =COUNTIF(T4:T447, "apagado") -> 69 | U3: =COUNTIF(U4:U447, "apagado") -> 71 | V3: =COUNTIF(V4:V447, "apagado") -> 67 | ... AS3: =COUNTIF(AS4:AS447, "apagado") -> 0
A4: Barrio | B4: a coseidi | C4: [Denominacion] | D4: [Ubicacion] | E4: [Tipo de Camara] | F4: [Tipo de Conexion] | G4: [Fundamento] | H4: [Detalle] | I4: Latitud | J4: Longitud | L4: DIAS FUNCIONANDO | M4: DIAS CAIDA | N4: EFECTIVIDAD | O4: 44621 | P4: 44622 | Q4: 44623 | R4: 44624 | S4: 44625 | T4: 44626 | U4: 44627 | V4: 44628 | W4: 44629 | X4: 44630 | Y4: 44631 | Z4: 44632 | AA4: 44633 | AB4: 44634 | AC4: 44635 | AD4: 44636 | AE4: 44637 | AF4: 44638 | AG4: 44639 | AH4: 44640 | AI4: 44641 | AJ4: 44642 | AK4: 44643 | AL4: 44644 | AM4: 44645 | AN4: 44646 | AO4: 44647 | AP4: 44648 | AQ4: 44649 | AR4: 44650 | AS4: 44651
A5: PRESIDENTE PERON (PEPSI) | B5: 44629 | C5: MAR 01 | D5: RP36 Y LA ESMERALDA | E5: DOMO | F5: Fibra Optica | G5: POSIBLE VIA DE ESCAPE. FLUJO VEHICULAR | I5: -348296270000 | J5: -582165860000 | K5: 172.20.11.101 | L5: =COUNTIF(O5:AP5,"") -> 14 | M5: =COUNTIF(O5:AP5,"APAGADO") -> 14 | N5: =(L5)/(M5+L5) -> 0.5 | O5: APAGADO | P5: APAGADO | Q5: APAGADO | R5: APAGADO | S5: APAGADO | T5: APAGADO | U5: APAGADO | V5: APAGADO | W5: APAGADO | X5: APAGADO | Y5: APAGADO | AK5: APAGADO | AL5: APAGADO | AM5: APAGADO
A6: MAYOL | C6: MAY 01 | D6: Eva Peron y Cabildo | E6: Domo | F6: Radio | G6: Flujo Vehicular, Futuro corredor escolar, Zona Comercial | I6: -348239900000 | J6: -582772350000 | K6: 172.20.200.194 | L6: =COUNTIF(O6:AP6,"") -> 28 | M6: =COUNTIF(O6:AP6,"APAGADO") -> 0 | N6: =(L6)/(M6+L6) -> 1
C7: MAY 02 | D7: EVA PERON Y MONTEVIDEO | E7: Domo | F7: Radio | I7: -348218190000 | J7: -582771380000 | K7: 172.20.200.168 | L7: =COUNTIF(O7:AP7,"") -> 28 | M7: =COUNTIF(O7:AP7,"APAGADO") -> 0 | N7: =(L7)/(M7+L7) -> 1
A8: MAYOL | C8: MAY 03 | D8: CHAÑAR Y SAN NICOLAS | E8: DOMO | F8: PTP A FO | H8: ALTA 29/10/2019 | I8: -348230700000 | J8: -582702540000 | K8: 172.20.10.18 | L8: =COUNTIF(O8:AP8,"") -> 28 | M8: =COUNTIF(O8:AP8,"APAGADO") -> 0 | N8: =(L8)/(M8+L8) -> 1
C9: MAY 04 | D9: MAR CHIQUITA Y RIO JACHAL | E9: DOMO | F9: Radio | H9: 08/07/2020 COMIENZA A REPORTAR IMAGEN | I9: -348252070000 | J9: -582711820000 | K9: 10.20.30.34 | L9: =COUNTIF(O9:AP9,"") -> 28 | M9: =COUNTIF(O9:AP9,"APAGADO") -> 0 | N9: =(L9)/(M9+L9) -> 1
A10: ALTAMIRA | C10: ALT06 | D10: LOPE DE VEGA Y NECOCHEA | E10: Domo | F10: PTP A FO | H10: Instalada sin alta en sistema. ALTA en sistema y en funcionamiento 04/05/2020 | I10: -347738090000 | J10: -582721410000 | K10: 172.20.12.12 | L10: =COUNTIF(O10:AP10,"") -> 26 | M10: =COUNTIF(O10:AP10,"APAGADO") -> 2 | N10: =(L10)/(M10+L10) -> 0.92857143 | AL10: APAGADO | AM10: APAGADO
A11: ALTAMIRA | C11: ALT01 | D11: Calchaqui y Sgto. Cabral | E11: Domo | F11: Fibra Optica | G11: Universidad, Zona Bancaria, Flujo Vehicular, Posible Via de Escape | I11: -347769580000 | J11: -582650900000 | K11: 172.20.10.6 | L11: =COUNTIF(O11:AP11,"") -> 28 | M11: =COUNTIF(O11:AP11,"APAGADO") -> 0 | N11: =(L11)/(M11+L11) -> 1
A12: ALTAMIRA | C12: ALT02 | D12: Calchaqui y Lope de Vega | E12: Domo | F12: PTP A FO | G12: Hospital, Flujo Vehicular, Peatonal | I12: -347718470000 | J12: -582688560000 | K12: 172.20.12.218 | L12: =COUNTIF(O12:AP12,"") -> 28 | M12: =COUNTIF(O12:AP12,"APAGADO") -> 0 | N12: =(L12)/(M12+L12) -> 1
A13: ALTAMIRA | B13: 44642 | C13: ALT03 | D13: Bombero Galarza y Necochea | E13: Domo | F13: Fibra Optica | G13: Hospital, Limite del Partido | I13: -347726570000 | J13: -582730620000 | K13: 172.20.12.54 | L13: =COUNTIF(O13:AP13,"") -> 25 | M13: =COUNTIF(O13:AP13,"APAGADO") -> 3 | N13: =(L13)/(M13+L13) -> 0.89285714 | AJ13: APAGADO | AL13: APAGADO | AM13: APAGADO
B14: 44642 | C14: ALT04 | D14: Francia y Necochea | E14: Domo | F14: Fibra Optica | G14: Zona RecreaciÃ³n | I14: -347705420000 | J14: -582748000000 | K14: 172.20.12.55 | L14: =COUNTIF(O14:AP14,"") -> 23 | M14: =COUNTIF(O14:AP14,"APAGADO") -> 5 | N14: =(L14)/(M14+L14) -> 0.82142857 | O14: APAGADO | AG14: APAGADO | AJ14: APAGADO | AL14: APAGADO | AM14: APAGADO
A15: ALTAMIRA | C15: ALT05 | D15: Av. Calchaqui y Bombero Galarza | E15: Domo | F15: PTP A FO | G15: Zona Bancaria, Flujo Vehicular, Posible via de escape, Limite del partido | I15: -347708370000 | J15: -582698000000 | K15: 172.20.12.216 | L15: =COUNTIF(O15:AP15,"") -> 27 | M15: =COUNTIF(O15:AP15,"APAGADO") -> 1 | N15: =(L15)/(M15+L15) -> 0.96428571 | AG15: APAGADO
A16: ALTAMIRA | C16: ALT07 | D16: AV. CALCHAQUI Y AV. DEL TRABAJO | E16: DOMO | F16: PTP A FO | H16: SE DA DE ALTA EL 17/09/2020 18:51HS | I16: -347737570000 | J16: -582676650000 | K16: 172.20.10.57 | L16: =COUNTIF(O16:AP16,"") -> 28 | M16: =COUNTIF(O16:AP16,"APAGADO") -> 0 | N16: =(L16)/(M16+L16) -> 1
A17: ALTAMIRA | B17: 44642 | C17: ALT08 | D17: HUMAITA Y NECOCHEA | E17: DOMO | F17: Fibra Optica | H17: REPORTA IMAGENES 20/08/2021 | I17: -347749440000 | J17: -582711610000 | K17: 172.20.11.215 | L17: =COUNTIF(O17:AP17,"") -> 25 | M17: =COUNTIF(O17:AP17,"APAGADO") -> 3 | N17: =(L17)/(M17+L17) -> 0.89285714 | AJ17: APAGADO | AL17: APAGADO | AM17: APAGADO
A18: ALTAMIRA | B18: 44642 | C18: ALT09 | D18: NECOCHEA Y CURUPAITY | E18: DOMO | F18: Fibra Optica | H18: SE DA DE ALTA 25/08/2021 | I18: -347743740000 | J18: -582715650000 | K18: 172.20.11.216 | L18: =COUNTIF(O18:AP18,"") -> 25 | M18: =COUNTIF(O18:AP18,"APAGADO") -> 3 | N18: =(L18)/(M18+L18) -> 0.89285714 | AJ18: APAGADO | AL18: APAGADO | AM18: APAGADO
A19: AGUSTIN RAMIREZ | C19: ARA01 | D19: Malambo y Tranquera | E19: Domo | F19: Fibra Optica | G19: Zona Escolar, Flujo Vehicular | I19: -347979380000 | J19: -583160950000 | K19: 172.20.12.110 | L19: =COUNTIF(O19:AP19,"") -> 19 | M19: =COUNTIF(O19:AP19,"APAGADO") -> 9 | N19: =(L19)/(M19+L19) -> 0.67857143 | P19: APAGADO | Q19: APAGADO | R19: APAGADO | S19: APAGADO | T19: APAGADO | U19: APAGADO | V19: APAGADO | W19: APAGADO | X19: APAGADO
A20: ALTAMIRA | C20: ALT10 | D20: REP. FRANCIA Y CALCHAQUI (RP 36) | E20: DOMO | F20: PTP A FO | H20: SE DA DE ALTA 10/11/2021 | I20: -347689160000 | J20: -582717100000 | K20: 172.20.12.156 | L20: =COUNTIF(O20:AP20,"") -> 27 | M20: =COUNTIF(O20:AP20,"APAGADO") -> 1 | N20: =(L20)/(M20+L20) -> 0.96428571 | AL20: APAGADO
A21: BELGRANO | C21: BEL01 | D21: San Martin y Dardo Rocha | E21: DOMO | F21: Fibra Optica | G21: Zona Escolar, Flujo Vehicular | H21: 19/03/2020 SE RETIRO DISPOSITIVO POR RIESGO DE CAIDA. 19/08/2020 comenzo a funcionar. | I21: -347918370000 | J21: -582786080000 | K21: 172.20.12.64 | L21: =COUNTIF(O21:AP21,"") -> 28 | M21: =COUNTIF(O21:AP21,"APAGADO") -> 0 | N21: =(L21)/(M21+L21) -> 1
C22: CEN51 | D22: ILLIA Y LAS HERAS | E22: FIJA | F22: Fibra Optica | G22: POSIBLE VIA DE ESCAPE, Y FLUJO VEHICULAR | I22: -347987830000 | J22: -582840920000 | K22: 172.20.11.29 | L22: =COUNTIF(O22:AP22,"") -> 26 | M22: =COUNTIF(O22:AP22,"APAGADO") -> 2 | N22: =(L22)/(M22+L22) -> 0.92857143 | W22: APAGADO | AG22: APAGADO
C23: CEN53 | D23: GUTIERREZ Y BROWN | E23: Domo | F23: Radio | I23: -348013650000 | J23: -582715700000 | K23: 172.20.200.166 | L23: =COUNTIF(O23:AP23,"") -> 28 | M23: =COUNTIF(O23:AP23,"APAGADO") -> 0 | N23: =(L23)/(M23+L23) -> 1
C24: CEN 54 | D24: GUTIERREZ Y PRINGLES | E24: Domo | F24: Radio | I24: -348013470000 | J24: -582698540000 | K24: 172.20.200.165 | L24: =COUNTIF(O24:AP24,"") -> 23 | M24: =COUNTIF(O24:AP24,"APAGADO") -> 5 | N24: =(L24)/(M24+L24) -> 0.82142857 | R24: APAGADO | S24: APAGADO | T24: APAGADO | U24: APAGADO | W24: APAGADO
C25: CEN 55 | D25: BOUREL Y URQUIZA | E25: Domo | F25: Radio | I25: -348019110000 | J25: -582819990000 | K25: 172.20.200.163 | L25: =COUNTIF(O25:AP25,"") -> 28 | M25: =COUNTIF(O25:AP25,"APAGADO") -> 0 | N25: =(L25)/(M25+L25) -> 1
A26: CENTRO | C26: CEN 56 | D26: Newbery y Falucho | E26: DOMO | F26: Radio | G26: Posible via de escape, Cruce Peligroso | I26: -348073990000 | J26: -582850080000 | K26: 172.20.200.161 | L26: =COUNTIF(O26:AP26,"") -> 28 | M26: =COUNTIF(O26:AP26,"APAGADO") -> 0 | N26: =(L26)/(M26+L26) -> 1
C27: CEN 57 | D27: 25 DE MAYO Y DORREGO | E27: DOMO | F27: Radio | I27: -348007360000 | J27: -582804240000 | K27: 172.20.200.199 | L27: =COUNTIF(O27:AP27,"") -> 28 | M27: =COUNTIF(O27:AP27,"APAGADO") -> 0 | N27: =(L27)/(M27+L27) -> 1
C28: CEN 58 | D28: EEUU Y MORENO | E28: DOMO | F28: Fibra Optica | H28: INSTALADA: 11/06/18. EN FUNCIONAMIENTO: 27/06/18. | I28: -348103030000 | J28: -582835720000 | K28: 172.20.11.84 | L28: =COUNTIF(O28:AP28,"") -> 28 | M28: =COUNTIF(O28:AP28,"APAGADO") -> 0 | N28: =(L28)/(M28+L28) -> 1
C29: CEN 59 | D29: CHACABUCO Y BOUREL | E29: DOMO | F29: Radio | H29: INSTALADA:11/06/18EN FUNCIONAMIENTO: 27/06/18 | I29: -348039300000 | J29: -582819780000 | K29: 172.20.200.188 | L29: =COUNTIF(O29:AP29,"") -> 28 | M29: =COUNTIF(O29:AP29,"APAGADO") -> 0 | N29: =(L29)/(M29+L29) -> 1
A30: CENTRO | C30: CEN 60 | D30: RECONQUISTA Y ILLIA | E30: DOMO | F30: PTP A FO | H30: ALTA 26/10/2019 | I30: -347999170000 | J30: -582863530000 | K30: 172.20.12.67 | L30: =COUNTIF(O30:AP30,"") -> 20 | M30: =COUNTIF(O30:AP30,"APAGADO") -> 8 | N30: =(L30)/(M30+L30) -> 0.71428571 | W30: APAGADO | AG30: APAGADO | AH30: APAGADO | AI30: APAGADO | AJ30: APAGADO | AK30: APAGADO | AL30: APAGADO | AM30: APAGADO
A31: CENTRO | C31: CEN 61 | D31: BOUREL Y MAIPU | E31: DOMO | F31: Radio | H31: ALTA EN FUNCIONAMIENTO 12/04/2019 | I31: -348040550000 | J31: -582819380000 | K31: 172.20.200.159 | L31: =COUNTIF(O31:AP31,"") -> 28 | M31: =COUNTIF(O31:AP31,"APAGADO") -> 0 | N31: =(L31)/(M31+L31) -> 1
A32: CENTRO | C32: CEN 62 | D32: ESPAÑA Y ALEM | E32: DOMO | F32: PTP A FO | H32: ALTA: 16/06/2020 | I32: -348038200000 | J32: -582766160000 | K32: 172.20.12.82 | L32: =COUNTIF(O32:AP32,"") -> 28 | M32: =COUNTIF(O32:AP32,"APAGADO") -> 0 | N32: =(L32)/(M32+L32) -> 1
A33: CENTRO | C33: CEN 63 | D33: SAN MARTIN Y URQUIZA | E33: DOMO | F33: Fibra Optica | H33: DADA DE ALTA ABRIL 2021 | I33: -348017700000 | J33: -582785020000 | K33: 172.20.11.112 | L33: =COUNTIF(O33:AP33,"") -> 28 | M33: =COUNTIF(O33:AP33,"APAGADO") -> 0 | N33: =(L33)/(M33+L33) -> 1
A34: CENTRO | C34: CEN 70 | D34: RIVADAVIA Y 25 MAYO | E34: Domo | F34: Fibra Optica | H34: alta en sistema 25/11/2021 | I34: -348091950000 | J34: -582800930000 | K34: 172.20.11.221 | L34: =COUNTIF(O34:AP34,"") -> 27 | M34: =COUNTIF(O34:AP34,"APAGADO") -> 1 | N34: =(L34)/(M34+L34) -> 0.96428571 | AL34: APAGADO
A35: CENTRO | C35: CEN 71 | D35: MORENO Y BOUREL | E35: Domo | F35: Fibra Optica | H35: alta en sistema 25/11/2021 | I35: -348103130000 | J35: -582818230000 | K35: 172.20.11.220 | L35: =COUNTIF(O35:AP35,"") -> 27 | M35: =COUNTIF(O35:AP35,"APAGADO") -> 1 | N35: =(L35)/(M35+L35) -> 0.96428571 | AL35: APAGADO
A36: CENTRO | C36: CEN 72 | D36: MORENO Y 25 DE MAYO | E36: Domo | F36: Fibra Optica | H36: ALTA EN SISTEMA 25/11/2021 | I36: -348102250000 | J36: -582800780000 | K36: 172.20.11.219 | L36: =COUNTIF(O36:AP36,"") -> 27 | M36: =COUNTIF(O36:AP36,"APAGADO") -> 1 | N36: =(L36)/(M36+L36) -> 0.96428571 | AL36: APAGADO
A37: CENTRO | C37: CEN01 | D37: San Martin y 9 de Julio | E37: Fija | F37: Fibra Optica | G37: Zona Comercial, Flujo Vehicular | I37: -348028100000 | J37: -582782860000 | K37: 172.20.11.10 | L37: =COUNTIF(O37:AP37,"") -> 21 | M37: =COUNTIF(O37:AP37,"APAGADO") -> 7 | N37: =(L37)/(M37+L37) -> 0.75 | O37: APAGADO | P37: APAGADO | Q37: APAGADO | R37: APAGADO | S37: APAGADO | T37: APAGADO | U37: APAGADO
A38: CENTRO | C38: CEN02 | D38: San Martin y Almafuerte | E38: Fija | F38: Fibra Optica | G38: Bomberos, Flujo Vehicular, Zona Comercial | I38: -348006070000 | J38: -582784580000 | K38: 172.20.11.11 | L38: =COUNTIF(O38:AP38,"") -> 27 | M38: =COUNTIF(O38:AP38,"APAGADO") -> 0 | N38: =(L38)/(M38+L38) -> 1
A39: CENTRO | C39: CEN03 | D39: San Martin y Sallares | E39: Domo | F39: Fibra Optica | G39: Zona Comercial, Flujo Vehicular | H39: 29/03/19 FUNCIONA EN COD 1 | I39: -348080340000 | J39: -582780930000 | K39: 172.20.12.30 | L39: =COUNTIF(O39:AP39,"") -> 28 | M39: =COUNTIF(O39:AP39,"APAGADO") -> 0 | N39: =(L39)/(M39+L39) -> 1
A40: CENTRO | C40: CEN04 | D40: San Martin y Contreras | E40: Domo | F40: Fibra Optica | G40: Zona de recreaciÃ³n, Flujo vehicular | I40: -348049240000 | J40: -582781680000 | K40: 172.20.12.29 | L40: =COUNTIF(O40:AP40,"") -> 28 | M40: =COUNTIF(O40:AP40,"APAGADO") -> 0 | N40: =(L40)/(M40+L40) -> 1
...

Sheet REPARACIONES DIARIAS
A1: REPARADOS POR DIA
A3: 44621
A4: 44622
A5: 44623
A6: 44624
A7: 44625
A8: 44626
A9: 44627
A10: 44628
A11: 44629
A12: 44630
A13: 44631
A14: 44632
... A33: 44651

Sheet ESTADISTICA
A1: ='RESUMEN TOTAL'!A4 -> Barrio | B1: ='RESUMEN TOTAL'!C4 -> [Denominacion] | C1: ='RESUMEN TOTAL'!D4 -> [Ubicacion] | D1: ='RESUMEN TOTAL'!E4 -> [Tipo de Camara] | E1: ='RESUMEN TOTAL'!F4 -> [Tipo de Conexion] | F1: ='RESUMEN TOTAL'!O4 -> 44621 | G1: ='RESUMEN TOTAL'!P4 -> 44622 | H1: ='RESUMEN TOTAL'!Q4 -> 44623 | I1: ='RESUMEN TOTAL'!R4 -> 44624 | J1: ='RESUMEN TOTAL'!S4 -> 44625 | K1: ='RESUMEN TOTAL'!T4 -> 44626 | L1: ='RESUMEN TOTAL'!U4 -> 44627 | M1: ='RESUMEN TOTAL'!V4 -> 44628 | ... AJ1: ='RESUMEN TOTAL'!AS4 -> 44651
A2: ='RESUMEN TOTAL'!A5 -> PRESIDENTE PERON (PEPSI) | B2: ='RESUMEN TOTAL'!C5 -> MAR 01 | C2: ='RESUMEN TOTAL'!D5 -> RP36 Y LA ESMERALDA | D2: ='RESUMEN TOTAL'!E5 -> DOMO | E2: ='RESUMEN TOTAL'!F5 -> Fibra Optica | F2: ='RESUMEN TOTAL'!O5 -> APAGADO | G2: ='RESUMEN TOTAL'!P5 -> APAGADO | H2: ='RESUMEN TOTAL'!Q5 -> APAGADO | I2: ='RESUMEN TOTAL'!R5 -> APAGADO | J2: ='RESUMEN TOTAL'!S5 -> APAGADO | K2: ='RESUMEN TOTAL'!T5 -> APAGADO | L2: ='RESUMEN TOTAL'!U5 -> APAGADO | M2: ='RESUMEN TOTAL'!V5 -> APAGADO | ... AG2: ='RESUMEN TOTAL'!AP5 -> 0
A3: ='RESUMEN TOTAL'!A6 -> MAYOL | B3: ='RESUMEN TOTAL'!C6 -> MAY 01 | C3: ='RESUMEN TOTAL'!D6 -> Eva Peron y Cabildo | D3: ='RESUMEN TOTAL'!E6 -> Domo | E3: ='RESUMEN TOTAL'!F6 -> Radio | F3: ='RESUMEN TOTAL'!O6 -> 0 | G3: ='RESUMEN TOTAL'!P6 -> 0 | H3: ='RESUMEN TOTAL'!Q6 -> 0 | I3: ='RESUMEN TOTAL'!R6 -> 0 | J3: ='RESUMEN TOTAL'!S6 -> 0 | K3: ='RESUMEN TOTAL'!T6 -> 0 | L3: ='RESUMEN TOTAL'!U6 -> 0 | M3: ='RESUMEN TOTAL'!V6 -> 0 | ... AG3: ='RESUMEN TOTAL'!AP6 -> 0
A4: ='RESUMEN TOTAL'!A7 -> 0 | B4: ='RESUMEN TOTAL'!C7 -> MAY 02 | C4: ='RESUMEN TOTAL'!D7 -> EVA PERON Y MONTEVIDEO | D4: ='RESUMEN TOTAL'!E7 -> Domo | E4: ='RESUMEN TOTAL'!F7 -> Radio | F4: ='RESUMEN TOTAL'!O7 -> 0 | G4: ='RESUMEN TOTAL'!P7 -> 0 | H4: ='RESUMEN TOTAL'!Q7 -> 0 | I4: ='RESUMEN TOTAL'!R7 -> 0 | J4: ='RESUMEN TOTAL'!S7 -> 0 | K4: ='RESUMEN TOTAL'!T7 -> 0 | L4: ='RESUMEN TOTAL'!U7 -> 0 | M4: ='RESUMEN TOTAL'!V7 -> 0 | ... AG4: ='RESUMEN TOTAL'!AP7 -> 0
A5: ='RESUMEN TOTAL'!A8 -> MAYOL | B5: ='RESUMEN TOTAL'!C8 -> MAY 03 | C5: ='RESUMEN TOTAL'!D8 -> CHAÑAR Y SAN NICOLAS | D5: ='RESUMEN TOTAL'!E8 -> DOMO | E5: ='RESUMEN TOTAL'!F8 -> PTP A FO | F5: ='RESUMEN TOTAL'!O8 -> 0 | G5: ='RESUMEN TOTAL'!P8 -> 0 | H5: ='RESUMEN TOTAL'!Q8 -> 0 | I5: ='RESUMEN TOTAL'!R8 -> 0 | J5: ='RESUMEN TOTAL'!S8 -> 0 | K5: ='RESUMEN TOTAL'!T8 -> 0 | L5: ='RESUMEN TOTAL'!U8 -> 0 | M5: ='RESUMEN TOTAL'!V8 -> 0 | ... AG5: ='RESUMEN TOTAL'!AP8 -> 0
A6: ='RESUMEN TOTAL'!A9 -> 0 | B6: ='RESUMEN TOTAL'!C9 -> MAY 04 | C6: ='RESUMEN TOTAL'!D9 -> MAR CHIQUITA Y RIO JACHAL | D6: ='RESUMEN TOTAL'!E9 -> DOMO | E6: ='RESUMEN TOTAL'!F9 -> Radio | F6: ='RESUMEN TOTAL'!O9 -> 0 | G6: ='RESUMEN TOTAL'!P9 -> 0 | H6: ='RESUMEN TOTAL'!Q9 -> 0 | I6: ='RESUMEN TOTAL'!R9 -> 0 | J6: ='RESUMEN TOTAL'!S9 -> 0 | K6: ='RESUMEN TOTAL'!T9 -> 0 | L6: ='RESUMEN TOTAL'!U9 -> 0 | M6: ='RESUMEN TOTAL'!V9 -> 0 | ... AG6: ='RESUMEN TOTAL'!AP9 -> 0
A7: ='RESUMEN TOTAL'!A10 -> ALTAMIRA | B7: ='RESUMEN TOTAL'!C10 -> ALT06 | C7: ='RESUMEN TOTAL'!D10 -> LOPE DE VEGA Y NECOCHEA | D7: ='RESUMEN TOTAL'!E10 -> Domo | E7: ='RESUMEN TOTAL'!F10 -> PTP A FO | F7: ='RESUMEN TOTAL'!O10 -> 0 | G7: ='RESUMEN TOTAL'!P10 -> 0 | H7: ='RESUMEN TOTAL'!Q10 -> 0 | I7: ='RESUMEN TOTAL'!R10 -> 0 | J7: ='RESUMEN TOTAL'!S10 -> 0 | K7: ='RESUMEN TOTAL'!T10 -> 0 | L7: ='RESUMEN TOTAL'!U10 -> 0 | M7: ='RESUMEN TOTAL'!V10 -> 0 | ... AG7: ='RESUMEN TOTAL'!AP10 -> 0
A8: ='RESUMEN TOTAL'!A11 -> ALTAMIRA | B8: ='RESUMEN TOTAL'!C11 -> ALT01 | C8: ='RESUMEN TOTAL'!D11 -> Calchaqui y Sgto. Cabral | D8: ='RESUMEN TOTAL'!E11 -> Domo | E8: ='RESUMEN TOTAL'!F11 -> Fibra Optica | F8: ='RESUMEN TOTAL'!O11 -> 0 | G8: ='RESUMEN TOTAL'!P11 -> 0 | H8: ='RESUMEN TOTAL'!Q11 -> 0 | I8: ='RESUMEN TOTAL'!R11 -> 0 | J8: ='RESUMEN TOTAL'!S11 -> 0 | K8: ='RESUMEN TOTAL'!T11 -> 0 | L8: ='RESUMEN TOTAL'!U11 -> 0 | M8: ='RESUMEN TOTAL'!V11 -> 0 | ... AG8: ='RESUMEN TOTAL'!AP11 -> 0
A9: ='RESUMEN TOTAL'!A12 -> ALTAMIRA | B9: ='RESUMEN TOTAL'!C12 -> ALT02 | C9: ='RESUMEN TOTAL'!D12 -> Calchaqui y Lope de Vega | D9: ='RESUMEN TOTAL'!E12 -> Domo | E9: ='RESUMEN TOTAL'!F12 -> PTP A FO | F9: ='RESUMEN TOTAL'!O12 -> 0 | G9: ='RESUMEN TOTAL'!P12 -> 0 | H9: ='RESUMEN TOTAL'!Q12 -> 0 | I9: ='RESUMEN TOTAL'!R12 -> 0 | J9: ='RESUMEN TOTAL'!S12 -> 0 | K9: ='RESUMEN TOTAL'!T12 -> 0 | L9: ='RESUMEN TOTAL'!U12 -> 0 | M9: ='RESUMEN TOTAL'!V12 -> 0 | ... AG9: ='RESUMEN TOTAL'!AP12 -> 0
A10: ='RESUMEN TOTAL'!A13 -> ALTAMIRA | B10: ='RESUMEN TOTAL'!C13 -> ALT03 | C10: ='RESUMEN TOTAL'!D13 -> Bombero Galarza y Necochea | D10: ='RESUMEN TOTAL'!E13 -> Domo | E10: ='RESUMEN TOTAL'!F13 -> Fibra Optica | F10: ='RESUMEN TOTAL'!O13 -> 0 | G10: ='RESUMEN TOTAL'!P13 -> 0 | H10: ='RESUMEN TOTAL'!Q13 -> 0 | I10: ='RESUMEN TOTAL'!R13 -> 0 | J10: ='RESUMEN TOTAL'!S13 -> 0 | K10: ='RESUMEN TOTAL'!T13 -> 0 | L10: ='RESUMEN TOTAL'!U13 -> 0 | M10: ='RESUMEN TOTAL'!V13 -> 0 | ... AG10: ='RESUMEN TOTAL'!AP13 -> 0
A11: ='RESUMEN TOTAL'!A14 -> 0 | B11: ='RESUMEN TOTAL'!C14 -> ALT04 | C11: ='RESUMEN TOTAL'!D14 -> Francia y Necochea | D11: ='RESUMEN TOTAL'!E14 -> Domo | E11: ='RESUMEN TOTAL'!F14 -> Fibra Optica | F11: ='RESUMEN TOTAL'!O14 -> APAGADO | G11: ='RESUMEN TOTAL'!P14 -> 0 | H11: ='RESUMEN TOTAL'!Q14 -> 0 | I11: ='RESUMEN TOTAL'!R14 -> 0 | J11: ='RESUMEN TOTAL'!S14 -> 0 | K11: ='RESUMEN TOTAL'!T14 -> 0 | L11: ='RESUMEN TOTAL'!U14 -> 0 | M11: ='RESUMEN TOTAL'!V14 -> 0 | ... AG11: ='RESUMEN TOTAL'!AP14 -> 0
A12: ='RESUMEN TOTAL'!A15 -> ALTAMIRA | B12: ='RESUMEN TOTAL'!C15 -> ALT05 | C12: ='RESUMEN TOTAL'!D15 -> Av. Calchaqui y Bombero Galarza | D12: ='RESUMEN TOTAL'!E15 -> Domo | E12: ='RESUMEN TOTAL'!F15 -> PTP A FO | F12: ='RESUMEN TOTAL'!O15 -> 0 | G12: ='RESUMEN TOTAL'!P15 -> 0 | H12: ='RESUMEN TOTAL'!Q15 -> 0 | I12: ='RESUMEN TOTAL'!R15 -> 0 | J12: ='RESUMEN TOTAL'!S15 -> 0 | K12: ='RESUMEN TOTAL'!T15 -> 0 | L12: ='RESUMEN TOTAL'!U15 -> 0 | M12: ='RESUMEN TOTAL'!V15 -> 0 | ... AG12: ='RESUMEN TOTAL'!AP15 -> 0
A13: ='RESUMEN TOTAL'!A16 -> ALTAMIRA | B13: ='RESUMEN TOTAL'!C16 -> ALT07 | C13: ='RESUMEN TOTAL'!D16 -> AV. CALCHAQUI Y AV. DEL TRABAJO | D13: ='RESUMEN TOTAL'!E16 -> DOMO | E13: ='RESUMEN TOTAL'!F16 -> PTP A FO | F13: ='RESUMEN TOTAL'!O16 -> 0 | G13: ='RESUMEN TOTAL'!P16 -> 0 | H13: ='RESUMEN TOTAL'!Q16 -> 0 | I13: ='RESUMEN TOTAL'!R16 -> 0 | J13: ='RESUMEN TOTAL'!S16 -> 0 | K13: ='RESUMEN TOTAL'!T16 -> 0 | L13: ='RESUMEN TOTAL'!U16 -> 0 | M13: ='RESUMEN TOTAL'!V16 -> 0 | ... AG13: ='RESUMEN TOTAL'!AP16 -> 0
... A374: ='RESUMEN TOTAL'!A377 -> 0 | B374: ='RESUMEN TOTAL'!C377 -> 0 | C374: ='RESUMEN TOTAL'!D377 -> 0 | D374: ='RESUMEN TOTAL'!E377 -> 0 | E374: ='RESUMEN TOTAL'!F377 -> 0 | F374: ='RESUMEN TOTAL'!O377 -> 0 | G374: ='RESUMEN TOTAL'!P377 -> 0 | H374: ='RESUMEN TOTAL'!Q377 -> 0 | I374: ='RESUMEN TOTAL'!R377 -> 0 | J374: ='RESUMEN TOTAL'!S377 -> 0 | K374: ='RESUMEN TOTAL'!T377 -> 0 | L374: ='RESUMEN TOTAL'!U377 -> 0 | M374: ='RESUMEN TOTAL'!V377 -> 0 | ... AG374: ='RESUMEN TOTAL'!AP377 -> 0

Sheet APAGADOS
E1: APAGADOS | F1: =COUNTIF(F3:F366, "APAGADO") -> 61 | G1: =COUNTIF(G3:G366, "APAGADO") -> 79 | H1: =COUNTIF(H3:H366, "APAGADO") -> 76 | I1: =COUNTIF(I3:I366, "APAGADO") -> 69 | J1: =COUNTIF(J3:J366, "APAGADO") -> 69 | K1: =COUNTIF(K3:K366, "APAGADO") -> 68 | L1: =COUNTIF(L3:L366, "APAGADO") -> 70 | M1: =COUNTIF(M3:M366, "APAGADO") -> 66 | ... V1: =COUNTIF(V3:V366, "APAGADO") -> 43 | W1: =COUNTIF(W3:W447, "APAGADO") -> 52 | X1: =COUNTIF(X3:X366, "APAGADO") -> 73 | Y1: =COUNTIF(Y3:Y366, "APAGADO") -> 52 | Z1: =COUNTIF(Z3:Z366, "APAGADO") -> 55 | AA1: =COUNTIF(AA3:AA366, "APAGADO") -> 68 | AB1: =COUNTIF(AB3:AB366, "APAGADO") -> 32 | AC1: =COUNTIF(AC3:AC366, "APAGADO") -> 85 | AD1: =COUNTIF(AD3:AD366, "APAGADO") -> 52 | AE1: =COUNTIF(AE3:AE366, "APAGADO") -> 0 | ... AG1: =COUNTIF(AG3:AG366, "APAGADO") -> 0
A2: =ESTADISTICA!A1 -> Barrio | B2: =ESTADISTICA!B1 -> [Denominacion] | C2: =ESTADISTICA!C1 -> [Ubicacion] | D2: =ESTADISTICA!D1 -> [Tipo de Camara] | E2: =ESTADISTICA!E1 -> [Tipo de Conexion] | F2: =ESTADISTICA!F1 -> 44621 | G2: =ESTADISTICA!G1 -> 44622 | H2: =ESTADISTICA!H1 -> 44623 | ... AG2: =ESTADISTICA!AG1 -> 44648
A3: =ESTADISTICA!A2 -> PRESIDENTE PERON (PEPSI) | B3: =ESTADISTICA!B2 -> MAR 01 | C3: =ESTADISTICA!C2 -> RP36 Y LA ESMERALDA | D3: =ESTADISTICA!D2 -> DOMO | E3: =ESTADISTICA!E2 -> Fibra Optica | F3: =ESTADISTICA!F2 -> APAGADO | G3: =ESTADISTICA!G2 -> APAGADO | H3: =ESTADISTICA!H2 -> APAGADO | ... AG3: =ESTADISTICA!AG2 -> 0
A4: =ESTADISTICA!A3 -> MAYOL | B4: =ESTADISTICA!B3 -> MAY 01 | C4: =ESTADISTICA!C3 -> Eva Peron y Cabildo | D4: =ESTADISTICA!D3 -> Domo | E4: =ESTADISTICA!E3 -> Radio | F4: =ESTADISTICA!F3 -> 0 | G4: =ESTADISTICA!G3 -> 0 | H4: =ESTADISTICA!H3 -> 0 | ... AG4: =ESTADISTICA!AG3 -> 0
A5: =ESTADISTICA!A4 -> 0 | B5: =ESTADISTICA!B4 -> MAY 02 | C5: =ESTADISTICA!C4 -> EVA PERON Y MONTEVIDEO | D5: =ESTADISTICA!D4 -> Domo | E5: =ESTADISTICA!E4 -> Radio | F5: =ESTADISTICA!F4 -> 0 | G5: =ESTADISTICA!G4 -> 0 | H5: =ESTADISTICA!H4 -> 0 | ... AG5: =ESTADISTICA!AG4 -> 0
A6: =ESTADISTICA!A5 -> MAYOL | B6: =ESTADISTICA!B5 -> MAY 03 | C6: =ESTADISTICA!C5 -> CHAÑAR Y SAN NICOLAS | D6: =ESTADISTICA!D5 -> DOMO | E6: =ESTADISTICA!E5 -> PTP A FO | F6: =ESTADISTICA!F5 -> 0 | G6: =ESTADISTICA!G5 -> 0 | H6: =ESTADISTICA!H5 -> 0 | ... AG6: =ESTADISTICA!AG5 -> 0
A7: =ESTADISTICA!A6 -> 0 | B7: =ESTADISTICA!B6 -> MAY 04 | C7: =ESTADISTICA!C6 -> MAR CHIQUITA Y RIO JACHAL | D7: =ESTADISTICA!D6 -> DOMO | E7: =ESTADISTICA!E6 -> Radio | F7: =ESTADISTICA!F6 -> 0 | G7: =ESTADISTICA!G6 -> 0 | H7: =ESTADISTICA!H6 -> 0 | ... AG7: =ESTADISTICA!AG6 -> 0
A8: =ESTADISTICA!A7 -> ALTAMIRA | B8: =ESTADISTICA!B7 -> ALT06 | C8: =ESTADISTICA!C7 -> LOPE DE VEGA Y NECOCHEA | D8: =ESTADISTICA!D7 -> Domo | E8: =ESTADISTICA!E7 -> PTP A FO | F8: =ESTADISTICA!F7 -> 0 | G8: =ESTADISTICA!G7 -> 0 | H8: =ESTADISTICA!H7 -> 0 | ... AG8: =ESTADISTICA!AG7 -> 0
A9: =ESTADISTICA!A8 -> ALTAMIRA | B9: =ESTADISTICA!B8 -> ALT01 | C9: =ESTADISTICA!C8 -> Calchaqui y Sgto. Cabral | D9: =ESTADISTICA!D8 -> Domo | E9: =ESTADISTICA!E8 -> Fibra Optica | F9: =ESTADISTICA!F8 -> 0 | G9: =ESTADISTICA!G8 -> 0 | H9: =ESTADISTICA!H8 -> 0 | ... AG9: =ESTADISTICA!AG8 -> 0
A10: =ESTADISTICA!A9 -> ALTAMIRA | B10: =ESTADISTICA!B9 -> ALT02 | C10: =ESTADISTICA!C9 -> Calchaqui y Lope de Vega | D10: =ESTADISTICA!D9 -> Domo | E10: =ESTADISTICA!E9 -> PTP A FO | F10: =ESTADISTICA!F9 -> 0 | G10: =ESTADISTICA!G9 -> 0 | H10: =ESTADISTICA!H9 -> 0 | ... AG10: =ESTADISTICA!AG9 -> 0
A11: =ESTADISTICA!A10 -> ALTAMIRA | B11: =ESTADISTICA!B10 -> ALT03 | C11: =ESTADISTICA!C10 -> Bombero Galarza y Necochea | D11: =ESTADISTICA!D10 -> Domo | E11: =ESTADISTICA!E10 -> Fibra Optica | F11: =ESTADISTICA!F10 -> 0 | G11: =ESTADISTICA!G10 -> 0 | H11: =ESTADISTICA!H10 -> 0 | ... AG11: =ESTADISTICA!AG10 -> 0
A12: =ESTADISTICA!A11 -> 0 | B12: =ESTADISTICA!B11 -> ALT04 | C12: =ESTADISTICA!C11 -> Francia y Necochea | D12: =ESTADISTICA!D11 -> Domo | E12: =ESTADISTICA!E11 -> Fibra Optica | F12: =ESTADISTICA!F11 -> APAGADO | G12: =ESTADISTICA!G11 -> 0 | H12: =ESTADISTICA!H11 -> 0 | ... AG12: =ESTADISTICA!AG11 -> 0
A13: =ESTADISTICA!A12 -> ALTAMIRA | B13: =ESTADISTICA!B12 -> ALT05 | C13: =ESTADISTICA!C12 -> Av. Calchaqui y Bombero Galarza | D13: =ESTADISTICA!D12 -> Domo | E13: =ESTADISTICA!E12 -> PTP A FO | F13: =ESTADISTICA!F12 -> 0 | G13: =ESTADISTICA!G12 -> 0 | H13: =ESTADISTICA!H12 -> 0 | ... AG13: =ESTADISTICA!AG12 -> 0
... A379: =ESTADISTICA!A378 -> 0 | B379: =ESTADISTICA!B378 -> 0 | C379: =ESTADISTICA!C378 -> 0 | D379: =ESTADISTICA!D378 -> 0 | E379: =ESTADISTICA!E378 -> 0 | F379: =ESTADISTICA!F378 -> 0 | G379: =ESTADISTICA!G378 -> 0 | H379: =ESTADISTICA!H378 -> 0 | ... AG379: =ESTADISTICA!AG378 -> 0

Sheet APAGADOS FIBRA
C1: TOTAL FIBRA | D1: =COUNTIFS(E4:E369,"=Fibra Optica") -> 237
E2: APAGADOS | F2: =COUNTIFS(F4:F367, "=APAGADO",E4:E367,"=Fibra Optica") -> 52 | G2: =COUNTIFS(G4:G367, "=APAGADO",E4:E367,"=Fibra Optica") -> 69 | H2: =COUNTIFS(H4:H367, "=APAGADO",E4:E367,"=Fibra Optica") -> 66 | I2: =COUNTIFS(I4:I367, "=APAGADO",E4:E367,"=Fibra Optica") -> 60 | J2: =COUNTIFS(J4:J367, "=APAGADO",E4:E367,"=Fibra Optica") -> 56 | K2: =COUNTIFS(K4:K367, "=APAGADO",E4:E367,"=Fibra Optica") -> 60 | L2: =COUNTIFS(L4:L367, "=APAGADO",E4:E367,"=Fibra Optica") -> 61 | M2: =COUNTIFS(M4:M367, "=APAGADO",E4:E367,"=Fibra Optica") -> 56 | N2: =COUNTIFS(N4:N367, "=APAGADO",E4:E367,"=Fibra Optica") -> 63 | O2: =COUNTIFS(O4:O367, "=APAGADO",E4:E367,"=Fibra Optica") -> 59 | P2: =COUNTIFS(P4:P367, "=APAGADO",E4:E367,"=Fibra Optica") -> 42 | Q2: =COUNTIFS(Q4:Q367, "=APAGADO",E4:E367,"=Fibra Optica") -> 35 | R2: =COUNTIFS(R4:R367, "=APAGADO",E4:E367,"=Fibra Optica") -> 37 | S2: =COUNTIFS(S4:S367, "=APAGADO",E4:E367,"=Fibra Optica") -> 46 | T2: =COUNTIFS(T4:T367, "=APAGADO",E4:E367,"=Fibra Optica") -> 35 | U2: =COUNTIFS(U4:U367, "=APAGADO",E4:E367,"=Fibra Optica") -> 49 | V2: =COUNTIFS(V4:V367, "=APAGADO",E4:E367,"=Fibra Optica") -> 28 | W2: =COUNTIFS(W4:W367, "=APAGADO",E4:E367,"=Fibra Optica") -> 37 | X2: =COUNTIFS(X4:X367, "=APAGADO",E4:E367,"=Fibra Optica") -> 50 | Y2: =COUNTIFS(Y4:Y367, "=APAGADO",E4:E367,"=Fibra Optica") -> 36 | Z2: =COUNTIFS(Z4:Z367, "=APAGADO",E4:E367,"=Fibra Optica") -> 39 | AA2: =COUNTIFS(AA4:AA367, "=APAGADO",E4:E367,"=Fibra Optica") -> 55 | AB2: =COUNTIFS(AB4:AB367, "=APAGADO",E4:E367,"=Fibra Optica") -> 28 | AC2: =COUNTIFS(AC4:AC367, "=APAGADO",E4:E367,"=Fibra Optica") -> 70 | AD2: =COUNTIFS(AD4:AD367, "=APAGADO",E4:E367,"=Fibra Optica") -> 43 | AE2: =COUNTIFS(AE4:AE367, "=APAGADO",AC4:AC367,"=Fibra Optica") -> 0 | AF2: =COUNTIFS(AF4:AF367, "=APAGADO",AC4:AC367,"=Fibra Optica") -> 0 | AG2: =COUNTIFS(AG4:AG367, "=APAGADO",AC4:AC367,"=Fibra Optica") -> 0 | AH2: =COUNTIFS(AH4:AH367, "=APAGADO",AD4:AD367,"=Fibra Optica") -> 0 | AI2: =COUNTIFS(AI4:AI367, "=APAGADO",AE4:AE367,"=Fibra Optica") -> 0 | AJ2: =COUNTIFS(AJ4:AJ367, "=APAGADO",AF4:AF367,"=Fibra Optica") -> 0
A3: =ESTADISTICA!A1 -> Barrio | B3: =ESTADISTICA!B1 -> [Denominacion] | C3: =ESTADISTICA!C1 -> [Ubicacion] | D3: =ESTADISTICA!D1 -> [Tipo de Camara] | E3: =ESTADISTICA!E1 -> [Tipo de Conexion] | F3: =ESTADISTICA!F1 -> 44621 | G3: =ESTADISTICA!G1 -> 44622 | H3: =ESTADISTICA!H1 -> 44623 | ... AJ3: =ESTADISTICA!AJ1 -> 44651
A4: =ESTADISTICA!A2 -> PRESIDENTE PERON (PEPSI) | B4: =ESTADISTICA!B2 -> MAR 01 | C4: =ESTADISTICA!C2 -> RP36 Y LA ESMERALDA | D4: =ESTADISTICA!D2 -> DOMO | E4: =ESTADISTICA!E2 -> Fibra Optica | F4: =ESTADISTICA!F2 -> APAGADO | G4: =ESTADISTICA!G2 -> APAGADO | H4: =ESTADISTICA!H2 -> APAGADO | ... AG4: =ESTADISTICA!AG2 -> 0
A5: =ESTADISTICA!A3 -> MAYOL | B5: =ESTADISTICA!B3 -> MAY 01 | C5: =ESTADISTICA!C3 -> Eva Peron y Cabildo | D5: =ESTADISTICA!D3 -> Domo | E5: =ESTADISTICA!E3 -> Radio | F5: =ESTADISTICA!F3 -> 0 | G5: =ESTADISTICA!G3 -> 0 | H5: =ESTADISTICA!H3 -> 0 | ... AG5: =ESTADISTICA!AG3 -> 0
A6: =ESTADISTICA!A4 -> 0 | B6: =ESTADISTICA!B4 -> MAY 02 | C6: =ESTADISTICA!C4 -> EVA PERON Y MONTEVIDEO | D6: =ESTADISTICA!D4 -> Domo | E6: =ESTADISTICA!E4 -> Radio | F6: =ESTADISTICA!F4 -> 0 | G6: =ESTADISTICA!G4 -> 0 | H6: =ESTADISTICA!H4 -> 0 | ... AG6: =ESTADISTICA!AG4 -> 0
A7: =ESTADISTICA!A5 -> MAYOL | B7: =ESTADISTICA!B5 -> MAY 03 | C7: =ESTADISTICA!C5 -> CHAÑAR Y SAN NICOLAS | D7: =ESTADISTICA!D5 -> DOMO | E7: =ESTADISTICA!E5 -> PTP A FO | F7: =ESTADISTICA!F5 -> 0 | G7: =ESTADISTICA!G5 -> 0 | H7: =ESTADISTICA!H5 -> 0 | ... AG7: =ESTADISTICA!AG5 -> 0
A8: =ESTADISTICA!A6 -> 0 | B8: =ESTADISTICA!B6 -> MAY 04 | C8: =ESTADISTICA!C6 -> MAR CHIQUITA Y RIO JACHAL | D8: =ESTADISTICA!D6 -> DOMO | E8: =ESTADISTICA!E6 -> Radio | F8: =ESTADISTICA!F6 -> 0 | G8: =ESTADISTICA!G6 -> 0 | H8: =ESTADISTICA!H6 -> 0 | ... AG8: =ESTADISTICA!AG6 -> 0
A9: =ESTADISTICA!A7 -> ALTAMIRA | B9: =ESTADISTICA!B7 -> ALT06 | C9: =ESTADISTICA!C7 -> LOPE DE VEGA Y NECOCHEA | D9: =ESTADISTICA!D7 -> Domo | E9: =ESTADISTICA!E7 -> PTP A FO | F9: =ESTADISTICA!F7 -> 0 | G9: =ESTADISTICA!G7 -> 0 | H9: =ESTADISTICA!H7 -> 0 | ... AG9: =ESTADISTICA!AG7 -> 0
A10: =ESTADISTICA!A8 -> ALTAMIRA | B10: =ESTADISTICA!B8 -> ALT01 | C10: =ESTADISTICA!C8 -> Calchaqui y Sgto. Cabral | D10: =ESTADISTICA!D8 -> Domo | E10: =ESTADISTICA!E8 -> Fibra Optica | F10: =ESTADISTICA!F8 -> 0 | G10: =ESTADISTICA!G8 -> 0 | H10: =ESTADISTICA!H8 -> 0 | ... AG10: =ESTADISTICA!AG8 -> 0
A11: =ESTADISTICA!A9 -> ALTAMIRA | B11: =ESTADISTICA!B9 -> ALT02 | C11: =ESTADISTICA!C9 -> Calchaqui y Lope de Vega | D11: =ESTADISTICA!D9 -> Domo | E11: =ESTADISTICA!E9 -> PTP A FO | F11: =ESTADISTICA!F9 -> 0 | G11: =ESTADISTICA!G9 -> 0 | H11: =ESTADISTICA!H9 -> 0 | ... AG11: =ESTADISTICA!AG9 -> 0
A12: =ESTADISTICA!A10 -> ALTAMIRA | B12: =ESTADISTICA!B10 -> ALT03 | C12: =ESTADISTICA!C10 -> Bombero Galarza y Necochea | D12: =ESTADISTICA!D10 -> Domo | E12: =ESTADISTICA!E10 -> Fibra Optica | F12: =ESTADISTICA!F10 -> 0 | G12: =ESTADISTICA!G10 -> 0 | H12: =ESTADISTICA!H10 -> 0 | ... AG12: =ESTADISTICA!AG10 -> 0
A13: =ESTADISTICA!A11 -> 0 | B13: =ESTADISTICA!B11 -> ALT04 | C13: =ESTADISTICA!C11 -> Francia y Necochea | D13: =ESTADISTICA!D11 -> Domo | E13: =ESTADISTICA!E11 -> Fibra Optica | F13: =ESTADISTICA!F11 -> APAGADO | G13: =ESTADISTICA!G11 -> 0 | H13: =ESTADISTICA!H11 -> 0 | ... AG13: =ESTADISTICA!AG11 -> 0
A14: =ESTADISTICA!A12 -> ALTAMIRA | B14: =ESTADISTICA!B12 -> ALT05 | C14: =ESTADISTICA!C12 -> Av. Calchaqui y Bombero Galarza | D14: =ESTADISTICA!D12 -> Domo | E14: =ESTADISTICA!E12 -> PTP A FO | F14: =ESTADISTICA!F12 -> 0 | G14: =ESTADISTICA!G12 -> 0 | H14: =ESTADISTICA!H12 -> 0 | ... AG14: =ESTADISTICA!AG12 -> 0
A15: =ESTADISTICA!A13 -> ALTAMIRA | B15: =ESTADISTICA!B13 -> ALT07 | C15: =ESTADISTICA!C13 -> AV. CALCHAQUI Y AV. DEL TRABAJO | D15: =ESTADISTICA!D13 -> DOMO | E15: =ESTADISTICA!E13 -> PTP A FO | F15: =ESTADISTICA!F13 -> 0 | G15: =ESTADISTICA!G13 -> 0 | H15: =ESTADISTICA!H13 -> 0 | ... AG15: =ESTADISTICA!AG13 -> 0
... A369: =ESTADISTICA!A367 -> 0 | B369: =ESTADISTICA!B367 -> ZEB04 | C369: =ESTADISTICA!C367 -> THEVENET Y DIAGONAL GRANADEROS | D369: =ESTADISTICA!D367 -> DOMO | E369: =ESTADISTICA!E367 -> Radio | F369: =ESTADISTICA!F367 -> 0 | G369: =ESTADISTICA!G367 -> 0 | H369: =ESTADISTICA!H367 -> 0 | ... AG369: =ESTADISTICA!AG367 -> 0

Sheet APAGADOS ANTENA
C1: TOTAL PTP A FO | D1: =COUNTIFS(E4:E367,"=PTP A FO") -> 38
E2: APAGADOS | F2: =COUNTIFS(F4:F367, "=APAGADO",E4:E367,"=PTP A FO") -> 2 | G2: =COUNTIFS(G4:G367, "=APAGADO",E4:E367,"=PTP A FO") -> 4 | H2: =COUNTIFS(H4:H367, "=APAGADO",E4:E367,"=PTP A FO") -> 3 | I2: =COUNTIFS(I4:I367, "=APAGADO",E4:E367,"=PTP A FO") -> 1 | J2: =COUNTIFS(J4:J367, "=APAGADO",E4:E367,"=PTP A FO") -> 4 | K2: =COUNTIFS(K4:K367, "=APAGADO",E4:E367,"=PTP A FO") -> 1 | L2: =COUNTIFS(L4:L367, "=APAGADO",E4:E367,"=PTP A FO") -> 1 | M2: =COUNTIFS(M4:M367, "=APAGADO",E4:E367,"=PTP A FO") -> 2 | N2: =COUNTIFS(N4:N367, "=APAGADO",E4:E367,"=PTP A FO") -> 6 | O2: =COUNTIFS(O4:O367,"APAGADO", E4:E367,"=PTP A FO" ) -> 2 | P2: =COUNTIFS(P4:P367, "=APAGADO",E4:E367,"=PTP A FO") -> 11 | Q2: =COUNTIFS(Q4:Q367, "=APAGADO",E4:E367,"=PTP A FO") -> 8 | R2: =COUNTIFS(R4:R367, "=APAGADO",E4:E367,"=PTP A FO") -> 10 | S2: =COUNTIFS(S4:S367, "=APAGADO",E4:E367,"=PTP A FO") -> 8 | T2: =COUNTIFS(T4:T367, "=APAGADO",E4:E367,"=PTP A FO") -> 9 | U2: =COUNTIFS(U4:U367, "=APAGADO",E4:E367,"=PTP A FO") -> 11 | V2: =COUNTIFS(V4:V367, "=APAGADO",E4:E367,"=PTP A FO") -> 12 | W2: =COUNTIFS(W4:W367, "=APAGADO",E4:E367,"=PTP A FO") -> 12 | X2: =COUNTIFS(X4:X367, "=APAGADO",E4:E367,"=PTP A FO") -> 16 | Y2: =COUNTIFS(Y4:Y367, "=APAGADO",E4:E367,"=PTP A FO") -> 13 | Z2: =COUNTIFS(Z4:Z367, "=APAGADO",E4:E367,"=PTP A FO") -> 13 | AA2: =COUNTIFS(AA4:AA367, "=APAGADO",E4:E367,"=PTP A FO") -> 10 | AB2: =COUNTIFS(AB4:AB367, "=APAGADO",E4:E367,"=PTP A FO") -> 2 | AC2: =COUNTIFS(AC4:AC367, "=APAGADO",E4:E367,"=PTP A FO") -> 7 | AD2: =COUNTIFS(AD4:AD367, "=APAGADO",E4:E367,"=PTP A FO") -> 4 | AE2: =COUNTIFS(AE4:AE367, "=APAGADO",E4:E367,"=PTP A FO") -> 0 | AF2: =COUNTIFS(AF4:AF367, "=APAGADO",E4:E367,"=PTP A FO") -> 0 | AG2: =COUNTIFS(AG4:AG367, "=APAGADO",E4:E367,"=PTP A FO") -> 0 | AH2: =COUNTIFS(AH4:AH367, "=APAGADO",F4:F367,"=PTP A FO") -> 0 | AI2: =COUNTIFS(AI4:AI367, "=APAGADO",G4:G367,"=PTP A FO") -> 0 | AJ2: =COUNTIFS(AJ4:AJ367, "=APAGADO",H4:H367,"=PTP A FO") -> 0
A3: =ESTADISTICA!A1 -> Barrio | B3: =ESTADISTICA!B1 -> [Denominacion] | C3: =ESTADISTICA!C1 -> [Ubicacion] | D3: =ESTADISTICA!D1 -> [Tipo de Camara] | E3: =ESTADISTICA!E1 -> [Tipo de Conexion] | F3: =ESTADISTICA!F1 -> 44621 | G3: =ESTADISTICA!G1 -> 44622 | H3: =ESTADISTICA!H1 -> 44623 | ... AJ3: =ESTADISTICA!AJ1 -> 44651
A4: =ESTADISTICA!A2 -> PRESIDENTE PERON (PEPSI) | B4: =ESTADISTICA!B2 -> MAR 01 | C4: =ESTADISTICA!C2 -> RP36 Y LA ESMERALDA | D4: =ESTADISTICA!D2 -> DOMO | E4: =ESTADISTICA!E2 -> Fibra Optica | F4: =ESTADISTICA!F2 -> APAGADO | G4: =ESTADISTICA!G2 -> APAGADO | H4: =ESTADISTICA!H2 -> APAGADO | ... AG4: =ESTADISTICA!AG2 -> 0
A5: =ESTADISTICA!A3 -> MAYOL | B5: =ESTADISTICA!B3 -> MAY 01 | C5: =ESTADISTICA!C3 -> Eva Peron y Cabildo | D5: =ESTADISTICA!D3 -> Domo | E5: =ESTADISTICA!E3 -> Radio | F5: =ESTADISTICA!F3 -> 0 | G5: =ESTADISTICA!G3 -> 0 | H5: =ESTADISTICA!H3 -> 0 | ... AG5: =ESTADISTICA!AG3 -> 0
A6: =ESTADISTICA!A4 -> 0 | B6: =ESTADISTICA!B4 -> MAY 02 | C6: =ESTADISTICA!C4 -> EVA PERON Y MONTEVIDEO | D6: =ESTADISTICA!D4 -> Domo | E6: =ESTADISTICA!E4 -> Radio | F6: =ESTADISTICA!F4 -> 0 | G6: =ESTADISTICA!G4 -> 0 | H6: =ESTADISTICA!H4 -> 0 | ... AG6: =ESTADISTICA!AG4 -> 0
A7: =ESTADISTICA!A5 -> MAYOL | B7: =ESTADISTICA!B5 -> MAY 03 | C7: =ESTADISTICA!C5 -> CHAÑAR Y SAN NICOLAS | D7: =ESTADISTICA!D5 -> DOMO | E7: =ESTADISTICA!E5 -> PTP A FO | F7: =ESTADISTICA!F5 -> 0 | G7: =ESTADISTICA!G5 -> 0 | H7: =ESTADISTICA!H5 -> 0 | ... AG7: =ESTADISTICA!AG5 -> 0
A8: =ESTADISTICA!A6 -> 0 | B8: =ESTADISTICA!B6 -> MAY 04 | C8: =ESTADISTICA!C6 -> MAR CHIQUITA Y RIO JACHAL | D8: =ESTADISTICA!D6 -> DOMO | E8: =ESTADISTICA!E6 -> Radio | F8: =ESTADISTICA!F6 -> 0 | G8: =ESTADISTICA!G6 -> 0 | H8: =ESTADISTICA!H6 -> 0 | ... AG8: =ESTADISTICA!AG6 -> 0
A9: =ESTADISTICA!A7 -> ALTAMIRA | B9: =ESTADISTICA!B7 -> ALT06 | C9: =ESTADISTICA!C7 -> LOPE DE VEGA Y NECOCHEA | D9: =ESTADISTICA!D7 -> Domo | E9: =ESTADISTICA!E7 -> PTP A FO | F9: =ESTADISTICA!F7 -> 0 | G9: =ESTADISTICA!G7 -> 0 | H9: =ESTADISTICA!H7 -> 0 | ... AG9: =ESTADISTICA!AG7 -> 0
A10: =ESTADISTICA!A8 -> ALTAMIRA | B10: =ESTADISTICA!B8 -> ALT01 | C10: =ESTADISTICA!C8 -> Calchaqui y Sgto. Cabral | D10: =ESTADISTICA!D8 -> Domo | E10: =ESTADISTICA!E8 -> Fibra Optica | F10: =ESTADISTICA!F8 -> 0 | G10: =ESTADISTICA!G8 -> 0 | H10: =ESTADISTICA!H8 -> 0 | ... AG10: =ESTADISTICA!AG8 -> 0
A11: =ESTADISTICA!A9 -> ALTAMIRA | B11: =ESTADISTICA!B9 -> ALT02 | C11: =ESTADISTICA!C9 -> Calchaqui y Lope de Vega | D11: =ESTADISTICA!D9 -> Domo | E11: =ESTADISTICA!E9 -> PTP A FO | F11: =ESTADISTICA!F9 -> 0 | G11: =ESTADISTICA!G9 -> 0 | H11: =ESTADISTICA!H9 -> 0 | ... AG11: =ESTADISTICA!AG9 -> 0
A12: =ESTADISTICA!A10 -> ALTAMIRA | B12: =ESTADISTICA!B10 -> ALT03 | C12: =ESTADISTICA!C10 -> Bombero Galarza y Necochea | D12: =ESTADISTICA!D10 -> Domo | E12: =ESTADISTICA!E10 -> Fibra Optica | F12: =ESTADISTICA!F10 -> 0 | G12: =ESTADISTICA!G10 -> 0 | H12: =ESTADISTICA!H10 -> 0 | ... AG12: =ESTADISTICA!AG10 -> 0
A13: =ESTADISTICA!A11 -> 0 | B13: =ESTADISTICA!B11 -> ALT04 | C13: =ESTADISTICA!C11 -> Francia y Necochea | D13: =ESTADISTICA!D11 -> Domo | E13: =ESTADISTICA!E11 -> Fibra Optica | F13: =ESTADISTICA!F11 -> APAGADO | G13: =ESTADISTICA!G11 -> 0 | H13: =ESTADISTICA!H11 -> 0 | ... AG13: =ESTADISTICA!AG11 -> 0
A14: =ESTADISTICA!A12 -> ALTAMIRA | B14: =ESTADISTICA!B12 -> ALT05 | C14: =ESTADISTICA!C12 -> Av. Calchaqui y Bombero Galarza | D14: =ESTADISTICA!D12 -> Domo | E14: =ESTADISTICA!E12 -> PTP A FO | F14: =ESTADISTICA!F12 -> 0 | G14: =ESTADISTICA!G12 -> 0 | H14: =ESTADISTICA!H12 -> 0 | ... AG14: =ESTADISTICA!AG12 -> 0
A15: =ESTADISTICA!A13 -> ALTAMIRA | B15: =ESTADISTICA!B13 -> ALT07 | C15: =ESTADISTICA!C13 -> AV. CALCHAQUI Y AV. DEL TRABAJO | D15: =ESTADISTICA!D13 -> DOMO | E15: =ESTADISTICA!E13 -> PTP A FO | F15: =ESTADISTICA!F13 -> 0 | G15: =ESTADISTICA!G13 -> 0 | H15: =ESTADISTICA!H13 -> 0 | ... AG15: =ESTADISTICA!AG13 -> 0
... A278: =ESTADISTICA!A276 -> SANTA ROSA | B278: =ESTADISTICA!B276 -> SRO11 | C278: =ESTADISTICA!C276 -> MILAN Y MALLORCA | D278: =ESTADISTICA!D276 -> DOMO | E278: =ESTADISTICA!E276 -> Radio | F278: =ESTADISTICA!F276 -> APAGADO | G278: =ESTADISTICA!G276 -> APAGADO | H278: =ESTADISTICA!H276 -> APAGADO | ... AG278: =ESTADISTICA!AG276 -> 0
B279: =ESTADISTICA!B277 -> SRO12 | C279: =ESTADISTICA!C277 -> YUGOSLAVIA Y PAYSANDU | D279: =ESTADISTICA!D277 -> DOMO | E279: =ESTADISTICA!E277 -> Radio | F279: =ESTADISTICA!F277 -> 0 | G279: =ESTADISTICA!G277 -> 0 | H279: =ESTADISTICA!H277 -> 0 | I279: =ESTADISTICA!I277 -> 0 | ... AG279: =ESTADISTICA!AG277 -> 0
A280: =ESTADISTICA!A278 -> ZONA RURAL SANTA ROSA | B280: =ESTADISTICA!B278 -> SRO13 (fija 1) | C280: =ESTADISTICA!C278 -> BRUSELAS E/ GRECIA Y CHECOSLOVAQUIA | D280: =ESTADISTICA!D278 -> Fija | E280: =ESTADISTICA!E278 -> RADIO | F280: =ESTADISTICA!F278 -> 0 | G280: =ESTADISTICA!G278 -> 0 | H280: =ESTADISTICA!H278 -> 0 | ... AG280: =ESTADISTICA!AG278 -> 0
A281: =ESTADISTICA!A279 -> ZONA RURAL SANTA ROSA | B281: =ESTADISTICA!B279 -> SRO14 (fija 2) | C281: =ESTADISTICA!C279 -> BRUSELAS E/ GRECIA Y CHECOSLOVAQUIA | D281: =ESTADISTICA!D279 -> Fija | E281: =ESTADISTICA!E279 -> RADIO | F281: =ESTADISTICA!F279 -> APAGADO | G281: =ESTADISTICA!G279 -> APAGADO | H281: =ESTADISTICA!H279 -> APAGADO | ... AG281: =ESTADISTICA!AG279 -> 0
A282: =ESTADISTICA!A280 -> SANTA ROSA | B282: =ESTADISTICA!B280 -> SRO15 | C282: =ESTADISTICA!C280 -> NOVAK Y TIRANA (614) | D282: =ESTADISTICA!D280 -> DOMO | E282: =ESTADISTICA!E280 -> Fibra Optica | F282: =ESTADISTICA!F280 -> 0 | G282: =ESTADISTICA!G280 -> 0 | H282: =ESTADISTICA!H280 -> 0 | ... AG282: =ESTADISTICA!AG280 -> 0
A283: =ESTADISTICA!A281 -> SANTA ROSA | B283: =ESTADISTICA!B281 -> SRO18 (fija 1) | C283: =ESTADISTICA!C281 -> GRAN CANARIA Y BUDAPEST | D283: =ESTADISTICA!D281 -> Fija | E283: =ESTADISTICA!E281 -> Fibra Optica | F283: =ESTADISTICA!F281 -> 0 | G283: =ESTADISTICA!G281 -> 0 | H283: =ESTADISTICA!H281 -> 0 | ... AG283: =ESTADISTICA!AG281 -> 0
A284: =ESTADISTICA!A282 -> SANTA ROSA | B284: =ESTADISTICA!B282 -> SRO19 (fija 2) | C284: =ESTADISTICA!C282 -> GRAN CANARIA Y BUDAPEST | D284: =ESTADISTICA!D282 -> Fija | E284: =ESTADISTICA!E282 -> Fibra Optica | F284: =ESTADISTICA!F282 -> 0 | G284: =ESTADISTICA!G282 -> 0 | H284: =ESTADISTICA!H282 -> 0 | ... AG284: =ESTADISTICA!AG282 -> 0
A285: =ESTADISTICA!A283 -> SAN RUDECINDO | B285: =ESTADISTICA!B283 -> SRU01 (fija 1) | C285: =ESTADISTICA!C283 -> HERNANDARIAS Y AMBATO | D285: =ESTADISTICA!D283 -> Fija | E285: =ESTADISTICA!E283 -> Fibra Optica | F285: =ESTADISTICA!F283 -> 0 | G285: =ESTADISTICA!G283 -> 0 | H285: =ESTADISTICA!H283 -> 0 | ... AG285: =ESTADISTICA!AG283 -> 0
A286: =ESTADISTICA!A284 -> SAN RUDECINDO | B286: =ESTADISTICA!B284 -> SRU02 (fija 2) | C286: =ESTADISTICA!C284 -> HERNANDARIAS Y AMBATO | D286: =ESTADISTICA!D284 -> Fija | E286: =ESTADISTICA!E284 -> Fibra Optica | F286: =ESTADISTICA!F284 -> 0 | G286: =ESTADISTICA!G284 -> 0 | H286: =ESTADISTICA!H284 -> 0 | ... AG286: =ESTADISTICA!AG284 -> 0
A287: =ESTADISTICA!A285 -> VILLA ANGELICA | B287: =ESTADISTICA!B285 -> VANG01 | C287: =ESTADISTICA!C285 -> Senzabello y Necochea | D287: =ESTADISTICA!D285 -> Domo | E287: =ESTADISTICA!E285 -> PTP A FO | F287: =ESTADISTICA!F285 -> 0 | G287: =ESTADISTICA!G285 -> 0 | H287: =ESTADISTICA!H285 -> 0 | ... AG287: =ESTADISTICA!AG285 -> 0
A288: =ESTADISTICA!A286 -> VILLA ANGELICA | B288: =ESTADISTICA!B286 -> VANG02 | C288: =ESTADISTICA!C286 -> Thevenet y Ruta 36 | D288: =ESTADISTICA!D286 -> Domo | E288: =ESTADISTICA!E286 -> Fibra Optica | F288: =ESTADISTICA!F286 -> 0 | G288: =ESTADISTICA!G286 -> 0 | H288: =ESTADISTICA!H286 -> 0 | ... AG288: =ESTADISTICA!AG286 -> 0
A289: =ESTADISTICA!A287 -> VILLA DEL PLATA | B289: =ESTADISTICA!B287 -> VANG03 | C289: =ESTADISTICA!C287 -> Thevenet 1950 | D289: =ESTADISTICA!D287 -> Domo | E289: =ESTADISTICA!E287 -> Fibra Optica | F289: =ESTADISTICA!F287 -> 0 | G289: =ESTADISTICA!G287 -> 0 | H289: =ESTADISTICA!H287 -> 0 | ... AG289: =ESTADISTICA!AG287 -> 0
A290: =ESTADISTICA!A288 -> VILLA ANGELICA | B290: =ESTADISTICA!B288 -> VANG04 | C290: =ESTADISTICA!C288 -> Storni e/Thevenet y Calle 158 | D290: =ESTADISTICA!D288 -> DOMO | E290: =ESTADISTICA!E288 -> Fibra Optica | F290: =ESTADISTICA!F288 -> 0 | G290: =ESTADISTICA!G288 -> 0 | H290: =ESTADISTICA!H288 -> 0 | ... AG290: =ESTADISTICA!AG288 -> 0
A291: =ESTADISTICA!A289 -> VILLA ANGELICA | B291: =ESTADISTICA!B289 -> VANG05 | C291: =ESTADISTICA!C289 -> Storni y Thevenet | D291: =ESTADISTICA!D289 -> Domo | E291: =ESTADISTICA!E289 -> Fibra Optica | F291: =ESTADISTICA!F289 -> 0 | G291: =ESTADISTICA!G289 -> 0 | H291: =ESTADISTICA!H289 -> 0 | ... AG291: =ESTADISTICA!AG289 -> 0
... A369: =ESTADISTICA!A367 -> 0 | B369: =ESTADISTICA!B367 -> ZEB04 | C369: =ESTADISTICA!C367 -> THEVENET Y DIAGONAL GRANADEROS | D369: =ESTADISTICA!D367 -> DOMO | E369: =ESTADISTICA!E367 -> Radio | F369: =ESTADISTICA!F367 -> 0 | G369: =ESTADISTICA!G367 -> 0 | H369: =ESTADISTICA!H367 -> 0 | ... AG369: =ESTADISTICA!AG367 -> 0

Sheet APAGADOS RADIO
C1: TOTAL RADIO | D1: =COUNTIFS(E4:E367,"=radio") -> 88
E2: APAGADOS | F2: =COUNTIFS(F4:F367, "=APAGADO",E4:E367,"=radio") -> 7 | G2: =COUNTIFS(G4:G367, "=APAGADO",E4:E367,"=radio") -> 6 | H2: =COUNTIFS(H4:H367, "=APAGADO",E4:E367,"=radio") -> 7 | I2: =COUNTIFS(I4:I367, "=APAGADO",E4:E367,"=radio") -> 8 | J2: =COUNTIFS(J4:J367, "=APAGADO",E4:E367,"=radio") -> 8 | K2: =COUNTIFS(K4:K367, "=APAGADO",E4:E367,"=radio") -> 6 | L2: =COUNTIFS(L4:L367, "=APAGADO",E4:E367,"=radio") -> 8 | M2: =COUNTIFS(M4:M367, "=APAGADO",E4:E367,"=radio") -> 8 | N2: =COUNTIFS(N4:N367, "=APAGADO",E4:E367,"=radio") -> 9 | O2: =COUNTIFS(O4:O367, "=APAGADO",E4:E367,"=radio") -> 7 | P2: =COUNTIFS(P4:P367, "=APAGADO",E4:E367,"=radio") -> 5 | Q2: =COUNTIFS(Q4:Q367, "=APAGADO",E4:E367,"=radio") -> 4 | R2: =COUNTIFS(R4:R367, "=APAGADO",E4:E367,"=radio") -> 5 | S2: =COUNTIFS(S4:S367, "=APAGADO",E4:E367,"=radio") -> 4 | T2: =COUNTIFS(T4:T367, "=APAGADO",E4:E367,"=radio") -> 4 | U2: =COUNTIFS(U4:U367, "=APAGADO",E4:E367,"=radio") -> 4 | V2: =COUNTIFS(V4:V367, "=APAGADO",E4:E367,"=radio") -> 3 | W2: =COUNTIFS(W4:W367, "=APAGADO",E4:E367,"=radio") -> 3 | X2: =COUNTIFS(X4:X367, "=APAGADO",E4:E367,"=radio") -> 6 | Y2: =COUNTIFS(Y4:Y367, "=APAGADO",E4:E367,"=radio") -> 3 | Z2: =COUNTIFS(Z4:Z367, "=APAGADO",E4:E367,"=radio") -> 3 | AA2: =COUNTIFS(AA4:AA367, "=APAGADO",E4:E367,"=radio") -> 3 | AB2: =COUNTIFS(AB4:AB367, "=APAGADO",E4:E367,"=radio") -> 2 | AC2: =COUNTIFS(AC4:AC367, "=APAGADO",E4:E367,"=radio") -> 7 | AD2: =COUNTIFS(AD4:AD367, "=APAGADO",E4:E367,"=radio") -> 5 | AE2: =COUNTIFS(AE4:AE367, "=APAGADO",E4:E367,"=radio") -> 0 | AF2: =COUNTIFS(AF4:AF367, "=APAGADO",E4:E367,"=radio") -> 0 | AG2: =COUNTIFS(AG4:AG367, "=APAGADO",E4:E367,"=radio") -> 0 | AH2: =COUNTIFS(AH4:AH367, "=APAGADO",F4:F367,"=radio") -> 0 | AI2: =COUNTIFS(AI4:AI367, "=APAGADO",G4:G367,"=radio") -> 0 | AJ2: =COUNTIFS(AJ4:AJ367, "=APAGADO",H4:H367,"=radio") -> 0
A3: =ESTADISTICA!A1 -> Barrio | B3: =ESTADISTICA!B1 -> [Denominacion] | C3: =ESTADISTICA!C1 -> [Ubicacion] | D3: =ESTADISTICA!D1 -> [Tipo de Camara] | E3: =ESTADISTICA!E1 -> [Tipo de Conexion] | F3: =ESTADISTICA!F1 -> 44621 | G3: =ESTADISTICA!G1 -> 44622 | H3: =ESTADISTICA!H1 -> 44623 | ... AJ3: =ESTADISTICA!AJ1 -> 44651
A4: =ESTADISTICA!A2 -> PRESIDENTE PERON (PEPSI) | B4: =ESTADISTICA!B2 -> MAR 01 | C4: =ESTADISTICA!C2 -> RP36 Y LA ESMERALDA | D4: =ESTADISTICA!D2 -> DOMO | E4: =ESTADISTICA!E2 -> Fibra Optica | F4: =ESTADISTICA!F2 -> APAGADO | G4: =ESTADISTICA!G2 -> APAGADO | H4: =ESTADISTICA!H2 -> APAGADO | ... AG4: =ESTADISTICA!AG2 -> 0
A5: =ESTADISTICA!A3 -> MAYOL | B5: =ESTADISTICA!B3 -> MAY 01 | C5: =ESTADISTICA!C3 -> Eva Peron y Cabildo | D5: =ESTADISTICA!D3 -> Domo | E5: =ESTADISTICA!E3 -> Radio | F5: =ESTADISTICA!F3 -> 0 | G5: =ESTADISTICA!G3 -> 0 | H5: =ESTADISTICA!H3 -> 0 | ... AG5: =ESTADISTICA!AG3 -> 0
A6: =ESTADISTICA!A4 -> 0 | B6: =ESTADISTICA!B4 -> MAY 02 | C6: =ESTADISTICA!C4 -> EVA PERON Y MONTEVIDEO | D6: =ESTADISTICA!D4 -> Domo | E6: =ESTADISTICA!E4 -> Radio | F6: =ESTADISTICA!F4 -> 0 | G6: =ESTADISTICA!G4 -> 0 | H6: =ESTADISTICA!H4 -> 0 | ... AG6: =ESTADISTICA!AG4 -> 0
A7: =ESTADISTICA!A5 -> MAYOL | B7: =ESTADISTICA!B5 -> MAY 03 | C7: =ESTADISTICA!C5 -> CHAÑAR Y SAN NICOLAS | D7: =ESTADISTICA!D5 -> DOMO | E7: =ESTADISTICA!E5 -> PTP A FO | F7: =ESTADISTICA!F5 -> 0 | G7: =ESTADISTICA!G5 -> 0 | H7: =ESTADISTICA!H5 -> 0 | ... AG7: =ESTADISTICA!AG5 -> 0
A8: =ESTADISTICA!A6 -> 0 | B8: =ESTADISTICA!B6 -> MAY 04 | C8: =ESTADISTICA!C6 -> MAR CHIQUITA Y RIO JACHAL | D8: =ESTADISTICA!D6 -> DOMO | E8: =ESTADISTICA!E6 -> Radio | F8: =ESTADISTICA!F6 -> 0 | G8: =ESTADISTICA!G6 -> 0 | H8: =ESTADISTICA!H6 -> 0 | ... AG8: =ESTADISTICA!AG6 -> 0
A9: =ESTADISTICA!A7 -> ALTAMIRA | B9: =ESTADISTICA!B7 -> ALT06 | C9: =ESTADISTICA!C7 -> LOPE DE VEGA Y NECOCHEA | D9: =ESTADISTICA!D7 -> Domo | E9: =ESTADISTICA!E7 -> PTP A FO | F9: =ESTADISTICA!F7 -> 0 | G9: =ESTADISTICA!G7 -> 0 | H9: =ESTADISTICA!H7 -> 0 | ... AG9: =ESTADISTICA!AG7 -> 0
A10: =ESTADISTICA!A8 -> ALTAMIRA | B10: =ESTADISTICA!B8 -> ALT01 | C10: =ESTADISTICA!C8 -> Calchaqui y Sgto. Cabral | D10: =ESTADISTICA!D8 -> Domo | E10: =ESTADISTICA!E8 -> Fibra Optica | F10: =ESTADISTICA!F8 -> 0 | G10: =ESTADISTICA!G8 -> 0 | H10: =ESTADISTICA!H8 -> 0 | ... AG10: =ESTADISTICA!AG8 -> 0
A11: =ESTADISTICA!A9 -> ALTAMIRA | B11: =ESTADISTICA!B9 -> ALT02 | C11: =ESTADISTICA!C9 -> Calchaqui y Lope de Vega | D11: =ESTADISTICA!D9 -> Domo | E11: =ESTADISTICA!E9 -> PTP A FO | F11: =ESTADISTICA!F9 -> 0 | G11: =ESTADISTICA!G9 -> 0 | H11: =ESTADISTICA!H9 -> 0 | ... AG11: =ESTADISTICA!AG9 -> 0
A12: =ESTADISTICA!A10 -> ALTAMIRA | B12: =ESTADISTICA!B10 -> ALT03 | C12: =ESTADISTICA!C10 -> Bombero Galarza y Necochea | D12: =ESTADISTICA!D10 -> Domo | E12: =ESTADISTICA!E10 -> Fibra Optica | F12: =ESTADISTICA!F10 -> 0 | G12: =ESTADISTICA!G10 -> 0 | H12: =ESTADISTICA!H10 -> 0 | ... AG12: =ESTADISTICA!AG10 -> 0
A13: =ESTADISTICA!A11 -> 0 | B13: =ESTADISTICA!B11 -> ALT04 | C13: =ESTADISTICA!C11 -> Francia y Necochea | D13: =ESTADISTICA!D11 -> Domo | E13: =ESTADISTICA!E11 -> Fibra Optica | F13: =ESTADISTICA!F11 -> APAGADO | G13: =ESTADISTICA!G11 -> 0 | H13: =ESTADISTICA!H11 -> 0 | ... AG13: =ESTADISTICA!AG11 -> 0
A14: =ESTADISTICA!A12 -> ALTAMIRA | B14: =ESTADISTICA!B12 -> ALT05 | C14: =ESTADISTICA!C12 -> Av. Calchaqui y Bombero Galarza | D14: =ESTADISTICA!D12 -> Domo | E14: =ESTADISTICA!E12 -> PTP A FO | F14: =ESTADISTICA!F12 -> 0 | G14: =ESTADISTICA!G12 -> 0 | H14: =ESTADISTICA!H12 -> 0 | ... AG14: =ESTADISTICA!AG12 -> 0
A15: =ESTADISTICA!A13 -> ALTAMIRA | B15: =ESTADISTICA!B13 -> ALT07 | C15: =ESTADISTICA!C13 -> AV. CALCHAQUI Y AV. DEL TRABAJO | D15: =ESTADISTICA!D13 -> DOMO | E15: =ESTADISTICA!E13 -> PTP A FO | F15: =ESTADISTICA!F13 -> 0 | G15: =ESTADISTICA!G13 -> 0 | H15: =ESTADISTICA!H13 -> 0 | ... AG15: =ESTADISTICA!AG13 -> 0
... A278: =ESTADISTICA!A276 -> SANTA ROSA | B278: =ESTADISTICA!B276 -> SRO11 | C278: =ESTADISTICA!C276 -> MILAN Y MALLORCA | D278: =ESTADISTICA!D276 -> DOMO | E278: =ESTADISTICA!E276 -> Radio | F278: =ESTADISTICA!F276 -> APAGADO | G278: =ESTADISTICA!G276 -> APAGADO | H278: =ESTADISTICA!H276 -> APAGADO | ... AG278: =ESTADISTICA!AG276 -> 0
B279: =ESTADISTICA!B277 -> SRO12 | C279: =ESTADISTICA!C277 -> YUGOSLAVIA Y PAYSANDU | D279: =ESTADISTICA!D277 -> DOMO | E279: =ESTADISTICA!E277 -> Radio | F279: =ESTADISTICA!F277 -> 0 | G279: =ESTADISTICA!G277 -> 0 | H279: =ESTADISTICA!H277 -> 0 | I279: =ESTADISTICA!I277 -> 0 | ... AG279: =ESTADISTICA!AG277 -> 0
A280: =ESTADISTICA!A278 -> ZONA RURAL SANTA ROSA | B280: =ESTADISTICA!B278 -> SRO13 (fija 1) | C280: =ESTADISTICA!C278 -> BRUSELAS E/ GRECIA Y CHECOSLOVAQUIA | D280: =ESTADISTICA!D278 -> Fija | E280: =ESTADISTICA!E278 -> RADIO | F280: =ESTADISTICA!F278 -> 0 | G280: =ESTADISTICA!G278 -> 0 | H280: =ESTADISTICA!H278 -> 0 | ... AG280: =ESTADISTICA!AG278 -> 0
A281: =ESTADISTICA!A279 -> ZONA RURAL SANTA ROSA | B281: =ESTADISTICA!B279 -> SRO14 (fija 2) | C281: =ESTADISTICA!C279 -> BRUSELAS E/ GRECIA Y CHECOSLOVAQUIA | D281: =ESTADISTICA!D279 -> Fija | E281: =ESTADISTICA!E279 -> RADIO | F281: =ESTADISTICA!F279 -> APAGADO | G281: =ESTADISTICA!G279 -> APAGADO | H281: =ESTADISTICA!H279 -> APAGADO | ... AG281: =ESTADISTICA!AG279 -> 0
A282: =ESTADISTICA!A280 -> SANTA ROSA | B282: =ESTADISTICA!B280 -> SRO15 | C282: =ESTADISTICA!C280 -> NOVAK Y TIRANA (614) | D282: =ESTADISTICA!D280 -> DOMO | E282: =ESTADISTICA!E280 -> Fibra Optica | F282: =ESTADISTICA!F280 -> 0 | G282: =ESTADISTICA!G280 -> 0 | H282: =ESTADISTICA!H280 -> 0 | ... AG282: =ESTADISTICA!AG280 -> 0
A283: =ESTADISTICA!A281 -> SANTA ROSA | B283: =ESTADISTICA!B281 -> SRO18 (fija 1) | C283: =ESTADISTICA!C281 -> GRAN CANARIA Y BUDAPEST | D283: =ESTADISTICA!D281 -> Fija | E283: =ESTADISTICA!E281 -> Fibra Optica | F283: =ESTADISTICA!F281 -> 0 | G283: =ESTADISTICA!G281 -> 0 | H283: =ESTADISTICA!H281 -> 0 | ... AG283: =ESTADISTICA!AG281 -> 0
A284: =ESTADISTICA!A282 -> SANTA ROSA | B284: =ESTADISTICA!B282 -> SRO19 (fija 2) | C284: =ESTADISTICA!C282 -> GRAN CANARIA Y BUDAPEST | D284: =ESTADISTICA!D282 -> Fija | E284: =ESTADISTICA!E282 -> Fibra Optica | F284: =ESTADISTICA!F282 -> 0 | G284: =ESTADISTICA!G282 -> 0 | H284: =ESTADISTICA!H282 -> 0 | ... AG284: =ESTADISTICA!AG282 -> 0
A285: =ESTADISTICA!A283 -> SAN RUDECINDO | B285: =ESTADISTICA!B283 -> SRU01 (fija 1) | C285: =ESTADISTICA!C283 -> HERNANDARIAS Y AMBATO | D285: =ESTADISTICA!D283 -> Fija | E285: =ESTADISTICA!E283 -> Fibra Optica | F285: =ESTADISTICA!F283 -> 0 | G285: =ESTADISTICA!G283 -> 0 | H285: =ESTADISTICA!H283 -> 0 | ... AG285: =ESTADISTICA!AG283 -> 0
A286: =ESTADISTICA!A284 -> SAN RUDECINDO | B286: =ESTADISTICA!B284 -> SRU02 (fija 2) | C286: =ESTADISTICA!C284 -> HERNANDARIAS Y AMBATO | D286: =ESTADISTICA!D284 -> Fija | E286: =ESTADISTICA!E284 -> Fibra Optica | F286: =ESTADISTICA!F284 -> 0 | G286: =ESTADISTICA!G284 -> 0 | H286: =ESTADISTICA!H284 -> 0 | ... AG286: =ESTADISTICA!AG284 -> 0
A287: =ESTADISTICA!A285 -> VILLA ANGELICA | B287: =ESTADISTICA!B285 -> VANG01 | C287: =ESTADISTICA!C285 -> Senzabello y Necochea | D287: =ESTADISTICA!D285 -> Domo | E287: =ESTADISTICA!E285 -> PTP A FO | F287: =ESTADISTICA!F285 -> 0 | G287: =ESTADISTICA!G285 -> 0 | H287: =ESTADISTICA!H285 -> 0 | ... AG287: =ESTADISTICA!AG285 -> 0
A288: =ESTADISTICA!A286 -> VILLA ANGELICA | B288: =ESTADISTICA!B286 -> VANG02 | C288: =ESTADISTICA!C286 -> Thevenet y Ruta 36 | D288: =ESTADISTICA!D286 -> Domo | E288: =ESTADISTICA!E286 -> Fibra Optica | F288: =ESTADISTICA!F286 -> 0 | G288: =ESTADISTICA!G286 -> 0 | H288: =ESTADISTICA!H286 -> 0 | ... AG288: =ESTADISTICA!AG286 -> 0
A289: =ESTADISTICA!A287 -> VILLA DEL PLATA | B289: =ESTADISTICA!B287 -> VANG03 | C289: =ESTADISTICA!C287 -> Thevenet 1950 | D289: =ESTADISTICA!D287 -> Domo | E289: =ESTADISTICA!E287 -> Fibra Optica | F289: =ESTADISTICA!F287 -> 0 | G289: =ESTADISTICA!G287 -> 0 | H289: =ESTADISTICA!H287 -> 0 | ... AG289: =ESTADISTICA!AG287 -> 0
A290: =ESTADISTICA!A288 -> VILLA ANGELICA | B290: =ESTADISTICA!B288 -> VANG04 | C290: =ESTADISTICA!C288 -> Storni e/Thevenet y Calle 158 | D290: =ESTADISTICA!D288 -> DOMO | E290: =ESTADISTICA!E288 -> Fibra Optica | F290: =ESTADISTICA!F288 -> 0 | G290: =ESTADISTICA!G288 -> 0 | H290: =ESTADISTICA!H288 -> 0 | ... AG290: =ESTADISTICA!AG288 -> 0
A291: =ESTADISTICA!A289 -> VILLA ANGELICA | B291: =ESTADISTICA!B289 -> VANG05 | C291: =ESTADISTICA!C289 -> Storni y Thevenet | D291: =ESTADISTICA!D289 -> Domo | E291: =ESTADISTICA!E289 -> Fibra Optica | F291: =ESTADISTICA!F289 -> 0 | G291: =ESTADISTICA!G289 -> 0 | H291: =ESTADISTICA!H289 -> 0 | ... AG291: =ESTADISTICA!AG289 -> 0
... A369: =ESTADISTICA!A367 -> 0 | B369: =ESTADISTICA!B367 -> ZEB04 | C369: =ESTADISTICA!C367 -> THEVENET Y DIAGONAL GRANADEROS | D369: =ESTADISTICA!D367 -> DOMO | E369: =ESTADISTICA!E367 -> Radio | F369: =ESTADISTICA!F367 -> 0 | G369: =ESTADISTICA!G367 -> 0 | H369: =ESTADISTICA!H367 -> 0 | ... AG369: =ESTADISTICA!AG367 -> 0

Sheet GRAFICO

Sheet GRAFICO2

Sheet BARRAS

Sheet AUXILIAR
A1: FECHA | B1: RADIO | C1: FIBRA | D1: ANTENA | E1: TOTAL APAGADOS | F1: INSTALADAS
A2: ='APAGADOS RADIO'!F3 -> 44621 | B2: ='APAGADOS RADIO'!F2+D2 -> 9 | C2: ='APAGADOS FIBRA'!F2 -> 52 | D2: ='APAGADOS ANTENA'!F2 -> 2 | E2: =B2+C2 -> 61 | F2: ='RESUMEN TOTAL'!C1 -> 368
A3: ='APAGADOS RADIO'!G3 -> 44622 | B3: ='APAGADOS RADIO'!G2+D3 -> 10 | C3: ='APAGADOS FIBRA'!G2 -> 69 | D3: ='APAGADOS ANTENA'!G2 -> 4 | E3: =B3+C3 -> 79 | F3: ='RESUMEN TOTAL'!C1 -> 368
A4: ='APAGADOS RADIO'!H3 -> 44623 | B4: ='APAGADOS RADIO'!H2+D4 -> 10 | C4: ='APAGADOS FIBRA'!H2 -> 66 | D4: ='APAGADOS ANTENA'!H2 -> 3 | E4: =B4+C4 -> 76 | F4: ='RESUMEN TOTAL'!C1 -> 368
A5: ='APAGADOS RADIO'!I3 -> 44624 | B5: ='APAGADOS RADIO'!I2+D5 -> 9 | C5: ='APAGADOS FIBRA'!I2 -> 60 | D5: ='APAGADOS ANTENA'!I2 -> 1 | E5: =B5+C5 -> 69 | F5: ='RESUMEN TOTAL'!C1 -> 368
A6: ='APAGADOS RADIO'!J3 -> 44625 | B6: ='APAGADOS RADIO'!J2+D6 -> 8 | C6: ='APAGADOS FIBRA'!J2 -> 56 | D6: ='APAGADOS ANTENA'!F52 -> 0 | E6: =B6+C6 -> 64 | F6: ='RESUMEN TOTAL'!C1 -> 368
A7: ='APAGADOS RADIO'!K3 -> 44626 | B7: ='APAGADOS RADIO'!K2+D7 -> 7 | C7: ='APAGADOS FIBRA'!K2 -> 60 | D7: ='APAGADOS ANTENA'!K2 -> 1 | E7: =B7+C7 -> 67 | F7: ='RESUMEN TOTAL'!C1 -> 368
A8: ='APAGADOS RADIO'!L3 -> 44627 | B8: ='APAGADOS RADIO'!L2+D8 -> 9 | C8: ='APAGADOS FIBRA'!L2 -> 61 | D8: ='APAGADOS ANTENA'!L2 -> 1 | E8: =B8+C8 -> 70 | F8: ='RESUMEN TOTAL'!C1 -> 368
A9: ='APAGADOS RADIO'!M3 -> 44628 | B9: ='APAGADOS RADIO'!M2+D9 -> 10 | C9: ='APAGADOS FIBRA'!M2 -> 56 | D9: ='APAGADOS ANTENA'!M2 -> 2 | E9: =B9+C9 -> 66 | F9: ='RESUMEN TOTAL'!C1 -> 368
A10: ='APAGADOS RADIO'!N3 -> 44629 | B10: ='APAGADOS RADIO'!N2+D10 -> 15 | C10: ='APAGADOS FIBRA'!N2 -> 63 | D10: ='APAGADOS ANTENA'!N2 -> 6 | E10: =B10+C10 -> 78 | F10: ='RESUMEN TOTAL'!C1 -> 368
A11: ='APAGADOS RADIO'!O3 -> 44630 | B11: ='APAGADOS RADIO'!O2+D11 -> 9 | C11: ='APAGADOS FIBRA'!O2 -> 59 | D11: ='APAGADOS ANTENA'!O2 -> 2 | E11: =B11+C11 -> 68 | F11: ='RESUMEN TOTAL'!C1 -> 368
A12: ='APAGADOS RADIO'!P3 -> 44631 | B12: ='APAGADOS RADIO'!P2+D12 -> 16 | C12: ='APAGADOS FIBRA'!P2 -> 42 | D12: ='APAGADOS ANTENA'!P2 -> 11 | E12: =B12+C12 -> 58 | F12: ='RESUMEN TOTAL'!C1 -> 368
A13: ='APAGADOS RADIO'!Q3 -> 44632 | B13: ='APAGADOS RADIO'!Q2+D13 -> 12 | C13: ='APAGADOS FIBRA'!Q2 -> 35 | D13: ='APAGADOS ANTENA'!Q2 -> 8 | E13: =B13+C13 -> 47 | F13: ='RESUMEN TOTAL'!C1 -> 368
A14: ='APAGADOS RADIO'!R3 -> 44633 | B14: ='APAGADOS RADIO'!R2+D14 -> 15 | C14: ='APAGADOS FIBRA'!R2 -> 37 | D14: ='APAGADOS ANTENA'!R2 -> 10 | E14: =B14+C14 -> 52 | F14: ='RESUMEN TOTAL'!C1 -> 368
A15: ='APAGADOS RADIO'!S3 -> 44634 | B15: ='APAGADOS RADIO'!S2+D15 -> 12 | C15: ='APAGADOS FIBRA'!S2 -> 46 | D15: ='APAGADOS ANTENA'!S2 -> 8 | E15: =B15+C15 -> 58 | F15: ='RESUMEN TOTAL'!C1 -> 368
A16: ='APAGADOS RADIO'!T3 -> 44635 | B16: ='APAGADOS RADIO'!T2+D16 -> 13 | C16: ='APAGADOS FIBRA'!T2 -> 35 | D16: ='APAGADOS ANTENA'!T2 -> 9 | E16: =B16+C16 -> 48 | F16: ='RESUMEN TOTAL'!C1 -> 368
A17: ='APAGADOS RADIO'!U3 -> 44636 | B17: ='APAGADOS RADIO'!U2+D17 -> 15 | C17: ='APAGADOS FIBRA'!U2 -> 49 | D17: ='APAGADOS ANTENA'!U2 -> 11 | E17: =B17+C17 -> 64 | F17: ='RESUMEN TOTAL'!C1 -> 368
A18: ='APAGADOS RADIO'!V3 -> 44637 | B18: ='APAGADOS RADIO'!V2+D18 -> 15 | C18: ='APAGADOS FIBRA'!V2 -> 28 | D18: ='APAGADOS ANTENA'!V2 -> 12 | E18: =B18+C18 -> 43 | F18: ='RESUMEN TOTAL'!C1 -> 368
A19: ='APAGADOS RADIO'!W3 -> 44638 | B19: ='APAGADOS RADIO'!W2+D19 -> 15 | C19: ='APAGADOS FIBRA'!W2 -> 37 | D19: ='APAGADOS ANTENA'!W2 -> 12 | E19: =B19+C19 -> 52 | F19: ='RESUMEN TOTAL'!C1 -> 368
A20: ='APAGADOS RADIO'!X3 -> 44639 | B20: ='APAGADOS RADIO'!X2+D20 -> 22 | C20: ='APAGADOS FIBRA'!X2 -> 50 | D20: ='APAGADOS ANTENA'!X2 -> 16 | E20: =B20+C20 -> 72 | F20: ='RESUMEN TOTAL'!C1 -> 368
A21: ='APAGADOS RADIO'!Y3 -> 44640 | B21: ='APAGADOS RADIO'!Y2+D21 -> 16 | C21: ='APAGADOS FIBRA'!Y2 -> 36 | D21: ='APAGADOS ANTENA'!Y2 -> 13 | E21: =B21+C21 -> 52 | F21: ='RESUMEN TOTAL'!C1 -> 368
A22: ='APAGADOS RADIO'!Z3 -> 44641 | B22: ='APAGADOS RADIO'!Z2+D22 -> 16 | C22: ='APAGADOS FIBRA'!Z2 -> 39 | D22: ='APAGADOS ANTENA'!Z2 -> 13 | E22: =B22+C22 -> 55 | F22: ='RESUMEN TOTAL'!C1 -> 368
A23: ='APAGADOS RADIO'!AA3 -> 44642 | B23: ='APAGADOS RADIO'!AA2+D23 -> 13 | C23: ='APAGADOS FIBRA'!AA2 -> 55 | D23: ='APAGADOS ANTENA'!AA2 -> 10 | E23: =B23+C23 -> 68 | F23: ='RESUMEN TOTAL'!C1 -> 368
A24: ='APAGADOS RADIO'!AB3 -> 44643 | B24: ='APAGADOS RADIO'!AB2+D24 -> 4 | C24: ='APAGADOS FIBRA'!AB2 -> 28 | D24: ='APAGADOS ANTENA'!AB2 -> 2 | E24: =B24+C24 -> 32 | F24: ='RESUMEN TOTAL'!C1 -> 368
A25: ='APAGADOS RADIO'!AC3 -> 44644 | B25: ='APAGADOS RADIO'!AC2+D25 -> 14 | C25: ='APAGADOS FIBRA'!AC2 -> 70 | D25: ='APAGADOS ANTENA'!AC2 -> 7 | E25: =B25+C25 -> 84 | F25: ='RESUMEN TOTAL'!C1 -> 368
A26: ='APAGADOS RADIO'!AD3 -> 44645 | B26: ='APAGADOS RADIO'!AD2+D26 -> 9 | C26: ='APAGADOS FIBRA'!AD2 -> 43 | D26: ='APAGADOS ANTENA'!AD2 -> 4 | E26: =B26+C26 -> 52 | F26: ='RESUMEN TOTAL'!C1 -> 368
A27: ='APAGADOS RADIO'!AE3 -> 44646 | F27: ='RESUMEN TOTAL'!C1 -> 368
A28: ='APAGADOS RADIO'!AF3 -> 44647 | F28: ='RESUMEN TOTAL'!C1 -> 368
A29: ='APAGADOS RADIO'!AG3 -> 44648 | F29: ='RESUMEN TOTAL'!C1 -> 368
A30: ='APAGADOS RADIO'!AH3 -> 44649 | F30: ='RESUMEN TOTAL'!C1 -> 368
A31: ='APAGADOS RADIO'!AI3 -> 44650 | F31: ='RESUMEN TOTAL'!C1 -> 368
A32: ='APAGADOS RADIO'!AJ3 -> 44651 | F32: ='RESUMEN TOTAL'!C1 -> 368
