Workbook
Name _25_de_agosto: 'RESUMEN TOTAL'!$A$4:$D$386
Name _25_de_agosto_3: 'RESUMEN TOTAL'!$A$4:$D$398
Name BONOMOcam: Hoja1!$B$2
Name CANTIDAD_DE_CAMARAS: 'RESUMEN TOTAL'!$B$1
Name COSEIDIcam: Hoja1!$B$4

Sheet RESUMEN TOTAL
A1: CANTIDAD DE CAMARAS | B1: =COUNTA(B5:B622) -> 534 | D1: PORCIENTO DE CAIDAS | L1: =(L3)/(L2+L3) -> 0.18913858 | M1: =(M3)/(M2+M3) -> 0.18726592 | N1: =(N3)/(N2+N3) -> 0.17041199 | O1: =(O3)/(O2+O3) -> 0.16104869 | P1: =(P3)/(P2+P3) -> 0.16479401 | Q1: =(Q3)/(Q2+Q3) -> 0.16479401 | R1: =(R3)/(R2+R3) -> 0.15730337 | S1: =(S3)/(S2+S3) -> 0.15917603 | ... X1: =(X3)/(X2+X3) -> 0.15168539 | Z1: =(Z3)/(Z2+Z3) -> 0.16104869 | AA1: =(AA3)/(AA2+AA3) -> 0.14044944 | AB1: =(AB3)/(AB2+AB3) -> 0.16479401 | AC1: =(AC3)/(AC2+AC3) -> 0.15168539 | AD1: =(AD3)/(AD2+AD3) -> 0.16853933 | AE1: =(AE3)/(AE2+AE3) -> 0.15543071 | AF1: =(AF3)/(AF2+AF3) -> 0.15917603 | AG1: =(AG3)/(AG2+AG3) -> 0.15917603 | ... AP1: =(AP3)/(AP2+AP3) -> 0
D2: FUNCIONAN | L2: =B1-L3 -> 433 | M2: =CANTIDAD_DE_CAMARAS-M3 -> 434 | N2: =CANTIDAD_DE_CAMARAS-N3 -> 443 | O2: =CANTIDAD_DE_CAMARAS-O3 -> 448 | P2: =CANTIDAD_DE_CAMARAS-P3 -> 446 | Q2: =CANTIDAD_DE_CAMARAS-Q3 -> 446 | R2: =CANTIDAD_DE_CAMARAS-R3 -> 450 | S2: =CANTIDAD_DE_CAMARAS-S3 -> 449 | T2: =CANTIDAD_DE_CAMARAS-T3 -> 459 | ... AP2: =CANTIDAD_DE_CAMARAS-AP3 -> 534
D3: CAIDAS | L3: =COUNTIF(L4:L622, "apagado") -> 101 | M3: =COUNTIF(M4:M622, "apagado") -> 100 | N3: =COUNTIF(N4:N622, "apagado") -> 91 | O3: =COUNTIF(O4:O622, "apagado") -> 86 | P3: =COUNTIF(P4:P622, "apagado") -> 88 | Q3: =COUNTIF(Q4:Q622, "apagado") -> 88 | R3: =COUNTIF(R4:R622, "apagado") -> 84 | S3: =COUNTIF(S4:S622, "apagado") -> 85 | ... W3: =COUNTIF(W4:W622, "apagado") -> 72 | X3: =COUNTIF(X4:X522, "apagado") -> 81 | Y3: =COUNTIF(Y4:Y522, "apagado") -> 71 | Z3: =COUNTIF(Z4:Z622, "apagado") -> 86 | AA3: =COUNTIF(AA4:AA622, "apagado") -> 75 | AB3: =COUNTIF(AB4:AB622, "apagado") -> 88 | AC3: =COUNTIF(AC4:AC622, "apagado") -> 81 | AD3: =COUNTIF(AD4:AD622, "apagado") -> 90 | AE3: =COUNTIF(AE4:AE622, "apagado") -> 83 | AF3: =COUNTIF(AF4:AF622, "apagado") -> 85 | AG3: =COUNTIF(AG4:AG622, "apagado") -> 85 | ... AP3: =COUNTIF(AP4:AP622, "apagado") -> 0
A4: Barrio | B4: [Denominacion] | C4: [Empresa Mantenimiento] | D4: [Ubicacion] | E4: [Tipo de Camara] | F4: [Tipo de Conexion] | G4: Destino | I4: DIAS FUNCIONANDO | J4: DIAS CAIDA | K4: EFECTIVIDAD | L4: 45292 | M4: 45293 | N4: 45294 | O4: 45295 | P4: 45296 | Q4: 45297 | R4: 45298 | S4: 45299 | T4: 45300 | U4: 45301 | V4: 45302 | W4: 45303 | X4: 45304 | Y4: 45305 | Z4: 45306 | AA4: 45307 | AB4: 45308 | AC4: 45309 | AD4: 45310 | AE4: 45311 | AF4: 45312 | AG4: 45313 | AH4: 45314 | AI4: 45315 | AJ4: 45316 | AK4: 45317 | AL4: 45318 | AM4: 45319 | AN4: 45320 | AO4: 45321 | AP4: 45322
A5: PARADAS SEGURAS | B5: 11 | C5: IPCOMS | D5: THEVENET Y BS. AS. SUR | E5: GFIJA | F5: GPON | I5: =COUNTIF(L5:AM5,"") -> 28 | J5: =COUNTIF(L5:AM5,"APAGADO") -> 0 | K5: =(I5)/(J5+I5) -> 1
A6: PARADAS SEGURAS | B6: 12 | C6: IPCOMS | D6: THEVENET E ISLAS ORCADAS NORTE | E6: GFIJA | F6: GPON | H6: 10.20.40.139 | I6: =COUNTIF(L6:AM6,"") -> 2 | J6: =COUNTIF(L6:AM6,"APAGADO") -> 26 | K6: =(I6)/(J6+I6) -> 0.071428571 | L6: APAGADO | M6: APAGADO | N6: APAGADO | O6: APAGADO | P6: APAGADO | Q6: APAGADO | R6: APAGADO | S6: APAGADO | T6: APAGADO | U6: APAGADO | V6: APAGADO | W6: APAGADO | X6: APAGADO | Y6: APAGADO | Z6: APAGADO | AA6: APAGADO | AB6: APAGADO | AC6: APAGADO | AD6: APAGADO | AE6: APAGADO | AF6: APAGADO | AG6: APAGADO | AH6: APAGADO | AI6: APAGADO | AJ6: APAGADO | AK6: APAGADO
A7: PARADAS SEGURAS | B7: 13 | C7: IPCOMS | D7: THEVENET Y GRANADEROS NORTE | E7: GFIJA | F7: GPON | H7: 10.20.40.140 | I7: =COUNTIF(L7:AM7,"") -> 2 | J7: =COUNTIF(L7:AM7,"APAGADO") -> 26 | K7: =(I7)/(J7+I7) -> 0.071428571 | L7: APAGADO | M7: APAGADO | N7: APAGADO | O7: APAGADO | P7: APAGADO | Q7: APAGADO | R7: APAGADO | S7: APAGADO | T7: APAGADO | U7: APAGADO | V7: APAGADO | W7: APAGADO | X7: APAGADO | Y7: APAGADO | Z7: APAGADO | AA7: APAGADO | AB7: APAGADO | AC7: APAGADO | AD7: APAGADO | AE7: APAGADO | AF7: APAGADO | AG7: APAGADO | AH7: APAGADO | AI7: APAGADO | AJ7: APAGADO | AK7: APAGADO
A8: PARADAS SEGURAS | B8: 14 | C8: IPCOMS | D8: THEVENET Y BERUTI NORTE | E8: GFIJA | F8: GPON | H8: 10:20:40:134 | I8: =COUNTIF(L8:AM8,"") -> 27 | J8: =COUNTIF(L8:AM8,"APAGADO") -> 1 | K8: =(I8)/(J8+I8) -> 0.96428571 | AD8: APAGADO
A9: PARADAS SEGURAS | B9: 15 | C9: IPCOMS | D9: THEVENET Y BERUTI SUR | E9: GFIJA | F9: GPON | H9: 10.20.40.135 | I9: =COUNTIF(L9:AM9,"") -> 22 | J9: =COUNTIF(L9:AM9,"APAGADO") -> 6 | K9: =(I9)/(J9+I9) -> 0.78571429 | L9: APAGADO | M9: APAGADO | N9: APAGADO | O9: APAGADO | P9: APAGADO | Q9: APAGADO
A10: PARADAS SEGURAS | B10: 16 | C10: IPCOMS | D10: THEVENET Y BRAILE NORTE | E10: GFIJA | F10: GPON | H10: 10.20.40.136 | I10: =COUNTIF(L10:AM10,"") -> 28 | J10: =COUNTIF(L10:AM10,"APAGADO") -> 0 | K10: =(I10)/(J10+I10) -> 1
A11: PARADAS SEGURAS | B11: 17 | C11: IPCOMS | D11: THEVENET Y ARENALES NORTE | E11: GFIJA | F11: GPON | H11: 10.20.40.132 | I11: =COUNTIF(L11:AM11,"") -> 22 | J11: =COUNTIF(L11:AM11,"APAGADO") -> 6 | K11: =(I11)/(J11+I11) -> 0.78571429 | L11: APAGADO | M11: APAGADO | N11: APAGADO | O11: APAGADO | P11: APAGADO | Q11: APAGADO
A12: PARADAS SEGURAS | B12: 18 | C12: IPCOMS | D12: THEVENET Y ARENALES SUR | E12: GFIJA | F12: GPON | H12: 10.20.40.133 | I12: =COUNTIF(L12:AM12,"") -> 28 | J12: =COUNTIF(L12:AM12,"APAGADO") -> 0 | K12: =(I12)/(J12+I12) -> 1
A13: PARADAS SEGURAS | B13: 19 | C13: IPCOMS | D13: THEVENET Y GORRITI NORTE | E13: GFIJA | F13: GPON | H13: 10.20.40.137 | I13: =COUNTIF(L13:AM13,"") -> 28 | J13: =COUNTIF(L13:AM13,"APAGADO") -> 0 | K13: =(I13)/(J13+I13) -> 1
A14: PARADAS SEGURAS | B14: 20 | C14: IPCOMS | D14: THEVENET Y GORRITI SUR | E14: GFIJA | F14: GPON | H14: 10.20.40.138 | I14: =COUNTIF(L14:AM14,"") -> 28 | J14: =COUNTIF(L14:AM14,"APAGADO") -> 0 | K14: =(I14)/(J14+I14) -> 1
A15: PARADAS SEGURAS | B15: 21 | C15: IPCOMS | D15: HUDSON Y CABILDO OESTE | E15: GFIJA | F15: GPON | H15: 10.20.40.105 | I15: =COUNTIF(L15:AM15,"") -> 28 | J15: =COUNTIF(L15:AM15,"APAGADO") -> 0 | K15: =(I15)/(J15+I15) -> 1
A16: PARADAS SEGURAS | B16: 22 | C16: IPCOMS | D16: HUDSON Y CABILDO ESTE | E16: GFIJA | F16: GPON | H16: 10.20.40.106 | I16: =COUNTIF(L16:AM16,"") -> 23 | J16: =COUNTIF(L16:AM16,"APAGADO") -> 5 | K16: =(I16)/(J16+I16) -> 0.82142857 | M16: APAGADO | N16: APAGADO | O16: APAGADO | P16: APAGADO | Q16: APAGADO
A17: PARADAS SEGURAS | B17: 23 | C17: IPCOMS | D17: HUDSON Y SAN NICOLAS OESTE | E17: GFIJA | F17: GPON | H17: 10.20.40.107 | I17: =COUNTIF(L17:AM17,"") -> 28 | J17: =COUNTIF(L17:AM17,"APAGADO") -> 0 | K17: =(I17)/(J17+I17) -> 1
A18: PARADAS SEGURAS | B18: 24 | C18: IPCOMS | D18: HUDSON Y ALDAO ESTE | E18: GFIJA | F18: GPON | H18: 10.20.40.118 | I18: =COUNTIF(L18:AM18,"") -> 28 | J18: =COUNTIF(L18:AM18,"APAGADO") -> 0 | K18: =(I18)/(J18+I18) -> 1
A19: PARADAS SEGURAS | B19: 25 | C19: IPCOMS | D19: HUDSON Y RIO JACHAL | E19: GFIJA | F19: GPON | H19: 10.20.40.119 | I19: =COUNTIF(L19:AM19,"") -> 28 | J19: =COUNTIF(L19:AM19,"APAGADO") -> 0 | K19: =(I19)/(J19+I19) -> 1
A20: PARADAS SEGURAS | B20: 26 | C20: IPCOMS | D20: HUDSON Y RIO COLORADO OESTE | E20: GFIJA | F20: GPON | H20: 10.20.40.108 | I20: =COUNTIF(L20:AM20,"") -> 28 | J20: =COUNTIF(L20:AM20,"APAGADO") -> 0 | K20: =(I20)/(J20+I20) -> 1
A21: PARADAS SEGURAS | B21: 27 | C21: IPCOMS | D21: HUDON Y 818 ESTE | E21: GFIJA | F21: GPON | H21: 10.20.40.109 | I21: =COUNTIF(L21:AM21,"") -> 2 | J21: =COUNTIF(L21:AM21,"APAGADO") -> 26 | K21: =(I21)/(J21+I21) -> 0.071428571 | L21: APAGADO | M21: APAGADO | N21: APAGADO | O21: APAGADO | P21: APAGADO | Q21: APAGADO | R21: APAGADO | S21: APAGADO | T21: APAGADO | U21: APAGADO | V21: APAGADO | W21: APAGADO | X21: APAGADO | Y21: APAGADO | Z21: APAGADO | AA21: APAGADO | AB21: APAGADO | AC21: APAGADO | AD21: APAGADO | AE21: APAGADO | AF21: APAGADO | AG21: APAGADO | AH21: APAGADO | AI21: APAGADO | AJ21: APAGADO | AK21: APAGADO
A22: PARADAS SEGURAS | B22: 28 | C22: IPCOMS | D22: HUDSON Y RIO TRAFUL OESTE | E22: GFIJA | F22: GPON | H22: 10.20.40.110 | I22: =COUNTIF(L22:AM22,"") -> 28 | J22: =COUNTIF(L22:AM22,"APAGADO") -> 0 | K22: =(I22)/(J22+I22) -> 1
A23: PARADAS SEGURAS | B23: 29 | C23: IPCOMS | D23: HUDSON Y ESTOMBA ESTE | E23: GFIJA | F23: GPON | H23: 10.20.40.111 | I23: =COUNTIF(L23:AM23,"") -> 19 | J23: =COUNTIF(L23:AM23,"APAGADO") -> 9 | K23: =(I23)/(J23+I23) -> 0.67857143 | AC23: APAGADO | AD23: APAGADO | AE23: APAGADO | AF23: APAGADO | AG23: APAGADO | AH23: APAGADO | AI23: APAGADO | AJ23: APAGADO | AK23: APAGADO
A24: PARADAS SEGURAS | B24: 30 | C24: IPCOMS | D24: HUDSON Y PICHEUTA OESTE | E24: GFIJA | F24: GPON | H24: 10.20.40.112 | I24: =COUNTIF(L24:AM24,"") -> 2 | J24: =COUNTIF(L24:AM24,"APAGADO") -> 26 | K24: =(I24)/(J24+I24) -> 0.071428571 | L24: APAGADO | M24: APAGADO | N24: APAGADO | O24: APAGADO | P24: APAGADO | Q24: APAGADO | R24: APAGADO | S24: APAGADO | T24: APAGADO | U24: APAGADO | V24: APAGADO | W24: APAGADO | X24: APAGADO | Y24: APAGADO | Z24: APAGADO | AA24: APAGADO | AB24: APAGADO | AC24: APAGADO | AD24: APAGADO | AE24: APAGADO | AF24: APAGADO | AG24: APAGADO | AH24: APAGADO | AI24: APAGADO | AJ24: APAGADO | AK24: APAGADO
A25: PARADAS SEGURAS | B25: 31 | C25: IPCOMS | D25: HUDSON Y 830 ESTE | E25: GFIJA | F25: GPON | H25: 10.20.40.113 | I25: =COUNTIF(L25:AM25,"") -> 28 | J25: =COUNTIF(L25:AM25,"APAGADO") -> 0 | K25: =(I25)/(J25+I25) -> 1
A26: PARADAS SEGURAS | B26: 11 I | C26: IPCOMS | D26: THEVENET Y BS. AS. SUR | E26: INTERCOMUNICADOR | F26: GPON | I26: =COUNTIF(L26:AM26,"") -> 28 | J26: =COUNTIF(L26:AM26,"APAGADO") -> 0 | K26: =(I26)/(J26+I26) -> 1
A27: PARADAS SEGURAS | B27: 12 I | C27: IPCOMS | D27: THEVENET E ISLAS ORCADAS NORTE | E27: INTERCOMUNICADOR | F27: GPON | H27: 10.20.40.87 | I27: =COUNTIF(L27:AM27,"") -> 3 | J27: =COUNTIF(L27:AM27,"APAGADO") -> 25 | K27: =(I27)/(J27+I27) -> 0.10714286 | L27: APAGADO | M27: APAGADO | N27: APAGADO | O27: APAGADO | P27: APAGADO | Q27: APAGADO | R27: APAGADO | S27: APAGADO | T27: APAGADO | U27: APAGADO | V27: APAGADO | W27: APAGADO | X27: APAGADO | Y27: APAGADO | Z27: APAGADO | AA27: APAGADO | AB27: APAGADO | AC27: APAGADO | AE27: APAGADO | AF27: APAGADO | AG27: APAGADO | AH27: APAGADO | AI27: APAGADO | AJ27: APAGADO | AK27: APAGADO
A28: PARADAS SEGURAS | B28: 13 I | C28: IPCOMS | D28: THEVENET Y GRANADEROS NORTE | E28: INTERCOMUNICADOR | F28: GPON | I28: =COUNTIF(L28:AM28,"") -> 27 | J28: =COUNTIF(L28:AM28,"APAGADO") -> 1 | K28: =(I28)/(J28+I28) -> 0.96428571 | AC28: APAGADO
A29: PARADAS SEGURAS | B29: 14 I | C29: IPCOMS | D29: THEVENET Y BERUTI NORTE | E29: INTERCOMUNICADOR | F29: GPON | H29: 10:20:40:82 | I29: =COUNTIF(L29:AM29,"") -> 28 | J29: =COUNTIF(L29:AM29,"APAGADO") -> 0 | K29: =(I29)/(J29+I29) -> 1
A30: PARADAS SEGURAS | B30: 15 I | C30: IPCOMS | D30: THEVENET Y BERUTI SUR | E30: INTERCOMUNICADOR | F30: GPON | H30: 10.20.40.83 | I30: =COUNTIF(L30:AM30,"") -> 22 | J30: =COUNTIF(L30:AM30,"APAGADO") -> 6 | K30: =(I30)/(J30+I30) -> 0.78571429 | L30: APAGADO | M30: APAGADO | N30: APAGADO | O30: APAGADO | P30: APAGADO | Q30: APAGADO
A31: PARADAS SEGURAS | B31: 16 I | C31: IPCOMS | D31: THEVENET Y BRAILE NORTE | E31: INTERCOMUNICADOR | F31: GPON | H31: 10.20.40.84 | I31: =COUNTIF(L31:AM31,"") -> 28 | J31: =COUNTIF(L31:AM31,"APAGADO") -> 0 | K31: =(I31)/(J31+I31) -> 1
A32: PARADAS SEGURAS | B32: 17 I | C32: IPCOMS | D32: THEVENET Y ARENALES NORTE | E32: INTERCOMUNICADOR | F32: GPON | H32: 10.20.40.80 | I32: =COUNTIF(L32:AM32,"") -> 22 | J32: =COUNTIF(L32:AM32,"APAGADO") -> 6 | K32: =(I32)/(J32+I32) -> 0.78571429 | L32: APAGADO | M32: APAGADO | N32: APAGADO | O32: APAGADO | P32: APAGADO | Q32: APAGADO
A33: PARADAS SEGURAS | B33: 18 I | C33: IPCOMS | D33: THEVENET Y ARENALES SUR | E33: INTERCOMUNICADOR | F33: GPON | H33: 10.20.40.81 | I33: =COUNTIF(L33:AM33,"") -> 28 | J33: =COUNTIF(L33:AM33,"APAGADO") -> 0 | K33: =(I33)/(J33+I33) -> 1
A34: PARADAS SEGURAS | B34: 19 I | C34: IPCOMS | D34: THEVENET Y GORRITI NORTE | E34: INTERCOMUNICADOR | F34: GPON | H34: 10.20.40.85 | I34: =COUNTIF(L34:AM34,"") -> 28 | J34: =COUNTIF(L34:AM34,"APAGADO") -> 0 | K34: =(I34)/(J34+I34) -> 1
A35: PARADAS SEGURAS | B35: 20 I | C35: IPCOMS | D35: THEVENET Y GORRITI SUR | E35: INTERCOMUNICADOR | F35: GPON | H35: 10.20.40.86 | I35: =COUNTIF(L35:AM35,"") -> 28 | J35: =COUNTIF(L35:AM35,"APAGADO") -> 0 | K35: =(I35)/(J35+I35) -> 1
A36: PARADAS SEGURAS | B36: 21 I | C36: IPCOMS | D36: HUDSON Y CABILDO OESTE | E36: INTERCOMUNICADOR | F36: GPON | H36: 10.20.40.53 | I36: =COUNTIF(L36:AM36,"") -> 28 | J36: =COUNTIF(L36:AM36,"APAGADO") -> 0 | K36: =(I36)/(J36+I36) -> 1
A37: PARADAS SEGURAS | B37: 22 I | C37: IPCOMS | D37: HUDSON Y CABILDO ESTE | E37: INTERCOMUNICADOR | F37: GPON | H37: 10.20.40.54 | I37: =COUNTIF(L37:AM37,"") -> 23 | J37: =COUNTIF(L37:AM37,"APAGADO") -> 5 | K37: =(I37)/(J37+I37) -> 0.82142857 | M37: APAGADO | N37: APAGADO | O37: APAGADO | P37: APAGADO | Q37: APAGADO
A38: PARADAS SEGURAS | B38: 23 I | C38: IPCOMS | D38: HUDSON Y SAN NICOLAS OESTE | E38: INTERCOMUNICADOR | F38: GPON | H38: 10.20.40.55 | I38: =COUNTIF(L38:AM38,"") -> 28 | J38: =COUNTIF(L38:AM38,"APAGADO") -> 0 | K38: =(I38)/(J38+I38) -> 1
A39: PARADAS SEGURAS | B39: 24 I | C39: IPCOMS | D39: HUDSON Y ALDAO ESTE | E39: INTERCOMUNICADOR | F39: GPON | H39: 10.20.40.56 | I39: =COUNTIF(L39:AM39,"") -> 28 | J39: =COUNTIF(L39:AM39,"APAGADO") -> 0 | K39: =(I39)/(J39+I39) -> 1
A40: PARADAS SEGURAS | B40: 25 I | C40: IPCOMS | D40: HUDSON Y RIO JACHAL | E40: INTERCOMUNICADOR | F40: GPON | H40: 10.20.40.57 | I40: =COUNTIF(L40:AM40,"") -> 28 | J40: =COUNTIF(L40:AM40,"APAGADO") -> 0 | K40: =(I40)/(J40+I40) -> 1
...

Sheet ESTADISTICA
A1: ='RESUMEN TOTAL'!A4 -> Barrio | B1: ='RESUMEN TOTAL'!B4 -> [Denominacion] | C1: ='RESUMEN TOTAL'!D4 -> [Ubicacion] | D1: ='RESUMEN TOTAL'!E4 -> [Tipo de Camara] | E1: ='RESUMEN TOTAL'!F4 -> [Tipo de Conexion] | F1: ='RESUMEN TOTAL'!L4 -> 45292 | G1: ='RESUMEN TOTAL'!M4 -> 45293 | H1: ='RESUMEN TOTAL'!N4 -> 45294 | I1: ='RESUMEN TOTAL'!O4 -> 45295 | J1: ='RESUMEN TOTAL'!P4 -> 45296 | K1: ='RESUMEN TOTAL'!Q4 -> 45297 | L1: ='RESUMEN TOTAL'!R4 -> 45298 | M1: ='RESUMEN TOTAL'!S4 -> 45299 | ... AI1: ='RESUMEN TOTAL'!AO4 -> 45321 | AJ1: ='RESUMEN TOTAL'!#REF! -> #REF!
A2: ='RESUMEN TOTAL'!A5 -> PARADAS SEGURAS | B2: ='RESUMEN TOTAL'!B5 -> 11 | C2: ='RESUMEN TOTAL'!D5 -> THEVENET Y BS. AS. SUR | D2: ='RESUMEN TOTAL'!E5 -> GFIJA | E2: ='RESUMEN TOTAL'!F5 -> GPON | F2: ='RESUMEN TOTAL'!L5 -> 0 | G2: ='RESUMEN TOTAL'!M5 -> 0 | H2: ='RESUMEN TOTAL'!N5 -> 0 | I2: ='RESUMEN TOTAL'!O5 -> 0 | J2: ='RESUMEN TOTAL'!P5 -> 0 | K2: ='RESUMEN TOTAL'!Q5 -> 0 | L2: ='RESUMEN TOTAL'!R5 -> 0 | M2: ='RESUMEN TOTAL'!S5 -> 0 | ... AI2: ='RESUMEN TOTAL'!AO5 -> 0 | AJ2: ='RESUMEN TOTAL'!#REF! -> #REF!
A3: ='RESUMEN TOTAL'!A6 -> PARADAS SEGURAS | B3: ='RESUMEN TOTAL'!B6 -> 12 | C3: ='RESUMEN TOTAL'!D6 -> THEVENET E ISLAS ORCADAS NORTE | D3: ='RESUMEN TOTAL'!E6 -> GFIJA | E3: ='RESUMEN TOTAL'!F6 -> GPON | F3: ='RESUMEN TOTAL'!L6 -> APAGADO | G3: ='RESUMEN TOTAL'!M6 -> APAGADO | H3: ='RESUMEN TOTAL'!N6 -> APAGADO | I3: ='RESUMEN TOTAL'!O6 -> APAGADO | J3: ='RESUMEN TOTAL'!P6 -> APAGADO | K3: ='RESUMEN TOTAL'!Q6 -> APAGADO | L3: ='RESUMEN TOTAL'!R6 -> APAGADO | M3: ='RESUMEN TOTAL'!S6 -> APAGADO | ... AI3: ='RESUMEN TOTAL'!AO6 -> 0 | AJ3: ='RESUMEN TOTAL'!#REF! -> #REF!
A4: ='RESUMEN TOTAL'!A7 -> PARADAS SEGURAS | B4: ='RESUMEN TOTAL'!B7 -> 13 | C4: ='RESUMEN TOTAL'!D7 -> THEVENET Y GRANADEROS NORTE | D4: ='RESUMEN TOTAL'!E7 -> GFIJA | E4: ='RESUMEN TOTAL'!F7 -> GPON | F4: ='RESUMEN TOTAL'!L7 -> APAGADO | G4: ='RESUMEN TOTAL'!M7 -> APAGADO | H4: ='RESUMEN TOTAL'!N7 -> APAGADO | I4: ='RESUMEN TOTAL'!O7 -> APAGADO | J4: ='RESUMEN TOTAL'!P7 -> APAGADO | K4: ='RESUMEN TOTAL'!Q7 -> APAGADO | L4: ='RESUMEN TOTAL'!R7 -> APAGADO | M4: ='RESUMEN TOTAL'!S7 -> APAGADO | ... AI4: ='RESUMEN TOTAL'!AO7 -> 0 | AJ4: ='RESUMEN TOTAL'!#REF! -> #REF!
A5: ='RESUMEN TOTAL'!A8 -> PARADAS SEGURAS | B5: ='RESUMEN TOTAL'!B8 -> 14 | C5: ='RESUMEN TOTAL'!D8 -> THEVENET Y BERUTI NORTE | D5: ='RESUMEN TOTAL'!E8 -> GFIJA | E5: ='RESUMEN TOTAL'!F8 -> GPON | F5: ='RESUMEN TOTAL'!L8 -> 0 | G5: ='RESUMEN TOTAL'!M8 -> 0 | H5: ='RESUMEN TOTAL'!N8 -> 0 | I5: ='RESUMEN TOTAL'!O8 -> 0 | J5: ='RESUMEN TOTAL'!P8 -> 0 | K5: ='RESUMEN TOTAL'!Q8 -> 0 | L5: ='RESUMEN TOTAL'!R8 -> 0 | M5: ='RESUMEN TOTAL'!S8 -> 0 | ... AI5: ='RESUMEN TOTAL'!AO8 -> 0 | AJ5: ='RESUMEN TOTAL'!#REF! -> #REF!
A6: ='RESUMEN TOTAL'!A9 -> PARADAS SEGURAS | B6: ='RESUMEN TOTAL'!B9 -> 15 | C6: ='RESUMEN TOTAL'!D9 -> THEVENET Y BERUTI SUR | D6: ='RESUMEN TOTAL'!E9 -> GFIJA | E6: ='RESUMEN TOTAL'!F9 -> GPON | F6: ='RESUMEN TOTAL'!L9 -> APAGADO | G6: ='RESUMEN TOTAL'!M9 -> APAGADO | H6: ='RESUMEN TOTAL'!N9 -> APAGADO | I6: ='RESUMEN TOTAL'!O9 -> APAGADO | J6: ='RESUMEN TOTAL'!P9 -> APAGADO | K6: ='RESUMEN TOTAL'!Q9 -> APAGADO | L6: ='RESUMEN TOTAL'!R9 -> 0 | M6: ='RESUMEN TOTAL'!S9 -> 0 | ... AI6: ='RESUMEN TOTAL'!AO9 -> 0 | AJ6: ='RESUMEN TOTAL'!#REF! -> #REF!
A7: ='RESUMEN TOTAL'!A10 -> PARADAS SEGURAS | B7: ='RESUMEN TOTAL'!B10 -> 16 | C7: ='RESUMEN TOTAL'!D10 -> THEVENET Y BRAILE NORTE | D7: ='RESUMEN TOTAL'!E10 -> GFIJA | E7: ='RESUMEN TOTAL'!F10 -> GPON | F7: ='RESUMEN TOTAL'!L10 -> 0 | G7: ='RESUMEN TOTAL'!M10 -> 0 | H7: ='RESUMEN TOTAL'!N10 -> 0 | I7: ='RESUMEN TOTAL'!O10 -> 0 | J7: ='RESUMEN TOTAL'!P10 -> 0 | K7: ='RESUMEN TOTAL'!Q10 -> 0 | L7: ='RESUMEN TOTAL'!R10 -> 0 | M7: ='RESUMEN TOTAL'!S10 -> 0 | ... AI7: ='RESUMEN TOTAL'!AO10 -> 0 | AJ7: ='RESUMEN TOTAL'!#REF! -> #REF!
A8: ='RESUMEN TOTAL'!A11 -> PARADAS SEGURAS | B8: ='RESUMEN TOTAL'!B11 -> 17 | C8: ='RESUMEN TOTAL'!D11 -> THEVENET Y ARENALES NORTE | D8: ='RESUMEN TOTAL'!E11 -> GFIJA | E8: ='RESUMEN TOTAL'!F11 -> GPON | F8: ='RESUMEN TOTAL'!L11 -> APAGADO | G8: ='RESUMEN TOTAL'!M11 -> APAGADO | H8: ='RESUMEN TOTAL'!N11 -> APAGADO | I8: ='RESUMEN TOTAL'!O11 -> APAGADO | J8: ='RESUMEN TOTAL'!P11 -> APAGADO | K8: ='RESUMEN TOTAL'!Q11 -> APAGADO | L8: ='RESUMEN TOTAL'!R11 -> 0 | M8: ='RESUMEN TOTAL'!S11 -> 0 | ... AI8: ='RESUMEN TOTAL'!AO11 -> 0 | AJ8: ='RESUMEN TOTAL'!#REF! -> #REF!
A9: ='RESUMEN TOTAL'!A12 -> PARADAS SEGURAS | B9: ='RESUMEN TOTAL'!B12 -> 18 | C9: ='RESUMEN TOTAL'!D12 -> THEVENET Y ARENALES SUR | D9: ='RESUMEN TOTAL'!E12 -> GFIJA | E9: ='RESUMEN TOTAL'!F12 -> GPON | F9: ='RESUMEN TOTAL'!L12 -> 0 | G9: ='RESUMEN TOTAL'!M12 -> 0 | H9: ='RESUMEN TOTAL'!N12 -> 0 | I9: ='RESUMEN TOTAL'!O12 -> 0 | J9: ='RESUMEN TOTAL'!P12 -> 0 | K9: ='RESUMEN TOTAL'!Q12 -> 0 | L9: ='RESUMEN TOTAL'!R12 -> 0 | M9: ='RESUMEN TOTAL'!S12 -> 0 | ... AI9: ='RESUMEN TOTAL'!AO12 -> 0 | AJ9: ='RESUMEN TOTAL'!#REF! -> #REF!
A10: ='RESUMEN TOTAL'!A13 -> PARADAS SEGURAS | B10: ='RESUMEN TOTAL'!B13 -> 19 | C10: ='RESUMEN TOTAL'!D13 -> THEVENET Y GORRITI NORTE | D10: ='RESUMEN TOTAL'!E13 -> GFIJA | E10: ='RESUMEN TOTAL'!F13 -> GPON | F10: ='RESUMEN TOTAL'!L13 -> 0 | G10: ='RESUMEN TOTAL'!M13 -> 0 | H10: ='RESUMEN TOTAL'!N13 -> 0 | I10: ='RESUMEN TOTAL'!O13 -> 0 | J10: ='RESUMEN TOTAL'!P13 -> 0 | K10: ='RESUMEN TOTAL'!Q13 -> 0 | L10: ='RESUMEN TOTAL'!R13 -> 0 | M10: ='RESUMEN TOTAL'!S13 -> 0 | ... AI10: ='RESUMEN TOTAL'!AO13 -> 0 | AJ10: ='RESUMEN TOTAL'!#REF! -> #REF!
A11: ='RESUMEN TOTAL'!A14 -> PARADAS SEGURAS | B11: ='RESUMEN TOTAL'!B14 -> 20 | C11: ='RESUMEN TOTAL'!D14 -> THEVENET Y GORRITI SUR | D11: ='RESUMEN TOTAL'!E14 -> GFIJA | E11: ='RESUMEN TOTAL'!F14 -> GPON | F11: ='RESUMEN TOTAL'!L14 -> 0 | G11: ='RESUMEN TOTAL'!M14 -> 0 | H11: ='RESUMEN TOTAL'!N14 -> 0 | I11: ='RESUMEN TOTAL'!O14 -> 0 | J11: ='RESUMEN TOTAL'!P14 -> 0 | K11: ='RESUMEN TOTAL'!Q14 -> 0 | L11: ='RESUMEN TOTAL'!R14 -> 0 | M11: ='RESUMEN TOTAL'!S14 -> 0 | ... AI11: ='RESUMEN TOTAL'!AO14 -> 0 | AJ11: ='RESUMEN TOTAL'!#REF! -> #REF!
A12: ='RESUMEN TOTAL'!A15 -> PARADAS SEGURAS | B12: ='RESUMEN TOTAL'!B15 -> 21 | C12: ='RESUMEN TOTAL'!D15 -> HUDSON Y CABILDO OESTE | D12: ='RESUMEN TOTAL'!E15 -> GFIJA | E12: ='RESUMEN TOTAL'!F15 -> GPON | F12: ='RESUMEN TOTAL'!L15 -> 0 | G12: ='RESUMEN TOTAL'!M15 -> 0 | H12: ='RESUMEN TOTAL'!N15 -> 0 | I12: ='RESUMEN TOTAL'!O15 -> 0 | J12: ='RESUMEN TOTAL'!P15 -> 0 | K12: ='RESUMEN TOTAL'!Q15 -> 0 | L12: ='RESUMEN TOTAL'!R15 -> 0 | M12: ='RESUMEN TOTAL'!S15 -> 0 | ... AI12: ='RESUMEN TOTAL'!AO15 -> 0 | AJ12: ='RESUMEN TOTAL'!#REF! -> #REF!
... A67: ='RESUMEN TOTAL'!A70 -> PARADAS SEGURAS | B67: ='RESUMEN TOTAL'!B70 -> 43 I | C67: ='RESUMEN TOTAL'!D70 -> Hudson y Manuel de Falla Este | D67: ='RESUMEN TOTAL'!E70 -> INTERCOMUNICADOR | E67: ='RESUMEN TOTAL'!F70 -> GPON | F67: ='RESUMEN TOTAL'!L70 -> 0 | G67: ='RESUMEN TOTAL'!M70 -> 0 | H67: ='RESUMEN TOTAL'!N70 -> 0 | I67: ='RESUMEN TOTAL'!O70 -> 0 | J67: ='RESUMEN TOTAL'!P70 -> 0 | K67: ='RESUMEN TOTAL'!Q70 -> 0 | L67: ='RESUMEN TOTAL'!R70 -> 0 | M67: ='RESUMEN TOTAL'!S70 -> 0 | ... AI67: ='RESUMEN TOTAL'!AO70 -> 0 | AJ67: ='RESUMEN TOTAL'!#REF! -> #REF!
A68: ='RESUMEN TOTAL'!A71 -> PARADAS SEGURAS | B68: ='RESUMEN TOTAL'!B71 -> 45 C | C68: ='RESUMEN TOTAL'!D71 -> Hudson y Benito Perez Galdos Este | D68: ='RESUMEN TOTAL'!E71 -> GFIJA | E68: ='RESUMEN TOTAL'!F71 -> GPON | F68: ='RESUMEN TOTAL'!L71 -> 0 | G68: ='RESUMEN TOTAL'!M71 -> 0 | H68: ='RESUMEN TOTAL'!N71 -> 0 | I68: ='RESUMEN TOTAL'!O71 -> 0 | J68: ='RESUMEN TOTAL'!P71 -> 0 | K68: ='RESUMEN TOTAL'!Q71 -> 0 | L68: ='RESUMEN TOTAL'!R71 -> 0 | M68: ='RESUMEN TOTAL'!S71 -> 0 | ... Z68: ='RESUMEN TOTAL'!AF71 -> 0 | AA68: ='RESUMEN TOTAL'!AG546 -> 0 | AB68: ='RESUMEN TOTAL'!AH71 -> 0 | AC68: ='RESUMEN TOTAL'!AI71 -> 0 | AD68: ='RESUMEN TOTAL'!AJ71 -> 0 | AE68: ='RESUMEN TOTAL'!AK71 -> 0 | AF68: ='RESUMEN TOTAL'!AL71 -> 0 | AG68: ='RESUMEN TOTAL'!AM71 -> 0 | AH68: ='RESUMEN TOTAL'!AN71 -> 0 | AI68: ='RESUMEN TOTAL'!AO71 -> 0 | AJ68: ='RESUMEN TOTAL'!#REF! -> #REF!
A69: ='RESUMEN TOTAL'!A72 -> PARADAS SEGURAS | B69: ='RESUMEN TOTAL'!B72 -> 45 I | C69: ='RESUMEN TOTAL'!D72 -> Hudson y Benito Perez Galdos Este | D69: ='RESUMEN TOTAL'!E72 -> INTERCOMUNICADOR | E69: ='RESUMEN TOTAL'!F72 -> GPON | F69: ='RESUMEN TOTAL'!L72 -> 0 | G69: ='RESUMEN TOTAL'!M72 -> 0 | H69: ='RESUMEN TOTAL'!N72 -> 0 | I69: ='RESUMEN TOTAL'!O72 -> 0 | J69: ='RESUMEN TOTAL'!P72 -> 0 | K69: ='RESUMEN TOTAL'!Q72 -> 0 | L69: ='RESUMEN TOTAL'!R72 -> 0 | M69: ='RESUMEN TOTAL'!S72 -> 0 | ... AI69: ='RESUMEN TOTAL'!AO72 -> 0 | AJ69: ='RESUMEN TOTAL'!#REF! -> #REF!
A70: ='RESUMEN TOTAL'!A73 -> PARADAS SEGURAS | B70: ='RESUMEN TOTAL'!B73 -> 46 C | C70: ='RESUMEN TOTAL'!D73 -> Hudson y Avenida Bosques Este | D70: ='RESUMEN TOTAL'!E73 -> GFIJA | E70: ='RESUMEN TOTAL'!F73 -> GPON | F70: ='RESUMEN TOTAL'!L73 -> 0 | G70: ='RESUMEN TOTAL'!M73 -> 0 | H70: ='RESUMEN TOTAL'!N73 -> 0 | I70: ='RESUMEN TOTAL'!O73 -> 0 | J70: ='RESUMEN TOTAL'!P73 -> 0 | K70: ='RESUMEN TOTAL'!Q73 -> 0 | L70: ='RESUMEN TOTAL'!R73 -> 0 | M70: ='RESUMEN TOTAL'!S73 -> 0 | ... AI70: ='RESUMEN TOTAL'!AO73 -> 0 | AJ70: ='RESUMEN TOTAL'!#REF! -> #REF!
A71: ='RESUMEN TOTAL'!A74 -> PARADAS SEGURAS | B71: ='RESUMEN TOTAL'!B74 -> 46 I | C71: ='RESUMEN TOTAL'!D74 -> Hudson y Avenida Bosques Este | D71: ='RESUMEN TOTAL'!E74 -> INTERCOMUNICADOR | E71: ='RESUMEN TOTAL'!F74 -> GPON | F71: ='RESUMEN TOTAL'!L74 -> 0 | G71: ='RESUMEN TOTAL'!M74 -> 0 | H71: ='RESUMEN TOTAL'!N74 -> 0 | I71: ='RESUMEN TOTAL'!O74 -> 0 | J71: ='RESUMEN TOTAL'!P74 -> 0 | K71: ='RESUMEN TOTAL'!Q74 -> 0 | L71: ='RESUMEN TOTAL'!R74 -> 0 | M71: ='RESUMEN TOTAL'!S74 -> 0 | ... AI71: ='RESUMEN TOTAL'!AO74 -> 0 | AJ71: ='RESUMEN TOTAL'!#REF! -> #REF!
A72: ='RESUMEN TOTAL'!A75 -> PARADAS SEGURAS | B72: ='RESUMEN TOTAL'!B75 -> 47 C | C72: ='RESUMEN TOTAL'!D75 -> Hudson y Avenida Bosques Oeste | D72: ='RESUMEN TOTAL'!E75 -> GFIJA | E72: ='RESUMEN TOTAL'!F75 -> GPON | F72: ='RESUMEN TOTAL'!L75 -> 0 | G72: ='RESUMEN TOTAL'!M75 -> 0 | H72: ='RESUMEN TOTAL'!N75 -> 0 | I72: ='RESUMEN TOTAL'!O75 -> 0 | J72: ='RESUMEN TOTAL'!P75 -> 0 | K72: ='RESUMEN TOTAL'!Q75 -> 0 | L72: ='RESUMEN TOTAL'!R75 -> 0 | M72: ='RESUMEN TOTAL'!S75 -> 0 | ... AI72: ='RESUMEN TOTAL'!AO75 -> 0 | AJ72: ='RESUMEN TOTAL'!#REF! -> #REF!
A73: ='RESUMEN TOTAL'!A76 -> PARADAS SEGURAS | B73: ='RESUMEN TOTAL'!B76 -> 47 I | C73: ='RESUMEN TOTAL'!D76 -> Hudson y Avenida Bosques Oeste | D73: ='RESUMEN TOTAL'!E76 -> INTERCOMUNICADOR | E73: ='RESUMEN TOTAL'!F76 -> GPON | F73: ='RESUMEN TOTAL'!L76 -> 0 | G73: ='RESUMEN TOTAL'!M76 -> 0 | H73: ='RESUMEN TOTAL'!N76 -> 0 | I73: ='RESUMEN TOTAL'!O76 -> 0 | J73: ='RESUMEN TOTAL'!P76 -> 0 | K73: ='RESUMEN TOTAL'!Q76 -> 0 | L73: ='RESUMEN TOTAL'!R76 -> 0 | M73: ='RESUMEN TOTAL'!S76 -> 0 | ... AI73: ='RESUMEN TOTAL'!AO76 -> 0 | AJ73: ='RESUMEN TOTAL'!#REF! -> #REF!
A74: ='RESUMEN TOTAL'!A77 -> PARADAS SEGURAS | B74: ='RESUMEN TOTAL'!B77 -> 64 C | C74: ='RESUMEN TOTAL'!D77 -> Lujan y Combate de los Pozos | D74: ='RESUMEN TOTAL'!E77 -> GFIJA | E74: ='RESUMEN TOTAL'!F77 -> GPON | F74: ='RESUMEN TOTAL'!L77 -> 0 | G74: ='RESUMEN TOTAL'!M77 -> 0 | H74: ='RESUMEN TOTAL'!N77 -> 0 | I74: ='RESUMEN TOTAL'!O77 -> 0 | J74: ='RESUMEN TOTAL'!P77 -> 0 | K74: ='RESUMEN TOTAL'!Q77 -> 0 | L74: ='RESUMEN TOTAL'!R77 -> 0 | M74: ='RESUMEN TOTAL'!S77 -> 0 | ... AI74: ='RESUMEN TOTAL'!AO77 -> 0 | AJ74: ='RESUMEN TOTAL'!#REF! -> #REF!
A75: ='RESUMEN TOTAL'!A78 -> PARADAS SEGURAS | B75: ='RESUMEN TOTAL'!B78 -> 64 I | C75: ='RESUMEN TOTAL'!D78 -> Lujan y Combate de los Pozos | D75: ='RESUMEN TOTAL'!E78 -> INTERCOMUNICADOR | E75: ='RESUMEN TOTAL'!F78 -> GPON | F75: ='RESUMEN TOTAL'!L78 -> 0 | G75: ='RESUMEN TOTAL'!M78 -> 0 | H75: ='RESUMEN TOTAL'!N78 -> 0 | I75: ='RESUMEN TOTAL'!O78 -> 0 | J75: ='RESUMEN TOTAL'!P78 -> 0 | K75: ='RESUMEN TOTAL'!Q78 -> 0 | L75: ='RESUMEN TOTAL'!R78 -> 0 | M75: ='RESUMEN TOTAL'!S78 -> 0 | ... AI75: ='RESUMEN TOTAL'!AO78 -> 0 | AJ75: ='RESUMEN TOTAL'!#REF! -> #REF!
A76: ='RESUMEN TOTAL'!A79 -> PARADAS SEGURAS | B76: ='RESUMEN TOTAL'!B79 -> 65 C | C76: ='RESUMEN TOTAL'!D79 -> Lujan y Combate de los Pozos | D76: ='RESUMEN TOTAL'!E79 -> GFIJA | E76: ='RESUMEN TOTAL'!F79 -> GPON | F76: ='RESUMEN TOTAL'!L79 -> 0 | G76: ='RESUMEN TOTAL'!M79 -> 0 | H76: ='RESUMEN TOTAL'!N79 -> 0 | I76: ='RESUMEN TOTAL'!O79 -> 0 | J76: ='RESUMEN TOTAL'!P79 -> 0 | K76: ='RESUMEN TOTAL'!Q79 -> 0 | L76: ='RESUMEN TOTAL'!R79 -> 0 | M76: ='RESUMEN TOTAL'!S79 -> 0 | ... AI76: ='RESUMEN TOTAL'!AO79 -> 0 | AJ76: ='RESUMEN TOTAL'!#REF! -> #REF!
A77: ='RESUMEN TOTAL'!A80 -> PARADAS SEGURAS | B77: ='RESUMEN TOTAL'!B80 -> 65 I | C77: ='RESUMEN TOTAL'!D80 -> Lujan y Combate de los Pozos | D77: ='RESUMEN TOTAL'!E80 -> INTERCOMUNICADOR | E77: ='RESUMEN TOTAL'!F80 -> GPON | F77: ='RESUMEN TOTAL'!L80 -> 0 | G77: ='RESUMEN TOTAL'!M80 -> 0 | H77: ='RESUMEN TOTAL'!N80 -> 0 | I77: ='RESUMEN TOTAL'!O80 -> 0 | J77: ='RESUMEN TOTAL'!P80 -> 0 | K77: ='RESUMEN TOTAL'!Q80 -> 0 | L77: ='RESUMEN TOTAL'!R80 -> 0 | M77: ='RESUMEN TOTAL'!S80 -> 0 | ... AI77: ='RESUMEN TOTAL'!AO80 -> 0 | AJ77: ='RESUMEN TOTAL'!#REF! -> #REF!
A78: ='RESUMEN TOTAL'!A81 -> PARADAS SEGURAS | B78: ='RESUMEN TOTAL'!B81 -> 67 C | C78: ='RESUMEN TOTAL'!D81 -> Lujan y 907 A | D78: ='RESUMEN TOTAL'!E81 -> GFIJA | E78: ='RESUMEN TOTAL'!F81 -> GPON | F78: ='RESUMEN TOTAL'!L81 -> 0 | G78: ='RESUMEN TOTAL'!M81 -> 0 | H78: ='RESUMEN TOTAL'!N81 -> 0 | I78: ='RESUMEN TOTAL'!O81 -> 0 | J78: ='RESUMEN TOTAL'!P81 -> 0 | K78: ='RESUMEN TOTAL'!Q81 -> 0 | L78: ='RESUMEN TOTAL'!R81 -> 0 | M78: ='RESUMEN TOTAL'!S81 -> 0 | ... AI78: ='RESUMEN TOTAL'!AO81 -> 0 | AJ78: ='RESUMEN TOTAL'!#REF! -> #REF!
A79: ='RESUMEN TOTAL'!A82 -> PARADAS SEGURAS | B79: ='RESUMEN TOTAL'!B82 -> 67 I | C79: ='RESUMEN TOTAL'!D82 -> Lujan y 907 A | D79: ='RESUMEN TOTAL'!E82 -> INTERCOMUNICADOR | E79: ='RESUMEN TOTAL'!F82 -> GPON | F79: ='RESUMEN TOTAL'!L82 -> 0 | G79: ='RESUMEN TOTAL'!M82 -> 0 | H79: ='RESUMEN TOTAL'!N82 -> 0 | I79: ='RESUMEN TOTAL'!O82 -> 0 | J79: ='RESUMEN TOTAL'!P82 -> 0 | K79: ='RESUMEN TOTAL'!Q82 -> 0 | L79: ='RESUMEN TOTAL'!R82 -> 0 | M79: ='RESUMEN TOTAL'!S82 -> 0 | ... AI79: ='RESUMEN TOTAL'!AO82 -> 0 | AJ79: ='RESUMEN TOTAL'!#REF! -> #REF!
A80: ='RESUMEN TOTAL'!A83 -> ALTAMIRA | B80: ='RESUMEN TOTAL'!B83 -> ALT 03 | C80: ='RESUMEN TOTAL'!D83 -> Bombero Galarza y Necochea | D80: ='RESUMEN TOTAL'!E83 -> Domo | E80: ='RESUMEN TOTAL'!F83 -> Fibra Optica | F80: ='RESUMEN TOTAL'!L83 -> 0 | G80: ='RESUMEN TOTAL'!M83 -> 0 | H80: ='RESUMEN TOTAL'!N83 -> 0 | I80: ='RESUMEN TOTAL'!O83 -> 0 | J80: ='RESUMEN TOTAL'!P83 -> 0 | K80: ='RESUMEN TOTAL'!Q83 -> 0 | L80: ='RESUMEN TOTAL'!R83 -> 0 | M80: ='RESUMEN TOTAL'!S83 -> 0 | ... AI80: ='RESUMEN TOTAL'!AO83 -> 0 | AJ80: ='RESUMEN TOTAL'!#REF! -> #REF!
... A121: ='RESUMEN TOTAL'!A124 -> CENTRO | B121: ='RESUMEN TOTAL'!B124 -> CEN 79 | C121: ='RESUMEN TOTAL'!D124 -> Diag. Constituyente y Brown | D121: ='RESUMEN TOTAL'!E124 -> Fija | E121: ='RESUMEN TOTAL'!F124 -> Fibra Optica | F121: ='RESUMEN TOTAL'!L124 -> 0 | G121: ='RESUMEN TOTAL'!M124 -> 0 | H121: ='RESUMEN TOTAL'!N124 -> 0 | I121: ='RESUMEN TOTAL'!O124 -> 0 | J121: ='RESUMEN TOTAL'!P124 -> 0 | K121: ='RESUMEN TOTAL'!Q124 -> 0 | L121: ='RESUMEN TOTAL'!R124 -> 0 | M121: ='RESUMEN TOTAL'!S124 -> 0 | ... AI121: ='RESUMEN TOTAL'!AO124 -> 0 | AJ121: ='RESUMEN TOTAL'!#REF! -> #REF!
A122: ='RESUMEN TOTAL'!A126 -> CENTRO | B122: ='RESUMEN TOTAL'!B126 -> CEN 81 | C122: ='RESUMEN TOTAL'!D126 -> Alberdi y A.del Valle | D122: ='RESUMEN TOTAL'!E126 -> Fija | E122: ='RESUMEN TOTAL'!F126 -> Fibra Optica | F122: ='RESUMEN TOTAL'!L126 -> 0 | G122: ='RESUMEN TOTAL'!M126 -> 0 | H122: ='RESUMEN TOTAL'!N126 -> 0 | I122: ='RESUMEN TOTAL'!O126 -> 0 | J122: ='RESUMEN TOTAL'!P126 -> 0 | K122: ='RESUMEN TOTAL'!Q126 -> 0 | L122: ='RESUMEN TOTAL'!R126 -> 0 | M122: ='RESUMEN TOTAL'!S126 -> 0 | ... AI122: ='RESUMEN TOTAL'!AO126 -> 0 | AJ122: ='RESUMEN TOTAL'!#REF! -> #REF!
A123: ='RESUMEN TOTAL'!A127 -> CENTRO | B123: ='RESUMEN TOTAL'!B127 -> CEN 82 | C123: ='RESUMEN TOTAL'!D127 -> DORREGO Y BOUREL | D123: ='RESUMEN TOTAL'!E127 -> Domo | E123: ='RESUMEN TOTAL'!F127 -> Fibra Optica | F123: ='RESUMEN TOTAL'!L127 -> 0 | G123: ='RESUMEN TOTAL'!M127 -> 0 | H123: ='RESUMEN TOTAL'!N127 -> 0 | I123: ='RESUMEN TOTAL'!O127 -> 0 | J123: ='RESUMEN TOTAL'!P127 -> 0 | K123: ='RESUMEN TOTAL'!Q127 -> 0 | L123: ='RESUMEN TOTAL'!R127 -> 0 | M123: ='RESUMEN TOTAL'!S127 -> 0 | ... AI123: ='RESUMEN TOTAL'!AO127 -> 0 | AJ123: ='RESUMEN TOTAL'!#REF! -> #REF!
A124: ='RESUMEN TOTAL'!A128 -> CENTRO | B124: ='RESUMEN TOTAL'!B128 -> CEN 84 | C124: ='RESUMEN TOTAL'!D128 -> 25 DE MAYO Y MAIPU | D124: ='RESUMEN TOTAL'!E128 -> Fija | E124: ='RESUMEN TOTAL'!F128 -> Fibra Optica | F124: ='RESUMEN TOTAL'!L128 -> APAGADO | G124: ='RESUMEN TOTAL'!M128 -> APAGADO | H124: ='RESUMEN TOTAL'!N128 -> APAGADO | I124: ='RESUMEN TOTAL'!O128 -> APAGADO | J124: ='RESUMEN TOTAL'!P128 -> APAGADO | K124: ='RESUMEN TOTAL'!Q128 -> APAGADO | L124: ='RESUMEN TOTAL'!R128 -> APAGADO | M124: ='RESUMEN TOTAL'!S128 -> APAGADO | ... AI124: ='RESUMEN TOTAL'!AO128 -> 0 | AJ124: ='RESUMEN TOTAL'!#REF! -> #REF!
A125: ='RESUMEN TOTAL'!A129 -> CENTRO | B125: ='RESUMEN TOTAL'!B129 -> CEN 85 | C125: ='RESUMEN TOTAL'!D129 -> PTE PERON E/ PRINGLES Y BROWN | D125: ='RESUMEN TOTAL'!E129 -> Fija | E125: ='RESUMEN TOTAL'!F129 -> Fibra Optica | F125: ='RESUMEN TOTAL'!L129 -> 0 | G125: ='RESUMEN TOTAL'!M129 -> 0 | H125: ='RESUMEN TOTAL'!N129 -> 0 | I125: ='RESUMEN TOTAL'!O129 -> 0 | J125: ='RESUMEN TOTAL'!P129 -> 0 | K125: ='RESUMEN TOTAL'!Q129 -> 0 | L125: ='RESUMEN TOTAL'!R129 -> 0 | M125: ='RESUMEN TOTAL'!S129 -> 0 | ... AI125: ='RESUMEN TOTAL'!AO129 -> 0 | AJ125: ='RESUMEN TOTAL'!#REF! -> #REF!
A126: ='RESUMEN TOTAL'!A130 -> CENTRO | B126: ='RESUMEN TOTAL'!B130 -> CEN 86 | C126: ='RESUMEN TOTAL'!D130 -> Monteagudo y Bocuzzi | D126: ='RESUMEN TOTAL'!E130 -> Fija | E126: ='RESUMEN TOTAL'!F130 -> Fibra Optica | F126: ='RESUMEN TOTAL'!L130 -> 0 | G126: ='RESUMEN TOTAL'!M130 -> 0 | H126: ='RESUMEN TOTAL'!N130 -> 0 | I126: ='RESUMEN TOTAL'!O130 -> 0 | J126: ='RESUMEN TOTAL'!P130 -> 0 | K126: ='RESUMEN TOTAL'!Q130 -> 0 | L126: ='RESUMEN TOTAL'!R130 -> 0 | M126: ='RESUMEN TOTAL'!S130 -> 0 | ... AI126: ='RESUMEN TOTAL'!AO130 -> 0 | AJ126: ='RESUMEN TOTAL'!#REF! -> #REF!
A127: ='RESUMEN TOTAL'!A131 -> CENTRO | B127: ='RESUMEN TOTAL'!B131 -> CEN01 | C127: ='RESUMEN TOTAL'!D131 -> San Martin y 9 de Julio | D127: ='RESUMEN TOTAL'!E131 -> Fija | E127: ='RESUMEN TOTAL'!F131 -> Fibra Optica | F127: ='RESUMEN TOTAL'!L131 -> 0 | G127: ='RESUMEN TOTAL'!M131 -> 0 | H127: ='RESUMEN TOTAL'!N131 -> APAGADO | I127: ='RESUMEN TOTAL'!O131 -> APAGADO | J127: ='RESUMEN TOTAL'!P131 -> APAGADO | K127: ='RESUMEN TOTAL'!Q131 -> APAGADO | L127: ='RESUMEN TOTAL'!R131 -> APAGADO | M127: ='RESUMEN TOTAL'!S131 -> APAGADO | ... AI127: ='RESUMEN TOTAL'!AO131 -> 0 | AJ127: ='RESUMEN TOTAL'!#REF! -> #REF!
A128: ='RESUMEN TOTAL'!A132 -> CENTRO | B128: ='RESUMEN TOTAL'!B132 -> CEN02 | C128: ='RESUMEN TOTAL'!D132 -> San Martin y Almafuerte | D128: ='RESUMEN TOTAL'!E132 -> Fija | E128: ='RESUMEN TOTAL'!F132 -> Fibra Optica | F128: ='RESUMEN TOTAL'!L132 -> 0 | G128: ='RESUMEN TOTAL'!M132 -> 0 | H128: ='RESUMEN TOTAL'!N132 -> 0 | I128: ='RESUMEN TOTAL'!O132 -> 0 | J128: ='RESUMEN TOTAL'!P132 -> 0 | K128: ='RESUMEN TOTAL'!Q132 -> 0 | L128: ='RESUMEN TOTAL'!R132 -> 0 | M128: ='RESUMEN TOTAL'!S132 -> 0 | ... AI128: ='RESUMEN TOTAL'!AO132 -> 0 | AJ128: ='RESUMEN TOTAL'!#REF! -> #REF!
A129: ='RESUMEN TOTAL'!A133 -> CENTRO | B129: ='RESUMEN TOTAL'!B133 -> CEN03 | C129: ='RESUMEN TOTAL'!D133 -> San Martin y Sallares | D129: ='RESUMEN TOTAL'!E133 -> Domo | E129: ='RESUMEN TOTAL'!F133 -> Fibra Optica | F129: ='RESUMEN TOTAL'!L133 -> 0 | G129: ='RESUMEN TOTAL'!M133 -> 0 | H129: ='RESUMEN TOTAL'!N133 -> 0 | I129: ='RESUMEN TOTAL'!O133 -> 0 | J129: ='RESUMEN TOTAL'!P133 -> 0 | K129: ='RESUMEN TOTAL'!Q133 -> 0 | L129: ='RESUMEN TOTAL'!R133 -> 0 | M129: ='RESUMEN TOTAL'!S133 -> 0 | ... AI129: ='RESUMEN TOTAL'!AO133 -> 0 | AJ129: ='RESUMEN TOTAL'!#REF! -> #REF!
A130: ='RESUMEN TOTAL'!A134 -> CENTRO | B130: ='RESUMEN TOTAL'!B134 -> CEN04 | C130: ='RESUMEN TOTAL'!D134 -> San Martin y Contreras | D130: ='RESUMEN TOTAL'!E134 -> Domo | E130: ='RESUMEN TOTAL'!F134 -> Fibra Optica | F130: ='RESUMEN TOTAL'!L134 -> 0 | G130: ='RESUMEN TOTAL'!M134 -> 0 | H130: ='RESUMEN TOTAL'!N134 -> 0 | I130: ='RESUMEN TOTAL'!O134 -> 0 | J130: ='RESUMEN TOTAL'!P134 -> 0 | K130: ='RESUMEN TOTAL'!Q134 -> 0 | L130: ='RESUMEN TOTAL'!R134 -> 0 | M130: ='RESUMEN TOTAL'!S134 -> 0 | ... AI130: ='RESUMEN TOTAL'!AO134 -> 0 | AJ130: ='RESUMEN TOTAL'!#REF! -> #REF!
A131: ='RESUMEN TOTAL'!A135 -> CENTRO | B131: ='RESUMEN TOTAL'!B135 -> CEN06 | C131: ='RESUMEN TOTAL'!D135 -> Monteagudo y A.del Valle | D131: ='RESUMEN TOTAL'!E135 -> Fija | E131: ='RESUMEN TOTAL'!F135 -> Fibra Optica | F131: ='RESUMEN TOTAL'!L135 -> 0 | G131: ='RESUMEN TOTAL'!M135 -> 0 | H131: ='RESUMEN TOTAL'!N135 -> 0 | I131: ='RESUMEN TOTAL'!O135 -> 0 | J131: ='RESUMEN TOTAL'!P135 -> 0 | K131: ='RESUMEN TOTAL'!Q135 -> 0 | L131: ='RESUMEN TOTAL'!R135 -> 0 | M131: ='RESUMEN TOTAL'!S135 -> 0 | ... AI131: ='RESUMEN TOTAL'!AO135 -> 0 | AJ131: ='RESUMEN TOTAL'!#REF! -> #REF!
A132: ='RESUMEN TOTAL'!A136 -> CENTRO | B132: ='RESUMEN TOTAL'!B136 -> CEN07 | C132: ='RESUMEN TOTAL'!D136 -> San Martin y Guemes | D132: ='RESUMEN TOTAL'!E136 -> DOMO | E132: ='RESUMEN TOTAL'!F136 -> Fibra Optica | F132: ='RESUMEN TOTAL'!L136 -> APAGADO | G132: ='RESUMEN TOTAL'!M136 -> APAGADO | H132: ='RESUMEN TOTAL'!N136 -> 0 | I132: ='RESUMEN TOTAL'!O136 -> 0 | J132: ='RESUMEN TOTAL'!P136 -> 0 | K132: ='RESUMEN TOTAL'!Q136 -> 0 | L132: ='RESUMEN TOTAL'!R136 -> 0 | M132: ='RESUMEN TOTAL'!S136 -> 0 | ... AI132: ='RESUMEN TOTAL'!AO136 -> 0 | AJ132: ='RESUMEN TOTAL'!#REF! -> #REF!
A133: ='RESUMEN TOTAL'!A137 -> CENTRO | B133: ='RESUMEN TOTAL'!B137 -> CEN08 | C133: ='RESUMEN TOTAL'!D137 -> San Martin y Pte.Peron | D133: ='RESUMEN TOTAL'!E137 -> Domo | E133: ='RESUMEN TOTAL'!F137 -> Fibra Optica | F133: ='RESUMEN TOTAL'!L137 -> 0 | G133: ='RESUMEN TOTAL'!M137 -> 0 | H133: ='RESUMEN TOTAL'!N137 -> 0 | I133: ='RESUMEN TOTAL'!O137 -> 0 | J133: ='RESUMEN TOTAL'!P137 -> 0 | K133: ='RESUMEN TOTAL'!Q137 -> 0 | L133: ='RESUMEN TOTAL'!R137 -> 0 | M133: ='RESUMEN TOTAL'!S137 -> 0 | ... AI133: ='RESUMEN TOTAL'!AO137 -> 0 | AJ133: ='RESUMEN TOTAL'!#REF! -> #REF!
... A200: ='RESUMEN TOTAL'!A204 -> EL PARQUE | B200: ='RESUMEN TOTAL'!B204 -> EPQ 01 | C200: ='RESUMEN TOTAL'!D204 -> 1282 Y GRIERSON | D200: ='RESUMEN TOTAL'!E204 -> DOMO | E200: ='RESUMEN TOTAL'!F204 -> Fibra Optica | F200: ='RESUMEN TOTAL'!L204 -> 0 | G200: ='RESUMEN TOTAL'!M204 -> 0 | H200: ='RESUMEN TOTAL'!N204 -> 0 | I200: ='RESUMEN TOTAL'!O204 -> 0 | J200: ='RESUMEN TOTAL'!P204 -> 0 | K200: ='RESUMEN TOTAL'!Q204 -> 0 | L200: ='RESUMEN TOTAL'!R204 -> 0 | M200: ='RESUMEN TOTAL'!S204 -> 0 | ... AI200: ='RESUMEN TOTAL'!AO204 -> 0 | AJ200: ='RESUMEN TOTAL'!#REF! -> #REF!
...

Sheet APAGADOS
E1: APAGADOS | F1: =COUNTIF(F3:F403, "APAGADO") -> 75 | G1: =COUNTIF(G3:G403, "APAGADO") -> 72 | H1: =COUNTIF(H3:H503, "APAGADO") -> 82 | I1: =COUNTIF(I3:I403, "APAGADO") -> 62 | J1: =COUNTIF(J3:J403, "APAGADO") -> 64 | K1: =COUNTIF(K3:K403, "APAGADO") -> 64 | L1: =COUNTIF(L3:L403, "APAGADO") -> 57 | M1: =COUNTIF(M3:M403, "APAGADO") -> 58 | N1: =COUNTIF(N3:N403, "APAGADO") -> 51 | O1: =COUNTIF(O3:O403, "APAGADO") -> 53 | P1: =COUNTIF(P3:P403, "APAGADO") -> 47 | ... AD1: =COUNTIF(AD3:AD403, "APAGADO") -> 52 | AE1: =COUNTIF(AE3:AE503, "APAGADO") -> 61 | AF1: =COUNTIF(AF3:AF403, "APAGADO") -> 0 | AG1: =COUNTIF(AG3:AG403, "APAGADO") -> 0 | AH1: =COUNTIF(AH3:AH403, "APAGADO") -> 0 | AI1: =COUNTIF(AI3:AI403, "APAGADO") -> 0 | AJ1: =COUNTIF(AJ3:AJ403, "APAGADO") -> 0
A2: =ESTADISTICA!A1 -> Barrio | B2: =ESTADISTICA!B1 -> [Denominacion] | C2: =ESTADISTICA!C1 -> [Ubicacion] | D2: =ESTADISTICA!D1 -> [Tipo de Camara] | E2: =ESTADISTICA!E1 -> [Tipo de Conexion] | F2: =ESTADISTICA!F1 -> 45292 | G2: =ESTADISTICA!G1 -> 45293 | H2: =ESTADISTICA!H1 -> 45294 | ... AJ2: =ESTADISTICA!AJ1 -> #REF!
A3: =ESTADISTICA!A2 -> PARADAS SEGURAS | B3: =ESTADISTICA!B2 -> 11 | C3: =ESTADISTICA!C2 -> THEVENET Y BS. AS. SUR | D3: =ESTADISTICA!D2 -> GFIJA | E3: =ESTADISTICA!E2 -> GPON | F3: =ESTADISTICA!F2 -> 0 | G3: =ESTADISTICA!G2 -> 0 | H3: =ESTADISTICA!H2 -> 0 | ... AJ3: =ESTADISTICA!AJ2 -> #REF!
A4: =ESTADISTICA!A3 -> PARADAS SEGURAS | B4: =ESTADISTICA!B3 -> 12 | C4: =ESTADISTICA!C3 -> THEVENET E ISLAS ORCADAS NORTE | D4: =ESTADISTICA!D3 -> GFIJA | E4: =ESTADISTICA!E3 -> GPON | F4: =ESTADISTICA!F3 -> APAGADO | G4: =ESTADISTICA!G3 -> APAGADO | H4: =ESTADISTICA!H3 -> APAGADO | ... AJ4: =ESTADISTICA!AJ3 -> #REF!
A5: =ESTADISTICA!A4 -> PARADAS SEGURAS | B5: =ESTADISTICA!B4 -> 13 | C5: =ESTADISTICA!C4 -> THEVENET Y GRANADEROS NORTE | D5: =ESTADISTICA!D4 -> GFIJA | E5: =ESTADISTICA!E4 -> GPON | F5: =ESTADISTICA!F4 -> APAGADO | G5: =ESTADISTICA!G4 -> APAGADO | H5: =ESTADISTICA!H4 -> APAGADO | ... AJ5: =ESTADISTICA!AJ4 -> #REF!
A6: =ESTADISTICA!A5 -> PARADAS SEGURAS | B6: =ESTADISTICA!B5 -> 14 | C6: =ESTADISTICA!C5 -> THEVENET Y BERUTI NORTE | D6: =ESTADISTICA!D5 -> GFIJA | E6: =ESTADISTICA!E5 -> GPON | F6: =ESTADISTICA!F5 -> 0 | G6: =ESTADISTICA!G5 -> 0 | H6: =ESTADISTICA!H5 -> 0 | ... AJ6: =ESTADISTICA!AJ5 -> #REF!
A7: =ESTADISTICA!A6 -> PARADAS SEGURAS | B7: =ESTADISTICA!B6 -> 15 | C7: =ESTADISTICA!C6 -> THEVENET Y BERUTI SUR | D7: =ESTADISTICA!D6 -> GFIJA | E7: =ESTADISTICA!E6 -> GPON | F7: =ESTADISTICA!F6 -> APAGADO | G7: =ESTADISTICA!G6 -> APAGADO | H7: =ESTADISTICA!H6 -> APAGADO | ... AJ7: =ESTADISTICA!AJ6 -> #REF!
A8: =ESTADISTICA!A7 -> PARADAS SEGURAS | B8: =ESTADISTICA!B7 -> 16 | C8: =ESTADISTICA!C7 -> THEVENET Y BRAILE NORTE | D8: =ESTADISTICA!D7 -> GFIJA | E8: =ESTADISTICA!E7 -> GPON | F8: =ESTADISTICA!F7 -> 0 | G8: =ESTADISTICA!G7 -> 0 | H8: =ESTADISTICA!H7 -> 0 | ... AJ8: =ESTADISTICA!AJ7 -> #REF!
A9: =ESTADISTICA!A8 -> PARADAS SEGURAS | B9: =ESTADISTICA!B8 -> 17 | C9: =ESTADISTICA!C8 -> THEVENET Y ARENALES NORTE | D9: =ESTADISTICA!D8 -> GFIJA | E9: =ESTADISTICA!E8 -> GPON | F9: =ESTADISTICA!F8 -> APAGADO | G9: =ESTADISTICA!G8 -> APAGADO | H9: =ESTADISTICA!H8 -> APAGADO | ... AJ9: =ESTADISTICA!AJ8 -> #REF!
A10: =ESTADISTICA!A9 -> PARADAS SEGURAS | B10: =ESTADISTICA!B9 -> 18 | C10: =ESTADISTICA!C9 -> THEVENET Y ARENALES SUR | D10: =ESTADISTICA!D9 -> GFIJA | E10: =ESTADISTICA!E9 -> GPON | F10: =ESTADISTICA!F9 -> 0 | G10: =ESTADISTICA!G9 -> 0 | H10: =ESTADISTICA!H9 -> 0 | ... AJ10: =ESTADISTICA!AJ9 -> #REF!
A11: =ESTADISTICA!A10 -> PARADAS SEGURAS | B11: =ESTADISTICA!B10 -> 19 | C11: =ESTADISTICA!C10 -> THEVENET Y GORRITI NORTE | D11: =ESTADISTICA!D10 -> GFIJA | E11: =ESTADISTICA!E10 -> GPON | F11: =ESTADISTICA!F10 -> 0 | G11: =ESTADISTICA!G10 -> 0 | H11: =ESTADISTICA!H10 -> 0 | ... AJ11: =ESTADISTICA!AJ10 -> #REF!
A12: =ESTADISTICA!A11 -> PARADAS SEGURAS | B12: =ESTADISTICA!B11 -> 20 | C12: =ESTADISTICA!C11 -> THEVENET Y GORRITI SUR | D12: =ESTADISTICA!D11 -> GFIJA | E12: =ESTADISTICA!E11 -> GPON | F12: =ESTADISTICA!F11 -> 0 | G12: =ESTADISTICA!G11 -> 0 | H12: =ESTADISTICA!H11 -> 0 | ... AJ12: =ESTADISTICA!AJ11 -> #REF!
A13: =ESTADISTICA!A12 -> PARADAS SEGURAS | B13: =ESTADISTICA!B12 -> 21 | C13: =ESTADISTICA!C12 -> HUDSON Y CABILDO OESTE | D13: =ESTADISTICA!D12 -> GFIJA | E13: =ESTADISTICA!E12 -> GPON | F13: =ESTADISTICA!F12 -> 0 | G13: =ESTADISTICA!G12 -> 0 | H13: =ESTADISTICA!H12 -> 0 | ... AJ13: =ESTADISTICA!AJ12 -> #REF!
... A207: =ESTADISTICA!A206 -> LA ESMERALDA | B207: =ESTADISTICA!B206 -> ESM 15 | C207: =ESTADISTICA!C206 -> Basualdo y Lieja | D207: =ESTADISTICA!D206 -> Fija | E207: =ESTADISTICA!E206 -> Fibra Optica | F207: =ESTADISTICA!F206 -> 0 | G207: =ESTADISTICA!G206 -> 0 | H207: =ESTADISTICA!H206 -> 0 | ... AJ207: =ESTADISTICA!AJ206 -> #REF!
A208: =ESTADISTICA!A208 -> LA ESMERALDA | B208: =ESTADISTICA!B208 -> ESM01 | C208: =ESTADISTICA!C208 -> Cabello y Brasil | D208: =ESTADISTICA!D208 -> Domo | E208: =ESTADISTICA!E208 -> Radio | F208: =ESTADISTICA!F208 -> 0 | G208: =ESTADISTICA!G208 -> 0 | H208: =ESTADISTICA!H208 -> 0 | ... AJ208: =ESTADISTICA!AJ208 -> #REF!
A209: =ESTADISTICA!A209 -> SAN JORGE | B209: =ESTADISTICA!B209 -> ESM02 | C209: =ESTADISTICA!C209 -> Novak y Cabello | D209: =ESTADISTICA!D209 -> Domo | E209: =ESTADISTICA!E209 -> PTO A FO | F209: =ESTADISTICA!F209 -> 0 | G209: =ESTADISTICA!G209 -> 0 | H209: =ESTADISTICA!H209 -> 0 | ... AJ209: =ESTADISTICA!AJ209 -> #REF!
A210: =ESTADISTICA!A210 -> 0 | B210: =ESTADISTICA!B210 -> ESM03 | C210: =ESTADISTICA!C210 -> Novak y Humahuaca | D210: =ESTADISTICA!D210 -> DOMO | E210: =ESTADISTICA!E210 -> PTO A FO | F210: =ESTADISTICA!F210 -> 0 | G210: =ESTADISTICA!G210 -> 0 | H210: =ESTADISTICA!H210 -> 0 | ... AJ210: =ESTADISTICA!AJ210 -> #REF!
A211: =ESTADISTICA!A211 -> LA ESMERALDA | B211: =ESTADISTICA!B211 -> ESM04 | C211: =ESTADISTICA!C211 -> Basualdo y Bengochea | D211: =ESTADISTICA!D211 -> Domo | E211: =ESTADISTICA!E211 -> Fibra Optica | F211: =ESTADISTICA!F211 -> APAGADO | G211: =ESTADISTICA!G211 -> APAGADO | H211: =ESTADISTICA!H211 -> APAGADO | ... AJ211: =ESTADISTICA!AJ211 -> #REF!
A212: =ESTADISTICA!A212 -> LA ESMERALDA | B212: =ESTADISTICA!B212 -> ESM05 | C212: =ESTADISTICA!C212 -> Aniceto Diaz y Villar | D212: =ESTADISTICA!D212 -> Domo | E212: =ESTADISTICA!E212 -> Fibra Optica | F212: =ESTADISTICA!F212 -> APAGADO | G212: =ESTADISTICA!G212 -> APAGADO | H212: =ESTADISTICA!H212 -> APAGADO | ... AJ212: =ESTADISTICA!AJ212 -> #REF!
A213: =ESTADISTICA!A213 -> LA ESMERALDA | B213: =ESTADISTICA!B213 -> ESM06 | C213: =ESTADISTICA!C213 -> Roselli y Cabello | D213: =ESTADISTICA!D213 -> Domo | E213: =ESTADISTICA!E213 -> Radio | F213: =ESTADISTICA!F213 -> 0 | G213: =ESTADISTICA!G213 -> 0 | H213: =ESTADISTICA!H213 -> 0 | ... AJ213: =ESTADISTICA!AJ213 -> #REF!
A214: =ESTADISTICA!A214 -> LA ESMERALDA | B214: =ESTADISTICA!B214 -> ESM07 | C214: =ESTADISTICA!C214 -> AV. NOVAK Y SERRANO | D214: =ESTADISTICA!D214 -> DOMO | E214: =ESTADISTICA!E214 -> PTO A FO | F214: =ESTADISTICA!F214 -> 0 | G214: =ESTADISTICA!G214 -> 0 | H214: =ESTADISTICA!H214 -> 0 | ... AJ214: =ESTADISTICA!AJ214 -> #REF!
A215: =ESTADISTICA!A215 -> LA ESMERALDA | B215: =ESTADISTICA!B215 -> ESM09 (fija 1) | C215: =ESTADISTICA!C215 -> EEUU Y CABELLO | D215: =ESTADISTICA!D215 -> Fija | E215: =ESTADISTICA!E215 -> Fibra Optica | F215: =ESTADISTICA!F215 -> 0 | G215: =ESTADISTICA!G215 -> 0 | H215: =ESTADISTICA!H215 -> 0 | ... AJ215: =ESTADISTICA!AJ215 -> #REF!
A216: =ESTADISTICA!A216 -> LA ESMERALDA | B216: =ESTADISTICA!B216 -> ESM10 (fija 2) | C216: =ESTADISTICA!C216 -> EEUU Y CABELLO | D216: =ESTADISTICA!D216 -> Fija | E216: =ESTADISTICA!E216 -> Fibra Optica | F216: =ESTADISTICA!F216 -> 0 | G216: =ESTADISTICA!G216 -> 0 | H216: =ESTADISTICA!H216 -> 0 | ... AJ216: =ESTADISTICA!AJ216 -> #REF!
A217: =ESTADISTICA!A217 -> LA ESMERALDA | B217: =ESTADISTICA!B217 -> ESM11 (fija 1) | C217: =ESTADISTICA!C217 -> NOVAK Y LAMBARDI | D217: =ESTADISTICA!D217 -> Fija | E217: =ESTADISTICA!E217 -> Fibra Optica | F217: =ESTADISTICA!F217 -> 0 | G217: =ESTADISTICA!G217 -> 0 | H217: =ESTADISTICA!H217 -> 0 | ... AJ217: =ESTADISTICA!AJ217 -> #REF!
A218: =ESTADISTICA!A218 -> LA ESMERALDA | B218: =ESTADISTICA!B218 -> ESM12 (fija 2) | C218: =ESTADISTICA!C218 -> NOVAK Y LAMBARDI | D218: =ESTADISTICA!D218 -> Fija | E218: =ESTADISTICA!E218 -> Fibra Optica | F218: =ESTADISTICA!F218 -> 0 | G218: =ESTADISTICA!G218 -> 0 | H218: =ESTADISTICA!H218 -> 0 | ... AJ218: =ESTADISTICA!AJ218 -> #REF!
A219: =ESTADISTICA!A219 -> INGENIERO ALLAN | B219: =ESTADISTICA!B219 -> INA 01 | C219: =ESTADISTICA!C219 -> 1138 Y 1155 | D219: =ESTADISTICA!D219 -> DOMO | E219: =ESTADISTICA!E219 -> Fibra Optica | F219: =ESTADISTICA!F219 -> 0 | G219: =ESTADISTICA!G219 -> 0 | H219: =ESTADISTICA!H219 -> 0 | ... AJ219: =ESTADISTICA!AJ219 -> #REF!
... A516: =ESTADISTICA!A516 -> 0 | B516: =ESTADISTICA!B516 -> 0 | C516: =ESTADISTICA!C516 -> 0 | D516: =ESTADISTICA!D516 -> 0 | E516: =ESTADISTICA!E516 -> 0 | F516: =ESTADISTICA!F516 -> 0 | G516: =ESTADISTICA!G516 -> 0 | H516: =ESTADISTICA!H516 -> 0 | ... AJ516: =ESTADISTICA!AJ516 -> #REF!

Sheet APAGADOS FIBRA
C1: TOTAL FIBRA | D1: =COUNTIFS(E4:E401,"=Fibra Optica") -> 221
E2: APAGADOS | F2: =COUNTIFS(F4:F501, "=APAGADO",E4:E501,"=Fibra Optica") -> 41 | G2: =COUNTIFS(G4:G501, "=APAGADO",E4:E501,"=Fibra Optica") -> 42 | H2: =COUNTIFS(H4:H501, "=APAGADO",E4:E501,"=Fibra Optica") -> 42 | I2: =COUNTIFS(I4:I501, "=APAGADO",E4:E501,"=Fibra Optica") -> 38 | J2: =COUNTIFS(J4:J501, "=APAGADO",E4:E501,"=Fibra Optica") -> 41 | K2: =COUNTIFS(K4:K501, "=APAGADO",E4:E501,"=Fibra Optica") -> 41 | L2: =COUNTIFS(L4:L501, "=APAGADO",E4:E501,"=Fibra Optica") -> 44 | M2: =COUNTIFS(M4:M501, "=APAGADO",E4:E501,"=Fibra Optica") -> 44 | N2: =COUNTIFS(N4:N501, "=APAGADO",E4:E501,"=Fibra Optica") -> 39 | O2: =COUNTIFS(O4:O501, "=APAGADO",E4:E501,"=Fibra Optica") -> 42 | P2: =COUNTIFS(P4:P601, "=APAGADO",E4:E601,"=Fibra Optica") -> 33 | Q2: =COUNTIFS(Q4:Q501, "=APAGADO",E4:E501,"=Fibra Optica") -> 32 | R2: =COUNTIFS(R4:R501, "=APAGADO",E4:E501,"=Fibra Optica") -> 43 | S2: =COUNTIFS(S4:S501, "=APAGADO",E4:E501,"=Fibra Optica") -> 34 | T2: =COUNTIFS(T4:T501, "=APAGADO",E4:E501,"=Fibra Optica") -> 45 | U2: =COUNTIFS(U4:U501, "=APAGADO",E4:E501,"=Fibra Optica") -> 36 | V2: =COUNTIFS(V4:V501, "=APAGADO",E4:E501,"=Fibra Optica") -> 37 | W2: =COUNTIFS(W4:W501, "=APAGADO",E4:E501,"=Fibra Optica") -> 37 | X2: =COUNTIFS(X4:X501, "=APAGADO",E4:E501,"=Fibra Optica") -> 37 | Y2: =COUNTIFS(Y4:Y501, "=APAGADO",E4:E501,"=Fibra Optica") -> 34 | Z2: =COUNTIFS(Z4:Z501, "=APAGADO",E4:E501,"=Fibra Optica") -> 34 | AA2: =COUNTIFS(AA4:AA501, "=APAGADO",E4:E501,"=Fibra Optica") -> 34 | AB2: =COUNTIFS(AB4:AB501, "=APAGADO",E4:E501,"=Fibra Optica") -> 34 | AC2: =COUNTIFS(AC4:AC601, "=APAGADO",E4:E601,"=Fibra Optica") -> 36 | AD2: =COUNTIFS(AD4:AD501, "=APAGADO",E4:E501,"=Fibra Optica") -> 35 | AE2: =COUNTIFS(AE4:AE501, "=APAGADO",E4:E501,"=Fibra Optica") -> 31 | AF2: =COUNTIFS(AF4:AF501, "=APAGADO",E4:E501,"=Fibra Optica") -> 0 | AG2: =COUNTIFS(AG4:AG501, "=APAGADO",E4:E501,"=Fibra Optica") -> 0 | AH2: =COUNTIFS(AH4:AH501, "=APAGADO",E4:E501,"=Fibra Optica") -> 0 | AI2: =COUNTIFS(AI4:AI401, "=APAGADO",E4:E401,"=Fibra Optica") -> 0 | AJ2: =COUNTIFS(AJ4:AJ401, "=APAGADO",F4:F401,"=Fibra Optica") -> 0
A3: =ESTADISTICA!A1 -> Barrio | B3: =ESTADISTICA!B1 -> [Denominacion] | C3: =ESTADISTICA!C1 -> [Ubicacion] | D3: =ESTADISTICA!D1 -> [Tipo de Camara] | E3: =ESTADISTICA!E1 -> [Tipo de Conexion] | F3: =ESTADISTICA!F1 -> 45292 | G3: =ESTADISTICA!G1 -> 45293 | H3: =ESTADISTICA!H1 -> 45294 | ... AJ3: =ESTADISTICA!AJ1 -> #REF!
A4: ='RESUMEN TOTAL'!A7 -> PARADAS SEGURAS | B4: ='RESUMEN TOTAL'!B7 -> 13 | C4: ='RESUMEN TOTAL'!D7 -> THEVENET Y GRANADEROS NORTE | D4: ='RESUMEN TOTAL'!E7 -> GFIJA | E4: ='RESUMEN TOTAL'!F7 -> GPON | F4: ='RESUMEN TOTAL'!L7 -> APAGADO | G4: ='RESUMEN TOTAL'!M7 -> APAGADO | H4: ='RESUMEN TOTAL'!N7 -> APAGADO | I4: ='RESUMEN TOTAL'!O7 -> APAGADO | J4: ='RESUMEN TOTAL'!P7 -> APAGADO | K4: ='RESUMEN TOTAL'!Q7 -> APAGADO | L4: ='RESUMEN TOTAL'!R7 -> APAGADO | M4: ='RESUMEN TOTAL'!S7 -> APAGADO | ... AI4: ='RESUMEN TOTAL'!AO7 -> 0 | AJ4: ='RESUMEN TOTAL'!#REF! -> #REF!
A5: ='RESUMEN TOTAL'!A8 -> PARADAS SEGURAS | B5: ='RESUMEN TOTAL'!B8 -> 14 | C5: ='RESUMEN TOTAL'!D8 -> THEVENET Y BERUTI NORTE | D5: ='RESUMEN TOTAL'!E8 -> GFIJA | E5: ='RESUMEN TOTAL'!F8 -> GPON | F5: ='RESUMEN TOTAL'!L8 -> 0 | G5: ='RESUMEN TOTAL'!M8 -> 0 | H5: ='RESUMEN TOTAL'!N8 -> 0 | I5: ='RESUMEN TOTAL'!O8 -> 0 | J5: ='RESUMEN TOTAL'!P8 -> 0 | K5: ='RESUMEN TOTAL'!Q8 -> 0 | L5: ='RESUMEN TOTAL'!R8 -> 0 | M5: ='RESUMEN TOTAL'!S8 -> 0 | ... AI5: ='RESUMEN TOTAL'!AO8 -> 0 | AJ5: ='RESUMEN TOTAL'!#REF! -> #REF!
A6: ='RESUMEN TOTAL'!A9 -> PARADAS SEGURAS | B6: ='RESUMEN TOTAL'!B9 -> 15 | C6: ='RESUMEN TOTAL'!D9 -> THEVENET Y BERUTI SUR | D6: ='RESUMEN TOTAL'!E9 -> GFIJA | E6: ='RESUMEN TOTAL'!F9 -> GPON | F6: ='RESUMEN TOTAL'!L9 -> APAGADO | G6: ='RESUMEN TOTAL'!M9 -> APAGADO | H6: ='RESUMEN TOTAL'!N9 -> APAGADO | I6: ='RESUMEN TOTAL'!O9 -> APAGADO | J6: ='RESUMEN TOTAL'!P9 -> APAGADO | K6: ='RESUMEN TOTAL'!Q9 -> APAGADO | L6: ='RESUMEN TOTAL'!R9 -> 0 | M6: ='RESUMEN TOTAL'!S9 -> 0 | ... AI6: ='RESUMEN TOTAL'!AO9 -> 0 | AJ6: ='RESUMEN TOTAL'!#REF! -> #REF!
A7: ='RESUMEN TOTAL'!A10 -> PARADAS SEGURAS | B7: ='RESUMEN TOTAL'!B10 -> 16 | C7: ='RESUMEN TOTAL'!D10 -> THEVENET Y BRAILE NORTE | D7: ='RESUMEN TOTAL'!E10 -> GFIJA | E7: ='RESUMEN TOTAL'!F10 -> GPON | F7: ='RESUMEN TOTAL'!L10 -> 0 | G7: ='RESUMEN TOTAL'!M10 -> 0 | H7: ='RESUMEN TOTAL'!N10 -> 0 | I7: ='RESUMEN TOTAL'!O10 -> 0 | J7: ='RESUMEN TOTAL'!P10 -> 0 | K7: ='RESUMEN TOTAL'!Q10 -> 0 | L7: ='RESUMEN TOTAL'!R10 -> 0 | M7: ='RESUMEN TOTAL'!S10 -> 0 | ... AI7: ='RESUMEN TOTAL'!AO10 -> 0 | AJ7: ='RESUMEN TOTAL'!#REF! -> #REF!
A8: ='RESUMEN TOTAL'!A11 -> PARADAS SEGURAS | B8: ='RESUMEN TOTAL'!B11 -> 17 | C8: ='RESUMEN TOTAL'!D11 -> THEVENET Y ARENALES NORTE | D8: ='RESUMEN TOTAL'!E11 -> GFIJA | E8: ='RESUMEN TOTAL'!F11 -> GPON | F8: ='RESUMEN TOTAL'!L11 -> APAGADO | G8: ='RESUMEN TOTAL'!M11 -> APAGADO | H8: ='RESUMEN TOTAL'!N11 -> APAGADO | I8: ='RESUMEN TOTAL'!O11 -> APAGADO | J8: ='RESUMEN TOTAL'!P11 -> APAGADO | K8: ='RESUMEN TOTAL'!Q11 -> APAGADO | L8: ='RESUMEN TOTAL'!R11 -> 0 | M8: ='RESUMEN TOTAL'!S11 -> 0 | ... AI8: ='RESUMEN TOTAL'!AO11 -> 0 | AJ8: ='RESUMEN TOTAL'!#REF! -> #REF!
A9: ='RESUMEN TOTAL'!A12 -> PARADAS SEGURAS | B9: ='RESUMEN TOTAL'!B12 -> 18 | C9: ='RESUMEN TOTAL'!D12 -> THEVENET Y ARENALES SUR | D9: ='RESUMEN TOTAL'!E12 -> GFIJA | E9: ='RESUMEN TOTAL'!F12 -> GPON | F9: ='RESUMEN TOTAL'!L12 -> 0 | G9: ='RESUMEN TOTAL'!M12 -> 0 | H9: ='RESUMEN TOTAL'!N12 -> 0 | I9: ='RESUMEN TOTAL'!O12 -> 0 | J9: ='RESUMEN TOTAL'!P12 -> 0 | K9: ='RESUMEN TOTAL'!Q12 -> 0 | L9: ='RESUMEN TOTAL'!R12 -> 0 | M9: ='RESUMEN TOTAL'!S12 -> 0 | ... AI9: ='RESUMEN TOTAL'!AO12 -> 0 | AJ9: ='RESUMEN TOTAL'!#REF! -> #REF!
A10: ='RESUMEN TOTAL'!A13 -> PARADAS SEGURAS | B10: ='RESUMEN TOTAL'!B13 -> 19 | C10: ='RESUMEN TOTAL'!D13 -> THEVENET Y GORRITI NORTE | D10: ='RESUMEN TOTAL'!E13 -> GFIJA | E10: ='RESUMEN TOTAL'!F13 -> GPON | F10: ='RESUMEN TOTAL'!L13 -> 0 | G10: ='RESUMEN TOTAL'!M13 -> 0 | H10: ='RESUMEN TOTAL'!N13 -> 0 | I10: ='RESUMEN TOTAL'!O13 -> 0 | J10: ='RESUMEN TOTAL'!P13 -> 0 | K10: ='RESUMEN TOTAL'!Q13 -> 0 | L10: ='RESUMEN TOTAL'!R13 -> 0 | M10: ='RESUMEN TOTAL'!S13 -> 0 | ... AI10: ='RESUMEN TOTAL'!AO13 -> 0 | AJ10: ='RESUMEN TOTAL'!#REF! -> #REF!
A11: ='RESUMEN TOTAL'!A14 -> PARADAS SEGURAS | B11: ='RESUMEN TOTAL'!B14 -> 20 | C11: ='RESUMEN TOTAL'!D14 -> THEVENET Y GORRITI SUR | D11: ='RESUMEN TOTAL'!E14 -> GFIJA | E11: ='RESUMEN TOTAL'!F14 -> GPON | F11: ='RESUMEN TOTAL'!L14 -> 0 | G11: ='RESUMEN TOTAL'!M14 -> 0 | H11: ='RESUMEN TOTAL'!N14 -> 0 | I11: ='RESUMEN TOTAL'!O14 -> 0 | J11: ='RESUMEN TOTAL'!P14 -> 0 | K11: ='RESUMEN TOTAL'!Q14 -> 0 | L11: ='RESUMEN TOTAL'!R14 -> 0 | M11: ='RESUMEN TOTAL'!S14 -> 0 | ... AI11: ='RESUMEN TOTAL'!AO14 -> 0 | AJ11: ='RESUMEN TOTAL'!#REF! -> #REF!
A12: ='RESUMEN TOTAL'!A15 -> PARADAS SEGURAS | B12: ='RESUMEN TOTAL'!B15 -> 21 | C12: ='RESUMEN TOTAL'!D15 -> HUDSON Y CABILDO OESTE | D12: ='RESUMEN TOTAL'!E15 -> GFIJA | E12: ='RESUMEN TOTAL'!F15 -> GPON | F12: ='RESUMEN TOTAL'!L15 -> 0 | G12: ='RESUMEN TOTAL'!M15 -> 0 | H12: ='RESUMEN TOTAL'!N15 -> 0 | I12: ='RESUMEN TOTAL'!O15 -> 0 | J12: ='RESUMEN TOTAL'!P15 -> 0 | K12: ='RESUMEN TOTAL'!Q15 -> 0 | L12: ='RESUMEN TOTAL'!R15 -> 0 | M12: ='RESUMEN TOTAL'!S15 -> 0 | ... AI12: ='RESUMEN TOTAL'!AO15 -> 0 | AJ12: ='RESUMEN TOTAL'!#REF! -> #REF!
A13: ='RESUMEN TOTAL'!A16 -> PARADAS SEGURAS | B13: ='RESUMEN TOTAL'!B16 -> 22 | C13: ='RESUMEN TOTAL'!D16 -> HUDSON Y CABILDO ESTE | D13: ='RESUMEN TOTAL'!E16 -> GFIJA | E13: ='RESUMEN TOTAL'!F16 -> GPON | F13: ='RESUMEN TOTAL'!L16 -> 0 | G13: ='RESUMEN TOTAL'!M16 -> APAGADO | H13: ='RESUMEN TOTAL'!N16 -> APAGADO | I13: ='RESUMEN TOTAL'!O16 -> APAGADO | J13: ='RESUMEN TOTAL'!P16 -> APAGADO | K13: ='RESUMEN TOTAL'!Q16 -> APAGADO | L13: ='RESUMEN TOTAL'!R16 -> 0 | M13: ='RESUMEN TOTAL'!S16 -> 0 | ... AI13: ='RESUMEN TOTAL'!AO16 -> 0 | AJ13: ='RESUMEN TOTAL'!#REF! -> #REF!
A14: ='RESUMEN TOTAL'!A17 -> PARADAS SEGURAS | B14: ='RESUMEN TOTAL'!B17 -> 23 | C14: ='RESUMEN TOTAL'!D17 -> HUDSON Y SAN NICOLAS OESTE | D14: ='RESUMEN TOTAL'!E17 -> GFIJA | E14: ='RESUMEN TOTAL'!F17 -> GPON | F14: ='RESUMEN TOTAL'!L17 -> 0 | G14: ='RESUMEN TOTAL'!M17 -> 0 | H14: ='RESUMEN TOTAL'!N17 -> 0 | I14: ='RESUMEN TOTAL'!O17 -> 0 | J14: ='RESUMEN TOTAL'!P17 -> 0 | K14: ='RESUMEN TOTAL'!Q17 -> 0 | L14: ='RESUMEN TOTAL'!R17 -> 0 | M14: ='RESUMEN TOTAL'!S17 -> 0 | ... AI14: ='RESUMEN TOTAL'!AO17 -> 0 | AJ14: ='RESUMEN TOTAL'!#REF! -> #REF!
A15: ='RESUMEN TOTAL'!A18 -> PARADAS SEGURAS | B15: ='RESUMEN TOTAL'!B18 -> 24 | C15: ='RESUMEN TOTAL'!D18 -> HUDSON Y ALDAO ESTE | D15: ='RESUMEN TOTAL'!E18 -> GFIJA | E15: ='RESUMEN TOTAL'!F18 -> GPON | F15: ='RESUMEN TOTAL'!L18 -> 0 | G15: ='RESUMEN TOTAL'!M18 -> 0 | H15: ='RESUMEN TOTAL'!N18 -> 0 | I15: ='RESUMEN TOTAL'!O18 -> 0 | J15: ='RESUMEN TOTAL'!P18 -> 0 | K15: ='RESUMEN TOTAL'!Q18 -> 0 | L15: ='RESUMEN TOTAL'!R18 -> 0 | M15: ='RESUMEN TOTAL'!S18 -> 0 | ... AI15: ='RESUMEN TOTAL'!AO18 -> 0 | AJ15: ='RESUMEN TOTAL'!#REF! -> #REF!
... A67: ='RESUMEN TOTAL'!A70 -> PARADAS SEGURAS | B67: ='RESUMEN TOTAL'!B70 -> 43 I | C67: ='RESUMEN TOTAL'!D70 -> Hudson y Manuel de Falla Este | D67: ='RESUMEN TOTAL'!E70 -> INTERCOMUNICADOR | E67: ='RESUMEN TOTAL'!F70 -> GPON | F67: ='RESUMEN TOTAL'!L70 -> 0 | G67: ='RESUMEN TOTAL'!M70 -> 0 | H67: ='RESUMEN TOTAL'!N70 -> 0 | I67: ='RESUMEN TOTAL'!O70 -> 0 | J67: ='RESUMEN TOTAL'!P70 -> 0 | K67: ='RESUMEN TOTAL'!Q70 -> 0 | L67: ='RESUMEN TOTAL'!R70 -> 0 | M67: ='RESUMEN TOTAL'!S70 -> 0 | ... AI67: ='RESUMEN TOTAL'!AO70 -> 0 | AJ67: ='RESUMEN TOTAL'!#REF! -> #REF!
A68: ='RESUMEN TOTAL'!A71 -> PARADAS SEGURAS | B68: ='RESUMEN TOTAL'!B71 -> 45 C | C68: ='RESUMEN TOTAL'!D71 -> Hudson y Benito Perez Galdos Este | D68: ='RESUMEN TOTAL'!E71 -> GFIJA | E68: ='RESUMEN TOTAL'!F71 -> GPON | F68: ='RESUMEN TOTAL'!L71 -> 0 | G68: ='RESUMEN TOTAL'!M71 -> 0 | H68: ='RESUMEN TOTAL'!N71 -> 0 | I68: ='RESUMEN TOTAL'!O71 -> 0 | J68: ='RESUMEN TOTAL'!P71 -> 0 | K68: ='RESUMEN TOTAL'!Q71 -> 0 | L68: ='RESUMEN TOTAL'!R71 -> 0 | M68: ='RESUMEN TOTAL'!S71 -> 0 | ... Z68: ='RESUMEN TOTAL'!AF71 -> 0 | AA68: ='RESUMEN TOTAL'!AG546 -> 0 | AB68: ='RESUMEN TOTAL'!AH71 -> 0 | AC68: ='RESUMEN TOTAL'!AI71 -> 0 | AD68: ='RESUMEN TOTAL'!AJ71 -> 0 | AE68: ='RESUMEN TOTAL'!AK71 -> 0 | AF68: ='RESUMEN TOTAL'!AL71 -> 0 | AG68: ='RESUMEN TOTAL'!AM71 -> 0 | AH68: ='RESUMEN TOTAL'!AN71 -> 0 | AI68: ='RESUMEN TOTAL'!AO71 -> 0 | AJ68: ='RESUMEN TOTAL'!#REF! -> #REF!
A69: ='RESUMEN TOTAL'!A72 -> PARADAS SEGURAS | B69: ='RESUMEN TOTAL'!B72 -> 45 I | C69: ='RESUMEN TOTAL'!D72 -> Hudson y Benito Perez Galdos Este | D69: ='RESUMEN TOTAL'!E72 -> INTERCOMUNICADOR | E69: ='RESUMEN TOTAL'!F72 -> GPON | F69: ='RESUMEN TOTAL'!L72 -> 0 | G69: ='RESUMEN TOTAL'!M72 -> 0 | H69: ='RESUMEN TOTAL'!N72 -> 0 | I69: ='RESUMEN TOTAL'!O72 -> 0 | J69: ='RESUMEN TOTAL'!P72 -> 0 | K69: ='RESUMEN TOTAL'!Q72 -> 0 | L69: ='RESUMEN TOTAL'!R72 -> 0 | M69: ='RESUMEN TOTAL'!S72 -> 0 | ... AI69: ='RESUMEN TOTAL'!AO72 -> 0 | AJ69: ='RESUMEN TOTAL'!#REF! -> #REF!
A70: ='RESUMEN TOTAL'!A73 -> PARADAS SEGURAS | B70: ='RESUMEN TOTAL'!B73 -> 46 C | C70: ='RESUMEN TOTAL'!D73 -> Hudson y Avenida Bosques Este | D70: ='RESUMEN TOTAL'!E73 -> GFIJA | E70: ='RESUMEN TOTAL'!F73 -> GPON | F70: ='RESUMEN TOTAL'!L73 -> 0 | G70: ='RESUMEN TOTAL'!M73 -> 0 | H70: ='RESUMEN TOTAL'!N73 -> 0 | I70: ='RESUMEN TOTAL'!O73 -> 0 | J70: ='RESUMEN TOTAL'!P73 -> 0 | K70: ='RESUMEN TOTAL'!Q73 -> 0 | L70: ='RESUMEN TOTAL'!R73 -> 0 | M70: ='RESUMEN TOTAL'!S73 -> 0 | ... AI70: ='RESUMEN TOTAL'!AO73 -> 0 | AJ70: ='RESUMEN TOTAL'!#REF! -> #REF!
A71: ='RESUMEN TOTAL'!A74 -> PARADAS SEGURAS | B71: ='RESUMEN TOTAL'!B74 -> 46 I | C71: ='RESUMEN TOTAL'!D74 -> Hudson y Avenida Bosques Este | D71: ='RESUMEN TOTAL'!E74 -> INTERCOMUNICADOR | E71: ='RESUMEN TOTAL'!F74 -> GPON | F71: ='RESUMEN TOTAL'!L74 -> 0 | G71: ='RESUMEN TOTAL'!M74 -> 0 | H71: ='RESUMEN TOTAL'!N74 -> 0 | I71: ='RESUMEN TOTAL'!O74 -> 0 | J71: ='RESUMEN TOTAL'!P74 -> 0 | K71: ='RESUMEN TOTAL'!Q74 -> 0 | L71: ='RESUMEN TOTAL'!R74 -> 0 | M71: ='RESUMEN TOTAL'!S74 -> 0 | ... AI71: ='RESUMEN TOTAL'!AO74 -> 0 | AJ71: ='RESUMEN TOTAL'!#REF! -> #REF!
A72: ='RESUMEN TOTAL'!A75 -> PARADAS SEGURAS | B72: ='RESUMEN TOTAL'!B75 -> 47 C | C72: ='RESUMEN TOTAL'!D75 -> Hudson y Avenida Bosques Oeste | D72: ='RESUMEN TOTAL'!E75 -> GFIJA | E72: ='RESUMEN TOTAL'!F75 -> GPON | F72: ='RESUMEN TOTAL'!L75 -> 0 | G72: ='RESUMEN TOTAL'!M75 -> 0 | H72: ='RESUMEN TOTAL'!N75 -> 0 | I72: ='RESUMEN TOTAL'!O75 -> 0 | J72: ='RESUMEN TOTAL'!P75 -> 0 | K72: ='RESUMEN TOTAL'!Q75 -> 0 | L72: ='RESUMEN TOTAL'!R75 -> 0 | M72: ='RESUMEN TOTAL'!S75 -> 0 | ... AI72: ='RESUMEN TOTAL'!AO75 -> 0 | AJ72: ='RESUMEN TOTAL'!#REF! -> #REF!
A73: ='RESUMEN TOTAL'!A76 -> PARADAS SEGURAS | B73: ='RESUMEN TOTAL'!B76 -> 47 I | C73: ='RESUMEN TOTAL'!D76 -> Hudson y Avenida Bosques Oeste | D73: ='RESUMEN TOTAL'!E76 -> INTERCOMUNICADOR | E73: ='RESUMEN TOTAL'!F76 -> GPON | F73: ='RESUMEN TOTAL'!L76 -> 0 | G73: ='RESUMEN TOTAL'!M76 -> 0 | H73: ='RESUMEN TOTAL'!N76 -> 0 | I73: ='RESUMEN TOTAL'!O76 -> 0 | J73: ='RESUMEN TOTAL'!P76 -> 0 | K73: ='RESUMEN TOTAL'!Q76 -> 0 | L73: ='RESUMEN TOTAL'!R76 -> 0 | M73: ='RESUMEN TOTAL'!S76 -> 0 | ... AI73: ='RESUMEN TOTAL'!AO76 -> 0 | AJ73: ='RESUMEN TOTAL'!#REF! -> #REF!
A74: ='RESUMEN TOTAL'!A77 -> PARADAS SEGURAS | B74: ='RESUMEN TOTAL'!B77 -> 64 C | C74: ='RESUMEN TOTAL'!D77 -> Lujan y Combate de los Pozos | D74: ='RESUMEN TOTAL'!E77 -> GFIJA | E74: ='RESUMEN TOTAL'!F77 -> GPON | F74: ='RESUMEN TOTAL'!L77 -> 0 | G74: ='RESUMEN TOTAL'!M77 -> 0 | H74: ='RESUMEN TOTAL'!N77 -> 0 | I74: ='RESUMEN TOTAL'!O77 -> 0 | J74: ='RESUMEN TOTAL'!P77 -> 0 | K74: ='RESUMEN TOTAL'!Q77 -> 0 | L74: ='RESUMEN TOTAL'!R77 -> 0 | M74: ='RESUMEN TOTAL'!S77 -> 0 | ... AI74: ='RESUMEN TOTAL'!AO77 -> 0 | AJ74: ='RESUMEN TOTAL'!#REF! -> #REF!
