Workbook
Name _25_de_agosto: 'RESUMEN TOTAL'!$A$4:$D$365
Name _25_de_agosto_3: 'RESUMEN TOTAL'!$A$4:$D$377
Name BONOMOcam: Hoja1!$B$2
Name CANTIDAD_DE_CAMARAS: 'RESUMEN TOTAL'!$B$1
Name COSEIDIcam: Hoja1!$B$4

Sheet RESUMEN TOTAL
A1: CANTIDAD DE CAMARAS | B1: =COUNTA(B5:B533) -> 435 | D1: PORCIENTO DE CAIDAS | K1: =(K3)/(K2+K3) -> 0.31034483 | L1: =(L3)/(L2+L3) -> 0.25977011 | M1: =(M3)/(M2+M3) -> 0.22298851 | N1: =(N3)/(N2+N3) -> 0.2183908 | O1: =(O3)/(O2+O3) -> 0.22528736 | P1: =(P3)/(P2+P3) -> 0.1862069 | Q1: =(Q3)/(Q2+Q3) -> 0.18850575 | R1: =(R3)/(R2+R3) -> 0.18850575 | ... AN1: =(AN3)/(AN2+AN3) -> 0
D2: FUNCIONAN | K2: =B1-K3 -> 300 | L2: =CANTIDAD_DE_CAMARAS-L3 -> 322 | M2: =CANTIDAD_DE_CAMARAS-M3 -> 338 | N2: =CANTIDAD_DE_CAMARAS-N3 -> 340 | O2: =CANTIDAD_DE_CAMARAS-O3 -> 337 | P2: =CANTIDAD_DE_CAMARAS-P3 -> 354 | Q2: =CANTIDAD_DE_CAMARAS-Q3 -> 353 | R2: =CANTIDAD_DE_CAMARAS-R3 -> 353 | S2: =CANTIDAD_DE_CAMARAS-S3 -> 343 | ... AN2: =CANTIDAD_DE_CAMARAS-AN3 -> 435
D3: CAIDAS | K3: =COUNTIF(K4:K453, "apagado") -> 135 | L3: =COUNTIF(L4:L453, "apagado") -> 113 | M3: =COUNTIF(M4:M453, "apagado") -> 97 | N3: =COUNTIF(N4:N453, "apagado") -> 95 | O3: =COUNTIF(O4:O453, "apagado") -> 98 | P3: =COUNTIF(P4:P453, "apagado") -> 81 | Q3: =COUNTIF(Q4:Q453, "apagado") -> 82 | R3: =COUNTIF(R4:R453, "apagado") -> 82 | ... AN3: =COUNTIF(AN4:AN453, "apagado") -> 0
A4: Barrio | B4: [Denominacion] | C4: [Empresa Mantenimiento] | D4: [Ubicacion] | E4: [Tipo de Camara] | F4: [Tipo de Conexion] | H4: DIAS FUNCIONANDO | I4: DIAS CAIDA | J4: EFECTIVIDAD | K4: 44896 | L4: 44897 | M4: 44898 | N4: 44899 | O4: 44900 | P4: 44901 | Q4: 44902 | R4: 44903 | S4: 44904 | T4: 44905 | U4: 44906 | V4: 44907 | W4: 44908 | X4: 44909 | Y4: 44910 | Z4: 44911 | AA4: 44912 | AB4: 44913 | AC4: 44914 | AD4: 44915 | AE4: 44916 | AF4: 44917 | AG4: 44918 | AH4: 44919 | AI4: 44920 | AJ4: 44921 | AK4: 44922 | AL4: 44923 | AM4: 44924 | AN4: 44925 | AO4: 44926
A5: ALTAMIRA | B5: ALT01 | C5: BONOMO | D5: Calchaqui y Sgto. Cabral | E5: Domo | F5: Fibra Optica | G5: 172.20.10.6 | H5: =COUNTIF(K5:AO5,"") -> 16 | I5: =COUNTIF(K5:AL5,"APAGADO") -> 15 | J5: =(H5)/(I5+H5) -> 0.51612903 | K5: APAGADO | L5: APAGADO | M5: APAGADO | N5: APAGADO | O5: APAGADO | P5: APAGADO | Q5: APAGADO | R5: APAGADO | S5: APAGADO | T5: APAGADO | U5: APAGADO | V5: APAGADO | W5: APAGADO | X5: APAGADO | Y5: APAGADO
A6: ALTAMIRA | B6: ALT02 | C6: BONOMO | D6: Calchaqui y Lope de Vega | E6: Domo | F6: PTO A FO | G6: 172.20.12.218 | H6: =COUNTIF(K6:AO6,"") -> 16 | I6: =COUNTIF(K6:AL6,"APAGADO") -> 15 | J6: =(H6)/(I6+H6) -> 0.51612903 | K6: APAGADO | L6: APAGADO | M6: APAGADO | N6: APAGADO | O6: APAGADO | P6: APAGADO | Q6: APAGADO | R6: APAGADO | S6: APAGADO | T6: APAGADO | U6: APAGADO | V6: APAGADO | W6: APAGADO | X6: APAGADO | Y6: APAGADO
A7: ALTAMIRA | B7: ALT 03 | C7: BONOMO | D7: Bombero Galarza y Necochea | E7: Domo | F7: FIBRA OPTICA | G7: 172.20.12.54 | H7: =COUNTIF(K7:AO7,"") -> 16 | I7: =COUNTIF(K7:AL7,"APAGADO") -> 15 | J7: =(H7)/(I7+H7) -> 0.51612903 | K7: APAGADO | L7: APAGADO | M7: APAGADO | N7: APAGADO | O7: APAGADO | P7: APAGADO | Q7: APAGADO | R7: APAGADO | S7: APAGADO | T7: APAGADO | U7: APAGADO | V7: APAGADO | W7: APAGADO | X7: APAGADO | Y7: APAGADO
A8: ALTAMIRA | B8: ALT 04 | C8: BONOMO | D8: Francia y Necochea | E8: Domo | F8: FIBRA OPTICA | G8: 172.20.12.55 | H8: =COUNTIF(K8:AO8,"") -> 16 | I8: =COUNTIF(K8:AL8,"APAGADO") -> 15 | J8: =(H8)/(I8+H8) -> 0.51612903 | K8: APAGADO | L8: APAGADO | M8: APAGADO | N8: APAGADO | O8: APAGADO | P8: APAGADO | Q8: APAGADO | R8: APAGADO | S8: APAGADO | T8: APAGADO | U8: APAGADO | V8: APAGADO | W8: APAGADO | X8: APAGADO | Y8: APAGADO
A9: ALTAMIRA | B9: ALT05 | C9: BONOMO | D9: Av. Calchaqui y Bombero Galarza | E9: Domo | F9: PTO A FO | G9: 172.20.12.216 | H9: =COUNTIF(K9:AO9,"") -> 16 | I9: =COUNTIF(K9:AL9,"APAGADO") -> 15 | J9: =(H9)/(I9+H9) -> 0.51612903 | K9: APAGADO | L9: APAGADO | M9: APAGADO | N9: APAGADO | O9: APAGADO | P9: APAGADO | Q9: APAGADO | R9: APAGADO | S9: APAGADO | T9: APAGADO | U9: APAGADO | V9: APAGADO | W9: APAGADO | X9: APAGADO | Y9: APAGADO
A10: ALTAMIRA | B10: ALT 06 | C10: BONOMO | D10: LOPE DE VEGA Y NECOCHEA | E10: Domo | F10: PTO A FO | G10: 172.20.12.12 | H10: =COUNTIF(K10:AO10,"") -> 16 | I10: =COUNTIF(K10:AL10,"APAGADO") -> 15 | J10: =(H10)/(I10+H10) -> 0.51612903 | K10: APAGADO | L10: APAGADO | M10: APAGADO | N10: APAGADO | O10: APAGADO | P10: APAGADO | Q10: APAGADO | R10: APAGADO | S10: APAGADO | T10: APAGADO | U10: APAGADO | V10: APAGADO | W10: APAGADO | X10: APAGADO | Y10: APAGADO
A11: ALTAMIRA | B11: ALT07 | C11: BONOMO | D11: AV. CALCHAQUI Y AV. DEL TRABAJO | E11: DOMO | F11: PTO A FO | G11: 172.20.10.57 | H11: =COUNTIF(K11:AO11,"") -> 16 | I11: =COUNTIF(K11:AL11,"APAGADO") -> 15 | J11: =(H11)/(I11+H11) -> 0.51612903 | K11: APAGADO | L11: APAGADO | M11: APAGADO | N11: APAGADO | O11: APAGADO | P11: APAGADO | Q11: APAGADO | R11: APAGADO | S11: APAGADO | T11: APAGADO | U11: APAGADO | V11: APAGADO | W11: APAGADO | X11: APAGADO | Y11: APAGADO
A12: ALTAMIRA | B12: ALT 08 | C12: BONOMO | D12: HUMAITA Y NECOCHEA | E12: DOMO | F12: Fibra Optica | G12: 172.20.11.215 | H12: =COUNTIF(K12:AO12,"") -> 16 | I12: =COUNTIF(K12:AL12,"APAGADO") -> 15 | J12: =(H12)/(I12+H12) -> 0.51612903 | K12: APAGADO | L12: APAGADO | M12: APAGADO | N12: APAGADO | O12: APAGADO | P12: APAGADO | Q12: APAGADO | R12: APAGADO | S12: APAGADO | T12: APAGADO | U12: APAGADO | V12: APAGADO | W12: APAGADO | X12: APAGADO | Y12: APAGADO
A13: ALTAMIRA | B13: ALT 09 | C13: BONOMO | D13: NECOCHEA Y CURUPAITY | E13: DOMO | F13: Fibra Optica | G13: 172.20.11.216 | H13: =COUNTIF(K13:AO13,"") -> 16 | I13: =COUNTIF(K13:AL13,"APAGADO") -> 15 | J13: =(H13)/(I13+H13) -> 0.51612903 | K13: APAGADO | L13: APAGADO | M13: APAGADO | N13: APAGADO | O13: APAGADO | P13: APAGADO | Q13: APAGADO | R13: APAGADO | S13: APAGADO | T13: APAGADO | U13: APAGADO | V13: APAGADO | W13: APAGADO | X13: APAGADO | Y13: APAGADO
A14: ALTAMIRA | B14: ALT 10 | C14: BONOMO | D14: Calchaqui y Francia | E14: Domo | F14: Radio | H14: =COUNTIF(K14:AO14,"") -> 16 | I14: =COUNTIF(K14:AL14,"APAGADO") -> 15 | J14: =(H14)/(I14+H14) -> 0.51612903 | K14: APAGADO | L14: APAGADO | M14: APAGADO | N14: APAGADO | O14: APAGADO | P14: APAGADO | Q14: APAGADO | R14: APAGADO | S14: APAGADO | T14: APAGADO | U14: APAGADO | V14: APAGADO | W14: APAGADO | X14: APAGADO | Y14: APAGADO
A15: AGUSTIN RAMIREZ | B15: ARA 01 | C15: COSEIDI | D15: Malambo y Tranquera | E15: Domo | F15: FIBRA OPTICA | G15: 172.20.12.110 | H15: =COUNTIF(K15:AO15,"") -> 30 | I15: =COUNTIF(K15:AL15,"APAGADO") -> 1 | J15: =(H15)/(I15+H15) -> 0.96774194 | AK15: APAGADO
A16: BELGRANO | B16: BEL 01 | C16: BONOMO | D16: San Martin y Dardo Rocha | E16: DOMO | F16: FIBRA OPTICA | G16: 172.20.12.64 | H16: =COUNTIF(K16:AO16,"") -> 5 | I16: =COUNTIF(K16:AL16,"APAGADO") -> 25 | J16: =(H16)/(I16+H16) -> 0.16666667 | K16: APAGADO | L16: APAGADO | M16: APAGADO | O16: APAGADO | P16: APAGADO | Q16: APAGADO | R16: APAGADO | S16: APAGADO | T16: APAGADO | U16: APAGADO | V16: X | W16: APAGADO | X16: APAGADO | Y16: APAGADO | Z16: APAGADO | AA16: APAGADO | AB16: APAGADO | AC16: APAGADO | AD16: APAGADO | AE16: APAGADO | AF16: APAGADO | AG16: APAGADO | AH16: APAGADO | AI16: APAGADO | AJ16: APAGADO | AK16: APAGADO
A17: BOSQUES CENTRO | B17: BOSQC 01 | C17: COSEIDI | D17: LUIS AGOTE E/DANUNCIO Y CAMPOAMOR | E17: Fija | F17: Radio | G17: 172.20.11.15 | H17: =COUNTIF(K17:AO17,"") -> 23 | I17: =COUNTIF(K17:AL17,"APAGADO") -> 8 | J17: =(H17)/(I17+H17) -> 0.74193548 | K17: APAGADO | L17: APAGADO | M17: APAGADO | N17: APAGADO | O17: APAGADO | Y17: APAGADO | Z17: APAGADO | AA17: APAGADO
A18: BOSQUES CENTRO | B18: BOSQC 02 | C18: COSEIDI | D18: LUIS AGOTE E/DANUNCIO Y CAMPOAMOR | E18: Fija | F18: Radio | G18: 172.20.11.16 | H18: =COUNTIF(K18:AO18,"") -> 23 | I18: =COUNTIF(K18:AL18,"APAGADO") -> 8 | J18: =(H18)/(I18+H18) -> 0.74193548 | K18: APAGADO | L18: APAGADO | M18: APAGADO | N18: APAGADO | O18: APAGADO | Y18: APAGADO | Z18: APAGADO | AA18: APAGADO
A19: BOSQUES CENTRO | B19: BOSQC 03 | C19: COSEIDI | D19: BENAVENTE Y LUIS AGOTE | E19: Fija | F19: Radio | G19: 172.20.11.13 | H19: =COUNTIF(K19:AO19,"") -> 23 | I19: =COUNTIF(K19:AL19,"APAGADO") -> 8 | J19: =(H19)/(I19+H19) -> 0.74193548 | K19: APAGADO | L19: APAGADO | M19: APAGADO | N19: APAGADO | O19: APAGADO | Y19: APAGADO | Z19: APAGADO | AA19: APAGADO
A20: BOSQUES CENTRO | B20: BOSQC 04 | C20: COSEIDI | D20: BENAVENTE Y LUIS AGOTE | E20: Fija | F20: Radio | G20: 172.20.11.113 | H20: =COUNTIF(K20:AO20,"") -> 23 | I20: =COUNTIF(K20:AL20,"APAGADO") -> 8 | J20: =(H20)/(I20+H20) -> 0.74193548 | K20: APAGADO | L20: APAGADO | M20: APAGADO | N20: APAGADO | O20: APAGADO | Y20: APAGADO | Z20: APAGADO | AA20: APAGADO
A21: BOSQUES CENTRO | B21: BOSQC 05 | C21: COSEIDI | D21: LUIS AGOTE Y RUTA 36 | E21: Fija | F21: Radio | G21: 172.20.11.17 | H21: =COUNTIF(K21:AO21,"") -> 25 | I21: =COUNTIF(K21:AL21,"APAGADO") -> 6 | J21: =(H21)/(I21+H21) -> 0.80645161 | K21: APAGADO | L21: APAGADO | M21: APAGADO | N21: APAGADO | O21: APAGADO | AA21: APAGADO
A22: BOSQUES CENTRO | B22: BOSQC 06 | C22: COSEIDI | D22: LUIS AGOTE Y RUTA 36 | E22: Fija | F22: Radio | G22: 172.20.11.18 | H22: =COUNTIF(K22:AO22,"") -> 25 | I22: =COUNTIF(K22:AL22,"APAGADO") -> 6 | J22: =(H22)/(I22+H22) -> 0.80645161 | K22: APAGADO | L22: APAGADO | M22: APAGADO | N22: APAGADO | O22: APAGADO | AA22: APAGADO
A23: CENTRO | B23: CEN01 | C23: BONOMO | D23: San Martin y 9 de Julio | E23: Fija | F23: Fibra Optica | G23: 172.20.11.10 | H23: =COUNTIF(K23:AO23,"") -> 30 | I23: =COUNTIF(K23:AL23,"APAGADO") -> 1 | J23: =(H23)/(I23+H23) -> 0.96774194 | AA23: APAGADO
A24: CENTRO | B24: CEN02 | C24: BONOMO | D24: San Martin y Almafuerte | E24: Fija | F24: Fibra Optica | G24: 172.20.11.11 | H24: =COUNTIF(K24:AO24,"") -> 29 | I24: =COUNTIF(K24:AL24,"APAGADO") -> 2 | J24: =(H24)/(I24+H24) -> 0.93548387 | Y24: APAGADO | Z24: APAGADO
A25: CENTRO | B25: CEN03 | C25: BONOMO | D25: San Martin y Sallares | E25: Domo | F25: Fibra Optica | G25: 172.20.12.30 | H25: =COUNTIF(K25:AO25,"") -> 31 | I25: =COUNTIF(K25:AL25,"APAGADO") -> 0 | J25: =(H25)/(I25+H25) -> 1
A26: CENTRO | B26: CEN04 | C26: BONOMO | D26: San Martin y Contreras | E26: Domo | F26: Fibra Optica | G26: 172.20.12.29 | H26: =COUNTIF(K26:AO26,"") -> 31 | I26: =COUNTIF(K26:AL26,"APAGADO") -> 0 | J26: =(H26)/(I26+H26) -> 1
A27: CENTRO | B27: CEN 05 | C27: BONOMO | D27: Bocuzzi e/España y San Martin | E27: DOMO | F27: Fibra Optica | G27: 172.20.10.200 | H27: =COUNTIF(K27:AO27,"") -> 29 | I27: =COUNTIF(K27:AL27,"APAGADO") -> 2 | J27: =(H27)/(I27+H27) -> 0.93548387 | K27: APAGADO | L27: APAGADO
A28: CENTRO | B28: CEN06 | C28: BONOMO | D28: Monteagudo y A.del Valle | E28: Fija | F28: Fibra Optica | G28: 172.20.10.02 | H28: =COUNTIF(K28:AO28,"") -> 31 | I28: =COUNTIF(K28:AL28,"APAGADO") -> 0 | J28: =(H28)/(I28+H28) -> 1
A29: CENTRO | B29: CEN07 | C29: BONOMO | D29: San Martin y Guemes | E29: DOMO | F29: Fibra Optica | G29: 172.20.11.20 | H29: =COUNTIF(K29:AO29,"") -> 31 | I29: =COUNTIF(K29:AL29,"APAGADO") -> 0 | J29: =(H29)/(I29+H29) -> 1
A30: CENTRO | B30: CEN08 | C30: BONOMO | D30: San Martin y Pte.Peron | E30: Domo | F30: Fibra Optica | G30: 172.20.11.21 | H30: =COUNTIF(K30:AO30,"") -> 31 | I30: =COUNTIF(K30:AL30,"APAGADO") -> 0 | J30: =(H30)/(I30+H30) -> 1
A31: CENTRO | B31: CEN09 | C31: BONOMO | D31: Chacabuco y 25 de Mayo | E31: Domo | F31: Fibra Optica | G31: 172.20.11.22 | H31: =COUNTIF(K31:AO31,"") -> 31 | I31: =COUNTIF(K31:AL31,"APAGADO") -> 0 | J31: =(H31)/(I31+H31) -> 1
A32: CENTRO | B32: CEN10 | C32: BONOMO | D32: Monteagudo y Pte. Peron | E32: Domo | F32: Fibra Optica | G32: 172.20.11.23 | H32: =COUNTIF(K32:AO32,"") -> 31 | I32: =COUNTIF(K32:AL32,"APAGADO") -> 0 | J32: =(H32)/(I32+H32) -> 1
A33: CENTRO | B33: CEN11 | C33: BONOMO | D33: Monteagudo y Bocuzzi | E33: Domo | F33: Fibra Optica | G33: 172.20.10.24 | H33: =COUNTIF(K33:AO33,"") -> 31 | I33: =COUNTIF(K33:AL33,"APAGADO") -> 0 | J33: =(H33)/(I33+H33) -> 1
A34: CENTRO | B34: CEN 12 | C34: BONOMO | D34: Monteagudo y Mitre | E34: Domo | F34: Fibra Optica | G34: 172.20.10.23 | H34: =COUNTIF(K34:AO34,"") -> 14 | I34: =COUNTIF(K34:AL34,"APAGADO") -> 17 | J34: =(H34)/(I34+H34) -> 0.4516129 | K34: APAGADO | L34: APAGADO | M34: APAGADO | N34: APAGADO | O34: APAGADO | P34: APAGADO | Q34: APAGADO | R34: APAGADO | S34: APAGADO | T34: APAGADO | U34: APAGADO | V34: APAGADO | W34: APAGADO | X34: APAGADO | Y34: APAGADO | Z34: APAGADO | AA34: APAGADO
A35: CENTRO | B35: CEN 13 | C35: BONOMO | D35: 25 de Mayo y Maipu | E35: DOMO | F35: Fibra Optica | G35: 172.20.10.20 | H35: =COUNTIF(K35:AO35,"") -> 31 | I35: =COUNTIF(K35:AL35,"APAGADO") -> 0 | J35: =(H35)/(I35+H35) -> 1
A36: CENTRO | B36: CEN14 | C36: BONOMO | D36: Pte.Peron e/Pringles y Brown | E36: Domo | F36: Fibra Optica | G36: 172.20.10.21 | H36: =COUNTIF(K36:AO36,"") -> 31 | I36: =COUNTIF(K36:AL36,"APAGADO") -> 0 | J36: =(H36)/(I36+H36) -> 1
A37: CENTRO | B37: CEN15 | C37: BONOMO | D37: Alberdi y A.del Valle | E37: Domo | F37: Fibra Optica | G37: 172.20.10.35 | H37: =COUNTIF(K37:AO37,"") -> 31 | I37: =COUNTIF(K37:AL37,"APAGADO") -> 0 | J37: =(H37)/(I37+H37) -> 1
A38: CENTRO | B38: CEN16 | C38: BONOMO | D38: San Martin y Pte. Peron | E38: Fija | F38: Fibra Optica | G38: 172.20.12.36 | H38: =COUNTIF(K38:AO38,"") -> 31 | I38: =COUNTIF(K38:AL38,"APAGADO") -> 0 | J38: =(H38)/(I38+H38) -> 1
A39: CENTRO | B39: CEN17 | C39: BONOMO | D39: San Martin y Mitre | E39: Domo | F39: PTO A FO | G39: 172.20.12.200 | H39: =COUNTIF(K39:AO39,"") -> 31 | I39: =COUNTIF(K39:AL39,"APAGADO") -> 0 | J39: =(H39)/(I39+H39) -> 1
A40: CENTRO | B40: CEN18 | C40: BONOMO | D40: Monteagudo e/Mitre y Sallares | E40: Fija | F40: Fibra Optica | G40: 172.20.10.26 | H40: =COUNTIF(K40:AO40,"") -> 4 | I40: =COUNTIF(K40:AL40,"APAGADO") -> 27 | J40: =(H40)/(I40+H40) -> 0.12903226 | K40: APAGADO | L40: APAGADO | M40: APAGADO | N40: APAGADO | O40: APAGADO | P40: APAGADO | Q40: APAGADO | R40: APAGADO | S40: APAGADO | T40: APAGADO | U40: APAGADO | V40: APAGADO | W40: APAGADO | X40: APAGADO | Y40: APAGADO | Z40: APAGADO | AA40: APAGADO | AB40: APAGADO | AC40: APAGADO | AD40: APAGADO | AE40: APAGADO | AF40: APAGADO | AG40: APAGADO | AH40: APAGADO | AI40: APAGADO | AJ40: APAGADO | AK40: APAGADO
...

Sheet ESTADISTICA
A1: ='RESUMEN TOTAL'!A4 -> Barrio | B1: ='RESUMEN TOTAL'!B4 -> [Denominacion] | C1: ='RESUMEN TOTAL'!D4 -> [Ubicacion] | D1: ='RESUMEN TOTAL'!E4 -> [Tipo de Camara] | E1: ='RESUMEN TOTAL'!F4 -> [Tipo de Conexion] | F1: ='RESUMEN TOTAL'!K4 -> 44896 | G1: ='RESUMEN TOTAL'!L4 -> 44897 | H1: ='RESUMEN TOTAL'!M4 -> 44898 | I1: ='RESUMEN TOTAL'!N4 -> 44899 | J1: ='RESUMEN TOTAL'!O4 -> 44900 | K1: ='RESUMEN TOTAL'!P4 -> 44901 | L1: ='RESUMEN TOTAL'!Q4 -> 44902 | M1: ='RESUMEN TOTAL'!R4 -> 44903 | ... AI1: ='RESUMEN TOTAL'!AN4 -> 44925
A2: ='RESUMEN TOTAL'!A5 -> ALTAMIRA | B2: ='RESUMEN TOTAL'!B5 -> ALT01 | C2: ='RESUMEN TOTAL'!D5 -> Calchaqui y Sgto. Cabral | D2: ='RESUMEN TOTAL'!E5 -> Domo | E2: ='RESUMEN TOTAL'!F5 -> Fibra Optica | F2: ='RESUMEN TOTAL'!K5 -> APAGADO | G2: ='RESUMEN TOTAL'!L5 -> APAGADO | H2: ='RESUMEN TOTAL'!M5 -> APAGADO | I2: ='RESUMEN TOTAL'!N5 -> APAGADO | J2: ='RESUMEN TOTAL'!O5 -> APAGADO | K2: ='RESUMEN TOTAL'!P5 -> APAGADO | L2: ='RESUMEN TOTAL'!Q5 -> APAGADO | M2: ='RESUMEN TOTAL'!R5 -> APAGADO | ... AI2: ='RESUMEN TOTAL'!AN5 -> 0
A3: ='RESUMEN TOTAL'!A6 -> ALTAMIRA | B3: ='RESUMEN TOTAL'!B6 -> ALT02 | C3: ='RESUMEN TOTAL'!D6 -> Calchaqui y Lope de Vega | D3: ='RESUMEN TOTAL'!E6 -> Domo | E3: ='RESUMEN TOTAL'!F6 -> PTO A FO | F3: ='RESUMEN TOTAL'!K6 -> APAGADO | G3: ='RESUMEN TOTAL'!L6 -> APAGADO | H3: ='RESUMEN TOTAL'!M6 -> APAGADO | I3: ='RESUMEN TOTAL'!N6 -> APAGADO | J3: ='RESUMEN TOTAL'!O6 -> APAGADO | K3: ='RESUMEN TOTAL'!P6 -> APAGADO | L3: ='RESUMEN TOTAL'!Q6 -> APAGADO | M3: ='RESUMEN TOTAL'!R6 -> APAGADO | ... AI3: ='RESUMEN TOTAL'!AN6 -> 0
A4: ='RESUMEN TOTAL'!A7 -> ALTAMIRA | B4: ='RESUMEN TOTAL'!B7 -> ALT 03 | C4: ='RESUMEN TOTAL'!D7 -> Bombero Galarza y Necochea | D4: ='RESUMEN TOTAL'!E7 -> Domo | E4: ='RESUMEN TOTAL'!F7 -> FIBRA OPTICA | F4: ='RESUMEN TOTAL'!K7 -> APAGADO | G4: ='RESUMEN TOTAL'!L7 -> APAGADO | H4: ='RESUMEN TOTAL'!M7 -> APAGADO | I4: ='RESUMEN TOTAL'!N7 -> APAGADO | J4: ='RESUMEN TOTAL'!O7 -> APAGADO | K4: ='RESUMEN TOTAL'!P7 -> APAGADO | L4: ='RESUMEN TOTAL'!Q7 -> APAGADO | M4: ='RESUMEN TOTAL'!R7 -> APAGADO | ... AI4: ='RESUMEN TOTAL'!AN7 -> 0
A5: ='RESUMEN TOTAL'!A8 -> ALTAMIRA | B5: ='RESUMEN TOTAL'!B8 -> ALT 04 | C5: ='RESUMEN TOTAL'!D8 -> Francia y Necochea | D5: ='RESUMEN TOTAL'!E8 -> Domo | E5: ='RESUMEN TOTAL'!F8 -> FIBRA OPTICA | F5: ='RESUMEN TOTAL'!K8 -> APAGADO | G5: ='RESUMEN TOTAL'!L8 -> APAGADO | H5: ='RESUMEN TOTAL'!M8 -> APAGADO | I5: ='RESUMEN TOTAL'!N8 -> APAGADO | J5: ='RESUMEN TOTAL'!O8 -> APAGADO | K5: ='RESUMEN TOTAL'!P8 -> APAGADO | L5: ='RESUMEN TOTAL'!Q8 -> APAGADO | M5: ='RESUMEN TOTAL'!R8 -> APAGADO | ... AI5: ='RESUMEN TOTAL'!AN8 -> 0
A6: ='RESUMEN TOTAL'!A9 -> ALTAMIRA | B6: ='RESUMEN TOTAL'!B9 -> ALT05 | C6: ='RESUMEN TOTAL'!D9 -> Av. Calchaqui y Bombero Galarza | D6: ='RESUMEN TOTAL'!E9 -> Domo | E6: ='RESUMEN TOTAL'!F9 -> PTO A FO | F6: ='RESUMEN TOTAL'!K9 -> APAGADO | G6: ='RESUMEN TOTAL'!L9 -> APAGADO | H6: ='RESUMEN TOTAL'!M9 -> APAGADO | I6: ='RESUMEN TOTAL'!N9 -> APAGADO | J6: ='RESUMEN TOTAL'!O9 -> APAGADO | K6: ='RESUMEN TOTAL'!P9 -> APAGADO | L6: ='RESUMEN TOTAL'!Q9 -> APAGADO | M6: ='RESUMEN TOTAL'!R9 -> APAGADO | ... AI6: ='RESUMEN TOTAL'!AN9 -> 0
A7: ='RESUMEN TOTAL'!A10 -> ALTAMIRA | B7: ='RESUMEN TOTAL'!B10 -> ALT 06 | C7: ='RESUMEN TOTAL'!D10 -> LOPE DE VEGA Y NECOCHEA | D7: ='RESUMEN TOTAL'!E10 -> Domo | E7: ='RESUMEN TOTAL'!F10 -> PTO A FO | F7: ='RESUMEN TOTAL'!K10 -> APAGADO | G7: ='RESUMEN TOTAL'!L10 -> APAGADO | H7: ='RESUMEN TOTAL'!M10 -> APAGADO | I7: ='RESUMEN TOTAL'!N10 -> APAGADO | J7: ='RESUMEN TOTAL'!O10 -> APAGADO | K7: ='RESUMEN TOTAL'!P10 -> APAGADO | L7: ='RESUMEN TOTAL'!Q10 -> APAGADO | M7: ='RESUMEN TOTAL'!R10 -> APAGADO | ... AI7: ='RESUMEN TOTAL'!AN10 -> 0
A8: ='RESUMEN TOTAL'!A11 -> ALTAMIRA | B8: ='RESUMEN TOTAL'!B11 -> ALT07 | C8: ='RESUMEN TOTAL'!D11 -> AV. CALCHAQUI Y AV. DEL TRABAJO | D8: ='RESUMEN TOTAL'!E11 -> DOMO | E8: ='RESUMEN TOTAL'!F11 -> PTO A FO | F8: ='RESUMEN TOTAL'!K11 -> APAGADO | G8: ='RESUMEN TOTAL'!L11 -> APAGADO | H8: ='RESUMEN TOTAL'!M11 -> APAGADO | I8: ='RESUMEN TOTAL'!N11 -> APAGADO | J8: ='RESUMEN TOTAL'!O11 -> APAGADO | K8: ='RESUMEN TOTAL'!P11 -> APAGADO | L8: ='RESUMEN TOTAL'!Q11 -> APAGADO | M8: ='RESUMEN TOTAL'!R11 -> APAGADO | ... AI8: ='RESUMEN TOTAL'!AN11 -> 0
A9: ='RESUMEN TOTAL'!A12 -> ALTAMIRA | B9: ='RESUMEN TOTAL'!B12 -> ALT 08 | C9: ='RESUMEN TOTAL'!D12 -> HUMAITA Y NECOCHEA | D9: ='RESUMEN TOTAL'!E12 -> DOMO | E9: ='RESUMEN TOTAL'!F12 -> Fibra Optica | F9: ='RESUMEN TOTAL'!K12 -> APAGADO | G9: ='RESUMEN TOTAL'!L12 -> APAGADO | H9: ='RESUMEN TOTAL'!M12 -> APAGADO | I9: ='RESUMEN TOTAL'!N12 -> APAGADO | J9: ='RESUMEN TOTAL'!O12 -> APAGADO | K9: ='RESUMEN TOTAL'!P12 -> APAGADO | L9: ='RESUMEN TOTAL'!Q12 -> APAGADO | M9: ='RESUMEN TOTAL'!R12 -> APAGADO | ... AI9: ='RESUMEN TOTAL'!AN12 -> 0
A10: ='RESUMEN TOTAL'!A13 -> ALTAMIRA | B10: ='RESUMEN TOTAL'!B13 -> ALT 09 | C10: ='RESUMEN TOTAL'!D13 -> NECOCHEA Y CURUPAITY | D10: ='RESUMEN TOTAL'!E13 -> DOMO | E10: ='RESUMEN TOTAL'!F13 -> Fibra Optica | F10: ='RESUMEN TOTAL'!K13 -> APAGADO | G10: ='RESUMEN TOTAL'!L13 -> APAGADO | H10: ='RESUMEN TOTAL'!M13 -> APAGADO | I10: ='RESUMEN TOTAL'!N13 -> APAGADO | J10: ='RESUMEN TOTAL'!O13 -> APAGADO | K10: ='RESUMEN TOTAL'!P13 -> APAGADO | L10: ='RESUMEN TOTAL'!Q13 -> APAGADO | M10: ='RESUMEN TOTAL'!R13 -> APAGADO | ... AI10: ='RESUMEN TOTAL'!AN13 -> 0
A11: ='RESUMEN TOTAL'!A14 -> ALTAMIRA | B11: ='RESUMEN TOTAL'!B14 -> ALT 10 | C11: ='RESUMEN TOTAL'!D14 -> Calchaqui y Francia | D11: ='RESUMEN TOTAL'!E14 -> Domo | E11: ='RESUMEN TOTAL'!F14 -> Radio | F11: ='RESUMEN TOTAL'!K14 -> APAGADO | G11: ='RESUMEN TOTAL'!L14 -> APAGADO | H11: ='RESUMEN TOTAL'!M14 -> APAGADO | I11: ='RESUMEN TOTAL'!N14 -> APAGADO | J11: ='RESUMEN TOTAL'!O14 -> APAGADO | K11: ='RESUMEN TOTAL'!P14 -> APAGADO | L11: ='RESUMEN TOTAL'!Q14 -> APAGADO | M11: ='RESUMEN TOTAL'!R14 -> APAGADO | ... AI11: ='RESUMEN TOTAL'!AN14 -> 0
A12: ='RESUMEN TOTAL'!A15 -> AGUSTIN RAMIREZ | B12: ='RESUMEN TOTAL'!B15 -> ARA 01 | C12: ='RESUMEN TOTAL'!D15 -> Malambo y Tranquera | D12: ='RESUMEN TOTAL'!E15 -> Domo | E12: ='RESUMEN TOTAL'!F15 -> FIBRA OPTICA | F12: ='RESUMEN TOTAL'!K15 -> 0 | G12: ='RESUMEN TOTAL'!L15 -> 0 | H12: ='RESUMEN TOTAL'!M15 -> 0 | I12: ='RESUMEN TOTAL'!N15 -> 0 | J12: ='RESUMEN TOTAL'!O15 -> 0 | K12: ='RESUMEN TOTAL'!P15 -> 0 | L12: ='RESUMEN TOTAL'!Q15 -> 0 | M12: ='RESUMEN TOTAL'!R15 -> 0 | ... AI12: ='RESUMEN TOTAL'!AN15 -> 0
... A19: ='RESUMEN TOTAL'!A22 -> BOSQUES CENTRO | B19: ='RESUMEN TOTAL'!B22 -> BOSQC 06 | C19: ='RESUMEN TOTAL'!D22 -> LUIS AGOTE Y RUTA 36 | D19: ='RESUMEN TOTAL'!E22 -> Fija | E19: ='RESUMEN TOTAL'!F22 -> Radio | F19: ='RESUMEN TOTAL'!K22 -> APAGADO | G19: ='RESUMEN TOTAL'!L22 -> APAGADO | H19: ='RESUMEN TOTAL'!M22 -> APAGADO | I19: ='RESUMEN TOTAL'!N22 -> APAGADO | J19: ='RESUMEN TOTAL'!O22 -> APAGADO | K19: ='RESUMEN TOTAL'!P22 -> 0 | L19: ='RESUMEN TOTAL'!Q22 -> 0 | M19: ='RESUMEN TOTAL'!R22 -> 0 | ... AI19: ='RESUMEN TOTAL'!AN22 -> 0
A20: ='RESUMEN TOTAL'!A265 -> RICARDO ROJAS | B20: ='RESUMEN TOTAL'!B265 -> RRJ 12 | C20: ='RESUMEN TOTAL'!D265 -> FADER Y DIAGONAL LOS POETAS | D20: ='RESUMEN TOTAL'!E265 -> Fija | E20: ='RESUMEN TOTAL'!F265 -> Fibra Optica | F20: ='RESUMEN TOTAL'!K265 -> APAGADO | G20: ='RESUMEN TOTAL'!L265 -> APAGADO | H20: ='RESUMEN TOTAL'!M265 -> APAGADO | I20: ='RESUMEN TOTAL'!N265 -> APAGADO | J20: ='RESUMEN TOTAL'!O265 -> APAGADO | K20: ='RESUMEN TOTAL'!P265 -> 0 | L20: ='RESUMEN TOTAL'!Q265 -> 0 | M20: ='RESUMEN TOTAL'!R265 -> 0 | ... AI20: ='RESUMEN TOTAL'!AN265 -> 0
A21: ='RESUMEN TOTAL'!A23 -> CENTRO | B21: ='RESUMEN TOTAL'!B23 -> CEN01 | C21: ='RESUMEN TOTAL'!D23 -> San Martin y 9 de Julio | D21: ='RESUMEN TOTAL'!E23 -> Fija | E21: ='RESUMEN TOTAL'!F23 -> Fibra Optica | F21: ='RESUMEN TOTAL'!K23 -> 0 | G21: ='RESUMEN TOTAL'!L23 -> 0 | H21: ='RESUMEN TOTAL'!M23 -> 0 | I21: ='RESUMEN TOTAL'!N23 -> 0 | J21: ='RESUMEN TOTAL'!O23 -> 0 | K21: ='RESUMEN TOTAL'!P23 -> 0 | L21: ='RESUMEN TOTAL'!Q23 -> 0 | M21: ='RESUMEN TOTAL'!R23 -> 0 | ... AI21: ='RESUMEN TOTAL'!AN23 -> 0
A22: ='RESUMEN TOTAL'!A24 -> CENTRO | B22: ='RESUMEN TOTAL'!B24 -> CEN02 | C22: ='RESUMEN TOTAL'!D24 -> San Martin y Almafuerte | D22: ='RESUMEN TOTAL'!E24 -> Fija | E22: ='RESUMEN TOTAL'!F24 -> Fibra Optica | F22: ='RESUMEN TOTAL'!K24 -> 0 | G22: ='RESUMEN TOTAL'!L24 -> 0 | H22: ='RESUMEN TOTAL'!M24 -> 0 | I22: ='RESUMEN TOTAL'!N24 -> 0 | J22: ='RESUMEN TOTAL'!O24 -> 0 | K22: ='RESUMEN TOTAL'!P24 -> 0 | L22: ='RESUMEN TOTAL'!Q24 -> 0 | M22: ='RESUMEN TOTAL'!R24 -> 0 | ... AI22: ='RESUMEN TOTAL'!AN24 -> 0
A23: ='RESUMEN TOTAL'!A25 -> CENTRO | B23: ='RESUMEN TOTAL'!B25 -> CEN03 | C23: ='RESUMEN TOTAL'!D25 -> San Martin y Sallares | D23: ='RESUMEN TOTAL'!E25 -> Domo | E23: ='RESUMEN TOTAL'!F25 -> Fibra Optica | F23: ='RESUMEN TOTAL'!K25 -> 0 | G23: ='RESUMEN TOTAL'!L25 -> 0 | H23: ='RESUMEN TOTAL'!M25 -> 0 | I23: ='RESUMEN TOTAL'!N25 -> 0 | J23: ='RESUMEN TOTAL'!O25 -> 0 | K23: ='RESUMEN TOTAL'!P25 -> 0 | L23: ='RESUMEN TOTAL'!Q25 -> 0 | M23: ='RESUMEN TOTAL'!R25 -> 0 | ... AI23: ='RESUMEN TOTAL'!AN25 -> 0
A24: ='RESUMEN TOTAL'!A26 -> CENTRO | B24: ='RESUMEN TOTAL'!B26 -> CEN04 | C24: ='RESUMEN TOTAL'!D26 -> San Martin y Contreras | D24: ='RESUMEN TOTAL'!E26 -> Domo | E24: ='RESUMEN TOTAL'!F26 -> Fibra Optica | F24: ='RESUMEN TOTAL'!K26 -> 0 | G24: ='RESUMEN TOTAL'!L26 -> 0 | H24: ='RESUMEN TOTAL'!M26 -> 0 | I24: ='RESUMEN TOTAL'!N26 -> 0 | J24: ='RESUMEN TOTAL'!O26 -> 0 | K24: ='RESUMEN TOTAL'!P26 -> 0 | L24: ='RESUMEN TOTAL'!Q26 -> 0 | M24: ='RESUMEN TOTAL'!R26 -> 0 | ... AI24: ='RESUMEN TOTAL'!AN26 -> 0
A25: ='RESUMEN TOTAL'!A27 -> CENTRO | B25: ='RESUMEN TOTAL'!B27 -> CEN 05 | C25: ='RESUMEN TOTAL'!D27 -> Bocuzzi e/España y San Martin | D25: ='RESUMEN TOTAL'!E27 -> DOMO | E25: ='RESUMEN TOTAL'!F27 -> Fibra Optica | F25: ='RESUMEN TOTAL'!K27 -> APAGADO | G25: ='RESUMEN TOTAL'!L27 -> APAGADO | H25: ='RESUMEN TOTAL'!M27 -> 0 | I25: ='RESUMEN TOTAL'!N27 -> 0 | J25: ='RESUMEN TOTAL'!O27 -> 0 | K25: ='RESUMEN TOTAL'!P27 -> 0 | L25: ='RESUMEN TOTAL'!Q27 -> 0 | M25: ='RESUMEN TOTAL'!R27 -> 0 | ... AI25: ='RESUMEN TOTAL'!AN27 -> 0
A26: ='RESUMEN TOTAL'!A28 -> CENTRO | B26: ='RESUMEN TOTAL'!B28 -> CEN06 | C26: ='RESUMEN TOTAL'!D28 -> Monteagudo y A.del Valle | D26: ='RESUMEN TOTAL'!E28 -> Fija | E26: ='RESUMEN TOTAL'!F28 -> Fibra Optica | F26: ='RESUMEN TOTAL'!K28 -> 0 | G26: ='RESUMEN TOTAL'!L28 -> 0 | H26: ='RESUMEN TOTAL'!M28 -> 0 | I26: ='RESUMEN TOTAL'!N28 -> 0 | J26: ='RESUMEN TOTAL'!O28 -> 0 | K26: ='RESUMEN TOTAL'!P28 -> 0 | L26: ='RESUMEN TOTAL'!Q28 -> 0 | M26: ='RESUMEN TOTAL'!R28 -> 0 | ... AI26: ='RESUMEN TOTAL'!AN28 -> 0
A27: ='RESUMEN TOTAL'!A29 -> CENTRO | B27: ='RESUMEN TOTAL'!B29 -> CEN07 | C27: ='RESUMEN TOTAL'!D29 -> San Martin y Guemes | D27: ='RESUMEN TOTAL'!E29 -> DOMO | E27: ='RESUMEN TOTAL'!F29 -> Fibra Optica | F27: ='RESUMEN TOTAL'!K29 -> 0 | G27: ='RESUMEN TOTAL'!L29 -> 0 | H27: ='RESUMEN TOTAL'!M29 -> 0 | I27: ='RESUMEN TOTAL'!N29 -> 0 | J27: ='RESUMEN TOTAL'!O29 -> 0 | K27: ='RESUMEN TOTAL'!P29 -> 0 | L27: ='RESUMEN TOTAL'!Q29 -> 0 | M27: ='RESUMEN TOTAL'!R29 -> 0 | ... AI27: ='RESUMEN TOTAL'!AN29 -> 0
A28: ='RESUMEN TOTAL'!A30 -> CENTRO | B28: ='RESUMEN TOTAL'!B30 -> CEN08 | C28: ='RESUMEN TOTAL'!D30 -> San Martin y Pte.Peron | D28: ='RESUMEN TOTAL'!E30 -> Domo | E28: ='RESUMEN TOTAL'!F30 -> Fibra Optica | F28: ='RESUMEN TOTAL'!K30 -> 0 | G28: ='RESUMEN TOTAL'!L30 -> 0 | H28: ='RESUMEN TOTAL'!M30 -> 0 | I28: ='RESUMEN TOTAL'!N30 -> 0 | J28: ='RESUMEN TOTAL'!O30 -> 0 | K28: ='RESUMEN TOTAL'!P30 -> 0 | L28: ='RESUMEN TOTAL'!Q30 -> 0 | M28: ='RESUMEN TOTAL'!R30 -> 0 | ... AI28: ='RESUMEN TOTAL'!AN30 -> 0
A29: ='RESUMEN TOTAL'!A31 -> CENTRO | B29: ='RESUMEN TOTAL'!B31 -> CEN09 | C29: ='RESUMEN TOTAL'!D31 -> Chacabuco y 25 de Mayo | D29: ='RESUMEN TOTAL'!E31 -> Domo | E29: ='RESUMEN TOTAL'!F31 -> Fibra Optica | F29: ='RESUMEN TOTAL'!K31 -> 0 | G29: ='RESUMEN TOTAL'!L31 -> 0 | H29: ='RESUMEN TOTAL'!M31 -> 0 | I29: ='RESUMEN TOTAL'!N31 -> 0 | J29: ='RESUMEN TOTAL'!O31 -> 0 | K29: ='RESUMEN TOTAL'!P31 -> 0 | L29: ='RESUMEN TOTAL'!Q31 -> 0 | M29: ='RESUMEN TOTAL'!R31 -> 0 | ... AI29: ='RESUMEN TOTAL'!AN31 -> 0
A30: ='RESUMEN TOTAL'!A32 -> CENTRO | B30: ='RESUMEN TOTAL'!B32 -> CEN10 | C30: ='RESUMEN TOTAL'!D32 -> Monteagudo y Pte. Peron | D30: ='RESUMEN TOTAL'!E32 -> Domo | E30: ='RESUMEN TOTAL'!F32 -> Fibra Optica | F30: ='RESUMEN TOTAL'!K32 -> 0 | G30: ='RESUMEN TOTAL'!L32 -> 0 | H30: ='RESUMEN TOTAL'!M32 -> 0 | I30: ='RESUMEN TOTAL'!N32 -> 0 | J30: ='RESUMEN TOTAL'!O32 -> 0 | K30: ='RESUMEN TOTAL'!P32 -> 0 | L30: ='RESUMEN TOTAL'!Q32 -> 0 | M30: ='RESUMEN TOTAL'!R32 -> 0 | ... AI30: ='RESUMEN TOTAL'!AN32 -> 0
A31: ='RESUMEN TOTAL'!A33 -> CENTRO | B31: ='RESUMEN TOTAL'!B33 -> CEN11 | C31: ='RESUMEN TOTAL'!D33 -> Monteagudo y Bocuzzi | D31: ='RESUMEN TOTAL'!E33 -> Domo | E31: ='RESUMEN TOTAL'!F33 -> Fibra Optica | F31: ='RESUMEN TOTAL'!K33 -> 0 | G31: ='RESUMEN TOTAL'!L33 -> 0 | H31: ='RESUMEN TOTAL'!M33 -> 0 | I31: ='RESUMEN TOTAL'!N33 -> 0 | J31: ='RESUMEN TOTAL'!O33 -> 0 | K31: ='RESUMEN TOTAL'!P33 -> 0 | L31: ='RESUMEN TOTAL'!Q33 -> 0 | M31: ='RESUMEN TOTAL'!R33 -> 0 | ... AI31: ='RESUMEN TOTAL'!AN33 -> 0
A32: ='RESUMEN TOTAL'!A34 -> CENTRO | B32: ='RESUMEN TOTAL'!B34 -> CEN 12 | C32: ='RESUMEN TOTAL'!D34 -> Monteagudo y Mitre | D32: ='RESUMEN TOTAL'!E34 -> Domo | E32: ='RESUMEN TOTAL'!F34 -> Fibra Optica | F32: ='RESUMEN TOTAL'!K34 -> APAGADO | G32: ='RESUMEN TOTAL'!L34 -> APAGADO | H32: ='RESUMEN TOTAL'!M34 -> APAGADO | I32: ='RESUMEN TOTAL'!N34 -> APAGADO | J32: ='RESUMEN TOTAL'!O34 -> APAGADO | K32: ='RESUMEN TOTAL'!P34 -> APAGADO | L32: ='RESUMEN TOTAL'!Q34 -> APAGADO | M32: ='RESUMEN TOTAL'!R34 -> APAGADO | ... AI32: ='RESUMEN TOTAL'!AN34 -> 0
... A121: ='RESUMEN TOTAL'!A123 -> EL PARQUE | B121: ='RESUMEN TOTAL'!B123 -> EPQ 04 | C121: ='RESUMEN TOTAL'!D123 -> 1282 Y MORENO | D121: ='RESUMEN TOTAL'!E123 -> DOMO | E121: ='RESUMEN TOTAL'!F123 -> Fibra Optica | F121: ='RESUMEN TOTAL'!K123 -> APAGADO | G121: ='RESUMEN TOTAL'!L123 -> 0 | H121: ='RESUMEN TOTAL'!M123 -> 0 | I121: ='RESUMEN TOTAL'!N123 -> 0 | J121: ='RESUMEN TOTAL'!O123 -> 0 | K121: ='RESUMEN TOTAL'!P123 -> 0 | L121: ='RESUMEN TOTAL'!Q123 -> 0 | M121: ='RESUMEN TOTAL'!R123 -> 0 | ... AI121: ='RESUMEN TOTAL'!AN123 -> 0
A122: ='RESUMEN TOTAL'!A131 -> LA ESMERALDA | B122: ='RESUMEN TOTAL'!B131 -> ESM 08 | C122: ='RESUMEN TOTAL'!D131 -> DAVINSON Y MORANCHEL | D122: ='RESUMEN TOTAL'!E131 -> FIJA | E122: ='RESUMEN TOTAL'!F131 -> Radio | F122: ='RESUMEN TOTAL'!K131 -> 0 | G122: ='RESUMEN TOTAL'!L131 -> 0 | H122: ='RESUMEN TOTAL'!M131 -> 0 | I122: ='RESUMEN TOTAL'!N131 -> 0 | J122: ='RESUMEN TOTAL'!O131 -> 0 | K122: ='RESUMEN TOTAL'!P131 -> 0 | L122: ='RESUMEN TOTAL'!Q131 -> 0 | M122: ='RESUMEN TOTAL'!R131 -> 0 | ... AI122: ='RESUMEN TOTAL'!AN131 -> 0
A123: ='RESUMEN TOTAL'!A124 -> LA ESMERALDA | B123: ='RESUMEN TOTAL'!B124 -> ESM01 | C123: ='RESUMEN TOTAL'!D124 -> Cabello y Brasil | D123: ='RESUMEN TOTAL'!E124 -> Domo | E123: ='RESUMEN TOTAL'!F124 -> Radio | F123: ='RESUMEN TOTAL'!K124 -> APAGADO | G123: ='RESUMEN TOTAL'!L124 -> APAGADO | H123: ='RESUMEN TOTAL'!M124 -> APAGADO | I123: ='RESUMEN TOTAL'!N124 -> APAGADO | J123: ='RESUMEN TOTAL'!O124 -> APAGADO | K123: ='RESUMEN TOTAL'!P124 -> APAGADO | L123: ='RESUMEN TOTAL'!Q124 -> APAGADO | M123: ='RESUMEN TOTAL'!R124 -> APAGADO | ... AI123: ='RESUMEN TOTAL'!AN124 -> 0
A124: ='RESUMEN TOTAL'!A125 -> SAN JORGE | B124: ='RESUMEN TOTAL'!B125 -> ESM02 | C124: ='RESUMEN TOTAL'!D125 -> Novak y Cabello | D124: ='RESUMEN TOTAL'!E125 -> Domo | E124: ='RESUMEN TOTAL'!F125 -> PTO A FO | F124: ='RESUMEN TOTAL'!K125 -> 0 | G124: ='RESUMEN TOTAL'!L125 -> 0 | H124: ='RESUMEN TOTAL'!M125 -> 0 | I124: ='RESUMEN TOTAL'!N125 -> 0 | J124: ='RESUMEN TOTAL'!O125 -> 0 | K124: ='RESUMEN TOTAL'!P125 -> 0 | L124: ='RESUMEN TOTAL'!Q125 -> 0 | M124: ='RESUMEN TOTAL'!R125 -> 0 | ... AI124: ='RESUMEN TOTAL'!AN125 -> 0
A125: ='RESUMEN TOTAL'!A126 -> LIBERTAD | B125: ='RESUMEN TOTAL'!B126 -> ESM03 | C125: ='RESUMEN TOTAL'!D126 -> Novak y Humahuaca | D125: ='RESUMEN TOTAL'!E126 -> DOMO | E125: ='RESUMEN TOTAL'!F126 -> PTO A FO | F125: ='RESUMEN TOTAL'!K126 -> 0 | G125: ='RESUMEN TOTAL'!L126 -> 0 | H125: ='RESUMEN TOTAL'!M126 -> 0 | I125: ='RESUMEN TOTAL'!N126 -> 0 | J125: ='RESUMEN TOTAL'!O126 -> 0 | K125: ='RESUMEN TOTAL'!P126 -> 0 | L125: ='RESUMEN TOTAL'!Q126 -> 0 | M125: ='RESUMEN TOTAL'!R126 -> 0 | ... AI125: ='RESUMEN TOTAL'!AN126 -> 0
A126: ='RESUMEN TOTAL'!A127 -> LA ESMERALDA | B126: ='RESUMEN TOTAL'!B127 -> ESM04 | C126: ='RESUMEN TOTAL'!D127 -> Basualdo y Bengochea | D126: ='RESUMEN TOTAL'!E127 -> Domo | E126: ='RESUMEN TOTAL'!F127 -> FIBRA OPTICA | F126: ='RESUMEN TOTAL'!K127 -> 0 | G126: ='RESUMEN TOTAL'!L127 -> 0 | H126: ='RESUMEN TOTAL'!M127 -> 0 | I126: ='RESUMEN TOTAL'!N127 -> 0 | J126: ='RESUMEN TOTAL'!O127 -> 0 | K126: ='RESUMEN TOTAL'!P127 -> 0 | L126: ='RESUMEN TOTAL'!Q127 -> 0 | M126: ='RESUMEN TOTAL'!R127 -> 0 | ... AI126: ='RESUMEN TOTAL'!AN127 -> 0
A127: ='RESUMEN TOTAL'!A128 -> LA ESMERALDA | B127: ='RESUMEN TOTAL'!B128 -> ESM05 | C127: ='RESUMEN TOTAL'!D128 -> Aniceto Diaz y Villar | D127: ='RESUMEN TOTAL'!E128 -> Domo | E127: ='RESUMEN TOTAL'!F128 -> FIBRA OPTICA | F127: ='RESUMEN TOTAL'!K128 -> 0 | G127: ='RESUMEN TOTAL'!L128 -> 0 | H127: ='RESUMEN TOTAL'!M128 -> 0 | I127: ='RESUMEN TOTAL'!N128 -> 0 | J127: ='RESUMEN TOTAL'!O128 -> 0 | K127: ='RESUMEN TOTAL'!P128 -> 0 | L127: ='RESUMEN TOTAL'!Q128 -> 0 | M127: ='RESUMEN TOTAL'!R128 -> 0 | ... AI127: ='RESUMEN TOTAL'!AN128 -> 0
A128: ='RESUMEN TOTAL'!A129 -> LA ESMERALDA | B128: ='RESUMEN TOTAL'!B129 -> ESM06 | C128: ='RESUMEN TOTAL'!D129 -> Roselli y Cabello | D128: ='RESUMEN TOTAL'!E129 -> Domo | E128: ='RESUMEN TOTAL'!F129 -> Radio | F128: ='RESUMEN TOTAL'!K129 -> 0 | G128: ='RESUMEN TOTAL'!L129 -> 0 | H128: ='RESUMEN TOTAL'!M129 -> 0 | I128: ='RESUMEN TOTAL'!N129 -> 0 | J128: ='RESUMEN TOTAL'!O129 -> 0 | K128: ='RESUMEN TOTAL'!P129 -> 0 | L128: ='RESUMEN TOTAL'!Q129 -> 0 | M128: ='RESUMEN TOTAL'!R129 -> 0 | ... AI128: ='RESUMEN TOTAL'!AN129 -> 0
A129: ='RESUMEN TOTAL'!A130 -> LA ESMERALDA | B129: ='RESUMEN TOTAL'!B130 -> ESM07 | C129: ='RESUMEN TOTAL'!D130 -> AV. NOVAK Y SERRANO | D129: ='RESUMEN TOTAL'!E130 -> DOMO | E129: ='RESUMEN TOTAL'!F130 -> PTO A FO | F129: ='RESUMEN TOTAL'!K130 -> 0 | G129: ='RESUMEN TOTAL'!L130 -> 0 | H129: ='RESUMEN TOTAL'!M130 -> 0 | I129: ='RESUMEN TOTAL'!N130 -> 0 | J129: ='RESUMEN TOTAL'!O130 -> 0 | K129: ='RESUMEN TOTAL'!P130 -> 0 | L129: ='RESUMEN TOTAL'!Q130 -> 0 | M129: ='RESUMEN TOTAL'!R130 -> 0 | ... AI129: ='RESUMEN TOTAL'!AN130 -> 0
A130: ='RESUMEN TOTAL'!A132 -> LA ESMERALDA | B130: ='RESUMEN TOTAL'!B132 -> ESM09 (fija 1) | C130: ='RESUMEN TOTAL'!D132 -> EEUU Y CABELLO | D130: ='RESUMEN TOTAL'!E132 -> Fija | E130: ='RESUMEN TOTAL'!F132 -> Fibra Optica | F130: ='RESUMEN TOTAL'!K132 -> 0 | G130: ='RESUMEN TOTAL'!L132 -> 0 | H130: ='RESUMEN TOTAL'!M132 -> 0 | I130: ='RESUMEN TOTAL'!N132 -> 0 | J130: ='RESUMEN TOTAL'!O132 -> 0 | K130: ='RESUMEN TOTAL'!P132 -> 0 | L130: ='RESUMEN TOTAL'!Q132 -> 0 | M130: ='RESUMEN TOTAL'!R132 -> 0 | ... AI130: ='RESUMEN TOTAL'!AN132 -> 0
A131: ='RESUMEN TOTAL'!A133 -> LA ESMERALDA | B131: ='RESUMEN TOTAL'!B133 -> ESM10 (fija 2) | C131: ='RESUMEN TOTAL'!D133 -> EEUU Y CABELLO | D131: ='RESUMEN TOTAL'!E133 -> Fija | E131: ='RESUMEN TOTAL'!F133 -> Fibra Optica | F131: ='RESUMEN TOTAL'!K133 -> 0 | G131: ='RESUMEN TOTAL'!L133 -> 0 | H131: ='RESUMEN TOTAL'!M133 -> 0 | I131: ='RESUMEN TOTAL'!N133 -> 0 | J131: ='RESUMEN TOTAL'!O133 -> 0 | K131: ='RESUMEN TOTAL'!P133 -> 0 | L131: ='RESUMEN TOTAL'!Q133 -> 0 | M131: ='RESUMEN TOTAL'!R133 -> 0 | ... AI131: ='RESUMEN TOTAL'!AN133 -> 0
A132: ='RESUMEN TOTAL'!A134 -> LA ESMERALDA | B132: ='RESUMEN TOTAL'!B134 -> ESM11 (fija 1) | C132: ='RESUMEN TOTAL'!D134 -> NOVAK Y LAMBARDI | D132: ='RESUMEN TOTAL'!E134 -> Fija | E132: ='RESUMEN TOTAL'!F134 -> Fibra Optica | F132: ='RESUMEN TOTAL'!K134 -> 0 | G132: ='RESUMEN TOTAL'!L134 -> 0 | H132: ='RESUMEN TOTAL'!M134 -> 0 | I132: ='RESUMEN TOTAL'!N134 -> 0 | J132: ='RESUMEN TOTAL'!O134 -> 0 | K132: ='RESUMEN TOTAL'!P134 -> 0 | L132: ='RESUMEN TOTAL'!Q134 -> APAGADO | M132: ='RESUMEN TOTAL'!R134 -> 0 | ... AI132: ='RESUMEN TOTAL'!AN134 -> 0
A133: ='RESUMEN TOTAL'!A135 -> LA ESMERALDA | B133: ='RESUMEN TOTAL'!B135 -> ESM12 (fija 2) | C133: ='RESUMEN TOTAL'!D135 -> NOVAK Y LAMBARDI | D133: ='RESUMEN TOTAL'!E135 -> Fija | E133: ='RESUMEN TOTAL'!F135 -> Fibra Optica | F133: ='RESUMEN TOTAL'!K135 -> 0 | G133: ='RESUMEN TOTAL'!L135 -> 0 | H133: ='RESUMEN TOTAL'!M135 -> 0 | I133: ='RESUMEN TOTAL'!N135 -> 0 | J133: ='RESUMEN TOTAL'!O135 -> 0 | K133: ='RESUMEN TOTAL'!P135 -> 0 | L133: ='RESUMEN TOTAL'!Q135 -> APAGADO | M133: ='RESUMEN TOTAL'!R135 -> 0 | ... AI133: ='RESUMEN TOTAL'!AN135 -> 0
A134: ='RESUMEN TOTAL'!A136 -> LA ESMERALDA | B134: ='RESUMEN TOTAL'!B136 -> ESM 13 | C134: ='RESUMEN TOTAL'!D136 -> Barzi y Serrano | D134: ='RESUMEN TOTAL'!E136 -> fija | E134: ='RESUMEN TOTAL'!F136 -> Fibra Optica | F134: ='RESUMEN TOTAL'!K136 -> 0 | G134: ='RESUMEN TOTAL'!L136 -> 0 | H134: ='RESUMEN TOTAL'!M136 -> 0 | I134: ='RESUMEN TOTAL'!N136 -> 0 | J134: ='RESUMEN TOTAL'!O136 -> 0 | K134: ='RESUMEN TOTAL'!P136 -> 0 | L134: ='RESUMEN TOTAL'!Q136 -> APAGADO | M134: ='RESUMEN TOTAL'!R136 -> 0 | ... AI134: ='RESUMEN TOTAL'!AN136 -> 0
...

Sheet APAGADOS
E1: APAGADOS | F1: =COUNTIF(F3:F400, "APAGADO") -> 132 | G1: =COUNTIF(G3:G400, "APAGADO") -> 110 | H1: =COUNTIF(H3:H500, "APAGADO") -> 97 | I1: =COUNTIF(I3:I400, "APAGADO") -> 93 | J1: =COUNTIF(J3:J400, "APAGADO") -> 97 | K1: =COUNTIF(K3:K400, "APAGADO") -> 79 | L1: =COUNTIF(L3:L400, "APAGADO") -> 78 | M1: =COUNTIF(M3:M400, "APAGADO") -> 79 | N1: =COUNTIF(N3:N400, "APAGADO") -> 89 | O1: =COUNTIF(O3:O400, "APAGADO") -> 96 | P1: =COUNTIF(P3:P400, "APAGADO") -> 88 | ... AD1: =COUNTIF(AD3:AD400, "APAGADO") -> 26 | AE1: =COUNTIF(AE3:AE500, "APAGADO") -> 32 | AF1: =COUNTIF(AF3:AF400, "APAGADO") -> 40 | AG1: =COUNTIF(AG3:AG400, "APAGADO") -> 0 | AH1: =COUNTIF(AH3:AH400, "APAGADO") -> 0 | AI1: =COUNTIF(AI3:AI400, "APAGADO") -> 0
A2: =ESTADISTICA!A1 -> Barrio | B2: =ESTADISTICA!B1 -> [Denominacion] | C2: =ESTADISTICA!C1 -> [Ubicacion] | D2: =ESTADISTICA!D1 -> [Tipo de Camara] | E2: =ESTADISTICA!E1 -> [Tipo de Conexion] | F2: =ESTADISTICA!F1 -> 44896 | G2: =ESTADISTICA!G1 -> 44897 | H2: =ESTADISTICA!H1 -> 44898 | ... AI2: =ESTADISTICA!AI1 -> 44925
A3: =ESTADISTICA!A2 -> ALTAMIRA | B3: =ESTADISTICA!B2 -> ALT01 | C3: =ESTADISTICA!C2 -> Calchaqui y Sgto. Cabral | D3: =ESTADISTICA!D2 -> Domo | E3: =ESTADISTICA!E2 -> Fibra Optica | F3: =ESTADISTICA!F2 -> APAGADO | G3: =ESTADISTICA!G2 -> APAGADO | H3: =ESTADISTICA!H2 -> APAGADO | ... AI3: =ESTADISTICA!AI2 -> 0
A4: =ESTADISTICA!A3 -> ALTAMIRA | B4: =ESTADISTICA!B3 -> ALT02 | C4: =ESTADISTICA!C3 -> Calchaqui y Lope de Vega | D4: =ESTADISTICA!D3 -> Domo | E4: =ESTADISTICA!E3 -> PTO A FO | F4: =ESTADISTICA!F3 -> APAGADO | G4: =ESTADISTICA!G3 -> APAGADO | H4: =ESTADISTICA!H3 -> APAGADO | ... AI4: =ESTADISTICA!AI3 -> 0
A5: =ESTADISTICA!A4 -> ALTAMIRA | B5: =ESTADISTICA!B4 -> ALT 03 | C5: =ESTADISTICA!C4 -> Bombero Galarza y Necochea | D5: =ESTADISTICA!D4 -> Domo | E5: =ESTADISTICA!E4 -> FIBRA OPTICA | F5: =ESTADISTICA!F4 -> APAGADO | G5: =ESTADISTICA!G4 -> APAGADO | H5: =ESTADISTICA!H4 -> APAGADO | ... AI5: =ESTADISTICA!AI4 -> 0
A6: =ESTADISTICA!A5 -> ALTAMIRA | B6: =ESTADISTICA!B5 -> ALT 04 | C6: =ESTADISTICA!C5 -> Francia y Necochea | D6: =ESTADISTICA!D5 -> Domo | E6: =ESTADISTICA!E5 -> FIBRA OPTICA | F6: =ESTADISTICA!F5 -> APAGADO | G6: =ESTADISTICA!G5 -> APAGADO | H6: =ESTADISTICA!H5 -> APAGADO | ... AI6: =ESTADISTICA!AI5 -> 0
A7: =ESTADISTICA!A6 -> ALTAMIRA | B7: =ESTADISTICA!B6 -> ALT05 | C7: =ESTADISTICA!C6 -> Av. Calchaqui y Bombero Galarza | D7: =ESTADISTICA!D6 -> Domo | E7: =ESTADISTICA!E6 -> PTO A FO | F7: =ESTADISTICA!F6 -> APAGADO | G7: =ESTADISTICA!G6 -> APAGADO | H7: =ESTADISTICA!H6 -> APAGADO | ... AI7: =ESTADISTICA!AI6 -> 0
A8: =ESTADISTICA!A7 -> ALTAMIRA | B8: =ESTADISTICA!B7 -> ALT 06 | C8: =ESTADISTICA!C7 -> LOPE DE VEGA Y NECOCHEA | D8: =ESTADISTICA!D7 -> Domo | E8: =ESTADISTICA!E7 -> PTO A FO | F8: =ESTADISTICA!F7 -> APAGADO | G8: =ESTADISTICA!G7 -> APAGADO | H8: =ESTADISTICA!H7 -> APAGADO | ... AI8: =ESTADISTICA!AI7 -> 0
A9: =ESTADISTICA!A8 -> ALTAMIRA | B9: =ESTADISTICA!B8 -> ALT07 | C9: =ESTADISTICA!C8 -> AV. CALCHAQUI Y AV. DEL TRABAJO | D9: =ESTADISTICA!D8 -> DOMO | E9: =ESTADISTICA!E8 -> PTO A FO | F9: =ESTADISTICA!F8 -> APAGADO | G9: =ESTADISTICA!G8 -> APAGADO | H9: =ESTADISTICA!H8 -> APAGADO | ... AI9: =ESTADISTICA!AI8 -> 0
A10: =ESTADISTICA!A9 -> ALTAMIRA | B10: =ESTADISTICA!B9 -> ALT 08 | C10: =ESTADISTICA!C9 -> HUMAITA Y NECOCHEA | D10: =ESTADISTICA!D9 -> DOMO | E10: =ESTADISTICA!E9 -> Fibra Optica | F10: =ESTADISTICA!F9 -> APAGADO | G10: =ESTADISTICA!G9 -> APAGADO | H10: =ESTADISTICA!H9 -> APAGADO | ... AI10: =ESTADISTICA!AI9 -> 0
A11: =ESTADISTICA!A10 -> ALTAMIRA | B11: =ESTADISTICA!B10 -> ALT 09 | C11: =ESTADISTICA!C10 -> NECOCHEA Y CURUPAITY | D11: =ESTADISTICA!D10 -> DOMO | E11: =ESTADISTICA!E10 -> Fibra Optica | F11: =ESTADISTICA!F10 -> APAGADO | G11: =ESTADISTICA!G10 -> APAGADO | H11: =ESTADISTICA!H10 -> APAGADO | ... AI11: =ESTADISTICA!AI10 -> 0
A12: =ESTADISTICA!A11 -> ALTAMIRA | B12: =ESTADISTICA!B11 -> ALT 10 | C12: =ESTADISTICA!C11 -> Calchaqui y Francia | D12: =ESTADISTICA!D11 -> Domo | E12: =ESTADISTICA!E11 -> Radio | F12: =ESTADISTICA!F11 -> APAGADO | G12: =ESTADISTICA!G11 -> APAGADO | H12: =ESTADISTICA!H11 -> APAGADO | ... AI12: =ESTADISTICA!AI11 -> 0
A13: =ESTADISTICA!A12 -> AGUSTIN RAMIREZ | B13: =ESTADISTICA!B12 -> ARA 01 | C13: =ESTADISTICA!C12 -> Malambo y Tranquera | D13: =ESTADISTICA!D12 -> Domo | E13: =ESTADISTICA!E12 -> FIBRA OPTICA | F13: =ESTADISTICA!F12 -> 0 | G13: =ESTADISTICA!G12 -> 0 | H13: =ESTADISTICA!H12 -> 0 | ... AI13: =ESTADISTICA!AI12 -> 0
... A513: =ESTADISTICA!A512 -> 0 | B513: =ESTADISTICA!B512 -> 0 | C513: =ESTADISTICA!C512 -> 0 | D513: =ESTADISTICA!D512 -> 0 | E513: =ESTADISTICA!E512 -> 0 | F513: =ESTADISTICA!F512 -> 0 | G513: =ESTADISTICA!G512 -> 0 | H513: =ESTADISTICA!H512 -> 0 | ... AI513: =ESTADISTICA!AI512 -> 0

Sheet APAGADOS FIBRA
C1: TOTAL FIBRA | D1: =COUNTIFS(E4:E400,"=Fibra Optica") -> 267
E2: APAGADOS | F2: =COUNTIFS(F4:F500, "=APAGADO",E4:E500,"=Fibra Optica") -> 100 | G2: =COUNTIFS(G4:G500, "=APAGADO",E4:E500,"=Fibra Optica") -> 81 | H2: =COUNTIFS(H4:H500, "=APAGADO",E4:E500,"=Fibra Optica") -> 65 | I2: =COUNTIFS(I4:I500, "=APAGADO",E4:E500,"=Fibra Optica") -> 64 | J2: =COUNTIFS(J4:J500, "=APAGADO",E4:E500,"=Fibra Optica") -> 70 | K2: =COUNTIFS(K4:K500, "=APAGADO",E4:E500,"=Fibra Optica") -> 55 | L2: =COUNTIFS(L4:L500, "=APAGADO",E4:E500,"=Fibra Optica") -> 59 | M2: =COUNTIFS(M4:M500, "=APAGADO",E4:E500,"=Fibra Optica") -> 63 | N2: =COUNTIFS(N4:N500, "=APAGADO",E4:E500,"=Fibra Optica") -> 73 | O2: =COUNTIFS(O4:O500, "=APAGADO",E4:E500,"=Fibra Optica") -> 76 | P2: =COUNTIFS(P4:P500, "=APAGADO",E4:E500,"=Fibra Optica") -> 70 | Q2: =COUNTIFS(Q4:Q500, "=APAGADO",E4:E500,"=Fibra Optica") -> 57 | R2: =COUNTIFS(R4:R500, "=APAGADO",E4:E500,"=Fibra Optica") -> 61 | S2: =COUNTIFS(S4:S500, "=APAGADO",E4:E500,"=Fibra Optica") -> 63 | T2: =COUNTIFS(T4:T500, "=APAGADO",E4:E500,"=Fibra Optica") -> 52 | U2: =COUNTIFS(U4:U500, "=APAGADO",E4:E500,"=Fibra Optica") -> 36 | V2: =COUNTIFS(V4:V500, "=APAGADO",E4:E500,"=Fibra Optica") -> 63 | W2: =COUNTIFS(W4:W500, "=APAGADO",E4:E500,"=Fibra Optica") -> 33 | X2: =COUNTIFS(X4:X500, "=APAGADO",E4:E500,"=Fibra Optica") -> 27 | Y2: =COUNTIFS(Y4:Y500, "=APAGADO",E4:E500,"=Fibra Optica") -> 29 | Z2: =COUNTIFS(Z4:Z500, "=APAGADO",E4:E500,"=Fibra Optica") -> 32 | AA2: =COUNTIFS(AA4:AA500, "=APAGADO",E4:E500,"=Fibra Optica") -> 26 | AB2: =COUNTIFS(AB4:AB500, "=APAGADO",E4:E500,"=Fibra Optica") -> 23 | AC2: =COUNTIFS(AC4:AC500, "=APAGADO",E4:E500,"=Fibra Optica") -> 20 | AD2: =COUNTIFS(AD4:AD500, "=APAGADO",E4:E500,"=Fibra Optica") -> 18 | AE2: =COUNTIFS(AE4:AE500, "=APAGADO",E4:E500,"=Fibra Optica") -> 23 | AF2: =COUNTIFS(AF4:AF500, "=APAGADO",E4:E500,"=Fibra Optica") -> 32 | AG2: =COUNTIFS(AG4:AG500, "=APAGADO",E4:E500,"=Fibra Optica") -> 0 | AH2: =COUNTIFS(AH4:AH500, "=APAGADO",E4:E500,"=Fibra Optica") -> 0 | AI2: =COUNTIFS(AI4:AI400, "=APAGADO",E4:E400,"=Fibra Optica") -> 0
A3: =ESTADISTICA!A1 -> Barrio | B3: =ESTADISTICA!B1 -> [Denominacion] | C3: =ESTADISTICA!C1 -> [Ubicacion] | D3: =ESTADISTICA!D1 -> [Tipo de Camara] | E3: =ESTADISTICA!E1 -> [Tipo de Conexion] | F3: =ESTADISTICA!F1 -> 44896 | G3: =ESTADISTICA!G1 -> 44897 | H3: =ESTADISTICA!H1 -> 44898 | ... AI3: =ESTADISTICA!AI1 -> 44925
A4: =ESTADISTICA!A2 -> ALTAMIRA | B4: =ESTADISTICA!B2 -> ALT01 | C4: =ESTADISTICA!C2 -> Calchaqui y Sgto. Cabral | D4: =ESTADISTICA!D2 -> Domo | E4: =ESTADISTICA!E2 -> Fibra Optica | F4: =ESTADISTICA!F2 -> APAGADO | G4: =ESTADISTICA!G2 -> APAGADO | H4: =ESTADISTICA!H2 -> APAGADO | ... AI4: =ESTADISTICA!AI2 -> 0
A5: =ESTADISTICA!A3 -> ALTAMIRA | B5: =ESTADISTICA!B3 -> ALT02 | C5: =ESTADISTICA!C3 -> Calchaqui y Lope de Vega | D5: =ESTADISTICA!D3 -> Domo | E5: =ESTADISTICA!E3 -> PTO A FO | F5: =ESTADISTICA!F3 -> APAGADO | G5: =ESTADISTICA!G3 -> APAGADO | H5: =ESTADISTICA!H3 -> APAGADO | ... AI5: =ESTADISTICA!AI3 -> 0
A6: =ESTADISTICA!A4 -> ALTAMIRA | B6: =ESTADISTICA!B4 -> ALT 03 | C6: =ESTADISTICA!C4 -> Bombero Galarza y Necochea | D6: =ESTADISTICA!D4 -> Domo | E6: =ESTADISTICA!E4 -> FIBRA OPTICA | F6: =ESTADISTICA!F4 -> APAGADO | G6: =ESTADISTICA!G4 -> APAGADO | H6: =ESTADISTICA!H4 -> APAGADO | ... AI6: =ESTADISTICA!AI4 -> 0
A7: =ESTADISTICA!A5 -> ALTAMIRA | B7: =ESTADISTICA!B5 -> ALT 04 | C7: =ESTADISTICA!C5 -> Francia y Necochea | D7: =ESTADISTICA!D5 -> Domo | E7: =ESTADISTICA!E5 -> FIBRA OPTICA | F7: =ESTADISTICA!F5 -> APAGADO | G7: =ESTADISTICA!G5 -> APAGADO | H7: =ESTADISTICA!H5 -> APAGADO | ... AI7: =ESTADISTICA!AI5 -> 0
A8: =ESTADISTICA!A6 -> ALTAMIRA | B8: =ESTADISTICA!B6 -> ALT05 | C8: =ESTADISTICA!C6 -> Av. Calchaqui y Bombero Galarza | D8: =ESTADISTICA!D6 -> Domo | E8: =ESTADISTICA!E6 -> PTO A FO | F8: =ESTADISTICA!F6 -> APAGADO | G8: =ESTADISTICA!G6 -> APAGADO | H8: =ESTADISTICA!H6 -> APAGADO | ... AI8: =ESTADISTICA!AI6 -> 0
A9: =ESTADISTICA!A7 -> ALTAMIRA | B9: =ESTADISTICA!B7 -> ALT 06 | C9: =ESTADISTICA!C7 -> LOPE DE VEGA Y NECOCHEA | D9: =ESTADISTICA!D7 -> Domo | E9: =ESTADISTICA!E7 -> PTO A FO | F9: =ESTADISTICA!F7 -> APAGADO | G9: =ESTADISTICA!G7 -> APAGADO | H9: =ESTADISTICA!H7 -> APAGADO | ... AI9: =ESTADISTICA!AI7 -> 0
A10: =ESTADISTICA!A8 -> ALTAMIRA | B10: =ESTADISTICA!B8 -> ALT07 | C10: =ESTADISTICA!C8 -> AV. CALCHAQUI Y AV. DEL TRABAJO | D10: =ESTADISTICA!D8 -> DOMO | E10: =ESTADISTICA!E8 -> PTO A FO | F10: =ESTADISTICA!F8 -> APAGADO | G10: =ESTADISTICA!G8 -> APAGADO | H10: =ESTADISTICA!H8 -> APAGADO | ... AI10: =ESTADISTICA!AI8 -> 0
A11: =ESTADISTICA!A9 -> ALTAMIRA | B11: =ESTADISTICA!B9 -> ALT 08 | C11: =ESTADISTICA!C9 -> HUMAITA Y NECOCHEA | D11: =ESTADISTICA!D9 -> DOMO | E11: =ESTADISTICA!E9 -> Fibra Optica | F11: =ESTADISTICA!F9 -> APAGADO | G11: =ESTADISTICA!G9 -> APAGADO | H11: =ESTADISTICA!H9 -> APAGADO | ... AI11: =ESTADISTICA!AI9 -> 0
A12: =ESTADISTICA!A10 -> ALTAMIRA | B12: =ESTADISTICA!B10 -> ALT 09 | C12: =ESTADISTICA!C10 -> NECOCHEA Y CURUPAITY | D12: =ESTADISTICA!D10 -> DOMO | E12: =ESTADISTICA!E10 -> Fibra Optica | F12: =ESTADISTICA!F10 -> APAGADO | G12: =ESTADISTICA!G10 -> APAGADO | H12: =ESTADISTICA!H10 -> APAGADO | ... AI12: =ESTADISTICA!AI10 -> 0
A13: =ESTADISTICA!A11 -> ALTAMIRA | B13: =ESTADISTICA!B11 -> ALT 10 | C13: =ESTADISTICA!C11 -> Calchaqui y Francia | D13: =ESTADISTICA!D11 -> Domo | E13: =ESTADISTICA!E11 -> Radio | F13: =ESTADISTICA!F11 -> APAGADO | G13: =ESTADISTICA!G11 -> APAGADO | H13: =ESTADISTICA!H11 -> APAGADO | ... AI13: =ESTADISTICA!AI11 -> 0
A14: =ESTADISTICA!A12 -> AGUSTIN RAMIREZ | B14: =ESTADISTICA!B12 -> ARA 01 | C14: =ESTADISTICA!C12 -> Malambo y Tranquera | D14: =ESTADISTICA!D12 -> Domo | E14: =ESTADISTICA!E12 -> FIBRA OPTICA | F14: =ESTADISTICA!F12 -> 0 | G14: =ESTADISTICA!G12 -> 0 | H14: =ESTADISTICA!H12 -> 0 | ... AI14: =ESTADISTICA!AI12 -> 0
... A601: =ESTADISTICA!A599 -> 0 | B601: =ESTADISTICA!B599 -> 0 | C601: =ESTADISTICA!C599 -> 0 | D601: =ESTADISTICA!D599 -> 0 | E601: =ESTADISTICA!E599 -> 0 | F601: =ESTADISTICA!F599 -> 0 | G601: =ESTADISTICA!G599 -> 0 | H601: =ESTADISTICA!H599 -> 0 | ... AI601: =ESTADISTICA!AI599 -> 0

Sheet APAGADOS ANTENA
C1: TOTAL PTO A FO
E2: APAGADOS | F2: =COUNTIFS(F4:F500, "=APAGADO",E4:E500,"=PTO A FO") -> 11 | G2: =COUNTIFS(G4:G500, "=APAGADO",E4:E500,"=PTO A FO") -> 11 | H2: =COUNTIFS(H4:H500, "=APAGADO",E4:E500,"=PTO A FO") -> 9 | I2: =COUNTIFS(I4:I500, "=APAGADO",E4:E500,"=PTO A FO") -> 11 | J2: =COUNTIFS(J4:J500, "=APAGADO",E4:E500,"=PTO A FO") -> 12 | K2: =COUNTIFS(K4:K500, "=APAGADO",E4:E500,"=PTO A FO") -> 11 | L2: =COUNTIFS(L4:L500, "=APAGADO",E4:E500,"=PTO A FO") -> 11 | M2: =COUNTIFS(M4:M500, "=APAGADO",E4:E500,"=PTO A FO") -> 8 | N2: =COUNTIFS(N4:N500, "=APAGADO",E4:E500,"=PTO A FO") -> 9 | O2: =COUNTIFS(O4:O500, "=APAGADO",E4:E500,"=PTO A FO") -> 9 | P2: =COUNTIFS(P4:P500, "=APAGADO",E4:E500,"=PTO A FO") -> 9 | Q2: =COUNTIFS(Q4:Q500, "=APAGADO",E4:E500,"=PTO A FO") -> 8 | R2: =COUNTIFS(R4:R500, "=APAGADO",E4:E500,"=PTO A FO") -> 7 | S2: =COUNTIFS(S4:S500, "=APAGADO",E4:E500,"=PTO A FO") -> 8 | T2: =COUNTIFS(T4:T500, "=APAGADO",E4:E500,"=PTO A FO") -> 10 | U2: =COUNTIFS(U4:U500, "=APAGADO",E4:E500,"=PTO A FO") -> 3 | V2: =COUNTIFS(V4:V500, "=APAGADO",E4:E500,"=PTO A FO") -> 2 | W2: =COUNTIFS(W4:W500, "=APAGADO",E4:E500,"=PTO A FO") -> 3 | X2: =COUNTIFS(X4:X500, "=APAGADO",E4:E500,"=PTO A FO") -> 2 | Y2: =COUNTIFS(Y4:Y500, "=APAGADO",E4:E500,"=PTO A FO") -> 2 | Z2: =COUNTIFS(Z4:Z500, "=APAGADO",E4:E500,"=PTO A FO") -> 1 | AA2: =COUNTIFS(AA4:AA500, "=APAGADO",E4:E500,"=PTO A FO") -> 1 | AB2: =COUNTIFS(AB4:AB500, "=APAGADO",E4:E500,"=PTO A FO") -> 2 | AC2: =COUNTIFS(AC4:AC500, "=APAGADO",E4:E500,"=PTO A FO") -> 2 | AD2: =COUNTIFS(AD4:AD500, "=APAGADO",E4:E500,"=PTO A FO") -> 0 | AE2: =COUNTIFS(AE4:AE500, "=APAGADO",E4:E500,"=PTO A FO") -> 2 | AF2: =COUNTIFS(AF4:AF500, "=APAGADO",E4:E500,"=PTO A FO") -> 2 | AG2: =COUNTIFS(AG4:AG500, "=APAGADO",E4:E500,"=PTO A FO") -> 0 | AH2: =COUNTIFS(AH4:AH500, "=APAGADO",E4:E500,"=PTO A FO") -> 0 | AI2: =COUNTIFS(AI4:AI500, "=APAGADO",E4:E500,"=PTO A FO") -> 0
A3: =ESTADISTICA!A1 -> Barrio | B3: =ESTADISTICA!B1 -> [Denominacion] | C3: =ESTADISTICA!C1 -> [Ubicacion] | D3: =ESTADISTICA!D1 -> [Tipo de Camara] | E3: =ESTADISTICA!E1 -> [Tipo de Conexion] | F3: =ESTADISTICA!F1 -> 44896 | G3: =ESTADISTICA!G1 -> 44897 | H3: =ESTADISTICA!H1 -> 44898 | ... AI3: =ESTADISTICA!AI1 -> 44925
A4: =ESTADISTICA!A2 -> ALTAMIRA | B4: =ESTADISTICA!B2 -> ALT01 | C4: =ESTADISTICA!C2 -> Calchaqui y Sgto. Cabral | D4: =ESTADISTICA!D2 -> Domo | E4: =ESTADISTICA!E2 -> Fibra Optica | F4: =ESTADISTICA!F2 -> APAGADO | G4: =ESTADISTICA!G2 -> APAGADO | H4: =ESTADISTICA!H2 -> APAGADO | ... AI4: =ESTADISTICA!AI2 -> 0
A5: =ESTADISTICA!A3 -> ALTAMIRA | B5: =ESTADISTICA!B3 -> ALT02 | C5: =ESTADISTICA!C3 -> Calchaqui y Lope de Vega | D5: =ESTADISTICA!D3 -> Domo | E5: =ESTADISTICA!E3 -> PTO A FO | F5: =ESTADISTICA!F3 -> APAGADO | G5: =ESTADISTICA!G3 -> APAGADO | H5: =ESTADISTICA!H3 -> APAGADO | ... AI5: =ESTADISTICA!AI3 -> 0
A6: =ESTADISTICA!A4 -> ALTAMIRA | B6: =ESTADISTICA!B4 -> ALT 03 | C6: =ESTADISTICA!C4 -> Bombero Galarza y Necochea | D6: =ESTADISTICA!D4 -> Domo | E6: =ESTADISTICA!E4 -> FIBRA OPTICA | F6: =ESTADISTICA!F4 -> APAGADO | G6: =ESTADISTICA!G4 -> APAGADO | H6: =ESTADISTICA!H4 -> APAGADO | ... AI6: =ESTADISTICA!AI4 -> 0
A7: =ESTADISTICA!A5 -> ALTAMIRA | B7: =ESTADISTICA!B5 -> ALT 04 | C7: =ESTADISTICA!C5 -> Francia y Necochea | D7: =ESTADISTICA!D5 -> Domo | E7: =ESTADISTICA!E5 -> FIBRA OPTICA | F7: =ESTADISTICA!F5 -> APAGADO | G7: =ESTADISTICA!G5 -> APAGADO | H7: =ESTADISTICA!H5 -> APAGADO | ... AI7: =ESTADISTICA!AI5 -> 0
A8: =ESTADISTICA!A6 -> ALTAMIRA | B8: =ESTADISTICA!B6 -> ALT05 | C8: =ESTADISTICA!C6 -> Av. Calchaqui y Bombero Galarza | D8: =ESTADISTICA!D6 -> Domo | E8: =ESTADISTICA!E6 -> PTO A FO | F8: =ESTADISTICA!F6 -> APAGADO | G8: =ESTADISTICA!G6 -> APAGADO | H8: =ESTADISTICA!H6 -> APAGADO | ... AI8: =ESTADISTICA!AI6 -> 0
A9: =ESTADISTICA!A7 -> ALTAMIRA | B9: =ESTADISTICA!B7 -> ALT 06 | C9: =ESTADISTICA!C7 -> LOPE DE VEGA Y NECOCHEA | D9: =ESTADISTICA!D7 -> Domo | E9: =ESTADISTICA!E7 -> PTO A FO | F9: =ESTADISTICA!F7 -> APAGADO | G9: =ESTADISTICA!G7 -> APAGADO | H9: =ESTADISTICA!H7 -> APAGADO | ... AI9: =ESTADISTICA!AI7 -> 0
A10: =ESTADISTICA!A8 -> ALTAMIRA | B10: =ESTADISTICA!B8 -> ALT07 | C10: =ESTADISTICA!C8 -> AV. CALCHAQUI Y AV. DEL TRABAJO | D10: =ESTADISTICA!D8 -> DOMO | E10: =ESTADISTICA!E8 -> PTO A FO | F10: =ESTADISTICA!F8 -> APAGADO | G10: =ESTADISTICA!G8 -> APAGADO | H10: =ESTADISTICA!H8 -> APAGADO | ... AI10: =ESTADISTICA!AI8 -> 0
A11: =ESTADISTICA!A9 -> ALTAMIRA | B11: =ESTADISTICA!B9 -> ALT 08 | C11: =ESTADISTICA!C9 -> HUMAITA Y NECOCHEA | D11: =ESTADISTICA!D9 -> DOMO | E11: =ESTADISTICA!E9 -> Fibra Optica | F11: =ESTADISTICA!F9 -> APAGADO | G11: =ESTADISTICA!G9 -> APAGADO | H11: =ESTADISTICA!H9 -> APAGADO | ... AI11: =ESTADISTICA!AI9 -> 0
A12: =ESTADISTICA!A10 -> ALTAMIRA | B12: =ESTADISTICA!B10 -> ALT 09 | C12: =ESTADISTICA!C10 -> NECOCHEA Y CURUPAITY | D12: =ESTADISTICA!D10 -> DOMO | E12: =ESTADISTICA!E10 -> Fibra Optica | F12: =ESTADISTICA!F10 -> APAGADO | G12: =ESTADISTICA!G10 -> APAGADO | H12: =ESTADISTICA!H10 -> APAGADO | ... AI12: =ESTADISTICA!AI10 -> 0
A13: =ESTADISTICA!A11 -> ALTAMIRA | B13: =ESTADISTICA!B11 -> ALT 10 | C13: =ESTADISTICA!C11 -> Calchaqui y Francia | D13: =ESTADISTICA!D11 -> Domo | E13: =ESTADISTICA!E11 -> Radio | F13: =ESTADISTICA!F11 -> APAGADO | G13: =ESTADISTICA!G11 -> APAGADO | H13: =ESTADISTICA!H11 -> APAGADO | ... AI13: =ESTADISTICA!AI11 -> 0
A14: =ESTADISTICA!A12 -> AGUSTIN RAMIREZ | B14: =ESTADISTICA!B12 -> ARA 01 | C14: =ESTADISTICA!C12 -> Malambo y Tranquera | D14: =ESTADISTICA!D12 -> Domo | E14: =ESTADISTICA!E12 -> FIBRA OPTICA | F14: =ESTADISTICA!F12 -> 0 | G14: =ESTADISTICA!G12 -> 0 | H14: =ESTADISTICA!H12 -> 0 | ... AI14: =ESTADISTICA!AI12 -> 0
... A539: =ESTADISTICA!A537 -> 0 | B539: =ESTADISTICA!B537 -> 0 | C539: =ESTADISTICA!C537 -> 0 | D539: =ESTADISTICA!D537 -> 0 | E539: =ESTADISTICA!E537 -> 0 | F539: =ESTADISTICA!F537 -> 0 | G539: =ESTADISTICA!G537 -> 0 | H539: =ESTADISTICA!H537 -> 0 | ... AI539: =ESTADISTICA!AI537 -> 0

Sheet APAGADOS RADIO
C1: TOTAL RADIO | D1: =COUNTIFS(E4:E400,"=radio") -> 94
E2: APAGADOS | F2: =COUNTIFS(F4:F500, "=APAGADO",E4:E500,"=radio") -> 24 | G2: =COUNTIFS(G4:G500, "=APAGADO",E4:E500,"=radio") -> 21 | H2: =COUNTIFS(H4:H500, "=APAGADO",E4:E500,"=radio") -> 23 | I2: =COUNTIFS(I4:I500, "=APAGADO",E4:E500,"=radio") -> 20 | J2: =COUNTIFS(J4:J500, "=APAGADO",E4:E500,"=radio") -> 16 | K2: =COUNTIFS(K4:K500, "=APAGADO",E4:E500,"=radio") -> 15 | L2: =COUNTIFS(L4:L500, "=APAGADO",E4:E500,"=radio") -> 12 | M2: =COUNTIFS(M4:M500, "=APAGADO",E4:E500,"=radio") -> 11 | N2: =COUNTIFS(N4:N500, "=APAGADO",E4:E500,"=radio") -> 10 | O2: =COUNTIFS(O4:O500, "=APAGADO",E4:E500,"=radio") -> 14 | P2: =COUNTIFS(P4:P500, "=APAGADO",E4:E500,"=radio") -> 12 | Q2: =COUNTIFS(Q4:Q367, "=APAGADO",E4:E367,"=radio") -> 10 | R2: =COUNTIFS(R4:R500, "=APAGADO",E4:E500,"=radio") -> 10 | S2: =COUNTIFS(S4:S500, "=APAGADO",E4:E500,"=radio") -> 11 | T2: =COUNTIFS(T4:T500, "=APAGADO",E4:E500,"=radio") -> 13 | U2: =COUNTIFS(U4:U500, "=APAGADO",E4:E500,"=radio") -> 12 | V2: =COUNTIFS(V4:V500, "=APAGADO",E4:E500,"=radio") -> 16 | W2: =COUNTIFS(W4:W500, "=APAGADO",E4:E500,"=radio") -> 9 | X2: =COUNTIFS(X4:X500, "=APAGADO",E4:E500,"=radio") -> 9 | Y2: =COUNTIFS(Y4:Y500, "=APAGADO",E4:E500,"=radio") -> 6 | Z2: =COUNTIFS(Z4:Z500, "=APAGADO",E4:E500,"=radio") -> 3 | AA2: =COUNTIFS(AA4:AA500, "=APAGADO",E4:E500,"=radio") -> 6 | AB2: =COUNTIFS(AB4:AB500, "=APAGADO",E4:E500,"=radio") -> 5 | AC2: =COUNTIFS(AC4:AC500, "=APAGADO",E4:E500,"=radio") -> 11 | AD2: =COUNTIFS(AD4:AD500, "=APAGADO",E4:E500,"=radio") -> 8 | AE2: =COUNTIFS(AE4:AE500, "=APAGADO",E4:E500,"=radio") -> 7 | AF2: =COUNTIFS(AF4:AF500, "=APAGADO",E4:E500,"=radio") -> 6 | AG2: =COUNTIFS(AG4:AG500, "=APAGADO",E4:E500,"=radio") -> 0 | AH2: =COUNTIFS(AH4:AH500, "=APAGADO",E4:E500,"=radio") -> 0 | AI2: =COUNTIFS(AI4:AI500, "=APAGADO",E4:E500,"=radio") -> 0
A3: =ESTADISTICA!A1 -> Barrio | B3: =ESTADISTICA!B1 -> [Denominacion] | C3: =ESTADISTICA!C1 -> [Ubicacion] | D3: =ESTADISTICA!D1 -> [Tipo de Camara] | E3: =ESTADISTICA!E1 -> [Tipo de Conexion] | F3: =ESTADISTICA!F1 -> 44896 | G3: =ESTADISTICA!G1 -> 44897 | H3: =ESTADISTICA!H1 -> 44898 | ... AI3: =ESTADISTICA!AI1 -> 44925
A4: =ESTADISTICA!A2 -> ALTAMIRA | B4: =ESTADISTICA!B2 -> ALT01 | C4: =ESTADISTICA!C2 -> Calchaqui y Sgto. Cabral | D4: =ESTADISTICA!D2 -> Domo | E4: =ESTADISTICA!E2 -> Fibra Optica | F4: =ESTADISTICA!F2 -> APAGADO | G4: =ESTADISTICA!G2 -> APAGADO | H4: =ESTADISTICA!H2 -> APAGADO | ... AI4: =ESTADISTICA!AI2 -> 0
A5: =ESTADISTICA!A3 -> ALTAMIRA | B5: =ESTADISTICA!B3 -> ALT02 | C5: =ESTADISTICA!C3 -> Calchaqui y Lope de Vega | D5: =ESTADISTICA!D3 -> Domo | E5: =ESTADISTICA!E3 -> PTO A FO | F5: =ESTADISTICA!F3 -> APAGADO | G5: =ESTADISTICA!G3 -> APAGADO | H5: =ESTADISTICA!H3 -> APAGADO | ... AI5: =ESTADISTICA!AI3 -> 0
A6: =ESTADISTICA!A4 -> ALTAMIRA | B6: =ESTADISTICA!B4 -> ALT 03 | C6: =ESTADISTICA!C4 -> Bombero Galarza y Necochea | D6: =ESTADISTICA!D4 -> Domo | E6: =ESTADISTICA!E4 -> FIBRA OPTICA | F6: =ESTADISTICA!F4 -> APAGADO | G6: =ESTADISTICA!G4 -> APAGADO | H6: =ESTADISTICA!H4 -> APAGADO | ... AI6: =ESTADISTICA!AI4 -> 0
A7: =ESTADISTICA!A5 -> ALTAMIRA | B7: =ESTADISTICA!B5 -> ALT 04 | C7: =ESTADISTICA!C5 -> Francia y Necochea | D7: =ESTADISTICA!D5 -> Domo | E7: =ESTADISTICA!E5 -> FIBRA OPTICA | F7: =ESTADISTICA!F5 -> APAGADO | G7: =ESTADISTICA!G5 -> APAGADO | H7: =ESTADISTICA!H5 -> APAGADO | ... AI7: =ESTADISTICA!AI5 -> 0
A8: =ESTADISTICA!A6 -> ALTAMIRA | B8: =ESTADISTICA!B6 -> ALT05 | C8: =ESTADISTICA!C6 -> Av. Calchaqui y Bombero Galarza | D8: =ESTADISTICA!D6 -> Domo | E8: =ESTADISTICA!E6 -> PTO A FO | F8: =ESTADISTICA!F6 -> APAGADO | G8: =ESTADISTICA!G6 -> APAGADO | H8: =ESTADISTICA!H6 -> APAGADO | ... AI8: =ESTADISTICA!AI6 -> 0
A9: =ESTADISTICA!A7 -> ALTAMIRA | B9: =ESTADISTICA!B7 -> ALT 06 | C9: =ESTADISTICA!C7 -> LOPE DE VEGA Y NECOCHEA | D9: =ESTADISTICA!D7 -> Domo | E9: =ESTADISTICA!E7 -> PTO A FO | F9: =ESTADISTICA!F7 -> APAGADO | G9: =ESTADISTICA!G7 -> APAGADO | H9: =ESTADISTICA!H7 -> APAGADO | ... AI9: =ESTADISTICA!AI7 -> 0
A10: =ESTADISTICA!A8 -> ALTAMIRA | B10: =ESTADISTICA!B8 -> ALT07 | C10: =ESTADISTICA!C8 -> AV. CALCHAQUI Y AV. DEL TRABAJO | D10: =ESTADISTICA!D8 -> DOMO | E10: =ESTADISTICA!E8 -> PTO A FO | F10: =ESTADISTICA!F8 -> APAGADO | G10: =ESTADISTICA!G8 -> APAGADO | H10: =ESTADISTICA!H8 -> APAGADO | ... AI10: =ESTADISTICA!AI8 -> 0
A11: =ESTADISTICA!A9 -> ALTAMIRA | B11: =ESTADISTICA!B9 -> ALT 08 | C11: =ESTADISTICA!C9 -> HUMAITA Y NECOCHEA | D11: =ESTADISTICA!D9 -> DOMO | E11: =ESTADISTICA!E9 -> Fibra Optica | F11: =ESTADISTICA!F9 -> APAGADO | G11: =ESTADISTICA!G9 -> APAGADO | H11: =ESTADISTICA!H9 -> APAGADO | ... AI11: =ESTADISTICA!AI9 -> 0
A12: =ESTADISTICA!A10 -> ALTAMIRA | B12: =ESTADISTICA!B10 -> ALT 09 | C12: =ESTADISTICA!C10 -> NECOCHEA Y CURUPAITY | D12: =ESTADISTICA!D10 -> DOMO | E12: =ESTADISTICA!E10 -> Fibra Optica | F12: =ESTADISTICA!F10 -> APAGADO | G12: =ESTADISTICA!G10 -> APAGADO | H12: =ESTADISTICA!H10 -> APAGADO | ... AI12: =ESTADISTICA!AI10 -> 0
A13: =ESTADISTICA!A11 -> ALTAMIRA | B13: =ESTADISTICA!B11 -> ALT 10 | C13: =ESTADISTICA!C11 -> Calchaqui y Francia | D13: =ESTADISTICA!D11 -> Domo | E13: =ESTADISTICA!E11 -> Radio | F13: =ESTADISTICA!F11 -> APAGADO | G13: =ESTADISTICA!G11 -> APAGADO | H13: =ESTADISTICA!H11 -> APAGADO | ... AI13: =ESTADISTICA!AI11 -> 0
A14: =ESTADISTICA!A12 -> AGUSTIN RAMIREZ | B14: =ESTADISTICA!B12 -> ARA 01 | C14: =ESTADISTICA!C12 -> Malambo y Tranquera | D14: =ESTADISTICA!D12 -> Domo | E14: =ESTADISTICA!E12 -> FIBRA OPTICA | F14: =ESTADISTICA!F12 -> 0 | G14: =ESTADISTICA!G12 -> 0 | H14: =ESTADISTICA!H12 -> 0 | ... AI14: =ESTADISTICA!AI12 -> 0
... A686: =ESTADISTICA!A684 -> 0 | B686: =ESTADISTICA!B684 -> 0 | C686: =ESTADISTICA!C684 -> 0 | D686: =ESTADISTICA!D684 -> 0 | E686: =ESTADISTICA!E684 -> 0 | F686: =ESTADISTICA!F684 -> 0 | G686: =ESTADISTICA!G684 -> 0 | H686: =ESTADISTICA!H684 -> 0 | ... AI686: =ESTADISTICA!AI684 -> 0

Sheet BARRAS

Sheet PORCENTAJE

Sheet informe
B1: CANTIDAD | D1: %
A2: TOTAL | B2: 435 | E2: 44896 | F2: tormenta con granizo el 30-11, hoy lluvioso
A3: CAIDAS | B3: 135 | C3: 135 | D3: =C3/B2 -> 0.31034483
A4: LLEGAMOS NOSOTROS | B4: 5 | C4: =C3-B4 -> 130 | D4: =C4/B2 -> 0.29885057
A5: NO ESTA LA CAMARA | B5: 3 | C5: =C4-B5 -> 127 | D5: =C5/B2 -> 0.29195402
A6: RADIO | B6: 24 | C6: =C5-B6 -> 103 | D6: =C6/B2 -> 0.23678161
A7: TOTAL | B7: 435 | E7: 44897
A8: CAIDAS | B8: 113 | C8: 113 | D8: =C8/B7 -> 0.25977011
A9: LLEGAMOS NOSOTROS | B9: 4 | C9: =C8-B9 -> 109 | D9: =C9/B7 -> 0.25057471
A10: NO ESTA LA CAMARA | B10: 3 | C10: =C9-B10 -> 106 | D10: =C10/B7 -> 0.24367816
A11: RADIO | B11: 21 | C11: =C10-B11 -> 85 | D11: =C11/B7 -> 0.1954023
A12: TOTAL | B12: 435 | E12: 44900
A13: CAIDAS | B13: 98 | C13: 98 | D13: =C13/B12 -> 0.22528736
A14: LLEGAMOS NOSOTROS | B14: 2 | C14: =C13-B14 -> 96 | D14: =C14/B12 -> 0.22068966
A15: NO ESTA LA CAMARA | B15: 3 | C15: =C14-B15 -> 93 | D15: =C15/B12 -> 0.2137931
A16: RADIO | B16: 16 | C16: =C15-B16 -> 77 | D16: =C16/B12 -> 0.17701149
A17: TOTAL | B17: 435 | E17: 44901
A18: CAIDAS | B18: 82 | C18: 82 | D18: =C18/B17 -> 0.18850575
