Workbook
Name _25_de_agosto: 'RESUMEN TOTAL'!$A$4:$D$349
Name BONOMOcam: Hoja1!$B$2
Name COSEIDIcam: Hoja1!$B$4

Sheet RESUMEN TOTAL
A1: CANTIDAD DE CAMARAS | B1: =COUNTA(B5:B527) -> 392 | D1: PORCIENTO DE CAIDAS | K1: =(K3)/(K2+K3) -> 0.10026385 | L1: =(L3)/(L2+L3) -> 0.10817942 | M1: =(M3)/(M2+M3) -> 0.081794195 | N1: =(N3)/(N2+N3) -> 0.089709763 | P1: =(P3)/(P2+P3) -> 0.13720317 | Q1: =(Q3)/(Q2+Q3) -> 0.19261214 | R1: =(R3)/(R2+R3) -> 0.13192612 | S1: =(S3)/(S2+S3) -> 0.13456464 | T1: =(T3)/(T2+T3) -> 0.16886544 | U1: =(U3)/(U2+U3) -> 0.10133333 | V1: =(V3)/(V2+V3) -> 0.12 | W1: =(W3)/(W2+W3) -> 0.074666667 | ... AO1: =(AO3)/(AO2+AO3) -> 0
D2: FUNCIONAN | K2: =COUNTIF(K5:K379, "") -> 341 | L2: =COUNTIF(L5:L379, "") -> 338 | M2: =COUNTIF(M5:M379, "") -> 348 | N2: =COUNTIF(N5:N379, "") -> 345 | P2: =COUNTIF(P5:P379, "") -> 327 | Q2: =COUNTIF(Q5:Q379, "") -> 306 | R2: =COUNTIF(R5:R379, "") -> 329 | S2: =COUNTIF(S5:S379, "") -> 328 | T2: =COUNTIF(T5:T379, "") -> 315 | U2: =COUNTIF(U5:U379, "") -> 337 | V2: =COUNTIF(V5:V379, "") -> 330 | W2: =COUNTIF(W5:W379, "") -> 347 | ... AO2: =COUNTIF(AO5:AO379, "") -> 375
D3: CAIDAS | K3: =COUNTIF(K4:K447, "apagado") -> 38 | L3: =COUNTIF(L4:L447, "apagado") -> 41 | M3: =COUNTIF(M4:M447, "apagado") -> 31 | N3: =COUNTIF(N4:N447, "apagado") -> 34 | P3: =COUNTIF(P4:P447, "apagado") -> 52 | Q3: =COUNTIF(Q4:Q447, "apagado") -> 73 | R3: =COUNTIF(R4:R447, "apagado") -> 50 | S3: =COUNTIF(S4:S447, "apagado") -> 51 | T3: =COUNTIF(T4:T447, "apagado") -> 64 | U3: =COUNTIF(U4:U447, "apagado") -> 38 | V3: =COUNTIF(V4:V447, "apagado") -> 45 | W3: =COUNTIF(W4:W447, "apagado") -> 28 | ... AO3: =COUNTIF(AO4:AO447, "apagado") -> 0
A4: Barrio | B4: [Denominacion] | C4: [Empresa Mantenimiento] | D4: [Ubicacion] | E4: [Tipo de Camara] | F4: [Tipo de Conexion] | H4: DIAS FUNCIONANDO | I4: DIAS CAIDA | J4: EFECTIVIDAD | K4: 44774 | L4: 44775 | M4: 44776 | N4: 44777 | O4: 44778 | P4: 44779 | Q4: 44780 | R4: 44781 | S4: 44782 | T4: 44783 | U4: 44784 | V4: 44785 | W4: 44786 | X4: 44787 | Y4: 44788 | Z4: 44789 | AA4: 44790 | AB4: 44791 | AC4: 44792 | AD4: 44793 | AE4: 44794 | AF4: 44795 | AG4: 44796 | AH4: 44797 | AI4: 44798 | AJ4: 44799 | AK4: 44800 | AL4: 44801 | AM4: 44802 | AN4: 44803 | AO4: 44804
A5: ALTAMIRA | B5: ALT 03 | C5: BONOMO | D5: Bombero Galarza y Necochea | E5: Domo | F5: FIBRA OPTICA | G5: 172.20.12.54 | H5: =COUNTIF(K5:AN5,"") -> 23 | I5: =COUNTIF(K5:AL5,"APAGADO") -> 7 | J5: =(H5)/(I5+H5) -> 0.76666667 | P5: APAGADO | Q5: APAGADO | R5: APAGADO | S5: APAGADO | T5: APAGADO | U5: APAGADO | V5: APAGADO
A6: ALTAMIRA | B6: ALT 04 | C6: BONOMO | D6: Francia y Necochea | E6: Domo | F6: FIBRA OPTICA | G6: 172.20.12.55 | H6: =COUNTIF(K6:AN6,"") -> 23 | I6: =COUNTIF(K6:AL6,"APAGADO") -> 7 | J6: =(H6)/(I6+H6) -> 0.76666667 | P6: APAGADO | Q6: APAGADO | R6: APAGADO | S6: APAGADO | T6: APAGADO | U6: APAGADO | V6: APAGADO
A7: ALTAMIRA | B7: ALT 06 | C7: BONOMO | D7: LOPE DE VEGA Y NECOCHEA | E7: Domo | F7: PTO A FO | G7: 172.20.12.12 | H7: =COUNTIF(K7:AN7,"") -> 19 | I7: =COUNTIF(K7:AL7,"APAGADO") -> 11 | J7: =(H7)/(I7+H7) -> 0.63333333 | P7: APAGADO | Q7: APAGADO | R7: APAGADO | S7: APAGADO | T7: APAGADO | U7: APAGADO | V7: APAGADO | Y7: APAGADO | AI7: APAGADO | AJ7: APAGADO | AK7: APAGADO
A8: ALTAMIRA | B8: ALT 08 | C8: BONOMO | D8: HUMAITA Y NECOCHEA | E8: DOMO | F8: Fibra Optica | G8: 172.20.11.215 | H8: =COUNTIF(K8:AN8,"") -> 23 | I8: =COUNTIF(K8:AL8,"APAGADO") -> 7 | J8: =(H8)/(I8+H8) -> 0.76666667 | P8: APAGADO | Q8: APAGADO | R8: APAGADO | S8: APAGADO | T8: APAGADO | U8: APAGADO | V8: APAGADO
A9: ALTAMIRA | B9: ALT 09 | C9: BONOMO | D9: NECOCHEA Y CURUPAITY | E9: DOMO | F9: Fibra Optica | G9: 172.20.11.216 | H9: =COUNTIF(K9:AN9,"") -> 23 | I9: =COUNTIF(K9:AL9,"APAGADO") -> 7 | J9: =(H9)/(I9+H9) -> 0.76666667 | P9: APAGADO | Q9: APAGADO | R9: APAGADO | S9: APAGADO | T9: APAGADO | U9: APAGADO | V9: APAGADO
A10: ALTAMIRA | B10: ALT 10 | C10: BONOMO | D10: Calchaqui y Francia | E10: Domo | F10: Radio | H10: =COUNTIF(K10:AN10,"") -> 20 | I10: =COUNTIF(K10:AL10,"APAGADO") -> 9 | J10: =(H10)/(I10+H10) -> 0.68965517 | AD10: APAGADO | AE10: APAGADO | AF10: APAGADO | AG10: APAGADO | AH10: APAGADO | AI10: APAGADO | AJ10: APAGADO | AK10: APAGADO | AL10: APAGADO | AM10: APAGADO
A11: ALTAMIRA | B11: ALT01 | C11: BONOMO | D11: Calchaqui y Sgto. Cabral | E11: Domo | F11: Fibra Optica | G11: 172.20.10.6 | H11: =COUNTIF(K11:AN11,"") -> 30 | I11: =COUNTIF(K11:AL11,"APAGADO") -> 0 | J11: =(H11)/(I11+H11) -> 1
A12: ALTAMIRA | B12: ALT02 | C12: BONOMO | D12: Calchaqui y Lope de Vega | E12: Domo | F12: PTO A FO | G12: 172.20.12.218 | H12: =COUNTIF(K12:AN12,"") -> 30 | I12: =COUNTIF(K12:AL12,"APAGADO") -> 0 | J12: =(H12)/(I12+H12) -> 1
A13: ALTAMIRA | B13: ALT05 | C13: BONOMO | D13: Av. Calchaqui y Bombero Galarza | E13: Domo | F13: PTO A FO | G13: 172.20.12.216 | H13: =COUNTIF(K13:AN13,"") -> 20 | I13: =COUNTIF(K13:AL13,"APAGADO") -> 9 | J13: =(H13)/(I13+H13) -> 0.68965517 | AD13: APAGADO | AE13: APAGADO | AF13: APAGADO | AG13: APAGADO | AH13: APAGADO | AI13: APAGADO | AJ13: APAGADO | AK13: APAGADO | AL13: APAGADO | AM13: APAGADO
A14: ALTAMIRA | B14: ALT07 | C14: BONOMO | D14: AV. CALCHAQUI Y AV. DEL TRABAJO | E14: DOMO | F14: PTO A FO | G14: 172.20.10.57 | H14: =COUNTIF(K14:AN14,"") -> 30 | I14: =COUNTIF(K14:AL14,"APAGADO") -> 0 | J14: =(H14)/(I14+H14) -> 1
A15: AGUSTIN RAMIREZ | B15: ARA 01 | C15: COSEIDI | D15: Malambo y Tranquera | E15: Domo | F15: FIBRA OPTICA | G15: 172.20.12.110 | H15: =COUNTIF(K15:AN15,"") -> 28 | I15: =COUNTIF(K15:AL15,"APAGADO") -> 2 | J15: =(H15)/(I15+H15) -> 0.93333333 | L15: APAGADO | P15: APAGADO
A16: BELGRANO | B16: BEL 01 | C16: BONOMO | D16: San Martin y Dardo Rocha | E16: DOMO | F16: FIBRA OPTICA | G16: 172.20.12.64 | H16: =COUNTIF(K16:AN16,"") -> 24 | I16: =COUNTIF(K16:AL16,"APAGADO") -> 6 | J16: =(H16)/(I16+H16) -> 0.8 | L16: APAGADO | W16: APAGADO | X16: APAGADO | Y16: APAGADO | AJ16: APAGADO | AK16: APAGADO
A17: CENTRO | B17: CEN 05 | C17: BONOMO | D17: Bocuzzi e/España y San Martin | E17: DOMO | F17: Fibra Optica | G17: 172.20.10.200 | H17: =COUNTIF(K17:AN17,"") -> 30 | I17: =COUNTIF(K17:AL17,"APAGADO") -> 0 | J17: =(H17)/(I17+H17) -> 1
A18: CENTRO | B18: CEN 12 | C18: BONOMO | D18: Monteagudo y Mitre | E18: Domo | F18: Fibra Optica | G18: 172.20.10.23 | H18: =COUNTIF(K18:AN18,"") -> 30 | I18: =COUNTIF(K18:AL18,"APAGADO") -> 0 | J18: =(H18)/(I18+H18) -> 1
A19: CENTRO | B19: CEN 13 | C19: BONOMO | D19: 25 de Mayo y Maipu | E19: DOMO | F19: Fibra Optica | G19: 172.20.10.20 | H19: =COUNTIF(K19:AN19,"") -> 30 | I19: =COUNTIF(K19:AL19,"APAGADO") -> 0 | J19: =(H19)/(I19+H19) -> 1
A20: CENTRO | B20: CEN 37 | C20: BONOMO | D20: Diagonal Granaderos y Monteagudo | E20: Domo | F20: Fibra Optica | G20: 172.20.12.52 | H20: =COUNTIF(K20:AN20,"") -> 30 | I20: =COUNTIF(K20:AL20,"APAGADO") -> 0 | J20: =(H20)/(I20+H20) -> 1
A21: CENTRO | B21: CEN 50 | C21: BONOMO | D21: Av. San Martin y Newbery | E21: Domo | F21: Radio | G21: 172.20.200.184 | H21: =COUNTIF(K21:AN21,"") -> 30 | I21: =COUNTIF(K21:AL21,"APAGADO") -> 0 | J21: =(H21)/(I21+H21) -> 1
A22: CENTRO | B22: CEN 51 | C22: BONOMO | D22: ILLIA Y LAS HERAS | E22: FIJA | F22: Fibra Optica | G22: 172.20.11.29 | H22: =COUNTIF(K22:AN22,"") -> 30 | I22: =COUNTIF(K22:AL22,"APAGADO") -> 0 | J22: =(H22)/(I22+H22) -> 1
A23: CENTRO | B23: CEN 53 | C23: BONOMO | D23: GUTIERREZ Y BROWN | E23: Domo | F23: Radio | G23: 172.20.200.166 | H23: =COUNTIF(K23:AN23,"") -> 30 | I23: =COUNTIF(K23:AL23,"APAGADO") -> 0 | J23: =(H23)/(I23+H23) -> 1
A24: CENTRO | B24: CEN 54 | C24: BONOMO | D24: GUTIERREZ Y PRINGLES | E24: Domo | F24: Radio | G24: 172.20.200.165 | H24: =COUNTIF(K24:AN24,"") -> 30 | I24: =COUNTIF(K24:AL24,"APAGADO") -> 0 | J24: =(H24)/(I24+H24) -> 1
A25: CENTRO | B25: CEN 55 | C25: BONOMO | D25: BOUREL Y URQUIZA | E25: Domo | F25: Radio | G25: 172.20.200.163 | H25: =COUNTIF(K25:AN25,"") -> 30 | I25: =COUNTIF(K25:AL25,"APAGADO") -> 0 | J25: =(H25)/(I25+H25) -> 1
A26: CENTRO | B26: CEN 56 | C26: BONOMO | D26: Newbery y Falucho | E26: DOMO | F26: Radio | G26: 172.20.200.161 | H26: =COUNTIF(K26:AN26,"") -> 29 | I26: =COUNTIF(K26:AL26,"APAGADO") -> 1 | J26: =(H26)/(I26+H26) -> 0.96666667 | P26: APAGADO
A27: CENTRO | B27: CEN 57 | C27: BONOMO | D27: 25 DE MAYO Y DORREGO | E27: DOMO | F27: Radio | G27: 172.20.200.199 | H27: =COUNTIF(K27:AN27,"") -> 30 | I27: =COUNTIF(K27:AL27,"APAGADO") -> 0 | J27: =(H27)/(I27+H27) -> 1
A28: CENTRO | B28: CEN 58 | C28: BONOMO | D28: EEUU Y MORENO | E28: DOMO | F28: FIBRA OPTICA | G28: 172.20.11.84 | H28: =COUNTIF(K28:AN28,"") -> 30 | I28: =COUNTIF(K28:AL28,"APAGADO") -> 0 | J28: =(H28)/(I28+H28) -> 1
A29: CENTRO | B29: CEN 60 | C29: BONOMO | D29: RECONQUISTA Y ILLIA | E29: DOMO | F29: PTO A FO | G29: 172.20.12.67 | H29: =COUNTIF(K29:AN29,"") -> 30 | I29: =COUNTIF(K29:AL29,"APAGADO") -> 0 | J29: =(H29)/(I29+H29) -> 1
A30: CENTRO | B30: CEN 61 | C30: BONOMO | D30: BOUREL Y MAIPU | E30: DOMO | F30: Radio | G30: 172.20.200.159 | H30: =COUNTIF(K30:AN30,"") -> 30 | I30: =COUNTIF(K30:AL30,"APAGADO") -> 0 | J30: =(H30)/(I30+H30) -> 1
A31: CENTRO | B31: CEN 65 | C31: BONOMO | D31: SAN MARTIN Y JUAN PERON | E31: FIJA | F31: Fibra Optica | G31: 172.20.11.135 | H31: =COUNTIF(K31:AN31,"") -> 13 | I31: =COUNTIF(K31:AL31,"APAGADO") -> 16 | J31: =(H31)/(I31+H31) -> 0.44827586 | K31: APAGADO | L31: APAGADO | M31: APAGADO | N31: APAGADO | P31: APAGADO | Q31: APAGADO | R31: APAGADO | S31: APAGADO | T31: APAGADO | V31: APAGADO | Z31: APAGADO | AB31: APAGADO | AC31: APAGADO | AD31: APAGADO | AE31: APAGADO | AG31: APAGADO | AM31: APAGADO
A32: CENTRO | B32: CEN 70 | C32: BONOMO | D32: RIVADAVIA Y 25 MAYO | E32: Domo | F32: Fibra Optica | G32: 172.20.11.221 | H32: =COUNTIF(K32:AN32,"") -> 30 | I32: =COUNTIF(K32:AL32,"APAGADO") -> 0 | J32: =(H32)/(I32+H32) -> 1
A33: CENTRO | B33: CEN 71 | C33: BONOMO | D33: MORENO Y BOUREL | E33: Domo | F33: Fibra Optica | G33: 172.20.11.220 | H33: =COUNTIF(K33:AN33,"") -> 30 | I33: =COUNTIF(K33:AL33,"APAGADO") -> 0 | J33: =(H33)/(I33+H33) -> 1
A34: CENTRO | B34: CEN 72 | C34: BONOMO | D34: MORENO Y 25 DE MAYO | E34: Domo | F34: Fibra Optica | G34: 172.20.11.219 | H34: =COUNTIF(K34:AN34,"") -> 1 | I34: =COUNTIF(K34:AL34,"APAGADO") -> 28 | J34: =(H34)/(I34+H34) -> 0.034482759 | K34: APAGADO | L34: APAGADO | M34: APAGADO | N34: APAGADO | O34: APAGADO | P34: APAGADO | Q34: APAGADO | R34: APAGADO | S34: APAGADO | T34: APAGADO | U34: APAGADO | V34: APAGADO | W34: APAGADO | X34: APAGADO | Y34: APAGADO | Z34: APAGADO | AA34: APAGADO | AB34: APAGADO | AC34: APAGADO | AD34: APAGADO | AE34: APAGADO | AF34: APAGADO | AG34: APAGADO | AH34: APAGADO | AI34: APAGADO | AJ34: APAGADO | AK34: APAGADO | AL34: APAGADO | AM34: APAGADO
A35: CENTRO | B35: CEN 75 | C35: BONOMO | D35: 25 DE MAYO Y CASTELLI | E35: Domo | F35: Fibra Optica | H35: =COUNTIF(K35:AN35,"") -> 30 | I35: =COUNTIF(K35:AL35,"APAGADO") -> 0 | J35: =(H35)/(I35+H35) -> 1
A36: CENTRO | B36: CEN 76 | C36: BONOMO | D36: ESPAÑA E/MITRE Y BOCUZZI | E36: Fija | F36: Fibra Optica | H36: =COUNTIF(K36:AN36,"") -> 30 | I36: =COUNTIF(K36:AL36,"APAGADO") -> 0 | J36: =(H36)/(I36+H36) -> 1
A37: CENTRO | B37: CEN01 | C37: BONOMO | D37: San Martin y 9 de Julio | E37: Fija | F37: Fibra Optica | G37: 172.20.11.10 | H37: =COUNTIF(K37:AN37,"") -> 30 | I37: =COUNTIF(K37:AL37,"APAGADO") -> 0 | J37: =(H37)/(I37+H37) -> 1
A38: CENTRO | B38: CEN02 | C38: BONOMO | D38: San Martin y Almafuerte | E38: Fija | F38: Fibra Optica | G38: 172.20.11.11 | H38: =COUNTIF(K38:AN38,"") -> 30 | I38: =COUNTIF(K38:AL38,"APAGADO") -> 0 | J38: =(H38)/(I38+H38) -> 1
A39: CENTRO | B39: CEN03 | C39: BONOMO | D39: San Martin y Sallares | E39: Domo | F39: Fibra Optica | G39: 172.20.12.30 | H39: =COUNTIF(K39:AN39,"") -> 30 | I39: =COUNTIF(K39:AL39,"APAGADO") -> 0 | J39: =(H39)/(I39+H39) -> 1
A40: CENTRO | B40: CEN04 | C40: BONOMO | D40: San Martin y Contreras | E40: Domo | F40: Fibra Optica | G40: 172.20.12.29 | H40: =COUNTIF(K40:AN40,"") -> 30 | I40: =COUNTIF(K40:AL40,"APAGADO") -> 0 | J40: =(H40)/(I40+H40) -> 1
...

Sheet ESTADISTICA
A1: ='RESUMEN TOTAL'!A4 -> Barrio | B1: ='RESUMEN TOTAL'!B4 -> [Denominacion] | C1: ='RESUMEN TOTAL'!D4 -> [Ubicacion] | D1: ='RESUMEN TOTAL'!E4 -> [Tipo de Camara] | E1: ='RESUMEN TOTAL'!F4 -> [Tipo de Conexion] | F1: ='RESUMEN TOTAL'!K4 -> 44774 | G1: ='RESUMEN TOTAL'!L4 -> 44775 | H1: ='RESUMEN TOTAL'!M4 -> 44776 | I1: ='RESUMEN TOTAL'!N4 -> 44777 | J1: ='RESUMEN TOTAL'!O4 -> 44778 | K1: ='RESUMEN TOTAL'!P4 -> 44779 | L1: ='RESUMEN TOTAL'!Q4 -> 44780 | M1: ='RESUMEN TOTAL'!R4 -> 44781 | ... AI1: ='RESUMEN TOTAL'!AN4 -> 44803
A2: ='RESUMEN TOTAL'!A5 -> ALTAMIRA | B2: ='RESUMEN TOTAL'!B5 -> ALT 03 | C2: ='RESUMEN TOTAL'!D5 -> Bombero Galarza y Necochea | D2: ='RESUMEN TOTAL'!E5 -> Domo | E2: ='RESUMEN TOTAL'!F5 -> FIBRA OPTICA | F2: ='RESUMEN TOTAL'!K5 -> 0 | G2: ='RESUMEN TOTAL'!L5 -> 0 | H2: ='RESUMEN TOTAL'!M5 -> 0 | I2: ='RESUMEN TOTAL'!N5 -> 0 | J2: ='RESUMEN TOTAL'!O5 -> 0 | K2: ='RESUMEN TOTAL'!P5 -> APAGADO | L2: ='RESUMEN TOTAL'!Q5 -> APAGADO | M2: ='RESUMEN TOTAL'!R5 -> APAGADO | ... AI2: ='RESUMEN TOTAL'!AN5 -> 0
A3: ='RESUMEN TOTAL'!A6 -> ALTAMIRA | B3: ='RESUMEN TOTAL'!B6 -> ALT 04 | C3: ='RESUMEN TOTAL'!D6 -> Francia y Necochea | D3: ='RESUMEN TOTAL'!E6 -> Domo | E3: ='RESUMEN TOTAL'!F6 -> FIBRA OPTICA | F3: ='RESUMEN TOTAL'!K6 -> 0 | G3: ='RESUMEN TOTAL'!L6 -> 0 | H3: ='RESUMEN TOTAL'!M6 -> 0 | I3: ='RESUMEN TOTAL'!N6 -> 0 | J3: ='RESUMEN TOTAL'!O6 -> 0 | K3: ='RESUMEN TOTAL'!P6 -> APAGADO | L3: ='RESUMEN TOTAL'!Q6 -> APAGADO | M3: ='RESUMEN TOTAL'!R6 -> APAGADO | ... AI3: ='RESUMEN TOTAL'!AN6 -> 0
A4: ='RESUMEN TOTAL'!A7 -> ALTAMIRA | B4: ='RESUMEN TOTAL'!B7 -> ALT 06 | C4: ='RESUMEN TOTAL'!D7 -> LOPE DE VEGA Y NECOCHEA | D4: ='RESUMEN TOTAL'!E7 -> Domo | E4: ='RESUMEN TOTAL'!F7 -> PTO A FO | F4: ='RESUMEN TOTAL'!K7 -> 0 | G4: ='RESUMEN TOTAL'!L7 -> 0 | H4: ='RESUMEN TOTAL'!M7 -> 0 | I4: ='RESUMEN TOTAL'!N7 -> 0 | J4: ='RESUMEN TOTAL'!O7 -> 0 | K4: ='RESUMEN TOTAL'!P7 -> APAGADO | L4: ='RESUMEN TOTAL'!Q7 -> APAGADO | M4: ='RESUMEN TOTAL'!R7 -> APAGADO | ... AI4: ='RESUMEN TOTAL'!AN7 -> 0
A5: ='RESUMEN TOTAL'!A8 -> ALTAMIRA | B5: ='RESUMEN TOTAL'!B8 -> ALT 08 | C5: ='RESUMEN TOTAL'!D8 -> HUMAITA Y NECOCHEA | D5: ='RESUMEN TOTAL'!E8 -> DOMO | E5: ='RESUMEN TOTAL'!F8 -> Fibra Optica | F5: ='RESUMEN TOTAL'!K8 -> 0 | G5: ='RESUMEN TOTAL'!L8 -> 0 | H5: ='RESUMEN TOTAL'!M8 -> 0 | I5: ='RESUMEN TOTAL'!N8 -> 0 | J5: ='RESUMEN TOTAL'!O8 -> 0 | K5: ='RESUMEN TOTAL'!P8 -> APAGADO | L5: ='RESUMEN TOTAL'!Q8 -> APAGADO | M5: ='RESUMEN TOTAL'!R8 -> APAGADO | ... AI5: ='RESUMEN TOTAL'!AN8 -> 0
A6: ='RESUMEN TOTAL'!A9 -> ALTAMIRA | B6: ='RESUMEN TOTAL'!B9 -> ALT 09 | C6: ='RESUMEN TOTAL'!D9 -> NECOCHEA Y CURUPAITY | D6: ='RESUMEN TOTAL'!E9 -> DOMO | E6: ='RESUMEN TOTAL'!F9 -> Fibra Optica | F6: ='RESUMEN TOTAL'!K9 -> 0 | G6: ='RESUMEN TOTAL'!L9 -> 0 | H6: ='RESUMEN TOTAL'!M9 -> 0 | I6: ='RESUMEN TOTAL'!N9 -> 0 | J6: ='RESUMEN TOTAL'!O9 -> 0 | K6: ='RESUMEN TOTAL'!P9 -> APAGADO | L6: ='RESUMEN TOTAL'!Q9 -> APAGADO | M6: ='RESUMEN TOTAL'!R9 -> APAGADO | ... AI6: ='RESUMEN TOTAL'!AN9 -> 0
A7: ='RESUMEN TOTAL'!A10 -> ALTAMIRA | B7: ='RESUMEN TOTAL'!B10 -> ALT 10 | C7: ='RESUMEN TOTAL'!D10 -> Calchaqui y Francia | D7: ='RESUMEN TOTAL'!E10 -> Domo | E7: ='RESUMEN TOTAL'!F10 -> Radio | F7: ='RESUMEN TOTAL'!K10 -> 0 | G7: ='RESUMEN TOTAL'!L10 -> 0 | H7: ='RESUMEN TOTAL'!M10 -> 0 | I7: ='RESUMEN TOTAL'!N10 -> 0 | J7: ='RESUMEN TOTAL'!O10 -> 0 | K7: ='RESUMEN TOTAL'!P10 -> 0 | L7: ='RESUMEN TOTAL'!Q10 -> 0 | M7: ='RESUMEN TOTAL'!R10 -> 0 | ... AI7: ='RESUMEN TOTAL'!AN10 -> 0
A8: ='RESUMEN TOTAL'!A11 -> ALTAMIRA | B8: ='RESUMEN TOTAL'!B11 -> ALT01 | C8: ='RESUMEN TOTAL'!D11 -> Calchaqui y Sgto. Cabral | D8: ='RESUMEN TOTAL'!E11 -> Domo | E8: ='RESUMEN TOTAL'!F11 -> Fibra Optica | F8: ='RESUMEN TOTAL'!K11 -> 0 | G8: ='RESUMEN TOTAL'!L11 -> 0 | H8: ='RESUMEN TOTAL'!M11 -> 0 | I8: ='RESUMEN TOTAL'!N11 -> 0 | J8: ='RESUMEN TOTAL'!O11 -> 0 | K8: ='RESUMEN TOTAL'!P11 -> 0 | L8: ='RESUMEN TOTAL'!Q11 -> 0 | M8: ='RESUMEN TOTAL'!R11 -> 0 | ... AI8: ='RESUMEN TOTAL'!AN11 -> 0
A9: ='RESUMEN TOTAL'!A12 -> ALTAMIRA | B9: ='RESUMEN TOTAL'!B12 -> ALT02 | C9: ='RESUMEN TOTAL'!D12 -> Calchaqui y Lope de Vega | D9: ='RESUMEN TOTAL'!E12 -> Domo | E9: ='RESUMEN TOTAL'!F12 -> PTO A FO | F9: ='RESUMEN TOTAL'!K12 -> 0 | G9: ='RESUMEN TOTAL'!L12 -> 0 | H9: ='RESUMEN TOTAL'!M12 -> 0 | I9: ='RESUMEN TOTAL'!N12 -> 0 | J9: ='RESUMEN TOTAL'!O12 -> 0 | K9: ='RESUMEN TOTAL'!P12 -> 0 | L9: ='RESUMEN TOTAL'!Q12 -> 0 | M9: ='RESUMEN TOTAL'!R12 -> 0 | ... AI9: ='RESUMEN TOTAL'!AN12 -> 0
A10: ='RESUMEN TOTAL'!A13 -> ALTAMIRA | B10: ='RESUMEN TOTAL'!B13 -> ALT05 | C10: ='RESUMEN TOTAL'!D13 -> Av. Calchaqui y Bombero Galarza | D10: ='RESUMEN TOTAL'!E13 -> Domo | E10: ='RESUMEN TOTAL'!F13 -> PTO A FO | F10: ='RESUMEN TOTAL'!K13 -> 0 | G10: ='RESUMEN TOTAL'!L13 -> 0 | H10: ='RESUMEN TOTAL'!M13 -> 0 | I10: ='RESUMEN TOTAL'!N13 -> 0 | J10: ='RESUMEN TOTAL'!O13 -> 0 | K10: ='RESUMEN TOTAL'!P13 -> 0 | L10: ='RESUMEN TOTAL'!Q13 -> 0 | M10: ='RESUMEN TOTAL'!R13 -> 0 | ... AI10: ='RESUMEN TOTAL'!AN13 -> 0
A11: ='RESUMEN TOTAL'!A14 -> ALTAMIRA | B11: ='RESUMEN TOTAL'!B14 -> ALT07 | C11: ='RESUMEN TOTAL'!D14 -> AV. CALCHAQUI Y AV. DEL TRABAJO | D11: ='RESUMEN TOTAL'!E14 -> DOMO | E11: ='RESUMEN TOTAL'!F14 -> PTO A FO | F11: ='RESUMEN TOTAL'!K14 -> 0 | G11: ='RESUMEN TOTAL'!L14 -> 0 | H11: ='RESUMEN TOTAL'!M14 -> 0 | I11: ='RESUMEN TOTAL'!N14 -> 0 | J11: ='RESUMEN TOTAL'!O14 -> 0 | K11: ='RESUMEN TOTAL'!P14 -> 0 | L11: ='RESUMEN TOTAL'!Q14 -> 0 | M11: ='RESUMEN TOTAL'!R14 -> 0 | ... AI11: ='RESUMEN TOTAL'!AN14 -> 0
A12: ='RESUMEN TOTAL'!A15 -> AGUSTIN RAMIREZ | B12: ='RESUMEN TOTAL'!B15 -> ARA 01 | C12: ='RESUMEN TOTAL'!D15 -> Malambo y Tranquera | D12: ='RESUMEN TOTAL'!E15 -> Domo | E12: ='RESUMEN TOTAL'!F15 -> FIBRA OPTICA | F12: ='RESUMEN TOTAL'!K15 -> 0 | G12: ='RESUMEN TOTAL'!L15 -> APAGADO | H12: ='RESUMEN TOTAL'!M15 -> 0 | I12: ='RESUMEN TOTAL'!N15 -> 0 | J12: ='RESUMEN TOTAL'!O15 -> 0 | K12: ='RESUMEN TOTAL'!P15 -> APAGADO | L12: ='RESUMEN TOTAL'!Q15 -> 0 | M12: ='RESUMEN TOTAL'!R15 -> 0 | ... AI12: ='RESUMEN TOTAL'!AN15 -> 0
... A399: ='RESUMEN TOTAL'!A402 -> 0 | B399: ='RESUMEN TOTAL'!B402 -> 0 | C399: ='RESUMEN TOTAL'!D402 -> 0 | D399: ='RESUMEN TOTAL'!E402 -> 0 | E399: ='RESUMEN TOTAL'!F402 -> 0 | F399: ='RESUMEN TOTAL'!K402 -> 0 | G399: ='RESUMEN TOTAL'!L402 -> 0 | H399: ='RESUMEN TOTAL'!M402 -> 0 | I399: ='RESUMEN TOTAL'!N402 -> 0 | J399: ='RESUMEN TOTAL'!O402 -> 0 | K399: ='RESUMEN TOTAL'!P402 -> 0 | L399: ='RESUMEN TOTAL'!Q402 -> 0 | M399: ='RESUMEN TOTAL'!R402 -> 0 | ... AI399: ='RESUMEN TOTAL'!AN402 -> 0

Sheet APAGADOS
E1: APAGADOS | F1: =COUNTIF(F3:F400, "APAGADO") -> 38 | G1: =COUNTIF(G3:G400, "APAGADO") -> 41 | H1: =COUNTIF(H3:H400, "APAGADO") -> 31 | I1: =COUNTIF(I3:I400, "APAGADO") -> 34 | J1: =COUNTIF(J3:J400, "APAGADO") -> 30 | K1: =COUNTIF(K3:K400, "APAGADO") -> 52 | L1: =COUNTIF(L3:L400, "APAGADO") -> 73 | M1: =COUNTIF(M3:M400, "APAGADO") -> 50 | ... AI1: =COUNTIF(AI3:AI400, "APAGADO") -> 0
A2: =ESTADISTICA!A1 -> Barrio | B2: =ESTADISTICA!B1 -> [Denominacion] | C2: =ESTADISTICA!C1 -> [Ubicacion] | D2: =ESTADISTICA!D1 -> [Tipo de Camara] | E2: =ESTADISTICA!E1 -> [Tipo de Conexion] | F2: =ESTADISTICA!F1 -> 44774 | G2: =ESTADISTICA!G1 -> 44775 | H2: =ESTADISTICA!H1 -> 44776 | ... AI2: =ESTADISTICA!AI1 -> 44803
A3: =ESTADISTICA!A2 -> ALTAMIRA | B3: =ESTADISTICA!B2 -> ALT 03 | C3: =ESTADISTICA!C2 -> Bombero Galarza y Necochea | D3: =ESTADISTICA!D2 -> Domo | E3: =ESTADISTICA!E2 -> FIBRA OPTICA | F3: =ESTADISTICA!F2 -> 0 | G3: =ESTADISTICA!G2 -> 0 | H3: =ESTADISTICA!H2 -> 0 | ... AI3: =ESTADISTICA!AI2 -> 0
A4: =ESTADISTICA!A3 -> ALTAMIRA | B4: =ESTADISTICA!B3 -> ALT 04 | C4: =ESTADISTICA!C3 -> Francia y Necochea | D4: =ESTADISTICA!D3 -> Domo | E4: =ESTADISTICA!E3 -> FIBRA OPTICA | F4: =ESTADISTICA!F3 -> 0 | G4: =ESTADISTICA!G3 -> 0 | H4: =ESTADISTICA!H3 -> 0 | ... AI4: =ESTADISTICA!AI3 -> 0
A5: =ESTADISTICA!A4 -> ALTAMIRA | B5: =ESTADISTICA!B4 -> ALT 06 | C5: =ESTADISTICA!C4 -> LOPE DE VEGA Y NECOCHEA | D5: =ESTADISTICA!D4 -> Domo | E5: =ESTADISTICA!E4 -> PTO A FO | F5: =ESTADISTICA!F4 -> 0 | G5: =ESTADISTICA!G4 -> 0 | H5: =ESTADISTICA!H4 -> 0 | ... AI5: =ESTADISTICA!AI4 -> 0
A6: =ESTADISTICA!A5 -> ALTAMIRA | B6: =ESTADISTICA!B5 -> ALT 08 | C6: =ESTADISTICA!C5 -> HUMAITA Y NECOCHEA | D6: =ESTADISTICA!D5 -> DOMO | E6: =ESTADISTICA!E5 -> Fibra Optica | F6: =ESTADISTICA!F5 -> 0 | G6: =ESTADISTICA!G5 -> 0 | H6: =ESTADISTICA!H5 -> 0 | ... AI6: =ESTADISTICA!AI5 -> 0
A7: =ESTADISTICA!A6 -> ALTAMIRA | B7: =ESTADISTICA!B6 -> ALT 09 | C7: =ESTADISTICA!C6 -> NECOCHEA Y CURUPAITY | D7: =ESTADISTICA!D6 -> DOMO | E7: =ESTADISTICA!E6 -> Fibra Optica | F7: =ESTADISTICA!F6 -> 0 | G7: =ESTADISTICA!G6 -> 0 | H7: =ESTADISTICA!H6 -> 0 | ... AI7: =ESTADISTICA!AI6 -> 0
A8: =ESTADISTICA!A7 -> ALTAMIRA | B8: =ESTADISTICA!B7 -> ALT 10 | C8: =ESTADISTICA!C7 -> Calchaqui y Francia | D8: =ESTADISTICA!D7 -> Domo | E8: =ESTADISTICA!E7 -> Radio | F8: =ESTADISTICA!F7 -> 0 | G8: =ESTADISTICA!G7 -> 0 | H8: =ESTADISTICA!H7 -> 0 | ... AI8: =ESTADISTICA!AI7 -> 0
A9: =ESTADISTICA!A8 -> ALTAMIRA | B9: =ESTADISTICA!B8 -> ALT01 | C9: =ESTADISTICA!C8 -> Calchaqui y Sgto. Cabral | D9: =ESTADISTICA!D8 -> Domo | E9: =ESTADISTICA!E8 -> Fibra Optica | F9: =ESTADISTICA!F8 -> 0 | G9: =ESTADISTICA!G8 -> 0 | H9: =ESTADISTICA!H8 -> 0 | ... AI9: =ESTADISTICA!AI8 -> 0
A10: =ESTADISTICA!A9 -> ALTAMIRA | B10: =ESTADISTICA!B9 -> ALT02 | C10: =ESTADISTICA!C9 -> Calchaqui y Lope de Vega | D10: =ESTADISTICA!D9 -> Domo | E10: =ESTADISTICA!E9 -> PTO A FO | F10: =ESTADISTICA!F9 -> 0 | G10: =ESTADISTICA!G9 -> 0 | H10: =ESTADISTICA!H9 -> 0 | ... AI10: =ESTADISTICA!AI9 -> 0
A11: =ESTADISTICA!A10 -> ALTAMIRA | B11: =ESTADISTICA!B10 -> ALT05 | C11: =ESTADISTICA!C10 -> Av. Calchaqui y Bombero Galarza | D11: =ESTADISTICA!D10 -> Domo | E11: =ESTADISTICA!E10 -> PTO A FO | F11: =ESTADISTICA!F10 -> 0 | G11: =ESTADISTICA!G10 -> 0 | H11: =ESTADISTICA!H10 -> 0 | ... AI11: =ESTADISTICA!AI10 -> 0
A12: =ESTADISTICA!A11 -> ALTAMIRA | B12: =ESTADISTICA!B11 -> ALT07 | C12: =ESTADISTICA!C11 -> AV. CALCHAQUI Y AV. DEL TRABAJO | D12: =ESTADISTICA!D11 -> DOMO | E12: =ESTADISTICA!E11 -> PTO A FO | F12: =ESTADISTICA!F11 -> 0 | G12: =ESTADISTICA!G11 -> 0 | H12: =ESTADISTICA!H11 -> 0 | ... AI12: =ESTADISTICA!AI11 -> 0
A13: =ESTADISTICA!A12 -> AGUSTIN RAMIREZ | B13: =ESTADISTICA!B12 -> ARA 01 | C13: =ESTADISTICA!C12 -> Malambo y Tranquera | D13: =ESTADISTICA!D12 -> Domo | E13: =ESTADISTICA!E12 -> FIBRA OPTICA | F13: =ESTADISTICA!F12 -> 0 | G13: =ESTADISTICA!G12 -> APAGADO | H13: =ESTADISTICA!H12 -> 0 | ... AI13: =ESTADISTICA!AI12 -> 0
... A401: =ESTADISTICA!A400 -> 0 | B401: =ESTADISTICA!B400 -> 0 | C401: =ESTADISTICA!C400 -> 0 | D401: =ESTADISTICA!D400 -> 0 | E401: =ESTADISTICA!E400 -> 0 | F401: =ESTADISTICA!F400 -> 0 | G401: =ESTADISTICA!G400 -> 0 | H401: =ESTADISTICA!H400 -> 0 | ... AI401: =ESTADISTICA!AI400 -> 0

Sheet APAGADOS FIBRA
C1: TOTAL FIBRA | D1: =COUNTIFS(E4:E400,"=Fibra Optica") -> 261
E2: APAGADOS | F2: =COUNTIFS(F4:F400, "=APAGADO",E4:E400,"=Fibra Optica") -> 31 | G2: =COUNTIFS(G4:G400, "=APAGADO",E4:E400,"=Fibra Optica") -> 35 | H2: =COUNTIFS(H4:H400, "=APAGADO",E4:E400,"=Fibra Optica") -> 25 | I2: =COUNTIFS(I4:I400, "=APAGADO",E4:E400,"=Fibra Optica") -> 28 | J2: =COUNTIFS(J4:J400, "=APAGADO",E4:E400,"=Fibra Optica") -> 25 | K2: =COUNTIFS(K4:K400, "=APAGADO",E4:E400,"=Fibra Optica") -> 44 | L2: =COUNTIFS(L4:L400, "=APAGADO",E4:E400,"=Fibra Optica") -> 66 | M2: =COUNTIFS(M4:M400, "=APAGADO",E4:E400,"=Fibra Optica") -> 43 | N2: =COUNTIFS(N4:N400, "=APAGADO",E4:E400,"=Fibra Optica") -> 45 | O2: =COUNTIFS(O4:O400, "=APAGADO",E4:E400,"=Fibra Optica") -> 48 | P2: =COUNTIFS(P4:P400, "=APAGADO",E4:E400,"=Fibra Optica") -> 33 | Q2: =COUNTIFS(Q4:Q400, "=APAGADO",E4:E400,"=Fibra Optica") -> 38 | R2: =COUNTIFS(R4:R400, "=APAGADO",E4:E400,"=Fibra Optica") -> 25 | S2: =COUNTIFS(S4:S400, "=APAGADO",E4:E400,"=Fibra Optica") -> 26 | T2: =COUNTIFS(T4:T400, "=APAGADO",E4:E400,"=Fibra Optica") -> 27 | U2: =COUNTIFS(U4:U400, "=APAGADO",E4:E400,"=Fibra Optica") -> 31 | V2: =COUNTIFS(V4:V400, "=APAGADO",E4:E400,"=Fibra Optica") -> 25 | W2: =COUNTIFS(W4:W400, "=APAGADO",E4:E400,"=Fibra Optica") -> 30 | X2: =COUNTIFS(X4:X400, "=APAGADO",E4:E400,"=Fibra Optica") -> 30 | Y2: =COUNTIFS(Y4:Y400, "=APAGADO",E4:E400,"=Fibra Optica") -> 28 | Z2: =COUNTIFS(Z4:Z400, "=APAGADO",E4:E400,"=Fibra Optica") -> 28 | AA2: =COUNTIFS(AA4:AA400, "=APAGADO",E4:E400,"=Fibra Optica") -> 27 | AB2: =COUNTIFS(AB4:AB400, "=APAGADO",E4:E400,"=Fibra Optica") -> 30 | AC2: =COUNTIFS(AC4:AC400, "=APAGADO",E4:E400,"=Fibra Optica") -> 25 | AD2: =COUNTIFS(AD4:AD400, "=APAGADO",E4:E400,"=Fibra Optica") -> 24 | AE2: =COUNTIFS(AE4:AE400, "=APAGADO",E4:E400,"=Fibra Optica") -> 25 | AF2: =COUNTIFS(AF4:AF400, "=APAGADO",E4:E400,"=Fibra Optica") -> 34 | AG2: =COUNTIFS(AG4:AG400, "=APAGADO",E4:E400,"=Fibra Optica") -> 31 | AH2: =COUNTIFS(AH4:AH400, "=APAGADO",E4:E400,"=Fibra Optica") -> 35 | AI2: =COUNTIFS(AI4:AI400, "=APAGADO",E4:E400,"=Fibra Optica") -> 0
A3: =ESTADISTICA!A1 -> Barrio | B3: =ESTADISTICA!B1 -> [Denominacion] | C3: =ESTADISTICA!C1 -> [Ubicacion] | D3: =ESTADISTICA!D1 -> [Tipo de Camara] | E3: =ESTADISTICA!E1 -> [Tipo de Conexion] | F3: =ESTADISTICA!F1 -> 44774 | G3: =ESTADISTICA!G1 -> 44775 | H3: =ESTADISTICA!H1 -> 44776 | ... AI3: =ESTADISTICA!AI1 -> 44803
A4: =ESTADISTICA!A2 -> ALTAMIRA | B4: =ESTADISTICA!B2 -> ALT 03 | C4: =ESTADISTICA!C2 -> Bombero Galarza y Necochea | D4: =ESTADISTICA!D2 -> Domo | E4: =ESTADISTICA!E2 -> FIBRA OPTICA | F4: =ESTADISTICA!F2 -> 0 | G4: =ESTADISTICA!G2 -> 0 | H4: =ESTADISTICA!H2 -> 0 | ... AI4: =ESTADISTICA!AI2 -> 0
A5: =ESTADISTICA!A3 -> ALTAMIRA | B5: =ESTADISTICA!B3 -> ALT 04 | C5: =ESTADISTICA!C3 -> Francia y Necochea | D5: =ESTADISTICA!D3 -> Domo | E5: =ESTADISTICA!E3 -> FIBRA OPTICA | F5: =ESTADISTICA!F3 -> 0 | G5: =ESTADISTICA!G3 -> 0 | H5: =ESTADISTICA!H3 -> 0 | ... AI5: =ESTADISTICA!AI3 -> 0
A6: =ESTADISTICA!A4 -> ALTAMIRA | B6: =ESTADISTICA!B4 -> ALT 06 | C6: =ESTADISTICA!C4 -> LOPE DE VEGA Y NECOCHEA | D6: =ESTADISTICA!D4 -> Domo | E6: =ESTADISTICA!E4 -> PTO A FO | F6: =ESTADISTICA!F4 -> 0 | G6: =ESTADISTICA!G4 -> 0 | H6: =ESTADISTICA!H4 -> 0 | ... AI6: =ESTADISTICA!AI4 -> 0
A7: =ESTADISTICA!A5 -> ALTAMIRA | B7: =ESTADISTICA!B5 -> ALT 08 | C7: =ESTADISTICA!C5 -> HUMAITA Y NECOCHEA | D7: =ESTADISTICA!D5 -> DOMO | E7: =ESTADISTICA!E5 -> Fibra Optica | F7: =ESTADISTICA!F5 -> 0 | G7: =ESTADISTICA!G5 -> 0 | H7: =ESTADISTICA!H5 -> 0 | ... AI7: =ESTADISTICA!AI5 -> 0
A8: =ESTADISTICA!A6 -> ALTAMIRA | B8: =ESTADISTICA!B6 -> ALT 09 | C8: =ESTADISTICA!C6 -> NECOCHEA Y CURUPAITY | D8: =ESTADISTICA!D6 -> DOMO | E8: =ESTADISTICA!E6 -> Fibra Optica | F8: =ESTADISTICA!F6 -> 0 | G8: =ESTADISTICA!G6 -> 0 | H8: =ESTADISTICA!H6 -> 0 | ... AI8: =ESTADISTICA!AI6 -> 0
A9: =ESTADISTICA!A7 -> ALTAMIRA | B9: =ESTADISTICA!B7 -> ALT 10 | C9: =ESTADISTICA!C7 -> Calchaqui y Francia | D9: =ESTADISTICA!D7 -> Domo | E9: =ESTADISTICA!E7 -> Radio | F9: =ESTADISTICA!F7 -> 0 | G9: =ESTADISTICA!G7 -> 0 | H9: =ESTADISTICA!H7 -> 0 | ... AI9: =ESTADISTICA!AI7 -> 0
A10: =ESTADISTICA!A8 -> ALTAMIRA | B10: =ESTADISTICA!B8 -> ALT01 | C10: =ESTADISTICA!C8 -> Calchaqui y Sgto. Cabral | D10: =ESTADISTICA!D8 -> Domo | E10: =ESTADISTICA!E8 -> Fibra Optica | F10: =ESTADISTICA!F8 -> 0 | G10: =ESTADISTICA!G8 -> 0 | H10: =ESTADISTICA!H8 -> 0 | ... AI10: =ESTADISTICA!AI8 -> 0
A11: =ESTADISTICA!A9 -> ALTAMIRA | B11: =ESTADISTICA!B9 -> ALT02 | C11: =ESTADISTICA!C9 -> Calchaqui y Lope de Vega | D11: =ESTADISTICA!D9 -> Domo | E11: =ESTADISTICA!E9 -> PTO A FO | F11: =ESTADISTICA!F9 -> 0 | G11: =ESTADISTICA!G9 -> 0 | H11: =ESTADISTICA!H9 -> 0 | ... AI11: =ESTADISTICA!AI9 -> 0
A12: =ESTADISTICA!A10 -> ALTAMIRA | B12: =ESTADISTICA!B10 -> ALT05 | C12: =ESTADISTICA!C10 -> Av. Calchaqui y Bombero Galarza | D12: =ESTADISTICA!D10 -> Domo | E12: =ESTADISTICA!E10 -> PTO A FO | F12: =ESTADISTICA!F10 -> 0 | G12: =ESTADISTICA!G10 -> 0 | H12: =ESTADISTICA!H10 -> 0 | ... AI12: =ESTADISTICA!AI10 -> 0
A13: =ESTADISTICA!A11 -> ALTAMIRA | B13: =ESTADISTICA!B11 -> ALT07 | C13: =ESTADISTICA!C11 -> AV. CALCHAQUI Y AV. DEL TRABAJO | D13: =ESTADISTICA!D11 -> DOMO | E13: =ESTADISTICA!E11 -> PTO A FO | F13: =ESTADISTICA!F11 -> 0 | G13: =ESTADISTICA!G11 -> 0 | H13: =ESTADISTICA!H11 -> 0 | ... AI13: =ESTADISTICA!AI11 -> 0
A14: =ESTADISTICA!A12 -> AGUSTIN RAMIREZ | B14: =ESTADISTICA!B12 -> ARA 01 | C14: =ESTADISTICA!C12 -> Malambo y Tranquera | D14: =ESTADISTICA!D12 -> Domo | E14: =ESTADISTICA!E12 -> FIBRA OPTICA | F14: =ESTADISTICA!F12 -> 0 | G14: =ESTADISTICA!G12 -> APAGADO | H14: =ESTADISTICA!H12 -> 0 | ... AI14: =ESTADISTICA!AI12 -> 0
... A400: =ESTADISTICA!A398 -> 0 | B400: =ESTADISTICA!B398 -> 0 | C400: =ESTADISTICA!C398 -> 0 | D400: =ESTADISTICA!D398 -> 0 | E400: =ESTADISTICA!E398 -> 0 | F400: =ESTADISTICA!F398 -> 0 | G400: =ESTADISTICA!G398 -> 0 | H400: =ESTADISTICA!H398 -> 0 | ... AI400: =ESTADISTICA!AI398 -> 0

Sheet APAGADOS ANTENA
C1: TOTAL PTO A FO
E2: APAGADOS | F2: =COUNTIFS(F4:F400, "=APAGADO",E4:E400,"=PTO A FO") -> 3 | G2: =COUNTIFS(G4:G400, "=APAGADO",E4:E400,"=PTO A FO") -> 2 | H2: =COUNTIFS(H4:H400, "=APAGADO",E4:E400,"=PTO A FO") -> 3 | I2: =COUNTIFS(I4:I400, "=APAGADO",E4:E400,"=PTO A FO") -> 3 | J2: =COUNTIFS(J4:J400, "=APAGADO",E4:E400,"=PTO A FO") -> 2 | K2: =COUNTIFS(K4:K400, "=APAGADO",E4:E400,"=PTO A FO") -> 3 | L2: =COUNTIFS(L4:L400, "=APAGADO",E4:E400,"=PTO A FO") -> 2 | M2: =COUNTIFS(M4:M400, "=APAGADO",E4:E400,"=PTO A FO") -> 2 | N2: =COUNTIFS(N4:N400, "=APAGADO",E4:E400,"=PTO A FO") -> 2 | O2: =COUNTIFS(O4:O500, "=APAGADO",E4:E500,"=PTO A FO") -> 10 | P2: =COUNTIFS(P4:P400, "=APAGADO",E4:E400,"=PTO A FO") -> 1 | Q2: =COUNTIFS(Q4:Q400, "=APAGADO",E4:E400,"=PTO A FO") -> 2 | R2: =COUNTIFS(R4:R400, "=APAGADO",E4:E400,"=PTO A FO") -> 0 | S2: =COUNTIFS(S4:S400, "=APAGADO",E4:E400,"=PTO A FO") -> 1 | T2: =COUNTIFS(T4:T400, "=APAGADO",E4:E400,"=PTO A FO") -> 3 | U2: =COUNTIFS(U4:U400, "=APAGADO",E4:E400,"=PTO A FO") -> 2 | V2: =COUNTIFS(V4:V400, "=APAGADO",E4:E400,"=PTO A FO") -> 2 | W2: =COUNTIFS(W4:W400, "=APAGADO",E4:E400,"=PTO A FO") -> 2 | X2: =COUNTIFS(X4:X400, "=APAGADO",E4:E400,"=PTO A FO") -> 2 | Y2: =COUNTIFS(Y4:Y400, "=APAGADO",E4:E400,"=PTO A FO") -> 3 | Z2: =COUNTIFS(Z4:Z400, "=APAGADO",E4:E400,"=PTO A FO") -> 3 | AA2: =COUNTIFS(AA4:AA400, "=APAGADO",E4:E400,"=PTO A FO") -> 2 | AB2: =COUNTIFS(AB4:AB400, "=APAGADO",E4:E400,"=PTO A FO") -> 2 | AC2: =COUNTIFS(AC4:AC400, "=APAGADO",E4:E400,"=PTO A FO") -> 1 | AD2: =COUNTIFS(AD4:AD400, "=APAGADO",E4:E400,"=PTO A FO") -> 2 | AE2: =COUNTIFS(AE4:AE400, "=APAGADO",E4:E400,"=PTO A FO") -> 2 | AF2: =COUNTIFS(AF4:AF400, "=APAGADO",E4:E400,"=PTO A FO") -> 4 | AG2: =COUNTIFS(AG4:AG400, "=APAGADO",E4:E400,"=PTO A FO") -> 3 | AH2: =COUNTIFS(AH4:AH400, "=APAGADO",E4:E400,"=PTO A FO") -> 2 | AI2: =COUNTIFS(AI4:AI400, "=APAGADO",E4:E400,"=PTO A FO") -> 0
A3: =ESTADISTICA!A1 -> Barrio | B3: =ESTADISTICA!B1 -> [Denominacion] | C3: =ESTADISTICA!C1 -> [Ubicacion] | D3: =ESTADISTICA!D1 -> [Tipo de Camara] | E3: =ESTADISTICA!E1 -> [Tipo de Conexion] | F3: =ESTADISTICA!F1 -> 44774 | G3: =ESTADISTICA!G1 -> 44775 | H3: =ESTADISTICA!H1 -> 44776 | ... AI3: =ESTADISTICA!AI1 -> 44803
A4: =ESTADISTICA!A2 -> ALTAMIRA | B4: =ESTADISTICA!B2 -> ALT 03 | C4: =ESTADISTICA!C2 -> Bombero Galarza y Necochea | D4: =ESTADISTICA!D2 -> Domo | E4: =ESTADISTICA!E2 -> FIBRA OPTICA | F4: =ESTADISTICA!F2 -> 0 | G4: =ESTADISTICA!G2 -> 0 | H4: =ESTADISTICA!H2 -> 0 | ... AI4: =ESTADISTICA!AI2 -> 0
A5: =ESTADISTICA!A3 -> ALTAMIRA | B5: =ESTADISTICA!B3 -> ALT 04 | C5: =ESTADISTICA!C3 -> Francia y Necochea | D5: =ESTADISTICA!D3 -> Domo | E5: =ESTADISTICA!E3 -> FIBRA OPTICA | F5: =ESTADISTICA!F3 -> 0 | G5: =ESTADISTICA!G3 -> 0 | H5: =ESTADISTICA!H3 -> 0 | ... AI5: =ESTADISTICA!AI3 -> 0
A6: =ESTADISTICA!A4 -> ALTAMIRA | B6: =ESTADISTICA!B4 -> ALT 06 | C6: =ESTADISTICA!C4 -> LOPE DE VEGA Y NECOCHEA | D6: =ESTADISTICA!D4 -> Domo | E6: =ESTADISTICA!E4 -> PTO A FO | F6: =ESTADISTICA!F4 -> 0 | G6: =ESTADISTICA!G4 -> 0 | H6: =ESTADISTICA!H4 -> 0 | ... AI6: =ESTADISTICA!AI4 -> 0
A7: =ESTADISTICA!A5 -> ALTAMIRA | B7: =ESTADISTICA!B5 -> ALT 08 | C7: =ESTADISTICA!C5 -> HUMAITA Y NECOCHEA | D7: =ESTADISTICA!D5 -> DOMO | E7: =ESTADISTICA!E5 -> Fibra Optica | F7: =ESTADISTICA!F5 -> 0 | G7: =ESTADISTICA!G5 -> 0 | H7: =ESTADISTICA!H5 -> 0 | ... AI7: =ESTADISTICA!AI5 -> 0
A8: =ESTADISTICA!A6 -> ALTAMIRA | B8: =ESTADISTICA!B6 -> ALT 09 | C8: =ESTADISTICA!C6 -> NECOCHEA Y CURUPAITY | D8: =ESTADISTICA!D6 -> DOMO | E8: =ESTADISTICA!E6 -> Fibra Optica | F8: =ESTADISTICA!F6 -> 0 | G8: =ESTADISTICA!G6 -> 0 | H8: =ESTADISTICA!H6 -> 0 | ... AI8: =ESTADISTICA!AI6 -> 0
A9: =ESTADISTICA!A7 -> ALTAMIRA | B9: =ESTADISTICA!B7 -> ALT 10 | C9: =ESTADISTICA!C7 -> Calchaqui y Francia | D9: =ESTADISTICA!D7 -> Domo | E9: =ESTADISTICA!E7 -> Radio | F9: =ESTADISTICA!F7 -> 0 | G9: =ESTADISTICA!G7 -> 0 | H9: =ESTADISTICA!H7 -> 0 | ... AI9: =ESTADISTICA!AI7 -> 0
A10: =ESTADISTICA!A8 -> ALTAMIRA | B10: =ESTADISTICA!B8 -> ALT01 | C10: =ESTADISTICA!C8 -> Calchaqui y Sgto. Cabral | D10: =ESTADISTICA!D8 -> Domo | E10: =ESTADISTICA!E8 -> Fibra Optica | F10: =ESTADISTICA!F8 -> 0 | G10: =ESTADISTICA!G8 -> 0 | H10: =ESTADISTICA!H8 -> 0 | ... AI10: =ESTADISTICA!AI8 -> 0
A11: =ESTADISTICA!A9 -> ALTAMIRA | B11: =ESTADISTICA!B9 -> ALT02 | C11: =ESTADISTICA!C9 -> Calchaqui y Lope de Vega | D11: =ESTADISTICA!D9 -> Domo | E11: =ESTADISTICA!E9 -> PTO A FO | F11: =ESTADISTICA!F9 -> 0 | G11: =ESTADISTICA!G9 -> 0 | H11: =ESTADISTICA!H9 -> 0 | ... AI11: =ESTADISTICA!AI9 -> 0
A12: =ESTADISTICA!A10 -> ALTAMIRA | B12: =ESTADISTICA!B10 -> ALT05 | C12: =ESTADISTICA!C10 -> Av. Calchaqui y Bombero Galarza | D12: =ESTADISTICA!D10 -> Domo | E12: =ESTADISTICA!E10 -> PTO A FO | F12: =ESTADISTICA!F10 -> 0 | G12: =ESTADISTICA!G10 -> 0 | H12: =ESTADISTICA!H10 -> 0 | ... AI12: =ESTADISTICA!AI10 -> 0
A13: =ESTADISTICA!A11 -> ALTAMIRA | B13: =ESTADISTICA!B11 -> ALT07 | C13: =ESTADISTICA!C11 -> AV. CALCHAQUI Y AV. DEL TRABAJO | D13: =ESTADISTICA!D11 -> DOMO | E13: =ESTADISTICA!E11 -> PTO A FO | F13: =ESTADISTICA!F11 -> 0 | G13: =ESTADISTICA!G11 -> 0 | H13: =ESTADISTICA!H11 -> 0 | ... AI13: =ESTADISTICA!AI11 -> 0
A14: =ESTADISTICA!A12 -> AGUSTIN RAMIREZ | B14: =ESTADISTICA!B12 -> ARA 01 | C14: =ESTADISTICA!C12 -> Malambo y Tranquera | D14: =ESTADISTICA!D12 -> Domo | E14: =ESTADISTICA!E12 -> FIBRA OPTICA | F14: =ESTADISTICA!F12 -> 0 | G14: =ESTADISTICA!G12 -> APAGADO | H14: =ESTADISTICA!H12 -> 0 | ... AI14: =ESTADISTICA!AI12 -> 0
... A278: =ESTADISTICA!A276 -> SAN JORGE | B278: =ESTADISTICA!B276 -> SJO07 (fija 1) | C278: =ESTADISTICA!C276 -> 503 Y 556 | D278: =ESTADISTICA!D276 -> Fija | E278: =ESTADISTICA!E276 -> Fibra Optica | F278: =ESTADISTICA!F276 -> 0 | G278: =ESTADISTICA!G276 -> 0 | H278: =ESTADISTICA!H276 -> 0 | ... AI278: =ESTADISTICA!AI276 -> 0
B279: =ESTADISTICA!B277 -> SJO08 (fija 2) | C279: =ESTADISTICA!C277 -> 503 Y 556 | D279: =ESTADISTICA!D277 -> Fija | E279: =ESTADISTICA!E277 -> Fibra Optica | F279: =ESTADISTICA!F277 -> 0 | G279: =ESTADISTICA!G277 -> 0 | H279: =ESTADISTICA!H277 -> 0 | I279: =ESTADISTICA!I277 -> 0 | ... AI279: =ESTADISTICA!AI277 -> 0
A280: =ESTADISTICA!A278 -> SANTO TOMAS | B280: =ESTADISTICA!B278 -> SJU01 | C280: =ESTADISTICA!C278 -> Ruta 36 y Pte.Peron | D280: =ESTADISTICA!D278 -> Domo | E280: =ESTADISTICA!E278 -> Radio | F280: =ESTADISTICA!F278 -> 0 | G280: =ESTADISTICA!G278 -> 0 | H280: =ESTADISTICA!H278 -> 0 | ... AI280: =ESTADISTICA!AI278 -> 0
A281: =ESTADISTICA!A279 -> VILLA GENERAL SAN MARTIN | B281: =ESTADISTICA!B279 -> SMA 03 | C281: =ESTADISTICA!C279 -> ROSARIO Y SAN NICOLAS | D281: =ESTADISTICA!D279 -> Domo | E281: =ESTADISTICA!E279 -> Radio | F281: =ESTADISTICA!F279 -> 0 | G281: =ESTADISTICA!G279 -> 0 | H281: =ESTADISTICA!H279 -> 0 | ... AI281: =ESTADISTICA!AI279 -> 0
A282: =ESTADISTICA!A280 -> VILLA GENERAL SAN MARTIN | B282: =ESTADISTICA!B280 -> SMA 04 | C282: =ESTADISTICA!C280 -> HUDSON Y MONTEVIDEO | D282: =ESTADISTICA!D280 -> FIJA | E282: =ESTADISTICA!E280 -> Radio | F282: =ESTADISTICA!F280 -> 0 | G282: =ESTADISTICA!G280 -> 0 | H282: =ESTADISTICA!H280 -> 0 | ... AI282: =ESTADISTICA!AI280 -> 0
A283: =ESTADISTICA!A281 -> VILLA GENERAL SAN MARTIN | B283: =ESTADISTICA!B281 -> SMA 06 | C283: =ESTADISTICA!C281 -> AV. HUDSON Y RIO IGUAZU | D283: =ESTADISTICA!D281 -> DOMO | E283: =ESTADISTICA!E281 -> Fibra Optica | F283: =ESTADISTICA!F281 -> 0 | G283: =ESTADISTICA!G281 -> 0 | H283: =ESTADISTICA!H281 -> 0 | ... AI283: =ESTADISTICA!AI281 -> 0
A284: =ESTADISTICA!A282 -> VILLA GENERAL SAN MARTIN | B284: =ESTADISTICA!B282 -> SMA 07 | C284: =ESTADISTICA!C282 -> AV. HUDSON Y RIO TURBIO | D284: =ESTADISTICA!D282 -> DOMO | E284: =ESTADISTICA!E282 -> Fibra Optica | F284: =ESTADISTICA!F282 -> 0 | G284: =ESTADISTICA!G282 -> 0 | H284: =ESTADISTICA!H282 -> 0 | ... AI284: =ESTADISTICA!AI282 -> 0
A285: =ESTADISTICA!A283 -> VILLA GENERAL SAN MARTIN | B285: =ESTADISTICA!B283 -> SMA01 | C285: =ESTADISTICA!C283 -> Hudson y Montevideo | D285: =ESTADISTICA!D283 -> DOMO | E285: =ESTADISTICA!E283 -> Radio | F285: =ESTADISTICA!F283 -> 0 | G285: =ESTADISTICA!G283 -> 0 | H285: =ESTADISTICA!H283 -> 0 | ... AI285: =ESTADISTICA!AI283 -> 0
A286: =ESTADISTICA!A284 -> VILLA GENERAL SAN MARTIN | B286: =ESTADISTICA!B284 -> SMA02 | C286: =ESTADISTICA!C284 -> Hudson y San Nicolas | D286: =ESTADISTICA!D284 -> Domo | E286: =ESTADISTICA!E284 -> Radio | F286: =ESTADISTICA!F284 -> 0 | G286: =ESTADISTICA!G284 -> 0 | H286: =ESTADISTICA!H284 -> 0 | ... AI286: =ESTADISTICA!AI284 -> 0
A287: =ESTADISTICA!A285 -> VILLA GENERAL SAN MARTIN | B287: =ESTADISTICA!B285 -> SMA05 | C287: =ESTADISTICA!C285 -> MONTEVIDEO Y VILLEGAS | D287: =ESTADISTICA!D285 -> DOMO | E287: =ESTADISTICA!E285 -> PTO A FO | F287: =ESTADISTICA!F285 -> 0 | G287: =ESTADISTICA!G285 -> 0 | H287: =ESTADISTICA!H285 -> 0 | ... AI287: =ESTADISTICA!AI285 -> 0
A288: =ESTADISTICA!A286 -> SAN NICOLAS | B288: =ESTADISTICA!B286 -> SNI 03 (fija 1) | C288: =ESTADISTICA!C286 -> SARRATEA Y LOS TREBOLES | D288: =ESTADISTICA!D286 -> Fija | E288: =ESTADISTICA!E286 -> Fibra Optica | F288: =ESTADISTICA!F286 -> APAGADO | G288: =ESTADISTICA!G286 -> APAGADO | H288: =ESTADISTICA!H286 -> 0 | ... AI288: =ESTADISTICA!AI286 -> 0
A289: =ESTADISTICA!A287 -> SAN NICOLAS | B289: =ESTADISTICA!B287 -> SNI 04 (fija 2) | C289: =ESTADISTICA!C287 -> SARRATEA Y LOS TREBOLES | D289: =ESTADISTICA!D287 -> Fija | E289: =ESTADISTICA!E287 -> Fibra Optica | F289: =ESTADISTICA!F287 -> APAGADO | G289: =ESTADISTICA!G287 -> APAGADO | H289: =ESTADISTICA!H287 -> 0 | ... AI289: =ESTADISTICA!AI287 -> 0
A290: =ESTADISTICA!A288 -> SAN NICOLAS | B290: =ESTADISTICA!B288 -> SNI01 (fija 1) | C290: =ESTADISTICA!C288 -> SARRATEA E/ EEUU DE A. Y AGRELO | D290: =ESTADISTICA!D288 -> Fija | E290: =ESTADISTICA!E288 -> Fibra Optica | F290: =ESTADISTICA!F288 -> APAGADO | G290: =ESTADISTICA!G288 -> APAGADO | H290: =ESTADISTICA!H288 -> 0 | ... AI290: =ESTADISTICA!AI288 -> 0
A291: =ESTADISTICA!A289 -> SAN NICOLAS | B291: =ESTADISTICA!B289 -> SNI02 (fija 2) | C291: =ESTADISTICA!C289 -> SARRATEA E/ EEUU DE A. Y AGRELO | D291: =ESTADISTICA!D289 -> Fija | E291: =ESTADISTICA!E289 -> Fibra Optica | F291: =ESTADISTICA!F289 -> APAGADO | G291: =ESTADISTICA!G289 -> APAGADO | H291: =ESTADISTICA!H289 -> 0 | ... AI291: =ESTADISTICA!AI289 -> 0
... A454: =ESTADISTICA!A452 -> 0 | B454: =ESTADISTICA!B452 -> 0 | C454: =ESTADISTICA!C452 -> 0 | D454: =ESTADISTICA!D452 -> 0 | E454: =ESTADISTICA!E452 -> 0 | F454: =ESTADISTICA!F452 -> 0 | G454: =ESTADISTICA!G452 -> 0 | H454: =ESTADISTICA!H452 -> 0 | ... AI454: =ESTADISTICA!AI452 -> 0

Sheet APAGADOS RADIO
C1: TOTAL RADIO | D1: =COUNTIFS(E4:E400,"=radio") -> 94
E2: APAGADOS | F2: =COUNTIFS(F4:F500, "=APAGADO",E4:E500,"=radio") -> 4 | G2: =COUNTIFS(G4:G500, "=APAGADO",E4:E500,"=radio") -> 4 | H2: =COUNTIFS(H4:H500, "=APAGADO",E4:E500,"=radio") -> 3 | I2: =COUNTIFS(I4:I500, "=APAGADO",E4:E500,"=radio") -> 3 | J2: =COUNTIFS(J4:J500, "=APAGADO",E4:E500,"=radio") -> 3 | K2: =COUNTIFS(K4:K500, "=APAGADO",E4:E500,"=radio") -> 5 | L2: =COUNTIFS(L4:L500, "=APAGADO",E4:E500,"=radio") -> 5 | M2: =COUNTIFS(M4:M500, "=APAGADO",E4:E500,"=radio") -> 5 | N2: =COUNTIFS(N4:N500, "=APAGADO",E4:E500,"=radio") -> 4 | O2: =COUNTIFS(O4:O500, "=APAGADO",E4:E500,"=radio") -> 6 | P2: =COUNTIFS(P4:P500, "=APAGADO",E4:E500,"=radio") -> 4 | Q2: =COUNTIFS(Q4:Q367, "=APAGADO",E4:E367,"=radio") -> 4 | R2: =COUNTIFS(R4:R367, "=APAGADO",E4:E367,"=radio") -> 3 | S2: =COUNTIFS(S4:S367, "=APAGADO",E4:E367,"=radio") -> 4 | T2: =COUNTIFS(T4:T367, "=APAGADO",E4:E367,"=radio") -> 4 | U2: =COUNTIFS(U4:U367, "=APAGADO",E4:E367,"=radio") -> 3 | V2: =COUNTIFS(V4:V367, "=APAGADO",E4:E367,"=radio") -> 3 | W2: =COUNTIFS(W4:W367, "=APAGADO",E4:E367,"=radio") -> 3 | X2: =COUNTIFS(X4:X367, "=APAGADO",E4:E367,"=radio") -> 3 | Y2: =COUNTIFS(Y4:Y367, "=APAGADO",E4:E367,"=radio") -> 4 | Z2: =COUNTIFS(Z4:Z367, "=APAGADO",E4:E367,"=radio") -> 4 | AA2: =COUNTIFS(AA4:AA367, "=APAGADO",E4:E367,"=radio") -> 4 | AB2: =COUNTIFS(AB4:AB367, "=APAGADO",E4:E367,"=radio") -> 4 | AC2: =COUNTIFS(AC4:AC367, "=APAGADO",E4:E367,"=radio") -> 4 | AD2: =COUNTIFS(AD4:AD367, "=APAGADO",E4:E367,"=radio") -> 4 | AE2: =COUNTIFS(AE4:AE367, "=APAGADO",E4:E367,"=radio") -> 6 | AF2: =COUNTIFS(AF4:AF367, "=APAGADO",E4:E367,"=radio") -> 4 | AG2: =COUNTIFS(AG4:AG367, "=APAGADO",E4:E367,"=radio") -> 4 | AH2: =COUNTIFS(AH4:AH400, "=APAGADO",E4:E400,"=radio") -> 5 | AI2: =COUNTIFS(AI4:AI367, "=APAGADO",E4:E367,"=radio") -> 0
A3: =ESTADISTICA!A1 -> Barrio | B3: =ESTADISTICA!B1 -> [Denominacion] | C3: =ESTADISTICA!C1 -> [Ubicacion] | D3: =ESTADISTICA!D1 -> [Tipo de Camara] | E3: =ESTADISTICA!E1 -> [Tipo de Conexion] | F3: =ESTADISTICA!F1 -> 44774 | G3: =ESTADISTICA!G1 -> 44775 | H3: =ESTADISTICA!H1 -> 44776 | ... AI3: =ESTADISTICA!AI1 -> 44803
A4: =ESTADISTICA!A2 -> ALTAMIRA | B4: =ESTADISTICA!B2 -> ALT 03 | C4: =ESTADISTICA!C2 -> Bombero Galarza y Necochea | D4: =ESTADISTICA!D2 -> Domo | E4: =ESTADISTICA!E2 -> FIBRA OPTICA | F4: =ESTADISTICA!F2 -> 0 | G4: =ESTADISTICA!G2 -> 0 | H4: =ESTADISTICA!H2 -> 0 | ... AI4: =ESTADISTICA!AI2 -> 0
A5: =ESTADISTICA!A3 -> ALTAMIRA | B5: =ESTADISTICA!B3 -> ALT 04 | C5: =ESTADISTICA!C3 -> Francia y Necochea | D5: =ESTADISTICA!D3 -> Domo | E5: =ESTADISTICA!E3 -> FIBRA OPTICA | F5: =ESTADISTICA!F3 -> 0 | G5: =ESTADISTICA!G3 -> 0 | H5: =ESTADISTICA!H3 -> 0 | ... AI5: =ESTADISTICA!AI3 -> 0
A6: =ESTADISTICA!A4 -> ALTAMIRA | B6: =ESTADISTICA!B4 -> ALT 06 | C6: =ESTADISTICA!C4 -> LOPE DE VEGA Y NECOCHEA | D6: =ESTADISTICA!D4 -> Domo | E6: =ESTADISTICA!E4 -> PTO A FO | F6: =ESTADISTICA!F4 -> 0 | G6: =ESTADISTICA!G4 -> 0 | H6: =ESTADISTICA!H4 -> 0 | ... AI6: =ESTADISTICA!AI4 -> 0
A7: =ESTADISTICA!A5 -> ALTAMIRA | B7: =ESTADISTICA!B5 -> ALT 08 | C7: =ESTADISTICA!C5 -> HUMAITA Y NECOCHEA | D7: =ESTADISTICA!D5 -> DOMO | E7: =ESTADISTICA!E5 -> Fibra Optica | F7: =ESTADISTICA!F5 -> 0 | G7: =ESTADISTICA!G5 -> 0 | H7: =ESTADISTICA!H5 -> 0 | ... AI7: =ESTADISTICA!AI5 -> 0
A8: =ESTADISTICA!A6 -> ALTAMIRA | B8: =ESTADISTICA!B6 -> ALT 09 | C8: =ESTADISTICA!C6 -> NECOCHEA Y CURUPAITY | D8: =ESTADISTICA!D6 -> DOMO | E8: =ESTADISTICA!E6 -> Fibra Optica | F8: =ESTADISTICA!F6 -> 0 | G8: =ESTADISTICA!G6 -> 0 | H8: =ESTADISTICA!H6 -> 0 | ... AI8: =ESTADISTICA!AI6 -> 0
A9: =ESTADISTICA!A7 -> ALTAMIRA | B9: =ESTADISTICA!B7 -> ALT 10 | C9: =ESTADISTICA!C7 -> Calchaqui y Francia | D9: =ESTADISTICA!D7 -> Domo | E9: =ESTADISTICA!E7 -> Radio | F9: =ESTADISTICA!F7 -> 0 | G9: =ESTADISTICA!G7 -> 0 | H9: =ESTADISTICA!H7 -> 0 | ... AI9: =ESTADISTICA!AI7 -> 0
A10: =ESTADISTICA!A8 -> ALTAMIRA | B10: =ESTADISTICA!B8 -> ALT01 | C10: =ESTADISTICA!C8 -> Calchaqui y Sgto. Cabral | D10: =ESTADISTICA!D8 -> Domo | E10: =ESTADISTICA!E8 -> Fibra Optica | F10: =ESTADISTICA!F8 -> 0 | G10: =ESTADISTICA!G8 -> 0 | H10: =ESTADISTICA!H8 -> 0 | ... AI10: =ESTADISTICA!AI8 -> 0
A11: =ESTADISTICA!A9 -> ALTAMIRA | B11: =ESTADISTICA!B9 -> ALT02 | C11: =ESTADISTICA!C9 -> Calchaqui y Lope de Vega | D11: =ESTADISTICA!D9 -> Domo | E11: =ESTADISTICA!E9 -> PTO A FO | F11: =ESTADISTICA!F9 -> 0 | G11: =ESTADISTICA!G9 -> 0 | H11: =ESTADISTICA!H9 -> 0 | ... AI11: =ESTADISTICA!AI9 -> 0
A12: =ESTADISTICA!A10 -> ALTAMIRA | B12: =ESTADISTICA!B10 -> ALT05 | C12: =ESTADISTICA!C10 -> Av. Calchaqui y Bombero Galarza | D12: =ESTADISTICA!D10 -> Domo | E12: =ESTADISTICA!E10 -> PTO A FO | F12: =ESTADISTICA!F10 -> 0 | G12: =ESTADISTICA!G10 -> 0 | H12: =ESTADISTICA!H10 -> 0 | ... AI12: =ESTADISTICA!AI10 -> 0
A13: =ESTADISTICA!A11 -> ALTAMIRA | B13: =ESTADISTICA!B11 -> ALT07 | C13: =ESTADISTICA!C11 -> AV. CALCHAQUI Y AV. DEL TRABAJO | D13: =ESTADISTICA!D11 -> DOMO | E13: =ESTADISTICA!E11 -> PTO A FO | F13: =ESTADISTICA!F11 -> 0 | G13: =ESTADISTICA!G11 -> 0 | H13: =ESTADISTICA!H11 -> 0 | ... AI13: =ESTADISTICA!AI11 -> 0
A14: =ESTADISTICA!A12 -> AGUSTIN RAMIREZ | B14: =ESTADISTICA!B12 -> ARA 01 | C14: =ESTADISTICA!C12 -> Malambo y Tranquera | D14: =ESTADISTICA!D12 -> Domo | E14: =ESTADISTICA!E12 -> FIBRA OPTICA | F14: =ESTADISTICA!F12 -> 0 | G14: =ESTADISTICA!G12 -> APAGADO | H14: =ESTADISTICA!H12 -> 0 | ... AI14: =ESTADISTICA!AI12 -> 0
... A278: =ESTADISTICA!A276 -> SAN JORGE | B278: =ESTADISTICA!B276 -> SJO07 (fija 1) | C278: =ESTADISTICA!C276 -> 503 Y 556 | D278: =ESTADISTICA!D276 -> Fija | E278: =ESTADISTICA!E276 -> Fibra Optica | F278: =ESTADISTICA!F276 -> 0 | G278: =ESTADISTICA!G276 -> 0 | H278: =ESTADISTICA!H276 -> 0 | ... AI278: =ESTADISTICA!AI276 -> 0
B279: =ESTADISTICA!B277 -> SJO08 (fija 2) | C279: =ESTADISTICA!C277 -> 503 Y 556 | D279: =ESTADISTICA!D277 -> Fija | E279: =ESTADISTICA!E277 -> Fibra Optica | F279: =ESTADISTICA!F277 -> 0 | G279: =ESTADISTICA!G277 -> 0 | H279: =ESTADISTICA!H277 -> 0 | I279: =ESTADISTICA!I277 -> 0 | ... AI279: =ESTADISTICA!AI277 -> 0
A280: =ESTADISTICA!A278 -> SANTO TOMAS | B280: =ESTADISTICA!B278 -> SJU01 | C280: =ESTADISTICA!C278 -> Ruta 36 y Pte.Peron | D280: =ESTADISTICA!D278 -> Domo | E280: =ESTADISTICA!E278 -> Radio | F280: =ESTADISTICA!F278 -> 0 | G280: =ESTADISTICA!G278 -> 0 | H280: =ESTADISTICA!H278 -> 0 | ... AI280: =ESTADISTICA!AI278 -> 0
A281: =ESTADISTICA!A279 -> VILLA GENERAL SAN MARTIN | B281: =ESTADISTICA!B279 -> SMA 03 | C281: =ESTADISTICA!C279 -> ROSARIO Y SAN NICOLAS | D281: =ESTADISTICA!D279 -> Domo | E281: =ESTADISTICA!E279 -> Radio | F281: =ESTADISTICA!F279 -> 0 | G281: =ESTADISTICA!G279 -> 0 | H281: =ESTADISTICA!H279 -> 0 | ... AI281: =ESTADISTICA!AI279 -> 0
A282: =ESTADISTICA!A280 -> VILLA GENERAL SAN MARTIN | B282: =ESTADISTICA!B280 -> SMA 04 | C282: =ESTADISTICA!C280 -> HUDSON Y MONTEVIDEO | D282: =ESTADISTICA!D280 -> FIJA | E282: =ESTADISTICA!E280 -> Radio | F282: =ESTADISTICA!F280 -> 0 | G282: =ESTADISTICA!G280 -> 0 | H282: =ESTADISTICA!H280 -> 0 | ... AI282: =ESTADISTICA!AI280 -> 0
A283: =ESTADISTICA!A281 -> VILLA GENERAL SAN MARTIN | B283: =ESTADISTICA!B281 -> SMA 06 | C283: =ESTADISTICA!C281 -> AV. HUDSON Y RIO IGUAZU | D283: =ESTADISTICA!D281 -> DOMO | E283: =ESTADISTICA!E281 -> Fibra Optica | F283: =ESTADISTICA!F281 -> 0 | G283: =ESTADISTICA!G281 -> 0 | H283: =ESTADISTICA!H281 -> 0 | ... AI283: =ESTADISTICA!AI281 -> 0
A284: =ESTADISTICA!A282 -> VILLA GENERAL SAN MARTIN | B284: =ESTADISTICA!B282 -> SMA 07 | C284: =ESTADISTICA!C282 -> AV. HUDSON Y RIO TURBIO | D284: =ESTADISTICA!D282 -> DOMO | E284: =ESTADISTICA!E282 -> Fibra Optica | F284: =ESTADISTICA!F282 -> 0 | G284: =ESTADISTICA!G282 -> 0 | H284: =ESTADISTICA!H282 -> 0 | ... AI284: =ESTADISTICA!AI282 -> 0
A285: =ESTADISTICA!A283 -> VILLA GENERAL SAN MARTIN | B285: =ESTADISTICA!B283 -> SMA01 | C285: =ESTADISTICA!C283 -> Hudson y Montevideo | D285: =ESTADISTICA!D283 -> DOMO | E285: =ESTADISTICA!E283 -> Radio | F285: =ESTADISTICA!F283 -> 0 | G285: =ESTADISTICA!G283 -> 0 | H285: =ESTADISTICA!H283 -> 0 | ... AI285: =ESTADISTICA!AI283 -> 0
A286: =ESTADISTICA!A284 -> VILLA GENERAL SAN MARTIN | B286: =ESTADISTICA!B284 -> SMA02 | C286: =ESTADISTICA!C284 -> Hudson y San Nicolas | D286: =ESTADISTICA!D284 -> Domo | E286: =ESTADISTICA!E284 -> Radio | F286: =ESTADISTICA!F284 -> 0 | G286: =ESTADISTICA!G284 -> 0 | H286: =ESTADISTICA!H284 -> 0 | ... AI286: =ESTADISTICA!AI284 -> 0
A287: =ESTADISTICA!A285 -> VILLA GENERAL SAN MARTIN | B287: =ESTADISTICA!B285 -> SMA05 | C287: =ESTADISTICA!C285 -> MONTEVIDEO Y VILLEGAS | D287: =ESTADISTICA!D285 -> DOMO | E287: =ESTADISTICA!E285 -> PTO A FO | F287: =ESTADISTICA!F285 -> 0 | G287: =ESTADISTICA!G285 -> 0 | H287: =ESTADISTICA!H285 -> 0 | ... AI287: =ESTADISTICA!AI285 -> 0
A288: =ESTADISTICA!A286 -> SAN NICOLAS | B288: =ESTADISTICA!B286 -> SNI 03 (fija 1) | C288: =ESTADISTICA!C286 -> SARRATEA Y LOS TREBOLES | D288: =ESTADISTICA!D286 -> Fija | E288: =ESTADISTICA!E286 -> Fibra Optica | F288: =ESTADISTICA!F286 -> APAGADO | G288: =ESTADISTICA!G286 -> APAGADO | H288: =ESTADISTICA!H286 -> 0 | ... AI288: =ESTADISTICA!AI286 -> 0
A289: =ESTADISTICA!A287 -> SAN NICOLAS | B289: =ESTADISTICA!B287 -> SNI 04 (fija 2) | C289: =ESTADISTICA!C287 -> SARRATEA Y LOS TREBOLES | D289: =ESTADISTICA!D287 -> Fija | E289: =ESTADISTICA!E287 -> Fibra Optica | F289: =ESTADISTICA!F287 -> APAGADO | G289: =ESTADISTICA!G287 -> APAGADO | H289: =ESTADISTICA!H287 -> 0 | ... AI289: =ESTADISTICA!AI287 -> 0
A290: =ESTADISTICA!A288 -> SAN NICOLAS | B290: =ESTADISTICA!B288 -> SNI01 (fija 1) | C290: =ESTADISTICA!C288 -> SARRATEA E/ EEUU DE A. Y AGRELO | D290: =ESTADISTICA!D288 -> Fija | E290: =ESTADISTICA!E288 -> Fibra Optica | F290: =ESTADISTICA!F288 -> APAGADO | G290: =ESTADISTICA!G288 -> APAGADO | H290: =ESTADISTICA!H288 -> 0 | ... AI290: =ESTADISTICA!AI288 -> 0
A291: =ESTADISTICA!A289 -> SAN NICOLAS | B291: =ESTADISTICA!B289 -> SNI02 (fija 2) | C291: =ESTADISTICA!C289 -> SARRATEA E/ EEUU DE A. Y AGRELO | D291: =ESTADISTICA!D289 -> Fija | E291: =ESTADISTICA!E289 -> Fibra Optica | F291: =ESTADISTICA!F289 -> APAGADO | G291: =ESTADISTICA!G289 -> APAGADO | H291: =ESTADISTICA!H289 -> 0 | ... AI291: =ESTADISTICA!AI289 -> 0
... A400: =ESTADISTICA!A398 -> 0 | B400: =ESTADISTICA!B398 -> 0 | C400: =ESTADISTICA!C398 -> 0 | D400: =ESTADISTICA!D398 -> 0 | E400: =ESTADISTICA!E398 -> 0 | F400: =ESTADISTICA!F398 -> 0 | G400: =ESTADISTICA!G398 -> 0 | H400: =ESTADISTICA!H398 -> 0 | ... AI400: =ESTADISTICA!AI398 -> 0

Sheet BARRAS

Sheet GRAFICO2

Sheet informe
B1: CANTIDAD | D1: %
A2: TOTAL | B2: 392 | E2: 44782
A3: CAIDAS | B3: 51 | C3: 51 | D3: =C3/B2 -> 0.13010204 | G3: MAY 03 | H3: CHAÑAR Y SAN NICOLAS | I3: DOMO | J3: PTP A FO | K3: 172.20.10.18 | L3: Se llega por ping y por web | M3: 44753
A4: LLEGAMOS NOSOTROS | B4: 2 | C4: =B3-B4 -> 49 | D4: =C4/B2 -> 0.125 | G4: NJU03 | H4: San Juan y Parrillo | I4: Domo | J4: PTP A FO | K4: 172.20.10.45 | L4: Se llega por ping y por web
A5: NO ESTA LA CAMARA | B5: 2 | C5: =C4-B5 -> 47 | D5: =C5/B2 -> 0.11989796 | G5: VAT 12 | H5: 12 DE OCTUBRE Y CHACO | I5: DOMO | J5: PTP A FO | K5: 172.20.12.127 | L5: se llega por ping y por web (No Video Display)
A6: RADIO | B6: 4 | C6: =C5-B6 -> 43 | D6: =C6/B2 -> 0.10969388 | G6: Punto Seguro - San Jorge (Domo) | H6: CALLE 523 E/ 554 Y 556 | I6: DOMO | J6: PTP A FO | K6: 172.20.12.101 | L6: Se llega por ping y por web (DAHUA)
A7: TOTAL | B7: 392 | E7: 44783 | G7: PUNTO SEGURO - SANTA ROSA (domo) | H7: BRUSELAS Y SICILIA | I7: DOMO | J7: Fibra Optica | K7: 172.20.12.145 | L7: Se llega por ping y por web (DAHUA)
A8: CAIDAS | B8: 64 | C8: 64 | D8: =C8/B7 -> 0.16326531 | G8: PUNTO SEGURO - SANTA ROSA (fija) | H8: BRUSELAS Y SICILIA | I8: Fija | J8: Fibra Optica | K8: 172.20.12.146 | L8: Se llega por ping y por web (DAHUA)
A9: LLEGAMOS NOSOTROS | B9: 2 | C9: =B8-B9 -> 62 | D9: =C9/B7 -> 0.15816327
A10: NO ESTA LA CAMARA | B10: 2 | C10: =C9-B10 -> 60 | D10: =C10/B7 -> 0.15306122 | G10: ALT06 | H10: LOPE DE VEGA Y NECOCHEA | I10: Domo | J10: PTP A FO | K10: 172.20.12.12 | L10: Se llega por ping y por web | M10: 44755
A11: RADIO | B11: 6 | C11: =C10-B11 -> 54 | D11: =C11/B7 -> 0.1377551 | G11: ESM04 | H11: Basualdo y Bengochea | I11: Domo | J11: Fibra Optica | K11: 172.20.12.46 | L11: Se llega por ping y por web
A12: TOTAL | B12: 392 | E12: 44784 | G12: LRO 01 | H12: H. IRIGOYEN Y BRAILE | I12: FIJA | J12: Fibra Optica | K12: 172.20.10.36 | L12: Se llega por ping y por web
A13: CAIDAS | B13: 38 | C13: 38 | D13: =C13/B12 -> 0.096938776 | G13: VAU01 | H13: San Martin y Monteverde | I13: Domo | J13: Fibra Optica | K13: 172.20.10.07 | L13: Se llega por ping y por web pide login
A14: LLEGAMOS NOSOTROS | B14: 2 | C14: =B13-B14 -> 36 | D14: =C14/B12 -> 0.091836735 | G14: Punto Seguro - San Jorge (Domo) | H14: CALLE 523 E/ 554 Y 556 | I14: DOMO | J14: PTP A FO | K14: 172.20.12.101 | L14: Se llega por ping y por web (DAHUA)
A15: NO ESTA LA CAMARA | B15: 2 | C15: =C14-B15 -> 34 | D15: =C15/B12 -> 0.086734694 | G15: PUNTO SEGURO - SANTA ROSA (fija) | H15: BRUSELAS Y SICILIA | I15: Fija | J15: Fibra Optica | K15: 172.20.12.146 | L15: Se llega por ping y por web (DAHUA)
A16: RADIO | B16: 4 | C16: =C15-B16 -> 30 | D16: =C16/B12 -> 0.076530612 | G16: ALT06 | H16: LOPE DE VEGA Y NECOCHEA | I16: Domo | J16: PTP A FO | K16: 172.20.12.12 | L16: Se llega por pimg y por web | M16: 44763
A17: TOTAL | B17: 392 | E17: 44790 | G17: ESM04 | H17: Basualdo y Bengochea | I17: Domo | J17: Fibra Optica | K17: 172.20.12.46 | L17: Se llega por ping y por web
A18: CAIDAS | B18: 30 | C18: 30 | D18: =C18/B17 -> 0.076530612 | G18: VLA04 | H18: ESPORA Y MARTIN GRASS | I18: DOMO | J18: Fibra Optica | K18: 172.20.11.163 | L18: Se llega por ping y por web (login)
A19: LLEGAMOS NOSOTROS | B19: 3 | C19: =B18-B19 -> 27 | D19: =C19/B17 -> 0.068877551 | G19: PUNTO SEGURO - SANTA ROSA (fija) | H19: BRUSELAS Y SICILIA | I19: Fija | J19: Fibra Optica | K19: 172.20.12.146 | L19: Se llega por ping y por web (DAHUA)
A20: NO ESTA LA CAMARA | B20: 2 | C20: =C19-B20 -> 25 | D20: =C20/B17 -> 0.06377551
A21: RADIO | B21: 2 | C21: =C20-B21 -> 23 | D21: =C21/B17 -> 0.058673469
A22: TOTAL | B22: 392 | E22: 44791
A23: CAIDAS | B23: 35 | C23: 35 | D23: =C23/B22 -> 0.089285714
A24: LLEGAMOS NOSOTROS | B24: 3 | C24: =B23-B24 -> 32 | D24: =C24/B22 -> 0.081632653
A25: NO ESTA LA CAMARA | B25: 2 | C25: =C24-B25 -> 30 | D25: =C25/B22 -> 0.076530612
A26: RADIO | B26: 3 | C26: =C25-B26 -> 27 | D26: =C26/B22 -> 0.068877551
A27: TOTAL | B27: 392 | E27: 44795
A28: CAIDAS | B28: 33 | C28: 33 | D28: =C28/B27 -> 0.084183673
A29: LLEGAMOS NOSOTROS | B29: 3 | C29: =B28-B29 -> 30 | D29: =C29/B27 -> 0.076530612
A30: NO ESTA LA CAMARA | B30: 2 | C30: =C29-B30 -> 28 | D30: =C30/B27 -> 0.071428571
A31: RADIO | B31: 4 | C31: =C30-B31 -> 24 | D31: =C31/B27 -> 0.06122449 | G31: VAT07 | H31: COSEIDI | I31: Eva Peron y Lavalle | J31: DOMO | K31: PTP A FO | L31: 172.20.11.26 | M31: Se llega por ping y se visualiza por web | N31: 44790
A32: TOTAL | B32: 392 | E32: 44796 | G32: VAT23 (fija 1) | H32: COSEIDI | I32: EVA PERON Y "EL TUNEL" (BAJO NIVEL) | J32: Fija | K32: Fibra Optica | L32: 172.20.11.139 | M32: Se llega por ping y por web pide login
A33: CAIDAS | B33: 36 | C33: 36 | D33: =C33/B32 -> 0.091836735 | G33: VAT24 (fija 2) | H33: COSEIDI | I33: EVA PERON Y "EL TUNEL" (BAJO NIVEL) | J33: Fija | K33: Fibra Optica | L33: 172.20.11.140 | M33: Se llega por ping y por web pide login
A34: LLEGAMOS NOSOTROS | B34: 3 | C34: =B33-B34 -> 33 | D34: =C34/B32 -> 0.084183673
A35: NO ESTA LA CAMARA | B35: 2 | C35: =C34-B35 -> 31 | D35: =C35/B32 -> 0.079081633
A36: RADIO | B36: 4 | C36: =C35-B36 -> 27 | D36: =C36/B32 -> 0.068877551
A37: TOTAL | B37: 392 | E37: 44797
A38: CAIDAS | B38: 30 | C38: 30 | D38: =C38/B37 -> 0.076530612
A39: LLEGAMOS NOSOTROS | B39: 3 | C39: =B38-B39 -> 27 | D39: =C39/B37 -> 0.068877551
A40: NO ESTA LA CAMARA | B40: 2 | C40: =C39-B40 -> 25 | D40: =C40/B37 -> 0.06377551
...

Sheet PORCENTAJE

Sheet AUXILIAR
A1: FECHA | B1: RADIO | C1: FIBRA | D1: ANTENA | E1: TOTAL APAGADOS | F1: INSTALADAS | G1: % APAGADOS
A2: ='APAGADOS RADIO'!F3 -> 44774 | B2: ='APAGADOS RADIO'!F2+D2 -> 7 | C2: ='APAGADOS FIBRA'!F2 -> 31 | D2: ='APAGADOS ANTENA'!F2 -> 3 | E2: =B2+C2 -> 38 | F2: ='RESUMEN TOTAL'!B1 -> 392 | G2: =E2/F2 -> 0.096938776
A3: ='APAGADOS RADIO'!G3 -> 44775 | B3: ='APAGADOS RADIO'!G2+D3 -> 6 | C3: ='APAGADOS FIBRA'!G2 -> 35 | D3: ='APAGADOS ANTENA'!G2 -> 2 | E3: =B3+C3 -> 41 | F3: ='RESUMEN TOTAL'!B1 -> 392 | G3: =E3/F3 -> 0.10459184
A4: ='APAGADOS RADIO'!H3 -> 44776 | B4: ='APAGADOS RADIO'!H2+D4 -> 6 | C4: ='APAGADOS FIBRA'!H2 -> 25 | D4: ='APAGADOS ANTENA'!H2 -> 3 | E4: =B4+C4 -> 31 | F4: ='RESUMEN TOTAL'!B1 -> 392 | G4: =E4/F4 -> 0.079081633
A5: ='APAGADOS RADIO'!I3 -> 44777 | B5: ='APAGADOS RADIO'!I2+D5 -> 6 | C5: ='APAGADOS FIBRA'!I2 -> 28 | D5: ='APAGADOS ANTENA'!I2 -> 3 | E5: =B5+C5 -> 34 | F5: ='RESUMEN TOTAL'!B1 -> 392 | G5: =E5/F5 -> 0.086734694
A6: ='APAGADOS RADIO'!J3 -> 44778 | B6: ='APAGADOS RADIO'!J2+D6 -> 5 | C6: ='APAGADOS FIBRA'!J2 -> 25 | D6: ='APAGADOS ANTENA'!J2 -> 2 | E6: =B6+C6 -> 30 | F6: ='RESUMEN TOTAL'!B1 -> 392 | G6: =E6/F6 -> 0.076530612
A7: ='APAGADOS RADIO'!K3 -> 44779 | B7: 8 | C7: 24 | D7: 3 | E7: 32 | F7: ='RESUMEN TOTAL'!B1 -> 392 | G7: =E7/F7 -> 0.081632653
A8: ='APAGADOS RADIO'!L3 -> 44780 | B8: ='APAGADOS RADIO'!L2+D8 -> 7 | C8: ='APAGADOS FIBRA'!L2 -> 66 | D8: ='APAGADOS ANTENA'!L2 -> 2 | E8: =B8+C8 -> 73 | F8: ='RESUMEN TOTAL'!B1 -> 392 | G8: =E8/F8 -> 0.18622449
A9: ='APAGADOS RADIO'!M3 -> 44781 | B9: ='APAGADOS RADIO'!M2+D9 -> 7 | C9: ='APAGADOS FIBRA'!M2 -> 43 | D9: ='APAGADOS ANTENA'!M2 -> 2 | E9: =B9+C9 -> 50 | F9: ='RESUMEN TOTAL'!B1 -> 392 | G9: =E9/F9 -> 0.12755102
A10: ='APAGADOS RADIO'!N3 -> 44782 | B10: ='APAGADOS RADIO'!N2+D10 -> 6 | C10: ='APAGADOS FIBRA'!N2 -> 45 | D10: ='APAGADOS ANTENA'!N2 -> 2 | E10: =B10+C10 -> 51 | F10: ='RESUMEN TOTAL'!B1 -> 392 | G10: =E10/F10 -> 0.13010204
A11: ='APAGADOS RADIO'!O3 -> 44783 | B11: ='APAGADOS RADIO'!O2+D11 -> 16 | C11: ='APAGADOS FIBRA'!O2 -> 48 | D11: ='APAGADOS ANTENA'!O2 -> 10 | E11: =B11+C11 -> 64 | F11: ='RESUMEN TOTAL'!B1 -> 392 | G11: =E11/F11 -> 0.16326531
A12: ='APAGADOS RADIO'!P3 -> 44784 | B12: ='APAGADOS RADIO'!P2+D12 -> 5 | C12: ='APAGADOS FIBRA'!P2 -> 33 | D12: ='APAGADOS ANTENA'!P2 -> 1 | E12: =B12+C12 -> 38 | F12: ='RESUMEN TOTAL'!B1 -> 392 | G12: =E12/F12 -> 0.096938776
A13: ='APAGADOS RADIO'!Q3 -> 44785 | B13: ='APAGADOS RADIO'!Q2+D13 -> 6 | C13: ='APAGADOS FIBRA'!Q2 -> 38 | D13: ='APAGADOS ANTENA'!Q2 -> 2 | E13: =B13+C13 -> 44 | F13: ='RESUMEN TOTAL'!B1 -> 392 | G13: =E13/F13 -> 0.1122449
A14: ='APAGADOS RADIO'!R3 -> 44786 | B14: ='APAGADOS RADIO'!R2+D14 -> 3 | C14: ='APAGADOS FIBRA'!R2 -> 25 | D14: ='APAGADOS ANTENA'!R2 -> 0 | E14: =B14+C14 -> 28 | F14: ='RESUMEN TOTAL'!B1 -> 392 | G14: =E14/F14 -> 0.071428571
A15: ='APAGADOS RADIO'!S3 -> 44787 | B15: ='APAGADOS RADIO'!S2+D15 -> 5 | C15: ='APAGADOS FIBRA'!S2 -> 26 | D15: ='APAGADOS ANTENA'!S2 -> 1 | E15: =B15+C15 -> 31 | F15: ='RESUMEN TOTAL'!B1 -> 392 | G15: =E15/F15 -> 0.079081633
A16: ='APAGADOS RADIO'!T3 -> 44788 | B16: ='APAGADOS RADIO'!T2+D16 -> 7 | C16: ='APAGADOS FIBRA'!T2 -> 27 | D16: ='APAGADOS ANTENA'!T2 -> 3 | E16: =B16+C16 -> 34 | F16: ='RESUMEN TOTAL'!B1 -> 392 | G16: =E16/F16 -> 0.086734694
A17: ='APAGADOS RADIO'!U3 -> 44789 | B17: ='APAGADOS RADIO'!U2+D17 -> 5 | C17: ='APAGADOS FIBRA'!U2 -> 31 | D17: ='APAGADOS ANTENA'!U2 -> 2 | E17: =B17+C17 -> 36 | F17: ='RESUMEN TOTAL'!B1 -> 392 | G17: =E17/F17 -> 0.091836735
A18: ='APAGADOS RADIO'!V3 -> 44790 | B18: ='APAGADOS RADIO'!V2+D18 -> 5 | C18: ='APAGADOS FIBRA'!V2 -> 25 | D18: ='APAGADOS ANTENA'!V2 -> 2 | E18: =B18+C18 -> 30 | F18: ='RESUMEN TOTAL'!B1 -> 392 | G18: =E18/F18 -> 0.076530612
A19: ='APAGADOS RADIO'!W3 -> 44791 | B19: ='APAGADOS RADIO'!W2+D19 -> 5 | C19: ='APAGADOS FIBRA'!W2 -> 30 | D19: ='APAGADOS ANTENA'!W2 -> 2 | E19: =B19+C19 -> 35 | F19: ='RESUMEN TOTAL'!B1 -> 392 | G19: =E19/F19 -> 0.089285714
A20: ='APAGADOS RADIO'!X3 -> 44792 | B20: ='APAGADOS RADIO'!X2+D20 -> 5 | C20: ='APAGADOS FIBRA'!X2 -> 30 | D20: ='APAGADOS ANTENA'!X2 -> 2 | E20: =B20+C20 -> 35 | F20: ='RESUMEN TOTAL'!B1 -> 392 | G20: =E20/F20 -> 0.089285714
