Workbook
Name _25_de_agosto: 'RESUMEN TOTAL'!$A$4:$D$390
Name _25_de_agosto_3: 'RESUMEN TOTAL'!$A$4:$D$402
Name _30_mar: 'APAGADOS ANTENA'!$AI$3
Name BONOMOcam: Hoja1!$B$2
Name CANTIDAD_DE_CAMARAS: 'RESUMEN TOTAL'!$B$1
Name COSEIDIcam: Hoja1!$B$4

Sheet RESUMEN TOTAL
A1: CANTIDAD DE CAMARAS | B1: =COUNTA(B5:B626) -> 540 | D1: PORCIENTO DE CAIDAS | L1: =(L3)/(L2+L3) -> 0.1625 | M1: =(M3)/(M2+M3) -> 0.1424 | N1: =(N3)/(N2+N3) -> 0.13408724 | O1: =(O3)/(O2+O3) -> 0.13687601 | P1: =(P3)/(P2+P3) -> 0.13128039 | Q1: =(Q3)/(Q2+Q3) -> 0.19033233 | R1: =(R3)/(R2+R3) -> 0.18787879 | S1: =(S3)/(S2+S3) -> 0.2 | ... X1: =(X3)/(X2+X3) -> 0.13687601 | Z1: =(Z3)/(Z2+Z3) -> 0.14513557 | AA1: =(AA3)/(AA2+AA3) -> 0.14785374 | AB1: =(AB3)/(AB2+AB3) -> 0.15323855 | AC1: =(AC3)/(AC2+AC3) -> 0.16380655 | AD1: =(AD3)/(AD2+AD3) -> 0.16770186 | AE1: =(AE3)/(AE2+AE3) -> 0.18417047 | AF1: =(AF3)/(AF2+AF3) -> 0.14649682 | AG1: =(AG3)/(AG2+AG3) -> 0.13687601 | ... AO1: =(AO3)/(AO2+AO3) -> 0
D2: FUNCIONAN | L2: 536 | M2: 536 | N2: 536 | O2: 536 | P2: 536 | Q2: 536 | R2: 536 | S2: 536 | T2: 536 | U2: 536 | V2: 536 | W2: 536 | X2: 536 | Y2: 536 | Z2: 536 | AA2: 536 | AB2: 536 | AC2: 536 | AD2: 536 | AE2: 536 | AF2: 536 | AG2: 536 | AH2: 536 | AI2: 536 | AJ2: 536 | AK2: 536 | AL2: 536 | AM2: 536 | AN2: 536 | AO2: 536
D3: CAIDAS | L3: =COUNTIF(L4:L626, "apagado") -> 104 | M3: =COUNTIF(M4:M626, "apagado") -> 89 | N3: =COUNTIF(N4:N626, "apagado") -> 83 | O3: =COUNTIF(O4:O626, "apagado") -> 85 | P3: =COUNTIF(P4:P626, "apagado") -> 81 | Q3: =COUNTIF(Q4:Q626, "apagado") -> 126 | R3: =COUNTIF(R4:R626, "apagado") -> 124 | S3: =COUNTIF(S4:S626, "apagado") -> 134 | ... W3: =COUNTIF(W4:W626, "apagado") -> 93 | X3: =COUNTIF(X4:X526, "apagado") -> 85 | Y3: =COUNTIF(Y4:Y526, "apagado") -> 92 | Z3: =COUNTIF(Z4:Z626, "apagado") -> 91 | AA3: =COUNTIF(AA4:AA626, "apagado") -> 93 | AB3: =COUNTIF(AB4:AB626, "apagado") -> 97 | AC3: =COUNTIF(AC4:AC626, "apagado") -> 105 | AD3: =COUNTIF(AD4:AD626, "apagado") -> 108 | AE3: =COUNTIF(AE4:AE626, "apagado") -> 121 | AF3: =COUNTIF(AF4:AF626, "apagado") -> 92 | AG3: =COUNTIF(AG4:AG626, "apagado") -> 85 | ... AO3: =COUNTIF(AO4:AO626, "apagado") -> 0
A4: Barrio | B4: [Denominacion] | C4: [Empresa Mantenimiento] | D4: [Ubicacion] | E4: [Tipo de Camara] | F4: [Tipo de Conexion] | G4: Destino | I4: DIAS FUNCIONANDO | J4: DIAS CAIDA | K4: EFECTIVIDAD | L4: 45474 | M4: 45475 | N4: 45476 | O4: 45477 | P4: 45478 | Q4: 45479 | R4: 45480 | S4: 45481 | T4: 45482 | U4: 45483 | V4: 45484 | W4: 45485 | X4: 45486 | Y4: 45487 | Z4: 45488 | AA4: 45489 | AB4: 45490 | AC4: 45491 | AD4: 45492 | AE4: 45493 | AF4: 45494 | AG4: 45495 | AH4: 45496 | AI4: 45497 | AJ4: 45498 | AK4: 45499 | AL4: 45500 | AM4: 45501 | AN4: 45502 | AO4: 45503
A5: ALTAMIRA | B5: ALT01 | C5: BONOMO | D5: Calchaqui y Sgto. Cabral | E5: Domo | F5: Fibra Optica | H5: 172.20.10.6 | I5: =COUNTIF(L5:AM5,"") -> 27 | J5: =COUNTIF(L5:AM5,"APAGADO") -> 1 | K5: =(I5)/(J5+I5) -> 0.96428571 | V5: APAGADO
A6: ALTAMIRA | B6: ALT02 | C6: BONOMO | D6: Calchaqui y Lope de Vega | E6: Domo | F6: PTO A FO | G6: CABRAL Y CALCHAQUI | H6: 172.20.12.218 | I6: =COUNTIF(L6:AM6,"") -> 27 | J6: =COUNTIF(L6:AM6,"APAGADO") -> 1 | K6: =(I6)/(J6+I6) -> 0.96428571 | V6: APAGADO
A7: ALTAMIRA | B7: ALT 03 | C7: BONOMO | D7: Bombero Galarza y Necochea | E7: Domo | F7: Fibra Optica | H7: 172.20.12.54 | I7: =COUNTIF(L7:AM7,"") -> 27 | J7: =COUNTIF(L7:AM7,"APAGADO") -> 1 | K7: =(I7)/(J7+I7) -> 0.96428571 | V7: APAGADO
A8: ALTAMIRA | B8: ALT 04 | C8: BONOMO | D8: Francia y Necochea | E8: Domo | F8: Fibra Optica | H8: 172.20.12.55 | I8: =COUNTIF(L8:AM8,"") -> 27 | J8: =COUNTIF(L8:AM8,"APAGADO") -> 1 | K8: =(I8)/(J8+I8) -> 0.96428571 | V8: APAGADO
A9: ALTAMIRA | B9: ALT05 | C9: BONOMO | D9: Av. Calchaqui y Bombero Galarza | E9: Domo | F9: PTO A FO | G9: NECOCHEA Y GALARZA | H9: 172.20.12.216 | I9: =COUNTIF(L9:AM9,"") -> 27 | J9: =COUNTIF(L9:AM9,"APAGADO") -> 1 | K9: =(I9)/(J9+I9) -> 0.96428571 | V9: APAGADO
A10: ALTAMIRA | B10: ALT 06 | C10: BONOMO | D10: LOPE DE VEGA Y NECOCHEA | E10: Domo | F10: PTO A FO | G10: NECOCHEA Y GALARZA | H10: 172.20.12.12 | I10: =COUNTIF(L10:AM10,"") -> 27 | J10: =COUNTIF(L10:AM10,"APAGADO") -> 1 | K10: =(I10)/(J10+I10) -> 0.96428571 | V10: APAGADO
A11: ALTAMIRA | B11: ALT07 | C11: BONOMO | D11: AV. CALCHAQUI Y AV. DEL TRABAJO | E11: DOMO | F11: PTO A FO | G11: CABRAL Y CALCHAQUI | H11: 172.20.10.57 | I11: =COUNTIF(L11:AM11,"") -> 27 | J11: =COUNTIF(L11:AM11,"APAGADO") -> 1 | K11: =(I11)/(J11+I11) -> 0.96428571 | V11: APAGADO
A12: ALTAMIRA | B12: ALT 08 | C12: BONOMO | D12: HUMAITA Y NECOCHEA | E12: DOMO | F12: Fibra Optica | H12: 172.20.11.215 | I12: =COUNTIF(L12:AM12,"") -> 27 | J12: =COUNTIF(L12:AM12,"APAGADO") -> 1 | K12: =(I12)/(J12+I12) -> 0.96428571 | V12: APAGADO
A13: ALTAMIRA | B13: ALT 09 | C13: BONOMO | D13: NECOCHEA Y CURUPAITY | E13: DOMO | F13: Fibra Optica | H13: 172.20.11.216 | I13: =COUNTIF(L13:AM13,"") -> 27 | J13: =COUNTIF(L13:AM13,"APAGADO") -> 1 | K13: =(I13)/(J13+I13) -> 0.96428571 | V13: APAGADO
A14: ALTAMIRA | B14: ALT 10 | C14: BONOMO | D14: Calchaqui y Francia | E14: Domo | F14: Radio | H14: 172.20.12.156 | I14: =COUNTIF(L14:AM14,"") -> 27 | J14: =COUNTIF(L14:AM14,"APAGADO") -> 1 | K14: =(I14)/(J14+I14) -> 0.96428571 | V14: APAGADO
A15: AGUSTIN RAMIREZ | B15: ARA 01 | C15: BONOMO | D15: Malambo y Tranquera | E15: Domo | F15: Fibra Optica | H15: 172.20.12.110 | I15: =COUNTIF(L15:AM15,"") -> 27 | J15: =COUNTIF(L15:AM15,"APAGADO") -> 1 | K15: =(I15)/(J15+I15) -> 0.96428571 | V15: APAGADO
A16: BELGRANO | B16: BEL 01 | C16: BONOMO | D16: San Martin y Dardo Rocha | E16: DOMO | F16: Fibra Optica | H16: 172.20.12.64 | I16: =COUNTIF(L16:AM16,"") -> 27 | J16: =COUNTIF(L16:AM16,"APAGADO") -> 1 | K16: =(I16)/(J16+I16) -> 0.96428571 | V16: APAGADO
A17: BELGRANO | B17: BEL 02 | C17: BONOMO | D17: Guardia vieja y Fronteriz | E17: DOMO | F17: Fibra Optica | I17: =COUNTIF(L17:AM17,"") -> 20 | J17: =COUNTIF(L17:AM17,"APAGADO") -> 8 | K17: =(I17)/(J17+I17) -> 0.71428571 | V17: APAGADO | AC17: APAGADO | AD17: APAGADO | AE17: APAGADO | AF17: APAGADO | AG17: APAGADO | AH17: APAGADO | AI17: APAGADO | AN17: APAGADO
A18: BOSQUES CENTRO | B18: BOSQC 01 | C18: COSEIDI | D18: LUIS AGOTE E/DANUNCIO Y CAMPOAMOR | E18: Fija | F18: Radio | H18: 172.20.11.15 | I18: =COUNTIF(L18:AM18,"") -> 26 | J18: =COUNTIF(L18:AM18,"APAGADO") -> 2 | K18: =(I18)/(J18+I18) -> 0.92857143 | S18: APAGADO | V18: APAGADO
A19: BOSQUES CENTRO | B19: BOSQC 02 | C19: COSEIDI | D19: LUIS AGOTE E/DANUNCIO Y CAMPOAMOR | E19: Fija | F19: Radio | H19: 172.20.11.16 | I19: =COUNTIF(L19:AM19,"") -> 26 | J19: =COUNTIF(L19:AM19,"APAGADO") -> 2 | K19: =(I19)/(J19+I19) -> 0.92857143 | S19: APAGADO | V19: APAGADO
A20: BOSQUES CENTRO | B20: BOSQC 03 | C20: COSEIDI | D20: BENAVENTE Y LUIS AGOTE | E20: Fija | F20: Radio | H20: 172.20.11.13 | I20: =COUNTIF(L20:AM20,"") -> 26 | J20: =COUNTIF(L20:AM20,"APAGADO") -> 2 | K20: =(I20)/(J20+I20) -> 0.92857143 | S20: APAGADO | V20: APAGADO
A21: BOSQUES CENTRO | B21: BOSQC 04 | C21: COSEIDI | D21: BENAVENTE Y LUIS AGOTE | E21: Fija | F21: Radio | H21: 172.20.11.113 | I21: =COUNTIF(L21:AM21,"") -> 26 | J21: =COUNTIF(L21:AM21,"APAGADO") -> 2 | K21: =(I21)/(J21+I21) -> 0.92857143 | S21: APAGADO | V21: APAGADO
A22: BOSQUES CENTRO | B22: BOSQC 05 | C22: COSEIDI | D22: LUIS AGOTE Y RUTA 36 | E22: Fija | F22: Radio | H22: 172.20.11.17 | I22: =COUNTIF(L22:AM22,"") -> 26 | J22: =COUNTIF(L22:AM22,"APAGADO") -> 2 | K22: =(I22)/(J22+I22) -> 0.92857143 | S22: APAGADO | V22: APAGADO
A23: BOSQUES CENTRO | B23: BOSQC 06 | C23: COSEIDI | D23: LUIS AGOTE Y RUTA 36 | E23: Fija | F23: Radio | H23: 172.20.11.18 | I23: =COUNTIF(L23:AM23,"") -> 26 | J23: =COUNTIF(L23:AM23,"APAGADO") -> 2 | K23: =(I23)/(J23+I23) -> 0.92857143 | S23: APAGADO | V23: APAGADO
A24: CENTRO | B24: CEN01 | C24: BONOMO | D24: San Martin y 9 de Julio | E24: Fija | F24: Fibra Optica | H24: 172.20.11.10 | I24: =COUNTIF(L24:AM24,"") -> 2 | J24: =COUNTIF(L24:AM24,"APAGADO") -> 26 | K24: =(I24)/(J24+I24) -> 0.071428571 | L24: APAGADO | M24: APAGADO | N24: APAGADO | O24: APAGADO | P24: APAGADO | Q24: APAGADO | R24: APAGADO | S24: APAGADO | T24: APAGADO | U24: APAGADO | V24: APAGADO | W24: APAGADO | X24: APAGADO | Y24: APAGADO | Z24: APAGADO | AA24: APAGADO | AB24: APAGADO | AC24: APAGADO | AD24: APAGADO | AE24: APAGADO | AF24: APAGADO | AG24: APAGADO | AH24: APAGADO | AI24: APAGADO | AJ24: APAGADO | AK24: APAGADO
A25: CENTRO | B25: CEN02 | C25: BONOMO | D25: San Martin y Almafuerte | E25: Fija | F25: Fibra Optica | H25: 172.20.11.11 | I25: =COUNTIF(L25:AM25,"") -> 2 | J25: =COUNTIF(L25:AM25,"APAGADO") -> 26 | K25: =(I25)/(J25+I25) -> 0.071428571 | L25: APAGADO | M25: APAGADO | N25: APAGADO | O25: APAGADO | P25: APAGADO | Q25: APAGADO | R25: APAGADO | S25: APAGADO | T25: APAGADO | U25: APAGADO | V25: APAGADO | W25: APAGADO | X25: APAGADO | Y25: APAGADO | Z25: APAGADO | AA25: APAGADO | AB25: APAGADO | AC25: APAGADO | AD25: APAGADO | AE25: APAGADO | AF25: APAGADO | AG25: APAGADO | AH25: APAGADO | AI25: APAGADO | AJ25: APAGADO | AK25: APAGADO | AN25: APAGADO
A26: CENTRO | B26: CEN03 | C26: BONOMO | D26: San Martin y Sallares | E26: Domo | F26: Fibra Optica | H26: 172.20.12.30 | I26: =COUNTIF(L26:AM26,"") -> 28 | J26: =COUNTIF(L26:AM26,"APAGADO") -> 0 | K26: =(I26)/(J26+I26) -> 1
A27: CENTRO | B27: CEN04 | C27: BONOMO | D27: San Martin y Contreras | E27: Domo | F27: Fibra Optica | H27: 172.20.12.29 | I27: =COUNTIF(L27:AM27,"") -> 28 | J27: =COUNTIF(L27:AM27,"APAGADO") -> 0 | K27: =(I27)/(J27+I27) -> 1
A28: CENTRO | B28: CEN 05 | C28: BONOMO | D28: Bocuzzi e/España y San Martin | E28: DOMO | F28: Fibra Optica | H28: 172.20.10.200 | I28: =COUNTIF(L28:AM28,"") -> 26 | J28: =COUNTIF(L28:AM28,"APAGADO") -> 2 | K28: =(I28)/(J28+I28) -> 0.92857143 | O28: APAGADO | P28: APAGADO
A29: CENTRO | B29: CEN06 | C29: BONOMO | D29: Monteagudo y A.del Valle | E29: Fija | F29: Fibra Optica | H29: 172.20.10.02 | I29: =COUNTIF(L29:AM29,"") -> 22 | J29: =COUNTIF(L29:AM29,"APAGADO") -> 6 | K29: =(I29)/(J29+I29) -> 0.78571429 | AD29: APAGADO | AE29: APAGADO | AF29: APAGADO | AG29: APAGADO | AH29: APAGADO | AI29: APAGADO
A30: CENTRO | B30: CEN07 | C30: BONOMO | D30: San Martin y Guemes | E30: DOMO | F30: Fibra Optica | H30: 172.20.11.20 | I30: =COUNTIF(L30:AM30,"") -> 27 | J30: =COUNTIF(L30:AM30,"APAGADO") -> 0 | K30: =(I30)/(J30+I30) -> 1
A31: CENTRO | B31: CEN08 | C31: BONOMO | D31: San Martin y Pte.Peron | E31: Domo | F31: Fibra Optica | H31: 172.20.11.21 | I31: =COUNTIF(L31:AM31,"") -> 26 | J31: =COUNTIF(L31:AM31,"APAGADO") -> 2 | K31: =(I31)/(J31+I31) -> 0.92857143 | O31: APAGADO | P31: APAGADO
A32: CENTRO | B32: CEN09 | C32: BONOMO | D32: Chacabuco y 25 de Mayo | E32: Domo | F32: Fibra Optica | H32: 172.20.11.22 | I32: =COUNTIF(L32:AM32,"") -> 28 | J32: =COUNTIF(L32:AM32,"APAGADO") -> 0 | K32: =(I32)/(J32+I32) -> 1
A33: CENTRO | B33: CEN10 | C33: BONOMO | D33: Monteagudo y Pte. Peron | E33: Domo | F33: Fibra Optica | H33: 172.20.11.23 | I33: =COUNTIF(L33:AM33,"") -> 28 | J33: =COUNTIF(L33:AM33,"APAGADO") -> 0 | K33: =(I33)/(J33+I33) -> 1
A34: CENTRO | B34: CEN11 | C34: BONOMO | D34: Monteagudo y Bocuzzi | E34: Domo | F34: Fibra Optica | H34: 172.20.10.24 | I34: =COUNTIF(L34:AM34,"") -> 28 | J34: =COUNTIF(L34:AM34,"APAGADO") -> 0 | K34: =(I34)/(J34+I34) -> 1
A35: CENTRO | B35: CEN 12 | C35: BONOMO | D35: Monteagudo y Mitre | E35: Domo | F35: Fibra Optica | H35: 172.20.10.23 | I35: =COUNTIF(L35:AM35,"") -> 28 | J35: =COUNTIF(L35:AM35,"APAGADO") -> 0 | K35: =(I35)/(J35+I35) -> 1
A36: CENTRO | B36: CEN 13 | C36: BONOMO | D36: 25 de Mayo y Maipu | E36: DOMO | F36: Fibra Optica | H36: 172.20.10.20 | I36: =COUNTIF(L36:AM36,"") -> 28 | J36: =COUNTIF(L36:AM36,"APAGADO") -> 0 | K36: =(I36)/(J36+I36) -> 1
A37: CENTRO | B37: CEN14 | C37: BONOMO | D37: Pte.Peron e/Pringles y Brown | E37: Domo | F37: Fibra Optica | H37: 172.20.10.94 | I37: =COUNTIF(L37:AM37,"") -> 28 | J37: =COUNTIF(L37:AM37,"APAGADO") -> 0 | K37: =(I37)/(J37+I37) -> 1
A38: CENTRO | B38: CEN15 | C38: BONOMO | D38: Alberdi y A.del Valle | E38: Domo | F38: Fibra Optica | H38: 172.20.10.35 | I38: =COUNTIF(L38:AM38,"") -> 28 | J38: =COUNTIF(L38:AM38,"APAGADO") -> 0 | K38: =(I38)/(J38+I38) -> 1
A39: CENTRO | B39: CEN16 | C39: BONOMO | D39: San Martin y Pte. Peron | E39: Fija | F39: Fibra Optica | H39: 172.20.12.36 | I39: =COUNTIF(L39:AM39,"") -> 26 | J39: =COUNTIF(L39:AM39,"APAGADO") -> 2 | K39: =(I39)/(J39+I39) -> 0.92857143 | O39: APAGADO | P39: APAGADO
A40: CENTRO | B40: CEN17 | C40: BONOMO | D40: San Martin y Mitre | E40: Domo | F40: PTO A FO | G40: SAN MARTIN Y SALLARES | H40: 172.20.12.200 | I40: =COUNTIF(L40:AM40,"") -> 28 | J40: =COUNTIF(L40:AM40,"APAGADO") -> 0 | K40: =(I40)/(J40+I40) -> 1
...

Sheet Hoja3

Sheet ESTADISTICA
A1: ='RESUMEN TOTAL'!A4 -> Barrio | B1: ='RESUMEN TOTAL'!B4 -> [Denominacion] | C1: ='RESUMEN TOTAL'!D4 -> [Ubicacion] | D1: ='RESUMEN TOTAL'!E4 -> [Tipo de Camara] | E1: ='RESUMEN TOTAL'!F4 -> [Tipo de Conexion] | F1: ='RESUMEN TOTAL'!L4 -> 45474 | G1: ='RESUMEN TOTAL'!M4 -> 45475 | H1: ='RESUMEN TOTAL'!N4 -> 45476 | I1: ='RESUMEN TOTAL'!O4 -> 45477 | J1: ='RESUMEN TOTAL'!P4 -> 45478 | K1: ='RESUMEN TOTAL'!Q4 -> 45479 | L1: ='RESUMEN TOTAL'!R4 -> 45480 | M1: ='RESUMEN TOTAL'!S4 -> 45481 | ... AI1: ='RESUMEN TOTAL'!AO4 -> 45503
A2: ='RESUMEN TOTAL'!A5 -> ALTAMIRA | B2: ='RESUMEN TOTAL'!B5 -> ALT01 | C2: ='RESUMEN TOTAL'!D5 -> Calchaqui y Sgto. Cabral | D2: ='RESUMEN TOTAL'!E5 -> Domo | E2: ='RESUMEN TOTAL'!F5 -> Fibra Optica | F2: ='RESUMEN TOTAL'!L5 -> 0 | G2: ='RESUMEN TOTAL'!M5 -> 0 | H2: ='RESUMEN TOTAL'!N5 -> 0 | I2: ='RESUMEN TOTAL'!O5 -> 0 | J2: ='RESUMEN TOTAL'!P5 -> 0 | K2: ='RESUMEN TOTAL'!Q5 -> 0 | L2: ='RESUMEN TOTAL'!R5 -> 0 | M2: ='RESUMEN TOTAL'!S5 -> 0 | ... AI2: ='RESUMEN TOTAL'!AO5 -> 0
A3: ='RESUMEN TOTAL'!A6 -> ALTAMIRA | B3: ='RESUMEN TOTAL'!B6 -> ALT02 | C3: ='RESUMEN TOTAL'!D6 -> Calchaqui y Lope de Vega | D3: ='RESUMEN TOTAL'!E6 -> Domo | E3: ='RESUMEN TOTAL'!F6 -> PTO A FO | F3: ='RESUMEN TOTAL'!L6 -> 0 | G3: ='RESUMEN TOTAL'!M6 -> 0 | H3: ='RESUMEN TOTAL'!N6 -> 0 | I3: ='RESUMEN TOTAL'!O6 -> 0 | J3: ='RESUMEN TOTAL'!P6 -> 0 | K3: ='RESUMEN TOTAL'!Q6 -> 0 | L3: ='RESUMEN TOTAL'!R6 -> 0 | M3: ='RESUMEN TOTAL'!S6 -> 0 | ... AI3: ='RESUMEN TOTAL'!AO6 -> 0
A4: ='RESUMEN TOTAL'!A7 -> ALTAMIRA | B4: ='RESUMEN TOTAL'!B7 -> ALT 03 | C4: ='RESUMEN TOTAL'!D7 -> Bombero Galarza y Necochea | D4: ='RESUMEN TOTAL'!E7 -> Domo | E4: ='RESUMEN TOTAL'!F7 -> Fibra Optica | F4: ='RESUMEN TOTAL'!L7 -> 0 | G4: ='RESUMEN TOTAL'!M7 -> 0 | H4: ='RESUMEN TOTAL'!N7 -> 0 | I4: ='RESUMEN TOTAL'!O7 -> 0 | J4: ='RESUMEN TOTAL'!P7 -> 0 | K4: ='RESUMEN TOTAL'!Q7 -> 0 | L4: ='RESUMEN TOTAL'!R7 -> 0 | M4: ='RESUMEN TOTAL'!S7 -> 0 | ... AI4: ='RESUMEN TOTAL'!AO7 -> 0
A5: ='RESUMEN TOTAL'!A8 -> ALTAMIRA | B5: ='RESUMEN TOTAL'!B8 -> ALT 04 | C5: ='RESUMEN TOTAL'!D8 -> Francia y Necochea | D5: ='RESUMEN TOTAL'!E8 -> Domo | E5: ='RESUMEN TOTAL'!F8 -> Fibra Optica | F5: ='RESUMEN TOTAL'!L8 -> 0 | G5: ='RESUMEN TOTAL'!M8 -> 0 | H5: ='RESUMEN TOTAL'!N8 -> 0 | I5: ='RESUMEN TOTAL'!O8 -> 0 | J5: ='RESUMEN TOTAL'!P8 -> 0 | K5: ='RESUMEN TOTAL'!Q8 -> 0 | L5: ='RESUMEN TOTAL'!R8 -> 0 | M5: ='RESUMEN TOTAL'!S8 -> 0 | ... AI5: ='RESUMEN TOTAL'!AO8 -> 0
A6: ='RESUMEN TOTAL'!A9 -> ALTAMIRA | B6: ='RESUMEN TOTAL'!B9 -> ALT05 | C6: ='RESUMEN TOTAL'!D9 -> Av. Calchaqui y Bombero Galarza | D6: ='RESUMEN TOTAL'!E9 -> Domo | E6: ='RESUMEN TOTAL'!F9 -> PTO A FO | F6: ='RESUMEN TOTAL'!L9 -> 0 | G6: ='RESUMEN TOTAL'!M9 -> 0 | H6: ='RESUMEN TOTAL'!N9 -> 0 | I6: ='RESUMEN TOTAL'!O9 -> 0 | J6: ='RESUMEN TOTAL'!P9 -> 0 | K6: ='RESUMEN TOTAL'!Q9 -> 0 | L6: ='RESUMEN TOTAL'!R9 -> 0 | M6: ='RESUMEN TOTAL'!S9 -> 0 | ... AI6: ='RESUMEN TOTAL'!AO9 -> 0
A7: ='RESUMEN TOTAL'!A10 -> ALTAMIRA | B7: ='RESUMEN TOTAL'!B10 -> ALT 06 | C7: ='RESUMEN TOTAL'!D10 -> LOPE DE VEGA Y NECOCHEA | D7: ='RESUMEN TOTAL'!E10 -> Domo | E7: ='RESUMEN TOTAL'!F10 -> PTO A FO | F7: ='RESUMEN TOTAL'!L10 -> 0 | G7: ='RESUMEN TOTAL'!M10 -> 0 | H7: ='RESUMEN TOTAL'!N10 -> 0 | I7: ='RESUMEN TOTAL'!O10 -> 0 | J7: ='RESUMEN TOTAL'!P10 -> 0 | K7: ='RESUMEN TOTAL'!Q10 -> 0 | L7: ='RESUMEN TOTAL'!R10 -> 0 | M7: ='RESUMEN TOTAL'!S10 -> 0 | ... AI7: ='RESUMEN TOTAL'!AO10 -> 0
A8: ='RESUMEN TOTAL'!A11 -> ALTAMIRA | B8: ='RESUMEN TOTAL'!B11 -> ALT07 | C8: ='RESUMEN TOTAL'!D11 -> AV. CALCHAQUI Y AV. DEL TRABAJO | D8: ='RESUMEN TOTAL'!E11 -> DOMO | E8: ='RESUMEN TOTAL'!F11 -> PTO A FO | F8: ='RESUMEN TOTAL'!L11 -> 0 | G8: ='RESUMEN TOTAL'!M11 -> 0 | H8: ='RESUMEN TOTAL'!N11 -> 0 | I8: ='RESUMEN TOTAL'!O11 -> 0 | J8: ='RESUMEN TOTAL'!P11 -> 0 | K8: ='RESUMEN TOTAL'!Q11 -> 0 | L8: ='RESUMEN TOTAL'!R11 -> 0 | M8: ='RESUMEN TOTAL'!S11 -> 0 | ... AI8: ='RESUMEN TOTAL'!AO11 -> 0
A9: ='RESUMEN TOTAL'!A12 -> ALTAMIRA | B9: ='RESUMEN TOTAL'!B12 -> ALT 08 | C9: ='RESUMEN TOTAL'!D12 -> HUMAITA Y NECOCHEA | D9: ='RESUMEN TOTAL'!E12 -> DOMO | E9: ='RESUMEN TOTAL'!F12 -> Fibra Optica | F9: ='RESUMEN TOTAL'!L12 -> 0 | G9: ='RESUMEN TOTAL'!M12 -> 0 | H9: ='RESUMEN TOTAL'!N12 -> 0 | I9: ='RESUMEN TOTAL'!O12 -> 0 | J9: ='RESUMEN TOTAL'!P12 -> 0 | K9: ='RESUMEN TOTAL'!Q12 -> 0 | L9: ='RESUMEN TOTAL'!R12 -> 0 | M9: ='RESUMEN TOTAL'!S12 -> 0 | ... AI9: ='RESUMEN TOTAL'!AO12 -> 0
A10: ='RESUMEN TOTAL'!A13 -> ALTAMIRA | B10: ='RESUMEN TOTAL'!B13 -> ALT 09 | C10: ='RESUMEN TOTAL'!D13 -> NECOCHEA Y CURUPAITY | D10: ='RESUMEN TOTAL'!E13 -> DOMO | E10: ='RESUMEN TOTAL'!F13 -> Fibra Optica | F10: ='RESUMEN TOTAL'!L13 -> 0 | G10: ='RESUMEN TOTAL'!M13 -> 0 | H10: ='RESUMEN TOTAL'!N13 -> 0 | I10: ='RESUMEN TOTAL'!O13 -> 0 | J10: ='RESUMEN TOTAL'!P13 -> 0 | K10: ='RESUMEN TOTAL'!Q13 -> 0 | L10: ='RESUMEN TOTAL'!R13 -> 0 | M10: ='RESUMEN TOTAL'!S13 -> 0 | ... AI10: ='RESUMEN TOTAL'!AO13 -> 0
A11: ='RESUMEN TOTAL'!A14 -> ALTAMIRA | B11: ='RESUMEN TOTAL'!B14 -> ALT 10 | C11: ='RESUMEN TOTAL'!D14 -> Calchaqui y Francia | D11: ='RESUMEN TOTAL'!E14 -> Domo | E11: ='RESUMEN TOTAL'!F14 -> Radio | F11: ='RESUMEN TOTAL'!L14 -> 0 | G11: ='RESUMEN TOTAL'!M14 -> 0 | H11: ='RESUMEN TOTAL'!N14 -> 0 | I11: ='RESUMEN TOTAL'!O14 -> 0 | J11: ='RESUMEN TOTAL'!P14 -> 0 | K11: ='RESUMEN TOTAL'!Q14 -> 0 | L11: ='RESUMEN TOTAL'!R14 -> 0 | M11: ='RESUMEN TOTAL'!S14 -> 0 | ... AI11: ='RESUMEN TOTAL'!AO14 -> 0
A12: ='RESUMEN TOTAL'!A15 -> AGUSTIN RAMIREZ | B12: ='RESUMEN TOTAL'!B15 -> ARA 01 | C12: ='RESUMEN TOTAL'!D15 -> Malambo y Tranquera | D12: ='RESUMEN TOTAL'!E15 -> Domo | E12: ='RESUMEN TOTAL'!F15 -> Fibra Optica | F12: ='RESUMEN TOTAL'!L15 -> 0 | G12: ='RESUMEN TOTAL'!M15 -> 0 | H12: ='RESUMEN TOTAL'!N15 -> 0 | I12: ='RESUMEN TOTAL'!O15 -> 0 | J12: ='RESUMEN TOTAL'!P15 -> 0 | K12: ='RESUMEN TOTAL'!Q15 -> 0 | L12: ='RESUMEN TOTAL'!R15 -> 0 | M12: ='RESUMEN TOTAL'!S15 -> 0 | ... AI12: ='RESUMEN TOTAL'!AO15 -> 0
... A123: ='RESUMEN TOTAL'!A126 -> DON ORIONE | B123: ='RESUMEN TOTAL'!B126 -> DORIO1 | C123: ='RESUMEN TOTAL'!D126 -> AV Bosques Y Theran | D123: ='RESUMEN TOTAL'!E126 -> Domo | E123: ='RESUMEN TOTAL'!F126 -> GPON | F123: ='RESUMEN TOTAL'!L126 -> APAGADO | G123: ='RESUMEN TOTAL'!M126 -> APAGADO | H123: ='RESUMEN TOTAL'!N126 -> APAGADO | I123: ='RESUMEN TOTAL'!O126 -> 0 | J123: ='RESUMEN TOTAL'!P126 -> 0 | K123: ='RESUMEN TOTAL'!Q126 -> APAGADO | L123: ='RESUMEN TOTAL'!R126 -> APAGADO | M123: ='RESUMEN TOTAL'!S126 -> 0 | ... AI123: ='RESUMEN TOTAL'!AO126 -> 0
A124: ='RESUMEN TOTAL'!A128 -> EL PARQUE | B124: ='RESUMEN TOTAL'!B128 -> EPQ 01 | C124: ='RESUMEN TOTAL'!D128 -> 1282 Y GRIERSON | D124: ='RESUMEN TOTAL'!E128 -> DOMO | E124: ='RESUMEN TOTAL'!F128 -> Fibra Optica | F124: ='RESUMEN TOTAL'!L128 -> 0 | G124: ='RESUMEN TOTAL'!M128 -> 0 | H124: ='RESUMEN TOTAL'!N128 -> 0 | I124: ='RESUMEN TOTAL'!O128 -> 0 | J124: ='RESUMEN TOTAL'!P128 -> 0 | K124: ='RESUMEN TOTAL'!Q128 -> APAGADO | L124: ='RESUMEN TOTAL'!R128 -> 0 | M124: ='RESUMEN TOTAL'!S128 -> 0 | ... AI124: ='RESUMEN TOTAL'!AO128 -> 0
A125: ='RESUMEN TOTAL'!A129 -> EL PARQUE | B125: ='RESUMEN TOTAL'!B129 -> EPQ 02 | C125: ='RESUMEN TOTAL'!D129 -> 1282 Y MASSE | D125: ='RESUMEN TOTAL'!E129 -> DOMO | E125: ='RESUMEN TOTAL'!F129 -> Fibra Optica | F125: ='RESUMEN TOTAL'!L129 -> 0 | G125: ='RESUMEN TOTAL'!M129 -> 0 | H125: ='RESUMEN TOTAL'!N129 -> 0 | I125: ='RESUMEN TOTAL'!O129 -> 0 | J125: ='RESUMEN TOTAL'!P129 -> 0 | K125: ='RESUMEN TOTAL'!Q129 -> APAGADO | L125: ='RESUMEN TOTAL'!R129 -> 0 | M125: ='RESUMEN TOTAL'!S129 -> 0 | ... AI125: ='RESUMEN TOTAL'!AO129 -> 0
A126: ='RESUMEN TOTAL'!A130 -> EL PARQUE | B126: ='RESUMEN TOTAL'!B130 -> EPQ 03 | C126: ='RESUMEN TOTAL'!D130 -> 1282 Y RP 36 | D126: ='RESUMEN TOTAL'!E130 -> Domo | E126: ='RESUMEN TOTAL'!F130 -> Fibra Optica | F126: ='RESUMEN TOTAL'!L130 -> APAGADO | G126: ='RESUMEN TOTAL'!M130 -> APAGADO | H126: ='RESUMEN TOTAL'!N130 -> APAGADO | I126: ='RESUMEN TOTAL'!O130 -> APAGADO | J126: ='RESUMEN TOTAL'!P130 -> APAGADO | K126: ='RESUMEN TOTAL'!Q130 -> APAGADO | L126: ='RESUMEN TOTAL'!R130 -> APAGADO | M126: ='RESUMEN TOTAL'!S130 -> APAGADO | ... AI126: ='RESUMEN TOTAL'!AO130 -> 0
A127: ='RESUMEN TOTAL'!A131 -> EL PARQUE | B127: ='RESUMEN TOTAL'!B131 -> EPQ 04 | C127: ='RESUMEN TOTAL'!D131 -> 1282 Y MORENO | D127: ='RESUMEN TOTAL'!E131 -> DOMO | E127: ='RESUMEN TOTAL'!F131 -> Fibra Optica | F127: ='RESUMEN TOTAL'!L131 -> 0 | G127: ='RESUMEN TOTAL'!M131 -> 0 | H127: ='RESUMEN TOTAL'!N131 -> 0 | I127: ='RESUMEN TOTAL'!O131 -> 0 | J127: ='RESUMEN TOTAL'!P131 -> 0 | K127: ='RESUMEN TOTAL'!Q131 -> APAGADO | L127: ='RESUMEN TOTAL'!R131 -> 0 | M127: ='RESUMEN TOTAL'!S131 -> 0 | ... AI127: ='RESUMEN TOTAL'!AO131 -> 0
A128: ='RESUMEN TOTAL'!A132 -> LA ESMERALDA | B128: ='RESUMEN TOTAL'!B132 -> ESM01 | C128: ='RESUMEN TOTAL'!D132 -> Cabello y Brasil | D128: ='RESUMEN TOTAL'!E132 -> Domo | E128: ='RESUMEN TOTAL'!F132 -> Radio | F128: ='RESUMEN TOTAL'!L132 -> 0 | G128: ='RESUMEN TOTAL'!M132 -> 0 | H128: ='RESUMEN TOTAL'!N132 -> 0 | I128: ='RESUMEN TOTAL'!O132 -> 0 | J128: ='RESUMEN TOTAL'!P132 -> 0 | K128: ='RESUMEN TOTAL'!Q132 -> 0 | L128: ='RESUMEN TOTAL'!R132 -> 0 | M128: ='RESUMEN TOTAL'!S132 -> 0 | ... AI128: ='RESUMEN TOTAL'!AO132 -> 0
A129: ='RESUMEN TOTAL'!A133 -> SAN JORGE | B129: ='RESUMEN TOTAL'!B133 -> ESM02 | C129: ='RESUMEN TOTAL'!D133 -> Novak y Cabello | D129: ='RESUMEN TOTAL'!E133 -> Domo | E129: ='RESUMEN TOTAL'!F133 -> PTO A FO | F129: ='RESUMEN TOTAL'!L133 -> 0 | G129: ='RESUMEN TOTAL'!M133 -> 0 | H129: ='RESUMEN TOTAL'!N133 -> 0 | I129: ='RESUMEN TOTAL'!O133 -> 0 | J129: ='RESUMEN TOTAL'!P133 -> 0 | K129: ='RESUMEN TOTAL'!Q133 -> 0 | L129: ='RESUMEN TOTAL'!R133 -> 0 | M129: ='RESUMEN TOTAL'!S133 -> 0 | ... AI129: ='RESUMEN TOTAL'!AO133 -> 0
A130: ='RESUMEN TOTAL'!A134 -> SAN JORGE | B130: ='RESUMEN TOTAL'!B134 -> ESM03 | C130: ='RESUMEN TOTAL'!D134 -> Novak y Humahuaca | D130: ='RESUMEN TOTAL'!E134 -> DOMO | E130: ='RESUMEN TOTAL'!F134 -> PTO A FO | F130: ='RESUMEN TOTAL'!L134 -> 0 | G130: ='RESUMEN TOTAL'!M134 -> 0 | H130: ='RESUMEN TOTAL'!N134 -> 0 | I130: ='RESUMEN TOTAL'!O134 -> 0 | J130: ='RESUMEN TOTAL'!P134 -> 0 | K130: ='RESUMEN TOTAL'!Q134 -> 0 | L130: ='RESUMEN TOTAL'!R134 -> 0 | M130: ='RESUMEN TOTAL'!S134 -> 0 | ... AI130: ='RESUMEN TOTAL'!AO134 -> 0
A131: ='RESUMEN TOTAL'!A135 -> LA ESMERALDA | B131: ='RESUMEN TOTAL'!B135 -> ESM04 | C131: ='RESUMEN TOTAL'!D135 -> Basualdo y Bengochea | D131: ='RESUMEN TOTAL'!E135 -> Domo | E131: ='RESUMEN TOTAL'!F135 -> Fibra Optica | F131: ='RESUMEN TOTAL'!L135 -> 0 | G131: ='RESUMEN TOTAL'!M135 -> 0 | H131: ='RESUMEN TOTAL'!N135 -> 0 | I131: ='RESUMEN TOTAL'!O135 -> 0 | J131: ='RESUMEN TOTAL'!P135 -> 0 | K131: ='RESUMEN TOTAL'!Q135 -> 0 | L131: ='RESUMEN TOTAL'!R135 -> 0 | M131: ='RESUMEN TOTAL'!S135 -> 0 | ... AI131: ='RESUMEN TOTAL'!AO135 -> 0
A132: ='RESUMEN TOTAL'!A136 -> LA ESMERALDA | B132: ='RESUMEN TOTAL'!B136 -> ESM05 | C132: ='RESUMEN TOTAL'!D136 -> Aniceto Diaz y Villar | D132: ='RESUMEN TOTAL'!E136 -> Domo | E132: ='RESUMEN TOTAL'!F136 -> Fibra Optica | F132: ='RESUMEN TOTAL'!L136 -> 0 | G132: ='RESUMEN TOTAL'!M136 -> 0 | H132: ='RESUMEN TOTAL'!N136 -> 0 | I132: ='RESUMEN TOTAL'!O136 -> 0 | J132: ='RESUMEN TOTAL'!P136 -> 0 | K132: ='RESUMEN TOTAL'!Q136 -> 0 | L132: ='RESUMEN TOTAL'!R136 -> 0 | M132: ='RESUMEN TOTAL'!S136 -> 0 | ... AI132: ='RESUMEN TOTAL'!AO136 -> 0
A133: ='RESUMEN TOTAL'!A137 -> LA ESMERALDA | B133: ='RESUMEN TOTAL'!B137 -> ESM06 | C133: ='RESUMEN TOTAL'!D137 -> Roselli y Cabello | D133: ='RESUMEN TOTAL'!E137 -> Domo | E133: ='RESUMEN TOTAL'!F137 -> Radio | F133: ='RESUMEN TOTAL'!L137 -> 0 | G133: ='RESUMEN TOTAL'!M137 -> 0 | H133: ='RESUMEN TOTAL'!N137 -> 0 | I133: ='RESUMEN TOTAL'!O137 -> 0 | J133: ='RESUMEN TOTAL'!P137 -> 0 | K133: ='RESUMEN TOTAL'!Q137 -> 0 | L133: ='RESUMEN TOTAL'!R137 -> 0 | M133: ='RESUMEN TOTAL'!S137 -> 0 | ... AI133: ='RESUMEN TOTAL'!AO137 -> 0
A134: ='RESUMEN TOTAL'!A138 -> LA ESMERALDA | B134: ='RESUMEN TOTAL'!B138 -> ESM07 | C134: ='RESUMEN TOTAL'!D138 -> AV. NOVAK Y SERRANO | D134: ='RESUMEN TOTAL'!E138 -> DOMO | E134: ='RESUMEN TOTAL'!F138 -> PTO A FO | F134: ='RESUMEN TOTAL'!L138 -> 0 | G134: ='RESUMEN TOTAL'!M138 -> 0 | H134: ='RESUMEN TOTAL'!N138 -> 0 | I134: ='RESUMEN TOTAL'!O138 -> 0 | J134: ='RESUMEN TOTAL'!P138 -> 0 | K134: ='RESUMEN TOTAL'!Q138 -> 0 | L134: ='RESUMEN TOTAL'!R138 -> 0 | M134: ='RESUMEN TOTAL'!S138 -> 0 | ... AI134: ='RESUMEN TOTAL'!AO138 -> 0
A135: ='RESUMEN TOTAL'!A139 -> LA ESMERALDA | B135: ='RESUMEN TOTAL'!B139 -> ESM 08 | C135: ='RESUMEN TOTAL'!D139 -> DAVINSON Y MORANCHEL | D135: ='RESUMEN TOTAL'!E139 -> FIJA | E135: ='RESUMEN TOTAL'!F139 -> Radio | F135: ='RESUMEN TOTAL'!L139 -> APAGADO | G135: ='RESUMEN TOTAL'!M139 -> APAGADO | H135: ='RESUMEN TOTAL'!N139 -> APAGADO | I135: ='RESUMEN TOTAL'!O139 -> 0 | J135: ='RESUMEN TOTAL'!P139 -> 0 | K135: ='RESUMEN TOTAL'!Q139 -> 0 | L135: ='RESUMEN TOTAL'!R139 -> 0 | M135: ='RESUMEN TOTAL'!S139 -> 0 | ... AI135: ='RESUMEN TOTAL'!AO139 -> 0
... A264: ='RESUMEN TOTAL'!A268 -> EL ROCIO | B264: ='RESUMEN TOTAL'!B268 -> RCO06 (fija 2) | C264: ='RESUMEN TOTAL'!D268 -> LOBOS Y CHASCOMUS | D264: ='RESUMEN TOTAL'!E268 -> FIJA | E264: ='RESUMEN TOTAL'!F268 -> Fibra Optica | F264: ='RESUMEN TOTAL'!L268 -> 0 | G264: ='RESUMEN TOTAL'!M268 -> 0 | H264: ='RESUMEN TOTAL'!N268 -> 0 | I264: ='RESUMEN TOTAL'!O268 -> 0 | J264: ='RESUMEN TOTAL'!P268 -> 0 | K264: ='RESUMEN TOTAL'!Q268 -> 0 | L264: ='RESUMEN TOTAL'!R268 -> 0 | M264: ='RESUMEN TOTAL'!S268 -> APAGADO | ... AI264: ='RESUMEN TOTAL'!AO268 -> 0
A265: ='RESUMEN TOTAL'!A270 -> RICARDO ROJAS | B265: ='RESUMEN TOTAL'!B270 -> RRJ01 | C265: ='RESUMEN TOTAL'!D270 -> AV. LUJAN Y BRAGADO | D265: ='RESUMEN TOTAL'!E270 -> DOMO | E265: ='RESUMEN TOTAL'!F270 -> Fibra Optica | F265: ='RESUMEN TOTAL'!L270 -> 0 | G265: ='RESUMEN TOTAL'!M270 -> 0 | H265: ='RESUMEN TOTAL'!N270 -> 0 | I265: ='RESUMEN TOTAL'!O270 -> 0 | J265: ='RESUMEN TOTAL'!P270 -> 0 | K265: ='RESUMEN TOTAL'!Q270 -> 0 | L265: ='RESUMEN TOTAL'!R270 -> 0 | M265: ='RESUMEN TOTAL'!S270 -> APAGADO | ... AI265: ='RESUMEN TOTAL'!AO270 -> 0
A266: ='RESUMEN TOTAL'!A271 -> RICARDO ROJAS | B266: ='RESUMEN TOTAL'!B271 -> RRJ02 | C266: ='RESUMEN TOTAL'!D271 -> AV. LUJAN Y DIAG. LOS POETAS | D266: ='RESUMEN TOTAL'!E271 -> DOMO | E266: ='RESUMEN TOTAL'!F271 -> Fibra Optica | F266: ='RESUMEN TOTAL'!L271 -> 0 | G266: ='RESUMEN TOTAL'!M271 -> 0 | H266: ='RESUMEN TOTAL'!N271 -> 0 | I266: ='RESUMEN TOTAL'!O271 -> 0 | J266: ='RESUMEN TOTAL'!P271 -> 0 | K266: ='RESUMEN TOTAL'!Q271 -> 0 | L266: ='RESUMEN TOTAL'!R271 -> 0 | M266: ='RESUMEN TOTAL'!S271 -> APAGADO | ... AI266: ='RESUMEN TOTAL'!AO271 -> 0
A267: ='RESUMEN TOTAL'!A272 -> RICARDO ROJAS | B267: ='RESUMEN TOTAL'!B272 -> RRJ03 (fija 1) | C267: ='RESUMEN TOTAL'!D272 -> RUBEN DARIO E/ FADER Y DIAG. LOS POETAS | D267: ='RESUMEN TOTAL'!E272 -> Fija | E267: ='RESUMEN TOTAL'!F272 -> Fibra Optica | F267: ='RESUMEN TOTAL'!L272 -> 0 | G267: ='RESUMEN TOTAL'!M272 -> 0 | H267: ='RESUMEN TOTAL'!N272 -> 0 | I267: ='RESUMEN TOTAL'!O272 -> 0 | J267: ='RESUMEN TOTAL'!P272 -> 0 | K267: ='RESUMEN TOTAL'!Q272 -> 0 | L267: ='RESUMEN TOTAL'!R272 -> APAGADO | M267: ='RESUMEN TOTAL'!S272 -> APAGADO | ... AI267: ='RESUMEN TOTAL'!AO272 -> 0
A268: ='RESUMEN TOTAL'!A273 -> RICARDO ROJAS | B268: ='RESUMEN TOTAL'!B273 -> RRJ04 (fija 2) | C268: ='RESUMEN TOTAL'!D273 -> RUBEN DARIO E/ FADER Y DIAG. LOS POETAS | D268: ='RESUMEN TOTAL'!E273 -> Fija | E268: ='RESUMEN TOTAL'!F273 -> Fibra Optica | F268: ='RESUMEN TOTAL'!L273 -> 0 | G268: ='RESUMEN TOTAL'!M273 -> 0 | H268: ='RESUMEN TOTAL'!N273 -> 0 | I268: ='RESUMEN TOTAL'!O273 -> 0 | J268: ='RESUMEN TOTAL'!P273 -> 0 | K268: ='RESUMEN TOTAL'!Q273 -> 0 | L268: ='RESUMEN TOTAL'!R273 -> APAGADO | M268: ='RESUMEN TOTAL'!S273 -> APAGADO | ... AI268: ='RESUMEN TOTAL'!AO273 -> 0
A269: ='RESUMEN TOTAL'!A274 -> RICARDO ROJAS | B269: ='RESUMEN TOTAL'!B274 -> RRJ 05 | C269: ='RESUMEN TOTAL'!D274 -> LUJAN Y RUTA 36 | D269: ='RESUMEN TOTAL'!E274 -> DOMO | E269: ='RESUMEN TOTAL'!F274 -> Fibra Optica | F269: ='RESUMEN TOTAL'!L274 -> 0 | G269: ='RESUMEN TOTAL'!M274 -> 0 | H269: ='RESUMEN TOTAL'!N274 -> 0 | I269: ='RESUMEN TOTAL'!O274 -> 0 | J269: ='RESUMEN TOTAL'!P274 -> 0 | K269: ='RESUMEN TOTAL'!Q274 -> 0 | L269: ='RESUMEN TOTAL'!R274 -> 0 | M269: ='RESUMEN TOTAL'!S274 -> APAGADO | ... AI269: ='RESUMEN TOTAL'!AO274 -> 0
A270: ='RESUMEN TOTAL'!A275 -> RICARDO ROJAS | B270: ='RESUMEN TOTAL'!B275 -> RRJ 06 | C270: ='RESUMEN TOTAL'!D275 -> Constancio Vigil y Pablo Groussac | D270: ='RESUMEN TOTAL'!E275 -> Domo | E270: ='RESUMEN TOTAL'!F275 -> Fibra Optica | F270: ='RESUMEN TOTAL'!L275 -> 0 | G270: ='RESUMEN TOTAL'!M275 -> 0 | H270: ='RESUMEN TOTAL'!N275 -> 0 | I270: ='RESUMEN TOTAL'!O275 -> 0 | J270: ='RESUMEN TOTAL'!P275 -> 0 | K270: ='RESUMEN TOTAL'!Q275 -> APAGADO | L270: ='RESUMEN TOTAL'!R275 -> APAGADO | M270: ='RESUMEN TOTAL'!S275 -> APAGADO | ... AI270: ='RESUMEN TOTAL'!AO275 -> 0
A271: ='RESUMEN TOTAL'!A276 -> RICARDO ROJAS | B271: ='RESUMEN TOTAL'!B276 -> RRJ 07 | C271: ='RESUMEN TOTAL'!D276 -> Constancio Vigil y Estanislao del Campo | D271: ='RESUMEN TOTAL'!E276 -> Domo | E271: ='RESUMEN TOTAL'!F276 -> Fibra Optica | F271: ='RESUMEN TOTAL'!L276 -> 0 | G271: ='RESUMEN TOTAL'!M276 -> 0 | H271: ='RESUMEN TOTAL'!N276 -> 0 | I271: ='RESUMEN TOTAL'!O276 -> 0 | J271: ='RESUMEN TOTAL'!P276 -> 0 | K271: ='RESUMEN TOTAL'!Q276 -> APAGADO | L271: ='RESUMEN TOTAL'!R276 -> APAGADO | M271: ='RESUMEN TOTAL'!S276 -> APAGADO | ... AI271: ='RESUMEN TOTAL'!AO276 -> 0
A272: ='RESUMEN TOTAL'!A277 -> RICARDO ROJAS | B272: ='RESUMEN TOTAL'!B277 -> RRJ 08 | C272: ='RESUMEN TOTAL'!D277 -> Constancio Vigil y Pablo Podesta | D272: ='RESUMEN TOTAL'!E277 -> Domo | E272: ='RESUMEN TOTAL'!F277 -> Fibra Optica | F272: ='RESUMEN TOTAL'!L277 -> APAGADO | G272: ='RESUMEN TOTAL'!M277 -> APAGADO | H272: ='RESUMEN TOTAL'!N277 -> APAGADO | I272: ='RESUMEN TOTAL'!O277 -> 0 | J272: ='RESUMEN TOTAL'!P277 -> APAGADO | K272: ='RESUMEN TOTAL'!Q277 -> APAGADO | L272: ='RESUMEN TOTAL'!R277 -> APAGADO | M272: ='RESUMEN TOTAL'!S277 -> APAGADO | ... AI272: ='RESUMEN TOTAL'!AO277 -> 0
A273: ='RESUMEN TOTAL'!A278 -> RICARDO ROJAS | B273: ='RESUMEN TOTAL'!B278 -> RRJ 09 | C273: ='RESUMEN TOTAL'!D278 -> Constancio Vigil y Jose Ingeniero | D273: ='RESUMEN TOTAL'!E278 -> Domo | E273: ='RESUMEN TOTAL'!F278 -> Fibra Optica | F273: ='RESUMEN TOTAL'!L278 -> APAGADO | G273: ='RESUMEN TOTAL'!M278 -> APAGADO | H273: ='RESUMEN TOTAL'!N278 -> APAGADO | I273: ='RESUMEN TOTAL'!O278 -> APAGADO | J273: ='RESUMEN TOTAL'!P278 -> APAGADO | K273: ='RESUMEN TOTAL'!Q278 -> APAGADO | L273: ='RESUMEN TOTAL'!R278 -> APAGADO | M273: ='RESUMEN TOTAL'!S278 -> APAGADO | ... AI273: ='RESUMEN TOTAL'!AO278 -> 0
A274: ='RESUMEN TOTAL'!A279 -> RICARDO ROJAS | B274: ='RESUMEN TOTAL'!B279 -> RRJ 10 | C274: ='RESUMEN TOTAL'!D279 -> LUGONES Y OBLIGADO | D274: ='RESUMEN TOTAL'!E279 -> Domo | E274: ='RESUMEN TOTAL'!F279 -> Fibra Optica | F274: ='RESUMEN TOTAL'!L279 -> 0 | G274: ='RESUMEN TOTAL'!M279 -> 0 | H274: ='RESUMEN TOTAL'!N279 -> 0 | I274: ='RESUMEN TOTAL'!O279 -> 0 | J274: ='RESUMEN TOTAL'!P279 -> 0 | K274: ='RESUMEN TOTAL'!Q279 -> 0 | L274: ='RESUMEN TOTAL'!R279 -> 0 | M274: ='RESUMEN TOTAL'!S279 -> APAGADO | ... AI274: ='RESUMEN TOTAL'!AO279 -> 0
A275: ='RESUMEN TOTAL'!A280 -> RICARDO ROJAS | B275: ='RESUMEN TOTAL'!B280 -> RRJ 11 | C275: ='RESUMEN TOTAL'!D280 -> LUGONES Y OBLIGADO | D275: ='RESUMEN TOTAL'!E280 -> Domo | E275: ='RESUMEN TOTAL'!F280 -> Fibra Optica | F275: ='RESUMEN TOTAL'!L280 -> 0 | G275: ='RESUMEN TOTAL'!M280 -> 0 | H275: ='RESUMEN TOTAL'!N280 -> 0 | I275: ='RESUMEN TOTAL'!O280 -> 0 | J275: ='RESUMEN TOTAL'!P280 -> 0 | K275: ='RESUMEN TOTAL'!Q280 -> 0 | L275: ='RESUMEN TOTAL'!R280 -> 0 | M275: ='RESUMEN TOTAL'!S280 -> APAGADO | ... AI275: ='RESUMEN TOTAL'!AO280 -> 0
A276: ='RESUMEN TOTAL'!A281 -> RICARDO ROJAS | B276: ='RESUMEN TOTAL'!B281 -> RRJ 12 | C276: ='RESUMEN TOTAL'!D281 -> FADER Y DIAGONAL LOS POETAS | D276: ='RESUMEN TOTAL'!E281 -> DOMO | E276: ='RESUMEN TOTAL'!F281 -> Fibra Optica | F276: ='RESUMEN TOTAL'!L281 -> 0 | G276: ='RESUMEN TOTAL'!M281 -> 0 | H276: ='RESUMEN TOTAL'!N281 -> 0 | I276: ='RESUMEN TOTAL'!O281 -> 0 | J276: ='RESUMEN TOTAL'!P281 -> 0 | K276: ='RESUMEN TOTAL'!Q281 -> 0 | L276: ='RESUMEN TOTAL'!R281 -> APAGADO | M276: ='RESUMEN TOTAL'!S281 -> APAGADO | ... AI276: ='RESUMEN TOTAL'!AO281 -> 0
... A315: ='RESUMEN TOTAL'!A320 -> SAN JORGE | B315: ='RESUMEN TOTAL'!B320 -> SJO 03 | C315: ='RESUMEN TOTAL'!D320 -> 517 Y 580 | D315: ='RESUMEN TOTAL'!E320 -> DOMO | E315: ='RESUMEN TOTAL'!F320 -> Radio | F315: ='RESUMEN TOTAL'!L320 -> APAGADO | G315: ='RESUMEN TOTAL'!M320 -> APAGADO | H315: ='RESUMEN TOTAL'!N320 -> APAGADO | I315: ='RESUMEN TOTAL'!O320 -> 0 | J315: ='RESUMEN TOTAL'!P320 -> 0 | K315: ='RESUMEN TOTAL'!Q320 -> 0 | L315: ='RESUMEN TOTAL'!R320 -> APAGADO | M315: ='RESUMEN TOTAL'!S320 -> 0 | ... AI315: ='RESUMEN TOTAL'!AO320 -> 0
A316: ='RESUMEN TOTAL'!A321 -> SAN JORGE | B316: ='RESUMEN TOTAL'!B321 -> SJO 04 | C316: ='RESUMEN TOTAL'!D321 -> 552 Y 519 | D316: ='RESUMEN TOTAL'!E321 -> DOMO | E316: ='RESUMEN TOTAL'!F321 -> Radio | F316: ='RESUMEN TOTAL'!L321 -> 0 | G316: ='RESUMEN TOTAL'!M321 -> 0 | H316: ='RESUMEN TOTAL'!O321 -> 0 | I316: ='RESUMEN TOTAL'!#REF! -> #REF! | J316: ='RESUMEN TOTAL'!P321 -> 0 | K316: ='RESUMEN TOTAL'!Q321 -> 0 | L316: ='RESUMEN TOTAL'!R321 -> 0 | M316: ='RESUMEN TOTAL'!S321 -> 0 | N316: ='RESUMEN TOTAL'!T321 -> 0 | O316: ='RESUMEN TOTAL'!U321 -> 0 | P316: ='RESUMEN TOTAL'!V321 -> 0 | Q316: ='RESUMEN TOTAL'!W321 -> 0 | ... AI316: ='RESUMEN TOTAL'!AO321 -> 0
...

Sheet APAGADOS
E1: APAGADOS | F1: =COUNTIF(F3:F404, "APAGADO") -> 67 | G1: =COUNTIF(G3:G404, "APAGADO") -> 54 | H1: =COUNTIF(H3:H504, "APAGADO") -> 70 | I1: =COUNTIF(I3:I404, "APAGADO") -> 48 | J1: =COUNTIF(J3:J404, "APAGADO") -> 48 | K1: =COUNTIF(K3:K404, "APAGADO") -> 76 | L1: =COUNTIF(L3:L404, "APAGADO") -> 72 | M1: =COUNTIF(M3:M404, "APAGADO") -> 93 | N1: =COUNTIF(N3:N404, "APAGADO") -> 46 | O1: =COUNTIF(O3:O404, "APAGADO") -> 57 | P1: =COUNTIF(P3:P404, "APAGADO") -> 113 | ... AD1: =COUNTIF(AD3:AD404, "APAGADO") -> 42 | AE1: =COUNTIF(AE3:AE504, "APAGADO") -> 67 | AF1: =COUNTIF(AF3:AF404, "APAGADO") -> 0 | AG1: =COUNTIF(AG3:AG404, "APAGADO") -> 0 | AH1: =COUNTIF(AH3:AH404, "APAGADO") -> 39 | AI1: =COUNTIF(AI3:AI404, "APAGADO") -> 0
A2: =ESTADISTICA!A1 -> Barrio | B2: =ESTADISTICA!B1 -> [Denominacion] | C2: =ESTADISTICA!C1 -> [Ubicacion] | D2: =ESTADISTICA!D1 -> [Tipo de Camara] | E2: =ESTADISTICA!E1 -> [Tipo de Conexion] | F2: =ESTADISTICA!F1 -> 45474 | G2: =ESTADISTICA!G1 -> 45475 | H2: =ESTADISTICA!H1 -> 45476 | ... AH2: =ESTADISTICA!AH1 -> 45502 | AI2: 182
A3: =ESTADISTICA!A2 -> ALTAMIRA | B3: =ESTADISTICA!B2 -> ALT01 | C3: =ESTADISTICA!C2 -> Calchaqui y Sgto. Cabral | D3: =ESTADISTICA!D2 -> Domo | E3: =ESTADISTICA!E2 -> Fibra Optica | F3: =ESTADISTICA!F2 -> 0 | G3: =ESTADISTICA!G2 -> 0 | H3: =ESTADISTICA!H2 -> 0 | ... AI3: =ESTADISTICA!AI2 -> 0
A4: =ESTADISTICA!A3 -> ALTAMIRA | B4: =ESTADISTICA!B3 -> ALT02 | C4: =ESTADISTICA!C3 -> Calchaqui y Lope de Vega | D4: =ESTADISTICA!D3 -> Domo | E4: =ESTADISTICA!E3 -> PTO A FO | F4: =ESTADISTICA!F3 -> 0 | G4: =ESTADISTICA!G3 -> 0 | H4: =ESTADISTICA!H3 -> 0 | ... AI4: =ESTADISTICA!AI3 -> 0
A5: =ESTADISTICA!A4 -> ALTAMIRA | B5: =ESTADISTICA!B4 -> ALT 03 | C5: =ESTADISTICA!C4 -> Bombero Galarza y Necochea | D5: =ESTADISTICA!D4 -> Domo | E5: =ESTADISTICA!E4 -> Fibra Optica | F5: =ESTADISTICA!F4 -> 0 | G5: =ESTADISTICA!G4 -> 0 | H5: =ESTADISTICA!H4 -> 0 | ... AI5: =ESTADISTICA!AI4 -> 0
A6: =ESTADISTICA!A5 -> ALTAMIRA | B6: =ESTADISTICA!B5 -> ALT 04 | C6: =ESTADISTICA!C5 -> Francia y Necochea | D6: =ESTADISTICA!D5 -> Domo | E6: =ESTADISTICA!E5 -> Fibra Optica | F6: =ESTADISTICA!F5 -> 0 | G6: =ESTADISTICA!G5 -> 0 | H6: =ESTADISTICA!H5 -> 0 | ... AI6: =ESTADISTICA!AI5 -> 0
A7: =ESTADISTICA!A6 -> ALTAMIRA | B7: =ESTADISTICA!B6 -> ALT05 | C7: =ESTADISTICA!C6 -> Av. Calchaqui y Bombero Galarza | D7: =ESTADISTICA!D6 -> Domo | E7: =ESTADISTICA!E6 -> PTO A FO | F7: =ESTADISTICA!F6 -> 0 | G7: =ESTADISTICA!G6 -> 0 | H7: =ESTADISTICA!H6 -> 0 | ... AI7: =ESTADISTICA!AI6 -> 0
A8: =ESTADISTICA!A7 -> ALTAMIRA | B8: =ESTADISTICA!B7 -> ALT 06 | C8: =ESTADISTICA!C7 -> LOPE DE VEGA Y NECOCHEA | D8: =ESTADISTICA!D7 -> Domo | E8: =ESTADISTICA!E7 -> PTO A FO | F8: =ESTADISTICA!F7 -> 0 | G8: =ESTADISTICA!G7 -> 0 | H8: =ESTADISTICA!H7 -> 0 | ... AI8: =ESTADISTICA!AI7 -> 0
A9: =ESTADISTICA!A8 -> ALTAMIRA | B9: =ESTADISTICA!B8 -> ALT07 | C9: =ESTADISTICA!C8 -> AV. CALCHAQUI Y AV. DEL TRABAJO | D9: =ESTADISTICA!D8 -> DOMO | E9: =ESTADISTICA!E8 -> PTO A FO | F9: =ESTADISTICA!F8 -> 0 | G9: =ESTADISTICA!G8 -> 0 | H9: =ESTADISTICA!H8 -> 0 | ... AI9: =ESTADISTICA!AI8 -> 0
A10: =ESTADISTICA!A9 -> ALTAMIRA | B10: =ESTADISTICA!B9 -> ALT 08 | C10: =ESTADISTICA!C9 -> HUMAITA Y NECOCHEA | D10: =ESTADISTICA!D9 -> DOMO | E10: =ESTADISTICA!E9 -> Fibra Optica | F10: =ESTADISTICA!F9 -> 0 | G10: =ESTADISTICA!G9 -> 0 | H10: =ESTADISTICA!H9 -> 0 | ... AI10: =ESTADISTICA!AI9 -> 0
A11: =ESTADISTICA!A10 -> ALTAMIRA | B11: =ESTADISTICA!B10 -> ALT 09 | C11: =ESTADISTICA!C10 -> NECOCHEA Y CURUPAITY | D11: =ESTADISTICA!D10 -> DOMO | E11: =ESTADISTICA!E10 -> Fibra Optica | F11: =ESTADISTICA!F10 -> 0 | G11: =ESTADISTICA!G10 -> 0 | H11: =ESTADISTICA!H10 -> 0 | ... AI11: =ESTADISTICA!AI10 -> 0
A12: =ESTADISTICA!A11 -> ALTAMIRA | B12: =ESTADISTICA!B11 -> ALT 10 | C12: =ESTADISTICA!C11 -> Calchaqui y Francia | D12: =ESTADISTICA!D11 -> Domo | E12: =ESTADISTICA!E11 -> Radio | F12: =ESTADISTICA!F11 -> 0 | G12: =ESTADISTICA!G11 -> 0 | H12: =ESTADISTICA!H11 -> 0 | ... AI12: =ESTADISTICA!AI11 -> 0
A13: =ESTADISTICA!A12 -> AGUSTIN RAMIREZ | B13: =ESTADISTICA!B12 -> ARA 01 | C13: =ESTADISTICA!C12 -> Malambo y Tranquera | D13: =ESTADISTICA!D12 -> Domo | E13: =ESTADISTICA!E12 -> Fibra Optica | F13: =ESTADISTICA!F12 -> 0 | G13: =ESTADISTICA!G12 -> 0 | H13: =ESTADISTICA!H12 -> 0 | ... AI13: =ESTADISTICA!AI12 -> 0
A14: =ESTADISTICA!A13 -> BELGRANO | B14: =ESTADISTICA!B13 -> BEL 01 | C14: =ESTADISTICA!C13 -> San Martin y Dardo Rocha | D14: =ESTADISTICA!D13 -> DOMO | E14: =ESTADISTICA!E13 -> Fibra Optica | F14: =ESTADISTICA!F13 -> 0 | G14: =ESTADISTICA!G13 -> 0 | H14: =ESTADISTICA!H13 -> 0 | ... AI14: =ESTADISTICA!AI13 -> 0
... A124: =ESTADISTICA!A123 -> DON ORIONE | B124: =ESTADISTICA!B123 -> DORIO1 | C124: =ESTADISTICA!C123 -> AV Bosques Y Theran | D124: =ESTADISTICA!D123 -> Domo | E124: =ESTADISTICA!E123 -> GPON | F124: =ESTADISTICA!F123 -> APAGADO | G124: =ESTADISTICA!G123 -> APAGADO | H124: =ESTADISTICA!H123 -> APAGADO | ... AI124: =ESTADISTICA!AI123 -> 0
A125: DON ORIONE | B125: DORI02 | C125: QUINQUELA MARTIN Y AV BOSQUES | F125: =ESTADISTICA!F124 -> 0 | G125: =ESTADISTICA!G124 -> 0 | H125: =ESTADISTICA!H124 -> 0 | I125: =ESTADISTICA!I124 -> 0 | J125: =ESTADISTICA!J124 -> 0 | K125: =ESTADISTICA!K124 -> APAGADO | L125: =ESTADISTICA!L124 -> 0 | M125: =ESTADISTICA!M124 -> 0 | ... AI125: =ESTADISTICA!AI124 -> 0
A126: =ESTADISTICA!A124 -> EL PARQUE | B126: =ESTADISTICA!B124 -> EPQ 01 | C126: =ESTADISTICA!C124 -> 1282 Y GRIERSON | D126: =ESTADISTICA!D124 -> DOMO | E126: =ESTADISTICA!E124 -> Fibra Optica | F126: =ESTADISTICA!F124 -> 0 | G126: =ESTADISTICA!G124 -> 0 | H126: =ESTADISTICA!H124 -> 0 | ... AI126: =ESTADISTICA!AI124 -> 0
A127: =ESTADISTICA!A125 -> EL PARQUE | B127: =ESTADISTICA!B125 -> EPQ 02 | C127: =ESTADISTICA!C125 -> 1282 Y MASSE | D127: =ESTADISTICA!D125 -> DOMO | E127: =ESTADISTICA!E125 -> Fibra Optica | F127: =ESTADISTICA!F125 -> 0 | G127: =ESTADISTICA!G125 -> 0 | H127: =ESTADISTICA!H125 -> 0 | ... AI127: =ESTADISTICA!AI125 -> 0
A128: =ESTADISTICA!A126 -> EL PARQUE | B128: =ESTADISTICA!B126 -> EPQ 03 | C128: =ESTADISTICA!C126 -> 1282 Y RP 36 | D128: =ESTADISTICA!D126 -> Domo | E128: =ESTADISTICA!E126 -> Fibra Optica | F128: =ESTADISTICA!F126 -> APAGADO | G128: =ESTADISTICA!G126 -> APAGADO | H128: =ESTADISTICA!H126 -> APAGADO | ... AI128: =ESTADISTICA!AI126 -> 0
A129: =ESTADISTICA!A127 -> EL PARQUE | B129: =ESTADISTICA!B127 -> EPQ 04 | C129: =ESTADISTICA!C127 -> 1282 Y MORENO | D129: =ESTADISTICA!D127 -> DOMO | E129: =ESTADISTICA!E127 -> Fibra Optica | F129: =ESTADISTICA!F127 -> 0 | G129: =ESTADISTICA!G127 -> 0 | H129: =ESTADISTICA!H127 -> 0 | ... AI129: =ESTADISTICA!AI127 -> 0
A130: =ESTADISTICA!A128 -> LA ESMERALDA | B130: =ESTADISTICA!B128 -> ESM01 | C130: =ESTADISTICA!C128 -> Cabello y Brasil | D130: =ESTADISTICA!D128 -> Domo | E130: =ESTADISTICA!E128 -> Radio | F130: =ESTADISTICA!F128 -> 0 | G130: =ESTADISTICA!G128 -> 0 | H130: =ESTADISTICA!H128 -> 0 | ... AI130: =ESTADISTICA!AI128 -> 0
A131: =ESTADISTICA!A129 -> SAN JORGE | B131: =ESTADISTICA!B129 -> ESM02 | C131: =ESTADISTICA!C129 -> Novak y Cabello | D131: =ESTADISTICA!D129 -> Domo | E131: =ESTADISTICA!E129 -> PTO A FO | F131: =ESTADISTICA!F129 -> 0 | G131: =ESTADISTICA!G129 -> 0 | H131: =ESTADISTICA!H129 -> 0 | ... AI131: =ESTADISTICA!AI129 -> 0
A132: =ESTADISTICA!A130 -> SAN JORGE | B132: =ESTADISTICA!B130 -> ESM03 | C132: =ESTADISTICA!C130 -> Novak y Humahuaca | D132: =ESTADISTICA!D130 -> DOMO | E132: =ESTADISTICA!E130 -> PTO A FO | F132: =ESTADISTICA!F130 -> 0 | G132: =ESTADISTICA!G130 -> 0 | H132: =ESTADISTICA!H130 -> 0 | ... AI132: =ESTADISTICA!AI130 -> 0
A133: =ESTADISTICA!A131 -> LA ESMERALDA | B133: =ESTADISTICA!B131 -> ESM04 | C133: =ESTADISTICA!C131 -> Basualdo y Bengochea | D133: =ESTADISTICA!D131 -> Domo | E133: =ESTADISTICA!E131 -> Fibra Optica | F133: =ESTADISTICA!F131 -> 0 | G133: =ESTADISTICA!G131 -> 0 | H133: =ESTADISTICA!H131 -> 0 | ... AI133: =ESTADISTICA!AI131 -> 0
A134: =ESTADISTICA!A132 -> LA ESMERALDA | B134: =ESTADISTICA!B132 -> ESM05 | C134: =ESTADISTICA!C132 -> Aniceto Diaz y Villar | D134: =ESTADISTICA!D132 -> Domo | E134: =ESTADISTICA!E132 -> Fibra Optica | F134: =ESTADISTICA!F132 -> 0 | G134: =ESTADISTICA!G132 -> 0 | H134: =ESTADISTICA!H132 -> 0 | ... AI134: =ESTADISTICA!AI132 -> 0
A135: =ESTADISTICA!A133 -> LA ESMERALDA | B135: =ESTADISTICA!B133 -> ESM06 | C135: =ESTADISTICA!C133 -> Roselli y Cabello | D135: =ESTADISTICA!D133 -> Domo | E135: =ESTADISTICA!E133 -> Radio | F135: =ESTADISTICA!F133 -> 0 | G135: =ESTADISTICA!G133 -> 0 | H135: =ESTADISTICA!H133 -> 0 | ... AI135: =ESTADISTICA!AI133 -> 0
A136: =ESTADISTICA!A134 -> LA ESMERALDA | B136: =ESTADISTICA!B134 -> ESM07 | C136: =ESTADISTICA!C134 -> AV. NOVAK Y SERRANO | D136: =ESTADISTICA!D134 -> DOMO | E136: =ESTADISTICA!E134 -> PTO A FO | F136: =ESTADISTICA!F134 -> 0 | G136: =ESTADISTICA!G134 -> 0 | H136: =ESTADISTICA!H134 -> 0 | ... AI136: =ESTADISTICA!AI134 -> 0
A137: =ESTADISTICA!A135 -> LA ESMERALDA | B137: =ESTADISTICA!B135 -> ESM 08 | C137: =ESTADISTICA!C135 -> DAVINSON Y MORANCHEL | D137: =ESTADISTICA!D135 -> FIJA | E137: =ESTADISTICA!E135 -> Radio | F137: =ESTADISTICA!F135 -> APAGADO | G137: =ESTADISTICA!G135 -> APAGADO | H137: =ESTADISTICA!H135 -> APAGADO | ... AI137: =ESTADISTICA!AI135 -> 0
... A204: =ESTADISTICA!A202 -> MAYOL | B204: =ESTADISTICA!B202 -> MAY 04 | C204: =ESTADISTICA!C202 -> MAR CHIQUITA Y RIO JACHAL | D204: =ESTADISTICA!D202 -> DOMO | E204: =ESTADISTICA!E202 -> Radio | F204: =ESTADISTICA!F202 -> APAGADO | G204: =ESTADISTICA!G202 -> APAGADO | H204: =ESTADISTICA!H202 -> APAGADO | ... AI204: =ESTADISTICA!AI202 -> 0
A205: MONTE CUDINE | B205: =ESTADISTICA!B203 -> MCUD 01 | C205: =ESTADISTICA!C203 -> TINOGASTA Y SAN LORENZO | D205: =ESTADISTICA!D203 -> Domo | E205: =ESTADISTICA!E203 -> Fibra Optica | F205: =ESTADISTICA!F203 -> 0 | G205: =ESTADISTICA!G203 -> 0 | H205: =ESTADISTICA!H203 -> 0 | I205: =ESTADISTICA!I203 -> 0 | ... AI205: =ESTADISTICA!AI203 -> 0
A206: MONTE CUDINE | B206: =ESTADISTICA!B204 -> MCUD 02 | C206: =ESTADISTICA!C204 -> CALLE 115 A Y 158 | D206: =ESTADISTICA!D204 -> DOMO | E206: =ESTADISTICA!E204 -> Fibra Optica | F206: =ESTADISTICA!F204 -> 0 | G206: =ESTADISTICA!G204 -> 0 | H206: =ESTADISTICA!H204 -> 0 | I206: =ESTADISTICA!I204 -> 0 | ... AI206: =ESTADISTICA!AI204 -> 0
A207: =ESTADISTICA!A205 -> MARTIN FIERRO | B207: =ESTADISTICA!B205 -> MFI 01 | C207: =ESTADISTICA!C205 -> Belgrano y Sgto. Cabral | D207: =ESTADISTICA!D205 -> Fija | E207: =ESTADISTICA!E205 -> Fibra Optica | F207: =ESTADISTICA!F205 -> 0 | G207: =ESTADISTICA!G205 -> 0 | H207: =ESTADISTICA!H205 -> 0 | ... AI207: =ESTADISTICA!AI205 -> 0
A208: =ESTADISTICA!A206 -> LOPEZ ROMERO | B208: =ESTADISTICA!B206 -> MFI02 | C208: =ESTADISTICA!C206 -> Calchaqui y Balcarce | D208: =ESTADISTICA!D206 -> Fija | E208: =ESTADISTICA!E206 -> Fibra Optica | F208: =ESTADISTICA!F206 -> 0 | G208: =ESTADISTICA!G206 -> 0 | H208: =ESTADISTICA!H206 -> 0 | ... AI208: =ESTADISTICA!AI206 -> 0
A209: =ESTADISTICA!A208 -> MARTIN FIERRO | B209: =ESTADISTICA!B208 -> MFI04 | C209: =ESTADISTICA!C208 -> Calchaqui y balcarce | D209: =ESTADISTICA!D208 -> Domo | E209: =ESTADISTICA!E208 -> Fibra Optica | F209: =ESTADISTICA!F208 -> 0 | G209: =ESTADISTICA!G208 -> 0 | H209: =ESTADISTICA!H208 -> 0 | ... AI209: =ESTADISTICA!AI208 -> 0
A210: =ESTADISTICA!A209 -> SAN EMILIO | B210: =ESTADISTICA!B209 -> MFI 05 | C210: =ESTADISTICA!C209 -> Cno. Gral. Belgrano y Guayaquil | D210: =ESTADISTICA!D209 -> Domo | E210: =ESTADISTICA!E209 -> Fibra Optica | F210: =ESTADISTICA!F209 -> 0 | G210: =ESTADISTICA!G209 -> 0 | H210: =ESTADISTICA!H209 -> 0 | ... AI210: =ESTADISTICA!AI209 -> 0
A211: =ESTADISTICA!A210 -> SAN EMILIO | B211: =ESTADISTICA!B210 -> MFI06 | C211: =ESTADISTICA!C210 -> Con. Gral. Belgrano y Bombero Galarza | D211: =ESTADISTICA!D210 -> DOMO | E211: =ESTADISTICA!E210 -> Radio | F211: =ESTADISTICA!F210 -> 0 | G211: =ESTADISTICA!G210 -> 0 | H211: =ESTADISTICA!H210 -> 0 | ... AI211: =ESTADISTICA!AI210 -> 0
A212: =ESTADISTICA!A211 -> MARTIN FIERRO | B212: =ESTADISTICA!B211 -> MFI 07 | C212: =ESTADISTICA!C211 -> Sargento Cabral y Carlos Gardel | D212: =ESTADISTICA!D211 -> Domo | E212: =ESTADISTICA!E211 -> PTO A FO | F212: =ESTADISTICA!F211 -> 0 | G212: =ESTADISTICA!G211 -> 0 | H212: =ESTADISTICA!H211 -> 0 | ... AI212: =ESTADISTICA!AI211 -> 0
A213: =ESTADISTICA!A212 -> MARTIN FIERRO | B213: =ESTADISTICA!B212 -> MFI 08 | C213: =ESTADISTICA!C212 -> Braile y Batalla de Callao | D213: =ESTADISTICA!D212 -> Domo | E213: =ESTADISTICA!E212 -> PTO A FO | F213: =ESTADISTICA!F212 -> 0 | G213: =ESTADISTICA!G212 -> 0 | H213: =ESTADISTICA!H212 -> 0 | ... AI213: =ESTADISTICA!AI212 -> 0
A214: =ESTADISTICA!A213 -> GOBERNADOR MONTEVERDE | B214: =ESTADISTICA!B213 -> MON01 | C214: =ESTADISTICA!C213 -> San Martin y Patricias Argentinas | D214: =ESTADISTICA!D213 -> Fija | E214: =ESTADISTICA!E213 -> Fibra Optica | F214: =ESTADISTICA!F213 -> 0 | G214: =ESTADISTICA!G213 -> 0 | H214: =ESTADISTICA!H213 -> 0 | ... AI214: =ESTADISTICA!AI213 -> 0
A215: =ESTADISTICA!A214 -> GOBERNADOR MONTEVERDE | B215: =ESTADISTICA!B214 -> MON02 | C215: =ESTADISTICA!C214 -> Senzabello y Famatina | D215: =ESTADISTICA!D214 -> Domo | E215: =ESTADISTICA!E214 -> Radio | F215: =ESTADISTICA!F214 -> 0 | G215: =ESTADISTICA!G214 -> 0 | H215: =ESTADISTICA!H214 -> 0 | ... AI215: =ESTADISTICA!AI214 -> 0
...

Sheet APAGADOS FIBRA
C1: TOTAL FIBRA | D1: =COUNTIFS(E4:E401,"=Fibra Optica") -> 270
E2: APAGADOS | F2: =COUNTIFS(F4:F501, "=APAGADO",E4:E501,"=Fibra Optica") -> 54 | G2: =COUNTIFS(G4:G501, "=APAGADO",E4:E501,"=Fibra Optica") -> 38 | H2: =COUNTIFS(H4:H501, "=APAGADO",E4:E501,"=Fibra Optica") -> 39 | I2: =COUNTIFS(I4:I501, "=APAGADO",E4:E501,"=Fibra Optica") -> 40 | J2: =COUNTIFS(J4:J501, "=APAGADO",E4:E501,"=Fibra Optica") -> 40 | K2: =COUNTIFS(K4:K501, "=APAGADO",E4:E501,"=Fibra Optica") -> 58 | L2: =COUNTIFS(L4:L501, "=APAGADO",E4:E501,"=Fibra Optica") -> 50 | M2: =COUNTIFS(M4:M501, "=APAGADO",E4:E501,"=Fibra Optica") -> 77 | N2: =COUNTIFS(N4:N501, "=APAGADO",E4:E501,"=Fibra Optica") -> 39 | O2: =COUNTIFS(O4:O501, "=APAGADO",E4:E501,"=Fibra Optica") -> 39 | P2: =COUNTIFS(P4:P601, "=APAGADO",E4:E601,"=Fibra Optica") -> 85 | Q2: =COUNTIFS(Q4:Q501, "=APAGADO",E4:E501,"=Fibra Optica") -> 40 | R2: =COUNTIFS(R4:R501, "=APAGADO",E4:E501,"=Fibra Optica") -> 39 | S2: =COUNTIFS(S4:S501, "=APAGADO",E4:E501,"=Fibra Optica") -> 38 | T2: =COUNTIFS(T4:T501, "=APAGADO",E4:E501,"=Fibra Optica") -> 37 | U2: =COUNTIFS(U4:U501, "=APAGADO",E4:E501,"=Fibra Optica") -> 41 | V2: =COUNTIFS(V4:V501, "=APAGADO",E4:E501,"=Fibra Optica") -> 46 | W2: =COUNTIFS(W4:W501, "=APAGADO",E4:E501,"=Fibra Optica") -> 51 | X2: =COUNTIFS(X4:X501, "=APAGADO",E4:E501,"=Fibra Optica") -> 51 | Y2: =COUNTIFS(Y4:Y501, "=APAGADO",E4:E501,"=Fibra Optica") -> 62 | Z2: =COUNTIFS(Z4:Z501, "=APAGADO",E4:E501,"=Fibra Optica") -> 42 | AA2: =COUNTIFS(AA4:AA501, "=APAGADO",E4:E501,"=Fibra Optica") -> 38 | AB2: =COUNTIFS(AB4:AB501, "=APAGADO",E4:E501,"=Fibra Optica") -> 34 | AC2: =COUNTIFS(AC4:AC601, "=APAGADO",E4:E601,"=Fibra Optica") -> 33 | AD2: =COUNTIFS(AD4:AD501, "=APAGADO",E4:E501,"=Fibra Optica") -> 33 | AE2: =COUNTIFS(AE4:AE501, "=APAGADO",E4:E501,"=Fibra Optica") -> 37 | AF2: =COUNTIFS(AF4:AF501, "=APAGADO",E4:E501,"=Fibra Optica") -> 0 | AG2: =COUNTIFS(AG4:AG501, "=APAGADO",E4:E501,"=Fibra Optica") -> 0 | AH2: =COUNTIFS(AH4:AH501, "=APAGADO",E4:E501,"=Fibra Optica") -> 33 | AI2: =COUNTIFS(AI4:AI501, "=APAGADO",F4:F501,"=Fibra Optica") -> 0
A3: =ESTADISTICA!A1 -> Barrio | B3: =ESTADISTICA!B1 -> [Denominacion] | C3: =ESTADISTICA!C1 -> [Ubicacion] | D3: =ESTADISTICA!D1 -> [Tipo de Camara] | E3: =ESTADISTICA!E1 -> [Tipo de Conexion] | F3: =ESTADISTICA!F1 -> 45474 | G3: =ESTADISTICA!G1 -> 45475 | H3: =ESTADISTICA!H1 -> 45476 | ... AH3: =ESTADISTICA!AH1 -> 45502 | AI3: 182
A4: ='RESUMEN TOTAL'!A7 -> ALTAMIRA | B4: ='RESUMEN TOTAL'!B7 -> ALT 03 | C4: ='RESUMEN TOTAL'!D7 -> Bombero Galarza y Necochea | D4: ='RESUMEN TOTAL'!E7 -> Domo | E4: ='RESUMEN TOTAL'!F7 -> Fibra Optica | F4: ='RESUMEN TOTAL'!L7 -> 0 | G4: ='RESUMEN TOTAL'!M7 -> 0 | H4: ='RESUMEN TOTAL'!N7 -> 0 | I4: ='RESUMEN TOTAL'!O7 -> 0 | J4: ='RESUMEN TOTAL'!P7 -> 0 | K4: ='RESUMEN TOTAL'!Q7 -> 0 | L4: ='RESUMEN TOTAL'!R7 -> 0 | M4: ='RESUMEN TOTAL'!S7 -> 0 | ... AI4: ='RESUMEN TOTAL'!AO7 -> 0
A5: ='RESUMEN TOTAL'!A8 -> ALTAMIRA | B5: ='RESUMEN TOTAL'!B8 -> ALT 04 | C5: ='RESUMEN TOTAL'!D8 -> Francia y Necochea | D5: ='RESUMEN TOTAL'!E8 -> Domo | E5: ='RESUMEN TOTAL'!F8 -> Fibra Optica | F5: ='RESUMEN TOTAL'!L8 -> 0 | G5: ='RESUMEN TOTAL'!M8 -> 0 | H5: ='RESUMEN TOTAL'!N8 -> 0 | I5: ='RESUMEN TOTAL'!O8 -> 0 | J5: ='RESUMEN TOTAL'!P8 -> 0 | K5: ='RESUMEN TOTAL'!Q8 -> 0 | L5: ='RESUMEN TOTAL'!R8 -> 0 | M5: ='RESUMEN TOTAL'!S8 -> 0 | ... AI5: ='RESUMEN TOTAL'!AO8 -> 0
A6: ='RESUMEN TOTAL'!A9 -> ALTAMIRA | B6: ='RESUMEN TOTAL'!B9 -> ALT05 | C6: ='RESUMEN TOTAL'!D9 -> Av. Calchaqui y Bombero Galarza | D6: ='RESUMEN TOTAL'!E9 -> Domo | E6: ='RESUMEN TOTAL'!F9 -> PTO A FO | F6: ='RESUMEN TOTAL'!L9 -> 0 | G6: ='RESUMEN TOTAL'!M9 -> 0 | H6: ='RESUMEN TOTAL'!N9 -> 0 | I6: ='RESUMEN TOTAL'!O9 -> 0 | J6: ='RESUMEN TOTAL'!P9 -> 0 | K6: ='RESUMEN TOTAL'!Q9 -> 0 | L6: ='RESUMEN TOTAL'!R9 -> 0 | M6: ='RESUMEN TOTAL'!S9 -> 0 | ... AI6: ='RESUMEN TOTAL'!AO9 -> 0
A7: ='RESUMEN TOTAL'!A10 -> ALTAMIRA | B7: ='RESUMEN TOTAL'!B10 -> ALT 06 | C7: ='RESUMEN TOTAL'!D10 -> LOPE DE VEGA Y NECOCHEA | D7: ='RESUMEN TOTAL'!E10 -> Domo | E7: ='RESUMEN TOTAL'!F10 -> PTO A FO | F7: ='RESUMEN TOTAL'!L10 -> 0 | G7: ='RESUMEN TOTAL'!M10 -> 0 | H7: ='RESUMEN TOTAL'!N10 -> 0 | I7: ='RESUMEN TOTAL'!O10 -> 0 | J7: ='RESUMEN TOTAL'!P10 -> 0 | K7: ='RESUMEN TOTAL'!Q10 -> 0 | L7: ='RESUMEN TOTAL'!R10 -> 0 | M7: ='RESUMEN TOTAL'!S10 -> 0 | ... AI7: ='RESUMEN TOTAL'!AO10 -> 0
A8: ='RESUMEN TOTAL'!A11 -> ALTAMIRA | B8: ='RESUMEN TOTAL'!B11 -> ALT07 | C8: ='RESUMEN TOTAL'!D11 -> AV. CALCHAQUI Y AV. DEL TRABAJO | D8: ='RESUMEN TOTAL'!E11 -> DOMO | E8: ='RESUMEN TOTAL'!F11 -> PTO A FO | F8: ='RESUMEN TOTAL'!L11 -> 0 | G8: ='RESUMEN TOTAL'!M11 -> 0 | H8: ='RESUMEN TOTAL'!N11 -> 0 | I8: ='RESUMEN TOTAL'!O11 -> 0 | J8: ='RESUMEN TOTAL'!P11 -> 0 | K8: ='RESUMEN TOTAL'!Q11 -> 0 | L8: ='RESUMEN TOTAL'!R11 -> 0 | M8: ='RESUMEN TOTAL'!S11 -> 0 | ... AI8: ='RESUMEN TOTAL'!AO11 -> 0
A9: ='RESUMEN TOTAL'!A12 -> ALTAMIRA | B9: ='RESUMEN TOTAL'!B12 -> ALT 08 | C9: ='RESUMEN TOTAL'!D12 -> HUMAITA Y NECOCHEA | D9: ='RESUMEN TOTAL'!E12 -> DOMO | E9: ='RESUMEN TOTAL'!F12 -> Fibra Optica | F9: ='RESUMEN TOTAL'!L12 -> 0 | G9: ='RESUMEN TOTAL'!M12 -> 0 | H9: ='RESUMEN TOTAL'!N12 -> 0 | I9: ='RESUMEN TOTAL'!O12 -> 0 | J9: ='RESUMEN TOTAL'!P12 -> 0 | K9: ='RESUMEN TOTAL'!Q12 -> 0 | L9: ='RESUMEN TOTAL'!R12 -> 0 | M9: ='RESUMEN TOTAL'!S12 -> 0 | ... AI9: ='RESUMEN TOTAL'!AO12 -> 0
A10: ='RESUMEN TOTAL'!A13 -> ALTAMIRA | B10: ='RESUMEN TOTAL'!B13 -> ALT 09 | C10: ='RESUMEN TOTAL'!D13 -> NECOCHEA Y CURUPAITY | D10: ='RESUMEN TOTAL'!E13 -> DOMO | E10: ='RESUMEN TOTAL'!F13 -> Fibra Optica | F10: ='RESUMEN TOTAL'!L13 -> 0 | G10: ='RESUMEN TOTAL'!M13 -> 0 | H10: ='RESUMEN TOTAL'!N13 -> 0 | I10: ='RESUMEN TOTAL'!O13 -> 0 | J10: ='RESUMEN TOTAL'!P13 -> 0 | K10: ='RESUMEN TOTAL'!Q13 -> 0 | L10: ='RESUMEN TOTAL'!R13 -> 0 | M10: ='RESUMEN TOTAL'!S13 -> 0 | ... AI10: ='RESUMEN TOTAL'!AO13 -> 0
A11: ='RESUMEN TOTAL'!A14 -> ALTAMIRA | B11: ='RESUMEN TOTAL'!B14 -> ALT 10 | C11: ='RESUMEN TOTAL'!D14 -> Calchaqui y Francia | D11: ='RESUMEN TOTAL'!E14 -> Domo | E11: ='RESUMEN TOTAL'!F14 -> Radio | F11: ='RESUMEN TOTAL'!L14 -> 0 | G11: ='RESUMEN TOTAL'!M14 -> 0 | H11: ='RESUMEN TOTAL'!N14 -> 0 | I11: ='RESUMEN TOTAL'!O14 -> 0 | J11: ='RESUMEN TOTAL'!P14 -> 0 | K11: ='RESUMEN TOTAL'!Q14 -> 0 | L11: ='RESUMEN TOTAL'!R14 -> 0 | M11: ='RESUMEN TOTAL'!S14 -> 0 | ... AI11: ='RESUMEN TOTAL'!AO14 -> 0
A12: ='RESUMEN TOTAL'!A15 -> AGUSTIN RAMIREZ | B12: ='RESUMEN TOTAL'!B15 -> ARA 01 | C12: ='RESUMEN TOTAL'!D15 -> Malambo y Tranquera | D12: ='RESUMEN TOTAL'!E15 -> Domo | E12: ='RESUMEN TOTAL'!F15 -> Fibra Optica | F12: ='RESUMEN TOTAL'!L15 -> 0 | G12: ='RESUMEN TOTAL'!M15 -> 0 | H12: ='RESUMEN TOTAL'!N15 -> 0 | I12: ='RESUMEN TOTAL'!O15 -> 0 | J12: ='RESUMEN TOTAL'!P15 -> 0 | K12: ='RESUMEN TOTAL'!Q15 -> 0 | L12: ='RESUMEN TOTAL'!R15 -> 0 | M12: ='RESUMEN TOTAL'!S15 -> 0 | ... AI12: ='RESUMEN TOTAL'!AO15 -> 0
A13: ='RESUMEN TOTAL'!A16 -> BELGRANO | B13: ='RESUMEN TOTAL'!B16 -> BEL 01 | C13: ='RESUMEN TOTAL'!D16 -> San Martin y Dardo Rocha | D13: ='RESUMEN TOTAL'!E16 -> DOMO | E13: ='RESUMEN TOTAL'!F16 -> Fibra Optica | F13: ='RESUMEN TOTAL'!L16 -> 0 | G13: ='RESUMEN TOTAL'!M16 -> 0 | H13: ='RESUMEN TOTAL'!N16 -> 0 | I13: ='RESUMEN TOTAL'!O16 -> 0 | J13: ='RESUMEN TOTAL'!P16 -> 0 | K13: ='RESUMEN TOTAL'!Q16 -> 0 | L13: ='RESUMEN TOTAL'!R16 -> 0 | M13: ='RESUMEN TOTAL'!S16 -> 0 | ... AI13: ='RESUMEN TOTAL'!AO16 -> 0
A14: ='RESUMEN TOTAL'!A17 -> BELGRANO | B14: ='RESUMEN TOTAL'!B17 -> BEL 02 | C14: ='RESUMEN TOTAL'!D17 -> Guardia vieja y Fronteriz | D14: ='RESUMEN TOTAL'!E17 -> DOMO | E14: ='RESUMEN TOTAL'!F17 -> Fibra Optica | F14: ='RESUMEN TOTAL'!L17 -> 0 | G14: ='RESUMEN TOTAL'!M17 -> 0 | H14: ='RESUMEN TOTAL'!N17 -> 0 | I14: ='RESUMEN TOTAL'!O17 -> 0 | J14: ='RESUMEN TOTAL'!P17 -> 0 | K14: ='RESUMEN TOTAL'!Q17 -> 0 | L14: ='RESUMEN TOTAL'!R17 -> 0 | M14: ='RESUMEN TOTAL'!S17 -> 0 | ... AI14: ='RESUMEN TOTAL'!AO17 -> 0
A15: ='RESUMEN TOTAL'!A18 -> BOSQUES CENTRO | B15: ='RESUMEN TOTAL'!B18 -> BOSQC 01 | C15: ='RESUMEN TOTAL'!D18 -> LUIS AGOTE E/DANUNCIO Y CAMPOAMOR | D15: ='RESUMEN TOTAL'!E18 -> Fija | E15: ='RESUMEN TOTAL'!F18 -> Radio | F15: ='RESUMEN TOTAL'!L18 -> 0 | G15: ='RESUMEN TOTAL'!M18 -> 0 | H15: ='RESUMEN TOTAL'!N18 -> 0 | I15: ='RESUMEN TOTAL'!O18 -> 0 | J15: ='RESUMEN TOTAL'!P18 -> 0 | K15: ='RESUMEN TOTAL'!Q18 -> 0 | L15: ='RESUMEN TOTAL'!R18 -> 0 | M15: ='RESUMEN TOTAL'!S18 -> APAGADO | ... AI15: ='RESUMEN TOTAL'!AO18 -> 0
... A67: ='RESUMEN TOTAL'!A70 -> CENTRO | B67: ='RESUMEN TOTAL'!B70 -> CEN47 | C67: ='RESUMEN TOTAL'!D70 -> Sallares y Brown | D67: ='RESUMEN TOTAL'!E70 -> Domo | E67: ='RESUMEN TOTAL'!F70 -> Fibra Optica | F67: ='RESUMEN TOTAL'!L70 -> 0 | G67: ='RESUMEN TOTAL'!M70 -> 0 | H67: ='RESUMEN TOTAL'!N70 -> 0 | I67: ='RESUMEN TOTAL'!O70 -> 0 | J67: ='RESUMEN TOTAL'!P70 -> 0 | K67: ='RESUMEN TOTAL'!Q70 -> 0 | L67: ='RESUMEN TOTAL'!R70 -> 0 | M67: ='RESUMEN TOTAL'!S70 -> 0 | ... AI67: ='RESUMEN TOTAL'!AO70 -> 0
A68: ='RESUMEN TOTAL'!A71 -> CENTRO | B68: ='RESUMEN TOTAL'!B71 -> CEN48 | C68: ='RESUMEN TOTAL'!D71 -> Velez Sarsfield y Las Heras | D68: ='RESUMEN TOTAL'!E71 -> Domo | E68: ='RESUMEN TOTAL'!F71 -> Radio | F68: ='RESUMEN TOTAL'!L71 -> 0 | G68: ='RESUMEN TOTAL'!M71 -> 0 | H68: ='RESUMEN TOTAL'!N71 -> 0 | I68: ='RESUMEN TOTAL'!O71 -> 0 | J68: ='RESUMEN TOTAL'!P71 -> 0 | K68: ='RESUMEN TOTAL'!Q71 -> 0 | L68: ='RESUMEN TOTAL'!R71 -> 0 | M68: ='RESUMEN TOTAL'!S71 -> 0 | ... Z68: ='RESUMEN TOTAL'!AF71 -> 0 | AA68: ='RESUMEN TOTAL'!AG550 -> 0 | AB68: ='RESUMEN TOTAL'!AH71 -> 0 | AC68: ='RESUMEN TOTAL'!AI71 -> 0 | AD68: ='RESUMEN TOTAL'!AJ71 -> 0 | AE68: ='RESUMEN TOTAL'!AK71 -> 0 | AF68: ='RESUMEN TOTAL'!AL71 -> 0 | AG68: ='RESUMEN TOTAL'!AM71 -> 0 | AH68: ='RESUMEN TOTAL'!AN71 -> 0 | AI68: ='RESUMEN TOTAL'!AO71 -> 0
A69: ='RESUMEN TOTAL'!A72 -> CENTRO | B69: ='RESUMEN TOTAL'!B72 -> CEN49 | C69: ='RESUMEN TOTAL'!D72 -> Av. San Martin y Florencio Sanchez | D69: ='RESUMEN TOTAL'!E72 -> Domo | E69: ='RESUMEN TOTAL'!F72 -> Radio | F69: ='RESUMEN TOTAL'!L72 -> 0 | G69: ='RESUMEN TOTAL'!M72 -> 0 | H69: ='RESUMEN TOTAL'!N72 -> 0 | I69: ='RESUMEN TOTAL'!O72 -> 0 | J69: ='RESUMEN TOTAL'!P72 -> 0 | K69: ='RESUMEN TOTAL'!Q72 -> 0 | L69: ='RESUMEN TOTAL'!R72 -> 0 | M69: ='RESUMEN TOTAL'!S72 -> 0 | ... AI69: ='RESUMEN TOTAL'!AO72 -> 0
A70: ='RESUMEN TOTAL'!A73 -> CENTRO | B70: ='RESUMEN TOTAL'!B73 -> CEN 50 | C70: ='RESUMEN TOTAL'!D73 -> Av. San Martin y Newbery | D70: ='RESUMEN TOTAL'!E73 -> Domo | E70: ='RESUMEN TOTAL'!F73 -> Radio | F70: ='RESUMEN TOTAL'!L73 -> 0 | G70: ='RESUMEN TOTAL'!M73 -> 0 | H70: ='RESUMEN TOTAL'!N73 -> 0 | I70: ='RESUMEN TOTAL'!O73 -> 0 | J70: ='RESUMEN TOTAL'!P73 -> 0 | K70: ='RESUMEN TOTAL'!Q73 -> 0 | L70: ='RESUMEN TOTAL'!R73 -> 0 | M70: ='RESUMEN TOTAL'!S73 -> 0 | ... AI70: ='RESUMEN TOTAL'!AO73 -> 0
A71: ='RESUMEN TOTAL'!A74 -> CENTRO | B71: ='RESUMEN TOTAL'!B74 -> CEN 51 | C71: ='RESUMEN TOTAL'!D74 -> ILLIA Y LAS HERAS | D71: ='RESUMEN TOTAL'!E74 -> FIJA | E71: ='RESUMEN TOTAL'!F74 -> Fibra Optica | F71: ='RESUMEN TOTAL'!L74 -> 0 | G71: ='RESUMEN TOTAL'!M74 -> 0 | H71: ='RESUMEN TOTAL'!N74 -> 0 | I71: ='RESUMEN TOTAL'!O74 -> 0 | J71: ='RESUMEN TOTAL'!P74 -> 0 | K71: ='RESUMEN TOTAL'!Q74 -> 0 | L71: ='RESUMEN TOTAL'!R74 -> 0 | M71: ='RESUMEN TOTAL'!S74 -> 0 | ... AI71: ='RESUMEN TOTAL'!AO74 -> 0
A72: ='RESUMEN TOTAL'!A75 -> CENTRO | B72: ='RESUMEN TOTAL'!B75 -> CEN52 | C72: ='RESUMEN TOTAL'!D75 -> San Martin y Almafuerte (ex San Martin y Dorrego) | D72: ='RESUMEN TOTAL'!E75 -> DOMO | E72: ='RESUMEN TOTAL'!F75 -> Radio | F72: ='RESUMEN TOTAL'!L75 -> 0 | G72: ='RESUMEN TOTAL'!M75 -> 0 | H72: ='RESUMEN TOTAL'!N75 -> 0 | I72: ='RESUMEN TOTAL'!O75 -> 0 | J72: ='RESUMEN TOTAL'!P75 -> 0 | K72: ='RESUMEN TOTAL'!Q75 -> 0 | L72: ='RESUMEN TOTAL'!R75 -> 0 | M72: ='RESUMEN TOTAL'!S75 -> 0 | ... AI72: ='RESUMEN TOTAL'!AO75 -> 0
