Workbook
Name _25_de_agosto: 'RESUMEN TOTAL'!$A$4:$D$363
Name _25_de_agosto_3: 'RESUMEN TOTAL'!$A$4:$D$375
Name BONOMOcam: Hoja1!$B$2
Name CANTIDAD_DE_CAMARAS: 'RESUMEN TOTAL'!$B$1
Name COSEIDIcam: Hoja1!$B$4

Sheet RESUMEN TOTAL
A1: CANTIDAD DE CAMARAS | B1: =COUNTA(B5:B530) -> 430 | D1: PORCIENTO DE CAIDAS | K1: =(K3)/(K2+K3) -> 0.095348837 | L1: =(L3)/(L2+L3) -> 0.074418605 | M1: =(M3)/(M2+M3) -> 0.08372093 | N1: =(N3)/(N2+N3) -> 0.088372093 | O1: =(O3)/(O2+O3) -> 0.088372093 | P1: =(P3)/(P2+P3) -> 0.090697674 | Q1: =(Q3)/(Q2+Q3) -> 0.086046512 | R1: =(R3)/(R2+R3) -> 0.08372093 | ... AN1: =(AN3)/(AN2+AN3) -> 0
D2: FUNCIONAN | K2: =B1-K3 -> 389 | L2: =CANTIDAD_DE_CAMARAS-L3 -> 398 | M2: =CANTIDAD_DE_CAMARAS-M3 -> 394 | N2: =CANTIDAD_DE_CAMARAS-N3 -> 392 | O2: =CANTIDAD_DE_CAMARAS-O3 -> 392 | P2: =CANTIDAD_DE_CAMARAS-P3 -> 391 | Q2: =CANTIDAD_DE_CAMARAS-Q3 -> 393 | R2: =CANTIDAD_DE_CAMARAS-R3 -> 394 | S2: =CANTIDAD_DE_CAMARAS-S3 -> 394 | ... AN2: =CANTIDAD_DE_CAMARAS-AN3 -> 430
D3: CAIDAS | K3: =COUNTIF(K4:K450, "apagado") -> 41 | L3: =COUNTIF(L4:L450, "apagado") -> 32 | M3: =COUNTIF(M4:M450, "apagado") -> 36 | N3: =COUNTIF(N4:N450, "apagado") -> 38 | O3: =COUNTIF(O4:O450, "apagado") -> 38 | P3: =COUNTIF(P4:P450, "apagado") -> 39 | Q3: =COUNTIF(Q4:Q450, "apagado") -> 37 | R3: =COUNTIF(R4:R450, "apagado") -> 36 | ... AN3: =COUNTIF(AN4:AN450, "apagado") -> 0
A4: Barrio | B4: [Denominacion] | C4: [Empresa Mantenimiento] | D4: [Ubicacion] | E4: [Tipo de Camara] | F4: [Tipo de Conexion] | H4: DIAS FUNCIONANDO | I4: DIAS CAIDA | J4: EFECTIVIDAD | K4: 44866 | L4: 44867 | M4: 44868 | N4: 44869 | O4: 44870 | P4: 44871 | Q4: 44872 | R4: 44873 | S4: 44874 | T4: 44875 | U4: 44876 | V4: 44877 | W4: 44878 | X4: 44879 | Y4: 44880 | Z4: 44881 | AA4: 44882 | AB4: 44883 | AC4: 44884 | AD4: 44885 | AE4: 44886 | AF4: 44887 | AG4: 44888 | AH4: 44889 | AI4: 44890 | AJ4: 44891 | AK4: 44892 | AL4: 44893 | AM4: 44894 | AN4: 44895
A5: ALTAMIRA | B5: ALT01 | C5: BONOMO | D5: Calchaqui y Sgto. Cabral | E5: Domo | F5: Fibra Optica | G5: 172.20.10.6 | H5: =COUNTIF(K5:AN5,"") -> 30 | I5: =COUNTIF(K5:AL5,"APAGADO") -> 0 | J5: =(H5)/(I5+H5) -> 1
A6: ALTAMIRA | B6: ALT02 | C6: BONOMO | D6: Calchaqui y Lope de Vega | E6: Domo | F6: PTO A FO | G6: 172.20.12.218 | H6: =COUNTIF(K6:AN6,"") -> 30 | I6: =COUNTIF(K6:AL6,"APAGADO") -> 0 | J6: =(H6)/(I6+H6) -> 1
A7: ALTAMIRA | B7: ALT 03 | C7: BONOMO | D7: Bombero Galarza y Necochea | E7: Domo | F7: FIBRA OPTICA | G7: 172.20.12.54 | H7: =COUNTIF(K7:AN7,"") -> 30 | I7: =COUNTIF(K7:AL7,"APAGADO") -> 0 | J7: =(H7)/(I7+H7) -> 1
A8: ALTAMIRA | B8: ALT 04 | C8: BONOMO | D8: Francia y Necochea | E8: Domo | F8: FIBRA OPTICA | G8: 172.20.12.55 | H8: =COUNTIF(K8:AN8,"") -> 29 | I8: =COUNTIF(K8:AL8,"APAGADO") -> 1 | J8: =(H8)/(I8+H8) -> 0.96666667 | N8: APAGADO
A9: ALTAMIRA | B9: ALT05 | C9: BONOMO | D9: Av. Calchaqui y Bombero Galarza | E9: Domo | F9: PTO A FO | G9: 172.20.12.216 | H9: =COUNTIF(K9:AN9,"") -> 30 | I9: =COUNTIF(K9:AL9,"APAGADO") -> 0 | J9: =(H9)/(I9+H9) -> 1
A10: ALTAMIRA | B10: ALT 06 | C10: BONOMO | D10: LOPE DE VEGA Y NECOCHEA | E10: Domo | F10: PTO A FO | G10: 172.20.12.12 | H10: =COUNTIF(K10:AN10,"") -> 30 | I10: =COUNTIF(K10:AL10,"APAGADO") -> 0 | J10: =(H10)/(I10+H10) -> 1
A11: ALTAMIRA | B11: ALT07 | C11: BONOMO | D11: AV. CALCHAQUI Y AV. DEL TRABAJO | E11: DOMO | F11: PTO A FO | G11: 172.20.10.57 | H11: =COUNTIF(K11:AN11,"") -> 30 | I11: =COUNTIF(K11:AL11,"APAGADO") -> 0 | J11: =(H11)/(I11+H11) -> 1
A12: ALTAMIRA | B12: ALT 08 | C12: BONOMO | D12: HUMAITA Y NECOCHEA | E12: DOMO | F12: Fibra Optica | G12: 172.20.11.215 | H12: =COUNTIF(K12:AN12,"") -> 30 | I12: =COUNTIF(K12:AL12,"APAGADO") -> 0 | J12: =(H12)/(I12+H12) -> 1
A13: ALTAMIRA | B13: ALT 09 | C13: BONOMO | D13: NECOCHEA Y CURUPAITY | E13: DOMO | F13: Fibra Optica | G13: 172.20.11.216 | H13: =COUNTIF(K13:AN13,"") -> 30 | I13: =COUNTIF(K13:AL13,"APAGADO") -> 0 | J13: =(H13)/(I13+H13) -> 1
A14: ALTAMIRA | B14: ALT 10 | C14: BONOMO | D14: Calchaqui y Francia | E14: Domo | F14: Radio | H14: =COUNTIF(K14:AN14,"") -> 30 | I14: =COUNTIF(K14:AL14,"APAGADO") -> 0 | J14: =(H14)/(I14+H14) -> 1
A15: AGUSTIN RAMIREZ | B15: ARA 01 | C15: COSEIDI | D15: Malambo y Tranquera | E15: Domo | F15: FIBRA OPTICA | G15: 172.20.12.110 | H15: =COUNTIF(K15:AN15,"") -> 29 | I15: =COUNTIF(K15:AL15,"APAGADO") -> 1 | J15: =(H15)/(I15+H15) -> 0.96666667 | S15: APAGADO
A16: BELGRANO | B16: BEL 01 | C16: BONOMO | D16: San Martin y Dardo Rocha | E16: DOMO | F16: FIBRA OPTICA | G16: 172.20.12.64 | H16: =COUNTIF(K16:AN16,"") -> 3 | I16: =COUNTIF(K16:AL16,"APAGADO") -> 26 | J16: =(H16)/(I16+H16) -> 0.10344828 | K16: APAGADO | L16: APAGADO | M16: APAGADO | O16: APAGADO | P16: APAGADO | Q16: APAGADO | R16: APAGADO | S16: APAGADO | T16: APAGADO | U16: APAGADO | V16: APAGADO | W16: APAGADO | X16: APAGADO | Y16: APAGADO | AA16: APAGADO | AB16: APAGADO | AC16: APAGADO | AD16: APAGADO | AE16: APAGADO | AF16: APAGADO | AG16: APAGADO | AH16: APAGADO | AI16: APAGADO | AJ16: APAGADO | AK16: APAGADO | AL16: APAGADO | AM16: APAGADO
A17: BOSQUES CENTRO | B17: BOSQC 01 | C17: COSEIDI | D17: LUIS AGOTE E/DANUNCIO Y CAMPOAMOR | E17: Fija | F17: Radio | G17: 172.20.11.15 | H17: =COUNTIF(K17:AN17,"") -> 26 | I17: =COUNTIF(K17:AL17,"APAGADO") -> 4 | J17: =(H17)/(I17+H17) -> 0.86666667 | T17: APAGADO | U17: APAGADO | W17: APAGADO | AC17: APAGADO
A18: BOSQUES CENTRO | B18: BOSQC 02 | C18: COSEIDI | D18: LUIS AGOTE E/DANUNCIO Y CAMPOAMOR | E18: Fija | F18: Radio | G18: 172.20.11.16 | H18: =COUNTIF(K18:AN18,"") -> 26 | I18: =COUNTIF(K18:AL18,"APAGADO") -> 4 | J18: =(H18)/(I18+H18) -> 0.86666667 | T18: APAGADO | U18: APAGADO | W18: APAGADO | AC18: APAGADO
A19: BOSQUES CENTRO | B19: BOSQC 03 | C19: COSEIDI | D19: BENAVENTE Y LUIS AGOTE | E19: Fija | F19: Radio | G19: 172.20.11.13 | H19: =COUNTIF(K19:AN19,"") -> 26 | I19: =COUNTIF(K19:AL19,"APAGADO") -> 4 | J19: =(H19)/(I19+H19) -> 0.86666667 | U19: APAGADO | W19: APAGADO | AA19: APAGADO | AC19: APAGADO
A20: BOSQUES CENTRO | B20: BOSQC 04 | C20: COSEIDI | D20: BENAVENTE Y LUIS AGOTE | E20: Fija | F20: Radio | G20: 172.20.11.113 | H20: =COUNTIF(K20:AN20,"") -> 28 | I20: =COUNTIF(K20:AL20,"APAGADO") -> 2 | J20: =(H20)/(I20+H20) -> 0.93333333 | AA20: APAGADO | AC20: APAGADO
A21: BOSQUES CENTRO | B21: BOSQC 05 | C21: COSEIDI | D21: LUIS AGOTE Y RUTA 36 | E21: Fija | F21: Radio | G21: 172.20.11.17 | H21: =COUNTIF(K21:AN21,"") -> 29 | I21: =COUNTIF(K21:AL21,"APAGADO") -> 1 | J21: =(H21)/(I21+H21) -> 0.96666667 | AC21: APAGADO
A22: BOSQUES CENTRO | B22: BOSQC 06 | C22: COSEIDI | D22: LUIS AGOTE Y RUTA 36 | E22: Fija | F22: Radio | G22: 172.20.11.18 | H22: =COUNTIF(K22:AN22,"") -> 29 | I22: =COUNTIF(K22:AL22,"APAGADO") -> 1 | J22: =(H22)/(I22+H22) -> 0.96666667 | AC22: APAGADO
A23: CENTRO | B23: CEN01 | C23: BONOMO | D23: San Martin y 9 de Julio | E23: Fija | F23: Fibra Optica | G23: 172.20.11.10 | H23: =COUNTIF(K23:AN23,"") -> 30 | I23: =COUNTIF(K23:AL23,"APAGADO") -> 0 | J23: =(H23)/(I23+H23) -> 1
A24: CENTRO | B24: CEN02 | C24: BONOMO | D24: San Martin y Almafuerte | E24: Fija | F24: Fibra Optica | G24: 172.20.11.11 | H24: =COUNTIF(K24:AN24,"") -> 30 | I24: =COUNTIF(K24:AL24,"APAGADO") -> 0 | J24: =(H24)/(I24+H24) -> 1
A25: CENTRO | B25: CEN03 | C25: BONOMO | D25: San Martin y Sallares | E25: Domo | F25: Fibra Optica | G25: 172.20.12.30 | H25: =COUNTIF(K25:AN25,"") -> 30 | I25: =COUNTIF(K25:AL25,"APAGADO") -> 0 | J25: =(H25)/(I25+H25) -> 1
A26: CENTRO | B26: CEN04 | C26: BONOMO | D26: San Martin y Contreras | E26: Domo | F26: Fibra Optica | G26: 172.20.12.29 | H26: =COUNTIF(K26:AN26,"") -> 30 | I26: =COUNTIF(K26:AL26,"APAGADO") -> 0 | J26: =(H26)/(I26+H26) -> 1
A27: CENTRO | B27: CEN 05 | C27: BONOMO | D27: Bocuzzi e/España y San Martin | E27: DOMO | F27: Fibra Optica | G27: 172.20.10.200 | H27: =COUNTIF(K27:AN27,"") -> 23 | I27: =COUNTIF(K27:AL27,"APAGADO") -> 6 | J27: =(H27)/(I27+H27) -> 0.79310345 | AG27: APAGADO | AH27: APAGADO | AI27: APAGADO | AJ27: APAGADO | AK27: APAGADO | AL27: APAGADO | AM27: APAGADO
A28: CENTRO | B28: CEN06 | C28: BONOMO | D28: Monteagudo y A.del Valle | E28: Fija | F28: Fibra Optica | G28: 172.20.10.02 | H28: =COUNTIF(K28:AN28,"") -> 30 | I28: =COUNTIF(K28:AL28,"APAGADO") -> 0 | J28: =(H28)/(I28+H28) -> 1
A29: CENTRO | B29: CEN07 | C29: BONOMO | D29: San Martin y Guemes | E29: DOMO | F29: Fibra Optica | G29: 172.20.11.20 | H29: =COUNTIF(K29:AN29,"") -> 30 | I29: =COUNTIF(K29:AL29,"APAGADO") -> 0 | J29: =(H29)/(I29+H29) -> 1
A30: CENTRO | B30: CEN08 | C30: BONOMO | D30: San Martin y Pte.Peron | E30: Domo | F30: Fibra Optica | G30: 172.20.11.21 | H30: =COUNTIF(K30:AN30,"") -> 30 | I30: =COUNTIF(K30:AL30,"APAGADO") -> 0 | J30: =(H30)/(I30+H30) -> 1
A31: CENTRO | B31: CEN09 | C31: BONOMO | D31: Chacabuco y 25 de Mayo | E31: Domo | F31: Fibra Optica | G31: 172.20.11.22 | H31: =COUNTIF(K31:AN31,"") -> 30 | I31: =COUNTIF(K31:AL31,"APAGADO") -> 0 | J31: =(H31)/(I31+H31) -> 1
A32: CENTRO | B32: CEN10 | C32: BONOMO | D32: Monteagudo y Pte. Peron | E32: Domo | F32: Fibra Optica | G32: 172.20.11.23 | H32: =COUNTIF(K32:AN32,"") -> 30 | I32: =COUNTIF(K32:AL32,"APAGADO") -> 0 | J32: =(H32)/(I32+H32) -> 1
A33: CENTRO | B33: CEN11 | C33: BONOMO | D33: Monteagudo y Bocuzzi | E33: Domo | F33: Fibra Optica | G33: 172.20.10.24 | H33: =COUNTIF(K33:AN33,"") -> 30 | I33: =COUNTIF(K33:AL33,"APAGADO") -> 0 | J33: =(H33)/(I33+H33) -> 1
A34: CENTRO | B34: CEN 12 | C34: BONOMO | D34: Monteagudo y Mitre | E34: Domo | F34: Fibra Optica | G34: 172.20.10.23 | H34: =COUNTIF(K34:AN34,"") -> 2 | I34: =COUNTIF(K34:AL34,"APAGADO") -> 27 | J34: =(H34)/(I34+H34) -> 0.068965517 | K34: APAGADO | L34: APAGADO | M34: APAGADO | N34: APAGADO | O34: APAGADO | P34: APAGADO | Q34: APAGADO | R34: APAGADO | S34: APAGADO | T34: APAGADO | U34: APAGADO | V34: APAGADO | W34: APAGADO | X34: APAGADO | Y34: APAGADO | Z34: APAGADO | AA34: APAGADO | AB34: APAGADO | AD34: APAGADO | AE34: APAGADO | AF34: APAGADO | AG34: APAGADO | AH34: APAGADO | AI34: APAGADO | AJ34: APAGADO | AK34: APAGADO | AL34: APAGADO | AM34: APAGADO
A35: CENTRO | B35: CEN 13 | C35: BONOMO | D35: 25 de Mayo y Maipu | E35: DOMO | F35: Fibra Optica | G35: 172.20.10.20 | H35: =COUNTIF(K35:AN35,"") -> 29 | I35: =COUNTIF(K35:AL35,"APAGADO") -> 1 | J35: =(H35)/(I35+H35) -> 0.96666667 | AG35: APAGADO
A36: CENTRO | B36: CEN14 | C36: BONOMO | D36: Pte.Peron e/Pringles y Brown | E36: Domo | F36: Fibra Optica | G36: 172.20.10.21 | H36: =COUNTIF(K36:AN36,"") -> 30 | I36: =COUNTIF(K36:AL36,"APAGADO") -> 0 | J36: =(H36)/(I36+H36) -> 1
A37: CENTRO | B37: CEN15 | C37: BONOMO | D37: Alberdi y A.del Valle | E37: Domo | F37: Fibra Optica | G37: 172.20.10.35 | H37: =COUNTIF(K37:AN37,"") -> 25 | I37: =COUNTIF(K37:AL37,"APAGADO") -> 5 | J37: =(H37)/(I37+H37) -> 0.83333333 | K37: APAGADO | Z37: APAGADO | AD37: APAGADO | AF37: APAGADO | AG37: APAGADO
A38: CENTRO | B38: CEN16 | C38: BONOMO | D38: San Martin y Pte. Peron | E38: Fija | F38: Fibra Optica | G38: 172.20.12.36 | H38: =COUNTIF(K38:AN38,"") -> 21 | I38: =COUNTIF(K38:AL38,"APAGADO") -> 9 | J38: =(H38)/(I38+H38) -> 0.7 | M38: APAGADO | N38: APAGADO | O38: APAGADO | P38: APAGADO | Q38: APAGADO | R38: APAGADO | T38: APAGADO | U38: APAGADO | AE38: APAGADO
A39: CENTRO | B39: CEN17 | C39: BONOMO | D39: San Martin y Mitre | E39: Domo | F39: PTO A FO | G39: 172.20.12.200 | H39: =COUNTIF(K39:AN39,"") -> 30 | I39: =COUNTIF(K39:AL39,"APAGADO") -> 0 | J39: =(H39)/(I39+H39) -> 1
A40: CENTRO | B40: CEN18 | C40: BONOMO | D40: Monteagudo e/Mitre y Sallares | E40: Fija | F40: Fibra Optica | G40: 172.20.10.26 | H40: =COUNTIF(K40:AN40,"") -> 1 | I40: =COUNTIF(K40:AL40,"APAGADO") -> 28 | J40: =(H40)/(I40+H40) -> 0.034482759 | K40: APAGADO | L40: APAGADO | M40: APAGADO | N40: APAGADO | O40: APAGADO | P40: APAGADO | Q40: APAGADO | R40: APAGADO | S40: APAGADO | T40: APAGADO | U40: APAGADO | V40: APAGADO | W40: APAGADO | X40: APAGADO | Y40: APAGADO | Z40: APAGADO | AA40: APAGADO | AB40: APAGADO | AC40: APAGADO | AD40: APAGADO | AE40: APAGADO | AF40: APAGADO | AG40: APAGADO | AH40: APAGADO | AI40: APAGADO | AJ40: APAGADO | AK40: APAGADO | AL40: APAGADO | AM40: APAGADO
...

Sheet ESTADISTICA
A1: ='RESUMEN TOTAL'!A4 -> Barrio | B1: ='RESUMEN TOTAL'!B4 -> [Denominacion] | C1: ='RESUMEN TOTAL'!D4 -> [Ubicacion] | D1: ='RESUMEN TOTAL'!E4 -> [Tipo de Camara] | E1: ='RESUMEN TOTAL'!F4 -> [Tipo de Conexion] | F1: ='RESUMEN TOTAL'!K4 -> 44866 | G1: ='RESUMEN TOTAL'!L4 -> 44867 | H1: ='RESUMEN TOTAL'!M4 -> 44868 | I1: ='RESUMEN TOTAL'!N4 -> 44869 | J1: ='RESUMEN TOTAL'!O4 -> 44870 | K1: ='RESUMEN TOTAL'!P4 -> 44871 | L1: ='RESUMEN TOTAL'!Q4 -> 44872 | M1: ='RESUMEN TOTAL'!R4 -> 44873 | ... AI1: ='RESUMEN TOTAL'!AN4 -> 44895
A2: ='RESUMEN TOTAL'!A5 -> ALTAMIRA | B2: ='RESUMEN TOTAL'!B5 -> ALT01 | C2: ='RESUMEN TOTAL'!D5 -> Calchaqui y Sgto. Cabral | D2: ='RESUMEN TOTAL'!E5 -> Domo | E2: ='RESUMEN TOTAL'!F5 -> Fibra Optica | F2: ='RESUMEN TOTAL'!K5 -> 0 | G2: ='RESUMEN TOTAL'!L5 -> 0 | H2: ='RESUMEN TOTAL'!M5 -> 0 | I2: ='RESUMEN TOTAL'!N5 -> 0 | J2: ='RESUMEN TOTAL'!O5 -> 0 | K2: ='RESUMEN TOTAL'!P5 -> 0 | L2: ='RESUMEN TOTAL'!Q5 -> 0 | M2: ='RESUMEN TOTAL'!R5 -> 0 | ... AI2: ='RESUMEN TOTAL'!AN5 -> 0
A3: ='RESUMEN TOTAL'!A6 -> ALTAMIRA | B3: ='RESUMEN TOTAL'!B6 -> ALT02 | C3: ='RESUMEN TOTAL'!D6 -> Calchaqui y Lope de Vega | D3: ='RESUMEN TOTAL'!E6 -> Domo | E3: ='RESUMEN TOTAL'!F6 -> PTO A FO | F3: ='RESUMEN TOTAL'!K6 -> 0 | G3: ='RESUMEN TOTAL'!L6 -> 0 | H3: ='RESUMEN TOTAL'!M6 -> 0 | I3: ='RESUMEN TOTAL'!N6 -> 0 | J3: ='RESUMEN TOTAL'!O6 -> 0 | K3: ='RESUMEN TOTAL'!P6 -> 0 | L3: ='RESUMEN TOTAL'!Q6 -> 0 | M3: ='RESUMEN TOTAL'!R6 -> 0 | ... AI3: ='RESUMEN TOTAL'!AN6 -> 0
A4: ='RESUMEN TOTAL'!A7 -> ALTAMIRA | B4: ='RESUMEN TOTAL'!B7 -> ALT 03 | C4: ='RESUMEN TOTAL'!D7 -> Bombero Galarza y Necochea | D4: ='RESUMEN TOTAL'!E7 -> Domo | E4: ='RESUMEN TOTAL'!F7 -> FIBRA OPTICA | F4: ='RESUMEN TOTAL'!K7 -> 0 | G4: ='RESUMEN TOTAL'!L7 -> 0 | H4: ='RESUMEN TOTAL'!M7 -> 0 | I4: ='RESUMEN TOTAL'!N7 -> 0 | J4: ='RESUMEN TOTAL'!O7 -> 0 | K4: ='RESUMEN TOTAL'!P7 -> 0 | L4: ='RESUMEN TOTAL'!Q7 -> 0 | M4: ='RESUMEN TOTAL'!R7 -> 0 | ... AI4: ='RESUMEN TOTAL'!AN7 -> 0
A5: ='RESUMEN TOTAL'!A8 -> ALTAMIRA | B5: ='RESUMEN TOTAL'!B8 -> ALT 04 | C5: ='RESUMEN TOTAL'!D8 -> Francia y Necochea | D5: ='RESUMEN TOTAL'!E8 -> Domo | E5: ='RESUMEN TOTAL'!F8 -> FIBRA OPTICA | F5: ='RESUMEN TOTAL'!K8 -> 0 | G5: ='RESUMEN TOTAL'!L8 -> 0 | H5: ='RESUMEN TOTAL'!M8 -> 0 | I5: ='RESUMEN TOTAL'!N8 -> APAGADO | J5: ='RESUMEN TOTAL'!O8 -> 0 | K5: ='RESUMEN TOTAL'!P8 -> 0 | L5: ='RESUMEN TOTAL'!Q8 -> 0 | M5: ='RESUMEN TOTAL'!R8 -> 0 | ... AI5: ='RESUMEN TOTAL'!AN8 -> 0
A6: ='RESUMEN TOTAL'!A9 -> ALTAMIRA | B6: ='RESUMEN TOTAL'!B9 -> ALT05 | C6: ='RESUMEN TOTAL'!D9 -> Av. Calchaqui y Bombero Galarza | D6: ='RESUMEN TOTAL'!E9 -> Domo | E6: ='RESUMEN TOTAL'!F9 -> PTO A FO | F6: ='RESUMEN TOTAL'!K9 -> 0 | G6: ='RESUMEN TOTAL'!L9 -> 0 | H6: ='RESUMEN TOTAL'!M9 -> 0 | I6: ='RESUMEN TOTAL'!N9 -> 0 | J6: ='RESUMEN TOTAL'!O9 -> 0 | K6: ='RESUMEN TOTAL'!P9 -> 0 | L6: ='RESUMEN TOTAL'!Q9 -> 0 | M6: ='RESUMEN TOTAL'!R9 -> 0 | ... AI6: ='RESUMEN TOTAL'!AN9 -> 0
A7: ='RESUMEN TOTAL'!A10 -> ALTAMIRA | B7: ='RESUMEN TOTAL'!B10 -> ALT 06 | C7: ='RESUMEN TOTAL'!D10 -> LOPE DE VEGA Y NECOCHEA | D7: ='RESUMEN TOTAL'!E10 -> Domo | E7: ='RESUMEN TOTAL'!F10 -> PTO A FO | F7: ='RESUMEN TOTAL'!K10 -> 0 | G7: ='RESUMEN TOTAL'!L10 -> 0 | H7: ='RESUMEN TOTAL'!M10 -> 0 | I7: ='RESUMEN TOTAL'!N10 -> 0 | J7: ='RESUMEN TOTAL'!O10 -> 0 | K7: ='RESUMEN TOTAL'!P10 -> 0 | L7: ='RESUMEN TOTAL'!Q10 -> 0 | M7: ='RESUMEN TOTAL'!R10 -> 0 | ... AI7: ='RESUMEN TOTAL'!AN10 -> 0
A8: ='RESUMEN TOTAL'!A11 -> ALTAMIRA | B8: ='RESUMEN TOTAL'!B11 -> ALT07 | C8: ='RESUMEN TOTAL'!D11 -> AV. CALCHAQUI Y AV. DEL TRABAJO | D8: ='RESUMEN TOTAL'!E11 -> DOMO | E8: ='RESUMEN TOTAL'!F11 -> PTO A FO | F8: ='RESUMEN TOTAL'!K11 -> 0 | G8: ='RESUMEN TOTAL'!L11 -> 0 | H8: ='RESUMEN TOTAL'!M11 -> 0 | I8: ='RESUMEN TOTAL'!N11 -> 0 | J8: ='RESUMEN TOTAL'!O11 -> 0 | K8: ='RESUMEN TOTAL'!P11 -> 0 | L8: ='RESUMEN TOTAL'!Q11 -> 0 | M8: ='RESUMEN TOTAL'!R11 -> 0 | ... AI8: ='RESUMEN TOTAL'!AN11 -> 0
A9: ='RESUMEN TOTAL'!A12 -> ALTAMIRA | B9: ='RESUMEN TOTAL'!B12 -> ALT 08 | C9: ='RESUMEN TOTAL'!D12 -> HUMAITA Y NECOCHEA | D9: ='RESUMEN TOTAL'!E12 -> DOMO | E9: ='RESUMEN TOTAL'!F12 -> Fibra Optica | F9: ='RESUMEN TOTAL'!K12 -> 0 | G9: ='RESUMEN TOTAL'!L12 -> 0 | H9: ='RESUMEN TOTAL'!M12 -> 0 | I9: ='RESUMEN TOTAL'!N12 -> 0 | J9: ='RESUMEN TOTAL'!O12 -> 0 | K9: ='RESUMEN TOTAL'!P12 -> 0 | L9: ='RESUMEN TOTAL'!Q12 -> 0 | M9: ='RESUMEN TOTAL'!R12 -> 0 | ... AI9: ='RESUMEN TOTAL'!AN12 -> 0
A10: ='RESUMEN TOTAL'!A13 -> ALTAMIRA | B10: ='RESUMEN TOTAL'!B13 -> ALT 09 | C10: ='RESUMEN TOTAL'!D13 -> NECOCHEA Y CURUPAITY | D10: ='RESUMEN TOTAL'!E13 -> DOMO | E10: ='RESUMEN TOTAL'!F13 -> Fibra Optica | F10: ='RESUMEN TOTAL'!K13 -> 0 | G10: ='RESUMEN TOTAL'!L13 -> 0 | H10: ='RESUMEN TOTAL'!M13 -> 0 | I10: ='RESUMEN TOTAL'!N13 -> 0 | J10: ='RESUMEN TOTAL'!O13 -> 0 | K10: ='RESUMEN TOTAL'!P13 -> 0 | L10: ='RESUMEN TOTAL'!Q13 -> 0 | M10: ='RESUMEN TOTAL'!R13 -> 0 | ... AI10: ='RESUMEN TOTAL'!AN13 -> 0
A11: ='RESUMEN TOTAL'!A14 -> ALTAMIRA | B11: ='RESUMEN TOTAL'!B14 -> ALT 10 | C11: ='RESUMEN TOTAL'!D14 -> Calchaqui y Francia | D11: ='RESUMEN TOTAL'!E14 -> Domo | E11: ='RESUMEN TOTAL'!F14 -> Radio | F11: ='RESUMEN TOTAL'!K14 -> 0 | G11: ='RESUMEN TOTAL'!L14 -> 0 | H11: ='RESUMEN TOTAL'!M14 -> 0 | I11: ='RESUMEN TOTAL'!N14 -> 0 | J11: ='RESUMEN TOTAL'!O14 -> 0 | K11: ='RESUMEN TOTAL'!P14 -> 0 | L11: ='RESUMEN TOTAL'!Q14 -> 0 | M11: ='RESUMEN TOTAL'!R14 -> 0 | ... AI11: ='RESUMEN TOTAL'!AN14 -> 0
A12: ='RESUMEN TOTAL'!A15 -> AGUSTIN RAMIREZ | B12: ='RESUMEN TOTAL'!B15 -> ARA 01 | C12: ='RESUMEN TOTAL'!D15 -> Malambo y Tranquera | D12: ='RESUMEN TOTAL'!E15 -> Domo | E12: ='RESUMEN TOTAL'!F15 -> FIBRA OPTICA | F12: ='RESUMEN TOTAL'!K15 -> 0 | G12: ='RESUMEN TOTAL'!L15 -> 0 | H12: ='RESUMEN TOTAL'!M15 -> 0 | I12: ='RESUMEN TOTAL'!N15 -> 0 | J12: ='RESUMEN TOTAL'!O15 -> 0 | K12: ='RESUMEN TOTAL'!P15 -> 0 | L12: ='RESUMEN TOTAL'!Q15 -> 0 | M12: ='RESUMEN TOTAL'!R15 -> 0 | ... AI12: ='RESUMEN TOTAL'!AN15 -> 0
... A19: ='RESUMEN TOTAL'!A22 -> BOSQUES CENTRO | B19: ='RESUMEN TOTAL'!B22 -> BOSQC 06 | C19: ='RESUMEN TOTAL'!D22 -> LUIS AGOTE Y RUTA 36 | D19: ='RESUMEN TOTAL'!E22 -> Fija | E19: ='RESUMEN TOTAL'!F22 -> Radio | F19: ='RESUMEN TOTAL'!K22 -> 0 | G19: ='RESUMEN TOTAL'!L22 -> 0 | H19: ='RESUMEN TOTAL'!M22 -> 0 | I19: ='RESUMEN TOTAL'!N22 -> 0 | J19: ='RESUMEN TOTAL'!O22 -> 0 | K19: ='RESUMEN TOTAL'!P22 -> 0 | L19: ='RESUMEN TOTAL'!Q22 -> 0 | M19: ='RESUMEN TOTAL'!R22 -> 0 | ... AI19: ='RESUMEN TOTAL'!AN22 -> 0
A20: ='RESUMEN TOTAL'!A263 -> RICARDO ROJAS | B20: ='RESUMEN TOTAL'!B263 -> RRJ 12 | C20: ='RESUMEN TOTAL'!D263 -> FADER Y DIAGONAL LOS POETAS | D20: ='RESUMEN TOTAL'!E263 -> Fija | E20: ='RESUMEN TOTAL'!F263 -> Fibra Optica | F20: ='RESUMEN TOTAL'!K263 -> 0 | G20: ='RESUMEN TOTAL'!L263 -> 0 | H20: ='RESUMEN TOTAL'!M263 -> 0 | I20: ='RESUMEN TOTAL'!N263 -> 0 | J20: ='RESUMEN TOTAL'!O263 -> 0 | K20: ='RESUMEN TOTAL'!P263 -> 0 | L20: ='RESUMEN TOTAL'!Q263 -> 0 | M20: ='RESUMEN TOTAL'!R263 -> 0 | ... AI20: ='RESUMEN TOTAL'!AN263 -> 0
A21: ='RESUMEN TOTAL'!A23 -> CENTRO | B21: ='RESUMEN TOTAL'!B23 -> CEN01 | C21: ='RESUMEN TOTAL'!D23 -> San Martin y 9 de Julio | D21: ='RESUMEN TOTAL'!E23 -> Fija | E21: ='RESUMEN TOTAL'!F23 -> Fibra Optica | F21: ='RESUMEN TOTAL'!K23 -> 0 | G21: ='RESUMEN TOTAL'!L23 -> 0 | H21: ='RESUMEN TOTAL'!M23 -> 0 | I21: ='RESUMEN TOTAL'!N23 -> 0 | J21: ='RESUMEN TOTAL'!O23 -> 0 | K21: ='RESUMEN TOTAL'!P23 -> 0 | L21: ='RESUMEN TOTAL'!Q23 -> 0 | M21: ='RESUMEN TOTAL'!R23 -> 0 | ... AI21: ='RESUMEN TOTAL'!AN23 -> 0
A22: ='RESUMEN TOTAL'!A24 -> CENTRO | B22: ='RESUMEN TOTAL'!B24 -> CEN02 | C22: ='RESUMEN TOTAL'!D24 -> San Martin y Almafuerte | D22: ='RESUMEN TOTAL'!E24 -> Fija | E22: ='RESUMEN TOTAL'!F24 -> Fibra Optica | F22: ='RESUMEN TOTAL'!K24 -> 0 | G22: ='RESUMEN TOTAL'!L24 -> 0 | H22: ='RESUMEN TOTAL'!M24 -> 0 | I22: ='RESUMEN TOTAL'!N24 -> 0 | J22: ='RESUMEN TOTAL'!O24 -> 0 | K22: ='RESUMEN TOTAL'!P24 -> 0 | L22: ='RESUMEN TOTAL'!Q24 -> 0 | M22: ='RESUMEN TOTAL'!R24 -> 0 | ... AI22: ='RESUMEN TOTAL'!AN24 -> 0
A23: ='RESUMEN TOTAL'!A25 -> CENTRO | B23: ='RESUMEN TOTAL'!B25 -> CEN03 | C23: ='RESUMEN TOTAL'!D25 -> San Martin y Sallares | D23: ='RESUMEN TOTAL'!E25 -> Domo | E23: ='RESUMEN TOTAL'!F25 -> Fibra Optica | F23: ='RESUMEN TOTAL'!K25 -> 0 | G23: ='RESUMEN TOTAL'!L25 -> 0 | H23: ='RESUMEN TOTAL'!M25 -> 0 | I23: ='RESUMEN TOTAL'!N25 -> 0 | J23: ='RESUMEN TOTAL'!O25 -> 0 | K23: ='RESUMEN TOTAL'!P25 -> 0 | L23: ='RESUMEN TOTAL'!Q25 -> 0 | M23: ='RESUMEN TOTAL'!R25 -> 0 | ... AI23: ='RESUMEN TOTAL'!AN25 -> 0
A24: ='RESUMEN TOTAL'!A26 -> CENTRO | B24: ='RESUMEN TOTAL'!B26 -> CEN04 | C24: ='RESUMEN TOTAL'!D26 -> San Martin y Contreras | D24: ='RESUMEN TOTAL'!E26 -> Domo | E24: ='RESUMEN TOTAL'!F26 -> Fibra Optica | F24: ='RESUMEN TOTAL'!K26 -> 0 | G24: ='RESUMEN TOTAL'!L26 -> 0 | H24: ='RESUMEN TOTAL'!M26 -> 0 | I24: ='RESUMEN TOTAL'!N26 -> 0 | J24: ='RESUMEN TOTAL'!O26 -> 0 | K24: ='RESUMEN TOTAL'!P26 -> 0 | L24: ='RESUMEN TOTAL'!Q26 -> 0 | M24: ='RESUMEN TOTAL'!R26 -> 0 | ... AI24: ='RESUMEN TOTAL'!AN26 -> 0
A25: ='RESUMEN TOTAL'!A27 -> CENTRO | B25: ='RESUMEN TOTAL'!B27 -> CEN 05 | C25: ='RESUMEN TOTAL'!D27 -> Bocuzzi e/España y San Martin | D25: ='RESUMEN TOTAL'!E27 -> DOMO | E25: ='RESUMEN TOTAL'!F27 -> Fibra Optica | F25: ='RESUMEN TOTAL'!K27 -> 0 | G25: ='RESUMEN TOTAL'!L27 -> 0 | H25: ='RESUMEN TOTAL'!M27 -> 0 | I25: ='RESUMEN TOTAL'!N27 -> 0 | J25: ='RESUMEN TOTAL'!O27 -> 0 | K25: ='RESUMEN TOTAL'!P27 -> 0 | L25: ='RESUMEN TOTAL'!Q27 -> 0 | M25: ='RESUMEN TOTAL'!R27 -> 0 | ... AI25: ='RESUMEN TOTAL'!AN27 -> 0
A26: ='RESUMEN TOTAL'!A28 -> CENTRO | B26: ='RESUMEN TOTAL'!B28 -> CEN06 | C26: ='RESUMEN TOTAL'!D28 -> Monteagudo y A.del Valle | D26: ='RESUMEN TOTAL'!E28 -> Fija | E26: ='RESUMEN TOTAL'!F28 -> Fibra Optica | F26: ='RESUMEN TOTAL'!K28 -> 0 | G26: ='RESUMEN TOTAL'!L28 -> 0 | H26: ='RESUMEN TOTAL'!M28 -> 0 | I26: ='RESUMEN TOTAL'!N28 -> 0 | J26: ='RESUMEN TOTAL'!O28 -> 0 | K26: ='RESUMEN TOTAL'!P28 -> 0 | L26: ='RESUMEN TOTAL'!Q28 -> 0 | M26: ='RESUMEN TOTAL'!R28 -> 0 | ... AI26: ='RESUMEN TOTAL'!AN28 -> 0
A27: ='RESUMEN TOTAL'!A29 -> CENTRO | B27: ='RESUMEN TOTAL'!B29 -> CEN07 | C27: ='RESUMEN TOTAL'!D29 -> San Martin y Guemes | D27: ='RESUMEN TOTAL'!E29 -> DOMO | E27: ='RESUMEN TOTAL'!F29 -> Fibra Optica | F27: ='RESUMEN TOTAL'!K29 -> 0 | G27: ='RESUMEN TOTAL'!L29 -> 0 | H27: ='RESUMEN TOTAL'!M29 -> 0 | I27: ='RESUMEN TOTAL'!N29 -> 0 | J27: ='RESUMEN TOTAL'!O29 -> 0 | K27: ='RESUMEN TOTAL'!P29 -> 0 | L27: ='RESUMEN TOTAL'!Q29 -> 0 | M27: ='RESUMEN TOTAL'!R29 -> 0 | ... AI27: ='RESUMEN TOTAL'!AN29 -> 0
A28: ='RESUMEN TOTAL'!A30 -> CENTRO | B28: ='RESUMEN TOTAL'!B30 -> CEN08 | C28: ='RESUMEN TOTAL'!D30 -> San Martin y Pte.Peron | D28: ='RESUMEN TOTAL'!E30 -> Domo | E28: ='RESUMEN TOTAL'!F30 -> Fibra Optica | F28: ='RESUMEN TOTAL'!K30 -> 0 | G28: ='RESUMEN TOTAL'!L30 -> 0 | H28: ='RESUMEN TOTAL'!M30 -> 0 | I28: ='RESUMEN TOTAL'!N30 -> 0 | J28: ='RESUMEN TOTAL'!O30 -> 0 | K28: ='RESUMEN TOTAL'!P30 -> 0 | L28: ='RESUMEN TOTAL'!Q30 -> 0 | M28: ='RESUMEN TOTAL'!R30 -> 0 | ... AI28: ='RESUMEN TOTAL'!AN30 -> 0
A29: ='RESUMEN TOTAL'!A31 -> CENTRO | B29: ='RESUMEN TOTAL'!B31 -> CEN09 | C29: ='RESUMEN TOTAL'!D31 -> Chacabuco y 25 de Mayo | D29: ='RESUMEN TOTAL'!E31 -> Domo | E29: ='RESUMEN TOTAL'!F31 -> Fibra Optica | F29: ='RESUMEN TOTAL'!K31 -> 0 | G29: ='RESUMEN TOTAL'!L31 -> 0 | H29: ='RESUMEN TOTAL'!M31 -> 0 | I29: ='RESUMEN TOTAL'!N31 -> 0 | J29: ='RESUMEN TOTAL'!O31 -> 0 | K29: ='RESUMEN TOTAL'!P31 -> 0 | L29: ='RESUMEN TOTAL'!Q31 -> 0 | M29: ='RESUMEN TOTAL'!R31 -> 0 | ... AI29: ='RESUMEN TOTAL'!AN31 -> 0
A30: ='RESUMEN TOTAL'!A32 -> CENTRO | B30: ='RESUMEN TOTAL'!B32 -> CEN10 | C30: ='RESUMEN TOTAL'!D32 -> Monteagudo y Pte. Peron | D30: ='RESUMEN TOTAL'!E32 -> Domo | E30: ='RESUMEN TOTAL'!F32 -> Fibra Optica | F30: ='RESUMEN TOTAL'!K32 -> 0 | G30: ='RESUMEN TOTAL'!L32 -> 0 | H30: ='RESUMEN TOTAL'!M32 -> 0 | I30: ='RESUMEN TOTAL'!N32 -> 0 | J30: ='RESUMEN TOTAL'!O32 -> 0 | K30: ='RESUMEN TOTAL'!P32 -> 0 | L30: ='RESUMEN TOTAL'!Q32 -> 0 | M30: ='RESUMEN TOTAL'!R32 -> 0 | ... AI30: ='RESUMEN TOTAL'!AN32 -> 0
A31: ='RESUMEN TOTAL'!A33 -> CENTRO | B31: ='RESUMEN TOTAL'!B33 -> CEN11 | C31: ='RESUMEN TOTAL'!D33 -> Monteagudo y Bocuzzi | D31: ='RESUMEN TOTAL'!E33 -> Domo | E31: ='RESUMEN TOTAL'!F33 -> Fibra Optica | F31: ='RESUMEN TOTAL'!K33 -> 0 | G31: ='RESUMEN TOTAL'!L33 -> 0 | H31: ='RESUMEN TOTAL'!M33 -> 0 | I31: ='RESUMEN TOTAL'!N33 -> 0 | J31: ='RESUMEN TOTAL'!O33 -> 0 | K31: ='RESUMEN TOTAL'!P33 -> 0 | L31: ='RESUMEN TOTAL'!Q33 -> 0 | M31: ='RESUMEN TOTAL'!R33 -> 0 | ... AI31: ='RESUMEN TOTAL'!AN33 -> 0
A32: ='RESUMEN TOTAL'!A34 -> CENTRO | B32: ='RESUMEN TOTAL'!B34 -> CEN 12 | C32: ='RESUMEN TOTAL'!D34 -> Monteagudo y Mitre | D32: ='RESUMEN TOTAL'!E34 -> Domo | E32: ='RESUMEN TOTAL'!F34 -> Fibra Optica | F32: ='RESUMEN TOTAL'!K34 -> APAGADO | G32: ='RESUMEN TOTAL'!L34 -> APAGADO | H32: ='RESUMEN TOTAL'!M34 -> APAGADO | I32: ='RESUMEN TOTAL'!N34 -> APAGADO | J32: ='RESUMEN TOTAL'!O34 -> APAGADO | K32: ='RESUMEN TOTAL'!P34 -> APAGADO | L32: ='RESUMEN TOTAL'!Q34 -> APAGADO | M32: ='RESUMEN TOTAL'!R34 -> APAGADO | ... AI32: ='RESUMEN TOTAL'!AN34 -> 0
... A119: ='RESUMEN TOTAL'!A121 -> EL PARQUE | B119: ='RESUMEN TOTAL'!B121 -> EPQ 04 | C119: ='RESUMEN TOTAL'!D121 -> 1282 Y MORENO | D119: ='RESUMEN TOTAL'!E121 -> DOMO | E119: ='RESUMEN TOTAL'!F121 -> Fibra Optica | F119: ='RESUMEN TOTAL'!K121 -> 0 | G119: ='RESUMEN TOTAL'!L121 -> 0 | H119: ='RESUMEN TOTAL'!M121 -> 0 | I119: ='RESUMEN TOTAL'!N121 -> 0 | J119: ='RESUMEN TOTAL'!O121 -> 0 | K119: ='RESUMEN TOTAL'!P121 -> 0 | L119: ='RESUMEN TOTAL'!Q121 -> 0 | M119: ='RESUMEN TOTAL'!R121 -> 0 | ... AI119: ='RESUMEN TOTAL'!AN121 -> 0
A120: ='RESUMEN TOTAL'!A129 -> LA ESMERALDA | B120: ='RESUMEN TOTAL'!B129 -> ESM 08 | C120: ='RESUMEN TOTAL'!D129 -> DAVINSON Y MORANCHEL | D120: ='RESUMEN TOTAL'!E129 -> FIJA | E120: ='RESUMEN TOTAL'!F129 -> Radio | F120: ='RESUMEN TOTAL'!K129 -> 0 | G120: ='RESUMEN TOTAL'!L129 -> 0 | H120: ='RESUMEN TOTAL'!M129 -> 0 | I120: ='RESUMEN TOTAL'!N129 -> 0 | J120: ='RESUMEN TOTAL'!O129 -> 0 | K120: ='RESUMEN TOTAL'!P129 -> 0 | L120: ='RESUMEN TOTAL'!Q129 -> 0 | M120: ='RESUMEN TOTAL'!R129 -> 0 | ... AI120: ='RESUMEN TOTAL'!AN129 -> 0
A121: ='RESUMEN TOTAL'!A122 -> LA ESMERALDA | B121: ='RESUMEN TOTAL'!B122 -> ESM01 | C121: ='RESUMEN TOTAL'!D122 -> Cabello y Brasil | D121: ='RESUMEN TOTAL'!E122 -> Domo | E121: ='RESUMEN TOTAL'!F122 -> Radio | F121: ='RESUMEN TOTAL'!K122 -> 0 | G121: ='RESUMEN TOTAL'!L122 -> 0 | H121: ='RESUMEN TOTAL'!M122 -> 0 | I121: ='RESUMEN TOTAL'!N122 -> 0 | J121: ='RESUMEN TOTAL'!O122 -> 0 | K121: ='RESUMEN TOTAL'!P122 -> APAGADO | L121: ='RESUMEN TOTAL'!Q122 -> APAGADO | M121: ='RESUMEN TOTAL'!R122 -> 0 | ... AI121: ='RESUMEN TOTAL'!AN122 -> 0
A122: ='RESUMEN TOTAL'!A123 -> SAN JORGE | B122: ='RESUMEN TOTAL'!B123 -> ESM02 | C122: ='RESUMEN TOTAL'!D123 -> Novak y Cabello | D122: ='RESUMEN TOTAL'!E123 -> Domo | E122: ='RESUMEN TOTAL'!F123 -> PTO A FO | F122: ='RESUMEN TOTAL'!K123 -> 0 | G122: ='RESUMEN TOTAL'!L123 -> 0 | H122: ='RESUMEN TOTAL'!M123 -> 0 | I122: ='RESUMEN TOTAL'!N123 -> 0 | J122: ='RESUMEN TOTAL'!O123 -> 0 | K122: ='RESUMEN TOTAL'!P123 -> 0 | L122: ='RESUMEN TOTAL'!Q123 -> 0 | M122: ='RESUMEN TOTAL'!R123 -> 0 | ... AI122: ='RESUMEN TOTAL'!AN123 -> 0
A123: ='RESUMEN TOTAL'!A124 -> LIBERTAD | B123: ='RESUMEN TOTAL'!B124 -> ESM03 | C123: ='RESUMEN TOTAL'!D124 -> Novak y Humahuaca | D123: ='RESUMEN TOTAL'!E124 -> DOMO | E123: ='RESUMEN TOTAL'!F124 -> PTO A FO | F123: ='RESUMEN TOTAL'!K124 -> 0 | G123: ='RESUMEN TOTAL'!L124 -> 0 | H123: ='RESUMEN TOTAL'!M124 -> 0 | I123: ='RESUMEN TOTAL'!N124 -> 0 | J123: ='RESUMEN TOTAL'!O124 -> 0 | K123: ='RESUMEN TOTAL'!P124 -> 0 | L123: ='RESUMEN TOTAL'!Q124 -> 0 | M123: ='RESUMEN TOTAL'!R124 -> 0 | ... AI123: ='RESUMEN TOTAL'!AN124 -> 0
A124: ='RESUMEN TOTAL'!A125 -> LA ESMERALDA | B124: ='RESUMEN TOTAL'!B125 -> ESM04 | C124: ='RESUMEN TOTAL'!D125 -> Basualdo y Bengochea | D124: ='RESUMEN TOTAL'!E125 -> Domo | E124: ='RESUMEN TOTAL'!F125 -> FIBRA OPTICA | F124: ='RESUMEN TOTAL'!K125 -> APAGADO | G124: ='RESUMEN TOTAL'!L125 -> APAGADO | H124: ='RESUMEN TOTAL'!M125 -> 0 | I124: ='RESUMEN TOTAL'!N125 -> 0 | J124: ='RESUMEN TOTAL'!O125 -> 0 | K124: ='RESUMEN TOTAL'!P125 -> 0 | L124: ='RESUMEN TOTAL'!Q125 -> 0 | M124: ='RESUMEN TOTAL'!R125 -> 0 | ... AI124: ='RESUMEN TOTAL'!AN125 -> 0
A125: ='RESUMEN TOTAL'!A126 -> LA ESMERALDA | B125: ='RESUMEN TOTAL'!B126 -> ESM05 | C125: ='RESUMEN TOTAL'!D126 -> Aniceto Diaz y Villar | D125: ='RESUMEN TOTAL'!E126 -> Domo | E125: ='RESUMEN TOTAL'!F126 -> FIBRA OPTICA | F125: ='RESUMEN TOTAL'!K126 -> 0 | G125: ='RESUMEN TOTAL'!L126 -> 0 | H125: ='RESUMEN TOTAL'!M126 -> 0 | I125: ='RESUMEN TOTAL'!N126 -> 0 | J125: ='RESUMEN TOTAL'!O126 -> 0 | K125: ='RESUMEN TOTAL'!P126 -> 0 | L125: ='RESUMEN TOTAL'!Q126 -> 0 | M125: ='RESUMEN TOTAL'!R126 -> 0 | ... AI125: ='RESUMEN TOTAL'!AN126 -> 0
A126: ='RESUMEN TOTAL'!A127 -> LA ESMERALDA | B126: ='RESUMEN TOTAL'!B127 -> ESM06 | C126: ='RESUMEN TOTAL'!D127 -> Roselli y Cabello | D126: ='RESUMEN TOTAL'!E127 -> Domo | E126: ='RESUMEN TOTAL'!F127 -> Radio | F126: ='RESUMEN TOTAL'!K127 -> 0 | G126: ='RESUMEN TOTAL'!L127 -> 0 | H126: ='RESUMEN TOTAL'!M127 -> 0 | I126: ='RESUMEN TOTAL'!N127 -> 0 | J126: ='RESUMEN TOTAL'!O127 -> 0 | K126: ='RESUMEN TOTAL'!P127 -> 0 | L126: ='RESUMEN TOTAL'!Q127 -> 0 | M126: ='RESUMEN TOTAL'!R127 -> 0 | ... AI126: ='RESUMEN TOTAL'!AN127 -> 0
A127: ='RESUMEN TOTAL'!A128 -> LA ESMERALDA | B127: ='RESUMEN TOTAL'!B128 -> ESM07 | C127: ='RESUMEN TOTAL'!D128 -> AV. NOVAK Y SERRANO | D127: ='RESUMEN TOTAL'!E128 -> DOMO | E127: ='RESUMEN TOTAL'!F128 -> PTO A FO | F127: ='RESUMEN TOTAL'!K128 -> 0 | G127: ='RESUMEN TOTAL'!L128 -> 0 | H127: ='RESUMEN TOTAL'!M128 -> 0 | I127: ='RESUMEN TOTAL'!N128 -> 0 | J127: ='RESUMEN TOTAL'!O128 -> 0 | K127: ='RESUMEN TOTAL'!P128 -> 0 | L127: ='RESUMEN TOTAL'!Q128 -> 0 | M127: ='RESUMEN TOTAL'!R128 -> 0 | ... AI127: ='RESUMEN TOTAL'!AN128 -> 0
A128: ='RESUMEN TOTAL'!A130 -> LA ESMERALDA | B128: ='RESUMEN TOTAL'!B130 -> ESM09 (fija 1) | C128: ='RESUMEN TOTAL'!D130 -> EEUU Y CABELLO | D128: ='RESUMEN TOTAL'!E130 -> Fija | E128: ='RESUMEN TOTAL'!F130 -> Fibra Optica | F128: ='RESUMEN TOTAL'!K130 -> 0 | G128: ='RESUMEN TOTAL'!L130 -> 0 | H128: ='RESUMEN TOTAL'!M130 -> 0 | I128: ='RESUMEN TOTAL'!N130 -> 0 | J128: ='RESUMEN TOTAL'!O130 -> 0 | K128: ='RESUMEN TOTAL'!P130 -> 0 | L128: ='RESUMEN TOTAL'!Q130 -> 0 | M128: ='RESUMEN TOTAL'!R130 -> 0 | ... AI128: ='RESUMEN TOTAL'!AN130 -> 0
A129: ='RESUMEN TOTAL'!A131 -> LA ESMERALDA | B129: ='RESUMEN TOTAL'!B131 -> ESM10 (fija 2) | C129: ='RESUMEN TOTAL'!D131 -> EEUU Y CABELLO | D129: ='RESUMEN TOTAL'!E131 -> Fija | E129: ='RESUMEN TOTAL'!F131 -> Fibra Optica | F129: ='RESUMEN TOTAL'!K131 -> 0 | G129: ='RESUMEN TOTAL'!L131 -> 0 | H129: ='RESUMEN TOTAL'!M131 -> 0 | I129: ='RESUMEN TOTAL'!N131 -> 0 | J129: ='RESUMEN TOTAL'!O131 -> 0 | K129: ='RESUMEN TOTAL'!P131 -> 0 | L129: ='RESUMEN TOTAL'!Q131 -> 0 | M129: ='RESUMEN TOTAL'!R131 -> 0 | ... AI129: ='RESUMEN TOTAL'!AN131 -> 0
A130: ='RESUMEN TOTAL'!A132 -> LA ESMERALDA | B130: ='RESUMEN TOTAL'!B132 -> ESM11 (fija 1) | C130: ='RESUMEN TOTAL'!D132 -> NOVAK Y LAMBARDI | D130: ='RESUMEN TOTAL'!E132 -> Fija | E130: ='RESUMEN TOTAL'!F132 -> Fibra Optica | F130: ='RESUMEN TOTAL'!K132 -> 0 | G130: ='RESUMEN TOTAL'!L132 -> 0 | H130: ='RESUMEN TOTAL'!M132 -> 0 | I130: ='RESUMEN TOTAL'!N132 -> 0 | J130: ='RESUMEN TOTAL'!O132 -> 0 | K130: ='RESUMEN TOTAL'!P132 -> 0 | L130: ='RESUMEN TOTAL'!Q132 -> 0 | M130: ='RESUMEN TOTAL'!R132 -> 0 | ... AI130: ='RESUMEN TOTAL'!AN132 -> 0
A131: ='RESUMEN TOTAL'!A133 -> LA ESMERALDA | B131: ='RESUMEN TOTAL'!B133 -> ESM12 (fija 2) | C131: ='RESUMEN TOTAL'!D133 -> NOVAK Y LAMBARDI | D131: ='RESUMEN TOTAL'!E133 -> Fija | E131: ='RESUMEN TOTAL'!F133 -> Fibra Optica | F131: ='RESUMEN TOTAL'!K133 -> 0 | G131: ='RESUMEN TOTAL'!L133 -> 0 | H131: ='RESUMEN TOTAL'!M133 -> 0 | I131: ='RESUMEN TOTAL'!N133 -> 0 | J131: ='RESUMEN TOTAL'!O133 -> 0 | K131: ='RESUMEN TOTAL'!P133 -> 0 | L131: ='RESUMEN TOTAL'!Q133 -> 0 | M131: ='RESUMEN TOTAL'!R133 -> 0 | ... AI131: ='RESUMEN TOTAL'!AN133 -> 0
A132: ='RESUMEN TOTAL'!A134 -> LA ESMERALDA | B132: ='RESUMEN TOTAL'!B134 -> ESM 13 | C132: ='RESUMEN TOTAL'!D134 -> Barzi y Serrano | D132: ='RESUMEN TOTAL'!E134 -> fija | E132: ='RESUMEN TOTAL'!F134 -> Fibra Optica | F132: ='RESUMEN TOTAL'!K134 -> 0 | G132: ='RESUMEN TOTAL'!L134 -> 0 | H132: ='RESUMEN TOTAL'!M134 -> 0 | I132: ='RESUMEN TOTAL'!N134 -> 0 | J132: ='RESUMEN TOTAL'!O134 -> 0 | K132: ='RESUMEN TOTAL'!P134 -> 0 | L132: ='RESUMEN TOTAL'!Q134 -> 0 | M132: ='RESUMEN TOTAL'!R134 -> 0 | ... AI132: ='RESUMEN TOTAL'!AN134 -> 0
...

Sheet APAGADOS
E1: APAGADOS | F1: =COUNTIF(F3:F400, "APAGADO") -> 38 | G1: =COUNTIF(G3:G400, "APAGADO") -> 29 | H1: =COUNTIF(H3:H500, "APAGADO") -> 36 | I1: =COUNTIF(I3:I400, "APAGADO") -> 35 | J1: =COUNTIF(J3:J400, "APAGADO") -> 35 | K1: =COUNTIF(K3:K400, "APAGADO") -> 36 | L1: =COUNTIF(L3:L400, "APAGADO") -> 34 | M1: =COUNTIF(M3:M400, "APAGADO") -> 32 | N1: =COUNTIF(N3:N400, "APAGADO") -> 32 | O1: =COUNTIF(O3:O400, "APAGADO") -> 90 | P1: =COUNTIF(P3:P400, "APAGADO") -> 89 | ... AI1: =COUNTIF(AI3:AI400, "APAGADO") -> 0
A2: =ESTADISTICA!A1 -> Barrio | B2: =ESTADISTICA!B1 -> [Denominacion] | C2: =ESTADISTICA!C1 -> [Ubicacion] | D2: =ESTADISTICA!D1 -> [Tipo de Camara] | E2: =ESTADISTICA!E1 -> [Tipo de Conexion] | F2: =ESTADISTICA!F1 -> 44866 | G2: =ESTADISTICA!G1 -> 44867 | H2: =ESTADISTICA!H1 -> 44868 | ... AI2: =ESTADISTICA!AI1 -> 44895
A3: =ESTADISTICA!A2 -> ALTAMIRA | B3: =ESTADISTICA!B2 -> ALT01 | C3: =ESTADISTICA!C2 -> Calchaqui y Sgto. Cabral | D3: =ESTADISTICA!D2 -> Domo | E3: =ESTADISTICA!E2 -> Fibra Optica | F3: =ESTADISTICA!F2 -> 0 | G3: =ESTADISTICA!G2 -> 0 | H3: =ESTADISTICA!H2 -> 0 | ... AI3: =ESTADISTICA!AI2 -> 0
A4: =ESTADISTICA!A3 -> ALTAMIRA | B4: =ESTADISTICA!B3 -> ALT02 | C4: =ESTADISTICA!C3 -> Calchaqui y Lope de Vega | D4: =ESTADISTICA!D3 -> Domo | E4: =ESTADISTICA!E3 -> PTO A FO | F4: =ESTADISTICA!F3 -> 0 | G4: =ESTADISTICA!G3 -> 0 | H4: =ESTADISTICA!H3 -> 0 | ... AI4: =ESTADISTICA!AI3 -> 0
A5: =ESTADISTICA!A4 -> ALTAMIRA | B5: =ESTADISTICA!B4 -> ALT 03 | C5: =ESTADISTICA!C4 -> Bombero Galarza y Necochea | D5: =ESTADISTICA!D4 -> Domo | E5: =ESTADISTICA!E4 -> FIBRA OPTICA | F5: =ESTADISTICA!F4 -> 0 | G5: =ESTADISTICA!G4 -> 0 | H5: =ESTADISTICA!H4 -> 0 | ... AI5: =ESTADISTICA!AI4 -> 0
A6: =ESTADISTICA!A5 -> ALTAMIRA | B6: =ESTADISTICA!B5 -> ALT 04 | C6: =ESTADISTICA!C5 -> Francia y Necochea | D6: =ESTADISTICA!D5 -> Domo | E6: =ESTADISTICA!E5 -> FIBRA OPTICA | F6: =ESTADISTICA!F5 -> 0 | G6: =ESTADISTICA!G5 -> 0 | H6: =ESTADISTICA!H5 -> 0 | ... AI6: =ESTADISTICA!AI5 -> 0
A7: =ESTADISTICA!A6 -> ALTAMIRA | B7: =ESTADISTICA!B6 -> ALT05 | C7: =ESTADISTICA!C6 -> Av. Calchaqui y Bombero Galarza | D7: =ESTADISTICA!D6 -> Domo | E7: =ESTADISTICA!E6 -> PTO A FO | F7: =ESTADISTICA!F6 -> 0 | G7: =ESTADISTICA!G6 -> 0 | H7: =ESTADISTICA!H6 -> 0 | ... AI7: =ESTADISTICA!AI6 -> 0
A8: =ESTADISTICA!A7 -> ALTAMIRA | B8: =ESTADISTICA!B7 -> ALT 06 | C8: =ESTADISTICA!C7 -> LOPE DE VEGA Y NECOCHEA | D8: =ESTADISTICA!D7 -> Domo | E8: =ESTADISTICA!E7 -> PTO A FO | F8: =ESTADISTICA!F7 -> 0 | G8: =ESTADISTICA!G7 -> 0 | H8: =ESTADISTICA!H7 -> 0 | ... AI8: =ESTADISTICA!AI7 -> 0
A9: =ESTADISTICA!A8 -> ALTAMIRA | B9: =ESTADISTICA!B8 -> ALT07 | C9: =ESTADISTICA!C8 -> AV. CALCHAQUI Y AV. DEL TRABAJO | D9: =ESTADISTICA!D8 -> DOMO | E9: =ESTADISTICA!E8 -> PTO A FO | F9: =ESTADISTICA!F8 -> 0 | G9: =ESTADISTICA!G8 -> 0 | H9: =ESTADISTICA!H8 -> 0 | ... AI9: =ESTADISTICA!AI8 -> 0
A10: =ESTADISTICA!A9 -> ALTAMIRA | B10: =ESTADISTICA!B9 -> ALT 08 | C10: =ESTADISTICA!C9 -> HUMAITA Y NECOCHEA | D10: =ESTADISTICA!D9 -> DOMO | E10: =ESTADISTICA!E9 -> Fibra Optica | F10: =ESTADISTICA!F9 -> 0 | G10: =ESTADISTICA!G9 -> 0 | H10: =ESTADISTICA!H9 -> 0 | ... AI10: =ESTADISTICA!AI9 -> 0
A11: =ESTADISTICA!A10 -> ALTAMIRA | B11: =ESTADISTICA!B10 -> ALT 09 | C11: =ESTADISTICA!C10 -> NECOCHEA Y CURUPAITY | D11: =ESTADISTICA!D10 -> DOMO | E11: =ESTADISTICA!E10 -> Fibra Optica | F11: =ESTADISTICA!F10 -> 0 | G11: =ESTADISTICA!G10 -> 0 | H11: =ESTADISTICA!H10 -> 0 | ... AI11: =ESTADISTICA!AI10 -> 0
A12: =ESTADISTICA!A11 -> ALTAMIRA | B12: =ESTADISTICA!B11 -> ALT 10 | C12: =ESTADISTICA!C11 -> Calchaqui y Francia | D12: =ESTADISTICA!D11 -> Domo | E12: =ESTADISTICA!E11 -> Radio | F12: =ESTADISTICA!F11 -> 0 | G12: =ESTADISTICA!G11 -> 0 | H12: =ESTADISTICA!H11 -> 0 | ... AI12: =ESTADISTICA!AI11 -> 0
A13: =ESTADISTICA!A12 -> AGUSTIN RAMIREZ | B13: =ESTADISTICA!B12 -> ARA 01 | C13: =ESTADISTICA!C12 -> Malambo y Tranquera | D13: =ESTADISTICA!D12 -> Domo | E13: =ESTADISTICA!E12 -> FIBRA OPTICA | F13: =ESTADISTICA!F12 -> 0 | G13: =ESTADISTICA!G12 -> 0 | H13: =ESTADISTICA!H12 -> 0 | ... AI13: =ESTADISTICA!AI12 -> 0
... A509: =ESTADISTICA!A508 -> 0 | B509: =ESTADISTICA!B508 -> 0 | C509: =ESTADISTICA!C508 -> 0 | D509: =ESTADISTICA!D508 -> 0 | E509: =ESTADISTICA!E508 -> 0 | F509: =ESTADISTICA!F508 -> 0 | G509: =ESTADISTICA!G508 -> 0 | H509: =ESTADISTICA!H508 -> 0 | ... AI509: =ESTADISTICA!AI508 -> 0

Sheet APAGADOS FIBRA
C1: TOTAL FIBRA | D1: =COUNTIFS(E4:E400,"=Fibra Optica") -> 268
E2: APAGADOS | F2: =COUNTIFS(F4:F500, "=APAGADO",E4:E500,"=Fibra Optica") -> 37 | G2: =COUNTIFS(G4:G500, "=APAGADO",E4:E500,"=Fibra Optica") -> 29 | H2: =COUNTIFS(H4:H500, "=APAGADO",E4:E500,"=Fibra Optica") -> 33 | I2: =COUNTIFS(I4:I500, "=APAGADO",E4:E500,"=Fibra Optica") -> 34 | J2: =COUNTIFS(J4:J500, "=APAGADO",E4:E500,"=Fibra Optica") -> 32 | K2: =COUNTIFS(K4:K500, "=APAGADO",E4:E500,"=Fibra Optica") -> 33 | L2: =COUNTIFS(L4:L500, "=APAGADO",E4:E500,"=Fibra Optica") -> 31 | M2: =COUNTIFS(M4:M500, "=APAGADO",E4:E500,"=Fibra Optica") -> 32 | N2: =COUNTIFS(N4:N500, "=APAGADO",E4:E500,"=Fibra Optica") -> 33 | O2: =COUNTIFS(O4:O500, "=APAGADO",E4:E500,"=Fibra Optica") -> 63 | P2: =COUNTIFS(P4:P500, "=APAGADO",E4:E500,"=Fibra Optica") -> 63 | Q2: =COUNTIFS(Q4:Q500, "=APAGADO",E4:E500,"=Fibra Optica") -> 36 | R2: =COUNTIFS(R4:R500, "=APAGADO",E4:E500,"=Fibra Optica") -> 61 | S2: =COUNTIFS(S4:S500, "=APAGADO",E4:E500,"=Fibra Optica") -> 36 | T2: =COUNTIFS(T4:T500, "=APAGADO",E4:E500,"=Fibra Optica") -> 35 | U2: =COUNTIFS(U4:U500, "=APAGADO",E4:E500,"=Fibra Optica") -> 36 | V2: =COUNTIFS(V4:V500, "=APAGADO",E4:E500,"=Fibra Optica") -> 36 | W2: =COUNTIFS(W4:W500, "=APAGADO",E4:E500,"=Fibra Optica") -> 41 | X2: =COUNTIFS(X4:X500, "=APAGADO",E4:E500,"=Fibra Optica") -> 34 | Y2: =COUNTIFS(Y4:Y500, "=APAGADO",E4:E500,"=Fibra Optica") -> 33 | Z2: =COUNTIFS(Z4:Z500, "=APAGADO",E4:E500,"=Fibra Optica") -> 28 | AA2: =COUNTIFS(AA4:AA500, "=APAGADO",E4:E500,"=Fibra Optica") -> 32 | AB2: =COUNTIFS(AB4:AB500, "=APAGADO",E4:E500,"=Fibra Optica") -> 41 | AC2: =COUNTIFS(AC4:AC500, "=APAGADO",E4:E500,"=Fibra Optica") -> 33 | AD2: =COUNTIFS(AD4:AD500, "=APAGADO",E4:E500,"=Fibra Optica") -> 50 | AE2: =COUNTIFS(AE4:AE500, "=APAGADO",E4:E500,"=Fibra Optica") -> 32 | AF2: =COUNTIFS(AF4:AF500, "=APAGADO",E4:E500,"=Fibra Optica") -> 33 | AG2: =COUNTIFS(AG4:AG500, "=APAGADO",E4:E500,"=Fibra Optica") -> 37 | AH2: =COUNTIFS(AH4:AH500, "=APAGADO",E4:E500,"=Fibra Optica") -> 35 | AI2: =COUNTIFS(AI4:AI400, "=APAGADO",E4:E400,"=Fibra Optica") -> 0
A3: =ESTADISTICA!A1 -> Barrio | B3: =ESTADISTICA!B1 -> [Denominacion] | C3: =ESTADISTICA!C1 -> [Ubicacion] | D3: =ESTADISTICA!D1 -> [Tipo de Camara] | E3: =ESTADISTICA!E1 -> [Tipo de Conexion] | F3: =ESTADISTICA!F1 -> 44866 | G3: =ESTADISTICA!G1 -> 44867 | H3: =ESTADISTICA!H1 -> 44868 | ... AI3: =ESTADISTICA!AI1 -> 44895
A4: =ESTADISTICA!A2 -> ALTAMIRA | B4: =ESTADISTICA!B2 -> ALT01 | C4: =ESTADISTICA!C2 -> Calchaqui y Sgto. Cabral | D4: =ESTADISTICA!D2 -> Domo | E4: =ESTADISTICA!E2 -> Fibra Optica | F4: =ESTADISTICA!F2 -> 0 | G4: =ESTADISTICA!G2 -> 0 | H4: =ESTADISTICA!H2 -> 0 | ... AI4: =ESTADISTICA!AI2 -> 0
A5: =ESTADISTICA!A3 -> ALTAMIRA | B5: =ESTADISTICA!B3 -> ALT02 | C5: =ESTADISTICA!C3 -> Calchaqui y Lope de Vega | D5: =ESTADISTICA!D3 -> Domo | E5: =ESTADISTICA!E3 -> PTO A FO | F5: =ESTADISTICA!F3 -> 0 | G5: =ESTADISTICA!G3 -> 0 | H5: =ESTADISTICA!H3 -> 0 | ... AI5: =ESTADISTICA!AI3 -> 0
A6: =ESTADISTICA!A4 -> ALTAMIRA | B6: =ESTADISTICA!B4 -> ALT 03 | C6: =ESTADISTICA!C4 -> Bombero Galarza y Necochea | D6: =ESTADISTICA!D4 -> Domo | E6: =ESTADISTICA!E4 -> FIBRA OPTICA | F6: =ESTADISTICA!F4 -> 0 | G6: =ESTADISTICA!G4 -> 0 | H6: =ESTADISTICA!H4 -> 0 | ... AI6: =ESTADISTICA!AI4 -> 0
A7: =ESTADISTICA!A5 -> ALTAMIRA | B7: =ESTADISTICA!B5 -> ALT 04 | C7: =ESTADISTICA!C5 -> Francia y Necochea | D7: =ESTADISTICA!D5 -> Domo | E7: =ESTADISTICA!E5 -> FIBRA OPTICA | F7: =ESTADISTICA!F5 -> 0 | G7: =ESTADISTICA!G5 -> 0 | H7: =ESTADISTICA!H5 -> 0 | ... AI7: =ESTADISTICA!AI5 -> 0
A8: =ESTADISTICA!A6 -> ALTAMIRA | B8: =ESTADISTICA!B6 -> ALT05 | C8: =ESTADISTICA!C6 -> Av. Calchaqui y Bombero Galarza | D8: =ESTADISTICA!D6 -> Domo | E8: =ESTADISTICA!E6 -> PTO A FO | F8: =ESTADISTICA!F6 -> 0 | G8: =ESTADISTICA!G6 -> 0 | H8: =ESTADISTICA!H6 -> 0 | ... AI8: =ESTADISTICA!AI6 -> 0
A9: =ESTADISTICA!A7 -> ALTAMIRA | B9: =ESTADISTICA!B7 -> ALT 06 | C9: =ESTADISTICA!C7 -> LOPE DE VEGA Y NECOCHEA | D9: =ESTADISTICA!D7 -> Domo | E9: =ESTADISTICA!E7 -> PTO A FO | F9: =ESTADISTICA!F7 -> 0 | G9: =ESTADISTICA!G7 -> 0 | H9: =ESTADISTICA!H7 -> 0 | ... AI9: =ESTADISTICA!AI7 -> 0
A10: =ESTADISTICA!A8 -> ALTAMIRA | B10: =ESTADISTICA!B8 -> ALT07 | C10: =ESTADISTICA!C8 -> AV. CALCHAQUI Y AV. DEL TRABAJO | D10: =ESTADISTICA!D8 -> DOMO | E10: =ESTADISTICA!E8 -> PTO A FO | F10: =ESTADISTICA!F8 -> 0 | G10: =ESTADISTICA!G8 -> 0 | H10: =ESTADISTICA!H8 -> 0 | ... AI10: =ESTADISTICA!AI8 -> 0
A11: =ESTADISTICA!A9 -> ALTAMIRA | B11: =ESTADISTICA!B9 -> ALT 08 | C11: =ESTADISTICA!C9 -> HUMAITA Y NECOCHEA | D11: =ESTADISTICA!D9 -> DOMO | E11: =ESTADISTICA!E9 -> Fibra Optica | F11: =ESTADISTICA!F9 -> 0 | G11: =ESTADISTICA!G9 -> 0 | H11: =ESTADISTICA!H9 -> 0 | ... AI11: =ESTADISTICA!AI9 -> 0
A12: =ESTADISTICA!A10 -> ALTAMIRA | B12: =ESTADISTICA!B10 -> ALT 09 | C12: =ESTADISTICA!C10 -> NECOCHEA Y CURUPAITY | D12: =ESTADISTICA!D10 -> DOMO | E12: =ESTADISTICA!E10 -> Fibra Optica | F12: =ESTADISTICA!F10 -> 0 | G12: =ESTADISTICA!G10 -> 0 | H12: =ESTADISTICA!H10 -> 0 | ... AI12: =ESTADISTICA!AI10 -> 0
A13: =ESTADISTICA!A11 -> ALTAMIRA | B13: =ESTADISTICA!B11 -> ALT 10 | C13: =ESTADISTICA!C11 -> Calchaqui y Francia | D13: =ESTADISTICA!D11 -> Domo | E13: =ESTADISTICA!E11 -> Radio | F13: =ESTADISTICA!F11 -> 0 | G13: =ESTADISTICA!G11 -> 0 | H13: =ESTADISTICA!H11 -> 0 | ... AI13: =ESTADISTICA!AI11 -> 0
A14: =ESTADISTICA!A12 -> AGUSTIN RAMIREZ | B14: =ESTADISTICA!B12 -> ARA 01 | C14: =ESTADISTICA!C12 -> Malambo y Tranquera | D14: =ESTADISTICA!D12 -> Domo | E14: =ESTADISTICA!E12 -> FIBRA OPTICA | F14: =ESTADISTICA!F12 -> 0 | G14: =ESTADISTICA!G12 -> 0 | H14: =ESTADISTICA!H12 -> 0 | ... AI14: =ESTADISTICA!AI12 -> 0
... A435: =ESTADISTICA!A433 -> 0 | B435: =ESTADISTICA!B433 -> 0 | C435: =ESTADISTICA!C433 -> 0 | D435: =ESTADISTICA!D433 -> 0 | E435: =ESTADISTICA!E433 -> 0 | F435: =ESTADISTICA!F433 -> 0 | G435: =ESTADISTICA!G433 -> 0 | H435: =ESTADISTICA!H433 -> 0 | ... AI435: =ESTADISTICA!AI433 -> 0

Sheet APAGADOS ANTENA
C1: TOTAL PTO A FO
E2: APAGADOS | F2: =COUNTIFS(F4:F500, "=APAGADO",E4:E500,"=PTO A FO") -> 2 | G2: =COUNTIFS(G4:G500, "=APAGADO",E4:E500,"=PTO A FO") -> 1 | H2: =COUNTIFS(H4:H500, "=APAGADO",E4:E500,"=PTO A FO") -> 2 | I2: =COUNTIFS(I4:I500, "=APAGADO",E4:E500,"=PTO A FO") -> 1 | J2: =COUNTIFS(J4:J500, "=APAGADO",E4:E500,"=PTO A FO") -> 1 | K2: =COUNTIFS(K4:K500, "=APAGADO",E4:E500,"=PTO A FO") -> 1 | L2: =COUNTIFS(L4:L500, "=APAGADO",E4:E500,"=PTO A FO") -> 1 | M2: =COUNTIFS(M4:M500, "=APAGADO",E4:E500,"=PTO A FO") -> 1 | N2: =COUNTIFS(N4:N500, "=APAGADO",E4:E500,"=PTO A FO") -> 2 | O2: =COUNTIFS(O4:O500, "=APAGADO",E4:E500,"=PTO A FO") -> 8 | P2: =COUNTIFS(P4:P500, "=APAGADO",E4:E500,"=PTO A FO") -> 9 | Q2: =COUNTIFS(Q4:Q500, "=APAGADO",E4:E500,"=PTO A FO") -> 2 | R2: =COUNTIFS(R4:R500, "=APAGADO",E4:E500,"=PTO A FO") -> 10 | S2: =COUNTIFS(S4:S500, "=APAGADO",E4:E500,"=PTO A FO") -> 4 | T2: =COUNTIFS(T4:T500, "=APAGADO",E4:E500,"=PTO A FO") -> 5 | U2: =COUNTIFS(U4:U500, "=APAGADO",E4:E500,"=PTO A FO") -> 2 | V2: =COUNTIFS(V4:V500, "=APAGADO",E4:E500,"=PTO A FO") -> 2 | W2: =COUNTIFS(W4:W500, "=APAGADO",E4:E500,"=PTO A FO") -> 2 | X2: =COUNTIFS(X4:X500, "=APAGADO",E4:E500,"=PTO A FO") -> 4 | Y2: =COUNTIFS(Y4:Y500, "=APAGADO",E4:E500,"=PTO A FO") -> 2 | Z2: =COUNTIFS(Z4:Z500, "=APAGADO",E4:E500,"=PTO A FO") -> 2 | AA2: =COUNTIFS(AA4:AA500, "=APAGADO",E4:E500,"=PTO A FO") -> 2 | AB2: =COUNTIFS(AB4:AB500, "=APAGADO",E4:E500,"=PTO A FO") -> 4 | AC2: =COUNTIFS(AC4:AC500, "=APAGADO",E4:E500,"=PTO A FO") -> 4 | AD2: =COUNTIFS(AD4:AD500, "=APAGADO",E4:E500,"=PTO A FO") -> 4 | AE2: =COUNTIFS(AE4:AE500, "=APAGADO",E4:E500,"=PTO A FO") -> 4 | AF2: =COUNTIFS(AF4:AF500, "=APAGADO",E4:E500,"=PTO A FO") -> 4 | AG2: =COUNTIFS(AG4:AG500, "=APAGADO",E4:E500,"=PTO A FO") -> 4 | AH2: =COUNTIFS(AH4:AH500, "=APAGADO",E4:E500,"=PTO A FO") -> 4 | AI2: =COUNTIFS(AI4:AI500, "=APAGADO",E4:E500,"=PTO A FO") -> 0
A3: =ESTADISTICA!A1 -> Barrio | B3: =ESTADISTICA!B1 -> [Denominacion] | C3: =ESTADISTICA!C1 -> [Ubicacion] | D3: =ESTADISTICA!D1 -> [Tipo de Camara] | E3: =ESTADISTICA!E1 -> [Tipo de Conexion] | F3: =ESTADISTICA!F1 -> 44866 | G3: =ESTADISTICA!G1 -> 44867 | H3: =ESTADISTICA!H1 -> 44868 | ... AI3: =ESTADISTICA!AI1 -> 44895
A4: =ESTADISTICA!A2 -> ALTAMIRA | B4: =ESTADISTICA!B2 -> ALT01 | C4: =ESTADISTICA!C2 -> Calchaqui y Sgto. Cabral | D4: =ESTADISTICA!D2 -> Domo | E4: =ESTADISTICA!E2 -> Fibra Optica | F4: =ESTADISTICA!F2 -> 0 | G4: =ESTADISTICA!G2 -> 0 | H4: =ESTADISTICA!H2 -> 0 | ... AI4: =ESTADISTICA!AI2 -> 0
A5: =ESTADISTICA!A3 -> ALTAMIRA | B5: =ESTADISTICA!B3 -> ALT02 | C5: =ESTADISTICA!C3 -> Calchaqui y Lope de Vega | D5: =ESTADISTICA!D3 -> Domo | E5: =ESTADISTICA!E3 -> PTO A FO | F5: =ESTADISTICA!F3 -> 0 | G5: =ESTADISTICA!G3 -> 0 | H5: =ESTADISTICA!H3 -> 0 | ... AI5: =ESTADISTICA!AI3 -> 0
A6: =ESTADISTICA!A4 -> ALTAMIRA | B6: =ESTADISTICA!B4 -> ALT 03 | C6: =ESTADISTICA!C4 -> Bombero Galarza y Necochea | D6: =ESTADISTICA!D4 -> Domo | E6: =ESTADISTICA!E4 -> FIBRA OPTICA | F6: =ESTADISTICA!F4 -> 0 | G6: =ESTADISTICA!G4 -> 0 | H6: =ESTADISTICA!H4 -> 0 | ... AI6: =ESTADISTICA!AI4 -> 0
A7: =ESTADISTICA!A5 -> ALTAMIRA | B7: =ESTADISTICA!B5 -> ALT 04 | C7: =ESTADISTICA!C5 -> Francia y Necochea | D7: =ESTADISTICA!D5 -> Domo | E7: =ESTADISTICA!E5 -> FIBRA OPTICA | F7: =ESTADISTICA!F5 -> 0 | G7: =ESTADISTICA!G5 -> 0 | H7: =ESTADISTICA!H5 -> 0 | ... AI7: =ESTADISTICA!AI5 -> 0
A8: =ESTADISTICA!A6 -> ALTAMIRA | B8: =ESTADISTICA!B6 -> ALT05 | C8: =ESTADISTICA!C6 -> Av. Calchaqui y Bombero Galarza | D8: =ESTADISTICA!D6 -> Domo | E8: =ESTADISTICA!E6 -> PTO A FO | F8: =ESTADISTICA!F6 -> 0 | G8: =ESTADISTICA!G6 -> 0 | H8: =ESTADISTICA!H6 -> 0 | ... AI8: =ESTADISTICA!AI6 -> 0
A9: =ESTADISTICA!A7 -> ALTAMIRA | B9: =ESTADISTICA!B7 -> ALT 06 | C9: =ESTADISTICA!C7 -> LOPE DE VEGA Y NECOCHEA | D9: =ESTADISTICA!D7 -> Domo | E9: =ESTADISTICA!E7 -> PTO A FO | F9: =ESTADISTICA!F7 -> 0 | G9: =ESTADISTICA!G7 -> 0 | H9: =ESTADISTICA!H7 -> 0 | ... AI9: =ESTADISTICA!AI7 -> 0
A10: =ESTADISTICA!A8 -> ALTAMIRA | B10: =ESTADISTICA!B8 -> ALT07 | C10: =ESTADISTICA!C8 -> AV. CALCHAQUI Y AV. DEL TRABAJO | D10: =ESTADISTICA!D8 -> DOMO | E10: =ESTADISTICA!E8 -> PTO A FO | F10: =ESTADISTICA!F8 -> 0 | G10: =ESTADISTICA!G8 -> 0 | H10: =ESTADISTICA!H8 -> 0 | ... AI10: =ESTADISTICA!AI8 -> 0
A11: =ESTADISTICA!A9 -> ALTAMIRA | B11: =ESTADISTICA!B9 -> ALT 08 | C11: =ESTADISTICA!C9 -> HUMAITA Y NECOCHEA | D11: =ESTADISTICA!D9 -> DOMO | E11: =ESTADISTICA!E9 -> Fibra Optica | F11: =ESTADISTICA!F9 -> 0 | G11: =ESTADISTICA!G9 -> 0 | H11: =ESTADISTICA!H9 -> 0 | ... AI11: =ESTADISTICA!AI9 -> 0
A12: =ESTADISTICA!A10 -> ALTAMIRA | B12: =ESTADISTICA!B10 -> ALT 09 | C12: =ESTADISTICA!C10 -> NECOCHEA Y CURUPAITY | D12: =ESTADISTICA!D10 -> DOMO | E12: =ESTADISTICA!E10 -> Fibra Optica | F12: =ESTADISTICA!F10 -> 0 | G12: =ESTADISTICA!G10 -> 0 | H12: =ESTADISTICA!H10 -> 0 | ... AI12: =ESTADISTICA!AI10 -> 0
A13: =ESTADISTICA!A11 -> ALTAMIRA | B13: =ESTADISTICA!B11 -> ALT 10 | C13: =ESTADISTICA!C11 -> Calchaqui y Francia | D13: =ESTADISTICA!D11 -> Domo | E13: =ESTADISTICA!E11 -> Radio | F13: =ESTADISTICA!F11 -> 0 | G13: =ESTADISTICA!G11 -> 0 | H13: =ESTADISTICA!H11 -> 0 | ... AI13: =ESTADISTICA!AI11 -> 0
A14: =ESTADISTICA!A12 -> AGUSTIN RAMIREZ | B14: =ESTADISTICA!B12 -> ARA 01 | C14: =ESTADISTICA!C12 -> Malambo y Tranquera | D14: =ESTADISTICA!D12 -> Domo | E14: =ESTADISTICA!E12 -> FIBRA OPTICA | F14: =ESTADISTICA!F12 -> 0 | G14: =ESTADISTICA!G12 -> 0 | H14: =ESTADISTICA!H12 -> 0 | ... AI14: =ESTADISTICA!AI12 -> 0
... A278: =ESTADISTICA!A276 -> SAN EMILIO | B278: =ESTADISTICA!B276 -> SEMI 02 | C278: =ESTADISTICA!C276 -> Cno. Gral. Belgrano y Francia | D278: =ESTADISTICA!D276 -> Domo | E278: =ESTADISTICA!E276 -> FIBRA OPTICA | F278: =ESTADISTICA!F276 -> 0 | G278: =ESTADISTICA!G276 -> 0 | H278: =ESTADISTICA!H276 -> 0 | ... AI278: =ESTADISTICA!AI276 -> 0
B279: =ESTADISTICA!B277 -> SEMI03 (fija 1) | C279: =ESTADISTICA!C277 -> GORRITI E/ GALARZA Y LOPE DE VEGA | D279: =ESTADISTICA!D277 -> Fija | E279: =ESTADISTICA!E277 -> Fibra Optica | F279: =ESTADISTICA!F277 -> 0 | G279: =ESTADISTICA!G277 -> 0 | H279: =ESTADISTICA!H277 -> 0 | I279: =ESTADISTICA!I277 -> 0 | ... AI279: =ESTADISTICA!AI277 -> 0
A280: =ESTADISTICA!A278 -> SAN EMILIO | B280: =ESTADISTICA!B278 -> SEMI04 (fija 2) | C280: =ESTADISTICA!C278 -> GORRITI E/ GALARZA Y LOPE DE VEGA | D280: =ESTADISTICA!D278 -> Fija | E280: =ESTADISTICA!E278 -> Fibra Optica | F280: =ESTADISTICA!F278 -> 0 | G280: =ESTADISTICA!G278 -> 0 | H280: =ESTADISTICA!H278 -> 0 | ... AI280: =ESTADISTICA!AI278 -> 0
A281: =ESTADISTICA!A279 -> LA SIRENA | B281: =ESTADISTICA!B279 -> SIR01 | C281: =ESTADISTICA!C279 -> Moran y Calle 14 | D281: =ESTADISTICA!D279 -> DOMO | E281: =ESTADISTICA!E279 -> Radio | F281: =ESTADISTICA!F279 -> 0 | G281: =ESTADISTICA!G279 -> 0 | H281: =ESTADISTICA!H279 -> 0 | ... AI281: =ESTADISTICA!AI279 -> 0
A282: =ESTADISTICA!A280 -> SAN EDUARDO | B282: =ESTADISTICA!B280 -> SIR 02 | C282: =ESTADISTICA!C280 -> Victorino de la Plaza y Argentina | D282: =ESTADISTICA!D280 -> Domo | E282: =ESTADISTICA!E280 -> Radio | F282: =ESTADISTICA!F280 -> 0 | G282: =ESTADISTICA!G280 -> 0 | H282: =ESTADISTICA!H280 -> 0 | ... AI282: =ESTADISTICA!AI280 -> 0
A283: =ESTADISTICA!A281 -> SAN EDUARDO | B283: =ESTADISTICA!B281 -> SIR 03 | C283: =ESTADISTICA!C281 -> MONTES Y LONARDI | D283: =ESTADISTICA!D281 -> DOMO | E283: =ESTADISTICA!E281 -> Radio | F283: =ESTADISTICA!F281 -> 0 | G283: =ESTADISTICA!G281 -> 0 | H283: =ESTADISTICA!H281 -> 0 | ... AI283: =ESTADISTICA!AI281 -> 0
A284: =ESTADISTICA!A282 -> LA SIRENA | B284: =ESTADISTICA!B282 -> SIR 04 | C284: =ESTADISTICA!C282 -> AV. MONTEVERDE Y MORAN | D284: =ESTADISTICA!D282 -> Domo | E284: =ESTADISTICA!E282 -> Fibra Optica | F284: =ESTADISTICA!F282 -> 0 | G284: =ESTADISTICA!G282 -> 0 | H284: =ESTADISTICA!H282 -> 0 | ... AI284: =ESTADISTICA!AI282 -> 0
A285: =ESTADISTICA!A283 -> LA SIRENA | B285: =ESTADISTICA!B283 -> SIR 05 (FIJA 01) | C285: =ESTADISTICA!C283 -> AV. MONTEVERDE Y MORAN | D285: =ESTADISTICA!D283 -> Fija | E285: =ESTADISTICA!E283 -> Fibra Optica | F285: =ESTADISTICA!F283 -> 0 | G285: =ESTADISTICA!G283 -> 0 | H285: =ESTADISTICA!H283 -> 0 | ... AI285: =ESTADISTICA!AI283 -> 0
A286: =ESTADISTICA!A284 -> LA SIRENA | B286: =ESTADISTICA!B284 -> SIR 06 (FIJA 02) | C286: =ESTADISTICA!C284 -> AV. MONTEVERDE Y MORAN | D286: =ESTADISTICA!D284 -> Fija | E286: =ESTADISTICA!E284 -> Fibra Optica | F286: =ESTADISTICA!F284 -> 0 | G286: =ESTADISTICA!G284 -> 0 | H286: =ESTADISTICA!H284 -> 0 | ... AI286: =ESTADISTICA!AI284 -> 0
A287: =ESTADISTICA!A285 -> VILLA AURORA | B287: =ESTADISTICA!B285 -> SIR07 (fija 1) | C287: =ESTADISTICA!C285 -> MONTEVERDE Y URIBURU | D287: =ESTADISTICA!D285 -> Fija | E287: =ESTADISTICA!E285 -> Fibra Optica | F287: =ESTADISTICA!F285 -> 0 | G287: =ESTADISTICA!G285 -> 0 | H287: =ESTADISTICA!H285 -> 0 | ... AI287: =ESTADISTICA!AI285 -> 0
A288: =ESTADISTICA!A286 -> VILLA AURORA | B288: =ESTADISTICA!B286 -> SIR08 (fija 2) | C288: =ESTADISTICA!C286 -> MONTEVERDE Y URIBURU | D288: =ESTADISTICA!D286 -> Fija | E288: =ESTADISTICA!E286 -> Fibra Optica | F288: =ESTADISTICA!F286 -> 0 | G288: =ESTADISTICA!G286 -> 0 | H288: =ESTADISTICA!H286 -> 0 | ... AI288: =ESTADISTICA!AI286 -> 0
A289: =ESTADISTICA!A287 -> LA SIRENA | B289: =ESTADISTICA!B287 -> SIR09 (fija 1) | C289: =ESTADISTICA!C287 -> GUIDO SPANO Y MORAN | D289: =ESTADISTICA!D287 -> Fija | E289: =ESTADISTICA!E287 -> Fibra Optica | F289: =ESTADISTICA!F287 -> 0 | G289: =ESTADISTICA!G287 -> 0 | H289: =ESTADISTICA!H287 -> 0 | ... AI289: =ESTADISTICA!AI287 -> 0
A290: =ESTADISTICA!A288 -> LA SIRENA | B290: =ESTADISTICA!B288 -> SIR10 (fija 2) | C290: =ESTADISTICA!C288 -> GUIDO SPANO Y MORAN | D290: =ESTADISTICA!D288 -> Fija | E290: =ESTADISTICA!E288 -> Fibra Optica | F290: =ESTADISTICA!F288 -> 0 | G290: =ESTADISTICA!G288 -> 0 | H290: =ESTADISTICA!H288 -> 0 | ... AI290: =ESTADISTICA!AI288 -> 0
A291: =ESTADISTICA!A289 -> LA SIRENA | B291: =ESTADISTICA!B289 -> SIR11 (fija 1) | C291: =ESTADISTICA!C289 -> LARREA Y GUARDIA NACIONAL | D291: =ESTADISTICA!D289 -> Fija | E291: =ESTADISTICA!E289 -> Fibra Optica | F291: =ESTADISTICA!F289 -> 0 | G291: =ESTADISTICA!G289 -> 0 | H291: =ESTADISTICA!H289 -> 0 | ... AI291: =ESTADISTICA!AI289 -> 0
... A454: =ESTADISTICA!A452 -> 0 | B454: =ESTADISTICA!B452 -> 0 | C454: =ESTADISTICA!C452 -> 0 | D454: =ESTADISTICA!D452 -> 0 | E454: =ESTADISTICA!E452 -> 0 | F454: =ESTADISTICA!F452 -> 0 | G454: =ESTADISTICA!G452 -> 0 | H454: =ESTADISTICA!H452 -> 0 | ... AI454: =ESTADISTICA!AI452 -> 0

Sheet APAGADOS RADIO
C1: TOTAL RADIO | D1: =COUNTIFS(E4:E400,"=radio") -> 93
E2: APAGADOS | F2: =COUNTIFS(F4:F500, "=APAGADO",E4:E500,"=radio") -> 2 | G2: =COUNTIFS(G4:G500, "=APAGADO",E4:E500,"=radio") -> 2 | H2: =COUNTIFS(H4:H500, "=APAGADO",E4:E500,"=radio") -> 1 | I2: =COUNTIFS(I4:I500, "=APAGADO",E4:E500,"=radio") -> 3 | J2: =COUNTIFS(J4:J500, "=APAGADO",E4:E500,"=radio") -> 5 | K2: =COUNTIFS(K4:K500, "=APAGADO",E4:E500,"=radio") -> 5 | L2: =COUNTIFS(L4:L500, "=APAGADO",E4:E500,"=radio") -> 5 | M2: =COUNTIFS(M4:M500, "=APAGADO",E4:E500,"=radio") -> 3 | N2: =COUNTIFS(N4:N500, "=APAGADO",E4:E500,"=radio") -> 1 | O2: =COUNTIFS(O4:O500, "=APAGADO",E4:E500,"=radio") -> 27 | P2: =COUNTIFS(P4:P500, "=APAGADO",E4:E500,"=radio") -> 25 | Q2: =COUNTIFS(Q4:Q367, "=APAGADO",E4:E367,"=radio") -> 5 | R2: =COUNTIFS(R4:R367, "=APAGADO",E4:E367,"=radio") -> 25 | S2: =COUNTIFS(S4:S500, "=APAGADO",E4:E500,"=radio") -> 1 | T2: =COUNTIFS(T4:T500, "=APAGADO",E4:E500,"=radio") -> 1 | U2: =COUNTIFS(U4:U500, "=APAGADO",E4:E500,"=radio") -> 6 | V2: =COUNTIFS(V4:V500, "=APAGADO",E4:E500,"=radio") -> 7 | W2: =COUNTIFS(W4:W500, "=APAGADO",E4:E500,"=radio") -> 4 | X2: =COUNTIFS(X4:X500, "=APAGADO",E4:E500,"=radio") -> 7 | Y2: =COUNTIFS(Y4:Y500, "=APAGADO",E4:E500,"=radio") -> 2 | Z2: =COUNTIFS(Z4:Z500, "=APAGADO",E4:E500,"=radio") -> 6 | AA2: =COUNTIFS(AA4:AA500, "=APAGADO",E4:E500,"=radio") -> 4 | AB2: =COUNTIFS(AB4:AB500, "=APAGADO",E4:E500,"=radio") -> 8 | AC2: =COUNTIFS(AC4:AC500, "=APAGADO",E4:E500,"=radio") -> 4 | AD2: =COUNTIFS(AD4:AD500, "=APAGADO",E4:E500,"=radio") -> 2 | AE2: =COUNTIFS(AE4:AE500, "=APAGADO",E4:E500,"=radio") -> 5 | AF2: =COUNTIFS(AF4:AF500, "=APAGADO",E4:E500,"=radio") -> 5 | AG2: =COUNTIFS(AG4:AG500, "=APAGADO",E4:E500,"=radio") -> 4 | AH2: =COUNTIFS(AH4:AH500, "=APAGADO",E4:E500,"=radio") -> 5 | AI2: =COUNTIFS(AI4:AI500, "=APAGADO",E4:E500,"=radio") -> 0
A3: =ESTADISTICA!A1 -> Barrio | B3: =ESTADISTICA!B1 -> [Denominacion] | C3: =ESTADISTICA!C1 -> [Ubicacion] | D3: =ESTADISTICA!D1 -> [Tipo de Camara] | E3: =ESTADISTICA!E1 -> [Tipo de Conexion] | F3: =ESTADISTICA!F1 -> 44866 | G3: =ESTADISTICA!G1 -> 44867 | H3: =ESTADISTICA!H1 -> 44868 | ... AI3: =ESTADISTICA!AI1 -> 44895
A4: =ESTADISTICA!A2 -> ALTAMIRA | B4: =ESTADISTICA!B2 -> ALT01 | C4: =ESTADISTICA!C2 -> Calchaqui y Sgto. Cabral | D4: =ESTADISTICA!D2 -> Domo | E4: =ESTADISTICA!E2 -> Fibra Optica | F4: =ESTADISTICA!F2 -> 0 | G4: =ESTADISTICA!G2 -> 0 | H4: =ESTADISTICA!H2 -> 0 | ... AI4: =ESTADISTICA!AI2 -> 0
A5: =ESTADISTICA!A3 -> ALTAMIRA | B5: =ESTADISTICA!B3 -> ALT02 | C5: =ESTADISTICA!C3 -> Calchaqui y Lope de Vega | D5: =ESTADISTICA!D3 -> Domo | E5: =ESTADISTICA!E3 -> PTO A FO | F5: =ESTADISTICA!F3 -> 0 | G5: =ESTADISTICA!G3 -> 0 | H5: =ESTADISTICA!H3 -> 0 | ... AI5: =ESTADISTICA!AI3 -> 0
A6: =ESTADISTICA!A4 -> ALTAMIRA | B6: =ESTADISTICA!B4 -> ALT 03 | C6: =ESTADISTICA!C4 -> Bombero Galarza y Necochea | D6: =ESTADISTICA!D4 -> Domo | E6: =ESTADISTICA!E4 -> FIBRA OPTICA | F6: =ESTADISTICA!F4 -> 0 | G6: =ESTADISTICA!G4 -> 0 | H6: =ESTADISTICA!H4 -> 0 | ... AI6: =ESTADISTICA!AI4 -> 0
A7: =ESTADISTICA!A5 -> ALTAMIRA | B7: =ESTADISTICA!B5 -> ALT 04 | C7: =ESTADISTICA!C5 -> Francia y Necochea | D7: =ESTADISTICA!D5 -> Domo | E7: =ESTADISTICA!E5 -> FIBRA OPTICA | F7: =ESTADISTICA!F5 -> 0 | G7: =ESTADISTICA!G5 -> 0 | H7: =ESTADISTICA!H5 -> 0 | ... AI7: =ESTADISTICA!AI5 -> 0
A8: =ESTADISTICA!A6 -> ALTAMIRA | B8: =ESTADISTICA!B6 -> ALT05 | C8: =ESTADISTICA!C6 -> Av. Calchaqui y Bombero Galarza | D8: =ESTADISTICA!D6 -> Domo | E8: =ESTADISTICA!E6 -> PTO A FO | F8: =ESTADISTICA!F6 -> 0 | G8: =ESTADISTICA!G6 -> 0 | H8: =ESTADISTICA!H6 -> 0 | ... AI8: =ESTADISTICA!AI6 -> 0
A9: =ESTADISTICA!A7 -> ALTAMIRA | B9: =ESTADISTICA!B7 -> ALT 06 | C9: =ESTADISTICA!C7 -> LOPE DE VEGA Y NECOCHEA | D9: =ESTADISTICA!D7 -> Domo | E9: =ESTADISTICA!E7 -> PTO A FO | F9: =ESTADISTICA!F7 -> 0 | G9: =ESTADISTICA!G7 -> 0 | H9: =ESTADISTICA!H7 -> 0 | ... AI9: =ESTADISTICA!AI7 -> 0
A10: =ESTADISTICA!A8 -> ALTAMIRA | B10: =ESTADISTICA!B8 -> ALT07 | C10: =ESTADISTICA!C8 -> AV. CALCHAQUI Y AV. DEL TRABAJO | D10: =ESTADISTICA!D8 -> DOMO | E10: =ESTADISTICA!E8 -> PTO A FO | F10: =ESTADISTICA!F8 -> 0 | G10: =ESTADISTICA!G8 -> 0 | H10: =ESTADISTICA!H8 -> 0 | ... AI10: =ESTADISTICA!AI8 -> 0
A11: =ESTADISTICA!A9 -> ALTAMIRA | B11: =ESTADISTICA!B9 -> ALT 08 | C11: =ESTADISTICA!C9 -> HUMAITA Y NECOCHEA | D11: =ESTADISTICA!D9 -> DOMO | E11: =ESTADISTICA!E9 -> Fibra Optica | F11: =ESTADISTICA!F9 -> 0 | G11: =ESTADISTICA!G9 -> 0 | H11: =ESTADISTICA!H9 -> 0 | ... AI11: =ESTADISTICA!AI9 -> 0
A12: =ESTADISTICA!A10 -> ALTAMIRA | B12: =ESTADISTICA!B10 -> ALT 09 | C12: =ESTADISTICA!C10 -> NECOCHEA Y CURUPAITY | D12: =ESTADISTICA!D10 -> DOMO | E12: =ESTADISTICA!E10 -> Fibra Optica | F12: =ESTADISTICA!F10 -> 0 | G12: =ESTADISTICA!G10 -> 0 | H12: =ESTADISTICA!H10 -> 0 | ... AI12: =ESTADISTICA!AI10 -> 0
A13: =ESTADISTICA!A11 -> ALTAMIRA | B13: =ESTADISTICA!B11 -> ALT 10 | C13: =ESTADISTICA!C11 -> Calchaqui y Francia | D13: =ESTADISTICA!D11 -> Domo | E13: =ESTADISTICA!E11 -> Radio | F13: =ESTADISTICA!F11 -> 0 | G13: =ESTADISTICA!G11 -> 0 | H13: =ESTADISTICA!H11 -> 0 | ... AI13: =ESTADISTICA!AI11 -> 0
A14: =ESTADISTICA!A12 -> AGUSTIN RAMIREZ | B14: =ESTADISTICA!B12 -> ARA 01 | C14: =ESTADISTICA!C12 -> Malambo y Tranquera | D14: =ESTADISTICA!D12 -> Domo | E14: =ESTADISTICA!E12 -> FIBRA OPTICA | F14: =ESTADISTICA!F12 -> 0 | G14: =ESTADISTICA!G12 -> 0 | H14: =ESTADISTICA!H12 -> 0 | ... AI14: =ESTADISTICA!AI12 -> 0
... A278: =ESTADISTICA!A276 -> SAN EMILIO | B278: =ESTADISTICA!B276 -> SEMI 02 | C278: =ESTADISTICA!C276 -> Cno. Gral. Belgrano y Francia | D278: =ESTADISTICA!D276 -> Domo | E278: =ESTADISTICA!E276 -> FIBRA OPTICA | F278: =ESTADISTICA!F276 -> 0 | G278: =ESTADISTICA!G276 -> 0 | H278: =ESTADISTICA!H276 -> 0 | ... AI278: =ESTADISTICA!AI276 -> 0
