Workbook
Name _25_de_agosto: 'RESUMEN TOTAL'!$A$4:$D$349

Sheet RESUMEN TOTAL
A1: CANTIDAD DE CAMARAS | B1: =COUNTA(B5:B527) -> 392 | D1: PORCIENTO DE CAIDAS | O1: =(O3)/(O2+O3) -> 0.093333333 | P1: =(P3)/(P2+P3) -> 0.088 | Q1: =(Q3)/(Q2+Q3) -> 0.096 | R1: =(R3)/(R2+R3) -> 0.10666667 | S1: =(S3)/(S2+S3) -> 0.085561497 | T1: =(T3)/(T2+T3) -> 0 | U1: =(U3)/(U2+U3) -> 0.152 | V1: =(V3)/(V2+V3) -> 0.128 | ... AS1: =(AS3)/(AS2+AS3) -> 0
D2: FUNCIONAN | O2: =COUNTIF(O5:O379, "") -> 340 | P2: =COUNTIF(P5:P379, "") -> 342 | Q2: =COUNTIF(Q5:Q379, "") -> 339 | R2: =COUNTIF(R5:R379, "") -> 335 | S2: =COUNTIF(S5:S379, "") -> 342 | T2: =COUNTIF(T5:T379, "") -> 375 | U2: =COUNTIF(U5:U379, "") -> 318 | V2: =COUNTIF(V5:V379, "") -> 327 | ... AS2: =COUNTIF(AS5:AS379, "") -> 375
D3: CAIDAS | O3: =COUNTIF(O4:O447, "apagado") -> 35 | P3: =COUNTIF(P4:P447, "apagado") -> 33 | Q3: =COUNTIF(Q4:Q447, "apagado") -> 36 | R3: =COUNTIF(R4:R447, "apagado") -> 40 | S3: =COUNTIF(S4:S447, "apagado") -> 32 | T3: =COUNTIF(T4:T447, "apagado") -> 0 | U3: =COUNTIF(U4:U447, "apagado") -> 57 | V3: =COUNTIF(V4:V447, "apagado") -> 48 | ... AS3: =COUNTIF(AS4:AS447, "apagado") -> 0
A4: Barrio | B4: [Denominacion] | C4: [Empresa Mantenimiento] | D4: [Ubicacion] | E4: [Tipo de Camara] | F4: [Tipo de Conexion] | G4: [Fundamento] | H4: [Detalle] | I4: Latitud | J4: Longitud | L4: DIAS FUNCIONANDO | M4: DIAS CAIDA | N4: EFECTIVIDAD | O4: 44743 | P4: 44744 | Q4: 44745 | R4: 44746 | S4: 44747 | T4: 44748 | U4: 44749 | V4: 44750 | W4: 44751 | X4: 44752 | Y4: 44753 | Z4: 44754 | AA4: 44755 | AB4: 44756 | AC4: 44757 | AD4: 44758 | AE4: 44759 | AF4: 44760 | AG4: 44761 | AH4: 44762 | AI4: 44763 | AJ4: 44764 | AK4: 44765 | AL4: 44766 | AM4: 44767 | AN4: 44768 | AO4: 44769 | AP4: 44770 | AQ4: 44771 | AR4: 44772 | AS4: 44773
A5: ALTAMIRA | B5: ALT 03 | C5: BONOMO | D5: Bombero Galarza y Necochea | E5: Domo | F5: FIBRA OPTICA | G5: Hospital, Limite del Partido | I5: -347726570000 | J5: -582730620000 | K5: 172.20.12.54 | L5: =COUNTIF(O5:AR5,"") -> 29 | M5: =COUNTIF(O5:AP5,"APAGADO") -> 1 | N5: =(L5)/(M5+L5) -> 0.96666667 | AE5: APAGADO
A6: ALTAMIRA | B6: ALT 04 | C6: BONOMO | D6: Francia y Necochea | E6: Domo | F6: FIBRA OPTICA | G6: Zona RecreaciÃ³n | I6: -347705420000 | J6: -582748000000 | K6: 172.20.12.55 | L6: =COUNTIF(O6:AR6,"") -> 30 | M6: =COUNTIF(O6:AP6,"APAGADO") -> 0 | N6: =(L6)/(M6+L6) -> 1
A7: ALTAMIRA | B7: ALT 06 | C7: BONOMO | D7: LOPE DE VEGA Y NECOCHEA | E7: Domo | F7: PTO A FO | H7: Instalada sin alta en sistema. ALTA en sistema y en funcionamiento 04/05/2020 | I7: -347738090000 | J7: -582721410000 | K7: 172.20.12.12 | L7: =COUNTIF(O7:AR7,"") -> 11 | M7: =COUNTIF(O7:AP7,"APAGADO") -> 19 | N7: =(L7)/(M7+L7) -> 0.36666667 | O7: APAGADO | P7: APAGADO | Q7: APAGADO | R7: APAGADO | S7: APAGADO | U7: APAGADO | V7: APAGADO | W7: APAGADO | X7: APAGADO | Y7: APAGADO | Z7: APAGADO | AA7: APAGADO | AB7: APAGADO | AC7: APAGADO | AD7: APAGADO | AE7: APAGADO | AF7: APAGADO | AG7: APAGADO | AH7: APAGADO
A8: ALTAMIRA | B8: ALT 08 | C8: BONOMO | D8: HUMAITA Y NECOCHEA | E8: DOMO | F8: Fibra Optica | H8: REPORTA IMAGENES 20/08/2021 | I8: -347749440000 | J8: -582711610000 | K8: 172.20.11.215 | L8: =COUNTIF(O8:AR8,"") -> 29 | M8: =COUNTIF(O8:AP8,"APAGADO") -> 1 | N8: =(L8)/(M8+L8) -> 0.96666667 | Y8: APAGADO
A9: ALTAMIRA | B9: ALT 09 | C9: BONOMO | D9: NECOCHEA Y CURUPAITY | E9: DOMO | F9: Fibra Optica | H9: SE DA DE ALTA 25/08/2021 | I9: -347743740000 | J9: -582715650000 | K9: 172.20.11.216 | L9: =COUNTIF(O9:AR9,"") -> 30 | M9: =COUNTIF(O9:AP9,"APAGADO") -> 0 | N9: =(L9)/(M9+L9) -> 1
A10: ALTAMIRA | B10: ALT 10 | C10: BONOMO | D10: Calchaqui y Francia | E10: Domo | F10: Radio | G10: Flujo Vehicular, Limite del Partido, Posible Via de Escape | I10: -347688500000 | J10: -582717420000 | L10: =COUNTIF(O10:AR10,"") -> 25 | M10: =COUNTIF(O10:AP10,"APAGADO") -> 5 | N10: =(L10)/(M10+L10) -> 0.83333333 | U10: APAGADO | V10: APAGADO | Z10: APAGADO | AA10: APAGADO | AB10: APAGADO
A11: ALTAMIRA | B11: ALT01 | C11: BONOMO | D11: Calchaqui y Sgto. Cabral | E11: Domo | F11: Fibra Optica | G11: Universidad, Zona Bancaria, Flujo Vehicular, Posible Via de Escape | I11: -347769580000 | J11: -582650900000 | K11: 172.20.10.6 | L11: =COUNTIF(O11:AR11,"") -> 30 | M11: =COUNTIF(O11:AP11,"APAGADO") -> 0 | N11: =(L11)/(M11+L11) -> 1
A12: ALTAMIRA | B12: ALT02 | C12: BONOMO | D12: Calchaqui y Lope de Vega | E12: Domo | F12: PTO A FO | G12: Hospital, Flujo Vehicular, Peatonal | I12: -347718470000 | J12: -582688560000 | K12: 172.20.12.218 | L12: =COUNTIF(O12:AR12,"") -> 30 | M12: =COUNTIF(O12:AP12,"APAGADO") -> 0 | N12: =(L12)/(M12+L12) -> 1
A13: ALTAMIRA | B13: ALT05 | C13: BONOMO | D13: Av. Calchaqui y Bombero Galarza | E13: Domo | F13: PTO A FO | G13: Zona Bancaria, Flujo Vehicular, Posible via de escape, Limite del partido | I13: -347708370000 | J13: -582698000000 | K13: 172.20.12.216 | L13: =COUNTIF(O13:AR13,"") -> 28 | M13: =COUNTIF(O13:AP13,"APAGADO") -> 2 | N13: =(L13)/(M13+L13) -> 0.93333333 | U13: APAGADO | V13: APAGADO
A14: ALTAMIRA | B14: ALT07 | C14: BONOMO | D14: AV. CALCHAQUI Y AV. DEL TRABAJO | E14: DOMO | F14: PTO A FO | H14: SE DA DE ALTA EL 17/09/2020 18:51HS | I14: -347737570000 | J14: -582676650000 | K14: 172.20.10.57 | L14: =COUNTIF(O14:AR14,"") -> 28 | M14: =COUNTIF(O14:AP14,"APAGADO") -> 2 | N14: =(L14)/(M14+L14) -> 0.93333333 | U14: APAGADO | V14: APAGADO
A15: AGUSTIN RAMIREZ | B15: ARA 01 | C15: COSEIDI | D15: Malambo y Tranquera | E15: Domo | F15: FIBRA OPTICA | G15: Zona Escolar, Flujo Vehicular | I15: -347979380000 | J15: -583160950000 | K15: 172.20.12.110 | L15: =COUNTIF(O15:AR15,"") -> 29 | M15: =COUNTIF(O15:AP15,"APAGADO") -> 0 | N15: =(L15)/(M15+L15) -> 1 | AQ15: APAGADO
A16: BELGRANO | B16: BEL 01 | C16: BONOMO | D16: San Martin y Dardo Rocha | E16: DOMO | F16: FIBRA OPTICA | G16: Zona Escolar, Flujo Vehicular | H16: 19/03/2020 SE RETIRO DISPOSITIVO POR RIESGO DE CAIDA. 19/08/2020 comenzo a funcionar. | I16: -347918370000 | J16: -582786080000 | K16: 172.20.12.64 | L16: =COUNTIF(O16:AR16,"") -> 26 | M16: =COUNTIF(O16:AP16,"APAGADO") -> 4 | N16: =(L16)/(M16+L16) -> 0.86666667 | AK16: APAGADO | AM16: APAGADO | AN16: APAGADO | AO16: APAGADO
A17: CENTRO | B17: CEN 05 | C17: BONOMO | D17: Bocuzzi e/EspaÃ±a y San Martin | E17: DOMO | F17: Fibra Optica | G17: Zona Bancaria, Flujo Vehicular | H17: 03/01/19 se realizo cambio de dispositivo de fija a DOMO. | I17: -348100680000 | J17: -582769560000 | K17: 172.20.10.200 | L17: =COUNTIF(O17:AR17,"") -> 28 | M17: =COUNTIF(O17:AP17,"APAGADO") -> 2 | N17: =(L17)/(M17+L17) -> 0.93333333 | U17: APAGADO | V17: APAGADO
A18: CENTRO | B18: CEN 12 | C18: BONOMO | D18: Monteagudo y Mitre | E18: Domo | F18: Fibra Optica | G18: Zona Comercial, Zona Bancaria, Peatonal | I18: -348088700000 | J18: -582747030000 | K18: 172.20.10.23 | L18: =COUNTIF(O18:AR18,"") -> 28 | M18: =COUNTIF(O18:AP18,"APAGADO") -> 2 | N18: =(L18)/(M18+L18) -> 0.93333333 | U18: APAGADO | V18: APAGADO
A19: CENTRO | B19: CEN 13 | C19: BONOMO | D19: 25 de Mayo y Maipu | E19: DOMO | F19: Fibra Optica | G19: Zona Escolar, Zona de RecreaciÃ³n | I19: -348050030000 | J19: -582802180000 | K19: 172.20.10.20 | L19: =COUNTIF(O19:AR19,"") -> 30 | M19: =COUNTIF(O19:AP19,"APAGADO") -> 0 | N19: =(L19)/(M19+L19) -> 1
A20: CENTRO | B20: CEN 37 | C20: BONOMO | D20: Diagonal Granaderos y Monteagudo | E20: Domo | F20: Fibra Optica | G20: Zona de Recreacion | I20: -347974350000 | J20: -582751320000 | K20: 172.20.12.52 | L20: =COUNTIF(O20:AR20,"") -> 30 | M20: =COUNTIF(O20:AP20,"APAGADO") -> 0 | N20: =(L20)/(M20+L20) -> 1
A21: CENTRO | B21: CEN 50 | C21: BONOMO | D21: Av. San Martin y Newbery | E21: Domo | F21: Radio | G21: Flujo Vehicular, Zona Comercial,Vecindad con establecimiento educativo, Futuro corredor escolar | H21: PIXELADA Y CAIDA FRECUENTE | I21: -348070120000 | J21: -582783830000 | K21: 172.20.200.184 | L21: =COUNTIF(O21:AR21,"") -> 27 | M21: =COUNTIF(O21:AP21,"APAGADO") -> 2 | N21: =(L21)/(M21+L21) -> 0.93103448 | W21: APAGADO | X21: APAGADO | AR21: APAGADO
A22: CENTRO | B22: CEN 51 | C22: BONOMO | D22: ILLIA Y LAS HERAS | E22: FIJA | F22: Fibra Optica | G22: POSIBLE VIA DE ESCAPE, Y FLUJO VEHICULAR | I22: -347987830000 | J22: -582840920000 | K22: 172.20.11.29 | L22: =COUNTIF(O22:AR22,"") -> 23 | M22: =COUNTIF(O22:AP22,"APAGADO") -> 6 | N22: =(L22)/(M22+L22) -> 0.79310345 | AK22: APAGADO | AL22: APAGADO | AM22: APAGADO | AN22: APAGADO | AO22: APAGADO | AP22: APAGADO | AQ22: APAGADO
A23: CENTRO | B23: CEN 53 | C23: BONOMO | D23: GUTIERREZ Y BROWN | E23: Domo | F23: Radio | I23: -348013650000 | J23: -582715700000 | K23: 172.20.200.166 | L23: =COUNTIF(O23:AR23,"") -> 30 | M23: =COUNTIF(O23:AP23,"APAGADO") -> 0 | N23: =(L23)/(M23+L23) -> 1
A24: CENTRO | B24: CEN 54 | C24: BONOMO | D24: GUTIERREZ Y PRINGLES | E24: Domo | F24: Radio | I24: -348013470000 | J24: -582698540000 | K24: 172.20.200.165 | L24: =COUNTIF(O24:AR24,"") -> 30 | M24: =COUNTIF(O24:AP24,"APAGADO") -> 0 | N24: =(L24)/(M24+L24) -> 1
A25: CENTRO | B25: CEN 55 | C25: BONOMO | D25: BOUREL Y URQUIZA | E25: Domo | F25: Radio | I25: -348019110000 | J25: -582819990000 | K25: 172.20.200.163 | L25: =COUNTIF(O25:AR25,"") -> 30 | M25: =COUNTIF(O25:AP25,"APAGADO") -> 0 | N25: =(L25)/(M25+L25) -> 1
A26: CENTRO | B26: CEN 56 | C26: BONOMO | D26: Newbery y Falucho | E26: DOMO | F26: Radio | G26: Posible via de escape, Cruce Peligroso | I26: -348073990000 | J26: -582850080000 | K26: 172.20.200.161 | L26: =COUNTIF(O26:AR26,"") -> 30 | M26: =COUNTIF(O26:AP26,"APAGADO") -> 0 | N26: =(L26)/(M26+L26) -> 1
A27: CENTRO | B27: CEN 57 | C27: BONOMO | D27: 25 DE MAYO Y DORREGO | E27: DOMO | F27: Radio | I27: -348007360000 | J27: -582804240000 | K27: 172.20.200.199 | L27: =COUNTIF(O27:AR27,"") -> 30 | M27: =COUNTIF(O27:AP27,"APAGADO") -> 0 | N27: =(L27)/(M27+L27) -> 1
A28: CENTRO | B28: CEN 58 | C28: BONOMO | D28: EEUU Y MORENO | E28: DOMO | F28: FIBRA OPTICA | H28: INSTALADA: 11/06/18. EN FUNCIONAMIENTO: 27/06/18. | I28: -348103030000 | J28: -582835720000 | K28: 172.20.11.84 | L28: =COUNTIF(O28:AR28,"") -> 30 | M28: =COUNTIF(O28:AP28,"APAGADO") -> 0 | N28: =(L28)/(M28+L28) -> 1
A29: CENTRO | B29: CEN 60 | C29: BONOMO | D29: RECONQUISTA Y ILLIA | E29: DOMO | F29: PTO A FO | H29: ALTA 26/10/2019 | I29: -347999170000 | J29: -582863530000 | K29: 172.20.12.67 | L29: =COUNTIF(O29:AR29,"") -> 23 | M29: =COUNTIF(O29:AP29,"APAGADO") -> 6 | N29: =(L29)/(M29+L29) -> 0.79310345 | AK29: APAGADO | AL29: APAGADO | AM29: APAGADO | AN29: APAGADO | AO29: APAGADO | AP29: APAGADO | AQ29: APAGADO
A30: CENTRO | B30: CEN 61 | C30: BONOMO | D30: BOUREL Y MAIPU | E30: DOMO | F30: Radio | H30: ALTA EN FUNCIONAMIENTO 12/04/2019 | I30: -348040550000 | J30: -582819380000 | K30: 172.20.200.159 | L30: =COUNTIF(O30:AR30,"") -> 30 | M30: =COUNTIF(O30:AP30,"APAGADO") -> 0 | N30: =(L30)/(M30+L30) -> 1
A31: CENTRO | B31: CEN 65 | C31: BONOMO | D31: SAN MARTIN Y JUAN PERON | E31: FIJA | F31: Fibra Optica | H31: EN FUNCIONAMIENTO 14/07/2021 | I31: -348107920000 | J31: -582777490000 | K31: 172.20.11.135 | L31: =COUNTIF(O31:AR31,"") -> 30 | M31: =COUNTIF(O31:AP31,"APAGADO") -> 0 | N31: =(L31)/(M31+L31) -> 1
A32: CENTRO | B32: CEN 70 | C32: BONOMO | D32: RIVADAVIA Y 25 MAYO | E32: Domo | F32: Fibra Optica | H32: alta en sistema 25/11/2021 | I32: -348091950000 | J32: -582800930000 | K32: 172.20.11.221 | L32: =COUNTIF(O32:AR32,"") -> 30 | M32: =COUNTIF(O32:AP32,"APAGADO") -> 0 | N32: =(L32)/(M32+L32) -> 1
A33: CENTRO | B33: CEN 71 | C33: BONOMO | D33: MORENO Y BOUREL | E33: Domo | F33: Fibra Optica | H33: alta en sistema 25/11/2021 | I33: -348103130000 | J33: -582818230000 | K33: 172.20.11.220 | L33: =COUNTIF(O33:AR33,"") -> 30 | M33: =COUNTIF(O33:AP33,"APAGADO") -> 0 | N33: =(L33)/(M33+L33) -> 1
A34: CENTRO | B34: CEN 72 | C34: BONOMO | D34: MORENO Y 25 DE MAYO | E34: Domo | F34: Fibra Optica | H34: ALTA EN SISTEMA 25/11/2021 | I34: -348102250000 | J34: -582800780000 | K34: 172.20.11.219 | L34: =COUNTIF(O34:AR34,"") -> 19 | M34: =COUNTIF(O34:AP34,"APAGADO") -> 9 | N34: =(L34)/(M34+L34) -> 0.67857143 | AH34: APAGADO | AI34: APAGADO | AJ34: APAGADO | AK34: APAGADO | AL34: APAGADO | AM34: APAGADO | AN34: APAGADO | AO34: APAGADO | AP34: APAGADO | AQ34: APAGADO | AR34: APAGADO
A35: CENTRO | B35: CEN 75 | C35: BONOMO | D35: 25 DE MAYO Y CASTELLI | E35: Domo | F35: Fibra Optica | I35: -348029280000 | J35: -582802660000 | L35: =COUNTIF(O35:AR35,"") -> 30 | M35: =COUNTIF(O35:AP35,"APAGADO") -> 0 | N35: =(L35)/(M35+L35) -> 1
A36: CENTRO | B36: CEN 76 | C36: BONOMO | D36: ESPAÃ‘A E/MITRE Y BOCUZZI | E36: Fija | F36: Fibra Optica | I36: -348093870000 | J36: -582762530000 | L36: =COUNTIF(O36:AR36,"") -> 13 | M36: =COUNTIF(O36:AP36,"APAGADO") -> 17 | N36: =(L36)/(M36+L36) -> 0.43333333 | P36: APAGADO | Q36: APAGADO | R36: APAGADO | S36: APAGADO | U36: APAGADO | V36: APAGADO | W36: APAGADO | X36: APAGADO | Y36: APAGADO | Z36: APAGADO | AA36: APAGADO | AB36: APAGADO | AC36: APAGADO | AD36: APAGADO | AE36: APAGADO | AF36: APAGADO | AG36: APAGADO
A37: CENTRO | B37: CEN01 | C37: BONOMO | D37: San Martin y 9 de Julio | E37: Fija | F37: Fibra Optica | G37: Zona Comercial, Flujo Vehicular | I37: -348028100000 | J37: -582782860000 | K37: 172.20.11.10 | L37: =COUNTIF(O37:AR37,"") -> 30 | M37: =COUNTIF(O37:AP37,"APAGADO") -> 0 | N37: =(L37)/(M37+L37) -> 1
A38: CENTRO | B38: CEN02 | C38: BONOMO | D38: San Martin y Almafuerte | E38: Fija | F38: Fibra Optica | G38: Bomberos, Flujo Vehicular, Zona Comercial | I38: -348006070000 | J38: -582784580000 | K38: 172.20.11.11 | L38: =COUNTIF(O38:AR38,"") -> 29 | M38: =COUNTIF(O38:AP38,"APAGADO") -> 0 | N38: =(L38)/(M38+L38) -> 1 | AR38: APAGADO
A39: CENTRO | B39: CEN03 | C39: BONOMO | D39: San Martin y Sallares | E39: Domo | F39: Fibra Optica | G39: Zona Comercial, Flujo Vehicular | H39: 29/03/19 FUNCIONA EN COD 1 | I39: -348080340000 | J39: -582780930000 | K39: 172.20.12.30 | L39: =COUNTIF(O39:AR39,"") -> 30 | M39: =COUNTIF(O39:AP39,"APAGADO") -> 0 | N39: =(L39)/(M39+L39) -> 1
A40: CENTRO | B40: CEN04 | C40: BONOMO | D40: San Martin y Contreras | E40: Domo | F40: Fibra Optica | G40: Zona de recreaciÃ³n, Flujo vehicular | I40: -348049240000 | J40: -582781680000 | K40: 172.20.12.29 | L40: =COUNTIF(O40:AR40,"") -> 30 | M40: =COUNTIF(O40:AP40,"APAGADO") -> 0 | N40: =(L40)/(M40+L40) -> 1
...

Sheet ESTADISTICA
A1: ='RESUMEN TOTAL'!A4 -> Barrio | B1: ='RESUMEN TOTAL'!B4 -> [Denominacion] | C1: ='RESUMEN TOTAL'!D4 -> [Ubicacion] | D1: ='RESUMEN TOTAL'!E4 -> [Tipo de Camara] | E1: ='RESUMEN TOTAL'!F4 -> [Tipo de Conexion] | F1: ='RESUMEN TOTAL'!O4 -> 44743 | G1: ='RESUMEN TOTAL'!P4 -> 44744 | H1: ='RESUMEN TOTAL'!Q4 -> 44745 | I1: ='RESUMEN TOTAL'!R4 -> 44746 | J1: ='RESUMEN TOTAL'!S4 -> 44747 | K1: ='RESUMEN TOTAL'!T4 -> 44748 | L1: ='RESUMEN TOTAL'!U4 -> 44749 | M1: ='RESUMEN TOTAL'!V4 -> 44750 | ... AI1: ='RESUMEN TOTAL'!AR4 -> 44772
A2: ='RESUMEN TOTAL'!A5 -> ALTAMIRA | B2: ='RESUMEN TOTAL'!B5 -> ALT 03 | C2: ='RESUMEN TOTAL'!D5 -> Bombero Galarza y Necochea | D2: ='RESUMEN TOTAL'!E5 -> Domo | E2: ='RESUMEN TOTAL'!F5 -> FIBRA OPTICA | F2: ='RESUMEN TOTAL'!O5 -> 0 | G2: ='RESUMEN TOTAL'!P5 -> 0 | H2: ='RESUMEN TOTAL'!Q5 -> 0 | I2: ='RESUMEN TOTAL'!R5 -> 0 | J2: ='RESUMEN TOTAL'!S5 -> 0 | K2: ='RESUMEN TOTAL'!T5 -> 0 | L2: ='RESUMEN TOTAL'!U5 -> 0 | M2: ='RESUMEN TOTAL'!V5 -> 0 | ... AI2: ='RESUMEN TOTAL'!AR5 -> 0
A3: ='RESUMEN TOTAL'!A6 -> ALTAMIRA | B3: ='RESUMEN TOTAL'!B6 -> ALT 04 | C3: ='RESUMEN TOTAL'!D6 -> Francia y Necochea | D3: ='RESUMEN TOTAL'!E6 -> Domo | E3: ='RESUMEN TOTAL'!F6 -> FIBRA OPTICA | F3: ='RESUMEN TOTAL'!O6 -> 0 | G3: ='RESUMEN TOTAL'!P6 -> 0 | H3: ='RESUMEN TOTAL'!Q6 -> 0 | I3: ='RESUMEN TOTAL'!R6 -> 0 | J3: ='RESUMEN TOTAL'!S6 -> 0 | K3: ='RESUMEN TOTAL'!T6 -> 0 | L3: ='RESUMEN TOTAL'!U6 -> 0 | M3: ='RESUMEN TOTAL'!V6 -> 0 | ... AI3: ='RESUMEN TOTAL'!AR6 -> 0
A4: ='RESUMEN TOTAL'!A7 -> ALTAMIRA | B4: ='RESUMEN TOTAL'!B7 -> ALT 06 | C4: ='RESUMEN TOTAL'!D7 -> LOPE DE VEGA Y NECOCHEA | D4: ='RESUMEN TOTAL'!E7 -> Domo | E4: ='RESUMEN TOTAL'!F7 -> PTO A FO | F4: ='RESUMEN TOTAL'!O7 -> APAGADO | G4: ='RESUMEN TOTAL'!P7 -> APAGADO | H4: ='RESUMEN TOTAL'!Q7 -> APAGADO | I4: ='RESUMEN TOTAL'!R7 -> APAGADO | J4: ='RESUMEN TOTAL'!S7 -> APAGADO | K4: ='RESUMEN TOTAL'!T7 -> 0 | L4: ='RESUMEN TOTAL'!U7 -> APAGADO | M4: ='RESUMEN TOTAL'!V7 -> APAGADO | ... AI4: ='RESUMEN TOTAL'!AR7 -> 0
A5: ='RESUMEN TOTAL'!A8 -> ALTAMIRA | B5: ='RESUMEN TOTAL'!B8 -> ALT 08 | C5: ='RESUMEN TOTAL'!D8 -> HUMAITA Y NECOCHEA | D5: ='RESUMEN TOTAL'!E8 -> DOMO | E5: ='RESUMEN TOTAL'!F8 -> Fibra Optica | F5: ='RESUMEN TOTAL'!O8 -> 0 | G5: ='RESUMEN TOTAL'!P8 -> 0 | H5: ='RESUMEN TOTAL'!Q8 -> 0 | I5: ='RESUMEN TOTAL'!R8 -> 0 | J5: ='RESUMEN TOTAL'!S8 -> 0 | K5: ='RESUMEN TOTAL'!T8 -> 0 | L5: ='RESUMEN TOTAL'!U8 -> 0 | M5: ='RESUMEN TOTAL'!V8 -> 0 | ... AI5: ='RESUMEN TOTAL'!AR8 -> 0
A6: ='RESUMEN TOTAL'!A9 -> ALTAMIRA | B6: ='RESUMEN TOTAL'!B9 -> ALT 09 | C6: ='RESUMEN TOTAL'!D9 -> NECOCHEA Y CURUPAITY | D6: ='RESUMEN TOTAL'!E9 -> DOMO | E6: ='RESUMEN TOTAL'!F9 -> Fibra Optica | F6: ='RESUMEN TOTAL'!O9 -> 0 | G6: ='RESUMEN TOTAL'!P9 -> 0 | H6: ='RESUMEN TOTAL'!Q9 -> 0 | I6: ='RESUMEN TOTAL'!R9 -> 0 | J6: ='RESUMEN TOTAL'!S9 -> 0 | K6: ='RESUMEN TOTAL'!T9 -> 0 | L6: ='RESUMEN TOTAL'!U9 -> 0 | M6: ='RESUMEN TOTAL'!V9 -> 0 | ... AI6: ='RESUMEN TOTAL'!AR9 -> 0
A7: ='RESUMEN TOTAL'!A10 -> ALTAMIRA | B7: ='RESUMEN TOTAL'!B10 -> ALT 10 | C7: ='RESUMEN TOTAL'!D10 -> Calchaqui y Francia | D7: ='RESUMEN TOTAL'!E10 -> Domo | E7: ='RESUMEN TOTAL'!F10 -> Radio | F7: ='RESUMEN TOTAL'!O10 -> 0 | G7: ='RESUMEN TOTAL'!P10 -> 0 | H7: ='RESUMEN TOTAL'!Q10 -> 0 | I7: ='RESUMEN TOTAL'!R10 -> 0 | J7: ='RESUMEN TOTAL'!S10 -> 0 | K7: ='RESUMEN TOTAL'!T10 -> 0 | L7: ='RESUMEN TOTAL'!U10 -> APAGADO | M7: ='RESUMEN TOTAL'!V10 -> APAGADO | ... AI7: ='RESUMEN TOTAL'!AR10 -> 0
A8: ='RESUMEN TOTAL'!A11 -> ALTAMIRA | B8: ='RESUMEN TOTAL'!B11 -> ALT01 | C8: ='RESUMEN TOTAL'!D11 -> Calchaqui y Sgto. Cabral | D8: ='RESUMEN TOTAL'!E11 -> Domo | E8: ='RESUMEN TOTAL'!F11 -> Fibra Optica | F8: ='RESUMEN TOTAL'!O11 -> 0 | G8: ='RESUMEN TOTAL'!P11 -> 0 | H8: ='RESUMEN TOTAL'!Q11 -> 0 | I8: ='RESUMEN TOTAL'!R11 -> 0 | J8: ='RESUMEN TOTAL'!S11 -> 0 | K8: ='RESUMEN TOTAL'!T11 -> 0 | L8: ='RESUMEN TOTAL'!U11 -> 0 | M8: ='RESUMEN TOTAL'!V11 -> 0 | ... AI8: ='RESUMEN TOTAL'!AR11 -> 0
A9: ='RESUMEN TOTAL'!A12 -> ALTAMIRA | B9: ='RESUMEN TOTAL'!B12 -> ALT02 | C9: ='RESUMEN TOTAL'!D12 -> Calchaqui y Lope de Vega | D9: ='RESUMEN TOTAL'!E12 -> Domo | E9: ='RESUMEN TOTAL'!F12 -> PTO A FO | F9: ='RESUMEN TOTAL'!O12 -> 0 | G9: ='RESUMEN TOTAL'!P12 -> 0 | H9: ='RESUMEN TOTAL'!Q12 -> 0 | I9: ='RESUMEN TOTAL'!R12 -> 0 | J9: ='RESUMEN TOTAL'!S12 -> 0 | K9: ='RESUMEN TOTAL'!T12 -> 0 | L9: ='RESUMEN TOTAL'!U12 -> 0 | M9: ='RESUMEN TOTAL'!V12 -> 0 | ... AI9: ='RESUMEN TOTAL'!AR12 -> 0
A10: ='RESUMEN TOTAL'!A13 -> ALTAMIRA | B10: ='RESUMEN TOTAL'!B13 -> ALT05 | C10: ='RESUMEN TOTAL'!D13 -> Av. Calchaqui y Bombero Galarza | D10: ='RESUMEN TOTAL'!E13 -> Domo | E10: ='RESUMEN TOTAL'!F13 -> PTO A FO | F10: ='RESUMEN TOTAL'!O13 -> 0 | G10: ='RESUMEN TOTAL'!P13 -> 0 | H10: ='RESUMEN TOTAL'!Q13 -> 0 | I10: ='RESUMEN TOTAL'!R13 -> 0 | J10: ='RESUMEN TOTAL'!S13 -> 0 | K10: ='RESUMEN TOTAL'!T13 -> 0 | L10: ='RESUMEN TOTAL'!U13 -> APAGADO | M10: ='RESUMEN TOTAL'!V13 -> APAGADO | ... AI10: ='RESUMEN TOTAL'!AR13 -> 0
A11: ='RESUMEN TOTAL'!A14 -> ALTAMIRA | B11: ='RESUMEN TOTAL'!B14 -> ALT07 | C11: ='RESUMEN TOTAL'!D14 -> AV. CALCHAQUI Y AV. DEL TRABAJO | D11: ='RESUMEN TOTAL'!E14 -> DOMO | E11: ='RESUMEN TOTAL'!F14 -> PTO A FO | F11: ='RESUMEN TOTAL'!O14 -> 0 | G11: ='RESUMEN TOTAL'!P14 -> 0 | H11: ='RESUMEN TOTAL'!Q14 -> 0 | I11: ='RESUMEN TOTAL'!R14 -> 0 | J11: ='RESUMEN TOTAL'!S14 -> 0 | K11: ='RESUMEN TOTAL'!T14 -> 0 | L11: ='RESUMEN TOTAL'!U14 -> APAGADO | M11: ='RESUMEN TOTAL'!V14 -> APAGADO | ... AI11: ='RESUMEN TOTAL'!AR14 -> 0
A12: ='RESUMEN TOTAL'!A15 -> AGUSTIN RAMIREZ | B12: ='RESUMEN TOTAL'!B15 -> ARA 01 | C12: ='RESUMEN TOTAL'!D15 -> Malambo y Tranquera | D12: ='RESUMEN TOTAL'!E15 -> Domo | E12: ='RESUMEN TOTAL'!F15 -> FIBRA OPTICA | F12: ='RESUMEN TOTAL'!O15 -> 0 | G12: ='RESUMEN TOTAL'!P15 -> 0 | H12: ='RESUMEN TOTAL'!Q15 -> 0 | I12: ='RESUMEN TOTAL'!R15 -> 0 | J12: ='RESUMEN TOTAL'!S15 -> 0 | K12: ='RESUMEN TOTAL'!T15 -> 0 | L12: ='RESUMEN TOTAL'!U15 -> 0 | M12: ='RESUMEN TOTAL'!V15 -> 0 | ... AI12: ='RESUMEN TOTAL'!AR15 -> 0
... A399: ='RESUMEN TOTAL'!A402 -> 0 | B399: ='RESUMEN TOTAL'!B402 -> 0 | C399: ='RESUMEN TOTAL'!D402 -> 0 | D399: ='RESUMEN TOTAL'!E402 -> 0 | E399: ='RESUMEN TOTAL'!F402 -> 0 | F399: ='RESUMEN TOTAL'!O402 -> 0 | G399: ='RESUMEN TOTAL'!P402 -> 0 | H399: ='RESUMEN TOTAL'!Q402 -> 0 | I399: ='RESUMEN TOTAL'!R402 -> 0 | J399: ='RESUMEN TOTAL'!S402 -> 0 | K399: ='RESUMEN TOTAL'!T402 -> 0 | L399: ='RESUMEN TOTAL'!U402 -> 0 | M399: ='RESUMEN TOTAL'!V402 -> 0 | ... AI399: ='RESUMEN TOTAL'!AR402 -> 0

Sheet APAGADOS
E1: APAGADOS | F1: =COUNTIF(F3:F400, "APAGADO") -> 35 | G1: =COUNTIF(G3:G400, "APAGADO") -> 33 | H1: =COUNTIF(H3:H400, "APAGADO") -> 36 | I1: =COUNTIF(I3:I400, "APAGADO") -> 40 | J1: =COUNTIF(J3:J400, "APAGADO") -> 32 | K1: =COUNTIF(K3:K400, "APAGADO") -> 0 | L1: =COUNTIF(L3:L400, "APAGADO") -> 57 | M1: =COUNTIF(M3:M400, "APAGADO") -> 48 | ... AI1: =COUNTIF(AI3:AI400, "APAGADO") -> 87
A2: =ESTADISTICA!A1 -> Barrio | B2: =ESTADISTICA!B1 -> [Denominacion] | C2: =ESTADISTICA!C1 -> [Ubicacion] | D2: =ESTADISTICA!D1 -> [Tipo de Camara] | E2: =ESTADISTICA!E1 -> [Tipo de Conexion] | F2: =ESTADISTICA!F1 -> 44743 | G2: =ESTADISTICA!G1 -> 44744 | H2: =ESTADISTICA!H1 -> 44745 | ... AI2: =ESTADISTICA!AI1 -> 44772
A3: =ESTADISTICA!A2 -> ALTAMIRA | B3: =ESTADISTICA!B2 -> ALT 03 | C3: =ESTADISTICA!C2 -> Bombero Galarza y Necochea | D3: =ESTADISTICA!D2 -> Domo | E3: =ESTADISTICA!E2 -> FIBRA OPTICA | F3: =ESTADISTICA!F2 -> 0 | G3: =ESTADISTICA!G2 -> 0 | H3: =ESTADISTICA!H2 -> 0 | ... AI3: =ESTADISTICA!AI2 -> 0
A4: =ESTADISTICA!A3 -> ALTAMIRA | B4: =ESTADISTICA!B3 -> ALT 04 | C4: =ESTADISTICA!C3 -> Francia y Necochea | D4: =ESTADISTICA!D3 -> Domo | E4: =ESTADISTICA!E3 -> FIBRA OPTICA | F4: =ESTADISTICA!F3 -> 0 | G4: =ESTADISTICA!G3 -> 0 | H4: =ESTADISTICA!H3 -> 0 | ... AI4: =ESTADISTICA!AI3 -> 0
A5: =ESTADISTICA!A4 -> ALTAMIRA | B5: =ESTADISTICA!B4 -> ALT 06 | C5: =ESTADISTICA!C4 -> LOPE DE VEGA Y NECOCHEA | D5: =ESTADISTICA!D4 -> Domo | E5: =ESTADISTICA!E4 -> PTO A FO | F5: =ESTADISTICA!F4 -> APAGADO | G5: =ESTADISTICA!G4 -> APAGADO | H5: =ESTADISTICA!H4 -> APAGADO | ... AI5: =ESTADISTICA!AI4 -> 0
A6: =ESTADISTICA!A5 -> ALTAMIRA | B6: =ESTADISTICA!B5 -> ALT 08 | C6: =ESTADISTICA!C5 -> HUMAITA Y NECOCHEA | D6: =ESTADISTICA!D5 -> DOMO | E6: =ESTADISTICA!E5 -> Fibra Optica | F6: =ESTADISTICA!F5 -> 0 | G6: =ESTADISTICA!G5 -> 0 | H6: =ESTADISTICA!H5 -> 0 | ... AI6: =ESTADISTICA!AI5 -> 0
A7: =ESTADISTICA!A6 -> ALTAMIRA | B7: =ESTADISTICA!B6 -> ALT 09 | C7: =ESTADISTICA!C6 -> NECOCHEA Y CURUPAITY | D7: =ESTADISTICA!D6 -> DOMO | E7: =ESTADISTICA!E6 -> Fibra Optica | F7: =ESTADISTICA!F6 -> 0 | G7: =ESTADISTICA!G6 -> 0 | H7: =ESTADISTICA!H6 -> 0 | ... AI7: =ESTADISTICA!AI6 -> 0
A8: =ESTADISTICA!A7 -> ALTAMIRA | B8: =ESTADISTICA!B7 -> ALT 10 | C8: =ESTADISTICA!C7 -> Calchaqui y Francia | D8: =ESTADISTICA!D7 -> Domo | E8: =ESTADISTICA!E7 -> Radio | F8: =ESTADISTICA!F7 -> 0 | G8: =ESTADISTICA!G7 -> 0 | H8: =ESTADISTICA!H7 -> 0 | ... AI8: =ESTADISTICA!AI7 -> 0
A9: =ESTADISTICA!A8 -> ALTAMIRA | B9: =ESTADISTICA!B8 -> ALT01 | C9: =ESTADISTICA!C8 -> Calchaqui y Sgto. Cabral | D9: =ESTADISTICA!D8 -> Domo | E9: =ESTADISTICA!E8 -> Fibra Optica | F9: =ESTADISTICA!F8 -> 0 | G9: =ESTADISTICA!G8 -> 0 | H9: =ESTADISTICA!H8 -> 0 | ... AI9: =ESTADISTICA!AI8 -> 0
A10: =ESTADISTICA!A9 -> ALTAMIRA | B10: =ESTADISTICA!B9 -> ALT02 | C10: =ESTADISTICA!C9 -> Calchaqui y Lope de Vega | D10: =ESTADISTICA!D9 -> Domo | E10: =ESTADISTICA!E9 -> PTO A FO | F10: =ESTADISTICA!F9 -> 0 | G10: =ESTADISTICA!G9 -> 0 | H10: =ESTADISTICA!H9 -> 0 | ... AI10: =ESTADISTICA!AI9 -> 0
A11: =ESTADISTICA!A10 -> ALTAMIRA | B11: =ESTADISTICA!B10 -> ALT05 | C11: =ESTADISTICA!C10 -> Av. Calchaqui y Bombero Galarza | D11: =ESTADISTICA!D10 -> Domo | E11: =ESTADISTICA!E10 -> PTO A FO | F11: =ESTADISTICA!F10 -> 0 | G11: =ESTADISTICA!G10 -> 0 | H11: =ESTADISTICA!H10 -> 0 | ... AI11: =ESTADISTICA!AI10 -> 0
A12: =ESTADISTICA!A11 -> ALTAMIRA | B12: =ESTADISTICA!B11 -> ALT07 | C12: =ESTADISTICA!C11 -> AV. CALCHAQUI Y AV. DEL TRABAJO | D12: =ESTADISTICA!D11 -> DOMO | E12: =ESTADISTICA!E11 -> PTO A FO | F12: =ESTADISTICA!F11 -> 0 | G12: =ESTADISTICA!G11 -> 0 | H12: =ESTADISTICA!H11 -> 0 | ... AI12: =ESTADISTICA!AI11 -> 0
A13: =ESTADISTICA!A12 -> AGUSTIN RAMIREZ | B13: =ESTADISTICA!B12 -> ARA 01 | C13: =ESTADISTICA!C12 -> Malambo y Tranquera | D13: =ESTADISTICA!D12 -> Domo | E13: =ESTADISTICA!E12 -> FIBRA OPTICA | F13: =ESTADISTICA!F12 -> 0 | G13: =ESTADISTICA!G12 -> 0 | H13: =ESTADISTICA!H12 -> 0 | ... AI13: =ESTADISTICA!AI12 -> 0
... A401: =ESTADISTICA!A400 -> 0 | B401: =ESTADISTICA!B400 -> 0 | C401: =ESTADISTICA!C400 -> 0 | D401: =ESTADISTICA!D400 -> 0 | E401: =ESTADISTICA!E400 -> 0 | F401: =ESTADISTICA!F400 -> 0 | G401: =ESTADISTICA!G400 -> 0 | H401: =ESTADISTICA!H400 -> 0 | ... AI401: =ESTADISTICA!AI400 -> 0

Sheet APAGADOS FIBRA
C1: TOTAL FIBRA | D1: =COUNTIFS(E4:E400,"=Fibra Optica") -> 261
E2: APAGADOS | F2: =COUNTIFS(F4:F400, "=APAGADO",E4:E400,"=Fibra Optica") -> 20 | G2: =COUNTIFS(G4:G400, "=APAGADO",E4:E400,"=Fibra Optica") -> 19 | H2: =COUNTIFS(H4:H400, "=APAGADO",E4:E400,"=Fibra Optica") -> 20 | I2: =COUNTIFS(I4:I400, "=APAGADO",E4:E400,"=Fibra Optica") -> 21 | J2: =COUNTIFS(J4:J400, "=APAGADO",E4:E400,"=Fibra Optica") -> 18 | K2: =COUNTIFS(K4:K400, "=APAGADO",E4:E400,"=Fibra Optica") -> 0 | L2: =COUNTIFS(L4:L400, "=APAGADO",E4:E400,"=Fibra Optica") -> 31 | M2: =COUNTIFS(M4:M400, "=APAGADO",E4:E400,"=Fibra Optica") -> 30 | N2: =COUNTIFS(N4:N400, "=APAGADO",E4:E400,"=Fibra Optica") -> 22 | O2: =COUNTIFS(O4:O400, "=APAGADO",E4:E400,"=Fibra Optica") -> 19 | P2: =COUNTIFS(P4:P400, "=APAGADO",E4:E400,"=Fibra Optica") -> 19 | Q2: =COUNTIFS(Q4:Q400, "=APAGADO",E4:E400,"=Fibra Optica") -> 20 | R2: =COUNTIFS(R4:R400, "=APAGADO",E4:E400,"=Fibra Optica") -> 23 | S2: =COUNTIFS(S4:S400, "=APAGADO",E4:E400,"=Fibra Optica") -> 21 | T2: =COUNTIFS(T4:T400, "=APAGADO",E4:E400,"=Fibra Optica") -> 19 | U2: =COUNTIFS(U4:U400, "=APAGADO",E4:E400,"=Fibra Optica") -> 18 | V2: =COUNTIFS(V4:V400, "=APAGADO",E4:E400,"=Fibra Optica") -> 47 | W2: =COUNTIFS(W4:W400, "=APAGADO",E4:E400,"=Fibra Optica") -> 18 | X2: =COUNTIFS(X4:X400, "=APAGADO",E4:E400,"=Fibra Optica") -> 16 | Y2: =COUNTIFS(Y4:Y400, "=APAGADO",E4:E400,"=Fibra Optica") -> 17 | Z2: =COUNTIFS(Z4:Z400, "=APAGADO",E4:E400,"=Fibra Optica") -> 16 | AA2: =COUNTIFS(AA4:AA400, "=APAGADO",E4:E400,"=Fibra Optica") -> 16 | AB2: =COUNTIFS(AB4:AB400, "=APAGADO",E4:E400,"=Fibra Optica") -> 24 | AC2: =COUNTIFS(AC4:AC400, "=APAGADO",E4:E400,"=Fibra Optica") -> 23 | AD2: =COUNTIFS(AD4:AD400, "=APAGADO",E4:E400,"=Fibra Optica") -> 27 | AE2: =COUNTIFS(AE4:AE400, "=APAGADO",E4:E400,"=Fibra Optica") -> 29 | AF2: =COUNTIFS(AF4:AF400, "=APAGADO",E4:E400,"=Fibra Optica") -> 38 | AG2: =COUNTIFS(AG4:AG400, "=APAGADO",E4:E400,"=Fibra Optica") -> 34 | AH2: =COUNTIFS(AH4:AH400, "=APAGADO",E4:E400,"=Fibra Optica") -> 32 | AI2: =COUNTIFS(AI4:AI400, "=APAGADO",E4:E400,"=Fibra Optica") -> 37
A3: =ESTADISTICA!A1 -> Barrio | B3: =ESTADISTICA!B1 -> [Denominacion] | C3: =ESTADISTICA!C1 -> [Ubicacion] | D3: =ESTADISTICA!D1 -> [Tipo de Camara] | E3: =ESTADISTICA!E1 -> [Tipo de Conexion] | F3: =ESTADISTICA!F1 -> 44743 | G3: =ESTADISTICA!G1 -> 44744 | H3: =ESTADISTICA!H1 -> 44745 | ... AI3: =ESTADISTICA!AI1 -> 44772
A4: =ESTADISTICA!A2 -> ALTAMIRA | B4: =ESTADISTICA!B2 -> ALT 03 | C4: =ESTADISTICA!C2 -> Bombero Galarza y Necochea | D4: =ESTADISTICA!D2 -> Domo | E4: =ESTADISTICA!E2 -> FIBRA OPTICA | F4: =ESTADISTICA!F2 -> 0 | G4: =ESTADISTICA!G2 -> 0 | H4: =ESTADISTICA!H2 -> 0 | ... AI4: =ESTADISTICA!AI2 -> 0
A5: =ESTADISTICA!A3 -> ALTAMIRA | B5: =ESTADISTICA!B3 -> ALT 04 | C5: =ESTADISTICA!C3 -> Francia y Necochea | D5: =ESTADISTICA!D3 -> Domo | E5: =ESTADISTICA!E3 -> FIBRA OPTICA | F5: =ESTADISTICA!F3 -> 0 | G5: =ESTADISTICA!G3 -> 0 | H5: =ESTADISTICA!H3 -> 0 | ... AG5: =ESTADISTICA!AG3 -> 0
A6: =ESTADISTICA!A4 -> ALTAMIRA | B6: =ESTADISTICA!B4 -> ALT 06 | C6: =ESTADISTICA!C4 -> LOPE DE VEGA Y NECOCHEA | D6: =ESTADISTICA!D4 -> Domo | E6: =ESTADISTICA!E4 -> PTO A FO | F6: =ESTADISTICA!F4 -> APAGADO | G6: =ESTADISTICA!G4 -> APAGADO | H6: =ESTADISTICA!H4 -> APAGADO | ... AG6: =ESTADISTICA!AG4 -> 0
A7: =ESTADISTICA!A5 -> ALTAMIRA | B7: =ESTADISTICA!B5 -> ALT 08 | C7: =ESTADISTICA!C5 -> HUMAITA Y NECOCHEA | D7: =ESTADISTICA!D5 -> DOMO | E7: =ESTADISTICA!E5 -> Fibra Optica | F7: =ESTADISTICA!F5 -> 0 | G7: =ESTADISTICA!G5 -> 0 | H7: =ESTADISTICA!H5 -> 0 | ... AG7: =ESTADISTICA!AG5 -> 0
A8: =ESTADISTICA!A6 -> ALTAMIRA | B8: =ESTADISTICA!B6 -> ALT 09 | C8: =ESTADISTICA!C6 -> NECOCHEA Y CURUPAITY | D8: =ESTADISTICA!D6 -> DOMO | E8: =ESTADISTICA!E6 -> Fibra Optica | F8: =ESTADISTICA!F6 -> 0 | G8: =ESTADISTICA!G6 -> 0 | H8: =ESTADISTICA!H6 -> 0 | ... AG8: =ESTADISTICA!AG6 -> 0
A9: =ESTADISTICA!A7 -> ALTAMIRA | B9: =ESTADISTICA!B7 -> ALT 10 | C9: =ESTADISTICA!C7 -> Calchaqui y Francia | D9: =ESTADISTICA!D7 -> Domo | E9: =ESTADISTICA!E7 -> Radio | F9: =ESTADISTICA!F7 -> 0 | G9: =ESTADISTICA!G7 -> 0 | H9: =ESTADISTICA!H7 -> 0 | ... AG9: =ESTADISTICA!AG7 -> 0
A10: =ESTADISTICA!A8 -> ALTAMIRA | B10: =ESTADISTICA!B8 -> ALT01 | C10: =ESTADISTICA!C8 -> Calchaqui y Sgto. Cabral | D10: =ESTADISTICA!D8 -> Domo | E10: =ESTADISTICA!E8 -> Fibra Optica | F10: =ESTADISTICA!F8 -> 0 | G10: =ESTADISTICA!G8 -> 0 | H10: =ESTADISTICA!H8 -> 0 | ... AI10: =ESTADISTICA!AI8 -> 0
A11: =ESTADISTICA!A9 -> ALTAMIRA | B11: =ESTADISTICA!B9 -> ALT02 | C11: =ESTADISTICA!C9 -> Calchaqui y Lope de Vega | D11: =ESTADISTICA!D9 -> Domo | E11: =ESTADISTICA!E9 -> PTO A FO | F11: =ESTADISTICA!F9 -> 0 | G11: =ESTADISTICA!G9 -> 0 | H11: =ESTADISTICA!H9 -> 0 | ... AG11: =ESTADISTICA!AG9 -> 0
A12: =ESTADISTICA!A10 -> ALTAMIRA | B12: =ESTADISTICA!B10 -> ALT05 | C12: =ESTADISTICA!C10 -> Av. Calchaqui y Bombero Galarza | D12: =ESTADISTICA!D10 -> Domo | E12: =ESTADISTICA!E10 -> PTO A FO | F12: =ESTADISTICA!F10 -> 0 | G12: =ESTADISTICA!G10 -> 0 | H12: =ESTADISTICA!H10 -> 0 | ... AI12: =ESTADISTICA!AI10 -> 0
A13: =ESTADISTICA!A11 -> ALTAMIRA | B13: =ESTADISTICA!B11 -> ALT07 | C13: =ESTADISTICA!C11 -> AV. CALCHAQUI Y AV. DEL TRABAJO | D13: =ESTADISTICA!D11 -> DOMO | E13: =ESTADISTICA!E11 -> PTO A FO | F13: =ESTADISTICA!F11 -> 0 | G13: =ESTADISTICA!G11 -> 0 | H13: =ESTADISTICA!H11 -> 0 | ... AI13: =ESTADISTICA!AI11 -> 0
A14: =ESTADISTICA!A12 -> AGUSTIN RAMIREZ | B14: =ESTADISTICA!B12 -> ARA 01 | C14: =ESTADISTICA!C12 -> Malambo y Tranquera | D14: =ESTADISTICA!D12 -> Domo | E14: =ESTADISTICA!E12 -> FIBRA OPTICA | F14: =ESTADISTICA!F12 -> 0 | G14: =ESTADISTICA!G12 -> 0 | H14: =ESTADISTICA!H12 -> 0 | ... AG14: =ESTADISTICA!AG12 -> 0
A15: =ESTADISTICA!A13 -> BELGRANO | B15: =ESTADISTICA!B13 -> BEL 01 | C15: =ESTADISTICA!C13 -> San Martin y Dardo Rocha | D15: =ESTADISTICA!D13 -> DOMO | E15: =ESTADISTICA!E13 -> FIBRA OPTICA | F15: =ESTADISTICA!F13 -> 0 | G15: =ESTADISTICA!G13 -> 0 | H15: =ESTADISTICA!H13 -> 0 | ... AG15: =ESTADISTICA!AG13 -> 0
A16: =ESTADISTICA!A14 -> CENTRO | B16: =ESTADISTICA!B14 -> CEN 05 | C16: =ESTADISTICA!C14 -> Bocuzzi e/EspaÃ±a y San Martin | D16: =ESTADISTICA!D14 -> DOMO | E16: =ESTADISTICA!E14 -> Fibra Optica | F16: =ESTADISTICA!F14 -> 0 | G16: =ESTADISTICA!G14 -> 0 | H16: =ESTADISTICA!H14 -> 0 | ... AI16: =ESTADISTICA!AI14 -> 0
A17: =ESTADISTICA!A15 -> CENTRO | B17: =ESTADISTICA!B15 -> CEN 12 | C17: =ESTADISTICA!C15 -> Monteagudo y Mitre | D17: =ESTADISTICA!D15 -> Domo | E17: =ESTADISTICA!E15 -> Fibra Optica | F17: =ESTADISTICA!F15 -> 0 | G17: =ESTADISTICA!G15 -> 0 | H17: =ESTADISTICA!H15 -> 0 | ... AI17: =ESTADISTICA!AI15 -> 0
A18: =ESTADISTICA!A16 -> CENTRO | B18: =ESTADISTICA!B16 -> CEN 13 | C18: =ESTADISTICA!C16 -> 25 de Mayo y Maipu | D18: =ESTADISTICA!D16 -> DOMO | E18: =ESTADISTICA!E16 -> Fibra Optica | F18: =ESTADISTICA!F16 -> 0 | G18: =ESTADISTICA!G16 -> 0 | H18: =ESTADISTICA!H16 -> 0 | ... AI18: =ESTADISTICA!AI16 -> 0
A19: =ESTADISTICA!A17 -> CENTRO | B19: =ESTADISTICA!B17 -> CEN 37 | C19: =ESTADISTICA!C17 -> Diagonal Granaderos y Monteagudo | D19: =ESTADISTICA!D17 -> Domo | E19: =ESTADISTICA!E17 -> Fibra Optica | F19: =ESTADISTICA!F17 -> 0 | G19: =ESTADISTICA!G17 -> 0 | H19: =ESTADISTICA!H17 -> 0 | ... AG19: =ESTADISTICA!AG17 -> 0
A20: =ESTADISTICA!A18 -> CENTRO | B20: =ESTADISTICA!B18 -> CEN 50 | C20: =ESTADISTICA!C18 -> Av. San Martin y Newbery | D20: =ESTADISTICA!D18 -> Domo | E20: =ESTADISTICA!E18 -> Radio | F20: =ESTADISTICA!F18 -> 0 | G20: =ESTADISTICA!G18 -> 0 | H20: =ESTADISTICA!H18 -> 0 | ... AI20: =ESTADISTICA!AI18 -> APAGADO
A21: =ESTADISTICA!A19 -> CENTRO | B21: =ESTADISTICA!B19 -> CEN 51 | C21: =ESTADISTICA!C19 -> ILLIA Y LAS HERAS | D21: =ESTADISTICA!D19 -> FIJA | E21: =ESTADISTICA!E19 -> Fibra Optica | F21: =ESTADISTICA!F19 -> 0 | G21: =ESTADISTICA!G19 -> 0 | H21: =ESTADISTICA!H19 -> 0 | ... AI21: =ESTADISTICA!AI19 -> 0
A22: =ESTADISTICA!A20 -> CENTRO | B22: =ESTADISTICA!B20 -> CEN 53 | C22: =ESTADISTICA!C20 -> GUTIERREZ Y BROWN | D22: =ESTADISTICA!D20 -> Domo | E22: =ESTADISTICA!E20 -> Radio | F22: =ESTADISTICA!F20 -> 0 | G22: =ESTADISTICA!G20 -> 0 | H22: =ESTADISTICA!H20 -> 0 | ... AG22: =ESTADISTICA!AG20 -> 0
A23: =ESTADISTICA!A21 -> CENTRO | B23: =ESTADISTICA!B21 -> CEN 54 | C23: =ESTADISTICA!C21 -> GUTIERREZ Y PRINGLES | D23: =ESTADISTICA!D21 -> Domo | E23: =ESTADISTICA!E21 -> Radio | F23: =ESTADISTICA!F21 -> 0 | G23: =ESTADISTICA!G21 -> 0 | H23: =ESTADISTICA!H21 -> 0 | ... AG23: =ESTADISTICA!AG21 -> 0
A24: =ESTADISTICA!A22 -> CENTRO | B24: =ESTADISTICA!B22 -> CEN 55 | C24: =ESTADISTICA!C22 -> BOUREL Y URQUIZA | D24: =ESTADISTICA!D22 -> Domo | E24: =ESTADISTICA!E22 -> Radio | F24: =ESTADISTICA!F22 -> 0 | G24: =ESTADISTICA!G22 -> 0 | H24: =ESTADISTICA!H22 -> 0 | ... AG24: =ESTADISTICA!AG22 -> 0
A25: =ESTADISTICA!A23 -> CENTRO | B25: =ESTADISTICA!B23 -> CEN 56 | C25: =ESTADISTICA!C23 -> Newbery y Falucho | D25: =ESTADISTICA!D23 -> DOMO | E25: =ESTADISTICA!E23 -> Radio | F25: =ESTADISTICA!F23 -> 0 | G25: =ESTADISTICA!G23 -> 0 | H25: =ESTADISTICA!H23 -> 0 | ... AG25: =ESTADISTICA!AG23 -> 0
A26: =ESTADISTICA!A24 -> CENTRO | B26: =ESTADISTICA!B24 -> CEN 57 | C26: =ESTADISTICA!C24 -> 25 DE MAYO Y DORREGO | D26: =ESTADISTICA!D24 -> DOMO | E26: =ESTADISTICA!E24 -> Radio | F26: =ESTADISTICA!F24 -> 0 | G26: =ESTADISTICA!G24 -> 0 | H26: =ESTADISTICA!H24 -> 0 | ... AG26: =ESTADISTICA!AG24 -> 0
A27: =ESTADISTICA!A25 -> CENTRO | B27: =ESTADISTICA!B25 -> CEN 58 | C27: =ESTADISTICA!C25 -> EEUU Y MORENO | D27: =ESTADISTICA!D25 -> DOMO | E27: =ESTADISTICA!E25 -> FIBRA OPTICA | F27: =ESTADISTICA!F25 -> 0 | G27: =ESTADISTICA!G25 -> 0 | H27: =ESTADISTICA!H25 -> 0 | ... AI27: =ESTADISTICA!AI25 -> 0
A28: =ESTADISTICA!A26 -> CENTRO | B28: =ESTADISTICA!B26 -> CEN 60 | C28: =ESTADISTICA!C26 -> RECONQUISTA Y ILLIA | D28: =ESTADISTICA!D26 -> DOMO | E28: =ESTADISTICA!E26 -> PTO A FO | F28: =ESTADISTICA!F26 -> 0 | G28: =ESTADISTICA!G26 -> 0 | H28: =ESTADISTICA!H26 -> 0 | ... AG28: =ESTADISTICA!AG26 -> APAGADO
A29: =ESTADISTICA!A27 -> CENTRO | B29: =ESTADISTICA!B27 -> CEN 61 | C29: =ESTADISTICA!C27 -> BOUREL Y MAIPU | D29: =ESTADISTICA!D27 -> DOMO | E29: =ESTADISTICA!E27 -> Radio | F29: =ESTADISTICA!F27 -> 0 | G29: =ESTADISTICA!G27 -> 0 | H29: =ESTADISTICA!H27 -> 0 | ... AG29: =ESTADISTICA!AG27 -> 0
A30: =ESTADISTICA!A28 -> CENTRO | B30: =ESTADISTICA!B28 -> CEN 65 | C30: =ESTADISTICA!C28 -> SAN MARTIN Y JUAN PERON | D30: =ESTADISTICA!D28 -> FIJA | E30: =ESTADISTICA!E28 -> Fibra Optica | F30: =ESTADISTICA!F28 -> 0 | G30: =ESTADISTICA!G28 -> 0 | H30: =ESTADISTICA!H28 -> 0 | ... AG30: =ESTADISTICA!AG28 -> 0
A31: =ESTADISTICA!A29 -> CENTRO | B31: =ESTADISTICA!B29 -> CEN 70 | C31: =ESTADISTICA!C29 -> RIVADAVIA Y 25 MAYO | D31: =ESTADISTICA!D29 -> Domo | E31: =ESTADISTICA!E29 -> Fibra Optica | F31: =ESTADISTICA!F29 -> 0 | G31: =ESTADISTICA!G29 -> 0 | H31: =ESTADISTICA!H29 -> 0 | ... AG31: =ESTADISTICA!AG29 -> 0
A32: =ESTADISTICA!A30 -> CENTRO | B32: =ESTADISTICA!B30 -> CEN 71 | C32: =ESTADISTICA!C30 -> MORENO Y BOUREL | D32: =ESTADISTICA!D30 -> Domo | E32: =ESTADISTICA!E30 -> Fibra Optica | F32: =ESTADISTICA!F30 -> 0 | G32: =ESTADISTICA!G30 -> 0 | H32: =ESTADISTICA!H30 -> 0 | ... AI32: =ESTADISTICA!AI30 -> 0
A33: =ESTADISTICA!A31 -> CENTRO | B33: =ESTADISTICA!B31 -> CEN 72 | C33: =ESTADISTICA!C31 -> MORENO Y 25 DE MAYO | D33: =ESTADISTICA!D31 -> Domo | E33: =ESTADISTICA!E31 -> Fibra Optica | F33: =ESTADISTICA!F31 -> 0 | G33: =ESTADISTICA!G31 -> 0 | H33: =ESTADISTICA!H31 -> 0 | ... AI33: =ESTADISTICA!AI31 -> APAGADO
A34: =ESTADISTICA!A32 -> CENTRO | B34: =ESTADISTICA!B32 -> CEN 75 | C34: =ESTADISTICA!C32 -> 25 DE MAYO Y CASTELLI | D34: =ESTADISTICA!D32 -> Domo | E34: =ESTADISTICA!E32 -> Fibra Optica | F34: =ESTADISTICA!F32 -> 0 | G34: =ESTADISTICA!G32 -> 0 | H34: =ESTADISTICA!H32 -> 0 | ... AI34: =ESTADISTICA!AI32 -> 0
A35: =ESTADISTICA!A33 -> CENTRO | B35: =ESTADISTICA!B33 -> CEN 76 | C35: =ESTADISTICA!C33 -> ESPAÃ‘A E/MITRE Y BOCUZZI | D35: =ESTADISTICA!D33 -> Fija | E35: =ESTADISTICA!E33 -> Fibra Optica | F35: =ESTADISTICA!F33 -> 0 | G35: =ESTADISTICA!G33 -> APAGADO | H35: =ESTADISTICA!H33 -> APAGADO | ... AI35: =ESTADISTICA!AI33 -> 0
A36: =ESTADISTICA!A34 -> CENTRO | B36: =ESTADISTICA!B34 -> CEN01 | C36: =ESTADISTICA!C34 -> San Martin y 9 de Julio | D36: =ESTADISTICA!D34 -> Fija | E36: =ESTADISTICA!E34 -> Fibra Optica | F36: =ESTADISTICA!F34 -> 0 | G36: =ESTADISTICA!G34 -> 0 | H36: =ESTADISTICA!H34 -> 0 | ... AI36: =ESTADISTICA!AI34 -> 0
A37: =ESTADISTICA!A35 -> CENTRO | B37: =ESTADISTICA!B35 -> CEN02 | C37: =ESTADISTICA!C35 -> San Martin y Almafuerte | D37: =ESTADISTICA!D35 -> Fija | E37: =ESTADISTICA!E35 -> Fibra Optica | F37: =ESTADISTICA!F35 -> 0 | G37: =ESTADISTICA!G35 -> 0 | H37: =ESTADISTICA!H35 -> 0 | ... AI37: =ESTADISTICA!AI35 -> APAGADO
A38: =ESTADISTICA!A36 -> CENTRO | B38: =ESTADISTICA!B36 -> CEN03 | C38: =ESTADISTICA!C36 -> San Martin y Sallares | D38: =ESTADISTICA!D36 -> Domo | E38: =ESTADISTICA!E36 -> Fibra Optica | F38: =ESTADISTICA!F36 -> 0 | G38: =ESTADISTICA!G36 -> 0 | H38: =ESTADISTICA!H36 -> 0 | ... AI38: =ESTADISTICA!AI36 -> 0
A39: =ESTADISTICA!A37 -> CENTRO | B39: =ESTADISTICA!B37 -> CEN04 | C39: =ESTADISTICA!C37 -> San Martin y Contreras | D39: =ESTADISTICA!D37 -> Domo | E39: =ESTADISTICA!E37 -> Fibra Optica | F39: =ESTADISTICA!F37 -> 0 | G39: =ESTADISTICA!G37 -> 0 | H39: =ESTADISTICA!H37 -> 0 | ... AI39: =ESTADISTICA!AI37 -> 0
A40: =ESTADISTICA!A38 -> CENTRO | B40: =ESTADISTICA!B38 -> CEN06 | C40: =ESTADISTICA!C38 -> Monteagudo y A.del Valle | D40: =ESTADISTICA!D38 -> Fija | E40: =ESTADISTICA!E38 -> Fibra Optica | F40: =ESTADISTICA!F38 -> 0 | G40: =ESTADISTICA!G38 -> 0 | H40: =ESTADISTICA!H38 -> 0 | ... AI40: =ESTADISTICA!AI38 -> 0
...

Sheet APAGADOS ANTENA
C1: TOTAL PTO A FO | D1: =COUNTIFS(E4:E400,"=PTo A FO") -> 37
E2: APAGADOS | F2: =COUNTIFS(F4:F400, "=APAGADO",E4:E400,"=PTO A FO") -> 9 | G2: =COUNTIFS(G4:G400, "=APAGADO",E4:E400,"=PTO A FO") -> 6 | H2: =COUNTIFS(H4:H400, "=APAGADO",E4:E400,"=PTO A FO") -> 5 | I2: =COUNTIFS(I4:I400, "=APAGADO",E4:E400,"=PTO A FO") -> 5 | J2: =COUNTIFS(J4:J400, "=APAGADO",E4:E400,"=PTO A FO") -> 5 | K2: =COUNTIFS(K4:K400, "=APAGADO",E4:E400,"=PTO A FO") -> 0 | L2: =COUNTIFS(L4:L400, "=APAGADO",E4:E400,"=PTO A FO") -> 11 | M2: =COUNTIFS(M4:M400, "=APAGADO",E4:E400,"=PTO A FO") -> 8 | N2: =COUNTIFS(N4:N400, "=APAGADO",E4:E400,"=PTO A FO") -> 5 | O2: =COUNTIFS(O4:O400, "=APAGADO",E4:E400,"=PTO A FO") -> 5 | P2: =COUNTIFS(P4:P400, "=APAGADO",E4:E400,"=PTO A FO") -> 5 | Q2: =COUNTIFS(Q4:Q400, "=APAGADO",E4:E400,"=PTO A FO") -> 5 | R2: =COUNTIFS(R4:R400, "=APAGADO",E4:E400,"=PTO A FO") -> 5 | S2: =COUNTIFS(S4:S400, "=APAGADO",E4:E400,"=PTO A FO") -> 6 | T2: =COUNTIFS(T4:T400, "=APAGADO",E4:E400,"=PTO A FO") -> 7 | U2: =COUNTIFS(U4:U400, "=APAGADO",E4:E400,"=PTO A FO") -> 5 | V2: =COUNTIFS(V4:V400, "=APAGADO",E4:E400,"=PTO A FO") -> 6 | W2: =COUNTIFS(W4:W400, "=APAGADO",E4:E400,"=PTO A FO") -> 5 | X2: =COUNTIFS(X4:X400, "=APAGADO",E4:E400,"=PTO A FO") -> 5 | Y2: =COUNTIFS(Y4:Y400, "=APAGADO",E4:E400,"=PTO A FO") -> 3 | Z2: =COUNTIFS(Z4:Z400, "=APAGADO",E4:E400,"=PTO A FO") -> 2 | AA2: =COUNTIFS(AA4:AA400, "=APAGADO",E4:E400,"=PTO A FO") -> 2 | AB2: =COUNTIFS(AB4:AB400, "=APAGADO",E4:E400,"=PTO A FO") -> 6 | AC2: =COUNTIFS(AC4:AC400, "=APAGADO",E4:E400,"=PTO A FO") -> 6 | AD2: =COUNTIFS(AD4:AD400, "=APAGADO",E4:E400,"=PTO A FO") -> 6 | AE2: =COUNTIFS(AE4:AE400, "=APAGADO",E4:E400,"=PTO A FO") -> 6 | AF2: =COUNTIFS(AF4:AF400, "=APAGADO",E4:E400,"=PTO A FO") -> 9 | AG2: =COUNTIFS(AG4:AG400, "=APAGADO",E4:E400,"=PTO A FO") -> 8 | AH2: =COUNTIFS(AH4:AH400, "=APAGADO",E4:E400,"=PTO A FO") -> 6 | AI2: =COUNTIFS(AI4:AI400, "=APAGADO",E4:E400,"=PTO A FO") -> 13
A3: =ESTADISTICA!A1 -> Barrio | B3: =ESTADISTICA!B1 -> [Denominacion] | C3: =ESTADISTICA!C1 -> [Ubicacion] | D3: =ESTADISTICA!D1 -> [Tipo de Camara] | E3: =ESTADISTICA!E1 -> [Tipo de Conexion] | F3: =ESTADISTICA!F1 -> 44743 | G3: =ESTADISTICA!G1 -> 44744 | H3: =ESTADISTICA!H1 -> 44745 | ... AI3: =ESTADISTICA!AI1 -> 44772
A4: =ESTADISTICA!A2 -> ALTAMIRA | B4: =ESTADISTICA!B2 -> ALT 03 | C4: =ESTADISTICA!C2 -> Bombero Galarza y Necochea | D4: =ESTADISTICA!D2 -> Domo | E4: =ESTADISTICA!E2 -> FIBRA OPTICA | F4: =ESTADISTICA!F2 -> 0 | G4: =ESTADISTICA!G2 -> 0 | H4: =ESTADISTICA!H2 -> 0 | ... AI4: =ESTADISTICA!AI2 -> 0
A5: =ESTADISTICA!A3 -> ALTAMIRA | B5: =ESTADISTICA!B3 -> ALT 04 | C5: =ESTADISTICA!C3 -> Francia y Necochea | D5: =ESTADISTICA!D3 -> Domo | E5: =ESTADISTICA!E3 -> FIBRA OPTICA | F5: =ESTADISTICA!F3 -> 0 | G5: =ESTADISTICA!G3 -> 0 | H5: =ESTADISTICA!H3 -> 0 | ... AI5: =ESTADISTICA!AI3 -> 0
A6: =ESTADISTICA!A4 -> ALTAMIRA | B6: =ESTADISTICA!B4 -> ALT 06 | C6: =ESTADISTICA!C4 -> LOPE DE VEGA Y NECOCHEA | D6: =ESTADISTICA!D4 -> Domo | E6: =ESTADISTICA!E4 -> PTO A FO | F6: =ESTADISTICA!F4 -> APAGADO | G6: =ESTADISTICA!G4 -> APAGADO | H6: =ESTADISTICA!H4 -> APAGADO | ... AI6: =ESTADISTICA!AI4 -> 0
A7: =ESTADISTICA!A5 -> ALTAMIRA | B7: =ESTADISTICA!B5 -> ALT 08 | C7: =ESTADISTICA!C5 -> HUMAITA Y NECOCHEA | D7: =ESTADISTICA!D5 -> DOMO | E7: =ESTADISTICA!E5 -> Fibra Optica | F7: =ESTADISTICA!F5 -> 0 | G7: =ESTADISTICA!G5 -> 0 | H7: =ESTADISTICA!H5 -> 0 | ... AI7: =ESTADISTICA!AI5 -> 0
A8: =ESTADISTICA!A6 -> ALTAMIRA | B8: =ESTADISTICA!B6 -> ALT 09 | C8: =ESTADISTICA!C6 -> NECOCHEA Y CURUPAITY | D8: =ESTADISTICA!D6 -> DOMO | E8: =ESTADISTICA!E6 -> Fibra Optica | F8: =ESTADISTICA!F6 -> 0 | G8: =ESTADISTICA!G6 -> 0 | H8: =ESTADISTICA!H6 -> 0 | ... AI8: =ESTADISTICA!AI6 -> 0
A9: =ESTADISTICA!A7 -> ALTAMIRA | B9: =ESTADISTICA!B7 -> ALT 10 | C9: =ESTADISTICA!C7 -> Calchaqui y Francia | D9: =ESTADISTICA!D7 -> Domo | E9: =ESTADISTICA!E7 -> Radio | F9: =ESTADISTICA!F7 -> 0 | G9: =ESTADISTICA!G7 -> 0 | H9: =ESTADISTICA!H7 -> 0 | ... AI9: =ESTADISTICA!AI7 -> 0
A10: =ESTADISTICA!A8 -> ALTAMIRA | B10: =ESTADISTICA!B8 -> ALT01 | C10: =ESTADISTICA!C8 -> Calchaqui y Sgto. Cabral | D10: =ESTADISTICA!D8 -> Domo | E10: =ESTADISTICA!E8 -> Fibra Optica | F10: =ESTADISTICA!F8 -> 0 | G10: =ESTADISTICA!G8 -> 0 | H10: =ESTADISTICA!H8 -> 0 | ... AI10: =ESTADISTICA!AI8 -> 0
A11: =ESTADISTICA!A9 -> ALTAMIRA | B11: =ESTADISTICA!B9 -> ALT02 | C11: =ESTADISTICA!C9 -> Calchaqui y Lope de Vega | D11: =ESTADISTICA!D9 -> Domo | E11: =ESTADISTICA!E9 -> PTO A FO | F11: =ESTADISTICA!F9 -> 0 | G11: =ESTADISTICA!G9 -> 0 | H11: =ESTADISTICA!H9 -> 0 | ... AI11: =ESTADISTICA!AI9 -> 0
A12: =ESTADISTICA!A10 -> ALTAMIRA | B12: =ESTADISTICA!B10 -> ALT05 | C12: =ESTADISTICA!C10 -> Av. Calchaqui y Bombero Galarza | D12: =ESTADISTICA!D10 -> Domo | E12: =ESTADISTICA!E10 -> PTO A FO | F12: =ESTADISTICA!F10 -> 0 | G12: =ESTADISTICA!G10 -> 0 | H12: =ESTADISTICA!H10 -> 0 | ... AI12: =ESTADISTICA!AI10 -> 0
A13: =ESTADISTICA!A11 -> ALTAMIRA | B13: =ESTADISTICA!B11 -> ALT07 | C13: =ESTADISTICA!C11 -> AV. CALCHAQUI Y AV. DEL TRABAJO | D13: =ESTADISTICA!D11 -> DOMO | E13: =ESTADISTICA!E11 -> PTO A FO | F13: =ESTADISTICA!F11 -> 0 | G13: =ESTADISTICA!G11 -> 0 | H13: =ESTADISTICA!H11 -> 0 | ... AI13: =ESTADISTICA!AI11 -> 0
A14: =ESTADISTICA!A12 -> AGUSTIN RAMIREZ | B14: =ESTADISTICA!B12 -> ARA 01 | C14: =ESTADISTICA!C12 -> Malambo y Tranquera | D14: =ESTADISTICA!D12 -> Domo | E14: =ESTADISTICA!E12 -> FIBRA OPTICA | F14: =ESTADISTICA!F12 -> 0 | G14: =ESTADISTICA!G12 -> 0 | H14: =ESTADISTICA!H12 -> 0 | ... AI14: =ESTADISTICA!AI12 -> 0
... A278: =ESTADISTICA!A276 -> SAN JORGE | B278: =ESTADISTICA!B276 -> SJO07 (fija 1) | C278: =ESTADISTICA!C276 -> 503 Y 556 | D278: =ESTADISTICA!D276 -> Fija | E278: =ESTADISTICA!E276 -> Fibra Optica | F278: =ESTADISTICA!F276 -> 0 | G278: =ESTADISTICA!G276 -> 0 | H278: =ESTADISTICA!H276 -> APAGADO | ... AI278: =ESTADISTICA!AI276 -> 0
B279: =ESTADISTICA!B277 -> SJO08 (fija 2) | C279: =ESTADISTICA!C277 -> 503 Y 556 | D279: =ESTADISTICA!D277 -> Fija | E279: =ESTADISTICA!E277 -> Fibra Optica | F279: =ESTADISTICA!F277 -> 0 | G279: =ESTADISTICA!G277 -> 0 | H279: =ESTADISTICA!H277 -> 0 | I279: =ESTADISTICA!I277 -> 0 | ... AI279: =ESTADISTICA!AI277 -> 0
A280: =ESTADISTICA!A278 -> SANTO TOMAS | B280: =ESTADISTICA!B278 -> SJU01 | C280: =ESTADISTICA!C278 -> Ruta 36 y Pte.Peron | D280: =ESTADISTICA!D278 -> Domo | E280: =ESTADISTICA!E278 -> Radio | F280: =ESTADISTICA!F278 -> 0 | G280: =ESTADISTICA!G278 -> 0 | H280: =ESTADISTICA!H278 -> 0 | ... AI280: =ESTADISTICA!AI278 -> APAGADO
A281: =ESTADISTICA!A279 -> VILLA GENERAL SAN MARTIN | B281: =ESTADISTICA!B279 -> SMA 03 | C281: =ESTADISTICA!C279 -> ROSARIO Y SAN NICOLAS | D281: =ESTADISTICA!D279 -> Domo | E281: =ESTADISTICA!E279 -> Radio | F281: =ESTADISTICA!F279 -> 0 | G281: =ESTADISTICA!G279 -> 0 | H281: =ESTADISTICA!H279 -> 0 | ... AI281: =ESTADISTICA!AI279 -> 0
A282: =ESTADISTICA!A280 -> VILLA GENERAL SAN MARTIN | B282: =ESTADISTICA!B280 -> SMA 04 | C282: =ESTADISTICA!C280 -> HUDSON Y MONTEVIDEO | D282: =ESTADISTICA!D280 -> FIJA | E282: =ESTADISTICA!E280 -> Radio | F282: =ESTADISTICA!F280 -> APAGADO | G282: =ESTADISTICA!G280 -> APAGADO | H282: =ESTADISTICA!H280 -> APAGADO | ... AI282: =ESTADISTICA!AI280 -> 0
A283: =ESTADISTICA!A281 -> VILLA GENERAL SAN MARTIN | B283: =ESTADISTICA!B281 -> SMA 06 | C283: =ESTADISTICA!C281 -> AV. HUDSON Y RIO IGUAZU | D283: =ESTADISTICA!D281 -> DOMO | E283: =ESTADISTICA!E281 -> Fibra Optica | F283: =ESTADISTICA!F281 -> 0 | G283: =ESTADISTICA!G281 -> 0 | H283: =ESTADISTICA!H281 -> 0 | ... AI283: =ESTADISTICA!AI281 -> 0
A284: =ESTADISTICA!A282 -> VILLA GENERAL SAN MARTIN | B284: =ESTADISTICA!B282 -> SMA 07 | C284: =ESTADISTICA!C282 -> AV. HUDSON Y RIO TURBIO | D284: =ESTADISTICA!D282 -> DOMO | E284: =ESTADISTICA!E282 -> Fibra Optica | F284: =ESTADISTICA!F282 -> 0 | G284: =ESTADISTICA!G282 -> 0 | H284: =ESTADISTICA!H282 -> 0 | ... AI284: =ESTADISTICA!AI282 -> 0
A285: =ESTADISTICA!A283 -> VILLA GENERAL SAN MARTIN | B285: =ESTADISTICA!B283 -> SMA01 | C285: =ESTADISTICA!C283 -> Hudson y Montevideo | D285: =ESTADISTICA!D283 -> DOMO | E285: =ESTADISTICA!E283 -> Radio | F285: =ESTADISTICA!F283 -> 0 | G285: =ESTADISTICA!G283 -> 0 | H285: =ESTADISTICA!H283 -> 0 | ... AI285: =ESTADISTICA!AI283 -> 0
A286: =ESTADISTICA!A284 -> VILLA GENERAL SAN MARTIN | B286: =ESTADISTICA!B284 -> SMA02 | C286: =ESTADISTICA!C284 -> Hudson y San Nicolas | D286: =ESTADISTICA!D284 -> Domo | E286: =ESTADISTICA!E284 -> Radio | F286: =ESTADISTICA!F284 -> 0 | G286: =ESTADISTICA!G284 -> 0 | H286: =ESTADISTICA!H284 -> 0 | ... AI286: =ESTADISTICA!AI284 -> 0
A287: =ESTADISTICA!A285 -> VILLA GENERAL SAN MARTIN | B287: =ESTADISTICA!B285 -> SMA05 | C287: =ESTADISTICA!C285 -> MONTEVIDEO Y VILLEGAS | D287: =ESTADISTICA!D285 -> DOMO | E287: =ESTADISTICA!E285 -> PTO A FO | F287: =ESTADISTICA!F285 -> 0 | G287: =ESTADISTICA!G285 -> 0 | H287: =ESTADISTICA!H285 -> 0 | ... AI287: =ESTADISTICA!AI285 -> 0
A288: =ESTADISTICA!A286 -> SAN NICOLAS | B288: =ESTADISTICA!B286 -> SNI 03 (fija 1) | C288: =ESTADISTICA!C286 -> SARRATEA Y LOS TREBOLES | D288: =ESTADISTICA!D286 -> Fija | E288: =ESTADISTICA!E286 -> Fibra Optica | F288: =ESTADISTICA!F286 -> 0 | G288: =ESTADISTICA!G286 -> 0 | H288: =ESTADISTICA!H286 -> 0 | ... AI288: =ESTADISTICA!AI286 -> 0
A289: =ESTADISTICA!A287 -> SAN NICOLAS | B289: =ESTADISTICA!B287 -> SNI 04 (fija 2) | C289: =ESTADISTICA!C287 -> SARRATEA Y LOS TREBOLES | D289: =ESTADISTICA!D287 -> Fija | E289: =ESTADISTICA!E287 -> Fibra Optica | F289: =ESTADISTICA!F287 -> 0 | G289: =ESTADISTICA!G287 -> 0 | H289: =ESTADISTICA!H287 -> 0 | ... AI289: =ESTADISTICA!AI287 -> 0
A290: =ESTADISTICA!A288 -> SAN NICOLAS | B290: =ESTADISTICA!B288 -> SNI01 (fija 1) | C290: =ESTADISTICA!C288 -> SARRATEA E/ EEUU DE A. Y AGRELO | D290: =ESTADISTICA!D288 -> Fija | E290: =ESTADISTICA!E288 -> Fibra Optica | F290: =ESTADISTICA!F288 -> 0 | G290: =ESTADISTICA!G288 -> 0 | H290: =ESTADISTICA!H288 -> 0 | ... AI290: =ESTADISTICA!AI288 -> 0
A291: =ESTADISTICA!A289 -> SAN NICOLAS | B291: =ESTADISTICA!B289 -> SNI02 (fija 2) | C291: =ESTADISTICA!C289 -> SARRATEA E/ EEUU DE A. Y AGRELO | D291: =ESTADISTICA!D289 -> Fija | E291: =ESTADISTICA!E289 -> Fibra Optica | F291: =ESTADISTICA!F289 -> 0 | G291: =ESTADISTICA!G289 -> 0 | H291: =ESTADISTICA!H289 -> 0 | ... AI291: =ESTADISTICA!AI289 -> 0
... A454: =ESTADISTICA!A452 -> 0 | B454: =ESTADISTICA!B452 -> 0 | C454: =ESTADISTICA!C452 -> 0 | D454: =ESTADISTICA!D452 -> 0 | E454: =ESTADISTICA!E452 -> 0 | F454: =ESTADISTICA!F452 -> 0 | G454: =ESTADISTICA!G452 -> 0 | H454: =ESTADISTICA!H452 -> 0 | ... AI454: =ESTADISTICA!AI452 -> 0

Sheet APAGADOS RADIO
C1: TOTAL RADIO | D1: =COUNTIFS(E4:E400,"=radio") -> 94
E2: APAGADOS | F2: =COUNTIFS(F4:F367, "=APAGADO",E4:E367,"=radio") -> 6 | G2: =COUNTIFS(G4:G367, "=APAGADO",E4:E367,"=radio") -> 8 | H2: =COUNTIFS(H4:H367, "=APAGADO",E4:E367,"=radio") -> 11 | I2: =COUNTIFS(I4:I367, "=APAGADO",E4:E367,"=radio") -> 14 | J2: =COUNTIFS(J4:J367, "=APAGADO",E4:E367,"=radio") -> 9 | K2: =COUNTIFS(K4:K367, "=APAGADO",E4:E367,"=radio") -> 0 | L2: =COUNTIFS(L4:L367, "=APAGADO",E4:E367,"=radio") -> 15 | M2: =COUNTIFS(M4:M367, "=APAGADO",E4:E367,"=radio") -> 10 | N2: =COUNTIFS(N4:N367, "=APAGADO",E4:E367,"=radio") -> 7 | O2: =COUNTIFS(O4:O367, "=APAGADO",E4:E367,"=radio") -> 5 | P2: =COUNTIFS(P4:P367, "=APAGADO",E4:E367,"=radio") -> 5 | Q2: =COUNTIFS(Q4:Q367, "=APAGADO",E4:E367,"=radio") -> 8 | R2: =COUNTIFS(R4:R367, "=APAGADO",E4:E367,"=radio") -> 8 | S2: =COUNTIFS(S4:S367, "=APAGADO",E4:E367,"=radio") -> 7 | T2: =COUNTIFS(T4:T367, "=APAGADO",E4:E367,"=radio") -> 7 | U2: =COUNTIFS(U4:U367, "=APAGADO",E4:E367,"=radio") -> 5 | V2: =COUNTIFS(V4:V367, "=APAGADO",E4:E367,"=radio") -> 10 | W2: =COUNTIFS(W4:W367, "=APAGADO",E4:E367,"=radio") -> 7 | X2: =COUNTIFS(X4:X367, "=APAGADO",E4:E367,"=radio") -> 6 | Y2: =COUNTIFS(Y4:Y367, "=APAGADO",E4:E367,"=radio") -> 4 | Z2: =COUNTIFS(Z4:Z367, "=APAGADO",E4:E367,"=radio") -> 5 | AA2: =COUNTIFS(AA4:AA367, "=APAGADO",E4:E367,"=radio") -> 7 | AB2: =COUNTIFS(AB4:AB367, "=APAGADO",E4:E367,"=radio") -> 5 | AC2: =COUNTIFS(AC4:AC367, "=APAGADO",E4:E367,"=radio") -> 7 | AD2: =COUNTIFS(AD4:AD367, "=APAGADO",E4:E367,"=radio") -> 5 | AE2: =COUNTIFS(AE4:AE367, "=APAGADO",E4:E367,"=radio") -> 5 | AF2: =COUNTIFS(AF4:AF367, "=APAGADO",E4:E367,"=radio") -> 8 | AG2: =COUNTIFS(AG4:AG367, "=APAGADO",E4:E367,"=radio") -> 8 | AH2: =COUNTIFS(AH4:AH367, "=APAGADO",E4:E367,"=radio") -> 7 | AI2: =COUNTIFS(AI4:AI367, "=APAGADO",E4:E367,"=radio") -> 25
A3: =ESTADISTICA!A1 -> Barrio | B3: =ESTADISTICA!B1 -> [Denominacion] | C3: =ESTADISTICA!C1 -> [Ubicacion] | D3: =ESTADISTICA!D1 -> [Tipo de Camara] | E3: =ESTADISTICA!E1 -> [Tipo de Conexion] | F3: =ESTADISTICA!F1 -> 44743 | G3: =ESTADISTICA!G1 -> 44744 | H3: =ESTADISTICA!H1 -> 44745 | ... AI3: =ESTADISTICA!AI1 -> 44772
A4: =ESTADISTICA!A2 -> ALTAMIRA | B4: =ESTADISTICA!B2 -> ALT 03 | C4: =ESTADISTICA!C2 -> Bombero Galarza y Necochea | D4: =ESTADISTICA!D2 -> Domo | E4: =ESTADISTICA!E2 -> FIBRA OPTICA | F4: =ESTADISTICA!F2 -> 0 | G4: =ESTADISTICA!G2 -> 0 | H4: =ESTADISTICA!H2 -> 0 | ... AI4: =ESTADISTICA!AI2 -> 0
A5: =ESTADISTICA!A3 -> ALTAMIRA | B5: =ESTADISTICA!B3 -> ALT 04 | C5: =ESTADISTICA!C3 -> Francia y Necochea | D5: =ESTADISTICA!D3 -> Domo | E5: =ESTADISTICA!E3 -> FIBRA OPTICA | F5: =ESTADISTICA!F3 -> 0 | G5: =ESTADISTICA!G3 -> 0 | H5: =ESTADISTICA!H3 -> 0 | ... AI5: =ESTADISTICA!AI3 -> 0
A6: =ESTADISTICA!A4 -> ALTAMIRA | B6: =ESTADISTICA!B4 -> ALT 06 | C6: =ESTADISTICA!C4 -> LOPE DE VEGA Y NECOCHEA | D6: =ESTADISTICA!D4 -> Domo | E6: =ESTADISTICA!E4 -> PTO A FO | F6: =ESTADISTICA!F4 -> APAGADO | G6: =ESTADISTICA!G4 -> APAGADO | H6: =ESTADISTICA!H4 -> APAGADO | ... AI6: =ESTADISTICA!AI4 -> 0
A7: =ESTADISTICA!A5 -> ALTAMIRA | B7: =ESTADISTICA!B5 -> ALT 08 | C7: =ESTADISTICA!C5 -> HUMAITA Y NECOCHEA | D7: =ESTADISTICA!D5 -> DOMO | E7: =ESTADISTICA!E5 -> Fibra Optica | F7: =ESTADISTICA!F5 -> 0 | G7: =ESTADISTICA!G5 -> 0 | H7: =ESTADISTICA!H5 -> 0 | ... AI7: =ESTADISTICA!AI5 -> 0
A8: =ESTADISTICA!A6 -> ALTAMIRA | B8: =ESTADISTICA!B6 -> ALT 09 | C8: =ESTADISTICA!C6 -> NECOCHEA Y CURUPAITY | D8: =ESTADISTICA!D6 -> DOMO | E8: =ESTADISTICA!E6 -> Fibra Optica | F8: =ESTADISTICA!F6 -> 0 | G8: =ESTADISTICA!G6 -> 0 | H8: =ESTADISTICA!H6 -> 0 | ... AI8: =ESTADISTICA!AI6 -> 0
A9: =ESTADISTICA!A7 -> ALTAMIRA | B9: =ESTADISTICA!B7 -> ALT 10 | C9: =ESTADISTICA!C7 -> Calchaqui y Francia | D9: =ESTADISTICA!D7 -> Domo | E9: =ESTADISTICA!E7 -> Radio | F9: =ESTADISTICA!F7 -> 0 | G9: =ESTADISTICA!G7 -> 0 | H9: =ESTADISTICA!H7 -> 0 | ... AI9: =ESTADISTICA!AI7 -> 0
A10: =ESTADISTICA!A8 -> ALTAMIRA | B10: =ESTADISTICA!B8 -> ALT01 | C10: =ESTADISTICA!C8 -> Calchaqui y Sgto. Cabral | D10: =ESTADISTICA!D8 -> Domo | E10: =ESTADISTICA!E8 -> Fibra Optica | F10: =ESTADISTICA!F8 -> 0 | G10: =ESTADISTICA!G8 -> 0 | H10: =ESTADISTICA!H8 -> 0 | ... AI10: =ESTADISTICA!AI8 -> 0
A11: =ESTADISTICA!A9 -> ALTAMIRA | B11: =ESTADISTICA!B9 -> ALT02 | C11: =ESTADISTICA!C9 -> Calchaqui y Lope de Vega | D11: =ESTADISTICA!D9 -> Domo | E11: =ESTADISTICA!E9 -> PTO A FO | F11: =ESTADISTICA!F9 -> 0 | G11: =ESTADISTICA!G9 -> 0 | H11: =ESTADISTICA!H9 -> 0 | ... AI11: =ESTADISTICA!AI9 -> 0
A12: =ESTADISTICA!A10 -> ALTAMIRA | B12: =ESTADISTICA!B10 -> ALT05 | C12: =ESTADISTICA!C10 -> Av. Calchaqui y Bombero Galarza | D12: =ESTADISTICA!D10 -> Domo | E12: =ESTADISTICA!E10 -> PTO A FO | F12: =ESTADISTICA!F10 -> 0 | G12: =ESTADISTICA!G10 -> 0 | H12: =ESTADISTICA!H10 -> 0 | ... AI12: =ESTADISTICA!AI10 -> 0
A13: =ESTADISTICA!A11 -> ALTAMIRA | B13: =ESTADISTICA!B11 -> ALT07 | C13: =ESTADISTICA!C11 -> AV. CALCHAQUI Y AV. DEL TRABAJO | D13: =ESTADISTICA!D11 -> DOMO | E13: =ESTADISTICA!E11 -> PTO A FO | F13: =ESTADISTICA!F11 -> 0 | G13: =ESTADISTICA!G11 -> 0 | H13: =ESTADISTICA!H11 -> 0 | ... AI13: =ESTADISTICA!AI11 -> 0
A14: =ESTADISTICA!A12 -> AGUSTIN RAMIREZ | B14: =ESTADISTICA!B12 -> ARA 01 | C14: =ESTADISTICA!C12 -> Malambo y Tranquera | D14: =ESTADISTICA!D12 -> Domo | E14: =ESTADISTICA!E12 -> FIBRA OPTICA | F14: =ESTADISTICA!F12 -> 0 | G14: =ESTADISTICA!G12 -> 0 | H14: =ESTADISTICA!H12 -> 0 | ... AI14: =ESTADISTICA!AI12 -> 0
... A278: =ESTADISTICA!A276 -> SAN JORGE | B278: =ESTADISTICA!B276 -> SJO07 (fija 1) | C278: =ESTADISTICA!C276 -> 503 Y 556 | D278: =ESTADISTICA!D276 -> Fija | E278: =ESTADISTICA!E276 -> Fibra Optica | F278: =ESTADISTICA!F276 -> 0 | G278: =ESTADISTICA!G276 -> 0 | H278: =ESTADISTICA!H276 -> APAGADO | ... AI278: =ESTADISTICA!AI276 -> 0
B279: =ESTADISTICA!B277 -> SJO08 (fija 2) | C279: =ESTADISTICA!C277 -> 503 Y 556 | D279: =ESTADISTICA!D277 -> Fija | E279: =ESTADISTICA!E277 -> Fibra Optica | F279: =ESTADISTICA!F277 -> 0 | G279: =ESTADISTICA!G277 -> 0 | H279: =ESTADISTICA!H277 -> 0 | I279: =ESTADISTICA!I277 -> 0 | ... AI279: =ESTADISTICA!AI277 -> 0
A280: =ESTADISTICA!A278 -> SANTO TOMAS | B280: =ESTADISTICA!B278 -> SJU01 | C280: =ESTADISTICA!C278 -> Ruta 36 y Pte.Peron | D280: =ESTADISTICA!D278 -> Domo | E280: =ESTADISTICA!E278 -> Radio | F280: =ESTADISTICA!F278 -> 0 | G280: =ESTADISTICA!G278 -> 0 | H280: =ESTADISTICA!H278 -> 0 | ... AI280: =ESTADISTICA!AI278 -> APAGADO
A281: =ESTADISTICA!A279 -> VILLA GENERAL SAN MARTIN | B281: =ESTADISTICA!B279 -> SMA 03 | C281: =ESTADISTICA!C279 -> ROSARIO Y SAN NICOLAS | D281: =ESTADISTICA!D279 -> Domo | E281: =ESTADISTICA!E279 -> Radio | F281: =ESTADISTICA!F279 -> 0 | G281: =ESTADISTICA!G279 -> 0 | H281: =ESTADISTICA!H279 -> 0 | ... AI281: =ESTADISTICA!AI279 -> 0
A282: =ESTADISTICA!A280 -> VILLA GENERAL SAN MARTIN | B282: =ESTADISTICA!B280 -> SMA 04 | C282: =ESTADISTICA!C280 -> HUDSON Y MONTEVIDEO | D282: =ESTADISTICA!D280 -> FIJA | E282: =ESTADISTICA!E280 -> Radio | F282: =ESTADISTICA!F280 -> APAGADO | G282: =ESTADISTICA!G280 -> APAGADO | H282: =ESTADISTICA!H280 -> APAGADO | ... AI282: =ESTADISTICA!AI280 -> 0
A283: =ESTADISTICA!A281 -> VILLA GENERAL SAN MARTIN | B283: =ESTADISTICA!B281 -> SMA 06 | C283: =ESTADISTICA!C281 -> AV. HUDSON Y RIO IGUAZU | D283: =ESTADISTICA!D281 -> DOMO | E283: =ESTADISTICA!E281 -> Fibra Optica | F283: =ESTADISTICA!F281 -> 0 | G283: =ESTADISTICA!G281 -> 0 | H283: =ESTADISTICA!H281 -> 0 | ... AI283: =ESTADISTICA!AI281 -> 0
A284: =ESTADISTICA!A282 -> VILLA GENERAL SAN MARTIN | B284: =ESTADISTICA!B282 -> SMA 07 | C284: =ESTADISTICA!C282 -> AV. HUDSON Y RIO TURBIO | D284: =ESTADISTICA!D282 -> DOMO | E284: =ESTADISTICA!E282 -> Fibra Optica | F284: =ESTADISTICA!F282 -> 0 | G284: =ESTADISTICA!G282 -> 0 | H284: =ESTADISTICA!H282 -> 0 | ... AI284: =ESTADISTICA!AI282 -> 0
A285: =ESTADISTICA!A283 -> VILLA GENERAL SAN MARTIN | B285: =ESTADISTICA!B283 -> SMA01 | C285: =ESTADISTICA!C283 -> Hudson y Montevideo | D285: =ESTADISTICA!D283 -> DOMO | E285: =ESTADISTICA!E283 -> Radio | F285: =ESTADISTICA!F283 -> 0 | G285: =ESTADISTICA!G283 -> 0 | H285: =ESTADISTICA!H283 -> 0 | ... AI285: =ESTADISTICA!AI283 -> 0
A286: =ESTADISTICA!A284 -> VILLA GENERAL SAN MARTIN | B286: =ESTADISTICA!B284 -> SMA02 | C286: =ESTADISTICA!C284 -> Hudson y San Nicolas | D286: =ESTADISTICA!D284 -> Domo | E286: =ESTADISTICA!E284 -> Radio | F286: =ESTADISTICA!F284 -> 0 | G286: =ESTADISTICA!G284 -> 0 | H286: =ESTADISTICA!H284 -> 0 | ... AI286: =ESTADISTICA!AI284 -> 0
A287: =ESTADISTICA!A285 -> VILLA GENERAL SAN MARTIN | B287: =ESTADISTICA!B285 -> SMA05 | C287: =ESTADISTICA!C285 -> MONTEVIDEO Y VILLEGAS | D287: =ESTADISTICA!D285 -> DOMO | E287: =ESTADISTICA!E285 -> PTO A FO | F287: =ESTADISTICA!F285 -> 0 | G287: =ESTADISTICA!G285 -> 0 | H287: =ESTADISTICA!H285 -> 0 | ... AI287: =ESTADISTICA!AI285 -> 0
A288: =ESTADISTICA!A286 -> SAN NICOLAS | B288: =ESTADISTICA!B286 -> SNI 03 (fija 1) | C288: =ESTADISTICA!C286 -> SARRATEA Y LOS TREBOLES | D288: =ESTADISTICA!D286 -> Fija | E288: =ESTADISTICA!E286 -> Fibra Optica | F288: =ESTADISTICA!F286 -> 0 | G288: =ESTADISTICA!G286 -> 0 | H288: =ESTADISTICA!H286 -> 0 | ... AI288: =ESTADISTICA!AI286 -> 0
A289: =ESTADISTICA!A287 -> SAN NICOLAS | B289: =ESTADISTICA!B287 -> SNI 04 (fija 2) | C289: =ESTADISTICA!C287 -> SARRATEA Y LOS TREBOLES | D289: =ESTADISTICA!D287 -> Fija | E289: =ESTADISTICA!E287 -> Fibra Optica | F289: =ESTADISTICA!F287 -> 0 | G289: =ESTADISTICA!G287 -> 0 | H289: =ESTADISTICA!H287 -> 0 | ... AI289: =ESTADISTICA!AI287 -> 0
A290: =ESTADISTICA!A288 -> SAN NICOLAS | B290: =ESTADISTICA!B288 -> SNI01 (fija 1) | C290: =ESTADISTICA!C288 -> SARRATEA E/ EEUU DE A. Y AGRELO | D290: =ESTADISTICA!D288 -> Fija | E290: =ESTADISTICA!E288 -> Fibra Optica | F290: =ESTADISTICA!F288 -> 0 | G290: =ESTADISTICA!G288 -> 0 | H290: =ESTADISTICA!H288 -> 0 | ... AI290: =ESTADISTICA!AI288 -> 0
A291: =ESTADISTICA!A289 -> SAN NICOLAS | B291: =ESTADISTICA!B289 -> SNI02 (fija 2) | C291: =ESTADISTICA!C289 -> SARRATEA E/ EEUU DE A. Y AGRELO | D291: =ESTADISTICA!D289 -> Fija | E291: =ESTADISTICA!E289 -> Fibra Optica | F291: =ESTADISTICA!F289 -> 0 | G291: =ESTADISTICA!G289 -> 0 | H291: =ESTADISTICA!H289 -> 0 | ... AI291: =ESTADISTICA!AI289 -> 0
