Workbook
Name _25_de_agosto: 'RESUMEN TOTAL'!$A$4:$D$389
Name _25_de_agosto_3: 'RESUMEN TOTAL'!$A$4:$D$401
Name _30_mar: 'APAGADOS ANTENA'!$AI$3
Name BONOMOcam: Hoja1!$B$2
Name CANTIDAD_DE_CAMARAS: 'RESUMEN TOTAL'!$B$1
Name COSEIDIcam: Hoja1!$B$4

Sheet RESUMEN TOTAL
A1: CANTIDAD DE CAMARAS | B1: =COUNTA(B5:B625) -> 539 | D1: PORCIENTO DE CAIDAS | L1: =(L3)/(L2+L3) -> 0.22655123 | M1: =(M3)/(M2+M3) -> 0.22318841 | N1: =(N3)/(N2+N3) -> 0.22093023 | O1: =(O3)/(O2+O3) -> 0.21176471 | P1: =(P3)/(P2+P3) -> 0.18167939 | Q1: =(Q3)/(Q2+Q3) -> 0.18541033 | R1: =(R3)/(R2+R3) -> 0.19033233 | S1: =(S3)/(S2+S3) -> 0.21522694 | ... X1: =(X3)/(X2+X3) -> 0 | Z1: =(Z3)/(Z2+Z3) -> 0.20119225 | AA1: =(AA3)/(AA2+AA3) -> 0.2 | AB1: =(AB3)/(AB2+AB3) -> 0.1964018 | AC1: =(AC3)/(AC2+AC3) -> 0.1951952 | AD1: =(AD3)/(AD2+AD3) -> 0.17917305 | AE1: =(AE3)/(AE2+AE3) -> 0.17917305 | AF1: =(AF3)/(AF2+AF3) -> 0.18042813 | AG1: =(AG3)/(AG2+AG3) -> 0.17538462 | ... AO1: =(AO3)/(AO2+AO3) -> 0.17665131
D2: FUNCIONAN | L2: 536 | M2: 536 | N2: 536 | O2: 536 | P2: 536 | Q2: 536 | R2: 536 | S2: 536 | T2: 536 | U2: 536 | V2: 536 | W2: 536 | X2: 536 | Y2: 536 | Z2: 536 | AA2: 536 | AB2: 536 | AC2: 536 | AD2: 536 | AE2: 536 | AF2: 536 | AG2: 536 | AH2: 536 | AI2: 536 | AJ2: 536 | AK2: 536 | AL2: 536 | AM2: 536 | AN2: 536 | AO2: 536
D3: CAIDAS | L3: =COUNTIF(L4:L625, "apagado") -> 157 | M3: =COUNTIF(M4:M625, "apagado") -> 154 | N3: =COUNTIF(N4:N625, "apagado") -> 152 | O3: =COUNTIF(O4:O625, "apagado") -> 144 | P3: =COUNTIF(P4:P625, "apagado") -> 119 | Q3: =COUNTIF(Q4:Q625, "apagado") -> 122 | R3: =COUNTIF(R4:R625, "apagado") -> 126 | S3: =COUNTIF(S4:S625, "apagado") -> 147 | ... W3: =COUNTIF(W4:W625, "apagado") -> 116 | X3: =COUNTIF(X4:X525, "apagado") -> 0 | Y3: =COUNTIF(Y4:Y525, "apagado") -> 146 | Z3: =COUNTIF(Z4:Z625, "apagado") -> 135 | AA3: =COUNTIF(AA4:AA625, "apagado") -> 134 | AB3: =COUNTIF(AB4:AB625, "apagado") -> 131 | AC3: =COUNTIF(AC4:AC625, "apagado") -> 130 | AD3: =COUNTIF(AD4:AD625, "apagado") -> 117 | AE3: =COUNTIF(AE4:AE625, "apagado") -> 117 | AF3: =COUNTIF(AF4:AF625, "apagado") -> 118 | AG3: =COUNTIF(AG4:AG625, "apagado") -> 114 | ... AO3: =COUNTIF(AO4:AO625, "apagado") -> 115
A4: Barrio | B4: [Denominacion] | C4: [Empresa Mantenimiento] | D4: [Ubicacion] | E4: [Tipo de Camara] | F4: [Tipo de Conexion] | G4: Destino | I4: DIAS FUNCIONANDO | J4: DIAS CAIDA | K4: EFECTIVIDAD | L4: 45383 | M4: 45384 | N4: 45385 | O4: 45386 | P4: 45387 | Q4: 45388 | R4: 45389 | S4: 45390 | T4: 45391 | U4: 45392 | V4: 45393 | W4: 45394 | X4: 45395 | Y4: 45396 | Z4: 45397 | AA4: 45398 | AB4: 45399 | AC4: 45400 | AD4: 45401 | AE4: 45402 | AF4: 45403 | AG4: 45404 | AH4: 45405 | AI4: 45406 | AJ4: 45407 | AK4: 45408 | AL4: 45409 | AM4: 45410 | AN4: 45411 | AO4: 45412
A5: ALTAMIRA | B5: ALT01 | C5: BONOMO | D5: Calchaqui y Sgto. Cabral | E5: Domo | F5: Fibra Optica | H5: 172.20.10.6 | I5: =COUNTIF(L5:AM5,"") -> 18 | J5: =COUNTIF(L5:AM5,"APAGADO") -> 10 | K5: =(I5)/(J5+I5) -> 0.64285714 | Y5: APAGADO | AA5: APAGADO | AB5: APAGADO | AC5: APAGADO | AD5: APAGADO | AE5: APAGADO | AF5: APAGADO | AG5: APAGADO | AH5: APAGADO | AI5: APAGADO
A6: ALTAMIRA | B6: ALT02 | C6: BONOMO | D6: Calchaqui y Lope de Vega | E6: Domo | F6: PTO A FO | G6: CABRAL Y CALCHAQUI | H6: 172.20.12.218 | I6: =COUNTIF(L6:AM6,"") -> 18 | J6: =COUNTIF(L6:AM6,"APAGADO") -> 10 | K6: =(I6)/(J6+I6) -> 0.64285714 | Y6: APAGADO | AA6: APAGADO | AB6: APAGADO | AC6: APAGADO | AD6: APAGADO | AE6: APAGADO | AF6: APAGADO | AG6: APAGADO | AH6: APAGADO | AI6: APAGADO
A7: ALTAMIRA | B7: ALT 03 | C7: BONOMO | D7: Bombero Galarza y Necochea | E7: Domo | F7: Fibra Optica | H7: 172.20.12.54 | I7: =COUNTIF(L7:AM7,"") -> 18 | J7: =COUNTIF(L7:AM7,"APAGADO") -> 10 | K7: =(I7)/(J7+I7) -> 0.64285714 | Y7: APAGADO | AA7: APAGADO | AB7: APAGADO | AC7: APAGADO | AD7: APAGADO | AE7: APAGADO | AF7: APAGADO | AG7: APAGADO | AH7: APAGADO | AI7: APAGADO
A8: ALTAMIRA | B8: ALT 04 | C8: BONOMO | D8: Francia y Necochea | E8: Domo | F8: Fibra Optica | H8: 172.20.12.55 | I8: =COUNTIF(L8:AM8,"") -> 18 | J8: =COUNTIF(L8:AM8,"APAGADO") -> 10 | K8: =(I8)/(J8+I8) -> 0.64285714 | Y8: APAGADO | AA8: APAGADO | AB8: APAGADO | AC8: APAGADO | AD8: APAGADO | AE8: APAGADO | AF8: APAGADO | AG8: APAGADO | AH8: APAGADO | AI8: APAGADO
A9: ALTAMIRA | B9: ALT05 | C9: BONOMO | D9: Av. Calchaqui y Bombero Galarza | E9: Domo | F9: PTO A FO | G9: NECOCHEA Y GALARZA | H9: 172.20.12.216 | I9: =COUNTIF(L9:AM9,"") -> 18 | J9: =COUNTIF(L9:AM9,"APAGADO") -> 10 | K9: =(I9)/(J9+I9) -> 0.64285714 | Y9: APAGADO | AA9: APAGADO | AB9: APAGADO | AC9: APAGADO | AD9: APAGADO | AE9: APAGADO | AF9: APAGADO | AG9: APAGADO | AH9: APAGADO | AI9: APAGADO
A10: ALTAMIRA | B10: ALT 06 | C10: BONOMO | D10: LOPE DE VEGA Y NECOCHEA | E10: Domo | F10: PTO A FO | G10: NECOCHEA Y GALARZA | H10: 172.20.12.12 | I10: =COUNTIF(L10:AM10,"") -> 18 | J10: =COUNTIF(L10:AM10,"APAGADO") -> 10 | K10: =(I10)/(J10+I10) -> 0.64285714 | Y10: APAGADO | AA10: APAGADO | AB10: APAGADO | AC10: APAGADO | AD10: APAGADO | AE10: APAGADO | AF10: APAGADO | AG10: APAGADO | AH10: APAGADO | AI10: APAGADO
A11: ALTAMIRA | B11: ALT07 | C11: BONOMO | D11: AV. CALCHAQUI Y AV. DEL TRABAJO | E11: DOMO | F11: PTO A FO | G11: CABRAL Y CALCHAQUI | H11: 172.20.10.57 | I11: =COUNTIF(L11:AM11,"") -> 18 | J11: =COUNTIF(L11:AM11,"APAGADO") -> 10 | K11: =(I11)/(J11+I11) -> 0.64285714 | Y11: APAGADO | AA11: APAGADO | AB11: APAGADO | AC11: APAGADO | AD11: APAGADO | AE11: APAGADO | AF11: APAGADO | AG11: APAGADO | AH11: APAGADO | AI11: APAGADO
A12: ALTAMIRA | B12: ALT 08 | C12: BONOMO | D12: HUMAITA Y NECOCHEA | E12: DOMO | F12: Fibra Optica | H12: 172.20.11.215 | I12: =COUNTIF(L12:AM12,"") -> 18 | J12: =COUNTIF(L12:AM12,"APAGADO") -> 10 | K12: =(I12)/(J12+I12) -> 0.64285714 | Y12: APAGADO | AA12: APAGADO | AB12: APAGADO | AC12: APAGADO | AD12: APAGADO | AE12: APAGADO | AF12: APAGADO | AG12: APAGADO | AH12: APAGADO | AI12: APAGADO
A13: ALTAMIRA | B13: ALT 09 | C13: BONOMO | D13: NECOCHEA Y CURUPAITY | E13: DOMO | F13: Fibra Optica | H13: 172.20.11.216 | I13: =COUNTIF(L13:AM13,"") -> 3 | J13: =COUNTIF(L13:AM13,"APAGADO") -> 25 | K13: =(I13)/(J13+I13) -> 0.10714286 | L13: APAGADO | M13: APAGADO | N13: APAGADO | O13: APAGADO | P13: APAGADO | Q13: APAGADO | R13: APAGADO | S13: APAGADO | T13: APAGADO | U13: APAGADO | V13: APAGADO | W13: APAGADO | Y13: APAGADO | Z13: APAGADO | AA13: APAGADO | AB13: APAGADO | AC13: APAGADO | AD13: APAGADO | AE13: APAGADO | AF13: APAGADO | AG13: APAGADO | AH13: APAGADO | AI13: APAGADO | AJ13: APAGADO | AK13: APAGADO | AO13: APAGADO
A14: ALTAMIRA | B14: ALT 10 | C14: BONOMO | D14: Calchaqui y Francia | E14: Domo | F14: Radio | H14: 172.20.12.156 | I14: =COUNTIF(L14:AM14,"") -> 18 | J14: =COUNTIF(L14:AM14,"APAGADO") -> 10 | K14: =(I14)/(J14+I14) -> 0.64285714 | Y14: APAGADO | AA14: APAGADO | AB14: APAGADO | AC14: APAGADO | AD14: APAGADO | AE14: APAGADO | AF14: APAGADO | AG14: APAGADO | AH14: APAGADO | AI14: APAGADO
A15: AGUSTIN RAMIREZ | B15: ARA 01 | C15: BONOMO | D15: Malambo y Tranquera | E15: Domo | F15: Fibra Optica | H15: 172.20.12.110 | I15: =COUNTIF(L15:AM15,"") -> 5 | J15: =COUNTIF(L15:AM15,"APAGADO") -> 23 | K15: =(I15)/(J15+I15) -> 0.17857143 | L15: APAGADO | M15: APAGADO | N15: APAGADO | O15: APAGADO | P15: APAGADO | Q15: APAGADO | R15: APAGADO | S15: APAGADO | T15: APAGADO | U15: APAGADO | V15: APAGADO | W15: APAGADO | Y15: APAGADO | Z15: APAGADO | AA15: APAGADO | AB15: APAGADO | AC15: APAGADO | AD15: APAGADO | AE15: APAGADO | AF15: APAGADO | AG15: APAGADO | AH15: APAGADO | AI15: APAGADO
A16: BELGRANO | B16: BEL 01 | C16: BONOMO | D16: San Martin y Dardo Rocha | E16: DOMO | F16: Fibra Optica | H16: 172.20.12.64 | I16: =COUNTIF(L16:AM16,"") -> 21 | J16: =COUNTIF(L16:AM16,"APAGADO") -> 7 | K16: =(I16)/(J16+I16) -> 0.75 | AE16: APAGADO | AF16: APAGADO | AG16: APAGADO | AH16: APAGADO | AI16: APAGADO | AJ16: APAGADO | AK16: APAGADO | AO16: APAGADO
A17: BELGRANO | B17: BEL 02 | C17: BONOMO | D17: Guardia vieja y Fronteriz | E17: DOMO | F17: Fibra Optica | I17: =COUNTIF(L17:AM17,"") -> 21 | J17: =COUNTIF(L17:AM17,"APAGADO") -> 7 | K17: =(I17)/(J17+I17) -> 0.75 | AE17: APAGADO | AF17: APAGADO | AG17: APAGADO | AH17: APAGADO | AI17: APAGADO | AJ17: APAGADO | AK17: APAGADO | AO17: APAGADO
A18: BOSQUES CENTRO | B18: BOSQC 01 | C18: COSEIDI | D18: LUIS AGOTE E/DANUNCIO Y CAMPOAMOR | E18: Fija | F18: Radio | H18: 172.20.11.15 | I18: =COUNTIF(L18:AM18,"") -> 28 | J18: =COUNTIF(L18:AM18,"APAGADO") -> 0 | K18: =(I18)/(J18+I18) -> 1
A19: BOSQUES CENTRO | B19: BOSQC 02 | C19: COSEIDI | D19: LUIS AGOTE E/DANUNCIO Y CAMPOAMOR | E19: Fija | F19: Radio | H19: 172.20.11.16 | I19: =COUNTIF(L19:AM19,"") -> 28 | J19: =COUNTIF(L19:AM19,"APAGADO") -> 0 | K19: =(I19)/(J19+I19) -> 1
A20: BOSQUES CENTRO | B20: BOSQC 03 | C20: COSEIDI | D20: BENAVENTE Y LUIS AGOTE | E20: Fija | F20: Radio | H20: 172.20.11.13 | I20: =COUNTIF(L20:AM20,"") -> 28 | J20: =COUNTIF(L20:AM20,"APAGADO") -> 0 | K20: =(I20)/(J20+I20) -> 1
A21: BOSQUES CENTRO | B21: BOSQC 04 | C21: COSEIDI | D21: BENAVENTE Y LUIS AGOTE | E21: Fija | F21: Radio | H21: 172.20.11.113 | I21: =COUNTIF(L21:AM21,"") -> 28 | J21: =COUNTIF(L21:AM21,"APAGADO") -> 0 | K21: =(I21)/(J21+I21) -> 1
A22: BOSQUES CENTRO | B22: BOSQC 05 | C22: COSEIDI | D22: LUIS AGOTE Y RUTA 36 | E22: Fija | F22: Radio | H22: 172.20.11.17 | I22: =COUNTIF(L22:AM22,"") -> 28 | J22: =COUNTIF(L22:AM22,"APAGADO") -> 0 | K22: =(I22)/(J22+I22) -> 1
A23: BOSQUES CENTRO | B23: BOSQC 06 | C23: COSEIDI | D23: LUIS AGOTE Y RUTA 36 | E23: Fija | F23: Radio | H23: 172.20.11.18 | I23: =COUNTIF(L23:AM23,"") -> 28 | J23: =COUNTIF(L23:AM23,"APAGADO") -> 0 | K23: =(I23)/(J23+I23) -> 1
A24: CENTRO | B24: CEN01 | C24: BONOMO | D24: San Martin y 9 de Julio | E24: Fija | F24: Fibra Optica | H24: 172.20.11.10 | I24: =COUNTIF(L24:AM24,"") -> 3 | J24: =COUNTIF(L24:AM24,"APAGADO") -> 25 | K24: =(I24)/(J24+I24) -> 0.10714286 | L24: APAGADO | M24: APAGADO | N24: APAGADO | O24: APAGADO | P24: APAGADO | Q24: APAGADO | R24: APAGADO | S24: APAGADO | T24: APAGADO | U24: APAGADO | V24: APAGADO | W24: APAGADO | Y24: APAGADO | Z24: APAGADO | AA24: APAGADO | AB24: APAGADO | AC24: APAGADO | AD24: APAGADO | AE24: APAGADO | AF24: APAGADO | AG24: APAGADO | AH24: APAGADO | AI24: APAGADO | AJ24: APAGADO | AK24: APAGADO | AO24: APAGADO
A25: CENTRO | B25: CEN02 | C25: BONOMO | D25: San Martin y Almafuerte | E25: Fija | F25: Fibra Optica | H25: 172.20.11.11 | I25: =COUNTIF(L25:AM25,"") -> 3 | J25: =COUNTIF(L25:AM25,"APAGADO") -> 25 | K25: =(I25)/(J25+I25) -> 0.10714286 | L25: APAGADO | M25: APAGADO | N25: APAGADO | O25: APAGADO | P25: APAGADO | Q25: APAGADO | R25: APAGADO | S25: APAGADO | T25: APAGADO | U25: APAGADO | V25: APAGADO | W25: APAGADO | Y25: APAGADO | Z25: APAGADO | AA25: APAGADO | AB25: APAGADO | AC25: APAGADO | AD25: APAGADO | AE25: APAGADO | AF25: APAGADO | AG25: APAGADO | AH25: APAGADO | AI25: APAGADO | AJ25: APAGADO | AK25: APAGADO | AO25: APAGADO
A26: CENTRO | B26: CEN03 | C26: BONOMO | D26: San Martin y Sallares | E26: Domo | F26: Fibra Optica | H26: 172.20.12.30 | I26: =COUNTIF(L26:AM26,"") -> 28 | J26: =COUNTIF(L26:AM26,"APAGADO") -> 0 | K26: =(I26)/(J26+I26) -> 1
A27: CENTRO | B27: CEN04 | C27: BONOMO | D27: San Martin y Contreras | E27: Domo | F27: Fibra Optica | H27: 172.20.12.29 | I27: =COUNTIF(L27:AM27,"") -> 28 | J27: =COUNTIF(L27:AM27,"APAGADO") -> 0 | K27: =(I27)/(J27+I27) -> 1
A28: CENTRO | B28: CEN 05 | C28: BONOMO | D28: Bocuzzi e/España y San Martin | E28: DOMO | F28: Fibra Optica | H28: 172.20.10.200 | I28: =COUNTIF(L28:AM28,"") -> 11 | J28: =COUNTIF(L28:AM28,"APAGADO") -> 17 | K28: =(I28)/(J28+I28) -> 0.39285714 | L28: APAGADO | M28: APAGADO | N28: APAGADO | O28: APAGADO | P28: APAGADO | Q28: APAGADO | R28: APAGADO | S28: APAGADO | T28: APAGADO | U28: APAGADO | V28: APAGADO | W28: APAGADO | Y28: APAGADO | Z28: APAGADO | AA28: APAGADO | AB28: APAGADO | AC28: APAGADO
A29: CENTRO | B29: CEN06 | C29: BONOMO | D29: Monteagudo y A.del Valle | E29: Fija | F29: Fibra Optica | H29: 172.20.10.02 | I29: =COUNTIF(L29:AM29,"") -> 3 | J29: =COUNTIF(L29:AM29,"APAGADO") -> 25 | K29: =(I29)/(J29+I29) -> 0.10714286 | L29: APAGADO | M29: APAGADO | N29: APAGADO | O29: APAGADO | P29: APAGADO | Q29: APAGADO | R29: APAGADO | S29: APAGADO | T29: APAGADO | U29: APAGADO | V29: APAGADO | W29: APAGADO | Y29: APAGADO | Z29: APAGADO | AA29: APAGADO | AB29: APAGADO | AC29: APAGADO | AD29: APAGADO | AE29: APAGADO | AF29: APAGADO | AG29: APAGADO | AH29: APAGADO | AI29: APAGADO | AJ29: APAGADO | AK29: APAGADO | AO29: APAGADO
A30: CENTRO | B30: CEN07 | C30: BONOMO | D30: San Martin y Guemes | E30: DOMO | F30: Fibra Optica | H30: 172.20.11.20 | I30: =COUNTIF(L30:AM30,"") -> 28 | J30: =COUNTIF(L30:AM30,"APAGADO") -> 0 | K30: =(I30)/(J30+I30) -> 1
A31: CENTRO | B31: CEN08 | C31: BONOMO | D31: San Martin y Pte.Peron | E31: Domo | F31: Fibra Optica | H31: 172.20.11.21 | I31: =COUNTIF(L31:AM31,"") -> 28 | J31: =COUNTIF(L31:AM31,"APAGADO") -> 0 | K31: =(I31)/(J31+I31) -> 1 | AO31: APAGADO
A32: CENTRO | B32: CEN09 | C32: BONOMO | D32: Chacabuco y 25 de Mayo | E32: Domo | F32: Fibra Optica | H32: 172.20.11.22 | I32: =COUNTIF(L32:AM32,"") -> 28 | J32: =COUNTIF(L32:AM32,"APAGADO") -> 0 | K32: =(I32)/(J32+I32) -> 1
A33: CENTRO | B33: CEN10 | C33: BONOMO | D33: Monteagudo y Pte. Peron | E33: Domo | F33: Fibra Optica | H33: 172.20.11.23 | I33: =COUNTIF(L33:AM33,"") -> 28 | J33: =COUNTIF(L33:AM33,"APAGADO") -> 0 | K33: =(I33)/(J33+I33) -> 1
A34: CENTRO | B34: CEN11 | C34: BONOMO | D34: Monteagudo y Bocuzzi | E34: Domo | F34: Fibra Optica | H34: 172.20.10.24 | I34: =COUNTIF(L34:AM34,"") -> 28 | J34: =COUNTIF(L34:AM34,"APAGADO") -> 0 | K34: =(I34)/(J34+I34) -> 1
A35: CENTRO | B35: CEN 12 | C35: BONOMO | D35: Monteagudo y Mitre | E35: Domo | F35: Fibra Optica | H35: 172.20.10.23 | I35: =COUNTIF(L35:AM35,"") -> 28 | J35: =COUNTIF(L35:AM35,"APAGADO") -> 0 | K35: =(I35)/(J35+I35) -> 1
A36: CENTRO | B36: CEN 13 | C36: BONOMO | D36: 25 de Mayo y Maipu | E36: DOMO | F36: Fibra Optica | H36: 172.20.10.20 | I36: =COUNTIF(L36:AM36,"") -> 28 | J36: =COUNTIF(L36:AM36,"APAGADO") -> 0 | K36: =(I36)/(J36+I36) -> 1
A37: CENTRO | B37: CEN14 | C37: BONOMO | D37: Pte.Peron e/Pringles y Brown | E37: Domo | F37: Fibra Optica | H37: 172.20.10.94 | I37: =COUNTIF(L37:AM37,"") -> 28 | J37: =COUNTIF(L37:AM37,"APAGADO") -> 0 | K37: =(I37)/(J37+I37) -> 1
A38: CENTRO | B38: CEN15 | C38: BONOMO | D38: Alberdi y A.del Valle | E38: Domo | F38: Fibra Optica | H38: 172.20.10.35 | I38: =COUNTIF(L38:AM38,"") -> 28 | J38: =COUNTIF(L38:AM38,"APAGADO") -> 0 | K38: =(I38)/(J38+I38) -> 1
A39: CENTRO | B39: CEN16 | C39: BONOMO | D39: San Martin y Pte. Peron | E39: Fija | F39: Fibra Optica | H39: 172.20.12.36 | I39: =COUNTIF(L39:AM39,"") -> 28 | J39: =COUNTIF(L39:AM39,"APAGADO") -> 0 | K39: =(I39)/(J39+I39) -> 1 | AO39: APAGADO
A40: CENTRO | B40: CEN17 | C40: BONOMO | D40: San Martin y Mitre | E40: Domo | F40: PTO A FO | G40: SAN MARTIN Y SALLARES | H40: 172.20.12.200 | I40: =COUNTIF(L40:AM40,"") -> 28 | J40: =COUNTIF(L40:AM40,"APAGADO") -> 0 | K40: =(I40)/(J40+I40) -> 1
...

Sheet Hoja3

Sheet ESTADISTICA
A1: ='RESUMEN TOTAL'!A4 -> Barrio | B1: ='RESUMEN TOTAL'!B4 -> [Denominacion] | C1: ='RESUMEN TOTAL'!D4 -> [Ubicacion] | D1: ='RESUMEN TOTAL'!E4 -> [Tipo de Camara] | E1: ='RESUMEN TOTAL'!F4 -> [Tipo de Conexion] | F1: ='RESUMEN TOTAL'!L4 -> 45383 | G1: ='RESUMEN TOTAL'!M4 -> 45384 | H1: ='RESUMEN TOTAL'!N4 -> 45385 | I1: ='RESUMEN TOTAL'!O4 -> 45386 | J1: ='RESUMEN TOTAL'!P4 -> 45387 | K1: ='RESUMEN TOTAL'!Q4 -> 45388 | L1: ='RESUMEN TOTAL'!R4 -> 45389 | M1: ='RESUMEN TOTAL'!S4 -> 45390 | ... AH1: ='RESUMEN TOTAL'!AN4 -> 45411
A2: ='RESUMEN TOTAL'!A5 -> ALTAMIRA | B2: ='RESUMEN TOTAL'!B5 -> ALT01 | C2: ='RESUMEN TOTAL'!D5 -> Calchaqui y Sgto. Cabral | D2: ='RESUMEN TOTAL'!E5 -> Domo | E2: ='RESUMEN TOTAL'!F5 -> Fibra Optica | F2: ='RESUMEN TOTAL'!L5 -> 0 | G2: ='RESUMEN TOTAL'!M5 -> 0 | H2: ='RESUMEN TOTAL'!N5 -> 0 | I2: ='RESUMEN TOTAL'!O5 -> 0 | J2: ='RESUMEN TOTAL'!P5 -> 0 | K2: ='RESUMEN TOTAL'!Q5 -> 0 | L2: ='RESUMEN TOTAL'!R5 -> 0 | M2: ='RESUMEN TOTAL'!S5 -> 0 | ... AH2: ='RESUMEN TOTAL'!AN5 -> 0
A3: ='RESUMEN TOTAL'!A6 -> ALTAMIRA | B3: ='RESUMEN TOTAL'!B6 -> ALT02 | C3: ='RESUMEN TOTAL'!D6 -> Calchaqui y Lope de Vega | D3: ='RESUMEN TOTAL'!E6 -> Domo | E3: ='RESUMEN TOTAL'!F6 -> PTO A FO | F3: ='RESUMEN TOTAL'!L6 -> 0 | G3: ='RESUMEN TOTAL'!M6 -> 0 | H3: ='RESUMEN TOTAL'!N6 -> 0 | I3: ='RESUMEN TOTAL'!O6 -> 0 | J3: ='RESUMEN TOTAL'!P6 -> 0 | K3: ='RESUMEN TOTAL'!Q6 -> 0 | L3: ='RESUMEN TOTAL'!R6 -> 0 | M3: ='RESUMEN TOTAL'!S6 -> 0 | ... AH3: ='RESUMEN TOTAL'!AN6 -> 0
A4: ='RESUMEN TOTAL'!A7 -> ALTAMIRA | B4: ='RESUMEN TOTAL'!B7 -> ALT 03 | C4: ='RESUMEN TOTAL'!D7 -> Bombero Galarza y Necochea | D4: ='RESUMEN TOTAL'!E7 -> Domo | E4: ='RESUMEN TOTAL'!F7 -> Fibra Optica | F4: ='RESUMEN TOTAL'!L7 -> 0 | G4: ='RESUMEN TOTAL'!M7 -> 0 | H4: ='RESUMEN TOTAL'!N7 -> 0 | I4: ='RESUMEN TOTAL'!O7 -> 0 | J4: ='RESUMEN TOTAL'!P7 -> 0 | K4: ='RESUMEN TOTAL'!Q7 -> 0 | L4: ='RESUMEN TOTAL'!R7 -> 0 | M4: ='RESUMEN TOTAL'!S7 -> 0 | ... AH4: ='RESUMEN TOTAL'!AN7 -> 0
A5: ='RESUMEN TOTAL'!A8 -> ALTAMIRA | B5: ='RESUMEN TOTAL'!B8 -> ALT 04 | C5: ='RESUMEN TOTAL'!D8 -> Francia y Necochea | D5: ='RESUMEN TOTAL'!E8 -> Domo | E5: ='RESUMEN TOTAL'!F8 -> Fibra Optica | F5: ='RESUMEN TOTAL'!L8 -> 0 | G5: ='RESUMEN TOTAL'!M8 -> 0 | H5: ='RESUMEN TOTAL'!N8 -> 0 | I5: ='RESUMEN TOTAL'!O8 -> 0 | J5: ='RESUMEN TOTAL'!P8 -> 0 | K5: ='RESUMEN TOTAL'!Q8 -> 0 | L5: ='RESUMEN TOTAL'!R8 -> 0 | M5: ='RESUMEN TOTAL'!S8 -> 0 | ... AH5: ='RESUMEN TOTAL'!AN8 -> 0
A6: ='RESUMEN TOTAL'!A9 -> ALTAMIRA | B6: ='RESUMEN TOTAL'!B9 -> ALT05 | C6: ='RESUMEN TOTAL'!D9 -> Av. Calchaqui y Bombero Galarza | D6: ='RESUMEN TOTAL'!E9 -> Domo | E6: ='RESUMEN TOTAL'!F9 -> PTO A FO | F6: ='RESUMEN TOTAL'!L9 -> 0 | G6: ='RESUMEN TOTAL'!M9 -> 0 | H6: ='RESUMEN TOTAL'!N9 -> 0 | I6: ='RESUMEN TOTAL'!O9 -> 0 | J6: ='RESUMEN TOTAL'!P9 -> 0 | K6: ='RESUMEN TOTAL'!Q9 -> 0 | L6: ='RESUMEN TOTAL'!R9 -> 0 | M6: ='RESUMEN TOTAL'!S9 -> 0 | ... AH6: ='RESUMEN TOTAL'!AN9 -> 0
A7: ='RESUMEN TOTAL'!A10 -> ALTAMIRA | B7: ='RESUMEN TOTAL'!B10 -> ALT 06 | C7: ='RESUMEN TOTAL'!D10 -> LOPE DE VEGA Y NECOCHEA | D7: ='RESUMEN TOTAL'!E10 -> Domo | E7: ='RESUMEN TOTAL'!F10 -> PTO A FO | F7: ='RESUMEN TOTAL'!L10 -> 0 | G7: ='RESUMEN TOTAL'!M10 -> 0 | H7: ='RESUMEN TOTAL'!N10 -> 0 | I7: ='RESUMEN TOTAL'!O10 -> 0 | J7: ='RESUMEN TOTAL'!P10 -> 0 | K7: ='RESUMEN TOTAL'!Q10 -> 0 | L7: ='RESUMEN TOTAL'!R10 -> 0 | M7: ='RESUMEN TOTAL'!S10 -> 0 | ... AH7: ='RESUMEN TOTAL'!AN10 -> 0
A8: ='RESUMEN TOTAL'!A11 -> ALTAMIRA | B8: ='RESUMEN TOTAL'!B11 -> ALT07 | C8: ='RESUMEN TOTAL'!D11 -> AV. CALCHAQUI Y AV. DEL TRABAJO | D8: ='RESUMEN TOTAL'!E11 -> DOMO | E8: ='RESUMEN TOTAL'!F11 -> PTO A FO | F8: ='RESUMEN TOTAL'!L11 -> 0 | G8: ='RESUMEN TOTAL'!M11 -> 0 | H8: ='RESUMEN TOTAL'!N11 -> 0 | I8: ='RESUMEN TOTAL'!O11 -> 0 | J8: ='RESUMEN TOTAL'!P11 -> 0 | K8: ='RESUMEN TOTAL'!Q11 -> 0 | L8: ='RESUMEN TOTAL'!R11 -> 0 | M8: ='RESUMEN TOTAL'!S11 -> 0 | ... AH8: ='RESUMEN TOTAL'!AN11 -> 0
A9: ='RESUMEN TOTAL'!A12 -> ALTAMIRA | B9: ='RESUMEN TOTAL'!B12 -> ALT 08 | C9: ='RESUMEN TOTAL'!D12 -> HUMAITA Y NECOCHEA | D9: ='RESUMEN TOTAL'!E12 -> DOMO | E9: ='RESUMEN TOTAL'!F12 -> Fibra Optica | F9: ='RESUMEN TOTAL'!L12 -> 0 | G9: ='RESUMEN TOTAL'!M12 -> 0 | H9: ='RESUMEN TOTAL'!N12 -> 0 | I9: ='RESUMEN TOTAL'!O12 -> 0 | J9: ='RESUMEN TOTAL'!P12 -> 0 | K9: ='RESUMEN TOTAL'!Q12 -> 0 | L9: ='RESUMEN TOTAL'!R12 -> 0 | M9: ='RESUMEN TOTAL'!S12 -> 0 | ... AH9: ='RESUMEN TOTAL'!AN12 -> 0
A10: ='RESUMEN TOTAL'!A13 -> ALTAMIRA | B10: ='RESUMEN TOTAL'!B13 -> ALT 09 | C10: ='RESUMEN TOTAL'!D13 -> NECOCHEA Y CURUPAITY | D10: ='RESUMEN TOTAL'!E13 -> DOMO | E10: ='RESUMEN TOTAL'!F13 -> Fibra Optica | F10: ='RESUMEN TOTAL'!L13 -> APAGADO | G10: ='RESUMEN TOTAL'!M13 -> APAGADO | H10: ='RESUMEN TOTAL'!N13 -> APAGADO | I10: ='RESUMEN TOTAL'!O13 -> APAGADO | J10: ='RESUMEN TOTAL'!P13 -> APAGADO | K10: ='RESUMEN TOTAL'!Q13 -> APAGADO | L10: ='RESUMEN TOTAL'!R13 -> APAGADO | M10: ='RESUMEN TOTAL'!S13 -> APAGADO | ... AH10: ='RESUMEN TOTAL'!AN13 -> 0
A11: ='RESUMEN TOTAL'!A14 -> ALTAMIRA | B11: ='RESUMEN TOTAL'!B14 -> ALT 10 | C11: ='RESUMEN TOTAL'!D14 -> Calchaqui y Francia | D11: ='RESUMEN TOTAL'!E14 -> Domo | E11: ='RESUMEN TOTAL'!F14 -> Radio | F11: ='RESUMEN TOTAL'!L14 -> 0 | G11: ='RESUMEN TOTAL'!M14 -> 0 | H11: ='RESUMEN TOTAL'!N14 -> 0 | I11: ='RESUMEN TOTAL'!O14 -> 0 | J11: ='RESUMEN TOTAL'!P14 -> 0 | K11: ='RESUMEN TOTAL'!Q14 -> 0 | L11: ='RESUMEN TOTAL'!R14 -> 0 | M11: ='RESUMEN TOTAL'!S14 -> 0 | ... AH11: ='RESUMEN TOTAL'!AN14 -> 0
A12: ='RESUMEN TOTAL'!A15 -> AGUSTIN RAMIREZ | B12: ='RESUMEN TOTAL'!B15 -> ARA 01 | C12: ='RESUMEN TOTAL'!D15 -> Malambo y Tranquera | D12: ='RESUMEN TOTAL'!E15 -> Domo | E12: ='RESUMEN TOTAL'!F15 -> Fibra Optica | F12: ='RESUMEN TOTAL'!L15 -> APAGADO | G12: ='RESUMEN TOTAL'!M15 -> APAGADO | H12: ='RESUMEN TOTAL'!N15 -> APAGADO | I12: ='RESUMEN TOTAL'!O15 -> APAGADO | J12: ='RESUMEN TOTAL'!P15 -> APAGADO | K12: ='RESUMEN TOTAL'!Q15 -> APAGADO | L12: ='RESUMEN TOTAL'!R15 -> APAGADO | M12: ='RESUMEN TOTAL'!S15 -> APAGADO | ... AH12: ='RESUMEN TOTAL'!AN15 -> 0
... A25: ='RESUMEN TOTAL'!A28 -> CENTRO | B25: ='RESUMEN TOTAL'!B28 -> CEN 05 | C25: ='RESUMEN TOTAL'!D28 -> Bocuzzi e/España y San Martin | D25: ='RESUMEN TOTAL'!E28 -> DOMO | E25: ='RESUMEN TOTAL'!F28 -> Fibra Optica | F25: ='RESUMEN TOTAL'!L28 -> APAGADO | G25: ='RESUMEN TOTAL'!M28 -> APAGADO | H25: ='RESUMEN TOTAL'!N28 -> APAGADO | I25: ='RESUMEN TOTAL'!O28 -> APAGADO | J25: ='RESUMEN TOTAL'!P28 -> APAGADO | K25: ='RESUMEN TOTAL'!Q28 -> APAGADO | L25: ='RESUMEN TOTAL'!R28 -> APAGADO | M25: ='RESUMEN TOTAL'!S28 -> APAGADO | ... AH25: ='RESUMEN TOTAL'!AN28 -> 0
A26: ='RESUMEN TOTAL'!A29 -> CENTRO | B26: ='RESUMEN TOTAL'!B29 -> CEN06 | C26: ='RESUMEN TOTAL'!D29 -> Monteagudo y A.del Valle | D26: ='RESUMEN TOTAL'!E29 -> Fija | E26: ='RESUMEN TOTAL'!F29 -> Fibra Optica | F26: ='RESUMEN TOTAL'!L29 -> APAGADO | G26: ='RESUMEN TOTAL'!M29 -> APAGADO | H26: ='RESUMEN TOTAL'!N29 -> APAGADO | I26: ='RESUMEN TOTAL'!O29 -> APAGADO | J26: ='RESUMEN TOTAL'!P29 -> APAGADO | K26: ='RESUMEN TOTAL'!Q29 -> APAGADO | L26: ='RESUMEN TOTAL'!R29 -> APAGADO | M26: ='RESUMEN TOTAL'!S29 -> APAGADO | ... AG26: ='RESUMEN TOTAL'!AM29 -> 0 | AH26: ='RESUMEN TOTAL'!#REF! -> #REF!
A27: ='RESUMEN TOTAL'!A30 -> CENTRO | B27: ='RESUMEN TOTAL'!B30 -> CEN07 | C27: ='RESUMEN TOTAL'!D30 -> San Martin y Guemes | D27: ='RESUMEN TOTAL'!E30 -> DOMO | E27: ='RESUMEN TOTAL'!F30 -> Fibra Optica | F27: ='RESUMEN TOTAL'!L30 -> 0 | G27: ='RESUMEN TOTAL'!M30 -> 0 | H27: ='RESUMEN TOTAL'!N30 -> 0 | I27: ='RESUMEN TOTAL'!O30 -> 0 | J27: ='RESUMEN TOTAL'!P30 -> 0 | K27: ='RESUMEN TOTAL'!Q30 -> 0 | L27: ='RESUMEN TOTAL'!R30 -> 0 | M27: ='RESUMEN TOTAL'!S30 -> 0 | ... AH27: ='RESUMEN TOTAL'!AN30 -> 0
A28: ='RESUMEN TOTAL'!A31 -> CENTRO | B28: ='RESUMEN TOTAL'!B31 -> CEN08 | C28: ='RESUMEN TOTAL'!D31 -> San Martin y Pte.Peron | D28: ='RESUMEN TOTAL'!E31 -> Domo | E28: ='RESUMEN TOTAL'!F31 -> Fibra Optica | F28: ='RESUMEN TOTAL'!L31 -> 0 | G28: ='RESUMEN TOTAL'!M31 -> 0 | H28: ='RESUMEN TOTAL'!N31 -> 0 | I28: ='RESUMEN TOTAL'!O31 -> 0 | J28: ='RESUMEN TOTAL'!P31 -> 0 | K28: ='RESUMEN TOTAL'!Q31 -> 0 | L28: ='RESUMEN TOTAL'!R31 -> 0 | M28: ='RESUMEN TOTAL'!S31 -> 0 | ... AG28: ='RESUMEN TOTAL'!AM31 -> 0 | AH28: ='RESUMEN TOTAL'!#REF! -> #REF!
A29: ='RESUMEN TOTAL'!A32 -> CENTRO | B29: ='RESUMEN TOTAL'!B32 -> CEN09 | C29: ='RESUMEN TOTAL'!D32 -> Chacabuco y 25 de Mayo | D29: ='RESUMEN TOTAL'!E32 -> Domo | E29: ='RESUMEN TOTAL'!F32 -> Fibra Optica | F29: ='RESUMEN TOTAL'!L32 -> 0 | G29: ='RESUMEN TOTAL'!M32 -> 0 | H29: ='RESUMEN TOTAL'!N32 -> 0 | I29: ='RESUMEN TOTAL'!O32 -> 0 | J29: ='RESUMEN TOTAL'!P32 -> 0 | K29: ='RESUMEN TOTAL'!Q32 -> 0 | L29: ='RESUMEN TOTAL'!R32 -> 0 | M29: ='RESUMEN TOTAL'!S32 -> 0 | ... AH29: ='RESUMEN TOTAL'!AN32 -> 0
A30: ='RESUMEN TOTAL'!A33 -> CENTRO | B30: ='RESUMEN TOTAL'!B33 -> CEN10 | C30: ='RESUMEN TOTAL'!D33 -> Monteagudo y Pte. Peron | D30: ='RESUMEN TOTAL'!E33 -> Domo | E30: ='RESUMEN TOTAL'!F33 -> Fibra Optica | F30: ='RESUMEN TOTAL'!L33 -> 0 | G30: ='RESUMEN TOTAL'!M33 -> 0 | H30: ='RESUMEN TOTAL'!N33 -> 0 | I30: ='RESUMEN TOTAL'!O33 -> 0 | J30: ='RESUMEN TOTAL'!P33 -> 0 | K30: ='RESUMEN TOTAL'!Q33 -> 0 | L30: ='RESUMEN TOTAL'!R33 -> 0 | M30: ='RESUMEN TOTAL'!S33 -> 0 | ... AH30: ='RESUMEN TOTAL'!AN33 -> 0
A31: ='RESUMEN TOTAL'!A34 -> CENTRO | B31: ='RESUMEN TOTAL'!B34 -> CEN11 | C31: ='RESUMEN TOTAL'!D34 -> Monteagudo y Bocuzzi | D31: ='RESUMEN TOTAL'!E34 -> Domo | E31: ='RESUMEN TOTAL'!F34 -> Fibra Optica | F31: ='RESUMEN TOTAL'!L34 -> 0 | G31: ='RESUMEN TOTAL'!M34 -> 0 | H31: ='RESUMEN TOTAL'!N34 -> 0 | I31: ='RESUMEN TOTAL'!O34 -> 0 | J31: ='RESUMEN TOTAL'!P34 -> 0 | K31: ='RESUMEN TOTAL'!Q34 -> 0 | L31: ='RESUMEN TOTAL'!R34 -> 0 | M31: ='RESUMEN TOTAL'!S34 -> 0 | ... AH31: ='RESUMEN TOTAL'!AN34 -> 0
A32: ='RESUMEN TOTAL'!A35 -> CENTRO | B32: ='RESUMEN TOTAL'!B35 -> CEN 12 | C32: ='RESUMEN TOTAL'!D35 -> Monteagudo y Mitre | D32: ='RESUMEN TOTAL'!E35 -> Domo | E32: ='RESUMEN TOTAL'!F35 -> Fibra Optica | F32: ='RESUMEN TOTAL'!L35 -> 0 | G32: ='RESUMEN TOTAL'!M35 -> 0 | H32: ='RESUMEN TOTAL'!N35 -> 0 | I32: ='RESUMEN TOTAL'!O35 -> 0 | J32: ='RESUMEN TOTAL'!P35 -> 0 | K32: ='RESUMEN TOTAL'!Q35 -> 0 | L32: ='RESUMEN TOTAL'!R35 -> 0 | M32: ='RESUMEN TOTAL'!S35 -> 0 | ... AH32: ='RESUMEN TOTAL'!AN35 -> 0
A33: ='RESUMEN TOTAL'!A36 -> CENTRO | B33: ='RESUMEN TOTAL'!B36 -> CEN 13 | C33: ='RESUMEN TOTAL'!D36 -> 25 de Mayo y Maipu | D33: ='RESUMEN TOTAL'!E36 -> DOMO | E33: ='RESUMEN TOTAL'!F36 -> Fibra Optica | F33: ='RESUMEN TOTAL'!L36 -> 0 | G33: ='RESUMEN TOTAL'!M36 -> 0 | H33: ='RESUMEN TOTAL'!N36 -> 0 | I33: ='RESUMEN TOTAL'!O36 -> 0 | J33: ='RESUMEN TOTAL'!P36 -> 0 | K33: ='RESUMEN TOTAL'!Q36 -> 0 | L33: ='RESUMEN TOTAL'!R36 -> 0 | M33: ='RESUMEN TOTAL'!S36 -> 0 | ... AH33: ='RESUMEN TOTAL'!AN36 -> 0
A34: ='RESUMEN TOTAL'!A37 -> CENTRO | B34: ='RESUMEN TOTAL'!B37 -> CEN14 | C34: ='RESUMEN TOTAL'!D37 -> Pte.Peron e/Pringles y Brown | D34: ='RESUMEN TOTAL'!E37 -> Domo | E34: ='RESUMEN TOTAL'!F37 -> Fibra Optica | F34: ='RESUMEN TOTAL'!L37 -> 0 | G34: ='RESUMEN TOTAL'!M37 -> 0 | H34: ='RESUMEN TOTAL'!N37 -> 0 | I34: ='RESUMEN TOTAL'!O37 -> 0 | J34: ='RESUMEN TOTAL'!P37 -> 0 | K34: ='RESUMEN TOTAL'!Q37 -> 0 | L34: ='RESUMEN TOTAL'!R37 -> 0 | M34: ='RESUMEN TOTAL'!S37 -> 0 | ... AH34: ='RESUMEN TOTAL'!AN37 -> 0
A35: ='RESUMEN TOTAL'!A38 -> CENTRO | B35: ='RESUMEN TOTAL'!B38 -> CEN15 | C35: ='RESUMEN TOTAL'!D38 -> Alberdi y A.del Valle | D35: ='RESUMEN TOTAL'!E38 -> Domo | E35: ='RESUMEN TOTAL'!F38 -> Fibra Optica | F35: ='RESUMEN TOTAL'!L38 -> 0 | G35: ='RESUMEN TOTAL'!M38 -> 0 | H35: ='RESUMEN TOTAL'!N38 -> 0 | I35: ='RESUMEN TOTAL'!O38 -> 0 | J35: ='RESUMEN TOTAL'!P38 -> 0 | K35: ='RESUMEN TOTAL'!Q38 -> 0 | L35: ='RESUMEN TOTAL'!R38 -> 0 | M35: ='RESUMEN TOTAL'!S38 -> 0 | ... AH35: ='RESUMEN TOTAL'!AN38 -> 0
A36: ='RESUMEN TOTAL'!A39 -> CENTRO | B36: ='RESUMEN TOTAL'!B39 -> CEN16 | C36: ='RESUMEN TOTAL'!D39 -> San Martin y Pte. Peron | D36: ='RESUMEN TOTAL'!E39 -> Fija | E36: ='RESUMEN TOTAL'!F39 -> Fibra Optica | F36: ='RESUMEN TOTAL'!L39 -> 0 | G36: ='RESUMEN TOTAL'!M39 -> 0 | H36: ='RESUMEN TOTAL'!N39 -> 0 | I36: ='RESUMEN TOTAL'!O39 -> 0 | J36: ='RESUMEN TOTAL'!P39 -> 0 | K36: ='RESUMEN TOTAL'!Q39 -> 0 | L36: ='RESUMEN TOTAL'!R39 -> 0 | M36: ='RESUMEN TOTAL'!S39 -> 0 | ... AG36: ='RESUMEN TOTAL'!AM39 -> 0 | AH36: ='RESUMEN TOTAL'!#REF! -> #REF!
A37: ='RESUMEN TOTAL'!A40 -> CENTRO | B37: ='RESUMEN TOTAL'!B40 -> CEN17 | C37: ='RESUMEN TOTAL'!D40 -> San Martin y Mitre | D37: ='RESUMEN TOTAL'!E40 -> Domo | E37: ='RESUMEN TOTAL'!F40 -> PTO A FO | F37: ='RESUMEN TOTAL'!L40 -> 0 | G37: ='RESUMEN TOTAL'!M40 -> 0 | H37: ='RESUMEN TOTAL'!N40 -> 0 | I37: ='RESUMEN TOTAL'!O40 -> 0 | J37: ='RESUMEN TOTAL'!P40 -> 0 | K37: ='RESUMEN TOTAL'!Q40 -> 0 | L37: ='RESUMEN TOTAL'!R40 -> 0 | M37: ='RESUMEN TOTAL'!S40 -> 0 | ... AH37: ='RESUMEN TOTAL'!AN40 -> 0
A38: ='RESUMEN TOTAL'!A41 -> CENTRO | B38: ='RESUMEN TOTAL'!B41 -> CEN18 | C38: ='RESUMEN TOTAL'!D41 -> Monteagudo e/Mitre y Sallares | D38: ='RESUMEN TOTAL'!E41 -> Fija | E38: ='RESUMEN TOTAL'!F41 -> Fibra Optica | F38: ='RESUMEN TOTAL'!L41 -> 0 | G38: ='RESUMEN TOTAL'!M41 -> 0 | H38: ='RESUMEN TOTAL'!N41 -> 0 | I38: ='RESUMEN TOTAL'!O41 -> 0 | J38: ='RESUMEN TOTAL'!P41 -> 0 | K38: ='RESUMEN TOTAL'!Q41 -> 0 | L38: ='RESUMEN TOTAL'!R41 -> 0 | M38: ='RESUMEN TOTAL'!S41 -> 0 | ... AH38: ='RESUMEN TOTAL'!AN41 -> 0
A39: ='RESUMEN TOTAL'!A42 -> CENTRO | B39: ='RESUMEN TOTAL'!B42 -> CEN19 | C39: ='RESUMEN TOTAL'!D42 -> Chacabuco y 25 de Mayo | D39: ='RESUMEN TOTAL'!E42 -> Fija | E39: ='RESUMEN TOTAL'!F42 -> Fibra Optica | F39: ='RESUMEN TOTAL'!L42 -> 0 | G39: ='RESUMEN TOTAL'!M42 -> 0 | H39: ='RESUMEN TOTAL'!N42 -> 0 | I39: ='RESUMEN TOTAL'!O42 -> 0 | J39: ='RESUMEN TOTAL'!P42 -> 0 | K39: ='RESUMEN TOTAL'!Q42 -> 0 | L39: ='RESUMEN TOTAL'!R42 -> 0 | M39: ='RESUMEN TOTAL'!S42 -> 0 | ... AH39: ='RESUMEN TOTAL'!AN42 -> 0
A40: ='RESUMEN TOTAL'!A43 -> LOMAS DE MONTEVERDE | B40: ='RESUMEN TOTAL'!B43 -> CEN20 | C40: ='RESUMEN TOTAL'!D43 -> Pte. Illia y Las Heras | D40: ='RESUMEN TOTAL'!E43 -> Domo | E40: ='RESUMEN TOTAL'!F43 -> Fibra Optica | F40: ='RESUMEN TOTAL'!L43 -> 0 | G40: ='RESUMEN TOTAL'!M43 -> 0 | H40: ='RESUMEN TOTAL'!N43 -> 0 | I40: ='RESUMEN TOTAL'!O43 -> 0 | J40: ='RESUMEN TOTAL'!P43 -> 0 | K40: ='RESUMEN TOTAL'!Q43 -> 0 | L40: ='RESUMEN TOTAL'!R43 -> 0 | M40: ='RESUMEN TOTAL'!S43 -> 0 | ... AH40: ='RESUMEN TOTAL'!AN43 -> 0
A41: ='RESUMEN TOTAL'!A44 -> CENTRO | B41: ='RESUMEN TOTAL'!B44 -> CEN21 | C41: ='RESUMEN TOTAL'!D44 -> Misiones y Urquiza | D41: ='RESUMEN TOTAL'!E44 -> Fija | E41: ='RESUMEN TOTAL'!F44 -> Radio | F41: ='RESUMEN TOTAL'!L44 -> 0 | G41: ='RESUMEN TOTAL'!M44 -> 0 | H41: ='RESUMEN TOTAL'!N44 -> 0 | I41: ='RESUMEN TOTAL'!O44 -> 0 | J41: ='RESUMEN TOTAL'!P44 -> 0 | K41: ='RESUMEN TOTAL'!Q44 -> 0 | L41: ='RESUMEN TOTAL'!R44 -> 0 | M41: ='RESUMEN TOTAL'!S44 -> 0 | ... AH41: ='RESUMEN TOTAL'!AN44 -> 0
A42: ='RESUMEN TOTAL'!A45 -> CENTRO | B42: ='RESUMEN TOTAL'!B45 -> CEN22 | C42: ='RESUMEN TOTAL'!D45 -> Las Heras y Chacabuco | D42: ='RESUMEN TOTAL'!E45 -> Domo | E42: ='RESUMEN TOTAL'!F45 -> Radio | F42: ='RESUMEN TOTAL'!L45 -> 0 | G42: ='RESUMEN TOTAL'!M45 -> 0 | H42: ='RESUMEN TOTAL'!N45 -> 0 | I42: ='RESUMEN TOTAL'!O45 -> 0 | J42: ='RESUMEN TOTAL'!P45 -> 0 | K42: ='RESUMEN TOTAL'!Q45 -> 0 | L42: ='RESUMEN TOTAL'!R45 -> 0 | M42: ='RESUMEN TOTAL'!S45 -> 0 | ... AH42: ='RESUMEN TOTAL'!AN45 -> 0
A43: ='RESUMEN TOTAL'!A46 -> CENTRO | B43: ='RESUMEN TOTAL'!B46 -> CEN23 | C43: ='RESUMEN TOTAL'!D46 -> Sallares y Monteagudo | D43: ='RESUMEN TOTAL'!E46 -> Domo | E43: ='RESUMEN TOTAL'!F46 -> Fibra Optica | F43: ='RESUMEN TOTAL'!L46 -> 0 | G43: ='RESUMEN TOTAL'!M46 -> 0 | H43: ='RESUMEN TOTAL'!N46 -> 0 | I43: ='RESUMEN TOTAL'!O46 -> 0 | J43: ='RESUMEN TOTAL'!P46 -> 0 | K43: ='RESUMEN TOTAL'!Q46 -> 0 | L43: ='RESUMEN TOTAL'!R46 -> 0 | M43: ='RESUMEN TOTAL'!S46 -> 0 | ... AH43: ='RESUMEN TOTAL'!AN46 -> 0
A44: ='RESUMEN TOTAL'!A47 -> CENTRO | B44: ='RESUMEN TOTAL'!B47 -> CEN24 | C44: ='RESUMEN TOTAL'!D47 -> Sallares y España | D44: ='RESUMEN TOTAL'!E47 -> Domo | E44: ='RESUMEN TOTAL'!F47 -> Fibra Optica | F44: ='RESUMEN TOTAL'!L47 -> 0 | G44: ='RESUMEN TOTAL'!M47 -> 0 | H44: ='RESUMEN TOTAL'!N47 -> 0 | I44: ='RESUMEN TOTAL'!O47 -> 0 | J44: ='RESUMEN TOTAL'!P47 -> 0 | K44: ='RESUMEN TOTAL'!Q47 -> 0 | L44: ='RESUMEN TOTAL'!R47 -> 0 | M44: ='RESUMEN TOTAL'!S47 -> 0 | ... AH44: ='RESUMEN TOTAL'!AN47 -> 0
A45: ='RESUMEN TOTAL'!A48 -> CENTRO | B45: ='RESUMEN TOTAL'!B48 -> CEN25 | C45: ='RESUMEN TOTAL'!D48 -> SAN MARTIN Y 9 DE JULIO | D45: ='RESUMEN TOTAL'!E48 -> Domo | E45: ='RESUMEN TOTAL'!F48 -> Fibra Optica | F45: ='RESUMEN TOTAL'!L48 -> 0 | G45: ='RESUMEN TOTAL'!M48 -> 0 | H45: ='RESUMEN TOTAL'!N48 -> 0 | I45: ='RESUMEN TOTAL'!O48 -> 0 | J45: ='RESUMEN TOTAL'!P48 -> 0 | K45: ='RESUMEN TOTAL'!Q48 -> 0 | L45: ='RESUMEN TOTAL'!R48 -> 0 | M45: ='RESUMEN TOTAL'!S48 -> 0 | ... AH45: ='RESUMEN TOTAL'!AN48 -> 0
A46: ='RESUMEN TOTAL'!A49 -> CENTRO | B46: ='RESUMEN TOTAL'!B49 -> CEN26 | C46: ='RESUMEN TOTAL'!D49 -> Mitre y España | D46: ='RESUMEN TOTAL'!E49 -> Domo | E46: ='RESUMEN TOTAL'!F49 -> Fibra Optica | F46: ='RESUMEN TOTAL'!L49 -> 0 | G46: ='RESUMEN TOTAL'!M49 -> 0 | H46: ='RESUMEN TOTAL'!N49 -> 0 | I46: ='RESUMEN TOTAL'!O49 -> 0 | J46: ='RESUMEN TOTAL'!P49 -> 0 | K46: ='RESUMEN TOTAL'!Q49 -> 0 | L46: ='RESUMEN TOTAL'!R49 -> 0 | M46: ='RESUMEN TOTAL'!S49 -> 0 | ... AH46: ='RESUMEN TOTAL'!AN49 -> 0
A47: ='RESUMEN TOTAL'!A50 -> CENTRO | B47: ='RESUMEN TOTAL'!B50 -> CEN27 | C47: ='RESUMEN TOTAL'!D50 -> San Juan y España | D47: ='RESUMEN TOTAL'!E50 -> Domo | E47: ='RESUMEN TOTAL'!F50 -> Fibra Optica | F47: ='RESUMEN TOTAL'!L50 -> 0 | G47: ='RESUMEN TOTAL'!M50 -> 0 | H47: ='RESUMEN TOTAL'!N50 -> 0 | I47: ='RESUMEN TOTAL'!O50 -> 0 | J47: ='RESUMEN TOTAL'!P50 -> 0 | K47: ='RESUMEN TOTAL'!Q50 -> 0 | L47: ='RESUMEN TOTAL'!R50 -> 0 | M47: ='RESUMEN TOTAL'!S50 -> 0 | ... AH47: ='RESUMEN TOTAL'!AN50 -> 0
A48: ='RESUMEN TOTAL'!A51 -> CENTRO | B48: ='RESUMEN TOTAL'!B51 -> CEN28 | C48: ='RESUMEN TOTAL'!D51 -> Mitre y Alberdi | D48: ='RESUMEN TOTAL'!E51 -> Domo | E48: ='RESUMEN TOTAL'!F51 -> Fibra Optica | F48: ='RESUMEN TOTAL'!L51 -> 0 | G48: ='RESUMEN TOTAL'!M51 -> 0 | H48: ='RESUMEN TOTAL'!N51 -> 0 | I48: ='RESUMEN TOTAL'!O51 -> 0 | J48: ='RESUMEN TOTAL'!P51 -> 0 | K48: ='RESUMEN TOTAL'!Q51 -> 0 | L48: ='RESUMEN TOTAL'!R51 -> 0 | M48: ='RESUMEN TOTAL'!S51 -> 0 | ... AH48: ='RESUMEN TOTAL'!AN51 -> 0
... A61: ='RESUMEN TOTAL'!A64 -> CENTRO | B61: ='RESUMEN TOTAL'!B64 -> CEN41 | C61: ='RESUMEN TOTAL'!D64 -> Contreras y Alberdi | D61: ='RESUMEN TOTAL'!E64 -> Domo | E61: ='RESUMEN TOTAL'!F64 -> Fibra Optica | F61: ='RESUMEN TOTAL'!L64 -> 0 | G61: ='RESUMEN TOTAL'!M64 -> 0 | H61: ='RESUMEN TOTAL'!N64 -> 0 | I61: ='RESUMEN TOTAL'!O64 -> 0 | J61: ='RESUMEN TOTAL'!P64 -> 0 | K61: ='RESUMEN TOTAL'!Q64 -> 0 | L61: ='RESUMEN TOTAL'!R64 -> 0 | M61: ='RESUMEN TOTAL'!S64 -> 0 | ... AH61: ='RESUMEN TOTAL'!AN64 -> 0
A62: ='RESUMEN TOTAL'!A65 -> CENTRO | B62: ='RESUMEN TOTAL'!B65 -> CEN42 | C62: ='RESUMEN TOTAL'!D65 -> Diagonal Constituyentes y Alem | D62: ='RESUMEN TOTAL'!E65 -> Domo | E62: ='RESUMEN TOTAL'!F65 -> Fibra Optica | F62: ='RESUMEN TOTAL'!L65 -> APAGADO | G62: ='RESUMEN TOTAL'!M65 -> APAGADO | H62: ='RESUMEN TOTAL'!N65 -> APAGADO | I62: ='RESUMEN TOTAL'!O65 -> APAGADO | J62: ='RESUMEN TOTAL'!P65 -> APAGADO | K62: ='RESUMEN TOTAL'!Q65 -> APAGADO | L62: ='RESUMEN TOTAL'!R65 -> APAGADO | M62: ='RESUMEN TOTAL'!S65 -> APAGADO | ... AG62: ='RESUMEN TOTAL'!AM65 -> 0 | AH62: ='RESUMEN TOTAL'!#REF! -> #REF!
A63: ='RESUMEN TOTAL'!A66 -> CENTRO | B63: ='RESUMEN TOTAL'!B66 -> CEN43 | C63: ='RESUMEN TOTAL'!D66 -> Sallares y Alberdi | D63: ='RESUMEN TOTAL'!E66 -> Domo | E63: ='RESUMEN TOTAL'!F66 -> Fibra Optica | F63: ='RESUMEN TOTAL'!L66 -> 0 | G63: ='RESUMEN TOTAL'!M66 -> 0 | H63: ='RESUMEN TOTAL'!N66 -> 0 | I63: ='RESUMEN TOTAL'!O66 -> 0 | J63: ='RESUMEN TOTAL'!P66 -> 0 | K63: ='RESUMEN TOTAL'!Q66 -> 0 | L63: ='RESUMEN TOTAL'!R66 -> 0 | M63: ='RESUMEN TOTAL'!S66 -> 0 | ... AH63: ='RESUMEN TOTAL'!AN66 -> 0
A64: ='RESUMEN TOTAL'!A67 -> CENTRO | B64: ='RESUMEN TOTAL'!B67 -> CEN44 | C64: ='RESUMEN TOTAL'!D67 -> Mitre y Brown | D64: ='RESUMEN TOTAL'!E67 -> Domo | E64: ='RESUMEN TOTAL'!F67 -> Fibra Optica | F64: ='RESUMEN TOTAL'!L67 -> 0 | G64: ='RESUMEN TOTAL'!M67 -> 0 | H64: ='RESUMEN TOTAL'!N67 -> 0 | I64: ='RESUMEN TOTAL'!O67 -> 0 | J64: ='RESUMEN TOTAL'!P67 -> 0 | K64: ='RESUMEN TOTAL'!Q67 -> 0 | L64: ='RESUMEN TOTAL'!R67 -> 0 | M64: ='RESUMEN TOTAL'!S67 -> 0 | ... AH64: ='RESUMEN TOTAL'!AN67 -> 0
...

Sheet APAGADOS
E1: APAGADOS | F1: =COUNTIF(F3:F403, "APAGADO") -> 90 | G1: =COUNTIF(G3:G403, "APAGADO") -> 87 | H1: =COUNTIF(H3:H503, "APAGADO") -> 128 | I1: =COUNTIF(I3:I403, "APAGADO") -> 82 | J1: =COUNTIF(J3:J403, "APAGADO") -> 63 | K1: =COUNTIF(K3:K403, "APAGADO") -> 73 | L1: =COUNTIF(L3:L403, "APAGADO") -> 77 | M1: =COUNTIF(M3:M403, "APAGADO") -> 91 | N1: =COUNTIF(N3:N403, "APAGADO") -> 74 | O1: =COUNTIF(O3:O403, "APAGADO") -> 79 | P1: =COUNTIF(P3:P403, "APAGADO") -> 64 | ... AD1: =COUNTIF(AD3:AD403, "APAGADO") -> 59 | AE1: =COUNTIF(AE3:AE503, "APAGADO") -> 120 | AF1: =COUNTIF(AF3:AF403, "APAGADO") -> 0 | AG1: =COUNTIF(AG3:AG403, "APAGADO") -> 0 | AH1: =COUNTIF(AH3:AH403, "APAGADO") -> 0 | AI1: =COUNTIF(AI3:AI403, "APAGADO") -> 0
A2: =ESTADISTICA!A1 -> Barrio | B2: =ESTADISTICA!B1 -> [Denominacion] | C2: =ESTADISTICA!C1 -> [Ubicacion] | D2: =ESTADISTICA!D1 -> [Tipo de Camara] | E2: =ESTADISTICA!E1 -> [Tipo de Conexion] | F2: =ESTADISTICA!F1 -> 45383 | G2: =ESTADISTICA!G1 -> 45384 | H2: =ESTADISTICA!H1 -> 45385 | ... AH2: =ESTADISTICA!AH1 -> 45411 | AI2: 121
A3: =ESTADISTICA!A2 -> ALTAMIRA | B3: =ESTADISTICA!B2 -> ALT01 | C3: =ESTADISTICA!C2 -> Calchaqui y Sgto. Cabral | D3: =ESTADISTICA!D2 -> Domo | E3: =ESTADISTICA!E2 -> Fibra Optica | F3: =ESTADISTICA!F2 -> 0 | G3: =ESTADISTICA!G2 -> 0 | H3: =ESTADISTICA!H2 -> 0 | ... AI3: =ESTADISTICA!AI2 -> 0
A4: =ESTADISTICA!A3 -> ALTAMIRA | B4: =ESTADISTICA!B3 -> ALT02 | C4: =ESTADISTICA!C3 -> Calchaqui y Lope de Vega | D4: =ESTADISTICA!D3 -> Domo | E4: =ESTADISTICA!E3 -> PTO A FO | F4: =ESTADISTICA!F3 -> 0 | G4: =ESTADISTICA!G3 -> 0 | H4: =ESTADISTICA!H3 -> 0 | ... AI4: =ESTADISTICA!AI3 -> 0
A5: =ESTADISTICA!A4 -> ALTAMIRA | B5: =ESTADISTICA!B4 -> ALT 03 | C5: =ESTADISTICA!C4 -> Bombero Galarza y Necochea | D5: =ESTADISTICA!D4 -> Domo | E5: =ESTADISTICA!E4 -> Fibra Optica | F5: =ESTADISTICA!F4 -> 0 | G5: =ESTADISTICA!G4 -> 0 | H5: =ESTADISTICA!H4 -> 0 | ... AI5: =ESTADISTICA!AI4 -> 0
A6: =ESTADISTICA!A5 -> ALTAMIRA | B6: =ESTADISTICA!B5 -> ALT 04 | C6: =ESTADISTICA!C5 -> Francia y Necochea | D6: =ESTADISTICA!D5 -> Domo | E6: =ESTADISTICA!E5 -> Fibra Optica | F6: =ESTADISTICA!F5 -> 0 | G6: =ESTADISTICA!G5 -> 0 | H6: =ESTADISTICA!H5 -> 0 | ... AI6: =ESTADISTICA!AI5 -> 0
A7: =ESTADISTICA!A6 -> ALTAMIRA | B7: =ESTADISTICA!B6 -> ALT05 | C7: =ESTADISTICA!C6 -> Av. Calchaqui y Bombero Galarza | D7: =ESTADISTICA!D6 -> Domo | E7: =ESTADISTICA!E6 -> PTO A FO | F7: =ESTADISTICA!F6 -> 0 | G7: =ESTADISTICA!G6 -> 0 | H7: =ESTADISTICA!H6 -> 0 | ... AI7: =ESTADISTICA!AI6 -> 0
A8: =ESTADISTICA!A7 -> ALTAMIRA | B8: =ESTADISTICA!B7 -> ALT 06 | C8: =ESTADISTICA!C7 -> LOPE DE VEGA Y NECOCHEA | D8: =ESTADISTICA!D7 -> Domo | E8: =ESTADISTICA!E7 -> PTO A FO | F8: =ESTADISTICA!F7 -> 0 | G8: =ESTADISTICA!G7 -> 0 | H8: =ESTADISTICA!H7 -> 0 | ... AI8: =ESTADISTICA!AI7 -> 0
A9: =ESTADISTICA!A8 -> ALTAMIRA | B9: =ESTADISTICA!B8 -> ALT07 | C9: =ESTADISTICA!C8 -> AV. CALCHAQUI Y AV. DEL TRABAJO | D9: =ESTADISTICA!D8 -> DOMO | E9: =ESTADISTICA!E8 -> PTO A FO | F9: =ESTADISTICA!F8 -> 0 | G9: =ESTADISTICA!G8 -> 0 | H9: =ESTADISTICA!H8 -> 0 | ... AI9: =ESTADISTICA!AI8 -> 0
A10: =ESTADISTICA!A9 -> ALTAMIRA | B10: =ESTADISTICA!B9 -> ALT 08 | C10: =ESTADISTICA!C9 -> HUMAITA Y NECOCHEA | D10: =ESTADISTICA!D9 -> DOMO | E10: =ESTADISTICA!E9 -> Fibra Optica | F10: =ESTADISTICA!F9 -> 0 | G10: =ESTADISTICA!G9 -> 0 | H10: =ESTADISTICA!H9 -> 0 | ... AI10: =ESTADISTICA!AI9 -> 0
A11: =ESTADISTICA!A10 -> ALTAMIRA | B11: =ESTADISTICA!B10 -> ALT 09 | C11: =ESTADISTICA!C10 -> NECOCHEA Y CURUPAITY | D11: =ESTADISTICA!D10 -> DOMO | E11: =ESTADISTICA!E10 -> Fibra Optica | F11: =ESTADISTICA!F10 -> APAGADO | G11: =ESTADISTICA!G10 -> APAGADO | H11: =ESTADISTICA!H10 -> APAGADO | ... AI11: =ESTADISTICA!AI10 -> 0
A12: =ESTADISTICA!A11 -> ALTAMIRA | B12: =ESTADISTICA!B11 -> ALT 10 | C12: =ESTADISTICA!C11 -> Calchaqui y Francia | D12: =ESTADISTICA!D11 -> Domo | E12: =ESTADISTICA!E11 -> Radio | F12: =ESTADISTICA!F11 -> 0 | G12: =ESTADISTICA!G11 -> 0 | H12: =ESTADISTICA!H11 -> 0 | ... AI12: =ESTADISTICA!AI11 -> 0
A13: =ESTADISTICA!A12 -> AGUSTIN RAMIREZ | B13: =ESTADISTICA!B12 -> ARA 01 | C13: =ESTADISTICA!C12 -> Malambo y Tranquera | D13: =ESTADISTICA!D12 -> Domo | E13: =ESTADISTICA!E12 -> Fibra Optica | F13: =ESTADISTICA!F12 -> APAGADO | G13: =ESTADISTICA!G12 -> APAGADO | H13: =ESTADISTICA!H12 -> APAGADO | ... AI13: =ESTADISTICA!AI12 -> 0
A14: =ESTADISTICA!A13 -> BELGRANO | B14: =ESTADISTICA!B13 -> BEL 01 | C14: =ESTADISTICA!C13 -> San Martin y Dardo Rocha | D14: =ESTADISTICA!D13 -> DOMO | E14: =ESTADISTICA!E13 -> Fibra Optica | F14: =ESTADISTICA!F13 -> 0 | G14: =ESTADISTICA!G13 -> 0 | H14: =ESTADISTICA!H13 -> 0 | ... AI14: =ESTADISTICA!AI13 -> 0
... A207: =ESTADISTICA!A206 -> LOPEZ ROMERO | B207: =ESTADISTICA!B206 -> MFI02 | C207: =ESTADISTICA!C206 -> Calchaqui y Balcarce | D207: =ESTADISTICA!D206 -> Fija | E207: =ESTADISTICA!E206 -> Fibra Optica | F207: =ESTADISTICA!F206 -> 0 | G207: =ESTADISTICA!G206 -> 0 | H207: =ESTADISTICA!H206 -> 0 | ... AI207: =ESTADISTICA!AI206 -> 0
A208: =ESTADISTICA!A208 -> MARTIN FIERRO | B208: =ESTADISTICA!B208 -> MFI04 | C208: =ESTADISTICA!C208 -> Calchaqui y balcarce | D208: =ESTADISTICA!D208 -> Domo | E208: =ESTADISTICA!E208 -> Fibra Optica | F208: =ESTADISTICA!F208 -> 0 | G208: =ESTADISTICA!G208 -> 0 | H208: =ESTADISTICA!H208 -> 0 | ... AI208: =ESTADISTICA!AI208 -> 0
A209: =ESTADISTICA!A209 -> SAN EMILIO | B209: =ESTADISTICA!B209 -> MFI 05 | C209: =ESTADISTICA!C209 -> Cno. Gral. Belgrano y Guayaquil | D209: =ESTADISTICA!D209 -> Domo | E209: =ESTADISTICA!E209 -> Fibra Optica | F209: =ESTADISTICA!F209 -> 0 | G209: =ESTADISTICA!G209 -> 0 | H209: =ESTADISTICA!H209 -> 0 | ... AI209: =ESTADISTICA!AI209 -> 0
A210: =ESTADISTICA!A210 -> SAN EMILIO | B210: =ESTADISTICA!B210 -> MFI06 | C210: =ESTADISTICA!C210 -> Con. Gral. Belgrano y Bombero Galarza | D210: =ESTADISTICA!D210 -> DOMO | E210: =ESTADISTICA!E210 -> Radio | F210: =ESTADISTICA!F210 -> APAGADO | G210: =ESTADISTICA!G210 -> APAGADO | H210: =ESTADISTICA!H210 -> APAGADO | ... AI210: =ESTADISTICA!AI210 -> 0
A211: =ESTADISTICA!A211 -> MARTIN FIERRO | B211: =ESTADISTICA!B211 -> MFI 07 | C211: =ESTADISTICA!C211 -> Sargento Cabral y Carlos Gardel | D211: =ESTADISTICA!D211 -> Domo | E211: =ESTADISTICA!E211 -> PTO A FO | F211: =ESTADISTICA!F211 -> 0 | G211: =ESTADISTICA!G211 -> 0 | H211: =ESTADISTICA!H211 -> 0 | ... AI211: =ESTADISTICA!AI211 -> 0
A212: =ESTADISTICA!A212 -> MARTIN FIERRO | B212: =ESTADISTICA!B212 -> MFI 08 | C212: =ESTADISTICA!C212 -> Braile y Batalla de Callao | D212: =ESTADISTICA!D212 -> Domo | E212: =ESTADISTICA!E212 -> PTO A FO | F212: =ESTADISTICA!F212 -> 0 | G212: =ESTADISTICA!G212 -> 0 | H212: =ESTADISTICA!H212 -> 0 | ... AI212: =ESTADISTICA!AI212 -> 0
A213: =ESTADISTICA!A213 -> GOBERNADOR MONTEVERDE | B213: =ESTADISTICA!B213 -> MON01 | C213: =ESTADISTICA!C213 -> San Martin y Patricias Argentinas | D213: =ESTADISTICA!D213 -> Fija | E213: =ESTADISTICA!E213 -> Fibra Optica | F213: =ESTADISTICA!F213 -> 0 | G213: =ESTADISTICA!G213 -> 0 | H213: =ESTADISTICA!H213 -> 0 | ... AI213: =ESTADISTICA!AI213 -> 0
A214: =ESTADISTICA!A214 -> GOBERNADOR MONTEVERDE | B214: =ESTADISTICA!B214 -> MON02 | C214: =ESTADISTICA!C214 -> Senzabello y Famatina | D214: =ESTADISTICA!D214 -> Domo | E214: =ESTADISTICA!E214 -> Radio | F214: =ESTADISTICA!F214 -> 0 | G214: =ESTADISTICA!G214 -> 0 | H214: =ESTADISTICA!H214 -> 0 | ... AI214: =ESTADISTICA!AI214 -> 0
A215: =ESTADISTICA!A215 -> GOBERNADOR MONTEVERDE | B215: =ESTADISTICA!B215 -> MON03 | C215: =ESTADISTICA!C215 -> Senzabello y Guemes | D215: =ESTADISTICA!D215 -> Domo | E215: =ESTADISTICA!E215 -> Radio | F215: =ESTADISTICA!F215 -> 0 | G215: =ESTADISTICA!G215 -> 0 | H215: =ESTADISTICA!H215 -> 0 | ... AI215: =ESTADISTICA!AI215 -> 0
A216: =ESTADISTICA!A216 -> GOBERNADOR MONTEVERDE | B216: =ESTADISTICA!B216 -> MON04 | C216: =ESTADISTICA!C216 -> Av. Yrigoyen y San Lorenzo | D216: =ESTADISTICA!D216 -> Domo | E216: =ESTADISTICA!E216 -> Radio | F216: =ESTADISTICA!F216 -> 0 | G216: =ESTADISTICA!G216 -> 0 | H216: =ESTADISTICA!H216 -> 0 | ... AI216: =ESTADISTICA!AI216 -> 0
A217: =ESTADISTICA!A217 -> 9 DE JULIO | B217: =ESTADISTICA!B217 -> NJU 01 | C217: =ESTADISTICA!C217 -> Sallares y Parrillo | D217: =ESTADISTICA!D217 -> Domo | E217: =ESTADISTICA!E217 -> Fibra Optica | F217: =ESTADISTICA!F217 -> 0 | G217: =ESTADISTICA!G217 -> 0 | H217: =ESTADISTICA!H217 -> 0 | ... AI217: =ESTADISTICA!AI217 -> 0
A218: =ESTADISTICA!A218 -> 9 DE JULIO | B218: =ESTADISTICA!B218 -> NJU02 | C218: =ESTADISTICA!C218 -> Ituzaingo y Boccuzzi | D218: =ESTADISTICA!D218 -> Domo | E218: =ESTADISTICA!E218 -> Radio | F218: =ESTADISTICA!F218 -> 0 | G218: =ESTADISTICA!G218 -> 0 | H218: =ESTADISTICA!H218 -> 0 | ... AI218: =ESTADISTICA!AI218 -> 0
A219: =ESTADISTICA!A219 -> 9 DE JULIO | B219: =ESTADISTICA!B219 -> NJU03 | C219: =ESTADISTICA!C219 -> San Juan y Parrillo | D219: =ESTADISTICA!D219 -> Domo | E219: =ESTADISTICA!E219 -> PTO A FO | F219: =ESTADISTICA!F219 -> 0 | G219: =ESTADISTICA!G219 -> 0 | H219: =ESTADISTICA!H219 -> 0 | ... AI219: =ESTADISTICA!AI219 -> 0
... A516: =ESTADISTICA!A516 -> PARADAS SEGURAS | B516: =ESTADISTICA!B516 -> 39 C | C516: =ESTADISTICA!C516 -> Hudson y Groussac Este | D516: =ESTADISTICA!D516 -> GFIJA | E516: =ESTADISTICA!E516 -> GPON | F516: =ESTADISTICA!F516 -> APAGADO | G516: =ESTADISTICA!G516 -> APAGADO | H516: =ESTADISTICA!H516 -> APAGADO | ... AI516: =ESTADISTICA!AI516 -> 0

Sheet APAGADOS FIBRA
C1: TOTAL FIBRA | D1: =COUNTIFS(E4:E401,"=Fibra Optica") -> 270
E2: APAGADOS | F2: =COUNTIFS(F4:F501, "=APAGADO",E4:E501,"=Fibra Optica") -> 86 | G2: =COUNTIFS(G4:G501, "=APAGADO",E4:E501,"=Fibra Optica") -> 82 | H2: =COUNTIFS(H4:H501, "=APAGADO",E4:E501,"=Fibra Optica") -> 81 | I2: =COUNTIFS(I4:I501, "=APAGADO",E4:E501,"=Fibra Optica") -> 76 | J2: =COUNTIFS(J4:J501, "=APAGADO",E4:E501,"=Fibra Optica") -> 65 | K2: =COUNTIFS(K4:K501, "=APAGADO",E4:E501,"=Fibra Optica") -> 67 | L2: =COUNTIFS(L4:L501, "=APAGADO",E4:E501,"=Fibra Optica") -> 71 | M2: =COUNTIFS(M4:M501, "=APAGADO",E4:E501,"=Fibra Optica") -> 89 | N2: =COUNTIFS(N4:N501, "=APAGADO",E4:E501,"=Fibra Optica") -> 68 | O2: =COUNTIFS(O4:O501, "=APAGADO",E4:E501,"=Fibra Optica") -> 78 | P2: =COUNTIFS(P4:P601, "=APAGADO",E4:E601,"=Fibra Optica") -> 58 | Q2: =COUNTIFS(Q4:Q501, "=APAGADO",E4:E501,"=Fibra Optica") -> 60 | R2: =COUNTIFS(R4:R501, "=APAGADO",E4:E501,"=Fibra Optica") -> 0 | S2: =COUNTIFS(S4:S501, "=APAGADO",E4:E501,"=Fibra Optica") -> 93 | T2: =COUNTIFS(T4:T501, "=APAGADO",E4:E501,"=Fibra Optica") -> 81 | U2: =COUNTIFS(U4:U501, "=APAGADO",E4:E501,"=Fibra Optica") -> 75 | V2: =COUNTIFS(V4:V501, "=APAGADO",E4:E501,"=Fibra Optica") -> 76 | W2: =COUNTIFS(W4:W501, "=APAGADO",E4:E501,"=Fibra Optica") -> 70 | X2: =COUNTIFS(X4:X501, "=APAGADO",E4:E501,"=Fibra Optica") -> 63 | Y2: =COUNTIFS(Y4:Y501, "=APAGADO",E4:E501,"=Fibra Optica") -> 64 | Z2: =COUNTIFS(Z4:Z501, "=APAGADO",E4:E501,"=Fibra Optica") -> 64 | AA2: =COUNTIFS(AA4:AA501, "=APAGADO",E4:E501,"=Fibra Optica") -> 63 | AB2: =COUNTIFS(AB4:AB501, "=APAGADO",E4:E501,"=Fibra Optica") -> 66 | AC2: =COUNTIFS(AC4:AC601, "=APAGADO",E4:E601,"=Fibra Optica") -> 64 | AD2: =COUNTIFS(AD4:AD501, "=APAGADO",E4:E501,"=Fibra Optica") -> 56 | AE2: =COUNTIFS(AE4:AE501, "=APAGADO",E4:E501,"=Fibra Optica") -> 69 | AF2: =COUNTIFS(AF4:AF501, "=APAGADO",E4:E501,"=Fibra Optica") -> 0 | AG2: =COUNTIFS(AG4:AG501, "=APAGADO",E4:E501,"=Fibra Optica") -> 0 | AH2: =COUNTIFS(AH4:AH501, "=APAGADO",E4:E501,"=Fibra Optica") -> 0 | AI2: =COUNTIFS(AI4:AI501, "=APAGADO",F4:F501,"=Fibra Optica") -> 0
A3: =ESTADISTICA!A1 -> Barrio | B3: =ESTADISTICA!B1 -> [Denominacion] | C3: =ESTADISTICA!C1 -> [Ubicacion] | D3: =ESTADISTICA!D1 -> [Tipo de Camara] | E3: =ESTADISTICA!E1 -> [Tipo de Conexion] | F3: =ESTADISTICA!F1 -> 45383 | G3: =ESTADISTICA!G1 -> 45384 | H3: =ESTADISTICA!H1 -> 45385 | ... AH3: =ESTADISTICA!AH1 -> 45411 | AI3: 30
A4: ='RESUMEN TOTAL'!A7 -> ALTAMIRA | B4: ='RESUMEN TOTAL'!B7 -> ALT 03 | C4: ='RESUMEN TOTAL'!D7 -> Bombero Galarza y Necochea | D4: ='RESUMEN TOTAL'!E7 -> Domo | E4: ='RESUMEN TOTAL'!F7 -> Fibra Optica | F4: ='RESUMEN TOTAL'!L7 -> 0 | G4: ='RESUMEN TOTAL'!M7 -> 0 | H4: ='RESUMEN TOTAL'!N7 -> 0 | I4: ='RESUMEN TOTAL'!O7 -> 0 | J4: ='RESUMEN TOTAL'!P7 -> 0 | K4: ='RESUMEN TOTAL'!Q7 -> 0 | L4: ='RESUMEN TOTAL'!R7 -> 0 | M4: ='RESUMEN TOTAL'!S7 -> 0 | ... AI4: ='RESUMEN TOTAL'!AO7 -> 0
A5: ='RESUMEN TOTAL'!A8 -> ALTAMIRA | B5: ='RESUMEN TOTAL'!B8 -> ALT 04 | C5: ='RESUMEN TOTAL'!D8 -> Francia y Necochea | D5: ='RESUMEN TOTAL'!E8 -> Domo | E5: ='RESUMEN TOTAL'!F8 -> Fibra Optica | F5: ='RESUMEN TOTAL'!L8 -> 0 | G5: ='RESUMEN TOTAL'!M8 -> 0 | H5: ='RESUMEN TOTAL'!N8 -> 0 | I5: ='RESUMEN TOTAL'!O8 -> 0 | J5: ='RESUMEN TOTAL'!P8 -> 0 | K5: ='RESUMEN TOTAL'!Q8 -> 0 | L5: ='RESUMEN TOTAL'!R8 -> 0 | M5: ='RESUMEN TOTAL'!S8 -> 0 | ... AI5: ='RESUMEN TOTAL'!AO8 -> 0
A6: ='RESUMEN TOTAL'!A9 -> ALTAMIRA | B6: ='RESUMEN TOTAL'!B9 -> ALT05 | C6: ='RESUMEN TOTAL'!D9 -> Av. Calchaqui y Bombero Galarza | D6: ='RESUMEN TOTAL'!E9 -> Domo | E6: ='RESUMEN TOTAL'!F9 -> PTO A FO | F6: ='RESUMEN TOTAL'!L9 -> 0 | G6: ='RESUMEN TOTAL'!M9 -> 0 | H6: ='RESUMEN TOTAL'!N9 -> 0 | I6: ='RESUMEN TOTAL'!O9 -> 0 | J6: ='RESUMEN TOTAL'!P9 -> 0 | K6: ='RESUMEN TOTAL'!Q9 -> 0 | L6: ='RESUMEN TOTAL'!R9 -> 0 | M6: ='RESUMEN TOTAL'!S9 -> 0 | ... AI6: ='RESUMEN TOTAL'!AO9 -> 0
A7: ='RESUMEN TOTAL'!A10 -> ALTAMIRA | B7: ='RESUMEN TOTAL'!B10 -> ALT 06 | C7: ='RESUMEN TOTAL'!D10 -> LOPE DE VEGA Y NECOCHEA | D7: ='RESUMEN TOTAL'!E10 -> Domo | E7: ='RESUMEN TOTAL'!F10 -> PTO A FO | F7: ='RESUMEN TOTAL'!L10 -> 0 | G7: ='RESUMEN TOTAL'!M10 -> 0 | H7: ='RESUMEN TOTAL'!N10 -> 0 | I7: ='RESUMEN TOTAL'!O10 -> 0 | J7: ='RESUMEN TOTAL'!P10 -> 0 | K7: ='RESUMEN TOTAL'!Q10 -> 0 | L7: ='RESUMEN TOTAL'!R10 -> 0 | M7: ='RESUMEN TOTAL'!S10 -> 0 | ... AI7: ='RESUMEN TOTAL'!AO10 -> 0
A8: ='RESUMEN TOTAL'!A11 -> ALTAMIRA | B8: ='RESUMEN TOTAL'!B11 -> ALT07 | C8: ='RESUMEN TOTAL'!D11 -> AV. CALCHAQUI Y AV. DEL TRABAJO | D8: ='RESUMEN TOTAL'!E11 -> DOMO | E8: ='RESUMEN TOTAL'!F11 -> PTO A FO | F8: ='RESUMEN TOTAL'!L11 -> 0 | G8: ='RESUMEN TOTAL'!M11 -> 0 | H8: ='RESUMEN TOTAL'!N11 -> 0 | I8: ='RESUMEN TOTAL'!O11 -> 0 | J8: ='RESUMEN TOTAL'!P11 -> 0 | K8: ='RESUMEN TOTAL'!Q11 -> 0 | L8: ='RESUMEN TOTAL'!R11 -> 0 | M8: ='RESUMEN TOTAL'!S11 -> 0 | ... AI8: ='RESUMEN TOTAL'!AO11 -> 0
A9: ='RESUMEN TOTAL'!A12 -> ALTAMIRA | B9: ='RESUMEN TOTAL'!B12 -> ALT 08 | C9: ='RESUMEN TOTAL'!D12 -> HUMAITA Y NECOCHEA | D9: ='RESUMEN TOTAL'!E12 -> DOMO | E9: ='RESUMEN TOTAL'!F12 -> Fibra Optica | F9: ='RESUMEN TOTAL'!L12 -> 0 | G9: ='RESUMEN TOTAL'!M12 -> 0 | H9: ='RESUMEN TOTAL'!N12 -> 0 | I9: ='RESUMEN TOTAL'!O12 -> 0 | J9: ='RESUMEN TOTAL'!P12 -> 0 | K9: ='RESUMEN TOTAL'!Q12 -> 0 | L9: ='RESUMEN TOTAL'!R12 -> 0 | M9: ='RESUMEN TOTAL'!S12 -> 0 | ... AI9: ='RESUMEN TOTAL'!AO12 -> 0
A10: ='RESUMEN TOTAL'!A13 -> ALTAMIRA | B10: ='RESUMEN TOTAL'!B13 -> ALT 09 | C10: ='RESUMEN TOTAL'!D13 -> NECOCHEA Y CURUPAITY | D10: ='RESUMEN TOTAL'!E13 -> DOMO | E10: ='RESUMEN TOTAL'!F13 -> Fibra Optica | F10: ='RESUMEN TOTAL'!L13 -> APAGADO | G10: ='RESUMEN TOTAL'!M13 -> APAGADO | H10: ='RESUMEN TOTAL'!N13 -> APAGADO | I10: ='RESUMEN TOTAL'!O13 -> APAGADO | J10: ='RESUMEN TOTAL'!P13 -> APAGADO | K10: ='RESUMEN TOTAL'!Q13 -> APAGADO | L10: ='RESUMEN TOTAL'!R13 -> APAGADO | M10: ='RESUMEN TOTAL'!S13 -> APAGADO | ... AI10: ='RESUMEN TOTAL'!AO13 -> APAGADO
A11: ='RESUMEN TOTAL'!A14 -> ALTAMIRA | B11: ='RESUMEN TOTAL'!B14 -> ALT 10 | C11: ='RESUMEN TOTAL'!D14 -> Calchaqui y Francia | D11: ='RESUMEN TOTAL'!E14 -> Domo | E11: ='RESUMEN TOTAL'!F14 -> Radio | F11: ='RESUMEN TOTAL'!L14 -> 0 | G11: ='RESUMEN TOTAL'!M14 -> 0 | H11: ='RESUMEN TOTAL'!N14 -> 0 | I11: ='RESUMEN TOTAL'!O14 -> 0 | J11: ='RESUMEN TOTAL'!P14 -> 0 | K11: ='RESUMEN TOTAL'!Q14 -> 0 | L11: ='RESUMEN TOTAL'!R14 -> 0 | M11: ='RESUMEN TOTAL'!S14 -> 0 | ... AI11: ='RESUMEN TOTAL'!AO14 -> 0
A12: ='RESUMEN TOTAL'!A15 -> AGUSTIN RAMIREZ | B12: ='RESUMEN TOTAL'!B15 -> ARA 01 | C12: ='RESUMEN TOTAL'!D15 -> Malambo y Tranquera | D12: ='RESUMEN TOTAL'!E15 -> Domo | E12: ='RESUMEN TOTAL'!F15 -> Fibra Optica | F12: ='RESUMEN TOTAL'!L15 -> APAGADO | G12: ='RESUMEN TOTAL'!M15 -> APAGADO | H12: ='RESUMEN TOTAL'!N15 -> APAGADO | I12: ='RESUMEN TOTAL'!O15 -> APAGADO | J12: ='RESUMEN TOTAL'!P15 -> APAGADO | K12: ='RESUMEN TOTAL'!Q15 -> APAGADO | L12: ='RESUMEN TOTAL'!R15 -> APAGADO | M12: ='RESUMEN TOTAL'!S15 -> APAGADO | ... AI12: ='RESUMEN TOTAL'!AO15 -> 0
A13: ='RESUMEN TOTAL'!A16 -> BELGRANO | B13: ='RESUMEN TOTAL'!B16 -> BEL 01 | C13: ='RESUMEN TOTAL'!D16 -> San Martin y Dardo Rocha | D13: ='RESUMEN TOTAL'!E16 -> DOMO | E13: ='RESUMEN TOTAL'!F16 -> Fibra Optica | F13: ='RESUMEN TOTAL'!L16 -> 0 | G13: ='RESUMEN TOTAL'!M16 -> 0 | H13: ='RESUMEN TOTAL'!N16 -> 0 | I13: ='RESUMEN TOTAL'!O16 -> 0 | J13: ='RESUMEN TOTAL'!P16 -> 0 | K13: ='RESUMEN TOTAL'!Q16 -> 0 | L13: ='RESUMEN TOTAL'!R16 -> 0 | M13: ='RESUMEN TOTAL'!S16 -> 0 | ... AI13: ='RESUMEN TOTAL'!AO16 -> APAGADO
A14: ='RESUMEN TOTAL'!A17 -> BELGRANO | B14: ='RESUMEN TOTAL'!B17 -> BEL 02 | C14: ='RESUMEN TOTAL'!D17 -> Guardia vieja y Fronteriz | D14: ='RESUMEN TOTAL'!E17 -> DOMO | E14: ='RESUMEN TOTAL'!F17 -> Fibra Optica | F14: ='RESUMEN TOTAL'!L17 -> 0 | G14: ='RESUMEN TOTAL'!M17 -> 0 | H14: ='RESUMEN TOTAL'!N17 -> 0 | I14: ='RESUMEN TOTAL'!O17 -> 0 | J14: ='RESUMEN TOTAL'!P17 -> 0 | K14: ='RESUMEN TOTAL'!Q17 -> 0 | L14: ='RESUMEN TOTAL'!R17 -> 0 | M14: ='RESUMEN TOTAL'!S17 -> 0 | ... AI14: ='RESUMEN TOTAL'!AO17 -> APAGADO
A15: ='RESUMEN TOTAL'!A18 -> BOSQUES CENTRO | B15: ='RESUMEN TOTAL'!B18 -> BOSQC 01 | C15: ='RESUMEN TOTAL'!D18 -> LUIS AGOTE E/DANUNCIO Y CAMPOAMOR | D15: ='RESUMEN TOTAL'!E18 -> Fija | E15: ='RESUMEN TOTAL'!F18 -> Radio | F15: ='RESUMEN TOTAL'!L18 -> 0 | G15: ='RESUMEN TOTAL'!M18 -> 0 | H15: ='RESUMEN TOTAL'!N18 -> 0 | I15: ='RESUMEN TOTAL'!O18 -> 0 | J15: ='RESUMEN TOTAL'!P18 -> 0 | K15: ='RESUMEN TOTAL'!Q18 -> 0 | L15: ='RESUMEN TOTAL'!R18 -> 0 | M15: ='RESUMEN TOTAL'!S18 -> 0 | ... AI15: ='RESUMEN TOTAL'!AO18 -> 0
... A25: ='RESUMEN TOTAL'!A28 -> CENTRO | B25: ='RESUMEN TOTAL'!B28 -> CEN 05 | C25: ='RESUMEN TOTAL'!D28 -> Bocuzzi e/España y San Martin | D25: ='RESUMEN TOTAL'!E28 -> DOMO | E25: ='RESUMEN TOTAL'!F28 -> Fibra Optica | F25: ='RESUMEN TOTAL'!L28 -> APAGADO | G25: ='RESUMEN TOTAL'!M28 -> APAGADO | H25: ='RESUMEN TOTAL'!N28 -> APAGADO | I25: ='RESUMEN TOTAL'!O28 -> APAGADO | J25: ='RESUMEN TOTAL'!P28 -> APAGADO | K25: ='RESUMEN TOTAL'!Q28 -> APAGADO | L25: ='RESUMEN TOTAL'!R28 -> APAGADO | M25: ='RESUMEN TOTAL'!S28 -> APAGADO | ... AI25: ='RESUMEN TOTAL'!AO28 -> 0
A26: ='RESUMEN TOTAL'!A29 -> CENTRO | B26: ='RESUMEN TOTAL'!B29 -> CEN06 | C26: ='RESUMEN TOTAL'!D29 -> Monteagudo y A.del Valle | D26: ='RESUMEN TOTAL'!E29 -> Fija | E26: ='RESUMEN TOTAL'!F29 -> Fibra Optica | F26: ='RESUMEN TOTAL'!L29 -> APAGADO | G26: ='RESUMEN TOTAL'!M29 -> APAGADO | H26: ='RESUMEN TOTAL'!N29 -> APAGADO | I26: ='RESUMEN TOTAL'!O29 -> APAGADO | J26: ='RESUMEN TOTAL'!P29 -> APAGADO | K26: ='RESUMEN TOTAL'!Q29 -> APAGADO | L26: ='RESUMEN TOTAL'!R29 -> APAGADO | M26: ='RESUMEN TOTAL'!S29 -> APAGADO | ... AG26: ='RESUMEN TOTAL'!AM29 -> 0 | AH26: ='RESUMEN TOTAL'!#REF! -> #REF! | AI26: ='RESUMEN TOTAL'!AN29 -> 0
A27: ='RESUMEN TOTAL'!A30 -> CENTRO | B27: ='RESUMEN TOTAL'!B30 -> CEN07 | C27: ='RESUMEN TOTAL'!D30 -> San Martin y Guemes | D27: ='RESUMEN TOTAL'!E30 -> DOMO | E27: ='RESUMEN TOTAL'!F30 -> Fibra Optica | F27: ='RESUMEN TOTAL'!L30 -> 0 | G27: ='RESUMEN TOTAL'!M30 -> 0 | H27: ='RESUMEN TOTAL'!N30 -> 0 | I27: ='RESUMEN TOTAL'!O30 -> 0 | J27: ='RESUMEN TOTAL'!P30 -> 0 | K27: ='RESUMEN TOTAL'!Q30 -> 0 | L27: ='RESUMEN TOTAL'!R30 -> 0 | M27: ='RESUMEN TOTAL'!S30 -> 0 | ... AI27: ='RESUMEN TOTAL'!AO30 -> 0
A28: ='RESUMEN TOTAL'!A31 -> CENTRO | B28: ='RESUMEN TOTAL'!B31 -> CEN08 | C28: ='RESUMEN TOTAL'!D31 -> San Martin y Pte.Peron | D28: ='RESUMEN TOTAL'!E31 -> Domo | E28: ='RESUMEN TOTAL'!F31 -> Fibra Optica | F28: ='RESUMEN TOTAL'!L31 -> 0 | G28: ='RESUMEN TOTAL'!M31 -> 0 | H28: ='RESUMEN TOTAL'!N31 -> 0 | I28: ='RESUMEN TOTAL'!O31 -> 0 | J28: ='RESUMEN TOTAL'!P31 -> 0 | K28: ='RESUMEN TOTAL'!Q31 -> 0 | L28: ='RESUMEN TOTAL'!R31 -> 0 | M28: ='RESUMEN TOTAL'!S31 -> 0 | ... AG28: ='RESUMEN TOTAL'!AM31 -> 0 | AH28: ='RESUMEN TOTAL'!#REF! -> #REF! | AI28: ='RESUMEN TOTAL'!AN31 -> 0
A29: ='RESUMEN TOTAL'!A32 -> CENTRO | B29: ='RESUMEN TOTAL'!B32 -> CEN09 | C29: ='RESUMEN TOTAL'!D32 -> Chacabuco y 25 de Mayo | D29: ='RESUMEN TOTAL'!E32 -> Domo | E29: ='RESUMEN TOTAL'!F32 -> Fibra Optica | F29: ='RESUMEN TOTAL'!L32 -> 0 | G29: ='RESUMEN TOTAL'!M32 -> 0 | H29: ='RESUMEN TOTAL'!N32 -> 0 | I29: ='RESUMEN TOTAL'!O32 -> 0 | J29: ='RESUMEN TOTAL'!P32 -> 0 | K29: ='RESUMEN TOTAL'!Q32 -> 0 | L29: ='RESUMEN TOTAL'!R32 -> 0 | M29: ='RESUMEN TOTAL'!S32 -> 0 | ... AI29: ='RESUMEN TOTAL'!AO32 -> 0
A30: ='RESUMEN TOTAL'!A33 -> CENTRO | B30: ='RESUMEN TOTAL'!B33 -> CEN10 | C30: ='RESUMEN TOTAL'!D33 -> Monteagudo y Pte. Peron | D30: ='RESUMEN TOTAL'!E33 -> Domo | E30: ='RESUMEN TOTAL'!F33 -> Fibra Optica | F30: ='RESUMEN TOTAL'!L33 -> 0 | G30: ='RESUMEN TOTAL'!M33 -> 0 | H30: ='RESUMEN TOTAL'!N33 -> 0 | I30: ='RESUMEN TOTAL'!O33 -> 0 | J30: ='RESUMEN TOTAL'!P33 -> 0 | K30: ='RESUMEN TOTAL'!Q33 -> 0 | L30: ='RESUMEN TOTAL'!R33 -> 0 | M30: ='RESUMEN TOTAL'!S33 -> 0 | ... AI30: ='RESUMEN TOTAL'!AO33 -> 0
A31: ='RESUMEN TOTAL'!A34 -> CENTRO | B31: ='RESUMEN TOTAL'!B34 -> CEN11 | C31: ='RESUMEN TOTAL'!D34 -> Monteagudo y Bocuzzi | D31: ='RESUMEN TOTAL'!E34 -> Domo | E31: ='RESUMEN TOTAL'!F34 -> Fibra Optica | F31: ='RESUMEN TOTAL'!L34 -> 0 | G31: ='RESUMEN TOTAL'!M34 -> 0 | H31: ='RESUMEN TOTAL'!N34 -> 0 | I31: ='RESUMEN TOTAL'!O34 -> 0 | J31: ='RESUMEN TOTAL'!P34 -> 0 | K31: ='RESUMEN TOTAL'!Q34 -> 0 | L31: ='RESUMEN TOTAL'!R34 -> 0 | M31: ='RESUMEN TOTAL'!S34 -> 0 | ... AI31: ='RESUMEN TOTAL'!AO34 -> 0
A32: ='RESUMEN TOTAL'!A35 -> CENTRO | B32: ='RESUMEN TOTAL'!B35 -> CEN 12 | C32: ='RESUMEN TOTAL'!D35 -> Monteagudo y Mitre | D32: ='RESUMEN TOTAL'!E35 -> Domo | E32: ='RESUMEN TOTAL'!F35 -> Fibra Optica | F32: ='RESUMEN TOTAL'!L35 -> 0 | G32: ='RESUMEN TOTAL'!M35 -> 0 | H32: ='RESUMEN TOTAL'!N35 -> 0 | I32: ='RESUMEN TOTAL'!O35 -> 0 | J32: ='RESUMEN TOTAL'!P35 -> 0 | K32: ='RESUMEN TOTAL'!Q35 -> 0 | L32: ='RESUMEN TOTAL'!R35 -> 0 | M32: ='RESUMEN TOTAL'!S35 -> 0 | ... AI32: ='RESUMEN TOTAL'!AO35 -> 0
A33: ='RESUMEN TOTAL'!A36 -> CENTRO | B33: ='RESUMEN TOTAL'!B36 -> CEN 13 | C33: ='RESUMEN TOTAL'!D36 -> 25 de Mayo y Maipu | D33: ='RESUMEN TOTAL'!E36 -> DOMO | E33: ='RESUMEN TOTAL'!F36 -> Fibra Optica | F33: ='RESUMEN TOTAL'!L36 -> 0 | G33: ='RESUMEN TOTAL'!M36 -> 0 | H33: ='RESUMEN TOTAL'!N36 -> 0 | I33: ='RESUMEN TOTAL'!O36 -> 0 | J33: ='RESUMEN TOTAL'!P36 -> 0 | K33: ='RESUMEN TOTAL'!Q36 -> 0 | L33: ='RESUMEN TOTAL'!R36 -> 0 | M33: ='RESUMEN TOTAL'!S36 -> 0 | ... AI33: ='RESUMEN TOTAL'!AO36 -> 0
A34: ='RESUMEN TOTAL'!A37 -> CENTRO | B34: ='RESUMEN TOTAL'!B37 -> CEN14 | C34: ='RESUMEN TOTAL'!D37 -> Pte.Peron e/Pringles y Brown | D34: ='RESUMEN TOTAL'!E37 -> Domo | E34: ='RESUMEN TOTAL'!F37 -> Fibra Optica | F34: ='RESUMEN TOTAL'!L37 -> 0 | G34: ='RESUMEN TOTAL'!M37 -> 0 | H34: ='RESUMEN TOTAL'!N37 -> 0 | I34: ='RESUMEN TOTAL'!O37 -> 0 | J34: ='RESUMEN TOTAL'!P37 -> 0 | K34: ='RESUMEN TOTAL'!Q37 -> 0 | L34: ='RESUMEN TOTAL'!R37 -> 0 | M34: ='RESUMEN TOTAL'!S37 -> 0 | ... AI34: ='RESUMEN TOTAL'!AO37 -> 0
A35: ='RESUMEN TOTAL'!A38 -> CENTRO | B35: ='RESUMEN TOTAL'!B38 -> CEN15 | C35: ='RESUMEN TOTAL'!D38 -> Alberdi y A.del Valle | D35: ='RESUMEN TOTAL'!E38 -> Domo | E35: ='RESUMEN TOTAL'!F38 -> Fibra Optica | F35: ='RESUMEN TOTAL'!L38 -> 0 | G35: ='RESUMEN TOTAL'!M38 -> 0 | H35: ='RESUMEN TOTAL'!N38 -> 0 | I35: ='RESUMEN TOTAL'!O38 -> 0 | J35: ='RESUMEN TOTAL'!P38 -> 0 | K35: ='RESUMEN TOTAL'!Q38 -> 0 | L35: ='RESUMEN TOTAL'!R38 -> 0 | M35: ='RESUMEN TOTAL'!S38 -> 0 | ... AI35: ='RESUMEN TOTAL'!AO38 -> 0
