Workbook
Name _25_de_agosto: 'RESUMEN TOTAL'!$A$4:$D$363
Name _25_de_agosto_3: 'RESUMEN TOTAL'!$A$4:$D$375
Name BONOMOcam: Hoja1!$B$2
Name COSEIDIcam: Hoja1!$B$4

Sheet RESUMEN TOTAL
A1: CANTIDAD DE CAMARAS | B1: =COUNTA(B5:B530) -> 430 | D1: PORCIENTO DE CAIDAS | K1: =(K3)/(K2+K3) -> 0.093676815 | L1: =(L3)/(L2+L3) -> 0.093676815 | M1: =(M3)/(M2+M3) -> 0.38461538 | N1: =(N3)/(N2+N3) -> 0.1030445 | O1: =(O3)/(O2+O3) -> 0.088992974 | P1: =(P3)/(P2+P3) -> 0 | Q1: =(Q3)/(Q2+Q3) -> 0.084309133 | R1: =(R3)/(R2+R3) -> 0 | ... AO1: =(AO3)/(AO2+AO3) -> 0.095348837
D2: FUNCIONAN | K2: =COUNTIF(K7:K433, "") -> 387 | L2: =COUNTIF(L7:L433, "") -> 387 | M2: =COUNTIF(M7:M433, "") -> 264 | N2: =COUNTIF(N7:N433, "") -> 383 | O2: =COUNTIF(O7:O433, "") -> 389 | P2: =COUNTIF(P7:P433, "") -> 427 | Q2: =COUNTIF(Q7:Q433, "") -> 391 | R2: =COUNTIF(R7:R433, "") -> 427 | ... AE2: =COUNTIF(AE7:AE433, "") -> 384 | AF2: =COUNTIF(AF5:AF434, "") -> 384 | AG2: =COUNTIF(AG5:AG434, "") -> 373 | AH2: =COUNTIF(AH5:AH434, "") -> 388 | AI2: =COUNTIF(AI5:AI434, "") -> 388 | AJ2: =COUNTIF(AJ5:AJ434, "") -> 390 | AK2: =COUNTIF(AK5:AK434, "") -> 383 | AL2: =COUNTIF(AL5:AL434, "") -> 382 | AM2: =COUNTIF(AM5:AM434, "") -> 398 | ... AO2: =COUNTIF(AO5:AO434, "") -> 389
D3: CAIDAS | K3: =COUNTIF(K4:K450, "apagado") -> 40 | L3: =COUNTIF(L4:L450, "apagado") -> 40 | M3: =COUNTIF(M4:M450, "apagado") -> 165 | N3: =COUNTIF(N4:N450, "apagado") -> 44 | O3: =COUNTIF(O4:O450, "apagado") -> 38 | P3: =COUNTIF(P4:P450, "apagado") -> 0 | Q3: =COUNTIF(Q4:Q450, "apagado") -> 36 | R3: =COUNTIF(R4:R450, "apagado") -> 0 | ... AO3: =COUNTIF(AO4:AO450, "apagado") -> 41
A4: Barrio | B4: [Denominacion] | C4: [Empresa Mantenimiento] | D4: [Ubicacion] | E4: [Tipo de Camara] | F4: [Tipo de Conexion] | H4: DIAS FUNCIONANDO | I4: DIAS CAIDA | J4: EFECTIVIDAD | K4: 44835 | L4: 44836 | M4: 44837 | N4: 44838 | O4: 44839 | P4: 44840 | Q4: 44841 | R4: 44842 | S4: 44843 | T4: 44844 | U4: 44845 | V4: 44846 | W4: 44847 | X4: 44848 | Y4: 44849 | Z4: 44850 | AA4: 44851 | AB4: 44852 | AC4: 44853 | AD4: 44854 | AE4: 44855 | AF4: 44856 | AG4: 44857 | AH4: 44858 | AI4: 44859 | AJ4: 44860 | AK4: 44861 | AL4: 44862 | AM4: 44863 | AN4: 44864 | AO4: 44865
A5: ALTAMIRA | B5: ALT01 | C5: BONOMO | D5: Calchaqui y Sgto. Cabral | E5: Domo | F5: Fibra Optica | G5: 172.20.10.6 | H5: =COUNTIF(K5:AN5,"") -> 29 | I5: =COUNTIF(K5:AL5,"APAGADO") -> 1 | J5: =(H5)/(I5+H5) -> 0.96666667 | M5: APAGADO
A6: ALTAMIRA | B6: ALT02 | C6: BONOMO | D6: Calchaqui y Lope de Vega | E6: Domo | F6: PTO A FO | G6: 172.20.12.218 | H6: =COUNTIF(K6:AN6,"") -> 29 | I6: =COUNTIF(K6:AL6,"APAGADO") -> 1 | J6: =(H6)/(I6+H6) -> 0.96666667 | M6: APAGADO
A7: ALTAMIRA | B7: ALT 03 | C7: BONOMO | D7: Bombero Galarza y Necochea | E7: Domo | F7: FIBRA OPTICA | G7: 172.20.12.54 | H7: =COUNTIF(K7:AN7,"") -> 30 | I7: =COUNTIF(K7:AL7,"APAGADO") -> 0 | J7: =(H7)/(I7+H7) -> 1
A8: ALTAMIRA | B8: ALT 04 | C8: BONOMO | D8: Francia y Necochea | E8: Domo | F8: FIBRA OPTICA | G8: 172.20.12.55 | H8: =COUNTIF(K8:AN8,"") -> 25 | I8: =COUNTIF(K8:AL8,"APAGADO") -> 5 | J8: =(H8)/(I8+H8) -> 0.83333333 | K8: APAGADO | L8: APAGADO | M8: APAGADO | N8: APAGADO | O8: APAGADO
A9: ALTAMIRA | B9: ALT05 | C9: BONOMO | D9: Av. Calchaqui y Bombero Galarza | E9: Domo | F9: PTO A FO | G9: 172.20.12.216 | H9: =COUNTIF(K9:AN9,"") -> 8 | I9: =COUNTIF(K9:AL9,"APAGADO") -> 22 | J9: =(H9)/(I9+H9) -> 0.26666667 | K9: APAGADO | L9: APAGADO | M9: APAGADO | N9: APAGADO | O9: APAGADO | Q9: APAGADO | S9: APAGADO | T9: APAGADO | U9: APAGADO | V9: APAGADO | W9: APAGADO | X9: APAGADO | Y9: APAGADO | Z9: APAGADO | AB9: APAGADO | AC9: APAGADO | AD9: APAGADO | AE9: APAGADO | AF9: APAGADO | AG9: APAGADO | AH9: APAGADO | AI9: APAGADO
A10: ALTAMIRA | B10: ALT 06 | C10: BONOMO | D10: LOPE DE VEGA Y NECOCHEA | E10: Domo | F10: PTO A FO | G10: 172.20.12.12 | H10: =COUNTIF(K10:AN10,"") -> 28 | I10: =COUNTIF(K10:AL10,"APAGADO") -> 2 | J10: =(H10)/(I10+H10) -> 0.93333333 | M10: APAGADO | N10: APAGADO
A11: ALTAMIRA | B11: ALT07 | C11: BONOMO | D11: AV. CALCHAQUI Y AV. DEL TRABAJO | E11: DOMO | F11: PTO A FO | G11: 172.20.10.57 | H11: =COUNTIF(K11:AN11,"") -> 30 | I11: =COUNTIF(K11:AL11,"APAGADO") -> 0 | J11: =(H11)/(I11+H11) -> 1
A12: ALTAMIRA | B12: ALT 08 | C12: BONOMO | D12: HUMAITA Y NECOCHEA | E12: DOMO | F12: Fibra Optica | G12: 172.20.11.215 | H12: =COUNTIF(K12:AN12,"") -> 30 | I12: =COUNTIF(K12:AL12,"APAGADO") -> 0 | J12: =(H12)/(I12+H12) -> 1
A13: ALTAMIRA | B13: ALT 09 | C13: BONOMO | D13: NECOCHEA Y CURUPAITY | E13: DOMO | F13: Fibra Optica | G13: 172.20.11.216 | H13: =COUNTIF(K13:AN13,"") -> 30 | I13: =COUNTIF(K13:AL13,"APAGADO") -> 0 | J13: =(H13)/(I13+H13) -> 1
A14: ALTAMIRA | B14: ALT 10 | C14: BONOMO | D14: Calchaqui y Francia | E14: Domo | F14: Radio | H14: =COUNTIF(K14:AN14,"") -> 9 | I14: =COUNTIF(K14:AL14,"APAGADO") -> 21 | J14: =(H14)/(I14+H14) -> 0.3 | K14: APAGADO | L14: APAGADO | M14: APAGADO | N14: APAGADO | O14: APAGADO | Q14: APAGADO | S14: APAGADO | T14: APAGADO | U14: APAGADO | V14: APAGADO | W14: APAGADO | X14: APAGADO | Y14: APAGADO | Z14: APAGADO | AB14: APAGADO | AC14: APAGADO | AD14: APAGADO | AE14: APAGADO | AF14: APAGADO | AG14: APAGADO | AH14: APAGADO
A15: AGUSTIN RAMIREZ | B15: ARA 01 | C15: COSEIDI | D15: Malambo y Tranquera | E15: Domo | F15: FIBRA OPTICA | G15: 172.20.12.110 | H15: =COUNTIF(K15:AN15,"") -> 28 | I15: =COUNTIF(K15:AL15,"APAGADO") -> 2 | J15: =(H15)/(I15+H15) -> 0.93333333 | M15: APAGADO | AC15: APAGADO
A16: BELGRANO | B16: BEL 01 | C16: BONOMO | D16: San Martin y Dardo Rocha | E16: DOMO | F16: FIBRA OPTICA | G16: 172.20.12.64 | H16: =COUNTIF(K16:AN16,"") -> 4 | I16: =COUNTIF(K16:AL16,"APAGADO") -> 24 | J16: =(H16)/(I16+H16) -> 0.14285714 | K16: APAGADO | L16: APAGADO | M16: APAGADO | N16: APAGADO | O16: APAGADO | Q16: APAGADO | T16: APAGADO | U16: APAGADO | V16: APAGADO | W16: APAGADO | X16: APAGADO | Y16: APAGADO | Z16: APAGADO | AB16: APAGADO | AC16: APAGADO | AD16: APAGADO | AE16: APAGADO | AF16: APAGADO | AG16: APAGADO | AH16: APAGADO | AI16: APAGADO | AJ16: APAGADO | AK16: APAGADO | AL16: APAGADO | AM16: APAGADO | AN16: APAGADO
A17: BOSQUES CENTRO | B17: BOSQC 01 | C17: COSEIDI | D17: LUIS AGOTE E/DANUNCIO Y CAMPOAMOR | E17: Fija | F17: Radio | G17: 172.20.11.15 | H17: =COUNTIF(K17:AN17,"") -> 30 | I17: =COUNTIF(K17:AL17,"APAGADO") -> 0 | J17: =(H17)/(I17+H17) -> 1
A18: BOSQUES CENTRO | B18: BOSQC 02 | C18: COSEIDI | D18: LUIS AGOTE E/DANUNCIO Y CAMPOAMOR | E18: Fija | F18: Radio | G18: 172.20.11.16 | H18: =COUNTIF(K18:AN18,"") -> 30 | I18: =COUNTIF(K18:AL18,"APAGADO") -> 0 | J18: =(H18)/(I18+H18) -> 1
A19: BOSQUES CENTRO | B19: BOSQC 03 | C19: COSEIDI | D19: BENAVENTE Y LUIS AGOTE | E19: Fija | F19: Radio | G19: 172.20.11.13 | H19: =COUNTIF(K19:AN19,"") -> 30 | I19: =COUNTIF(K19:AL19,"APAGADO") -> 0 | J19: =(H19)/(I19+H19) -> 1
A20: BOSQUES CENTRO | B20: BOSQC 04 | C20: COSEIDI | D20: BENAVENTE Y LUIS AGOTE | E20: Fija | F20: Radio | G20: 172.20.11.113 | H20: =COUNTIF(K20:AN20,"") -> 30 | I20: =COUNTIF(K20:AL20,"APAGADO") -> 0 | J20: =(H20)/(I20+H20) -> 1
A21: BOSQUES CENTRO | B21: BOSQC 05 | C21: COSEIDI | D21: LUIS AGOTE Y RUTA 36 | E21: Fija | F21: Radio | G21: 172.20.11.17 | H21: =COUNTIF(K21:AN21,"") -> 30 | I21: =COUNTIF(K21:AL21,"APAGADO") -> 0 | J21: =(H21)/(I21+H21) -> 1
A22: BOSQUES CENTRO | B22: BOSQC 06 | C22: COSEIDI | D22: LUIS AGOTE Y RUTA 36 | E22: Fija | F22: Radio | G22: 172.20.11.18 | H22: =COUNTIF(K22:AN22,"") -> 30 | I22: =COUNTIF(K22:AL22,"APAGADO") -> 0 | J22: =(H22)/(I22+H22) -> 1
A23: CENTRO | B23: CEN01 | C23: BONOMO | D23: San Martin y 9 de Julio | E23: Fija | F23: Fibra Optica | G23: 172.20.11.10 | H23: =COUNTIF(K23:AN23,"") -> 29 | I23: =COUNTIF(K23:AL23,"APAGADO") -> 1 | J23: =(H23)/(I23+H23) -> 0.96666667 | M23: APAGADO
A24: CENTRO | B24: CEN02 | C24: BONOMO | D24: San Martin y Almafuerte | E24: Fija | F24: Fibra Optica | G24: 172.20.11.11 | H24: =COUNTIF(K24:AN24,"") -> 29 | I24: =COUNTIF(K24:AL24,"APAGADO") -> 1 | J24: =(H24)/(I24+H24) -> 0.96666667 | M24: APAGADO
A25: CENTRO | B25: CEN03 | C25: BONOMO | D25: San Martin y Sallares | E25: Domo | F25: Fibra Optica | G25: 172.20.12.30 | H25: =COUNTIF(K25:AN25,"") -> 29 | I25: =COUNTIF(K25:AL25,"APAGADO") -> 1 | J25: =(H25)/(I25+H25) -> 0.96666667 | M25: APAGADO
A26: CENTRO | B26: CEN04 | C26: BONOMO | D26: San Martin y Contreras | E26: Domo | F26: Fibra Optica | G26: 172.20.12.29 | H26: =COUNTIF(K26:AN26,"") -> 30 | I26: =COUNTIF(K26:AL26,"APAGADO") -> 0 | J26: =(H26)/(I26+H26) -> 1
A27: CENTRO | B27: CEN 05 | C27: BONOMO | D27: Bocuzzi e/España y San Martin | E27: DOMO | F27: Fibra Optica | G27: 172.20.10.200 | H27: =COUNTIF(K27:AN27,"") -> 29 | I27: =COUNTIF(K27:AL27,"APAGADO") -> 1 | J27: =(H27)/(I27+H27) -> 0.96666667 | M27: APAGADO
A28: CENTRO | B28: CEN06 | C28: BONOMO | D28: Monteagudo y A.del Valle | E28: Fija | F28: Fibra Optica | G28: 172.20.10.02 | H28: =COUNTIF(K28:AN28,"") -> 29 | I28: =COUNTIF(K28:AL28,"APAGADO") -> 1 | J28: =(H28)/(I28+H28) -> 0.96666667 | M28: APAGADO
A29: CENTRO | B29: CEN07 | C29: BONOMO | D29: San Martin y Guemes | E29: DOMO | F29: Fibra Optica | G29: 172.20.11.20 | H29: =COUNTIF(K29:AN29,"") -> 29 | I29: =COUNTIF(K29:AL29,"APAGADO") -> 1 | J29: =(H29)/(I29+H29) -> 0.96666667 | M29: APAGADO
A30: CENTRO | B30: CEN08 | C30: BONOMO | D30: San Martin y Pte.Peron | E30: Domo | F30: Fibra Optica | G30: 172.20.11.21 | H30: =COUNTIF(K30:AN30,"") -> 30 | I30: =COUNTIF(K30:AL30,"APAGADO") -> 0 | J30: =(H30)/(I30+H30) -> 1
A31: CENTRO | B31: CEN09 | C31: BONOMO | D31: Chacabuco y 25 de Mayo | E31: Domo | F31: Fibra Optica | G31: 172.20.11.22 | H31: =COUNTIF(K31:AN31,"") -> 30 | I31: =COUNTIF(K31:AL31,"APAGADO") -> 0 | J31: =(H31)/(I31+H31) -> 1
A32: CENTRO | B32: CEN10 | C32: BONOMO | D32: Monteagudo y Pte. Peron | E32: Domo | F32: Fibra Optica | G32: 172.20.11.23 | H32: =COUNTIF(K32:AN32,"") -> 29 | I32: =COUNTIF(K32:AL32,"APAGADO") -> 1 | J32: =(H32)/(I32+H32) -> 0.96666667 | M32: APAGADO
A33: CENTRO | B33: CEN11 | C33: BONOMO | D33: Monteagudo y Bocuzzi | E33: Domo | F33: Fibra Optica | G33: 172.20.10.24 | H33: =COUNTIF(K33:AN33,"") -> 30 | I33: =COUNTIF(K33:AL33,"APAGADO") -> 0 | J33: =(H33)/(I33+H33) -> 1
A34: CENTRO | B34: CEN 12 | C34: BONOMO | D34: Monteagudo y Mitre | E34: Domo | F34: Fibra Optica | G34: 172.20.10.23 | H34: =COUNTIF(K34:AN34,"") -> 11 | I34: =COUNTIF(K34:AL34,"APAGADO") -> 17 | J34: =(H34)/(I34+H34) -> 0.39285714 | N34: APAGADO | O34: APAGADO | W34: APAGADO | X34: APAGADO | Y34: APAGADO | Z34: APAGADO | AB34: APAGADO | AC34: APAGADO | AD34: APAGADO | AE34: APAGADO | AF34: APAGADO | AG34: APAGADO | AH34: APAGADO | AI34: APAGADO | AJ34: APAGADO | AK34: APAGADO | AL34: APAGADO | AM34: APAGADO | AN34: APAGADO | AO34: APAGADO
A35: CENTRO | B35: CEN 13 | C35: BONOMO | D35: 25 de Mayo y Maipu | E35: DOMO | F35: Fibra Optica | G35: 172.20.10.20 | H35: =COUNTIF(K35:AN35,"") -> 27 | I35: =COUNTIF(K35:AL35,"APAGADO") -> 3 | J35: =(H35)/(I35+H35) -> 0.9 | M35: APAGADO | Q35: APAGADO | AK35: APAGADO
A36: CENTRO | B36: CEN14 | C36: BONOMO | D36: Pte.Peron e/Pringles y Brown | E36: Domo | F36: Fibra Optica | G36: 172.20.10.21 | H36: =COUNTIF(K36:AN36,"") -> 30 | I36: =COUNTIF(K36:AL36,"APAGADO") -> 0 | J36: =(H36)/(I36+H36) -> 1
A37: CENTRO | B37: CEN15 | C37: BONOMO | D37: Alberdi y A.del Valle | E37: Domo | F37: Fibra Optica | G37: 172.20.10.35 | H37: =COUNTIF(K37:AN37,"") -> 4 | I37: =COUNTIF(K37:AL37,"APAGADO") -> 24 | J37: =(H37)/(I37+H37) -> 0.14285714 | K37: APAGADO | L37: APAGADO | M37: APAGADO | N37: APAGADO | O37: APAGADO | S37: APAGADO | T37: APAGADO | U37: APAGADO | V37: APAGADO | W37: APAGADO | X37: APAGADO | Y37: APAGADO | Z37: APAGADO | AB37: APAGADO | AC37: APAGADO | AD37: APAGADO | AE37: APAGADO | AF37: APAGADO | AG37: APAGADO | AH37: APAGADO | AI37: APAGADO | AJ37: APAGADO | AK37: APAGADO | AL37: APAGADO | AM37: APAGADO | AN37: APAGADO | AO37: APAGADO
A38: CENTRO | B38: CEN16 | C38: BONOMO | D38: San Martin y Pte. Peron | E38: Fija | F38: Fibra Optica | G38: 172.20.12.36 | H38: =COUNTIF(K38:AN38,"") -> 29 | I38: =COUNTIF(K38:AL38,"APAGADO") -> 1 | J38: =(H38)/(I38+H38) -> 0.96666667 | M38: APAGADO
A39: CENTRO | B39: CEN17 | C39: BONOMO | D39: San Martin y Mitre | E39: Domo | F39: PTO A FO | G39: 172.20.12.200 | H39: =COUNTIF(K39:AN39,"") -> 29 | I39: =COUNTIF(K39:AL39,"APAGADO") -> 1 | J39: =(H39)/(I39+H39) -> 0.96666667 | M39: APAGADO
A40: CENTRO | B40: CEN18 | C40: BONOMO | D40: Monteagudo e/Mitre y Sallares | E40: Fija | F40: Fibra Optica | G40: 172.20.10.26 | H40: =COUNTIF(K40:AN40,"") -> 4 | I40: =COUNTIF(K40:AL40,"APAGADO") -> 25 | J40: =(H40)/(I40+H40) -> 0.13793103 | K40: APAGADO | L40: APAGADO | M40: APAGADO | N40: APAGADO | O40: APAGADO | Q40: APAGADO | S40: APAGADO | T40: APAGADO | U40: APAGADO | V40: APAGADO | W40: APAGADO | X40: APAGADO | Y40: APAGADO | Z40: APAGADO | AB40: APAGADO | AC40: APAGADO | AD40: APAGADO | AE40: APAGADO | AF40: APAGADO | AG40: APAGADO | AH40: APAGADO | AI40: APAGADO | AJ40: APAGADO | AK40: APAGADO | AL40: APAGADO | AM40: APAGADO | AO40: APAGADO
...

Sheet ESTADISTICA
A1: ='RESUMEN TOTAL'!A4 -> Barrio | B1: ='RESUMEN TOTAL'!B4 -> [Denominacion] | C1: ='RESUMEN TOTAL'!D4 -> [Ubicacion] | D1: ='RESUMEN TOTAL'!E4 -> [Tipo de Camara] | E1: ='RESUMEN TOTAL'!F4 -> [Tipo de Conexion] | F1: ='RESUMEN TOTAL'!K4 -> 44835 | G1: ='RESUMEN TOTAL'!L4 -> 44836 | H1: ='RESUMEN TOTAL'!M4 -> 44837 | I1: ='RESUMEN TOTAL'!N4 -> 44838 | J1: ='RESUMEN TOTAL'!O4 -> 44839 | K1: ='RESUMEN TOTAL'!P4 -> 44840 | L1: ='RESUMEN TOTAL'!Q4 -> 44841 | M1: ='RESUMEN TOTAL'!R4 -> 44842 | ... AI1: ='RESUMEN TOTAL'!AN4 -> 44864
A2: ='RESUMEN TOTAL'!A5 -> ALTAMIRA | B2: ='RESUMEN TOTAL'!B5 -> ALT01 | C2: ='RESUMEN TOTAL'!D5 -> Calchaqui y Sgto. Cabral | D2: ='RESUMEN TOTAL'!E5 -> Domo | E2: ='RESUMEN TOTAL'!F5 -> Fibra Optica | F2: ='RESUMEN TOTAL'!K5 -> 0 | G2: ='RESUMEN TOTAL'!L5 -> 0 | H2: ='RESUMEN TOTAL'!M5 -> APAGADO | I2: ='RESUMEN TOTAL'!N5 -> 0 | J2: ='RESUMEN TOTAL'!O5 -> 0 | K2: ='RESUMEN TOTAL'!P5 -> 0 | L2: ='RESUMEN TOTAL'!Q5 -> 0 | M2: ='RESUMEN TOTAL'!R5 -> 0 | ... AI2: ='RESUMEN TOTAL'!AN5 -> 0
A3: ='RESUMEN TOTAL'!A6 -> ALTAMIRA | B3: ='RESUMEN TOTAL'!B6 -> ALT02 | C3: ='RESUMEN TOTAL'!D6 -> Calchaqui y Lope de Vega | D3: ='RESUMEN TOTAL'!E6 -> Domo | E3: ='RESUMEN TOTAL'!F6 -> PTO A FO | F3: ='RESUMEN TOTAL'!K6 -> 0 | G3: ='RESUMEN TOTAL'!L6 -> 0 | H3: ='RESUMEN TOTAL'!M6 -> APAGADO | I3: ='RESUMEN TOTAL'!N6 -> 0 | J3: ='RESUMEN TOTAL'!O6 -> 0 | K3: ='RESUMEN TOTAL'!P6 -> 0 | L3: ='RESUMEN TOTAL'!Q6 -> 0 | M3: ='RESUMEN TOTAL'!R6 -> 0 | ... AI3: ='RESUMEN TOTAL'!AN6 -> 0
A4: ='RESUMEN TOTAL'!A7 -> ALTAMIRA | B4: ='RESUMEN TOTAL'!B7 -> ALT 03 | C4: ='RESUMEN TOTAL'!D7 -> Bombero Galarza y Necochea | D4: ='RESUMEN TOTAL'!E7 -> Domo | E4: ='RESUMEN TOTAL'!F7 -> FIBRA OPTICA | F4: ='RESUMEN TOTAL'!K7 -> 0 | G4: ='RESUMEN TOTAL'!L7 -> 0 | H4: ='RESUMEN TOTAL'!M7 -> 0 | I4: ='RESUMEN TOTAL'!N7 -> 0 | J4: ='RESUMEN TOTAL'!O7 -> 0 | K4: ='RESUMEN TOTAL'!P7 -> 0 | L4: ='RESUMEN TOTAL'!Q7 -> 0 | M4: ='RESUMEN TOTAL'!R7 -> 0 | ... AI4: ='RESUMEN TOTAL'!AN7 -> 0
A5: ='RESUMEN TOTAL'!A8 -> ALTAMIRA | B5: ='RESUMEN TOTAL'!B8 -> ALT 04 | C5: ='RESUMEN TOTAL'!D8 -> Francia y Necochea | D5: ='RESUMEN TOTAL'!E8 -> Domo | E5: ='RESUMEN TOTAL'!F8 -> FIBRA OPTICA | F5: ='RESUMEN TOTAL'!K8 -> APAGADO | G5: ='RESUMEN TOTAL'!L8 -> APAGADO | H5: ='RESUMEN TOTAL'!M8 -> APAGADO | I5: ='RESUMEN TOTAL'!N8 -> APAGADO | J5: ='RESUMEN TOTAL'!O8 -> APAGADO | K5: ='RESUMEN TOTAL'!P8 -> 0 | L5: ='RESUMEN TOTAL'!Q8 -> 0 | M5: ='RESUMEN TOTAL'!R8 -> 0 | ... AI5: ='RESUMEN TOTAL'!AN8 -> 0
A6: ='RESUMEN TOTAL'!A9 -> ALTAMIRA | B6: ='RESUMEN TOTAL'!B9 -> ALT05 | C6: ='RESUMEN TOTAL'!D9 -> Av. Calchaqui y Bombero Galarza | D6: ='RESUMEN TOTAL'!E9 -> Domo | E6: ='RESUMEN TOTAL'!F9 -> PTO A FO | F6: ='RESUMEN TOTAL'!K9 -> APAGADO | G6: ='RESUMEN TOTAL'!L9 -> APAGADO | H6: ='RESUMEN TOTAL'!M9 -> APAGADO | I6: ='RESUMEN TOTAL'!N9 -> APAGADO | J6: ='RESUMEN TOTAL'!O9 -> APAGADO | K6: ='RESUMEN TOTAL'!P9 -> 0 | L6: ='RESUMEN TOTAL'!Q9 -> APAGADO | M6: ='RESUMEN TOTAL'!R9 -> 0 | ... AI6: ='RESUMEN TOTAL'!AN9 -> 0
A7: ='RESUMEN TOTAL'!A10 -> ALTAMIRA | B7: ='RESUMEN TOTAL'!B10 -> ALT 06 | C7: ='RESUMEN TOTAL'!D10 -> LOPE DE VEGA Y NECOCHEA | D7: ='RESUMEN TOTAL'!E10 -> Domo | E7: ='RESUMEN TOTAL'!F10 -> PTO A FO | F7: ='RESUMEN TOTAL'!K10 -> 0 | G7: ='RESUMEN TOTAL'!L10 -> 0 | H7: ='RESUMEN TOTAL'!M10 -> APAGADO | I7: ='RESUMEN TOTAL'!N10 -> APAGADO | J7: ='RESUMEN TOTAL'!O10 -> 0 | K7: ='RESUMEN TOTAL'!P10 -> 0 | L7: ='RESUMEN TOTAL'!Q10 -> 0 | M7: ='RESUMEN TOTAL'!R10 -> 0 | ... AI7: ='RESUMEN TOTAL'!AN10 -> 0
A8: ='RESUMEN TOTAL'!A11 -> ALTAMIRA | B8: ='RESUMEN TOTAL'!B11 -> ALT07 | C8: ='RESUMEN TOTAL'!D11 -> AV. CALCHAQUI Y AV. DEL TRABAJO | D8: ='RESUMEN TOTAL'!E11 -> DOMO | E8: ='RESUMEN TOTAL'!F11 -> PTO A FO | F8: ='RESUMEN TOTAL'!K11 -> 0 | G8: ='RESUMEN TOTAL'!L11 -> 0 | H8: ='RESUMEN TOTAL'!M11 -> 0 | I8: ='RESUMEN TOTAL'!N11 -> 0 | J8: ='RESUMEN TOTAL'!O11 -> 0 | K8: ='RESUMEN TOTAL'!P11 -> 0 | L8: ='RESUMEN TOTAL'!Q11 -> 0 | M8: ='RESUMEN TOTAL'!R11 -> 0 | ... AI8: ='RESUMEN TOTAL'!AN11 -> 0
A9: ='RESUMEN TOTAL'!A12 -> ALTAMIRA | B9: ='RESUMEN TOTAL'!B12 -> ALT 08 | C9: ='RESUMEN TOTAL'!D12 -> HUMAITA Y NECOCHEA | D9: ='RESUMEN TOTAL'!E12 -> DOMO | E9: ='RESUMEN TOTAL'!F12 -> Fibra Optica | F9: ='RESUMEN TOTAL'!K12 -> 0 | G9: ='RESUMEN TOTAL'!L12 -> 0 | H9: ='RESUMEN TOTAL'!M12 -> 0 | I9: ='RESUMEN TOTAL'!N12 -> 0 | J9: ='RESUMEN TOTAL'!O12 -> 0 | K9: ='RESUMEN TOTAL'!P12 -> 0 | L9: ='RESUMEN TOTAL'!Q12 -> 0 | M9: ='RESUMEN TOTAL'!R12 -> 0 | ... AI9: ='RESUMEN TOTAL'!AN12 -> 0
A10: ='RESUMEN TOTAL'!A13 -> ALTAMIRA | B10: ='RESUMEN TOTAL'!B13 -> ALT 09 | C10: ='RESUMEN TOTAL'!D13 -> NECOCHEA Y CURUPAITY | D10: ='RESUMEN TOTAL'!E13 -> DOMO | E10: ='RESUMEN TOTAL'!F13 -> Fibra Optica | F10: ='RESUMEN TOTAL'!K13 -> 0 | G10: ='RESUMEN TOTAL'!L13 -> 0 | H10: ='RESUMEN TOTAL'!M13 -> 0 | I10: ='RESUMEN TOTAL'!N13 -> 0 | J10: ='RESUMEN TOTAL'!O13 -> 0 | K10: ='RESUMEN TOTAL'!P13 -> 0 | L10: ='RESUMEN TOTAL'!Q13 -> 0 | M10: ='RESUMEN TOTAL'!R13 -> 0 | ... AI10: ='RESUMEN TOTAL'!AN13 -> 0
A11: ='RESUMEN TOTAL'!A14 -> ALTAMIRA | B11: ='RESUMEN TOTAL'!B14 -> ALT 10 | C11: ='RESUMEN TOTAL'!D14 -> Calchaqui y Francia | D11: ='RESUMEN TOTAL'!E14 -> Domo | E11: ='RESUMEN TOTAL'!F14 -> Radio | F11: ='RESUMEN TOTAL'!K14 -> APAGADO | G11: ='RESUMEN TOTAL'!L14 -> APAGADO | H11: ='RESUMEN TOTAL'!M14 -> APAGADO | I11: ='RESUMEN TOTAL'!N14 -> APAGADO | J11: ='RESUMEN TOTAL'!O14 -> APAGADO | K11: ='RESUMEN TOTAL'!P14 -> 0 | L11: ='RESUMEN TOTAL'!Q14 -> APAGADO | M11: ='RESUMEN TOTAL'!R14 -> 0 | ... AI11: ='RESUMEN TOTAL'!AN14 -> 0
A12: ='RESUMEN TOTAL'!A15 -> AGUSTIN RAMIREZ | B12: ='RESUMEN TOTAL'!B15 -> ARA 01 | C12: ='RESUMEN TOTAL'!D15 -> Malambo y Tranquera | D12: ='RESUMEN TOTAL'!E15 -> Domo | E12: ='RESUMEN TOTAL'!F15 -> FIBRA OPTICA | F12: ='RESUMEN TOTAL'!K15 -> 0 | G12: ='RESUMEN TOTAL'!L15 -> 0 | H12: ='RESUMEN TOTAL'!M15 -> APAGADO | I12: ='RESUMEN TOTAL'!N15 -> 0 | J12: ='RESUMEN TOTAL'!O15 -> 0 | K12: ='RESUMEN TOTAL'!P15 -> 0 | L12: ='RESUMEN TOTAL'!Q15 -> 0 | M12: ='RESUMEN TOTAL'!R15 -> 0 | ... AI12: ='RESUMEN TOTAL'!AN15 -> 0
... A19: ='RESUMEN TOTAL'!A22 -> BOSQUES CENTRO | B19: ='RESUMEN TOTAL'!B22 -> BOSQC 06 | C19: ='RESUMEN TOTAL'!D22 -> LUIS AGOTE Y RUTA 36 | D19: ='RESUMEN TOTAL'!E22 -> Fija | E19: ='RESUMEN TOTAL'!F22 -> Radio | F19: ='RESUMEN TOTAL'!K22 -> 0 | G19: ='RESUMEN TOTAL'!L22 -> 0 | H19: ='RESUMEN TOTAL'!M22 -> 0 | I19: ='RESUMEN TOTAL'!N22 -> 0 | J19: ='RESUMEN TOTAL'!O22 -> 0 | K19: ='RESUMEN TOTAL'!P22 -> 0 | L19: ='RESUMEN TOTAL'!Q22 -> 0 | M19: ='RESUMEN TOTAL'!R22 -> 0 | ... AI19: ='RESUMEN TOTAL'!AN22 -> 0
A20: ='RESUMEN TOTAL'!A263 -> RICARDO ROJAS | B20: ='RESUMEN TOTAL'!B263 -> RRJ 12 | C20: ='RESUMEN TOTAL'!D263 -> FADER Y DIAGONAL LOS POETAS | D20: ='RESUMEN TOTAL'!E263 -> Fija | E20: ='RESUMEN TOTAL'!F263 -> Fibra Optica | F20: ='RESUMEN TOTAL'!K263 -> 0 | G20: ='RESUMEN TOTAL'!L263 -> 0 | H20: ='RESUMEN TOTAL'!M263 -> 0 | I20: ='RESUMEN TOTAL'!N263 -> 0 | J20: ='RESUMEN TOTAL'!O263 -> 0 | K20: ='RESUMEN TOTAL'!P263 -> 0 | L20: ='RESUMEN TOTAL'!Q263 -> 0 | M20: ='RESUMEN TOTAL'!R263 -> 0 | ... AI20: ='RESUMEN TOTAL'!AN263 -> 0
A21: ='RESUMEN TOTAL'!A23 -> CENTRO | B21: ='RESUMEN TOTAL'!B23 -> CEN01 | C21: ='RESUMEN TOTAL'!D23 -> San Martin y 9 de Julio | D21: ='RESUMEN TOTAL'!E23 -> Fija | E21: ='RESUMEN TOTAL'!F23 -> Fibra Optica | F21: ='RESUMEN TOTAL'!K23 -> 0 | G21: ='RESUMEN TOTAL'!L23 -> 0 | H21: ='RESUMEN TOTAL'!M23 -> APAGADO | I21: ='RESUMEN TOTAL'!N23 -> 0 | J21: ='RESUMEN TOTAL'!O23 -> 0 | K21: ='RESUMEN TOTAL'!P23 -> 0 | L21: ='RESUMEN TOTAL'!Q23 -> 0 | M21: ='RESUMEN TOTAL'!R23 -> 0 | ... AI21: ='RESUMEN TOTAL'!AN23 -> 0
A22: ='RESUMEN TOTAL'!A24 -> CENTRO | B22: ='RESUMEN TOTAL'!B24 -> CEN02 | C22: ='RESUMEN TOTAL'!D24 -> San Martin y Almafuerte | D22: ='RESUMEN TOTAL'!E24 -> Fija | E22: ='RESUMEN TOTAL'!F24 -> Fibra Optica | F22: ='RESUMEN TOTAL'!K24 -> 0 | G22: ='RESUMEN TOTAL'!L24 -> 0 | H22: ='RESUMEN TOTAL'!M24 -> APAGADO | I22: ='RESUMEN TOTAL'!N24 -> 0 | J22: ='RESUMEN TOTAL'!O24 -> 0 | K22: ='RESUMEN TOTAL'!P24 -> 0 | L22: ='RESUMEN TOTAL'!Q24 -> 0 | M22: ='RESUMEN TOTAL'!R24 -> 0 | ... AI22: ='RESUMEN TOTAL'!AN24 -> 0
A23: ='RESUMEN TOTAL'!A25 -> CENTRO | B23: ='RESUMEN TOTAL'!B25 -> CEN03 | C23: ='RESUMEN TOTAL'!D25 -> San Martin y Sallares | D23: ='RESUMEN TOTAL'!E25 -> Domo | E23: ='RESUMEN TOTAL'!F25 -> Fibra Optica | F23: ='RESUMEN TOTAL'!K25 -> 0 | G23: ='RESUMEN TOTAL'!L25 -> 0 | H23: ='RESUMEN TOTAL'!M25 -> APAGADO | I23: ='RESUMEN TOTAL'!N25 -> 0 | J23: ='RESUMEN TOTAL'!O25 -> 0 | K23: ='RESUMEN TOTAL'!P25 -> 0 | L23: ='RESUMEN TOTAL'!Q25 -> 0 | M23: ='RESUMEN TOTAL'!R25 -> 0 | ... AI23: ='RESUMEN TOTAL'!AN25 -> 0
A24: ='RESUMEN TOTAL'!A26 -> CENTRO | B24: ='RESUMEN TOTAL'!B26 -> CEN04 | C24: ='RESUMEN TOTAL'!D26 -> San Martin y Contreras | D24: ='RESUMEN TOTAL'!E26 -> Domo | E24: ='RESUMEN TOTAL'!F26 -> Fibra Optica | F24: ='RESUMEN TOTAL'!K26 -> 0 | G24: ='RESUMEN TOTAL'!L26 -> 0 | H24: ='RESUMEN TOTAL'!M26 -> 0 | I24: ='RESUMEN TOTAL'!N26 -> 0 | J24: ='RESUMEN TOTAL'!O26 -> 0 | K24: ='RESUMEN TOTAL'!P26 -> 0 | L24: ='RESUMEN TOTAL'!Q26 -> 0 | M24: ='RESUMEN TOTAL'!R26 -> 0 | ... AI24: ='RESUMEN TOTAL'!AN26 -> 0
A25: ='RESUMEN TOTAL'!A27 -> CENTRO | B25: ='RESUMEN TOTAL'!B27 -> CEN 05 | C25: ='RESUMEN TOTAL'!D27 -> Bocuzzi e/España y San Martin | D25: ='RESUMEN TOTAL'!E27 -> DOMO | E25: ='RESUMEN TOTAL'!F27 -> Fibra Optica | F25: ='RESUMEN TOTAL'!K27 -> 0 | G25: ='RESUMEN TOTAL'!L27 -> 0 | H25: ='RESUMEN TOTAL'!M27 -> APAGADO | I25: ='RESUMEN TOTAL'!N27 -> 0 | J25: ='RESUMEN TOTAL'!O27 -> 0 | K25: ='RESUMEN TOTAL'!P27 -> 0 | L25: ='RESUMEN TOTAL'!Q27 -> 0 | M25: ='RESUMEN TOTAL'!R27 -> 0 | ... AI25: ='RESUMEN TOTAL'!AN27 -> 0
A26: ='RESUMEN TOTAL'!A28 -> CENTRO | B26: ='RESUMEN TOTAL'!B28 -> CEN06 | C26: ='RESUMEN TOTAL'!D28 -> Monteagudo y A.del Valle | D26: ='RESUMEN TOTAL'!E28 -> Fija | E26: ='RESUMEN TOTAL'!F28 -> Fibra Optica | F26: ='RESUMEN TOTAL'!K28 -> 0 | G26: ='RESUMEN TOTAL'!L28 -> 0 | H26: ='RESUMEN TOTAL'!M28 -> APAGADO | I26: ='RESUMEN TOTAL'!N28 -> 0 | J26: ='RESUMEN TOTAL'!O28 -> 0 | K26: ='RESUMEN TOTAL'!P28 -> 0 | L26: ='RESUMEN TOTAL'!Q28 -> 0 | M26: ='RESUMEN TOTAL'!R28 -> 0 | ... AI26: ='RESUMEN TOTAL'!AN28 -> 0
A27: ='RESUMEN TOTAL'!A29 -> CENTRO | B27: ='RESUMEN TOTAL'!B29 -> CEN07 | C27: ='RESUMEN TOTAL'!D29 -> San Martin y Guemes | D27: ='RESUMEN TOTAL'!E29 -> DOMO | E27: ='RESUMEN TOTAL'!F29 -> Fibra Optica | F27: ='RESUMEN TOTAL'!K29 -> 0 | G27: ='RESUMEN TOTAL'!L29 -> 0 | H27: ='RESUMEN TOTAL'!M29 -> APAGADO | I27: ='RESUMEN TOTAL'!N29 -> 0 | J27: ='RESUMEN TOTAL'!O29 -> 0 | K27: ='RESUMEN TOTAL'!P29 -> 0 | L27: ='RESUMEN TOTAL'!Q29 -> 0 | M27: ='RESUMEN TOTAL'!R29 -> 0 | ... AI27: ='RESUMEN TOTAL'!AN29 -> 0
A28: ='RESUMEN TOTAL'!A30 -> CENTRO | B28: ='RESUMEN TOTAL'!B30 -> CEN08 | C28: ='RESUMEN TOTAL'!D30 -> San Martin y Pte.Peron | D28: ='RESUMEN TOTAL'!E30 -> Domo | E28: ='RESUMEN TOTAL'!F30 -> Fibra Optica | F28: ='RESUMEN TOTAL'!K30 -> 0 | G28: ='RESUMEN TOTAL'!L30 -> 0 | H28: ='RESUMEN TOTAL'!M30 -> 0 | I28: ='RESUMEN TOTAL'!N30 -> 0 | J28: ='RESUMEN TOTAL'!O30 -> 0 | K28: ='RESUMEN TOTAL'!P30 -> 0 | L28: ='RESUMEN TOTAL'!Q30 -> 0 | M28: ='RESUMEN TOTAL'!R30 -> 0 | ... AI28: ='RESUMEN TOTAL'!AN30 -> 0
A29: ='RESUMEN TOTAL'!A31 -> CENTRO | B29: ='RESUMEN TOTAL'!B31 -> CEN09 | C29: ='RESUMEN TOTAL'!D31 -> Chacabuco y 25 de Mayo | D29: ='RESUMEN TOTAL'!E31 -> Domo | E29: ='RESUMEN TOTAL'!F31 -> Fibra Optica | F29: ='RESUMEN TOTAL'!K31 -> 0 | G29: ='RESUMEN TOTAL'!L31 -> 0 | H29: ='RESUMEN TOTAL'!M31 -> 0 | I29: ='RESUMEN TOTAL'!N31 -> 0 | J29: ='RESUMEN TOTAL'!O31 -> 0 | K29: ='RESUMEN TOTAL'!P31 -> 0 | L29: ='RESUMEN TOTAL'!Q31 -> 0 | M29: ='RESUMEN TOTAL'!R31 -> 0 | ... AI29: ='RESUMEN TOTAL'!AN31 -> 0
A30: ='RESUMEN TOTAL'!A32 -> CENTRO | B30: ='RESUMEN TOTAL'!B32 -> CEN10 | C30: ='RESUMEN TOTAL'!D32 -> Monteagudo y Pte. Peron | D30: ='RESUMEN TOTAL'!E32 -> Domo | E30: ='RESUMEN TOTAL'!F32 -> Fibra Optica | F30: ='RESUMEN TOTAL'!K32 -> 0 | G30: ='RESUMEN TOTAL'!L32 -> 0 | H30: ='RESUMEN TOTAL'!M32 -> APAGADO | I30: ='RESUMEN TOTAL'!N32 -> 0 | J30: ='RESUMEN TOTAL'!O32 -> 0 | K30: ='RESUMEN TOTAL'!P32 -> 0 | L30: ='RESUMEN TOTAL'!Q32 -> 0 | M30: ='RESUMEN TOTAL'!R32 -> 0 | ... AI30: ='RESUMEN TOTAL'!AN32 -> 0
A31: ='RESUMEN TOTAL'!A33 -> CENTRO | B31: ='RESUMEN TOTAL'!B33 -> CEN11 | C31: ='RESUMEN TOTAL'!D33 -> Monteagudo y Bocuzzi | D31: ='RESUMEN TOTAL'!E33 -> Domo | E31: ='RESUMEN TOTAL'!F33 -> Fibra Optica | F31: ='RESUMEN TOTAL'!K33 -> 0 | G31: ='RESUMEN TOTAL'!L33 -> 0 | H31: ='RESUMEN TOTAL'!M33 -> 0 | I31: ='RESUMEN TOTAL'!N33 -> 0 | J31: ='RESUMEN TOTAL'!O33 -> 0 | K31: ='RESUMEN TOTAL'!P33 -> 0 | L31: ='RESUMEN TOTAL'!Q33 -> 0 | M31: ='RESUMEN TOTAL'!R33 -> 0 | ... AI31: ='RESUMEN TOTAL'!AN33 -> 0
A32: ='RESUMEN TOTAL'!A34 -> CENTRO | B32: ='RESUMEN TOTAL'!B34 -> CEN 12 | C32: ='RESUMEN TOTAL'!D34 -> Monteagudo y Mitre | D32: ='RESUMEN TOTAL'!E34 -> Domo | E32: ='RESUMEN TOTAL'!F34 -> Fibra Optica | F32: ='RESUMEN TOTAL'!K34 -> 0 | G32: ='RESUMEN TOTAL'!L34 -> 0 | H32: ='RESUMEN TOTAL'!M34 -> 0 | I32: ='RESUMEN TOTAL'!N34 -> APAGADO | J32: ='RESUMEN TOTAL'!O34 -> APAGADO | K32: ='RESUMEN TOTAL'!P34 -> 0 | L32: ='RESUMEN TOTAL'!Q34 -> 0 | M32: ='RESUMEN TOTAL'!R34 -> 0 | ... AI32: ='RESUMEN TOTAL'!AN34 -> APAGADO
... A260: ='RESUMEN TOTAL'!A262 -> RICARDO ROJAS | B260: ='RESUMEN TOTAL'!B262 -> RRJ 11 | C260: ='RESUMEN TOTAL'!D262 -> LUGONES Y OBLIGADO | D260: ='RESUMEN TOTAL'!E262 -> Domo | E260: ='RESUMEN TOTAL'!F262 -> Fibra Optica | F260: ='RESUMEN TOTAL'!K262 -> 0 | G260: ='RESUMEN TOTAL'!L262 -> 0 | H260: ='RESUMEN TOTAL'!M262 -> 0 | I260: ='RESUMEN TOTAL'!N262 -> 0 | J260: ='RESUMEN TOTAL'!O262 -> 0 | K260: ='RESUMEN TOTAL'!P262 -> 0 | L260: ='RESUMEN TOTAL'!Q262 -> 0 | M260: ='RESUMEN TOTAL'!R262 -> 0 | ... AI260: ='RESUMEN TOTAL'!AN262 -> 0
A261: ='RESUMEN TOTAL'!A264 -> SANTA ANA | B261: ='RESUMEN TOTAL'!B264 -> SAN 02 | C261: ='RESUMEN TOTAL'!D264 -> HUDSON Y SUIPACHA | D261: ='RESUMEN TOTAL'!E264 -> Fija 2 | E261: ='RESUMEN TOTAL'!F264 -> Fibra Optica | F261: ='RESUMEN TOTAL'!K264 -> 0 | G261: ='RESUMEN TOTAL'!L264 -> 0 | H261: ='RESUMEN TOTAL'!M264 -> 0 | I261: ='RESUMEN TOTAL'!N264 -> 0 | J261: ='RESUMEN TOTAL'!O264 -> 0 | K261: ='RESUMEN TOTAL'!P264 -> 0 | L261: ='RESUMEN TOTAL'!Q264 -> 0 | M261: ='RESUMEN TOTAL'!R264 -> 0 | ... AI261: ='RESUMEN TOTAL'!AN264 -> 0
A262: ='RESUMEN TOTAL'!A265 -> SANTA ANA | B262: ='RESUMEN TOTAL'!B265 -> SAN01 | C262: ='RESUMEN TOTAL'!D265 -> HUDSON Y SUIPACHA | D262: ='RESUMEN TOTAL'!E265 -> Fija 1 | E262: ='RESUMEN TOTAL'!F265 -> Fibra Optica | F262: ='RESUMEN TOTAL'!K265 -> 0 | G262: ='RESUMEN TOTAL'!L265 -> 0 | H262: ='RESUMEN TOTAL'!M265 -> 0 | I262: ='RESUMEN TOTAL'!N265 -> 0 | J262: ='RESUMEN TOTAL'!O265 -> 0 | K262: ='RESUMEN TOTAL'!P265 -> 0 | L262: ='RESUMEN TOTAL'!Q265 -> 0 | M262: ='RESUMEN TOTAL'!R265 -> 0 | ... AI262: ='RESUMEN TOTAL'!AN265 -> 0
A263: ='RESUMEN TOTAL'!A266 -> PRESIDENTE SARMIENTO | B263: ='RESUMEN TOTAL'!B266 -> SAR01 | C263: ='RESUMEN TOTAL'!D266 -> Storni Y Sanchez de Loria | D263: ='RESUMEN TOTAL'!E266 -> Domo | E263: ='RESUMEN TOTAL'!F266 -> Fibra Optica | F263: ='RESUMEN TOTAL'!K266 -> 0 | G263: ='RESUMEN TOTAL'!L266 -> 0 | H263: ='RESUMEN TOTAL'!M266 -> 0 | I263: ='RESUMEN TOTAL'!N266 -> 0 | J263: ='RESUMEN TOTAL'!O266 -> 0 | K263: ='RESUMEN TOTAL'!P266 -> 0 | L263: ='RESUMEN TOTAL'!Q266 -> 0 | M263: ='RESUMEN TOTAL'!R266 -> 0 | ... AI263: ='RESUMEN TOTAL'!AN266 -> 0
A264: ='RESUMEN TOTAL'!A267 -> PRESIDENTE SARMIENTO | B264: ='RESUMEN TOTAL'!B267 -> SAR 02 (fija 1) | C264: ='RESUMEN TOTAL'!D267 -> DARDO ROCHA Y GABRIELA MISTRAL | D264: ='RESUMEN TOTAL'!E267 -> Fija | E264: ='RESUMEN TOTAL'!F267 -> Fibra Optica | F264: ='RESUMEN TOTAL'!K267 -> 0 | G264: ='RESUMEN TOTAL'!L267 -> 0 | H264: ='RESUMEN TOTAL'!M267 -> 0 | I264: ='RESUMEN TOTAL'!N267 -> 0 | J264: ='RESUMEN TOTAL'!O267 -> 0 | K264: ='RESUMEN TOTAL'!P267 -> 0 | L264: ='RESUMEN TOTAL'!Q267 -> 0 | M264: ='RESUMEN TOTAL'!R267 -> 0 | ... AI264: ='RESUMEN TOTAL'!AN267 -> 0
A265: ='RESUMEN TOTAL'!A268 -> PRESIDENTE SARMIENTO | B265: ='RESUMEN TOTAL'!B268 -> SAR 03 (fija 2) | C265: ='RESUMEN TOTAL'!D268 -> DARDO ROCHA Y GABRIELA MISTRAL | D265: ='RESUMEN TOTAL'!E268 -> Fija | E265: ='RESUMEN TOTAL'!F268 -> Fibra Optica | F265: ='RESUMEN TOTAL'!K268 -> 0 | G265: ='RESUMEN TOTAL'!L268 -> 0 | H265: ='RESUMEN TOTAL'!M268 -> APAGADO | I265: ='RESUMEN TOTAL'!N268 -> 0 | J265: ='RESUMEN TOTAL'!O268 -> 0 | K265: ='RESUMEN TOTAL'!P268 -> 0 | L265: ='RESUMEN TOTAL'!Q268 -> 0 | M265: ='RESUMEN TOTAL'!R268 -> 0 | ... AI265: ='RESUMEN TOTAL'!AN268 -> 0
A266: ='RESUMEN TOTAL'!A269 -> PRESIDENTE SARMIENTO | B266: ='RESUMEN TOTAL'!B269 -> SAR 04 | C266: ='RESUMEN TOTAL'!D269 -> MONTES DE OCA Y ALVARADO | D266: ='RESUMEN TOTAL'!E269 -> Domo | E266: ='RESUMEN TOTAL'!F269 -> Fibra Optica | F266: ='RESUMEN TOTAL'!K269 -> 0 | G266: ='RESUMEN TOTAL'!L269 -> 0 | H266: ='RESUMEN TOTAL'!M269 -> APAGADO | I266: ='RESUMEN TOTAL'!N269 -> 0 | J266: ='RESUMEN TOTAL'!O269 -> 0 | K266: ='RESUMEN TOTAL'!P269 -> 0 | L266: ='RESUMEN TOTAL'!Q269 -> 0 | M266: ='RESUMEN TOTAL'!R269 -> 0 | ... AI266: ='RESUMEN TOTAL'!AN269 -> 0
A267: ='RESUMEN TOTAL'!A270 -> PRESIDENTE SARMIENTO | B267: ='RESUMEN TOTAL'!B270 -> SAR 05 | C267: ='RESUMEN TOTAL'!D270 -> ALVARADO Y ROCHA | D267: ='RESUMEN TOTAL'!E270 -> Domo | E267: ='RESUMEN TOTAL'!F270 -> Fibra Optica | F267: ='RESUMEN TOTAL'!K270 -> 0 | G267: ='RESUMEN TOTAL'!L270 -> 0 | H267: ='RESUMEN TOTAL'!M270 -> APAGADO | I267: ='RESUMEN TOTAL'!N270 -> 0 | J267: ='RESUMEN TOTAL'!O270 -> 0 | K267: ='RESUMEN TOTAL'!P270 -> 0 | L267: ='RESUMEN TOTAL'!Q270 -> 0 | M267: ='RESUMEN TOTAL'!R270 -> 0 | ... AI267: ='RESUMEN TOTAL'!AN270 -> 0
A268: ='RESUMEN TOTAL'!A271 -> PRESIDENTE SARMIENTO | B268: ='RESUMEN TOTAL'!B271 -> SAR 06 | C268: ='RESUMEN TOTAL'!D271 -> Necochea y Lorenzini | D268: ='RESUMEN TOTAL'!E271 -> Fija | E268: ='RESUMEN TOTAL'!F271 -> Fibra Optica | F268: ='RESUMEN TOTAL'!K271 -> 0 | G268: ='RESUMEN TOTAL'!L271 -> 0 | H268: ='RESUMEN TOTAL'!M271 -> 0 | I268: ='RESUMEN TOTAL'!N271 -> 0 | J268: ='RESUMEN TOTAL'!O271 -> 0 | K268: ='RESUMEN TOTAL'!P271 -> 0 | L268: ='RESUMEN TOTAL'!Q271 -> 0 | M268: ='RESUMEN TOTAL'!R271 -> 0 | ... AI268: ='RESUMEN TOTAL'!AN271 -> 0
A269: ='RESUMEN TOTAL'!A272 -> PRESIDENTE SARMIENTO | B269: ='RESUMEN TOTAL'!B272 -> SAR 07 | C269: ='RESUMEN TOTAL'!D272 -> Necochea y Lorenzini | D269: ='RESUMEN TOTAL'!E272 -> Fija | E269: ='RESUMEN TOTAL'!F272 -> Fibra Optica | F269: ='RESUMEN TOTAL'!K272 -> 0 | G269: ='RESUMEN TOTAL'!L272 -> 0 | H269: ='RESUMEN TOTAL'!M272 -> 0 | I269: ='RESUMEN TOTAL'!N272 -> 0 | J269: ='RESUMEN TOTAL'!O272 -> 0 | K269: ='RESUMEN TOTAL'!P272 -> 0 | L269: ='RESUMEN TOTAL'!Q272 -> 0 | M269: ='RESUMEN TOTAL'!R272 -> 0 | ... AI269: ='RESUMEN TOTAL'!AN272 -> 0
A270: ='RESUMEN TOTAL'!A273 -> PRESIDENTE SARMIENTO | B270: ='RESUMEN TOTAL'!B273 -> SAR 08 | C270: ='RESUMEN TOTAL'!D273 -> Necochea y Montes de Oca | D270: ='RESUMEN TOTAL'!E273 -> Fija | E270: ='RESUMEN TOTAL'!F273 -> Fibra Optica | F270: ='RESUMEN TOTAL'!K273 -> 0 | G270: ='RESUMEN TOTAL'!L273 -> 0 | H270: ='RESUMEN TOTAL'!M273 -> APAGADO | I270: ='RESUMEN TOTAL'!N273 -> 0 | J270: ='RESUMEN TOTAL'!O273 -> 0 | K270: ='RESUMEN TOTAL'!P273 -> 0 | L270: ='RESUMEN TOTAL'!Q273 -> 0 | M270: ='RESUMEN TOTAL'!R273 -> 0 | ... AI270: ='RESUMEN TOTAL'!AN273 -> 0
A271: ='RESUMEN TOTAL'!A274 -> PRESIDENTE SARMIENTO | B271: ='RESUMEN TOTAL'!B274 -> SAR 09 | C271: ='RESUMEN TOTAL'!D274 -> Necochea y Montes de Oca | D271: ='RESUMEN TOTAL'!E274 -> Fija | E271: ='RESUMEN TOTAL'!F274 -> Fibra Optica | F271: ='RESUMEN TOTAL'!K274 -> 0 | G271: ='RESUMEN TOTAL'!L274 -> 0 | H271: ='RESUMEN TOTAL'!M274 -> APAGADO | I271: ='RESUMEN TOTAL'!N274 -> 0 | J271: ='RESUMEN TOTAL'!O274 -> 0 | K271: ='RESUMEN TOTAL'!P274 -> 0 | L271: ='RESUMEN TOTAL'!Q274 -> 0 | M271: ='RESUMEN TOTAL'!R274 -> 0 | ... AI271: ='RESUMEN TOTAL'!AN274 -> 0
A272: ='RESUMEN TOTAL'!A275 -> SAN EDUARDO | B272: ='RESUMEN TOTAL'!B275 -> SEDU01 | C272: ='RESUMEN TOTAL'!D275 -> San Martin y Sperandio | D272: ='RESUMEN TOTAL'!E275 -> Domo | E272: ='RESUMEN TOTAL'!F275 -> Fibra Optica | F272: ='RESUMEN TOTAL'!K275 -> 0 | G272: ='RESUMEN TOTAL'!L275 -> 0 | H272: ='RESUMEN TOTAL'!M275 -> APAGADO | I272: ='RESUMEN TOTAL'!N275 -> 0 | J272: ='RESUMEN TOTAL'!O275 -> 0 | K272: ='RESUMEN TOTAL'!P275 -> 0 | L272: ='RESUMEN TOTAL'!Q275 -> 0 | M272: ='RESUMEN TOTAL'!R275 -> 0 | ... AI272: ='RESUMEN TOTAL'!AN275 -> 0
... A442: ='RESUMEN TOTAL'!A445 -> 0 | B442: ='RESUMEN TOTAL'!B445 -> 0 | C442: ='RESUMEN TOTAL'!D445 -> 0 | D442: ='RESUMEN TOTAL'!E445 -> 0 | E442: ='RESUMEN TOTAL'!F445 -> 0 | F442: ='RESUMEN TOTAL'!K445 -> 0 | G442: ='RESUMEN TOTAL'!L445 -> 0 | H442: ='RESUMEN TOTAL'!M445 -> 0 | I442: ='RESUMEN TOTAL'!N445 -> 0 | J442: ='RESUMEN TOTAL'!O445 -> 0 | K442: ='RESUMEN TOTAL'!P445 -> 0 | L442: ='RESUMEN TOTAL'!Q445 -> 0 | M442: ='RESUMEN TOTAL'!R445 -> 0 | ... AI442: ='RESUMEN TOTAL'!AN445 -> 0

Sheet APAGADOS
E1: APAGADOS | F1: =COUNTIF(F3:F400, "APAGADO") -> 39 | G1: =COUNTIF(G3:G400, "APAGADO") -> 39 | H1: =COUNTIF(H3:H400, "APAGADO") -> 157 | I1: =COUNTIF(I3:I400, "APAGADO") -> 43 | J1: =COUNTIF(J3:J400, "APAGADO") -> 37 | K1: =COUNTIF(K3:K400, "APAGADO") -> 0 | L1: =COUNTIF(L3:L400, "APAGADO") -> 35 | M1: =COUNTIF(M3:M400, "APAGADO") -> 0 | ... AI1: =COUNTIF(AI3:AI400, "APAGADO") -> 32
A2: =ESTADISTICA!A1 -> Barrio | B2: =ESTADISTICA!B1 -> [Denominacion] | C2: =ESTADISTICA!C1 -> [Ubicacion] | D2: =ESTADISTICA!D1 -> [Tipo de Camara] | E2: =ESTADISTICA!E1 -> [Tipo de Conexion] | F2: =ESTADISTICA!F1 -> 44835 | G2: =ESTADISTICA!G1 -> 44836 | H2: =ESTADISTICA!H1 -> 44837 | ... AI2: =ESTADISTICA!AI1 -> 44864
A3: =ESTADISTICA!A2 -> ALTAMIRA | B3: =ESTADISTICA!B2 -> ALT01 | C3: =ESTADISTICA!C2 -> Calchaqui y Sgto. Cabral | D3: =ESTADISTICA!D2 -> Domo | E3: =ESTADISTICA!E2 -> Fibra Optica | F3: =ESTADISTICA!F2 -> 0 | G3: =ESTADISTICA!G2 -> 0 | H3: =ESTADISTICA!H2 -> APAGADO | ... AI3: =ESTADISTICA!AI2 -> 0
A4: =ESTADISTICA!A3 -> ALTAMIRA | B4: =ESTADISTICA!B3 -> ALT02 | C4: =ESTADISTICA!C3 -> Calchaqui y Lope de Vega | D4: =ESTADISTICA!D3 -> Domo | E4: =ESTADISTICA!E3 -> PTO A FO | F4: =ESTADISTICA!F3 -> 0 | G4: =ESTADISTICA!G3 -> 0 | H4: =ESTADISTICA!H3 -> APAGADO | ... AI4: =ESTADISTICA!AI3 -> 0
A5: =ESTADISTICA!A4 -> ALTAMIRA | B5: =ESTADISTICA!B4 -> ALT 03 | C5: =ESTADISTICA!C4 -> Bombero Galarza y Necochea | D5: =ESTADISTICA!D4 -> Domo | E5: =ESTADISTICA!E4 -> FIBRA OPTICA | F5: =ESTADISTICA!F4 -> 0 | G5: =ESTADISTICA!G4 -> 0 | H5: =ESTADISTICA!H4 -> 0 | ... AI5: =ESTADISTICA!AI4 -> 0
A6: =ESTADISTICA!A5 -> ALTAMIRA | B6: =ESTADISTICA!B5 -> ALT 04 | C6: =ESTADISTICA!C5 -> Francia y Necochea | D6: =ESTADISTICA!D5 -> Domo | E6: =ESTADISTICA!E5 -> FIBRA OPTICA | F6: =ESTADISTICA!F5 -> APAGADO | G6: =ESTADISTICA!G5 -> APAGADO | H6: =ESTADISTICA!H5 -> APAGADO | ... AI6: =ESTADISTICA!AI5 -> 0
A7: =ESTADISTICA!A6 -> ALTAMIRA | B7: =ESTADISTICA!B6 -> ALT05 | C7: =ESTADISTICA!C6 -> Av. Calchaqui y Bombero Galarza | D7: =ESTADISTICA!D6 -> Domo | E7: =ESTADISTICA!E6 -> PTO A FO | F7: =ESTADISTICA!F6 -> APAGADO | G7: =ESTADISTICA!G6 -> APAGADO | H7: =ESTADISTICA!H6 -> APAGADO | ... AI7: =ESTADISTICA!AI6 -> 0
A8: =ESTADISTICA!A7 -> ALTAMIRA | B8: =ESTADISTICA!B7 -> ALT 06 | C8: =ESTADISTICA!C7 -> LOPE DE VEGA Y NECOCHEA | D8: =ESTADISTICA!D7 -> Domo | E8: =ESTADISTICA!E7 -> PTO A FO | F8: =ESTADISTICA!F7 -> 0 | G8: =ESTADISTICA!G7 -> 0 | H8: =ESTADISTICA!H7 -> APAGADO | ... AI8: =ESTADISTICA!AI7 -> 0
A9: =ESTADISTICA!A8 -> ALTAMIRA | B9: =ESTADISTICA!B8 -> ALT07 | C9: =ESTADISTICA!C8 -> AV. CALCHAQUI Y AV. DEL TRABAJO | D9: =ESTADISTICA!D8 -> DOMO | E9: =ESTADISTICA!E8 -> PTO A FO | F9: =ESTADISTICA!F8 -> 0 | G9: =ESTADISTICA!G8 -> 0 | H9: =ESTADISTICA!H8 -> 0 | ... AI9: =ESTADISTICA!AI8 -> 0
A10: =ESTADISTICA!A9 -> ALTAMIRA | B10: =ESTADISTICA!B9 -> ALT 08 | C10: =ESTADISTICA!C9 -> HUMAITA Y NECOCHEA | D10: =ESTADISTICA!D9 -> DOMO | E10: =ESTADISTICA!E9 -> Fibra Optica | F10: =ESTADISTICA!F9 -> 0 | G10: =ESTADISTICA!G9 -> 0 | H10: =ESTADISTICA!H9 -> 0 | ... AI10: =ESTADISTICA!AI9 -> 0
A11: =ESTADISTICA!A10 -> ALTAMIRA | B11: =ESTADISTICA!B10 -> ALT 09 | C11: =ESTADISTICA!C10 -> NECOCHEA Y CURUPAITY | D11: =ESTADISTICA!D10 -> DOMO | E11: =ESTADISTICA!E10 -> Fibra Optica | F11: =ESTADISTICA!F10 -> 0 | G11: =ESTADISTICA!G10 -> 0 | H11: =ESTADISTICA!H10 -> 0 | ... AI11: =ESTADISTICA!AI10 -> 0
A12: =ESTADISTICA!A11 -> ALTAMIRA | B12: =ESTADISTICA!B11 -> ALT 10 | C12: =ESTADISTICA!C11 -> Calchaqui y Francia | D12: =ESTADISTICA!D11 -> Domo | E12: =ESTADISTICA!E11 -> Radio | F12: =ESTADISTICA!F11 -> APAGADO | G12: =ESTADISTICA!G11 -> APAGADO | H12: =ESTADISTICA!H11 -> APAGADO | ... AI12: =ESTADISTICA!AI11 -> 0
A13: =ESTADISTICA!A12 -> AGUSTIN RAMIREZ | B13: =ESTADISTICA!B12 -> ARA 01 | C13: =ESTADISTICA!C12 -> Malambo y Tranquera | D13: =ESTADISTICA!D12 -> Domo | E13: =ESTADISTICA!E12 -> FIBRA OPTICA | F13: =ESTADISTICA!F12 -> 0 | G13: =ESTADISTICA!G12 -> 0 | H13: =ESTADISTICA!H12 -> APAGADO | ... AI13: =ESTADISTICA!AI12 -> 0
... A401: =ESTADISTICA!A400 -> VILLA DEL PLATA | B401: =ESTADISTICA!B400 -> VDPL03 | C401: =ESTADISTICA!C400 -> Neuquen y Alvarado | D401: =ESTADISTICA!D400 -> Domo | E401: =ESTADISTICA!E400 -> Radio | F401: =ESTADISTICA!F400 -> 0 | G401: =ESTADISTICA!G400 -> 0 | H401: =ESTADISTICA!H400 -> 0 | ... AI401: =ESTADISTICA!AI400 -> 0

Sheet APAGADOS FIBRA
C1: TOTAL FIBRA | D1: =COUNTIFS(E4:E400,"=Fibra Optica") -> 268
E2: APAGADOS | F2: =COUNTIFS(F4:F400, "=APAGADO",E4:E400,"=Fibra Optica") -> 32 | G2: =COUNTIFS(G4:G400, "=APAGADO",E4:E400,"=Fibra Optica") -> 34 | H2: =COUNTIFS(H4:H400, "=APAGADO",E4:E400,"=Fibra Optica") -> 99 | I2: =COUNTIFS(I4:I400, "=APAGADO",E4:E400,"=Fibra Optica") -> 34 | J2: =COUNTIFS(J4:J400, "=APAGADO",E4:E400,"=Fibra Optica") -> 31 | K2: =COUNTIFS(K4:K400, "=APAGADO",E4:E400,"=Fibra Optica") -> 0 | L2: =COUNTIFS(L4:L400, "=APAGADO",E4:E400,"=Fibra Optica") -> 31 | M2: =COUNTIFS(M4:M400, "=APAGADO",E4:E400,"=Fibra Optica") -> 0 | N2: =COUNTIFS(N4:N400, "=APAGADO",E4:E400,"=Fibra Optica") -> 38 | O2: =COUNTIFS(O4:O400, "=APAGADO",E4:E400,"=Fibra Optica") -> 37 | P2: =COUNTIFS(P4:P400, "=APAGADO",E4:E400,"=Fibra Optica") -> 37 | Q2: =COUNTIFS(Q4:Q400, "=APAGADO",E4:E400,"=Fibra Optica") -> 30 | R2: =COUNTIFS(R4:R400, "=APAGADO",E4:E400,"=Fibra Optica") -> 39 | S2: =COUNTIFS(S4:S400, "=APAGADO",E4:E400,"=Fibra Optica") -> 26 | T2: =COUNTIFS(T4:T400, "=APAGADO",E4:E400,"=Fibra Optica") -> 25 | U2: =COUNTIFS(U4:U400, "=APAGADO",E4:E400,"=Fibra Optica") -> 47 | V2: =COUNTIFS(V4:V400, "=APAGADO",E4:E400,"=Fibra Optica") -> 0 | W2: =COUNTIFS(W4:W400, "=APAGADO",E4:E400,"=Fibra Optica") -> 40 | X2: =COUNTIFS(X4:X400, "=APAGADO",E4:E400,"=Fibra Optica") -> 78 | Y2: =COUNTIFS(Y4:Y400, "=APAGADO",E4:E400,"=Fibra Optica") -> 38 | Z2: =COUNTIFS(Z4:Z400, "=APAGADO",E4:E400,"=Fibra Optica") -> 33 | AA2: =COUNTIFS(AA4:AA400, "=APAGADO",E4:E400,"=Fibra Optica") -> 32 | AB2: =COUNTIFS(AB4:AB400, "=APAGADO",E4:E400,"=Fibra Optica") -> 40 | AC2: =COUNTIFS(AC4:AC400, "=APAGADO",E4:E400,"=Fibra Optica") -> 31 | AD2: =COUNTIFS(AD4:AD400, "=APAGADO",E4:E400,"=Fibra Optica") -> 30 | AE2: =COUNTIFS(AE4:AE500, "=APAGADO",E4:E500,"=Fibra Optica") -> 34 | AF2: =COUNTIFS(AF4:AF500, "=APAGADO",E4:E500,"=Fibra Optica") -> 39 | AG2: =COUNTIFS(AG4:AG500, "=APAGADO",E4:E500,"=Fibra Optica") -> 42 | AH2: =COUNTIFS(AH4:AH400, "=APAGADO",E4:E400,"=Fibra Optica") -> 25 | AI2: =COUNTIFS(AI4:AI400, "=APAGADO",E4:E400,"=Fibra Optica") -> 27
A3: =ESTADISTICA!A1 -> Barrio | B3: =ESTADISTICA!B1 -> [Denominacion] | C3: =ESTADISTICA!C1 -> [Ubicacion] | D3: =ESTADISTICA!D1 -> [Tipo de Camara] | E3: =ESTADISTICA!E1 -> [Tipo de Conexion] | F3: =ESTADISTICA!F1 -> 44835 | G3: =ESTADISTICA!G1 -> 44836 | H3: =ESTADISTICA!H1 -> 44837 | ... AI3: =ESTADISTICA!AI1 -> 44864
A4: =ESTADISTICA!A2 -> ALTAMIRA | B4: =ESTADISTICA!B2 -> ALT01 | C4: =ESTADISTICA!C2 -> Calchaqui y Sgto. Cabral | D4: =ESTADISTICA!D2 -> Domo | E4: =ESTADISTICA!E2 -> Fibra Optica | F4: =ESTADISTICA!F2 -> 0 | G4: =ESTADISTICA!G2 -> 0 | H4: =ESTADISTICA!H2 -> APAGADO | ... AI4: =ESTADISTICA!AI2 -> 0
A5: =ESTADISTICA!A3 -> ALTAMIRA | B5: =ESTADISTICA!B3 -> ALT02 | C5: =ESTADISTICA!C3 -> Calchaqui y Lope de Vega | D5: =ESTADISTICA!D3 -> Domo | E5: =ESTADISTICA!E3 -> PTO A FO | F5: =ESTADISTICA!F3 -> 0 | G5: =ESTADISTICA!G3 -> 0 | H5: =ESTADISTICA!H3 -> APAGADO | ... AI5: =ESTADISTICA!AI3 -> 0
A6: =ESTADISTICA!A4 -> ALTAMIRA | B6: =ESTADISTICA!B4 -> ALT 03 | C6: =ESTADISTICA!C4 -> Bombero Galarza y Necochea | D6: =ESTADISTICA!D4 -> Domo | E6: =ESTADISTICA!E4 -> FIBRA OPTICA | F6: =ESTADISTICA!F4 -> 0 | G6: =ESTADISTICA!G4 -> 0 | H6: =ESTADISTICA!H4 -> 0 | ... AI6: =ESTADISTICA!AI4 -> 0
A7: =ESTADISTICA!A5 -> ALTAMIRA | B7: =ESTADISTICA!B5 -> ALT 04 | C7: =ESTADISTICA!C5 -> Francia y Necochea | D7: =ESTADISTICA!D5 -> Domo | E7: =ESTADISTICA!E5 -> FIBRA OPTICA | F7: =ESTADISTICA!F5 -> APAGADO | G7: =ESTADISTICA!G5 -> APAGADO | H7: =ESTADISTICA!H5 -> APAGADO | ... AI7: =ESTADISTICA!AI5 -> 0
A8: =ESTADISTICA!A6 -> ALTAMIRA | B8: =ESTADISTICA!B6 -> ALT05 | C8: =ESTADISTICA!C6 -> Av. Calchaqui y Bombero Galarza | D8: =ESTADISTICA!D6 -> Domo | E8: =ESTADISTICA!E6 -> PTO A FO | F8: =ESTADISTICA!F6 -> APAGADO | G8: =ESTADISTICA!G6 -> APAGADO | H8: =ESTADISTICA!H6 -> APAGADO | ... AI8: =ESTADISTICA!AI6 -> 0
A9: =ESTADISTICA!A7 -> ALTAMIRA | B9: =ESTADISTICA!B7 -> ALT 06 | C9: =ESTADISTICA!C7 -> LOPE DE VEGA Y NECOCHEA | D9: =ESTADISTICA!D7 -> Domo | E9: =ESTADISTICA!E7 -> PTO A FO | F9: =ESTADISTICA!F7 -> 0 | G9: =ESTADISTICA!G7 -> 0 | H9: =ESTADISTICA!H7 -> APAGADO | ... AI9: =ESTADISTICA!AI7 -> 0
A10: =ESTADISTICA!A8 -> ALTAMIRA | B10: =ESTADISTICA!B8 -> ALT07 | C10: =ESTADISTICA!C8 -> AV. CALCHAQUI Y AV. DEL TRABAJO | D10: =ESTADISTICA!D8 -> DOMO | E10: =ESTADISTICA!E8 -> PTO A FO | F10: =ESTADISTICA!F8 -> 0 | G10: =ESTADISTICA!G8 -> 0 | H10: =ESTADISTICA!H8 -> 0 | ... AI10: =ESTADISTICA!AI8 -> 0
A11: =ESTADISTICA!A9 -> ALTAMIRA | B11: =ESTADISTICA!B9 -> ALT 08 | C11: =ESTADISTICA!C9 -> HUMAITA Y NECOCHEA | D11: =ESTADISTICA!D9 -> DOMO | E11: =ESTADISTICA!E9 -> Fibra Optica | F11: =ESTADISTICA!F9 -> 0 | G11: =ESTADISTICA!G9 -> 0 | H11: =ESTADISTICA!H9 -> 0 | ... AI11: =ESTADISTICA!AI9 -> 0
A12: =ESTADISTICA!A10 -> ALTAMIRA | B12: =ESTADISTICA!B10 -> ALT 09 | C12: =ESTADISTICA!C10 -> NECOCHEA Y CURUPAITY | D12: =ESTADISTICA!D10 -> DOMO | E12: =ESTADISTICA!E10 -> Fibra Optica | F12: =ESTADISTICA!F10 -> 0 | G12: =ESTADISTICA!G10 -> 0 | H12: =ESTADISTICA!H10 -> 0 | ... AI12: =ESTADISTICA!AI10 -> 0
A13: =ESTADISTICA!A11 -> ALTAMIRA | B13: =ESTADISTICA!B11 -> ALT 10 | C13: =ESTADISTICA!C11 -> Calchaqui y Francia | D13: =ESTADISTICA!D11 -> Domo | E13: =ESTADISTICA!E11 -> Radio | F13: =ESTADISTICA!F11 -> APAGADO | G13: =ESTADISTICA!G11 -> APAGADO | H13: =ESTADISTICA!H11 -> APAGADO | ... AI13: =ESTADISTICA!AI11 -> 0
A14: =ESTADISTICA!A12 -> AGUSTIN RAMIREZ | B14: =ESTADISTICA!B12 -> ARA 01 | C14: =ESTADISTICA!C12 -> Malambo y Tranquera | D14: =ESTADISTICA!D12 -> Domo | E14: =ESTADISTICA!E12 -> FIBRA OPTICA | F14: =ESTADISTICA!F12 -> 0 | G14: =ESTADISTICA!G12 -> 0 | H14: =ESTADISTICA!H12 -> APAGADO | ... AI14: =ESTADISTICA!AI12 -> 0
... A435: =ESTADISTICA!A433 -> 0 | B435: =ESTADISTICA!B433 -> 0 | C435: =ESTADISTICA!C433 -> 0 | D435: =ESTADISTICA!D433 -> 0 | E435: =ESTADISTICA!E433 -> 0 | F435: =ESTADISTICA!F433 -> 0 | G435: =ESTADISTICA!G433 -> 0 | H435: =ESTADISTICA!H433 -> 0 | ... AI435: =ESTADISTICA!AI433 -> 0

Sheet APAGADOS ANTENA
C1: TOTAL PTO A FO
E2: APAGADOS | F2: =COUNTIFS(F4:F400, "=APAGADO",E4:E400,"=PTO A FO") -> 2 | G2: =COUNTIFS(G4:G400, "=APAGADO",E4:E400,"=PTO A FO") -> 3 | H2: =COUNTIFS(H4:H400, "=APAGADO",E4:E400,"=PTO A FO") -> 16 | I2: =COUNTIFS(I4:I400, "=APAGADO",E4:E400,"=PTO A FO") -> 4 | J2: =COUNTIFS(J4:J400, "=APAGADO",E4:E400,"=PTO A FO") -> 3 | K2: =COUNTIFS(K4:K400, "=APAGADO",E4:E400,"=PTO A FO") -> 0 | L2: =COUNTIFS(L4:L400, "=APAGADO",E4:E400,"=PTO A FO") -> 3 | M2: =COUNTIFS(M4:M400, "=APAGADO",E4:E400,"=PTO A FO") -> 0 | N2: =COUNTIFS(N4:N400, "=APAGADO",E4:E400,"=PTO A FO") -> 4 | O2: =COUNTIFS(O4:O500, "=APAGADO",E4:E500,"=PTO A FO") -> 5 | P2: =COUNTIFS(P4:P400, "=APAGADO",E4:E400,"=PTO A FO") -> 3 | Q2: =COUNTIFS(Q4:Q400, "=APAGADO",E4:E400,"=PTO A FO") -> 3 | R2: =COUNTIFS(R4:R400, "=APAGADO",E4:E400,"=PTO A FO") -> 3 | S2: =COUNTIFS(S4:S400, "=APAGADO",E4:E400,"=PTO A FO") -> 3 | T2: =COUNTIFS(T4:T400, "=APAGADO",E4:E400,"=PTO A FO") -> 4 | U2: =COUNTIFS(U4:U400, "=APAGADO",E4:E400,"=PTO A FO") -> 6 | V2: =COUNTIFS(V4:V400, "=APAGADO",E4:E400,"=PTO A FO") -> 0 | W2: =COUNTIFS(W4:W400, "=APAGADO",E4:E400,"=PTO A FO") -> 2 | X2: =COUNTIFS(X4:X400, "=APAGADO",E4:E400,"=PTO A FO") -> 11 | Y2: =COUNTIFS(Y4:Y400, "=APAGADO",E4:E400,"=PTO A FO") -> 3 | Z2: =COUNTIFS(Z4:Z400, "=APAGADO",E4:E400,"=PTO A FO") -> 3 | AA2: =COUNTIFS(AA4:AA400, "=APAGADO",E4:E400,"=PTO A FO") -> 5 | AB2: =COUNTIFS(AB4:AB400, "=APAGADO",E4:E400,"=PTO A FO") -> 5 | AC2: =COUNTIFS(AC4:AC400, "=APAGADO",E4:E400,"=PTO A FO") -> 3 | AD2: =COUNTIFS(AD4:AD400, "=APAGADO",E4:E400,"=PTO A FO") -> 3 | AE2: =COUNTIFS(AE4:AE500, "=APAGADO",E4:E500,"=PTO A FO") -> 3 | AF2: =COUNTIFS(AF4:AF500, "=APAGADO",E4:E500,"=PTO A FO") -> 5 | AG2: =COUNTIFS(AG4:AG500, "=APAGADO",E4:E500,"=PTO A FO") -> 4 | AH2: =COUNTIFS(AH4:AH400, "=APAGADO",E4:E400,"=PTO A FO") -> 1 | AI2: =COUNTIFS(AI4:AI400, "=APAGADO",E4:E400,"=PTO A FO") -> 1
A3: =ESTADISTICA!A1 -> Barrio | B3: =ESTADISTICA!B1 -> [Denominacion] | C3: =ESTADISTICA!C1 -> [Ubicacion] | D3: =ESTADISTICA!D1 -> [Tipo de Camara] | E3: =ESTADISTICA!E1 -> [Tipo de Conexion] | F3: =ESTADISTICA!F1 -> 44835 | G3: =ESTADISTICA!G1 -> 44836 | H3: =ESTADISTICA!H1 -> 44837 | ... AI3: =ESTADISTICA!AI1 -> 44864
A4: =ESTADISTICA!A2 -> ALTAMIRA | B4: =ESTADISTICA!B2 -> ALT01 | C4: =ESTADISTICA!C2 -> Calchaqui y Sgto. Cabral | D4: =ESTADISTICA!D2 -> Domo | E4: =ESTADISTICA!E2 -> Fibra Optica | F4: =ESTADISTICA!F2 -> 0 | G4: =ESTADISTICA!G2 -> 0 | H4: =ESTADISTICA!H2 -> APAGADO | ... AI4: =ESTADISTICA!AI2 -> 0
A5: =ESTADISTICA!A3 -> ALTAMIRA | B5: =ESTADISTICA!B3 -> ALT02 | C5: =ESTADISTICA!C3 -> Calchaqui y Lope de Vega | D5: =ESTADISTICA!D3 -> Domo | E5: =ESTADISTICA!E3 -> PTO A FO | F5: =ESTADISTICA!F3 -> 0 | G5: =ESTADISTICA!G3 -> 0 | H5: =ESTADISTICA!H3 -> APAGADO | ... AI5: =ESTADISTICA!AI3 -> 0
A6: =ESTADISTICA!A4 -> ALTAMIRA | B6: =ESTADISTICA!B4 -> ALT 03 | C6: =ESTADISTICA!C4 -> Bombero Galarza y Necochea | D6: =ESTADISTICA!D4 -> Domo | E6: =ESTADISTICA!E4 -> FIBRA OPTICA | F6: =ESTADISTICA!F4 -> 0 | G6: =ESTADISTICA!G4 -> 0 | H6: =ESTADISTICA!H4 -> 0 | ... AI6: =ESTADISTICA!AI4 -> 0
A7: =ESTADISTICA!A5 -> ALTAMIRA | B7: =ESTADISTICA!B5 -> ALT 04 | C7: =ESTADISTICA!C5 -> Francia y Necochea | D7: =ESTADISTICA!D5 -> Domo | E7: =ESTADISTICA!E5 -> FIBRA OPTICA | F7: =ESTADISTICA!F5 -> APAGADO | G7: =ESTADISTICA!G5 -> APAGADO | H7: =ESTADISTICA!H5 -> APAGADO | ... AI7: =ESTADISTICA!AI5 -> 0
A8: =ESTADISTICA!A6 -> ALTAMIRA | B8: =ESTADISTICA!B6 -> ALT05 | C8: =ESTADISTICA!C6 -> Av. Calchaqui y Bombero Galarza | D8: =ESTADISTICA!D6 -> Domo | E8: =ESTADISTICA!E6 -> PTO A FO | F8: =ESTADISTICA!F6 -> APAGADO | G8: =ESTADISTICA!G6 -> APAGADO | H8: =ESTADISTICA!H6 -> APAGADO | ... AI8: =ESTADISTICA!AI6 -> 0
A9: =ESTADISTICA!A7 -> ALTAMIRA | B9: =ESTADISTICA!B7 -> ALT 06 | C9: =ESTADISTICA!C7 -> LOPE DE VEGA Y NECOCHEA | D9: =ESTADISTICA!D7 -> Domo | E9: =ESTADISTICA!E7 -> PTO A FO | F9: =ESTADISTICA!F7 -> 0 | G9: =ESTADISTICA!G7 -> 0 | H9: =ESTADISTICA!H7 -> APAGADO | ... AI9: =ESTADISTICA!AI7 -> 0
A10: =ESTADISTICA!A8 -> ALTAMIRA | B10: =ESTADISTICA!B8 -> ALT07 | C10: =ESTADISTICA!C8 -> AV. CALCHAQUI Y AV. DEL TRABAJO | D10: =ESTADISTICA!D8 -> DOMO | E10: =ESTADISTICA!E8 -> PTO A FO | F10: =ESTADISTICA!F8 -> 0 | G10: =ESTADISTICA!G8 -> 0 | H10: =ESTADISTICA!H8 -> 0 | ... AI10: =ESTADISTICA!AI8 -> 0
A11: =ESTADISTICA!A9 -> ALTAMIRA | B11: =ESTADISTICA!B9 -> ALT 08 | C11: =ESTADISTICA!C9 -> HUMAITA Y NECOCHEA | D11: =ESTADISTICA!D9 -> DOMO | E11: =ESTADISTICA!E9 -> Fibra Optica | F11: =ESTADISTICA!F9 -> 0 | G11: =ESTADISTICA!G9 -> 0 | H11: =ESTADISTICA!H9 -> 0 | ... AI11: =ESTADISTICA!AI9 -> 0
A12: =ESTADISTICA!A10 -> ALTAMIRA | B12: =ESTADISTICA!B10 -> ALT 09 | C12: =ESTADISTICA!C10 -> NECOCHEA Y CURUPAITY | D12: =ESTADISTICA!D10 -> DOMO | E12: =ESTADISTICA!E10 -> Fibra Optica | F12: =ESTADISTICA!F10 -> 0 | G12: =ESTADISTICA!G10 -> 0 | H12: =ESTADISTICA!H10 -> 0 | ... AI12: =ESTADISTICA!AI10 -> 0
A13: =ESTADISTICA!A11 -> ALTAMIRA | B13: =ESTADISTICA!B11 -> ALT 10 | C13: =ESTADISTICA!C11 -> Calchaqui y Francia | D13: =ESTADISTICA!D11 -> Domo | E13: =ESTADISTICA!E11 -> Radio | F13: =ESTADISTICA!F11 -> APAGADO | G13: =ESTADISTICA!G11 -> APAGADO | H13: =ESTADISTICA!H11 -> APAGADO | ... AI13: =ESTADISTICA!AI11 -> 0
A14: =ESTADISTICA!A12 -> AGUSTIN RAMIREZ | B14: =ESTADISTICA!B12 -> ARA 01 | C14: =ESTADISTICA!C12 -> Malambo y Tranquera | D14: =ESTADISTICA!D12 -> Domo | E14: =ESTADISTICA!E12 -> FIBRA OPTICA | F14: =ESTADISTICA!F12 -> 0 | G14: =ESTADISTICA!G12 -> 0 | H14: =ESTADISTICA!H12 -> APAGADO | ... AI14: =ESTADISTICA!AI12 -> 0
... A278: =ESTADISTICA!A276 -> SAN EMILIO | B278: =ESTADISTICA!B276 -> SEMI 02 | C278: =ESTADISTICA!C276 -> Cno. Gral. Belgrano y Francia | D278: =ESTADISTICA!D276 -> Domo | E278: =ESTADISTICA!E276 -> FIBRA OPTICA | F278: =ESTADISTICA!F276 -> APAGADO | G278: =ESTADISTICA!G276 -> APAGADO | H278: =ESTADISTICA!H276 -> APAGADO | ... AI278: =ESTADISTICA!AI276 -> 0
B279: =ESTADISTICA!B277 -> SEMI03 (fija 1) | C279: =ESTADISTICA!C277 -> GORRITI E/ GALARZA Y LOPE DE VEGA | D279: =ESTADISTICA!D277 -> Fija | E279: =ESTADISTICA!E277 -> Fibra Optica | F279: =ESTADISTICA!F277 -> 0 | G279: =ESTADISTICA!G277 -> 0 | H279: =ESTADISTICA!H277 -> 0 | I279: =ESTADISTICA!I277 -> 0 | ... AI279: =ESTADISTICA!AI277 -> 0
A280: =ESTADISTICA!A278 -> SAN EMILIO | B280: =ESTADISTICA!B278 -> SEMI04 (fija 2) | C280: =ESTADISTICA!C278 -> GORRITI E/ GALARZA Y LOPE DE VEGA | D280: =ESTADISTICA!D278 -> Fija | E280: =ESTADISTICA!E278 -> Fibra Optica | F280: =ESTADISTICA!F278 -> 0 | G280: =ESTADISTICA!G278 -> 0 | H280: =ESTADISTICA!H278 -> 0 | ... AI280: =ESTADISTICA!AI278 -> 0
A281: =ESTADISTICA!A279 -> LA SIRENA | B281: =ESTADISTICA!B279 -> SIR01 | C281: =ESTADISTICA!C279 -> Moran y Calle 14 | D281: =ESTADISTICA!D279 -> DOMO | E281: =ESTADISTICA!E279 -> Radio | F281: =ESTADISTICA!F279 -> 0 | G281: =ESTADISTICA!G279 -> 0 | H281: =ESTADISTICA!H279 -> 0 | ... AI281: =ESTADISTICA!AI279 -> 0
A282: =ESTADISTICA!A280 -> SAN EDUARDO | B282: =ESTADISTICA!B280 -> SIR 02 | C282: =ESTADISTICA!C280 -> Victorino de la Plaza y Argentina | D282: =ESTADISTICA!D280 -> Domo | E282: =ESTADISTICA!E280 -> Radio | F282: =ESTADISTICA!F280 -> 0 | G282: =ESTADISTICA!G280 -> 0 | H282: =ESTADISTICA!H280 -> APAGADO | ... AI282: =ESTADISTICA!AI280 -> 0
A283: =ESTADISTICA!A281 -> SAN EDUARDO | B283: =ESTADISTICA!B281 -> SIR 03 | C283: =ESTADISTICA!C281 -> MONTES Y LONARDI | D283: =ESTADISTICA!D281 -> DOMO | E283: =ESTADISTICA!E281 -> Radio | F283: =ESTADISTICA!F281 -> 0 | G283: =ESTADISTICA!G281 -> 0 | H283: =ESTADISTICA!H281 -> 0 | ... AI283: =ESTADISTICA!AI281 -> 0
A284: =ESTADISTICA!A282 -> LA SIRENA | B284: =ESTADISTICA!B282 -> SIR 04 | C284: =ESTADISTICA!C282 -> AV. MONTEVERDE Y MORAN | D284: =ESTADISTICA!D282 -> Domo | E284: =ESTADISTICA!E282 -> Fibra Optica | F284: =ESTADISTICA!F282 -> 0 | G284: =ESTADISTICA!G282 -> 0 | H284: =ESTADISTICA!H282 -> 0 | ... AI284: =ESTADISTICA!AI282 -> 0
A285: =ESTADISTICA!A283 -> LA SIRENA | B285: =ESTADISTICA!B283 -> SIR 05 (FIJA 01) | C285: =ESTADISTICA!C283 -> AV. MONTEVERDE Y MORAN | D285: =ESTADISTICA!D283 -> Fija | E285: =ESTADISTICA!E283 -> Fibra Optica | F285: =ESTADISTICA!F283 -> 0 | G285: =ESTADISTICA!G283 -> 0 | H285: =ESTADISTICA!H283 -> 0 | ... AI285: =ESTADISTICA!AI283 -> 0
A286: =ESTADISTICA!A284 -> LA SIRENA | B286: =ESTADISTICA!B284 -> SIR 06 (FIJA 02) | C286: =ESTADISTICA!C284 -> AV. MONTEVERDE Y MORAN | D286: =ESTADISTICA!D284 -> Fija | E286: =ESTADISTICA!E284 -> Fibra Optica | F286: =ESTADISTICA!F284 -> 0 | G286: =ESTADISTICA!G284 -> 0 | H286: =ESTADISTICA!H284 -> 0 | ... AI286: =ESTADISTICA!AI284 -> 0
A287: =ESTADISTICA!A285 -> VILLA AURORA | B287: =ESTADISTICA!B285 -> SIR07 (fija 1) | C287: =ESTADISTICA!C285 -> MONTEVERDE Y URIBURU | D287: =ESTADISTICA!D285 -> Fija | E287: =ESTADISTICA!E285 -> Fibra Optica | F287: =ESTADISTICA!F285 -> 0 | G287: =ESTADISTICA!G285 -> 0 | H287: =ESTADISTICA!H285 -> 0 | ... AI287: =ESTADISTICA!AI285 -> 0
A288: =ESTADISTICA!A286 -> VILLA AURORA | B288: =ESTADISTICA!B286 -> SIR08 (fija 2) | C288: =ESTADISTICA!C286 -> MONTEVERDE Y URIBURU | D288: =ESTADISTICA!D286 -> Fija | E288: =ESTADISTICA!E286 -> Fibra Optica | F288: =ESTADISTICA!F286 -> 0 | G288: =ESTADISTICA!G286 -> 0 | H288: =ESTADISTICA!H286 -> 0 | ... AI288: =ESTADISTICA!AI286 -> 0
A289: =ESTADISTICA!A287 -> LA SIRENA | B289: =ESTADISTICA!B287 -> SIR09 (fija 1) | C289: =ESTADISTICA!C287 -> GUIDO SPANO Y MORAN | D289: =ESTADISTICA!D287 -> Fija | E289: =ESTADISTICA!E287 -> Fibra Optica | F289: =ESTADISTICA!F287 -> 0 | G289: =ESTADISTICA!G287 -> 0 | H289: =ESTADISTICA!H287 -> 0 | ... AI289: =ESTADISTICA!AI287 -> 0
A290: =ESTADISTICA!A288 -> LA SIRENA | B290: =ESTADISTICA!B288 -> SIR10 (fija 2) | C290: =ESTADISTICA!C288 -> GUIDO SPANO Y MORAN | D290: =ESTADISTICA!D288 -> Fija | E290: =ESTADISTICA!E288 -> Fibra Optica | F290: =ESTADISTICA!F288 -> 0 | G290: =ESTADISTICA!G288 -> 0 | H290: =ESTADISTICA!H288 -> 0 | ... AI290: =ESTADISTICA!AI288 -> 0
A291: =ESTADISTICA!A289 -> LA SIRENA | B291: =ESTADISTICA!B289 -> SIR11 (fija 1) | C291: =ESTADISTICA!C289 -> LARREA Y GUARDIA NACIONAL | D291: =ESTADISTICA!D289 -> Fija | E291: =ESTADISTICA!E289 -> Fibra Optica | F291: =ESTADISTICA!F289 -> 0 | G291: =ESTADISTICA!G289 -> 0 | H291: =ESTADISTICA!H289 -> 0 | ... AI291: =ESTADISTICA!AI289 -> 0
... A454: =ESTADISTICA!A452 -> 0 | B454: =ESTADISTICA!B452 -> 0 | C454: =ESTADISTICA!C452 -> 0 | D454: =ESTADISTICA!D452 -> 0 | E454: =ESTADISTICA!E452 -> 0 | F454: =ESTADISTICA!F452 -> 0 | G454: =ESTADISTICA!G452 -> 0 | H454: =ESTADISTICA!H452 -> 0 | ... AI454: =ESTADISTICA!AI452 -> 0

Sheet APAGADOS RADIO
C1: TOTAL RADIO | D1: =COUNTIFS(E4:E400,"=radio") -> 93
E2: APAGADOS | F2: =COUNTIFS(F4:F500, "=APAGADO",E4:E500,"=radio") -> 4 | G2: =COUNTIFS(G4:G500, "=APAGADO",E4:E500,"=radio") -> 1 | H2: =COUNTIFS(H4:H500, "=APAGADO",E4:E500,"=radio") -> 45 | I2: =COUNTIFS(I4:I500, "=APAGADO",E4:E500,"=radio") -> 4 | J2: =COUNTIFS(J4:J500, "=APAGADO",E4:E500,"=radio") -> 2 | K2: =COUNTIFS(K4:K500, "=APAGADO",E4:E500,"=radio") -> 0 | L2: =COUNTIFS(L4:L500, "=APAGADO",E4:E500,"=radio") -> 1 | M2: =COUNTIFS(M4:M500, "=APAGADO",E4:E500,"=radio") -> 0 | N2: =COUNTIFS(N4:N500, "=APAGADO",E4:E500,"=radio") -> 4 | O2: =COUNTIFS(O4:O500, "=APAGADO",E4:E500,"=radio") -> 3 | P2: =COUNTIFS(P4:P500, "=APAGADO",E4:E500,"=radio") -> 4 | Q2: =COUNTIFS(Q4:Q367, "=APAGADO",E4:E367,"=radio") -> 3 | R2: =COUNTIFS(R4:R367, "=APAGADO",E4:E367,"=radio") -> 8 | S2: =COUNTIFS(S4:S367, "=APAGADO",E4:E367,"=radio") -> 1 | T2: =COUNTIFS(T4:T367, "=APAGADO",E4:E367,"=radio") -> 2 | U2: =COUNTIFS(U4:U367, "=APAGADO",E4:E367,"=radio") -> 3 | V2: =COUNTIFS(V4:V367, "=APAGADO",E4:E367,"=radio") -> 0 | W2: =COUNTIFS(W4:W367, "=APAGADO",E4:E367,"=radio") -> 3 | X2: =COUNTIFS(X4:X367, "=APAGADO",E4:E367,"=radio") -> 5 | Y2: =COUNTIFS(Y4:Y367, "=APAGADO",E4:E367,"=radio") -> 7 | Z2: =COUNTIFS(Z4:Z367, "=APAGADO",E4:E367,"=radio") -> 2 | AA2: =COUNTIFS(AA4:AA367, "=APAGADO",E4:E367,"=radio") -> 4 | AB2: =COUNTIFS(AB4:AB367, "=APAGADO",E4:E367,"=radio") -> 8 | AC2: =COUNTIFS(AC4:AC367, "=APAGADO",E4:E367,"=radio") -> 3 | AD2: =COUNTIFS(AD4:AD367, "=APAGADO",E4:E367,"=radio") -> 4 | AE2: =COUNTIFS(AE4:AE500, "=APAGADO",E4:E500,"=radio") -> 3 | AF2: =COUNTIFS(AF4:AF500, "=APAGADO",E4:E500,"=radio") -> 3 | AG2: =COUNTIFS(AG4:AG500, "=APAGADO",E4:E500,"=radio") -> 2 | AH2: =COUNTIFS(AH4:AH400, "=APAGADO",E4:E400,"=radio") -> 1 | AI2: =COUNTIFS(AI4:AI500, "=APAGADO",E4:E500,"=radio") -> 3
A3: =ESTADISTICA!A1 -> Barrio | B3: =ESTADISTICA!B1 -> [Denominacion] | C3: =ESTADISTICA!C1 -> [Ubicacion] | D3: =ESTADISTICA!D1 -> [Tipo de Camara] | E3: =ESTADISTICA!E1 -> [Tipo de Conexion] | F3: =ESTADISTICA!F1 -> 44835 | G3: =ESTADISTICA!G1 -> 44836 | H3: =ESTADISTICA!H1 -> 44837 | ... AI3: =ESTADISTICA!AI1 -> 44864
A4: =ESTADISTICA!A2 -> ALTAMIRA | B4: =ESTADISTICA!B2 -> ALT01 | C4: =ESTADISTICA!C2 -> Calchaqui y Sgto. Cabral | D4: =ESTADISTICA!D2 -> Domo | E4: =ESTADISTICA!E2 -> Fibra Optica | F4: =ESTADISTICA!F2 -> 0 | G4: =ESTADISTICA!G2 -> 0 | H4: =ESTADISTICA!H2 -> APAGADO | ... AI4: =ESTADISTICA!AI2 -> 0
A5: =ESTADISTICA!A3 -> ALTAMIRA | B5: =ESTADISTICA!B3 -> ALT02 | C5: =ESTADISTICA!C3 -> Calchaqui y Lope de Vega | D5: =ESTADISTICA!D3 -> Domo | E5: =ESTADISTICA!E3 -> PTO A FO | F5: =ESTADISTICA!F3 -> 0 | G5: =ESTADISTICA!G3 -> 0 | H5: =ESTADISTICA!H3 -> APAGADO | ... AI5: =ESTADISTICA!AI3 -> 0
A6: =ESTADISTICA!A4 -> ALTAMIRA | B6: =ESTADISTICA!B4 -> ALT 03 | C6: =ESTADISTICA!C4 -> Bombero Galarza y Necochea | D6: =ESTADISTICA!D4 -> Domo | E6: =ESTADISTICA!E4 -> FIBRA OPTICA | F6: =ESTADISTICA!F4 -> 0 | G6: =ESTADISTICA!G4 -> 0 | H6: =ESTADISTICA!H4 -> 0 | ... AI6: =ESTADISTICA!AI4 -> 0
A7: =ESTADISTICA!A5 -> ALTAMIRA | B7: =ESTADISTICA!B5 -> ALT 04 | C7: =ESTADISTICA!C5 -> Francia y Necochea | D7: =ESTADISTICA!D5 -> Domo | E7: =ESTADISTICA!E5 -> FIBRA OPTICA | F7: =ESTADISTICA!F5 -> APAGADO | G7: =ESTADISTICA!G5 -> APAGADO | H7: =ESTADISTICA!H5 -> APAGADO | ... AI7: =ESTADISTICA!AI5 -> 0
A8: =ESTADISTICA!A6 -> ALTAMIRA | B8: =ESTADISTICA!B6 -> ALT05 | C8: =ESTADISTICA!C6 -> Av. Calchaqui y Bombero Galarza | D8: =ESTADISTICA!D6 -> Domo | E8: =ESTADISTICA!E6 -> PTO A FO | F8: =ESTADISTICA!F6 -> APAGADO | G8: =ESTADISTICA!G6 -> APAGADO | H8: =ESTADISTICA!H6 -> APAGADO | ... AI8: =ESTADISTICA!AI6 -> 0
A9: =ESTADISTICA!A7 -> ALTAMIRA | B9: =ESTADISTICA!B7 -> ALT 06 | C9: =ESTADISTICA!C7 -> LOPE DE VEGA Y NECOCHEA | D9: =ESTADISTICA!D7 -> Domo | E9: =ESTADISTICA!E7 -> PTO A FO | F9: =ESTADISTICA!F7 -> 0 | G9: =ESTADISTICA!G7 -> 0 | H9: =ESTADISTICA!H7 -> APAGADO | ... AI9: =ESTADISTICA!AI7 -> 0
A10: =ESTADISTICA!A8 -> ALTAMIRA | B10: =ESTADISTICA!B8 -> ALT07 | C10: =ESTADISTICA!C8 -> AV. CALCHAQUI Y AV. DEL TRABAJO | D10: =ESTADISTICA!D8 -> DOMO | E10: =ESTADISTICA!E8 -> PTO A FO | F10: =ESTADISTICA!F8 -> 0 | G10: =ESTADISTICA!G8 -> 0 | H10: =ESTADISTICA!H8 -> 0 | ... AI10: =ESTADISTICA!AI8 -> 0
A11: =ESTADISTICA!A9 -> ALTAMIRA | B11: =ESTADISTICA!B9 -> ALT 08 | C11: =ESTADISTICA!C9 -> HUMAITA Y NECOCHEA | D11: =ESTADISTICA!D9 -> DOMO | E11: =ESTADISTICA!E9 -> Fibra Optica | F11: =ESTADISTICA!F9 -> 0 | G11: =ESTADISTICA!G9 -> 0 | H11: =ESTADISTICA!H9 -> 0 | ... AI11: =ESTADISTICA!AI9 -> 0
