Workbook
Name _25_de_agosto: 'RESUMEN TOTAL'!$A$4:$D$388
Name _25_de_agosto_3: 'RESUMEN TOTAL'!$A$4:$D$400
Name _30_mar: 'APAGADOS ANTENA'!$AI$3
Name BONOMOcam: Hoja1!$B$2
Name CANTIDAD_DE_CAMARAS: 'RESUMEN TOTAL'!$B$1
Name COSEIDIcam: Hoja1!$B$4

Sheet RESUMEN TOTAL
A1: CANTIDAD DE CAMARAS | B1: =COUNTA(B5:B624) -> 536 | D1: PORCIENTO DE CAIDAS | L1: =(L3)/(L2+L3) -> 0.15855573 | M1: =(M3)/(M2+M3) -> 0 | N1: =(N3)/(N2+N3) -> 0 | O1: =(O3)/(O2+O3) -> 0.17538462 | P1: =(P3)/(P2+P3) -> 0 | Q1: =(Q3)/(Q2+Q3) -> 0 | R1: =(R3)/(R2+R3) -> 0 | S1: =(S3)/(S2+S3) -> 0 | ... X1: =(X3)/(X2+X3) -> 0 | Z1: =(Z3)/(Z2+Z3) -> 0 | AA1: =(AA3)/(AA2+AA3) -> 0 | AB1: =(AB3)/(AB2+AB3) -> 0 | AC1: =(AC3)/(AC2+AC3) -> 0 | AD1: =(AD3)/(AD2+AD3) -> 0 | AE1: =(AE3)/(AE2+AE3) -> 0 | AF1: =(AF3)/(AF2+AF3) -> 0 | AG1: =(AG3)/(AG2+AG3) -> 0 | ... AP1: =(AP3)/(AP2+AP3) -> 0
D2: FUNCIONAN | L2: 536 | M2: 536 | N2: 536 | O2: 536 | P2: 536 | Q2: 536 | R2: 536 | S2: 536 | T2: 536 | U2: 536 | V2: 536 | W2: 536 | X2: 536 | Y2: 536 | Z2: 536 | AA2: 536 | AB2: 536 | AC2: 536 | AD2: 536 | AE2: 536 | AF2: 536 | AG2: 536 | AH2: 536 | AI2: 536 | AJ2: 536 | AK2: 536 | AL2: 536 | AM2: 536 | AN2: 536 | AO2: 536 | AP2: 536
D3: CAIDAS | L3: =COUNTIF(L4:L624, "apagado") -> 101 | M3: =COUNTIF(M4:M624, "apagado") -> 0 | N3: =COUNTIF(N4:N624, "apagado") -> 0 | O3: =COUNTIF(O4:O624, "apagado") -> 114 | P3: =COUNTIF(P4:P624, "apagado") -> 0 | Q3: =COUNTIF(Q4:Q624, "apagado") -> 0 | R3: =COUNTIF(R4:R624, "apagado") -> 0 | S3: =COUNTIF(S4:S624, "apagado") -> 0 | ... W3: =COUNTIF(W4:W624, "apagado") -> 0 | X3: =COUNTIF(X4:X524, "apagado") -> 0 | Y3: =COUNTIF(Y4:Y524, "apagado") -> 0 | Z3: =COUNTIF(Z4:Z624, "apagado") -> 0 | AA3: =COUNTIF(AA4:AA624, "apagado") -> 0 | AB3: =COUNTIF(AB4:AB624, "apagado") -> 0 | AC3: =COUNTIF(AC4:AC624, "apagado") -> 0 | AD3: =COUNTIF(AD4:AD624, "apagado") -> 0 | AE3: =COUNTIF(AE4:AE624, "apagado") -> 0 | AF3: =COUNTIF(AF4:AF624, "apagado") -> 0 | AG3: =COUNTIF(AG4:AG624, "apagado") -> 0 | ... AP3: =COUNTIF(AP4:AP624, "apagado") -> 0
A4: Barrio | B4: [Denominacion] | C4: [Empresa Mantenimiento] | D4: [Ubicacion] | E4: [Tipo de Camara] | F4: [Tipo de Conexion] | G4: Destino | I4: DIAS FUNCIONANDO | J4: DIAS CAIDA | K4: EFECTIVIDAD | L4: 45352 | M4: 45353 | N4: 45354 | O4: 45355 | P4: 45356 | Q4: 45357 | R4: 45358 | S4: 45359 | T4: 45360 | U4: 45361 | V4: 45362 | W4: 45363 | X4: 45364 | Y4: 45365 | Z4: 45366 | AA4: 45367 | AB4: 45368 | AC4: 45369 | AD4: 45370 | AE4: 45371 | AF4: 45372 | AG4: 45373 | AH4: 45374 | AI4: 45375 | AJ4: 45376 | AK4: 45377 | AL4: 45378 | AM4: 45379 | AN4: 45380 | AO4: 45381 | AP4: 45382
A5: ALTAMIRA | B5: ALT01 | C5: BONOMO | D5: Calchaqui y Sgto. Cabral | E5: Domo | F5: Fibra Optica | H5: 172.20.10.6 | I5: =COUNTIF(L5:AM5,"") -> 28 | J5: =COUNTIF(L5:AM5,"APAGADO") -> 0 | K5: =(I5)/(J5+I5) -> 1
A6: ALTAMIRA | B6: ALT02 | C6: BONOMO | D6: Calchaqui y Lope de Vega | E6: Domo | F6: PTO A FO | G6: CABRAL Y CALCHAQUI | H6: 172.20.12.218 | I6: =COUNTIF(L6:AM6,"") -> 28 | J6: =COUNTIF(L6:AM6,"APAGADO") -> 0 | K6: =(I6)/(J6+I6) -> 1
A7: ALTAMIRA | B7: ALT 03 | C7: BONOMO | D7: Bombero Galarza y Necochea | E7: Domo | F7: Fibra Optica | H7: 172.20.12.54 | I7: =COUNTIF(L7:AM7,"") -> 28 | J7: =COUNTIF(L7:AM7,"APAGADO") -> 0 | K7: =(I7)/(J7+I7) -> 1
A8: ALTAMIRA | B8: ALT 04 | C8: BONOMO | D8: Francia y Necochea | E8: Domo | F8: Fibra Optica | H8: 172.20.12.55 | I8: =COUNTIF(L8:AM8,"") -> 28 | J8: =COUNTIF(L8:AM8,"APAGADO") -> 0 | K8: =(I8)/(J8+I8) -> 1
A9: ALTAMIRA | B9: ALT05 | C9: BONOMO | D9: Av. Calchaqui y Bombero Galarza | E9: Domo | F9: PTO A FO | G9: NECOCHEA Y GALARZA | H9: 172.20.12.216 | I9: =COUNTIF(L9:AM9,"") -> 28 | J9: =COUNTIF(L9:AM9,"APAGADO") -> 0 | K9: =(I9)/(J9+I9) -> 1
A10: ALTAMIRA | B10: ALT 06 | C10: BONOMO | D10: LOPE DE VEGA Y NECOCHEA | E10: Domo | F10: PTO A FO | G10: NECOCHEA Y GALARZA | H10: 172.20.12.12 | I10: =COUNTIF(L10:AM10,"") -> 28 | J10: =COUNTIF(L10:AM10,"APAGADO") -> 0 | K10: =(I10)/(J10+I10) -> 1
A11: ALTAMIRA | B11: ALT07 | C11: BONOMO | D11: AV. CALCHAQUI Y AV. DEL TRABAJO | E11: DOMO | F11: PTO A FO | G11: CABRAL Y CALCHAQUI | H11: 172.20.10.57 | I11: =COUNTIF(L11:AM11,"") -> 28 | J11: =COUNTIF(L11:AM11,"APAGADO") -> 0 | K11: =(I11)/(J11+I11) -> 1
A12: ALTAMIRA | B12: ALT 08 | C12: BONOMO | D12: HUMAITA Y NECOCHEA | E12: DOMO | F12: Fibra Optica | H12: 172.20.11.215 | I12: =COUNTIF(L12:AM12,"") -> 28 | J12: =COUNTIF(L12:AM12,"APAGADO") -> 0 | K12: =(I12)/(J12+I12) -> 1
A13: ALTAMIRA | B13: ALT 09 | C13: BONOMO | D13: NECOCHEA Y CURUPAITY | E13: DOMO | F13: Fibra Optica | H13: 172.20.11.216 | I13: =COUNTIF(L13:AM13,"") -> 28 | J13: =COUNTIF(L13:AM13,"APAGADO") -> 0 | K13: =(I13)/(J13+I13) -> 1
A14: ALTAMIRA | B14: ALT 10 | C14: BONOMO | D14: Calchaqui y Francia | E14: Domo | F14: Radio | H14: 172.20.12.156 | I14: =COUNTIF(L14:AM14,"") -> 28 | J14: =COUNTIF(L14:AM14,"APAGADO") -> 0 | K14: =(I14)/(J14+I14) -> 1
A15: AGUSTIN RAMIREZ | B15: ARA 01 | C15: BONOMO | D15: Malambo y Tranquera | E15: Domo | F15: Fibra Optica | H15: 172.20.12.110 | I15: =COUNTIF(L15:AM15,"") -> 28 | J15: =COUNTIF(L15:AM15,"APAGADO") -> 0 | K15: =(I15)/(J15+I15) -> 1
A16: BELGRANO | B16: BEL 01 | C16: BONOMO | D16: San Martin y Dardo Rocha | E16: DOMO | F16: Fibra Optica | H16: 172.20.12.64 | I16: =COUNTIF(L16:AM16,"") -> 26 | J16: =COUNTIF(L16:AM16,"APAGADO") -> 2 | K16: =(I16)/(J16+I16) -> 0.92857143 | L16: APAGADO | O16: APAGADO
A17: BELGRANO | B17: BEL 02 | C17: BONOMO | D17: Guardia vieja y Fronteriz | E17: DOMO | F17: Fibra Optica | I17: =COUNTIF(L17:AM17,"") -> 28 | J17: =COUNTIF(L17:AM17,"APAGADO") -> 0 | K17: =(I17)/(J17+I17) -> 1
A18: BOSQUES CENTRO | B18: BOSQC 01 | C18: COSEIDI | D18: LUIS AGOTE E/DANUNCIO Y CAMPOAMOR | E18: Fija | F18: Radio | H18: 172.20.11.15 | I18: =COUNTIF(L18:AM18,"") -> 28 | J18: =COUNTIF(L18:AM18,"APAGADO") -> 0 | K18: =(I18)/(J18+I18) -> 1
A19: BOSQUES CENTRO | B19: BOSQC 02 | C19: COSEIDI | D19: LUIS AGOTE E/DANUNCIO Y CAMPOAMOR | E19: Fija | F19: Radio | H19: 172.20.11.16 | I19: =COUNTIF(L19:AM19,"") -> 28 | J19: =COUNTIF(L19:AM19,"APAGADO") -> 0 | K19: =(I19)/(J19+I19) -> 1
A20: BOSQUES CENTRO | B20: BOSQC 03 | C20: COSEIDI | D20: BENAVENTE Y LUIS AGOTE | E20: Fija | F20: Radio | H20: 172.20.11.13 | I20: =COUNTIF(L20:AM20,"") -> 28 | J20: =COUNTIF(L20:AM20,"APAGADO") -> 0 | K20: =(I20)/(J20+I20) -> 1
A21: BOSQUES CENTRO | B21: BOSQC 04 | C21: COSEIDI | D21: BENAVENTE Y LUIS AGOTE | E21: Fija | F21: Radio | H21: 172.20.11.113 | I21: =COUNTIF(L21:AM21,"") -> 28 | J21: =COUNTIF(L21:AM21,"APAGADO") -> 0 | K21: =(I21)/(J21+I21) -> 1
A22: BOSQUES CENTRO | B22: BOSQC 05 | C22: COSEIDI | D22: LUIS AGOTE Y RUTA 36 | E22: Fija | F22: Radio | H22: 172.20.11.17 | I22: =COUNTIF(L22:AM22,"") -> 28 | J22: =COUNTIF(L22:AM22,"APAGADO") -> 0 | K22: =(I22)/(J22+I22) -> 1
A23: BOSQUES CENTRO | B23: BOSQC 06 | C23: COSEIDI | D23: LUIS AGOTE Y RUTA 36 | E23: Fija | F23: Radio | H23: 172.20.11.18 | I23: =COUNTIF(L23:AM23,"") -> 28 | J23: =COUNTIF(L23:AM23,"APAGADO") -> 0 | K23: =(I23)/(J23+I23) -> 1
A24: CENTRO | B24: CEN01 | C24: BONOMO | D24: San Martin y 9 de Julio | E24: Fija | F24: Fibra Optica | H24: 172.20.11.10 | I24: =COUNTIF(L24:AM24,"") -> 26 | J24: =COUNTIF(L24:AM24,"APAGADO") -> 2 | K24: =(I24)/(J24+I24) -> 0.92857143 | L24: APAGADO | O24: APAGADO
A25: CENTRO | B25: CEN02 | C25: BONOMO | D25: San Martin y Almafuerte | E25: Fija | F25: Fibra Optica | H25: 172.20.11.11 | I25: =COUNTIF(L25:AM25,"") -> 26 | J25: =COUNTIF(L25:AM25,"APAGADO") -> 2 | K25: =(I25)/(J25+I25) -> 0.92857143 | L25: APAGADO | O25: APAGADO
A26: CENTRO | B26: CEN03 | C26: BONOMO | D26: San Martin y Sallares | E26: Domo | F26: Fibra Optica | H26: 172.20.12.30 | I26: =COUNTIF(L26:AM26,"") -> 28 | J26: =COUNTIF(L26:AM26,"APAGADO") -> 0 | K26: =(I26)/(J26+I26) -> 1
A27: CENTRO | B27: CEN04 | C27: BONOMO | D27: San Martin y Contreras | E27: Domo | F27: Fibra Optica | H27: 172.20.12.29 | I27: =COUNTIF(L27:AM27,"") -> 28 | J27: =COUNTIF(L27:AM27,"APAGADO") -> 0 | K27: =(I27)/(J27+I27) -> 1
A28: CENTRO | B28: CEN 05 | C28: BONOMO | D28: Bocuzzi e/España y San Martin | E28: DOMO | F28: Fibra Optica | H28: 172.20.10.200 | I28: =COUNTIF(L28:AM28,"") -> 28 | J28: =COUNTIF(L28:AM28,"APAGADO") -> 0 | K28: =(I28)/(J28+I28) -> 1
A29: CENTRO | B29: CEN06 | C29: BONOMO | D29: Monteagudo y A.del Valle | E29: Fija | F29: Fibra Optica | H29: 172.20.10.02 | I29: =COUNTIF(L29:AM29,"") -> 26 | J29: =COUNTIF(L29:AM29,"APAGADO") -> 2 | K29: =(I29)/(J29+I29) -> 0.92857143 | L29: APAGADO | O29: APAGADO
A30: CENTRO | B30: CEN07 | C30: BONOMO | D30: San Martin y Guemes | E30: DOMO | F30: Fibra Optica | H30: 172.20.11.20 | I30: =COUNTIF(L30:AM30,"") -> 28 | J30: =COUNTIF(L30:AM30,"APAGADO") -> 0 | K30: =(I30)/(J30+I30) -> 1
A31: CENTRO | B31: CEN08 | C31: BONOMO | D31: San Martin y Pte.Peron | E31: Domo | F31: Fibra Optica | H31: 172.20.11.21 | I31: =COUNTIF(L31:AM31,"") -> 28 | J31: =COUNTIF(L31:AM31,"APAGADO") -> 0 | K31: =(I31)/(J31+I31) -> 1
A32: CENTRO | B32: CEN09 | C32: BONOMO | D32: Chacabuco y 25 de Mayo | E32: Domo | F32: Fibra Optica | H32: 172.20.11.22 | I32: =COUNTIF(L32:AM32,"") -> 28 | J32: =COUNTIF(L32:AM32,"APAGADO") -> 0 | K32: =(I32)/(J32+I32) -> 1
A33: CENTRO | B33: CEN10 | C33: BONOMO | D33: Monteagudo y Pte. Peron | E33: Domo | F33: Fibra Optica | H33: 172.20.11.23 | I33: =COUNTIF(L33:AM33,"") -> 28 | J33: =COUNTIF(L33:AM33,"APAGADO") -> 0 | K33: =(I33)/(J33+I33) -> 1
A34: CENTRO | B34: CEN11 | C34: BONOMO | D34: Monteagudo y Bocuzzi | E34: Domo | F34: Fibra Optica | H34: 172.20.10.24 | I34: =COUNTIF(L34:AM34,"") -> 28 | J34: =COUNTIF(L34:AM34,"APAGADO") -> 0 | K34: =(I34)/(J34+I34) -> 1
A35: CENTRO | B35: CEN 12 | C35: BONOMO | D35: Monteagudo y Mitre | E35: Domo | F35: Fibra Optica | H35: 172.20.10.23 | I35: =COUNTIF(L35:AM35,"") -> 28 | J35: =COUNTIF(L35:AM35,"APAGADO") -> 0 | K35: =(I35)/(J35+I35) -> 1
A36: CENTRO | B36: CEN 13 | C36: BONOMO | D36: 25 de Mayo y Maipu | E36: DOMO | F36: Fibra Optica | H36: 172.20.10.20 | I36: =COUNTIF(L36:AM36,"") -> 28 | J36: =COUNTIF(L36:AM36,"APAGADO") -> 0 | K36: =(I36)/(J36+I36) -> 1
A37: CENTRO | B37: CEN14 | C37: BONOMO | D37: Pte.Peron e/Pringles y Brown | E37: Domo | F37: Fibra Optica | H37: 172.20.10.94 | I37: =COUNTIF(L37:AM37,"") -> 28 | J37: =COUNTIF(L37:AM37,"APAGADO") -> 0 | K37: =(I37)/(J37+I37) -> 1
A38: CENTRO | B38: CEN15 | C38: BONOMO | D38: Alberdi y A.del Valle | E38: Domo | F38: Fibra Optica | H38: 172.20.10.35 | I38: =COUNTIF(L38:AM38,"") -> 28 | J38: =COUNTIF(L38:AM38,"APAGADO") -> 0 | K38: =(I38)/(J38+I38) -> 1
A39: CENTRO | B39: CEN16 | C39: BONOMO | D39: San Martin y Pte. Peron | E39: Fija | F39: Fibra Optica | H39: 172.20.12.36 | I39: =COUNTIF(L39:AM39,"") -> 28 | J39: =COUNTIF(L39:AM39,"APAGADO") -> 0 | K39: =(I39)/(J39+I39) -> 1
A40: CENTRO | B40: CEN17 | C40: BONOMO | D40: San Martin y Mitre | E40: Domo | F40: PTO A FO | G40: SAN MARTIN Y SALLARES | H40: 172.20.12.200 | I40: =COUNTIF(L40:AM40,"") -> 28 | J40: =COUNTIF(L40:AM40,"APAGADO") -> 0 | K40: =(I40)/(J40+I40) -> 1
...

Sheet Hoja3

Sheet ESTADISTICA
A1: ='RESUMEN TOTAL'!A4 -> Barrio | B1: ='RESUMEN TOTAL'!B4 -> [Denominacion] | C1: ='RESUMEN TOTAL'!D4 -> [Ubicacion] | D1: ='RESUMEN TOTAL'!E4 -> [Tipo de Camara] | E1: ='RESUMEN TOTAL'!F4 -> [Tipo de Conexion] | F1: ='RESUMEN TOTAL'!L4 -> 45352 | G1: ='RESUMEN TOTAL'!M4 -> 45353 | H1: ='RESUMEN TOTAL'!N4 -> 45354 | I1: ='RESUMEN TOTAL'!O4 -> 45355 | J1: ='RESUMEN TOTAL'!P4 -> 45356 | K1: ='RESUMEN TOTAL'!Q4 -> 45357 | L1: ='RESUMEN TOTAL'!R4 -> 45358 | M1: ='RESUMEN TOTAL'!S4 -> 45359 | ... AH1: ='RESUMEN TOTAL'!AN4 -> 45380
A2: ='RESUMEN TOTAL'!A5 -> ALTAMIRA | B2: ='RESUMEN TOTAL'!B5 -> ALT01 | C2: ='RESUMEN TOTAL'!D5 -> Calchaqui y Sgto. Cabral | D2: ='RESUMEN TOTAL'!E5 -> Domo | E2: ='RESUMEN TOTAL'!F5 -> Fibra Optica | F2: ='RESUMEN TOTAL'!L5 -> 0 | G2: ='RESUMEN TOTAL'!M5 -> 0 | H2: ='RESUMEN TOTAL'!N5 -> 0 | I2: ='RESUMEN TOTAL'!O5 -> 0 | J2: ='RESUMEN TOTAL'!P5 -> 0 | K2: ='RESUMEN TOTAL'!Q5 -> 0 | L2: ='RESUMEN TOTAL'!R5 -> 0 | M2: ='RESUMEN TOTAL'!S5 -> 0 | ... AH2: ='RESUMEN TOTAL'!AN5 -> 0
A3: ='RESUMEN TOTAL'!A6 -> ALTAMIRA | B3: ='RESUMEN TOTAL'!B6 -> ALT02 | C3: ='RESUMEN TOTAL'!D6 -> Calchaqui y Lope de Vega | D3: ='RESUMEN TOTAL'!E6 -> Domo | E3: ='RESUMEN TOTAL'!F6 -> PTO A FO | F3: ='RESUMEN TOTAL'!L6 -> 0 | G3: ='RESUMEN TOTAL'!M6 -> 0 | H3: ='RESUMEN TOTAL'!N6 -> 0 | I3: ='RESUMEN TOTAL'!O6 -> 0 | J3: ='RESUMEN TOTAL'!P6 -> 0 | K3: ='RESUMEN TOTAL'!Q6 -> 0 | L3: ='RESUMEN TOTAL'!R6 -> 0 | M3: ='RESUMEN TOTAL'!S6 -> 0 | ... AH3: ='RESUMEN TOTAL'!AN6 -> 0
A4: ='RESUMEN TOTAL'!A7 -> ALTAMIRA | B4: ='RESUMEN TOTAL'!B7 -> ALT 03 | C4: ='RESUMEN TOTAL'!D7 -> Bombero Galarza y Necochea | D4: ='RESUMEN TOTAL'!E7 -> Domo | E4: ='RESUMEN TOTAL'!F7 -> Fibra Optica | F4: ='RESUMEN TOTAL'!L7 -> 0 | G4: ='RESUMEN TOTAL'!M7 -> 0 | H4: ='RESUMEN TOTAL'!N7 -> 0 | I4: ='RESUMEN TOTAL'!O7 -> 0 | J4: ='RESUMEN TOTAL'!P7 -> 0 | K4: ='RESUMEN TOTAL'!Q7 -> 0 | L4: ='RESUMEN TOTAL'!R7 -> 0 | M4: ='RESUMEN TOTAL'!S7 -> 0 | ... AH4: ='RESUMEN TOTAL'!AN7 -> 0
A5: ='RESUMEN TOTAL'!A8 -> ALTAMIRA | B5: ='RESUMEN TOTAL'!B8 -> ALT 04 | C5: ='RESUMEN TOTAL'!D8 -> Francia y Necochea | D5: ='RESUMEN TOTAL'!E8 -> Domo | E5: ='RESUMEN TOTAL'!F8 -> Fibra Optica | F5: ='RESUMEN TOTAL'!L8 -> 0 | G5: ='RESUMEN TOTAL'!M8 -> 0 | H5: ='RESUMEN TOTAL'!N8 -> 0 | I5: ='RESUMEN TOTAL'!O8 -> 0 | J5: ='RESUMEN TOTAL'!P8 -> 0 | K5: ='RESUMEN TOTAL'!Q8 -> 0 | L5: ='RESUMEN TOTAL'!R8 -> 0 | M5: ='RESUMEN TOTAL'!S8 -> 0 | ... AH5: ='RESUMEN TOTAL'!AN8 -> 0
A6: ='RESUMEN TOTAL'!A9 -> ALTAMIRA | B6: ='RESUMEN TOTAL'!B9 -> ALT05 | C6: ='RESUMEN TOTAL'!D9 -> Av. Calchaqui y Bombero Galarza | D6: ='RESUMEN TOTAL'!E9 -> Domo | E6: ='RESUMEN TOTAL'!F9 -> PTO A FO | F6: ='RESUMEN TOTAL'!L9 -> 0 | G6: ='RESUMEN TOTAL'!M9 -> 0 | H6: ='RESUMEN TOTAL'!N9 -> 0 | I6: ='RESUMEN TOTAL'!O9 -> 0 | J6: ='RESUMEN TOTAL'!P9 -> 0 | K6: ='RESUMEN TOTAL'!Q9 -> 0 | L6: ='RESUMEN TOTAL'!R9 -> 0 | M6: ='RESUMEN TOTAL'!S9 -> 0 | ... AH6: ='RESUMEN TOTAL'!AN9 -> 0
A7: ='RESUMEN TOTAL'!A10 -> ALTAMIRA | B7: ='RESUMEN TOTAL'!B10 -> ALT 06 | C7: ='RESUMEN TOTAL'!D10 -> LOPE DE VEGA Y NECOCHEA | D7: ='RESUMEN TOTAL'!E10 -> Domo | E7: ='RESUMEN TOTAL'!F10 -> PTO A FO | F7: ='RESUMEN TOTAL'!L10 -> 0 | G7: ='RESUMEN TOTAL'!M10 -> 0 | H7: ='RESUMEN TOTAL'!N10 -> 0 | I7: ='RESUMEN TOTAL'!O10 -> 0 | J7: ='RESUMEN TOTAL'!P10 -> 0 | K7: ='RESUMEN TOTAL'!Q10 -> 0 | L7: ='RESUMEN TOTAL'!R10 -> 0 | M7: ='RESUMEN TOTAL'!S10 -> 0 | ... AH7: ='RESUMEN TOTAL'!AN10 -> 0
A8: ='RESUMEN TOTAL'!A11 -> ALTAMIRA | B8: ='RESUMEN TOTAL'!B11 -> ALT07 | C8: ='RESUMEN TOTAL'!D11 -> AV. CALCHAQUI Y AV. DEL TRABAJO | D8: ='RESUMEN TOTAL'!E11 -> DOMO | E8: ='RESUMEN TOTAL'!F11 -> PTO A FO | F8: ='RESUMEN TOTAL'!L11 -> 0 | G8: ='RESUMEN TOTAL'!M11 -> 0 | H8: ='RESUMEN TOTAL'!N11 -> 0 | I8: ='RESUMEN TOTAL'!O11 -> 0 | J8: ='RESUMEN TOTAL'!P11 -> 0 | K8: ='RESUMEN TOTAL'!Q11 -> 0 | L8: ='RESUMEN TOTAL'!R11 -> 0 | M8: ='RESUMEN TOTAL'!S11 -> 0 | ... AH8: ='RESUMEN TOTAL'!AN11 -> 0
A9: ='RESUMEN TOTAL'!A12 -> ALTAMIRA | B9: ='RESUMEN TOTAL'!B12 -> ALT 08 | C9: ='RESUMEN TOTAL'!D12 -> HUMAITA Y NECOCHEA | D9: ='RESUMEN TOTAL'!E12 -> DOMO | E9: ='RESUMEN TOTAL'!F12 -> Fibra Optica | F9: ='RESUMEN TOTAL'!L12 -> 0 | G9: ='RESUMEN TOTAL'!M12 -> 0 | H9: ='RESUMEN TOTAL'!N12 -> 0 | I9: ='RESUMEN TOTAL'!O12 -> 0 | J9: ='RESUMEN TOTAL'!P12 -> 0 | K9: ='RESUMEN TOTAL'!Q12 -> 0 | L9: ='RESUMEN TOTAL'!R12 -> 0 | M9: ='RESUMEN TOTAL'!S12 -> 0 | ... AH9: ='RESUMEN TOTAL'!AN12 -> 0
A10: ='RESUMEN TOTAL'!A13 -> ALTAMIRA | B10: ='RESUMEN TOTAL'!B13 -> ALT 09 | C10: ='RESUMEN TOTAL'!D13 -> NECOCHEA Y CURUPAITY | D10: ='RESUMEN TOTAL'!E13 -> DOMO | E10: ='RESUMEN TOTAL'!F13 -> Fibra Optica | F10: ='RESUMEN TOTAL'!L13 -> 0 | G10: ='RESUMEN TOTAL'!M13 -> 0 | H10: ='RESUMEN TOTAL'!N13 -> 0 | I10: ='RESUMEN TOTAL'!O13 -> 0 | J10: ='RESUMEN TOTAL'!P13 -> 0 | K10: ='RESUMEN TOTAL'!Q13 -> 0 | L10: ='RESUMEN TOTAL'!R13 -> 0 | M10: ='RESUMEN TOTAL'!S13 -> 0 | ... AH10: ='RESUMEN TOTAL'!AN13 -> 0
A11: ='RESUMEN TOTAL'!A14 -> ALTAMIRA | B11: ='RESUMEN TOTAL'!B14 -> ALT 10 | C11: ='RESUMEN TOTAL'!D14 -> Calchaqui y Francia | D11: ='RESUMEN TOTAL'!E14 -> Domo | E11: ='RESUMEN TOTAL'!F14 -> Radio | F11: ='RESUMEN TOTAL'!L14 -> 0 | G11: ='RESUMEN TOTAL'!M14 -> 0 | H11: ='RESUMEN TOTAL'!N14 -> 0 | I11: ='RESUMEN TOTAL'!O14 -> 0 | J11: ='RESUMEN TOTAL'!P14 -> 0 | K11: ='RESUMEN TOTAL'!Q14 -> 0 | L11: ='RESUMEN TOTAL'!R14 -> 0 | M11: ='RESUMEN TOTAL'!S14 -> 0 | ... AH11: ='RESUMEN TOTAL'!AN14 -> 0
A12: ='RESUMEN TOTAL'!A15 -> AGUSTIN RAMIREZ | B12: ='RESUMEN TOTAL'!B15 -> ARA 01 | C12: ='RESUMEN TOTAL'!D15 -> Malambo y Tranquera | D12: ='RESUMEN TOTAL'!E15 -> Domo | E12: ='RESUMEN TOTAL'!F15 -> Fibra Optica | F12: ='RESUMEN TOTAL'!L15 -> 0 | G12: ='RESUMEN TOTAL'!M15 -> 0 | H12: ='RESUMEN TOTAL'!N15 -> 0 | I12: ='RESUMEN TOTAL'!O15 -> 0 | J12: ='RESUMEN TOTAL'!P15 -> 0 | K12: ='RESUMEN TOTAL'!Q15 -> 0 | L12: ='RESUMEN TOTAL'!R15 -> 0 | M12: ='RESUMEN TOTAL'!S15 -> 0 | ... AH12: ='RESUMEN TOTAL'!AN15 -> 0
... A315: ='RESUMEN TOTAL'!A318 -> SAN JORGE | B315: ='RESUMEN TOTAL'!B318 -> SJO 03 | C315: ='RESUMEN TOTAL'!D318 -> 517 Y 580 | D315: ='RESUMEN TOTAL'!E318 -> DOMO | E315: ='RESUMEN TOTAL'!F318 -> Radio | F315: ='RESUMEN TOTAL'!L318 -> 0 | G315: ='RESUMEN TOTAL'!M318 -> 0 | H315: ='RESUMEN TOTAL'!N318 -> 0 | I315: ='RESUMEN TOTAL'!O318 -> 0 | J315: ='RESUMEN TOTAL'!P318 -> 0 | K315: ='RESUMEN TOTAL'!Q318 -> 0 | L315: ='RESUMEN TOTAL'!R318 -> 0 | M315: ='RESUMEN TOTAL'!S318 -> 0 | ... AH315: ='RESUMEN TOTAL'!AN318 -> 0
A316: ='RESUMEN TOTAL'!A319 -> SAN JORGE | B316: ='RESUMEN TOTAL'!B319 -> SJO 04 | C316: ='RESUMEN TOTAL'!D319 -> 552 Y 519 | D316: ='RESUMEN TOTAL'!E319 -> DOMO | E316: ='RESUMEN TOTAL'!F319 -> Radio | F316: ='RESUMEN TOTAL'!L319 -> 0 | G316: ='RESUMEN TOTAL'!M319 -> 0 | H316: ='RESUMEN TOTAL'!O319 -> APAGADO | I316: ='RESUMEN TOTAL'!#REF! -> #REF! | J316: ='RESUMEN TOTAL'!P319 -> 0 | K316: ='RESUMEN TOTAL'!Q319 -> 0 | L316: ='RESUMEN TOTAL'!R319 -> 0 | M316: ='RESUMEN TOTAL'!S319 -> 0 | N316: ='RESUMEN TOTAL'!T319 -> 0 | O316: ='RESUMEN TOTAL'!U319 -> 0 | P316: ='RESUMEN TOTAL'!V319 -> 0 | Q316: ='RESUMEN TOTAL'!W319 -> 0 | ... AH316: ='RESUMEN TOTAL'!AN319 -> 0
A317: ='RESUMEN TOTAL'!A320 -> SAN JORGE | B317: ='RESUMEN TOTAL'!B320 -> SJO 09 (FIJA 1) | C317: ='RESUMEN TOTAL'!D320 -> 515 Y 566 | D317: ='RESUMEN TOTAL'!E320 -> Fija | E317: ='RESUMEN TOTAL'!F320 -> Radio | F317: ='RESUMEN TOTAL'!L320 -> 0 | G317: ='RESUMEN TOTAL'!M320 -> 0 | H317: ='RESUMEN TOTAL'!N320 -> 0 | I317: ='RESUMEN TOTAL'!O320 -> 0 | J317: ='RESUMEN TOTAL'!P320 -> 0 | K317: ='RESUMEN TOTAL'!Q320 -> 0 | L317: ='RESUMEN TOTAL'!R320 -> 0 | M317: ='RESUMEN TOTAL'!S320 -> 0 | ... AH317: ='RESUMEN TOTAL'!AN320 -> 0
A318: ='RESUMEN TOTAL'!A321 -> SAN JORGE | B318: ='RESUMEN TOTAL'!B321 -> SJO 10 (FIJA 2) | C318: ='RESUMEN TOTAL'!D321 -> 515 Y 566 | D318: ='RESUMEN TOTAL'!E321 -> Fija | E318: ='RESUMEN TOTAL'!F321 -> Radio | F318: ='RESUMEN TOTAL'!L321 -> 0 | G318: ='RESUMEN TOTAL'!M321 -> 0 | H318: ='RESUMEN TOTAL'!N321 -> 0 | I318: ='RESUMEN TOTAL'!O321 -> 0 | J318: ='RESUMEN TOTAL'!P321 -> 0 | K318: ='RESUMEN TOTAL'!Q321 -> 0 | L318: ='RESUMEN TOTAL'!R321 -> 0 | M318: ='RESUMEN TOTAL'!S321 -> 0 | ... AH318: ='RESUMEN TOTAL'!AN321 -> 0
A319: ='RESUMEN TOTAL'!A322 -> SAN JORGE | B319: ='RESUMEN TOTAL'!B322 -> SJO01 | C319: ='RESUMEN TOTAL'!D322 -> Calle 554 y 527 | D319: ='RESUMEN TOTAL'!E322 -> Domo | E319: ='RESUMEN TOTAL'!F322 -> Radio | F319: ='RESUMEN TOTAL'!L322 -> 0 | G319: ='RESUMEN TOTAL'!M322 -> 0 | H319: ='RESUMEN TOTAL'!N322 -> 0 | I319: ='RESUMEN TOTAL'!O322 -> 0 | J319: ='RESUMEN TOTAL'!P322 -> 0 | K319: ='RESUMEN TOTAL'!Q322 -> 0 | L319: ='RESUMEN TOTAL'!R322 -> 0 | M319: ='RESUMEN TOTAL'!S322 -> 0 | ... AH319: ='RESUMEN TOTAL'!AN322 -> 0
A320: ='RESUMEN TOTAL'!A323 -> SAN JORGE | B320: ='RESUMEN TOTAL'!B323 -> SJO02 | C320: ='RESUMEN TOTAL'!D323 -> Calle 554 y 511 | D320: ='RESUMEN TOTAL'!E323 -> Domo | E320: ='RESUMEN TOTAL'!F323 -> Radio | F320: ='RESUMEN TOTAL'!L323 -> 0 | G320: ='RESUMEN TOTAL'!M323 -> 0 | H320: ='RESUMEN TOTAL'!O323 -> APAGADO | I320: ='RESUMEN TOTAL'!#REF! -> #REF! | J320: ='RESUMEN TOTAL'!P323 -> 0 | K320: ='RESUMEN TOTAL'!Q323 -> 0 | L320: ='RESUMEN TOTAL'!R323 -> 0 | M320: ='RESUMEN TOTAL'!S323 -> 0 | N320: ='RESUMEN TOTAL'!T323 -> 0 | O320: ='RESUMEN TOTAL'!U323 -> 0 | P320: ='RESUMEN TOTAL'!V323 -> 0 | Q320: ='RESUMEN TOTAL'!W323 -> 0 | ... AH320: ='RESUMEN TOTAL'!AN323 -> 0
A321: ='RESUMEN TOTAL'!A324 -> SAN JORGE | B321: ='RESUMEN TOTAL'!B324 -> SJO05 (fija 1) | C321: ='RESUMEN TOTAL'!D324 -> 511 Y 560 | D321: ='RESUMEN TOTAL'!E324 -> Fija | E321: ='RESUMEN TOTAL'!F324 -> Fibra Optica | F321: ='RESUMEN TOTAL'!L324 -> APAGADO | G321: ='RESUMEN TOTAL'!M324 -> 0 | H321: ='RESUMEN TOTAL'!O324 -> APAGADO | I321: ='RESUMEN TOTAL'!#REF! -> #REF! | J321: ='RESUMEN TOTAL'!P324 -> 0 | K321: ='RESUMEN TOTAL'!Q324 -> 0 | L321: ='RESUMEN TOTAL'!R324 -> 0 | M321: ='RESUMEN TOTAL'!S324 -> 0 | N321: ='RESUMEN TOTAL'!T324 -> 0 | O321: ='RESUMEN TOTAL'!U324 -> 0 | P321: ='RESUMEN TOTAL'!V324 -> 0 | Q321: ='RESUMEN TOTAL'!W324 -> 0 | ... AH321: ='RESUMEN TOTAL'!AN324 -> 0
A322: ='RESUMEN TOTAL'!A325 -> SAN JORGE | B322: ='RESUMEN TOTAL'!B325 -> SJO06 (fija 2) | C322: ='RESUMEN TOTAL'!D325 -> 511 Y 560 | D322: ='RESUMEN TOTAL'!E325 -> Fija | E322: ='RESUMEN TOTAL'!F325 -> Fibra Optica | F322: ='RESUMEN TOTAL'!L325 -> APAGADO | G322: ='RESUMEN TOTAL'!M325 -> 0 | H322: ='RESUMEN TOTAL'!O325 -> APAGADO | I322: ='RESUMEN TOTAL'!#REF! -> #REF! | J322: ='RESUMEN TOTAL'!P325 -> 0 | K322: ='RESUMEN TOTAL'!Q325 -> 0 | L322: ='RESUMEN TOTAL'!R325 -> 0 | M322: ='RESUMEN TOTAL'!S325 -> 0 | N322: ='RESUMEN TOTAL'!T325 -> 0 | O322: ='RESUMEN TOTAL'!U325 -> 0 | P322: ='RESUMEN TOTAL'!V325 -> 0 | Q322: ='RESUMEN TOTAL'!W325 -> 0 | ... AH322: ='RESUMEN TOTAL'!AN325 -> 0
A323: ='RESUMEN TOTAL'!A326 -> SAN JORGE | B323: ='RESUMEN TOTAL'!B326 -> SJO07 (fija 1) | C323: ='RESUMEN TOTAL'!D326 -> 503 Y 556 | D323: ='RESUMEN TOTAL'!E326 -> Fija | E323: ='RESUMEN TOTAL'!F326 -> Fibra Optica | F323: ='RESUMEN TOTAL'!L326 -> APAGADO | G323: ='RESUMEN TOTAL'!M326 -> 0 | H323: ='RESUMEN TOTAL'!O326 -> APAGADO | I323: ='RESUMEN TOTAL'!#REF! -> #REF! | J323: ='RESUMEN TOTAL'!P326 -> 0 | K323: ='RESUMEN TOTAL'!Q326 -> 0 | L323: ='RESUMEN TOTAL'!R326 -> 0 | M323: ='RESUMEN TOTAL'!S326 -> 0 | N323: ='RESUMEN TOTAL'!T326 -> 0 | O323: ='RESUMEN TOTAL'!U326 -> 0 | P323: ='RESUMEN TOTAL'!V326 -> 0 | Q323: ='RESUMEN TOTAL'!W326 -> 0 | ... AH323: ='RESUMEN TOTAL'!AN326 -> 0
A324: ='RESUMEN TOTAL'!A327 -> SAN JORGE | B324: ='RESUMEN TOTAL'!B327 -> SJO08 (fija 2) | C324: ='RESUMEN TOTAL'!D327 -> 503 Y 556 | D324: ='RESUMEN TOTAL'!E327 -> Fija | E324: ='RESUMEN TOTAL'!F327 -> Fibra Optica | F324: ='RESUMEN TOTAL'!L327 -> APAGADO | G324: ='RESUMEN TOTAL'!M327 -> 0 | H324: ='RESUMEN TOTAL'!O327 -> APAGADO | I324: ='RESUMEN TOTAL'!#REF! -> #REF! | J324: ='RESUMEN TOTAL'!P327 -> 0 | K324: ='RESUMEN TOTAL'!Q327 -> 0 | L324: ='RESUMEN TOTAL'!R327 -> 0 | M324: ='RESUMEN TOTAL'!S327 -> 0 | N324: ='RESUMEN TOTAL'!T327 -> 0 | O324: ='RESUMEN TOTAL'!U327 -> 0 | P324: ='RESUMEN TOTAL'!V327 -> 0 | Q324: ='RESUMEN TOTAL'!W327 -> 0 | ... AH324: ='RESUMEN TOTAL'!AN327 -> 0
A325: ='RESUMEN TOTAL'!A328 -> SANTO TOMAS | B325: ='RESUMEN TOTAL'!B328 -> SJU01 | C325: ='RESUMEN TOTAL'!D328 -> Ruta 36 y Pte.Peron | D325: ='RESUMEN TOTAL'!E328 -> Domo | E325: ='RESUMEN TOTAL'!F328 -> Radio | F325: ='RESUMEN TOTAL'!L328 -> 0 | G325: ='RESUMEN TOTAL'!M328 -> 0 | H325: ='RESUMEN TOTAL'!N328 -> 0 | I325: ='RESUMEN TOTAL'!O328 -> 0 | J325: ='RESUMEN TOTAL'!P328 -> 0 | K325: ='RESUMEN TOTAL'!Q328 -> 0 | L325: ='RESUMEN TOTAL'!R328 -> 0 | M325: ='RESUMEN TOTAL'!S328 -> 0 | ... AH325: ='RESUMEN TOTAL'!AN328 -> 0
A326: ='RESUMEN TOTAL'!A329 -> VILLA GENERAL SAN MARTIN | B326: ='RESUMEN TOTAL'!B329 -> SMA01 | C326: ='RESUMEN TOTAL'!D329 -> Hudson y Montevideo | D326: ='RESUMEN TOTAL'!E329 -> DOMO | E326: ='RESUMEN TOTAL'!F329 -> Radio | F326: ='RESUMEN TOTAL'!L329 -> 0 | G326: ='RESUMEN TOTAL'!M329 -> 0 | H326: ='RESUMEN TOTAL'!N329 -> 0 | I326: ='RESUMEN TOTAL'!O329 -> 0 | J326: ='RESUMEN TOTAL'!P329 -> 0 | K326: ='RESUMEN TOTAL'!Q329 -> 0 | L326: ='RESUMEN TOTAL'!R329 -> 0 | M326: ='RESUMEN TOTAL'!S329 -> 0 | ... AH326: ='RESUMEN TOTAL'!AN329 -> 0
A327: ='RESUMEN TOTAL'!A330 -> VILLA GENERAL SAN MARTIN | B327: ='RESUMEN TOTAL'!B330 -> SMA02 | C327: ='RESUMEN TOTAL'!D330 -> Hudson y San Nicolas | D327: ='RESUMEN TOTAL'!E330 -> Domo | E327: ='RESUMEN TOTAL'!F330 -> Radio | F327: ='RESUMEN TOTAL'!L330 -> 0 | G327: ='RESUMEN TOTAL'!M330 -> 0 | H327: ='RESUMEN TOTAL'!N330 -> 0 | I327: ='RESUMEN TOTAL'!O330 -> 0 | J327: ='RESUMEN TOTAL'!P330 -> 0 | K327: ='RESUMEN TOTAL'!Q330 -> 0 | L327: ='RESUMEN TOTAL'!R330 -> 0 | M327: ='RESUMEN TOTAL'!S330 -> 0 | ... AH327: ='RESUMEN TOTAL'!AN330 -> 0
A328: ='RESUMEN TOTAL'!A331 -> VILLA GENERAL SAN MARTIN | B328: ='RESUMEN TOTAL'!B331 -> SMA 03 | C328: ='RESUMEN TOTAL'!D331 -> ROSARIO Y SAN NICOLAS | D328: ='RESUMEN TOTAL'!E331 -> Domo | E328: ='RESUMEN TOTAL'!F331 -> Radio | F328: ='RESUMEN TOTAL'!L331 -> 0 | G328: ='RESUMEN TOTAL'!M331 -> 0 | H328: ='RESUMEN TOTAL'!N331 -> 0 | I328: ='RESUMEN TOTAL'!O331 -> 0 | J328: ='RESUMEN TOTAL'!P331 -> 0 | K328: ='RESUMEN TOTAL'!Q331 -> 0 | L328: ='RESUMEN TOTAL'!R331 -> 0 | M328: ='RESUMEN TOTAL'!S331 -> 0 | ... AH328: ='RESUMEN TOTAL'!AN331 -> 0
A329: ='RESUMEN TOTAL'!A332 -> VILLA GENERAL SAN MARTIN | B329: ='RESUMEN TOTAL'!B332 -> SMA 04 | C329: ='RESUMEN TOTAL'!D332 -> HUDSON Y MONTEVIDEO | D329: ='RESUMEN TOTAL'!E332 -> FIJA | E329: ='RESUMEN TOTAL'!F332 -> Radio | F329: ='RESUMEN TOTAL'!L332 -> 0 | G329: ='RESUMEN TOTAL'!M332 -> 0 | H329: ='RESUMEN TOTAL'!N332 -> 0 | I329: ='RESUMEN TOTAL'!O332 -> 0 | J329: ='RESUMEN TOTAL'!P332 -> 0 | K329: ='RESUMEN TOTAL'!Q332 -> 0 | L329: ='RESUMEN TOTAL'!R332 -> 0 | M329: ='RESUMEN TOTAL'!S332 -> 0 | ... AH329: ='RESUMEN TOTAL'!AN332 -> 0
A330: ='RESUMEN TOTAL'!A333 -> VILLA GENERAL SAN MARTIN | B330: ='RESUMEN TOTAL'!B333 -> SMA05 | C330: ='RESUMEN TOTAL'!D333 -> MONTEVIDEO Y VILLEGAS | D330: ='RESUMEN TOTAL'!E333 -> DOMO | E330: ='RESUMEN TOTAL'!F333 -> PTO A FO | F330: ='RESUMEN TOTAL'!L333 -> 0 | G330: ='RESUMEN TOTAL'!M333 -> 0 | H330: ='RESUMEN TOTAL'!N333 -> 0 | I330: ='RESUMEN TOTAL'!O333 -> 0 | J330: ='RESUMEN TOTAL'!P333 -> 0 | K330: ='RESUMEN TOTAL'!Q333 -> 0 | L330: ='RESUMEN TOTAL'!R333 -> 0 | M330: ='RESUMEN TOTAL'!S333 -> 0 | ... AH330: ='RESUMEN TOTAL'!AN333 -> 0
A331: ='RESUMEN TOTAL'!A334 -> VILLA GENERAL SAN MARTIN | B331: ='RESUMEN TOTAL'!B334 -> SMA 06 | C331: ='RESUMEN TOTAL'!D334 -> AV. HUDSON Y RIO IGUAZU | D331: ='RESUMEN TOTAL'!E334 -> DOMO | E331: ='RESUMEN TOTAL'!F334 -> Fibra Optica | F331: ='RESUMEN TOTAL'!L334 -> 0 | G331: ='RESUMEN TOTAL'!M334 -> 0 | H331: ='RESUMEN TOTAL'!N334 -> 0 | I331: ='RESUMEN TOTAL'!O334 -> 0 | J331: ='RESUMEN TOTAL'!P334 -> 0 | K331: ='RESUMEN TOTAL'!Q334 -> 0 | L331: ='RESUMEN TOTAL'!R334 -> 0 | M331: ='RESUMEN TOTAL'!S334 -> 0 | ... AH331: ='RESUMEN TOTAL'!AN334 -> 0
A332: ='RESUMEN TOTAL'!A335 -> VILLA GENERAL SAN MARTIN | B332: ='RESUMEN TOTAL'!B335 -> SMA 07 | C332: ='RESUMEN TOTAL'!D335 -> AV. HUDSON Y RIO TURBIO | D332: ='RESUMEN TOTAL'!E335 -> DOMO | E332: ='RESUMEN TOTAL'!F335 -> Fibra Optica | F332: ='RESUMEN TOTAL'!L335 -> 0 | G332: ='RESUMEN TOTAL'!M335 -> 0 | H332: ='RESUMEN TOTAL'!N335 -> 0 | I332: ='RESUMEN TOTAL'!O335 -> 0 | J332: ='RESUMEN TOTAL'!P335 -> 0 | K332: ='RESUMEN TOTAL'!Q335 -> 0 | L332: ='RESUMEN TOTAL'!R335 -> 0 | M332: ='RESUMEN TOTAL'!S335 -> 0 | ... AH332: ='RESUMEN TOTAL'!AN335 -> 0
A333: ='RESUMEN TOTAL'!A336 -> SAN MARTIN | B333: ='RESUMEN TOTAL'!B336 -> SMA 08 | C333: ='RESUMEN TOTAL'!D336 -> 12 De Octubre y H. Lagos | D333: ='RESUMEN TOTAL'!E336 -> fija | E333: ='RESUMEN TOTAL'!F336 -> Fibra Optica | F333: ='RESUMEN TOTAL'!L336 -> APAGADO | G333: ='RESUMEN TOTAL'!M336 -> 0 | H333: ='RESUMEN TOTAL'!O336 -> APAGADO | I333: ='RESUMEN TOTAL'!#REF! -> #REF! | J333: ='RESUMEN TOTAL'!P336 -> 0 | K333: ='RESUMEN TOTAL'!Q336 -> 0 | L333: ='RESUMEN TOTAL'!R336 -> 0 | M333: ='RESUMEN TOTAL'!S336 -> 0 | N333: ='RESUMEN TOTAL'!T336 -> 0 | O333: ='RESUMEN TOTAL'!U336 -> 0 | P333: ='RESUMEN TOTAL'!V336 -> 0 | Q333: ='RESUMEN TOTAL'!W336 -> 0 | ... AH333: ='RESUMEN TOTAL'!AN336 -> 0
A334: ='RESUMEN TOTAL'!A337 -> SAN MARTIN | B334: ='RESUMEN TOTAL'!B337 -> SMA 09 | C334: ='RESUMEN TOTAL'!D337 -> 12 De Octubre y H. Lagos | D334: ='RESUMEN TOTAL'!E337 -> fija | E334: ='RESUMEN TOTAL'!F337 -> Fibra Optica | F334: ='RESUMEN TOTAL'!L337 -> APAGADO | G334: ='RESUMEN TOTAL'!M337 -> 0 | H334: ='RESUMEN TOTAL'!O337 -> APAGADO | I334: ='RESUMEN TOTAL'!#REF! -> #REF! | J334: ='RESUMEN TOTAL'!P337 -> 0 | K334: ='RESUMEN TOTAL'!Q337 -> 0 | L334: ='RESUMEN TOTAL'!R337 -> 0 | M334: ='RESUMEN TOTAL'!S337 -> 0 | N334: ='RESUMEN TOTAL'!T337 -> 0 | O334: ='RESUMEN TOTAL'!U337 -> 0 | P334: ='RESUMEN TOTAL'!V337 -> 0 | Q334: ='RESUMEN TOTAL'!W337 -> 0 | ... AH334: ='RESUMEN TOTAL'!AN337 -> 0
A335: ='RESUMEN TOTAL'!A338 -> SAN NICOLAS | B335: ='RESUMEN TOTAL'!B338 -> SNI01 (fija 1) | C335: ='RESUMEN TOTAL'!D338 -> SARRATEA E/ EEUU DE A. Y AGRELO | D335: ='RESUMEN TOTAL'!E338 -> Fija | E335: ='RESUMEN TOTAL'!F338 -> Fibra Optica | F335: ='RESUMEN TOTAL'!L338 -> 0 | G335: ='RESUMEN TOTAL'!M338 -> 0 | H335: ='RESUMEN TOTAL'!N338 -> 0 | I335: ='RESUMEN TOTAL'!O338 -> APAGADO | J335: ='RESUMEN TOTAL'!P338 -> 0 | K335: ='RESUMEN TOTAL'!Q338 -> 0 | L335: ='RESUMEN TOTAL'!R338 -> 0 | M335: ='RESUMEN TOTAL'!S338 -> 0 | ... AH335: ='RESUMEN TOTAL'!AN338 -> 0
A336: ='RESUMEN TOTAL'!A339 -> SAN NICOLAS | B336: ='RESUMEN TOTAL'!B339 -> SNI02 (fija 2) | C336: ='RESUMEN TOTAL'!D339 -> SARRATEA E/ EEUU DE A. Y AGRELO | D336: ='RESUMEN TOTAL'!E339 -> Fija | E336: ='RESUMEN TOTAL'!F339 -> Fibra Optica | F336: ='RESUMEN TOTAL'!L339 -> 0 | G336: ='RESUMEN TOTAL'!M339 -> 0 | H336: ='RESUMEN TOTAL'!N339 -> 0 | I336: ='RESUMEN TOTAL'!O339 -> APAGADO | J336: ='RESUMEN TOTAL'!P339 -> 0 | K336: ='RESUMEN TOTAL'!Q339 -> 0 | L336: ='RESUMEN TOTAL'!R339 -> 0 | M336: ='RESUMEN TOTAL'!S339 -> 0 | ... AH336: ='RESUMEN TOTAL'!AN339 -> 0
A337: ='RESUMEN TOTAL'!A340 -> SAN NICOLAS | B337: ='RESUMEN TOTAL'!B340 -> SNI 03 (fija 1) | C337: ='RESUMEN TOTAL'!D340 -> SARRATEA Y LOS TREBOLES | D337: ='RESUMEN TOTAL'!E340 -> Fija | E337: ='RESUMEN TOTAL'!F340 -> Fibra Optica | F337: ='RESUMEN TOTAL'!L340 -> 0 | G337: ='RESUMEN TOTAL'!M340 -> 0 | H337: ='RESUMEN TOTAL'!N340 -> 0 | I337: ='RESUMEN TOTAL'!O340 -> APAGADO | J337: ='RESUMEN TOTAL'!P340 -> 0 | K337: ='RESUMEN TOTAL'!Q340 -> 0 | L337: ='RESUMEN TOTAL'!R340 -> 0 | M337: ='RESUMEN TOTAL'!S340 -> 0 | ... AH337: ='RESUMEN TOTAL'!AN340 -> 0
A338: ='RESUMEN TOTAL'!A341 -> SAN NICOLAS | B338: ='RESUMEN TOTAL'!B341 -> SNI 04 (fija 2) | C338: ='RESUMEN TOTAL'!D341 -> SARRATEA Y LOS TREBOLES | D338: ='RESUMEN TOTAL'!E341 -> Fija | E338: ='RESUMEN TOTAL'!F341 -> Fibra Optica | F338: ='RESUMEN TOTAL'!L341 -> 0 | G338: ='RESUMEN TOTAL'!M341 -> 0 | H338: ='RESUMEN TOTAL'!N341 -> 0 | I338: ='RESUMEN TOTAL'!O341 -> APAGADO | J338: ='RESUMEN TOTAL'!P341 -> 0 | K338: ='RESUMEN TOTAL'!Q341 -> 0 | L338: ='RESUMEN TOTAL'!R341 -> 0 | M338: ='RESUMEN TOTAL'!S341 -> 0 | ... AH338: ='RESUMEN TOTAL'!AN341 -> 0
A339: ='RESUMEN TOTAL'!A342 -> SANTA ROSA | B339: ='RESUMEN TOTAL'!B342 -> SRO01 | C339: ='RESUMEN TOTAL'!D342 -> Yugoslavia y MilÃ¡n | D339: ='RESUMEN TOTAL'!E342 -> Domo | E339: ='RESUMEN TOTAL'!F342 -> Radio | F339: ='RESUMEN TOTAL'!L342 -> 0 | G339: ='RESUMEN TOTAL'!M342 -> 0 | H339: ='RESUMEN TOTAL'!N342 -> 0 | I339: ='RESUMEN TOTAL'!O342 -> 0 | J339: ='RESUMEN TOTAL'!P342 -> 0 | K339: ='RESUMEN TOTAL'!Q342 -> 0 | L339: ='RESUMEN TOTAL'!R342 -> 0 | M339: ='RESUMEN TOTAL'!S342 -> 0 | ... AH339: ='RESUMEN TOTAL'!AN342 -> 0
A340: ='RESUMEN TOTAL'!A343 -> ZONA RURAL SANTA ROSA | B340: ='RESUMEN TOTAL'!B343 -> SRO02 | C340: ='RESUMEN TOTAL'!D343 -> Bruselas y Calle 647 | D340: ='RESUMEN TOTAL'!E343 -> Domo | E340: ='RESUMEN TOTAL'!F343 -> Radio | F340: ='RESUMEN TOTAL'!L343 -> 0 | G340: ='RESUMEN TOTAL'!M343 -> 0 | H340: ='RESUMEN TOTAL'!N343 -> 0 | I340: ='RESUMEN TOTAL'!O343 -> 0 | J340: ='RESUMEN TOTAL'!P343 -> 0 | K340: ='RESUMEN TOTAL'!Q343 -> 0 | L340: ='RESUMEN TOTAL'!R343 -> 0 | M340: ='RESUMEN TOTAL'!S343 -> 0 | ... AH340: ='RESUMEN TOTAL'!AN343 -> 0
A341: ='RESUMEN TOTAL'!A344 -> SANTA ROSA | B341: ='RESUMEN TOTAL'!B344 -> SRO03 | C341: ='RESUMEN TOTAL'!D344 -> Eva Peron y Paysandu | D341: ='RESUMEN TOTAL'!E344 -> Domo | E341: ='RESUMEN TOTAL'!F344 -> Radio | F341: ='RESUMEN TOTAL'!L344 -> 0 | G341: ='RESUMEN TOTAL'!M344 -> 0 | H341: ='RESUMEN TOTAL'!N344 -> 0 | I341: ='RESUMEN TOTAL'!O344 -> 0 | J341: ='RESUMEN TOTAL'!P344 -> 0 | K341: ='RESUMEN TOTAL'!Q344 -> 0 | L341: ='RESUMEN TOTAL'!R344 -> 0 | M341: ='RESUMEN TOTAL'!S344 -> 0 | ... AH341: ='RESUMEN TOTAL'!AN344 -> 0
A342: ='RESUMEN TOTAL'!A345 -> SANTA ROSA | B342: ='RESUMEN TOTAL'!B345 -> SRO 04 | C342: ='RESUMEN TOTAL'!D345 -> Belgica y Andorra | D342: ='RESUMEN TOTAL'!E345 -> Domo | E342: ='RESUMEN TOTAL'!F345 -> Radio | F342: ='RESUMEN TOTAL'!L345 -> 0 | G342: ='RESUMEN TOTAL'!M345 -> 0 | H342: ='RESUMEN TOTAL'!N345 -> 0 | I342: ='RESUMEN TOTAL'!O345 -> 0 | J342: ='RESUMEN TOTAL'!P345 -> 0 | K342: ='RESUMEN TOTAL'!Q345 -> 0 | L342: ='RESUMEN TOTAL'!R345 -> 0 | M342: ='RESUMEN TOTAL'!S345 -> 0 | ... AH342: ='RESUMEN TOTAL'!AN345 -> 0
...

Sheet APAGADOS
E1: APAGADOS | F1: =COUNTIF(F3:F403, "APAGADO") -> 52 | G1: =COUNTIF(G3:G403, "APAGADO") -> 0 | H1: =COUNTIF(H3:H503, "APAGADO") -> 8 | I1: =COUNTIF(I3:I403, "APAGADO") -> 52 | J1: =COUNTIF(J3:J403, "APAGADO") -> 0 | K1: =COUNTIF(K3:K403, "APAGADO") -> 0 | L1: =COUNTIF(L3:L403, "APAGADO") -> 0 | M1: =COUNTIF(M3:M403, "APAGADO") -> 0 | N1: =COUNTIF(N3:N403, "APAGADO") -> 0 | O1: =COUNTIF(O3:O403, "APAGADO") -> 0 | P1: =COUNTIF(P3:P403, "APAGADO") -> 0 | ... AD1: =COUNTIF(AD3:AD403, "APAGADO") -> 0 | AE1: =COUNTIF(AE3:AE503, "APAGADO") -> 0 | AF1: =COUNTIF(AF3:AF403, "APAGADO") -> 0 | AG1: =COUNTIF(AG3:AG403, "APAGADO") -> 0 | AH1: =COUNTIF(AH3:AH403, "APAGADO") -> 0
A2: =ESTADISTICA!A1 -> Barrio | B2: =ESTADISTICA!B1 -> [Denominacion] | C2: =ESTADISTICA!C1 -> [Ubicacion] | D2: =ESTADISTICA!D1 -> [Tipo de Camara] | E2: =ESTADISTICA!E1 -> [Tipo de Conexion] | F2: =ESTADISTICA!F1 -> 45352 | G2: =ESTADISTICA!G1 -> 45353 | H2: =ESTADISTICA!H1 -> 45354 | ... AH2: =ESTADISTICA!AH1 -> 45380
A3: =ESTADISTICA!A2 -> ALTAMIRA | B3: =ESTADISTICA!B2 -> ALT01 | C3: =ESTADISTICA!C2 -> Calchaqui y Sgto. Cabral | D3: =ESTADISTICA!D2 -> Domo | E3: =ESTADISTICA!E2 -> Fibra Optica | F3: =ESTADISTICA!F2 -> 0 | G3: =ESTADISTICA!G2 -> 0 | H3: =ESTADISTICA!H2 -> 0 | ... AH3: =ESTADISTICA!AH2 -> 0
A4: =ESTADISTICA!A3 -> ALTAMIRA | B4: =ESTADISTICA!B3 -> ALT02 | C4: =ESTADISTICA!C3 -> Calchaqui y Lope de Vega | D4: =ESTADISTICA!D3 -> Domo | E4: =ESTADISTICA!E3 -> PTO A FO | F4: =ESTADISTICA!F3 -> 0 | G4: =ESTADISTICA!G3 -> 0 | H4: =ESTADISTICA!H3 -> 0 | ... AH4: =ESTADISTICA!AH3 -> 0
A5: =ESTADISTICA!A4 -> ALTAMIRA | B5: =ESTADISTICA!B4 -> ALT 03 | C5: =ESTADISTICA!C4 -> Bombero Galarza y Necochea | D5: =ESTADISTICA!D4 -> Domo | E5: =ESTADISTICA!E4 -> Fibra Optica | F5: =ESTADISTICA!F4 -> 0 | G5: =ESTADISTICA!G4 -> 0 | H5: =ESTADISTICA!H4 -> 0 | ... AH5: =ESTADISTICA!AH4 -> 0
A6: =ESTADISTICA!A5 -> ALTAMIRA | B6: =ESTADISTICA!B5 -> ALT 04 | C6: =ESTADISTICA!C5 -> Francia y Necochea | D6: =ESTADISTICA!D5 -> Domo | E6: =ESTADISTICA!E5 -> Fibra Optica | F6: =ESTADISTICA!F5 -> 0 | G6: =ESTADISTICA!G5 -> 0 | H6: =ESTADISTICA!H5 -> 0 | ... AH6: =ESTADISTICA!AH5 -> 0
A7: =ESTADISTICA!A6 -> ALTAMIRA | B7: =ESTADISTICA!B6 -> ALT05 | C7: =ESTADISTICA!C6 -> Av. Calchaqui y Bombero Galarza | D7: =ESTADISTICA!D6 -> Domo | E7: =ESTADISTICA!E6 -> PTO A FO | F7: =ESTADISTICA!F6 -> 0 | G7: =ESTADISTICA!G6 -> 0 | H7: =ESTADISTICA!H6 -> 0 | ... AH7: =ESTADISTICA!AH6 -> 0
A8: =ESTADISTICA!A7 -> ALTAMIRA | B8: =ESTADISTICA!B7 -> ALT 06 | C8: =ESTADISTICA!C7 -> LOPE DE VEGA Y NECOCHEA | D8: =ESTADISTICA!D7 -> Domo | E8: =ESTADISTICA!E7 -> PTO A FO | F8: =ESTADISTICA!F7 -> 0 | G8: =ESTADISTICA!G7 -> 0 | H8: =ESTADISTICA!H7 -> 0 | ... AH8: =ESTADISTICA!AH7 -> 0
A9: =ESTADISTICA!A8 -> ALTAMIRA | B9: =ESTADISTICA!B8 -> ALT07 | C9: =ESTADISTICA!C8 -> AV. CALCHAQUI Y AV. DEL TRABAJO | D9: =ESTADISTICA!D8 -> DOMO | E9: =ESTADISTICA!E8 -> PTO A FO | F9: =ESTADISTICA!F8 -> 0 | G9: =ESTADISTICA!G8 -> 0 | H9: =ESTADISTICA!H8 -> 0 | ... AH9: =ESTADISTICA!AH8 -> 0
A10: =ESTADISTICA!A9 -> ALTAMIRA | B10: =ESTADISTICA!B9 -> ALT 08 | C10: =ESTADISTICA!C9 -> HUMAITA Y NECOCHEA | D10: =ESTADISTICA!D9 -> DOMO | E10: =ESTADISTICA!E9 -> Fibra Optica | F10: =ESTADISTICA!F9 -> 0 | G10: =ESTADISTICA!G9 -> 0 | H10: =ESTADISTICA!H9 -> 0 | ... AH10: =ESTADISTICA!AH9 -> 0
A11: =ESTADISTICA!A10 -> ALTAMIRA | B11: =ESTADISTICA!B10 -> ALT 09 | C11: =ESTADISTICA!C10 -> NECOCHEA Y CURUPAITY | D11: =ESTADISTICA!D10 -> DOMO | E11: =ESTADISTICA!E10 -> Fibra Optica | F11: =ESTADISTICA!F10 -> 0 | G11: =ESTADISTICA!G10 -> 0 | H11: =ESTADISTICA!H10 -> 0 | ... AH11: =ESTADISTICA!AH10 -> 0
A12: =ESTADISTICA!A11 -> ALTAMIRA | B12: =ESTADISTICA!B11 -> ALT 10 | C12: =ESTADISTICA!C11 -> Calchaqui y Francia | D12: =ESTADISTICA!D11 -> Domo | E12: =ESTADISTICA!E11 -> Radio | F12: =ESTADISTICA!F11 -> 0 | G12: =ESTADISTICA!G11 -> 0 | H12: =ESTADISTICA!H11 -> 0 | ... AH12: =ESTADISTICA!AH11 -> 0
A13: =ESTADISTICA!A12 -> AGUSTIN RAMIREZ | B13: =ESTADISTICA!B12 -> ARA 01 | C13: =ESTADISTICA!C12 -> Malambo y Tranquera | D13: =ESTADISTICA!D12 -> Domo | E13: =ESTADISTICA!E12 -> Fibra Optica | F13: =ESTADISTICA!F12 -> 0 | G13: =ESTADISTICA!G12 -> 0 | H13: =ESTADISTICA!H12 -> 0 | ... AH13: =ESTADISTICA!AH12 -> 0
... A207: =ESTADISTICA!A206 -> LOPEZ ROMERO | B207: =ESTADISTICA!B206 -> MFI02 | C207: =ESTADISTICA!C206 -> Calchaqui y Balcarce | D207: =ESTADISTICA!D206 -> Fija | E207: =ESTADISTICA!E206 -> Fibra Optica | F207: =ESTADISTICA!F206 -> 0 | G207: =ESTADISTICA!G206 -> 0 | H207: =ESTADISTICA!H206 -> 0 | ... AH207: =ESTADISTICA!AH206 -> 0
A208: =ESTADISTICA!A208 -> MARTIN FIERRO | B208: =ESTADISTICA!B208 -> MFI04 | C208: =ESTADISTICA!C208 -> Calchaqui y balcarce | D208: =ESTADISTICA!D208 -> Domo | E208: =ESTADISTICA!E208 -> Fibra Optica | F208: =ESTADISTICA!F208 -> 0 | G208: =ESTADISTICA!G208 -> 0 | H208: =ESTADISTICA!H208 -> 0 | ... AH208: =ESTADISTICA!AH208 -> 0
A209: =ESTADISTICA!A209 -> SAN EMILIO | B209: =ESTADISTICA!B209 -> MFI 05 | C209: =ESTADISTICA!C209 -> Cno. Gral. Belgrano y Guayaquil | D209: =ESTADISTICA!D209 -> Domo | E209: =ESTADISTICA!E209 -> Fibra Optica | F209: =ESTADISTICA!F209 -> 0 | G209: =ESTADISTICA!G209 -> 0 | H209: =ESTADISTICA!H209 -> 0 | ... AH209: =ESTADISTICA!AH209 -> 0
A210: =ESTADISTICA!A210 -> SAN EMILIO | B210: =ESTADISTICA!B210 -> MFI06 | C210: =ESTADISTICA!C210 -> Con. Gral. Belgrano y Bombero Galarza | D210: =ESTADISTICA!D210 -> DOMO | E210: =ESTADISTICA!E210 -> Radio | F210: =ESTADISTICA!F210 -> APAGADO | G210: =ESTADISTICA!G210 -> 0 | H210: =ESTADISTICA!H210 -> 0 | ... AH210: =ESTADISTICA!AH210 -> 0
A211: =ESTADISTICA!A211 -> MARTIN FIERRO | B211: =ESTADISTICA!B211 -> MFI 07 | C211: =ESTADISTICA!C211 -> Sargento Cabral y Carlos Gardel | D211: =ESTADISTICA!D211 -> Domo | E211: =ESTADISTICA!E211 -> PTO A FO | F211: =ESTADISTICA!F211 -> 0 | G211: =ESTADISTICA!G211 -> 0 | H211: =ESTADISTICA!H211 -> 0 | ... AH211: =ESTADISTICA!AH211 -> 0
A212: =ESTADISTICA!A212 -> MARTIN FIERRO | B212: =ESTADISTICA!B212 -> MFI 08 | C212: =ESTADISTICA!C212 -> Braile y Batalla de Callao | D212: =ESTADISTICA!D212 -> Domo | E212: =ESTADISTICA!E212 -> PTO A FO | F212: =ESTADISTICA!F212 -> 0 | G212: =ESTADISTICA!G212 -> 0 | H212: =ESTADISTICA!H212 -> 0 | ... AH212: =ESTADISTICA!AH212 -> 0
A213: =ESTADISTICA!A213 -> GOBERNADOR MONTEVERDE | B213: =ESTADISTICA!B213 -> MON01 | C213: =ESTADISTICA!C213 -> San Martin y Patricias Argentinas | D213: =ESTADISTICA!D213 -> Fija | E213: =ESTADISTICA!E213 -> Fibra Optica | F213: =ESTADISTICA!F213 -> 0 | G213: =ESTADISTICA!G213 -> 0 | H213: =ESTADISTICA!H213 -> 0 | ... AH213: =ESTADISTICA!AH213 -> 0
A214: =ESTADISTICA!A214 -> GOBERNADOR MONTEVERDE | B214: =ESTADISTICA!B214 -> MON02 | C214: =ESTADISTICA!C214 -> Senzabello y Famatina | D214: =ESTADISTICA!D214 -> Domo | E214: =ESTADISTICA!E214 -> Radio | F214: =ESTADISTICA!F214 -> APAGADO | G214: =ESTADISTICA!G214 -> 0 | H214: =ESTADISTICA!H214 -> 0 | ... AH214: =ESTADISTICA!AH214 -> 0
A215: =ESTADISTICA!A215 -> GOBERNADOR MONTEVERDE | B215: =ESTADISTICA!B215 -> MON03 | C215: =ESTADISTICA!C215 -> Senzabello y Guemes | D215: =ESTADISTICA!D215 -> Domo | E215: =ESTADISTICA!E215 -> Radio | F215: =ESTADISTICA!F215 -> 0 | G215: =ESTADISTICA!G215 -> 0 | H215: =ESTADISTICA!H215 -> 0 | ... AH215: =ESTADISTICA!AH215 -> 0
A216: =ESTADISTICA!A216 -> GOBERNADOR MONTEVERDE | B216: =ESTADISTICA!B216 -> MON04 | C216: =ESTADISTICA!C216 -> Av. Yrigoyen y San Lorenzo | D216: =ESTADISTICA!D216 -> Domo | E216: =ESTADISTICA!E216 -> Radio | F216: =ESTADISTICA!F216 -> 0 | G216: =ESTADISTICA!G216 -> 0 | H216: =ESTADISTICA!H216 -> 0 | ... AH216: =ESTADISTICA!AH216 -> 0
A217: =ESTADISTICA!A217 -> 9 DE JULIO | B217: =ESTADISTICA!B217 -> NJU 01 | C217: =ESTADISTICA!C217 -> Sallares y Parrillo | D217: =ESTADISTICA!D217 -> Domo | E217: =ESTADISTICA!E217 -> Fibra Optica | F217: =ESTADISTICA!F217 -> 0 | G217: =ESTADISTICA!G217 -> 0 | H217: =ESTADISTICA!H217 -> 0 | ... AH217: =ESTADISTICA!AH217 -> 0
A218: =ESTADISTICA!A218 -> 9 DE JULIO | B218: =ESTADISTICA!B218 -> NJU02 | C218: =ESTADISTICA!C218 -> Ituzaingo y Boccuzzi | D218: =ESTADISTICA!D218 -> Domo | E218: =ESTADISTICA!E218 -> Radio | F218: =ESTADISTICA!F218 -> 0 | G218: =ESTADISTICA!G218 -> 0 | H218: =ESTADISTICA!H218 -> 0 | ... AH218: =ESTADISTICA!AH218 -> 0
A219: =ESTADISTICA!A219 -> 9 DE JULIO | B219: =ESTADISTICA!B219 -> NJU03 | C219: =ESTADISTICA!C219 -> San Juan y Parrillo | D219: =ESTADISTICA!D219 -> Domo | E219: =ESTADISTICA!E219 -> PTO A FO | F219: =ESTADISTICA!F219 -> 0 | G219: =ESTADISTICA!G219 -> 0 | H219: =ESTADISTICA!H219 -> 0 | ... AH219: =ESTADISTICA!AH219 -> 0
... A516: =ESTADISTICA!A516 -> PARADAS SEGURAS | B516: =ESTADISTICA!B516 -> 39 C | C516: =ESTADISTICA!C516 -> Hudson y Groussac Este | D516: =ESTADISTICA!D516 -> GFIJA | E516: =ESTADISTICA!E516 -> GPON | F516: =ESTADISTICA!F516 -> APAGADO | G516: =ESTADISTICA!G516 -> 0 | H516: =ESTADISTICA!H516 -> 0 | ... AH516: =ESTADISTICA!AH516 -> 0

Sheet APAGADOS FIBRA
C1: TOTAL FIBRA | D1: =COUNTIFS(E4:E401,"=Fibra Optica") -> 270
E2: APAGADOS | F2: =COUNTIFS(F4:F501, "=APAGADO",E4:E501,"=Fibra Optica") -> 45 | G2: =COUNTIFS(G4:G501, "=APAGADO",E4:E501,"=Fibra Optica") -> 0 | H2: =COUNTIFS(H4:H501, "=APAGADO",E4:E501,"=Fibra Optica") -> 6 | I2: =COUNTIFS(I4:I501, "=APAGADO",E4:E501,"=Fibra Optica") -> 44 | J2: =COUNTIFS(J4:J501, "=APAGADO",E4:E501,"=Fibra Optica") -> 0 | K2: =COUNTIFS(K4:K501, "=APAGADO",E4:E501,"=Fibra Optica") -> 0 | L2: =COUNTIFS(L4:L501, "=APAGADO",E4:E501,"=Fibra Optica") -> 0 | M2: =COUNTIFS(M4:M501, "=APAGADO",E4:E501,"=Fibra Optica") -> 0 | N2: =COUNTIFS(N4:N501, "=APAGADO",E4:E501,"=Fibra Optica") -> 0 | O2: =COUNTIFS(O4:O501, "=APAGADO",E4:E501,"=Fibra Optica") -> 0 | P2: =COUNTIFS(P4:P601, "=APAGADO",E4:E601,"=Fibra Optica") -> 0 | Q2: =COUNTIFS(Q4:Q501, "=APAGADO",E4:E501,"=Fibra Optica") -> 0 | R2: =COUNTIFS(R4:R501, "=APAGADO",E4:E501,"=Fibra Optica") -> 0 | S2: =COUNTIFS(S4:S501, "=APAGADO",E4:E501,"=Fibra Optica") -> 0 | T2: =COUNTIFS(T4:T501, "=APAGADO",E4:E501,"=Fibra Optica") -> 0 | U2: =COUNTIFS(U4:U501, "=APAGADO",E4:E501,"=Fibra Optica") -> 0 | V2: =COUNTIFS(V4:V501, "=APAGADO",E4:E501,"=Fibra Optica") -> 0 | W2: =COUNTIFS(W4:W501, "=APAGADO",E4:E501,"=Fibra Optica") -> 0 | X2: =COUNTIFS(X4:X501, "=APAGADO",E4:E501,"=Fibra Optica") -> 0 | Y2: =COUNTIFS(Y4:Y501, "=APAGADO",E4:E501,"=Fibra Optica") -> 0 | Z2: =COUNTIFS(Z4:Z501, "=APAGADO",E4:E501,"=Fibra Optica") -> 0 | AA2: =COUNTIFS(AA4:AA501, "=APAGADO",E4:E501,"=Fibra Optica") -> 0 | AB2: =COUNTIFS(AB4:AB501, "=APAGADO",E4:E501,"=Fibra Optica") -> 0 | AC2: =COUNTIFS(AC4:AC601, "=APAGADO",E4:E601,"=Fibra Optica") -> 0 | AD2: =COUNTIFS(AD4:AD501, "=APAGADO",E4:E501,"=Fibra Optica") -> 0 | AE2: =COUNTIFS(AE4:AE501, "=APAGADO",E4:E501,"=Fibra Optica") -> 0 | AF2: =COUNTIFS(AF4:AF501, "=APAGADO",E4:E501,"=Fibra Optica") -> 0 | AG2: =COUNTIFS(AG4:AG501, "=APAGADO",E4:E501,"=Fibra Optica") -> 0 | AH2: =COUNTIFS(AH4:AH501, "=APAGADO",E4:E501,"=Fibra Optica") -> 0 | AI2: =COUNTIFS(AI4:AI501, "=APAGADO",F4:F501,"=Fibra Optica") -> 0 | AJ2: =COUNTIFS(AJ4:AJ501, "=APAGADO",G4:G501,"=Fibra Optica") -> 0
A3: =ESTADISTICA!A1 -> Barrio | B3: =ESTADISTICA!B1 -> [Denominacion] | C3: =ESTADISTICA!C1 -> [Ubicacion] | D3: =ESTADISTICA!D1 -> [Tipo de Camara] | E3: =ESTADISTICA!E1 -> [Tipo de Conexion] | F3: =ESTADISTICA!F1 -> 45352 | G3: =ESTADISTICA!G1 -> 45353 | H3: =ESTADISTICA!H1 -> 45354 | ... AI3: =ESTADISTICA!AI1 -> 0
A4: ='RESUMEN TOTAL'!A7 -> ALTAMIRA | B4: ='RESUMEN TOTAL'!B7 -> ALT 03 | C4: ='RESUMEN TOTAL'!D7 -> Bombero Galarza y Necochea | D4: ='RESUMEN TOTAL'!E7 -> Domo | E4: ='RESUMEN TOTAL'!F7 -> Fibra Optica | F4: ='RESUMEN TOTAL'!L7 -> 0 | G4: ='RESUMEN TOTAL'!M7 -> 0 | H4: ='RESUMEN TOTAL'!N7 -> 0 | I4: ='RESUMEN TOTAL'!O7 -> 0 | J4: ='RESUMEN TOTAL'!P7 -> 0 | K4: ='RESUMEN TOTAL'!Q7 -> 0 | L4: ='RESUMEN TOTAL'!R7 -> 0 | M4: ='RESUMEN TOTAL'!S7 -> 0 | ... AH4: ='RESUMEN TOTAL'!AN7 -> 0
A5: ='RESUMEN TOTAL'!A8 -> ALTAMIRA | B5: ='RESUMEN TOTAL'!B8 -> ALT 04 | C5: ='RESUMEN TOTAL'!D8 -> Francia y Necochea | D5: ='RESUMEN TOTAL'!E8 -> Domo | E5: ='RESUMEN TOTAL'!F8 -> Fibra Optica | F5: ='RESUMEN TOTAL'!L8 -> 0 | G5: ='RESUMEN TOTAL'!M8 -> 0 | H5: ='RESUMEN TOTAL'!N8 -> 0 | I5: ='RESUMEN TOTAL'!O8 -> 0 | J5: ='RESUMEN TOTAL'!P8 -> 0 | K5: ='RESUMEN TOTAL'!Q8 -> 0 | L5: ='RESUMEN TOTAL'!R8 -> 0 | M5: ='RESUMEN TOTAL'!S8 -> 0 | ... AH5: ='RESUMEN TOTAL'!AN8 -> 0
A6: ='RESUMEN TOTAL'!A9 -> ALTAMIRA | B6: ='RESUMEN TOTAL'!B9 -> ALT05 | C6: ='RESUMEN TOTAL'!D9 -> Av. Calchaqui y Bombero Galarza | D6: ='RESUMEN TOTAL'!E9 -> Domo | E6: ='RESUMEN TOTAL'!F9 -> PTO A FO | F6: ='RESUMEN TOTAL'!L9 -> 0 | G6: ='RESUMEN TOTAL'!M9 -> 0 | H6: ='RESUMEN TOTAL'!N9 -> 0 | I6: ='RESUMEN TOTAL'!O9 -> 0 | J6: ='RESUMEN TOTAL'!P9 -> 0 | K6: ='RESUMEN TOTAL'!Q9 -> 0 | L6: ='RESUMEN TOTAL'!R9 -> 0 | M6: ='RESUMEN TOTAL'!S9 -> 0 | ... AH6: ='RESUMEN TOTAL'!AN9 -> 0
A7: ='RESUMEN TOTAL'!A10 -> ALTAMIRA | B7: ='RESUMEN TOTAL'!B10 -> ALT 06 | C7: ='RESUMEN TOTAL'!D10 -> LOPE DE VEGA Y NECOCHEA | D7: ='RESUMEN TOTAL'!E10 -> Domo | E7: ='RESUMEN TOTAL'!F10 -> PTO A FO | F7: ='RESUMEN TOTAL'!L10 -> 0 | G7: ='RESUMEN TOTAL'!M10 -> 0 | H7: ='RESUMEN TOTAL'!N10 -> 0 | I7: ='RESUMEN TOTAL'!O10 -> 0 | J7: ='RESUMEN TOTAL'!P10 -> 0 | K7: ='RESUMEN TOTAL'!Q10 -> 0 | L7: ='RESUMEN TOTAL'!R10 -> 0 | M7: ='RESUMEN TOTAL'!S10 -> 0 | ... AH7: ='RESUMEN TOTAL'!AN10 -> 0
A8: ='RESUMEN TOTAL'!A11 -> ALTAMIRA | B8: ='RESUMEN TOTAL'!B11 -> ALT07 | C8: ='RESUMEN TOTAL'!D11 -> AV. CALCHAQUI Y AV. DEL TRABAJO | D8: ='RESUMEN TOTAL'!E11 -> DOMO | E8: ='RESUMEN TOTAL'!F11 -> PTO A FO | F8: ='RESUMEN TOTAL'!L11 -> 0 | G8: ='RESUMEN TOTAL'!M11 -> 0 | H8: ='RESUMEN TOTAL'!N11 -> 0 | I8: ='RESUMEN TOTAL'!O11 -> 0 | J8: ='RESUMEN TOTAL'!P11 -> 0 | K8: ='RESUMEN TOTAL'!Q11 -> 0 | L8: ='RESUMEN TOTAL'!R11 -> 0 | M8: ='RESUMEN TOTAL'!S11 -> 0 | ... AH8: ='RESUMEN TOTAL'!AN11 -> 0
A9: ='RESUMEN TOTAL'!A12 -> ALTAMIRA | B9: ='RESUMEN TOTAL'!B12 -> ALT 08 | C9: ='RESUMEN TOTAL'!D12 -> HUMAITA Y NECOCHEA | D9: ='RESUMEN TOTAL'!E12 -> DOMO | E9: ='RESUMEN TOTAL'!F12 -> Fibra Optica | F9: ='RESUMEN TOTAL'!L12 -> 0 | G9: ='RESUMEN TOTAL'!M12 -> 0 | H9: ='RESUMEN TOTAL'!N12 -> 0 | I9: ='RESUMEN TOTAL'!O12 -> 0 | J9: ='RESUMEN TOTAL'!P12 -> 0 | K9: ='RESUMEN TOTAL'!Q12 -> 0 | L9: ='RESUMEN TOTAL'!R12 -> 0 | M9: ='RESUMEN TOTAL'!S12 -> 0 | ... AH9: ='RESUMEN TOTAL'!AN12 -> 0
A10: ='RESUMEN TOTAL'!A13 -> ALTAMIRA | B10: ='RESUMEN TOTAL'!B13 -> ALT 09 | C10: ='RESUMEN TOTAL'!D13 -> NECOCHEA Y CURUPAITY | D10: ='RESUMEN TOTAL'!E13 -> DOMO | E10: ='RESUMEN TOTAL'!F13 -> Fibra Optica | F10: ='RESUMEN TOTAL'!L13 -> 0 | G10: ='RESUMEN TOTAL'!M13 -> 0 | H10: ='RESUMEN TOTAL'!N13 -> 0 | I10: ='RESUMEN TOTAL'!O13 -> 0 | J10: ='RESUMEN TOTAL'!P13 -> 0 | K10: ='RESUMEN TOTAL'!Q13 -> 0 | L10: ='RESUMEN TOTAL'!R13 -> 0 | M10: ='RESUMEN TOTAL'!S13 -> 0 | ... AH10: ='RESUMEN TOTAL'!AN13 -> 0
A11: ='RESUMEN TOTAL'!A14 -> ALTAMIRA | B11: ='RESUMEN TOTAL'!B14 -> ALT 10 | C11: ='RESUMEN TOTAL'!D14 -> Calchaqui y Francia | D11: ='RESUMEN TOTAL'!E14 -> Domo | E11: ='RESUMEN TOTAL'!F14 -> Radio | F11: ='RESUMEN TOTAL'!L14 -> 0 | G11: ='RESUMEN TOTAL'!M14 -> 0 | H11: ='RESUMEN TOTAL'!N14 -> 0 | I11: ='RESUMEN TOTAL'!O14 -> 0 | J11: ='RESUMEN TOTAL'!P14 -> 0 | K11: ='RESUMEN TOTAL'!Q14 -> 0 | L11: ='RESUMEN TOTAL'!R14 -> 0 | M11: ='RESUMEN TOTAL'!S14 -> 0 | ... AH11: ='RESUMEN TOTAL'!AN14 -> 0
A12: ='RESUMEN TOTAL'!A15 -> AGUSTIN RAMIREZ | B12: ='RESUMEN TOTAL'!B15 -> ARA 01 | C12: ='RESUMEN TOTAL'!D15 -> Malambo y Tranquera | D12: ='RESUMEN TOTAL'!E15 -> Domo | E12: ='RESUMEN TOTAL'!F15 -> Fibra Optica | F12: ='RESUMEN TOTAL'!L15 -> 0 | G12: ='RESUMEN TOTAL'!M15 -> 0 | H12: ='RESUMEN TOTAL'!N15 -> 0 | I12: ='RESUMEN TOTAL'!O15 -> 0 | J12: ='RESUMEN TOTAL'!P15 -> 0 | K12: ='RESUMEN TOTAL'!Q15 -> 0 | L12: ='RESUMEN TOTAL'!R15 -> 0 | M12: ='RESUMEN TOTAL'!S15 -> 0 | ... AH12: ='RESUMEN TOTAL'!AN15 -> 0
A13: ='RESUMEN TOTAL'!A16 -> BELGRANO | B13: ='RESUMEN TOTAL'!B16 -> BEL 01 | C13: ='RESUMEN TOTAL'!D16 -> San Martin y Dardo Rocha | D13: ='RESUMEN TOTAL'!E16 -> DOMO | E13: ='RESUMEN TOTAL'!F16 -> Fibra Optica | F13: ='RESUMEN TOTAL'!L16 -> APAGADO | G13: ='RESUMEN TOTAL'!M16 -> 0 | H13: ='RESUMEN TOTAL'!N16 -> 0 | I13: ='RESUMEN TOTAL'!O16 -> APAGADO | J13: ='RESUMEN TOTAL'!P16 -> 0 | K13: ='RESUMEN TOTAL'!Q16 -> 0 | L13: ='RESUMEN TOTAL'!R16 -> 0 | M13: ='RESUMEN TOTAL'!S16 -> 0 | ... AH13: ='RESUMEN TOTAL'!AN16 -> 0
A14: ='RESUMEN TOTAL'!A17 -> BELGRANO | B14: ='RESUMEN TOTAL'!B17 -> BEL 02 | C14: ='RESUMEN TOTAL'!D17 -> Guardia vieja y Fronteriz | D14: ='RESUMEN TOTAL'!E17 -> DOMO | E14: ='RESUMEN TOTAL'!F17 -> Fibra Optica | F14: ='RESUMEN TOTAL'!L17 -> 0 | G14: ='RESUMEN TOTAL'!M17 -> 0 | H14: ='RESUMEN TOTAL'!N17 -> 0 | I14: ='RESUMEN TOTAL'!O17 -> 0 | J14: ='RESUMEN TOTAL'!P17 -> 0 | K14: ='RESUMEN TOTAL'!Q17 -> 0 | L14: ='RESUMEN TOTAL'!R17 -> 0 | M14: ='RESUMEN TOTAL'!S17 -> 0 | ... AH14: ='RESUMEN TOTAL'!AN17 -> 0
A15: ='RESUMEN TOTAL'!A18 -> BOSQUES CENTRO | B15: ='RESUMEN TOTAL'!B18 -> BOSQC 01 | C15: ='RESUMEN TOTAL'!D18 -> LUIS AGOTE E/DANUNCIO Y CAMPOAMOR | D15: ='RESUMEN TOTAL'!E18 -> Fija | E15: ='RESUMEN TOTAL'!F18 -> Radio | F15: ='RESUMEN TOTAL'!L18 -> 0 | G15: ='RESUMEN TOTAL'!M18 -> 0 | H15: ='RESUMEN TOTAL'!N18 -> 0 | I15: ='RESUMEN TOTAL'!O18 -> 0 | J15: ='RESUMEN TOTAL'!P18 -> 0 | K15: ='RESUMEN TOTAL'!Q18 -> 0 | L15: ='RESUMEN TOTAL'!R18 -> 0 | M15: ='RESUMEN TOTAL'!S18 -> 0 | ... AH15: ='RESUMEN TOTAL'!AN18 -> 0
... A67: ='RESUMEN TOTAL'!A70 -> CENTRO | B67: ='RESUMEN TOTAL'!B70 -> CEN47 | C67: ='RESUMEN TOTAL'!D70 -> Sallares y Brown | D67: ='RESUMEN TOTAL'!E70 -> Domo | E67: ='RESUMEN TOTAL'!F70 -> Fibra Optica | F67: ='RESUMEN TOTAL'!L70 -> 0 | G67: ='RESUMEN TOTAL'!M70 -> 0 | H67: ='RESUMEN TOTAL'!N70 -> 0 | I67: ='RESUMEN TOTAL'!O70 -> 0 | J67: ='RESUMEN TOTAL'!P70 -> 0 | K67: ='RESUMEN TOTAL'!Q70 -> 0 | L67: ='RESUMEN TOTAL'!R70 -> 0 | M67: ='RESUMEN TOTAL'!S70 -> 0 | ... AH67: ='RESUMEN TOTAL'!AN70 -> 0
A68: ='RESUMEN TOTAL'!A71 -> CENTRO | B68: ='RESUMEN TOTAL'!B71 -> CEN48 | C68: ='RESUMEN TOTAL'!D71 -> Velez Sarsfield y Las Heras | D68: ='RESUMEN TOTAL'!E71 -> Domo | E68: ='RESUMEN TOTAL'!F71 -> Radio | F68: ='RESUMEN TOTAL'!L71 -> APAGADO | G68: ='RESUMEN TOTAL'!M71 -> 0 | H68: ='RESUMEN TOTAL'!N71 -> 0 | I68: ='RESUMEN TOTAL'!O71 -> 0 | J68: ='RESUMEN TOTAL'!P71 -> 0 | K68: ='RESUMEN TOTAL'!Q71 -> 0 | L68: ='RESUMEN TOTAL'!R71 -> 0 | M68: ='RESUMEN TOTAL'!S71 -> 0 | ... Z68: ='RESUMEN TOTAL'!AF71 -> 0 | AA68: ='RESUMEN TOTAL'!AG548 -> 0 | AB68: ='RESUMEN TOTAL'!AH71 -> 0 | AC68: ='RESUMEN TOTAL'!AI71 -> 0 | AD68: ='RESUMEN TOTAL'!AJ71 -> 0 | AE68: ='RESUMEN TOTAL'!AK71 -> 0 | AF68: ='RESUMEN TOTAL'!AL71 -> 0 | AG68: ='RESUMEN TOTAL'!AM71 -> 0 | AH68: ='RESUMEN TOTAL'!AN71 -> 0
A69: ='RESUMEN TOTAL'!A72 -> CENTRO | B69: ='RESUMEN TOTAL'!B72 -> CEN49 | C69: ='RESUMEN TOTAL'!D72 -> Av. San Martin y Florencio Sanchez | D69: ='RESUMEN TOTAL'!E72 -> Domo | E69: ='RESUMEN TOTAL'!F72 -> Radio | F69: ='RESUMEN TOTAL'!L72 -> 0 | G69: ='RESUMEN TOTAL'!M72 -> 0 | H69: ='RESUMEN TOTAL'!N72 -> 0 | I69: ='RESUMEN TOTAL'!O72 -> 0 | J69: ='RESUMEN TOTAL'!P72 -> 0 | K69: ='RESUMEN TOTAL'!Q72 -> 0 | L69: ='RESUMEN TOTAL'!R72 -> 0 | M69: ='RESUMEN TOTAL'!S72 -> 0 | ... AH69: ='RESUMEN TOTAL'!AN72 -> 0
A70: ='RESUMEN TOTAL'!A73 -> CENTRO | B70: ='RESUMEN TOTAL'!B73 -> CEN 50 | C70: ='RESUMEN TOTAL'!D73 -> Av. San Martin y Newbery | D70: ='RESUMEN TOTAL'!E73 -> Domo | E70: ='RESUMEN TOTAL'!F73 -> Radio | F70: ='RESUMEN TOTAL'!L73 -> 0 | G70: ='RESUMEN TOTAL'!M73 -> 0 | H70: ='RESUMEN TOTAL'!N73 -> 0 | I70: ='RESUMEN TOTAL'!O73 -> 0 | J70: ='RESUMEN TOTAL'!P73 -> 0 | K70: ='RESUMEN TOTAL'!Q73 -> 0 | L70: ='RESUMEN TOTAL'!R73 -> 0 | M70: ='RESUMEN TOTAL'!S73 -> 0 | ... AH70: ='RESUMEN TOTAL'!AN73 -> 0
A71: ='RESUMEN TOTAL'!A74 -> CENTRO | B71: ='RESUMEN TOTAL'!B74 -> CEN 51 | C71: ='RESUMEN TOTAL'!D74 -> ILLIA Y LAS HERAS | D71: ='RESUMEN TOTAL'!E74 -> FIJA | E71: ='RESUMEN TOTAL'!F74 -> Fibra Optica | F71: ='RESUMEN TOTAL'!L74 -> 0 | G71: ='RESUMEN TOTAL'!M74 -> 0 | H71: ='RESUMEN TOTAL'!N74 -> 0 | I71: ='RESUMEN TOTAL'!O74 -> 0 | J71: ='RESUMEN TOTAL'!P74 -> 0 | K71: ='RESUMEN TOTAL'!Q74 -> 0 | L71: ='RESUMEN TOTAL'!R74 -> 0 | M71: ='RESUMEN TOTAL'!S74 -> 0 | ... AH71: ='RESUMEN TOTAL'!AN74 -> 0
A72: ='RESUMEN TOTAL'!A75 -> CENTRO | B72: ='RESUMEN TOTAL'!B75 -> CEN52 | C72: ='RESUMEN TOTAL'!D75 -> San Martin y Almafuerte (ex San Martin y Dorrego) | D72: ='RESUMEN TOTAL'!E75 -> DOMO | E72: ='RESUMEN TOTAL'!F75 -> Radio | F72: ='RESUMEN TOTAL'!L75 -> 0 | G72: ='RESUMEN TOTAL'!M75 -> 0 | H72: ='RESUMEN TOTAL'!N75 -> 0 | I72: ='RESUMEN TOTAL'!O75 -> 0 | J72: ='RESUMEN TOTAL'!P75 -> 0 | K72: ='RESUMEN TOTAL'!Q75 -> 0 | L72: ='RESUMEN TOTAL'!R75 -> 0 | M72: ='RESUMEN TOTAL'!S75 -> 0 | ... AH72: ='RESUMEN TOTAL'!AN75 -> 0
A73: ='RESUMEN TOTAL'!A76 -> CENTRO | B73: ='RESUMEN TOTAL'!B76 -> CEN 53 | C73: ='RESUMEN TOTAL'!D76 -> GUTIERREZ Y BROWN | D73: ='RESUMEN TOTAL'!E76 -> Domo | E73: ='RESUMEN TOTAL'!F76 -> Radio | F73: ='RESUMEN TOTAL'!L76 -> 0 | G73: ='RESUMEN TOTAL'!M76 -> 0 | H73: ='RESUMEN TOTAL'!N76 -> 0 | I73: ='RESUMEN TOTAL'!O76 -> 0 | J73: ='RESUMEN TOTAL'!P76 -> 0 | K73: ='RESUMEN TOTAL'!Q76 -> 0 | L73: ='RESUMEN TOTAL'!R76 -> 0 | M73: ='RESUMEN TOTAL'!S76 -> 0 | ... AH73: ='RESUMEN TOTAL'!AN76 -> 0
A74: ='RESUMEN TOTAL'!A77 -> CENTRO | B74: ='RESUMEN TOTAL'!B77 -> CEN 54 | C74: ='RESUMEN TOTAL'!D77 -> GUTIERREZ Y PRINGLES | D74: ='RESUMEN TOTAL'!E77 -> Domo | E74: ='RESUMEN TOTAL'!F77 -> Radio | F74: ='RESUMEN TOTAL'!L77 -> 0 | G74: ='RESUMEN TOTAL'!M77 -> 0 | H74: ='RESUMEN TOTAL'!N77 -> 0 | I74: ='RESUMEN TOTAL'!O77 -> 0 | J74: ='RESUMEN TOTAL'!P77 -> 0 | K74: ='RESUMEN TOTAL'!Q77 -> 0 | L74: ='RESUMEN TOTAL'!R77 -> 0 | M74: ='RESUMEN TOTAL'!S77 -> 0 | ... AH74: ='RESUMEN TOTAL'!AN77 -> 0
A75: ='RESUMEN TOTAL'!A78 -> CENTRO | B75: ='RESUMEN TOTAL'!B78 -> CEN 55 | C75: ='RESUMEN TOTAL'!D78 -> BOUREL Y URQUIZA | D75: ='RESUMEN TOTAL'!E78 -> Domo | E75: ='RESUMEN TOTAL'!F78 -> Radio | F75: ='RESUMEN TOTAL'!L78 -> 0 | G75: ='RESUMEN TOTAL'!M78 -> 0 | H75: ='RESUMEN TOTAL'!N78 -> 0 | I75: ='RESUMEN TOTAL'!O78 -> 0 | J75: ='RESUMEN TOTAL'!P78 -> 0 | K75: ='RESUMEN TOTAL'!Q78 -> 0 | L75: ='RESUMEN TOTAL'!R78 -> 0 | M75: ='RESUMEN TOTAL'!S78 -> 0 | ... AH75: ='RESUMEN TOTAL'!AN78 -> 0
A76: ='RESUMEN TOTAL'!A79 -> CENTRO | B76: ='RESUMEN TOTAL'!B79 -> CEN 56 | C76: ='RESUMEN TOTAL'!D79 -> Newbery y Falucho | D76: ='RESUMEN TOTAL'!E79 -> DOMO | E76: ='RESUMEN TOTAL'!F79 -> Radio | F76: ='RESUMEN TOTAL'!L79 -> 0 | G76: ='RESUMEN TOTAL'!M79 -> 0 | H76: ='RESUMEN TOTAL'!N79 -> 0 | I76: ='RESUMEN TOTAL'!O79 -> 0 | J76: ='RESUMEN TOTAL'!P79 -> 0 | K76: ='RESUMEN TOTAL'!Q79 -> 0 | L76: ='RESUMEN TOTAL'!R79 -> 0 | M76: ='RESUMEN TOTAL'!S79 -> 0 | ... AH76: ='RESUMEN TOTAL'!AN79 -> 0
A77: ='RESUMEN TOTAL'!A80 -> CENTRO | B77: ='RESUMEN TOTAL'!B80 -> CEN 57 | C77: ='RESUMEN TOTAL'!D80 -> 25 DE MAYO Y DORREGO | D77: ='RESUMEN TOTAL'!E80 -> DOMO | E77: ='RESUMEN TOTAL'!F80 -> Radio | F77: ='RESUMEN TOTAL'!L80 -> 0 | G77: ='RESUMEN TOTAL'!M80 -> 0 | H77: ='RESUMEN TOTAL'!N80 -> 0 | I77: ='RESUMEN TOTAL'!O80 -> 0 | J77: ='RESUMEN TOTAL'!P80 -> 0 | K77: ='RESUMEN TOTAL'!Q80 -> 0 | L77: ='RESUMEN TOTAL'!R80 -> 0 | M77: ='RESUMEN TOTAL'!S80 -> 0 | ... AH77: ='RESUMEN TOTAL'!AN80 -> 0
A78: ='RESUMEN TOTAL'!A81 -> CENTRO | B78: ='RESUMEN TOTAL'!B81 -> CEN 58 | C78: ='RESUMEN TOTAL'!D81 -> EEUU Y MORENO | D78: ='RESUMEN TOTAL'!E81 -> DOMO | E78: ='RESUMEN TOTAL'!F81 -> Fibra Optica | F78: ='RESUMEN TOTAL'!L81 -> 0 | G78: ='RESUMEN TOTAL'!M81 -> 0 | H78: ='RESUMEN TOTAL'!N81 -> 0 | I78: ='RESUMEN TOTAL'!O81 -> 0 | J78: ='RESUMEN TOTAL'!P81 -> 0 | K78: ='RESUMEN TOTAL'!Q81 -> 0 | L78: ='RESUMEN TOTAL'!R81 -> 0 | M78: ='RESUMEN TOTAL'!S81 -> 0 | ... AH78: ='RESUMEN TOTAL'!AN81 -> 0
A79: ='RESUMEN TOTAL'!A82 -> CENTRO | B79: ='RESUMEN TOTAL'!B82 -> CEN59 | C79: ='RESUMEN TOTAL'!D82 -> CHACABUCO Y BOUREL | D79: ='RESUMEN TOTAL'!E82 -> DOMO | E79: ='RESUMEN TOTAL'!F82 -> Radio | F79: ='RESUMEN TOTAL'!L82 -> 0 | G79: ='RESUMEN TOTAL'!M82 -> 0 | H79: ='RESUMEN TOTAL'!N82 -> 0 | I79: ='RESUMEN TOTAL'!O82 -> 0 | J79: ='RESUMEN TOTAL'!P82 -> 0 | K79: ='RESUMEN TOTAL'!Q82 -> 0 | L79: ='RESUMEN TOTAL'!R82 -> 0 | M79: ='RESUMEN TOTAL'!S82 -> 0 | ... AH79: ='RESUMEN TOTAL'!AN82 -> 0
A80: ='RESUMEN TOTAL'!A83 -> CENTRO | B80: ='RESUMEN TOTAL'!B83 -> CEN 60 | C80: ='RESUMEN TOTAL'!D83 -> RECONQUISTA Y ILLIA | D80: ='RESUMEN TOTAL'!E83 -> DOMO | E80: ='RESUMEN TOTAL'!F83 -> PTO A FO | F80: ='RESUMEN TOTAL'!L83 -> 0 | G80: ='RESUMEN TOTAL'!M83 -> 0 | H80: ='RESUMEN TOTAL'!N83 -> 0 | I80: ='RESUMEN TOTAL'!O83 -> 0 | J80: ='RESUMEN TOTAL'!P83 -> 0 | K80: ='RESUMEN TOTAL'!Q83 -> 0 | L80: ='RESUMEN TOTAL'!R83 -> 0 | M80: ='RESUMEN TOTAL'!S83 -> 0 | ... AH80: ='RESUMEN TOTAL'!AN83 -> 0
... A106: ='RESUMEN TOTAL'!A109 -> CENTRO | B106: ='RESUMEN TOTAL'!B109 -> CEN 86 | C106: ='RESUMEN TOTAL'!D109 -> Monteagudo y Bocuzzi | D106: ='RESUMEN TOTAL'!E109 -> Fija | E106: ='RESUMEN TOTAL'!F109 -> Fibra Optica | F106: ='RESUMEN TOTAL'!L109 -> 0 | G106: ='RESUMEN TOTAL'!M109 -> 0 | H106: ='RESUMEN TOTAL'!N109 -> 0 | I106: ='RESUMEN TOTAL'!O109 -> 0 | J106: ='RESUMEN TOTAL'!P109 -> 0 | K106: ='RESUMEN TOTAL'!Q109 -> 0 | L106: ='RESUMEN TOTAL'!R109 -> 0 | M106: ='RESUMEN TOTAL'!S109 -> 0 | ... AH106: ='RESUMEN TOTAL'!AN109 -> 0
A107: ='RESUMEN TOTAL'!A111 -> SAN NICOLAS | B107: ='RESUMEN TOTAL'!B111 -> CHA01 | C107: ='RESUMEN TOTAL'!D111 -> Novak y Pte Illia | D107: ='RESUMEN TOTAL'!E111 -> Domo | E107: ='RESUMEN TOTAL'!F111 -> Radio | F107: ='RESUMEN TOTAL'!L111 -> 0 | G107: ='RESUMEN TOTAL'!M111 -> 0 | H107: ='RESUMEN TOTAL'!N111 -> 0 | I107: ='RESUMEN TOTAL'!O111 -> 0 | J107: ='RESUMEN TOTAL'!P111 -> 0 | K107: ='RESUMEN TOTAL'!Q111 -> 0 | L107: ='RESUMEN TOTAL'!R111 -> 0 | M107: ='RESUMEN TOTAL'!S111 -> 0 | ... AH107: ='RESUMEN TOTAL'!AN111 -> 0
