Workbook
Name _25_de_agosto: 'RESUMEN TOTAL'!$A$4:$D$383
Name _25_de_agosto_3: 'RESUMEN TOTAL'!$A$4:$D$395
Name BONOMOcam: Hoja1!$B$2
Name CANTIDAD_DE_CAMARAS: 'RESUMEN TOTAL'!$B$1
Name COSEIDIcam: Hoja1!$B$4

Sheet RESUMEN TOTAL
A1: CANTIDAD DE CAMARAS | B1: =COUNTA(B5:B547) -> 462 | D1: PORCIENTO DE CAIDAS | L1: =(L3)/(L2+L3) -> 0 | M1: =(M3)/(M2+M3) -> 0 | N1: =(N3)/(N2+N3) -> 0 | O1: =(O3)/(O2+O3) -> 0 | P1: =(P3)/(P2+P3) -> 0 | Q1: =(Q3)/(Q2+Q3) -> 0.054112554 | R1: =(R3)/(R2+R3) -> 0.032467532 | S1: =(S3)/(S2+S3) -> 0 | ... X1: =(X3)/(X2+X3) -> 0.15367965 | Z1: =(Z3)/(Z2+Z3) -> 0.1017316 | AA1: =(AA3)/(AA2+AA3) -> 0.13203463 | AB1: =(AB3)/(AB2+AB3) -> 0.22943723 | AC1: =(AC3)/(AC2+AC3) -> 0.19047619 | AD1: =(AD3)/(AD2+AD3) -> 0.22294372 | AE1: =(AE3)/(AE2+AE3) -> 0.093073593 | AF1: =(AF3)/(AF2+AF3) -> 0.090909091 | AG1: =(AG3)/(AG2+AG3) -> 0.090909091 | ... AP1: =(AP3)/(AP2+AP3) -> 0
D2: FUNCIONAN | L2: =B1-L3 -> 462 | M2: =CANTIDAD_DE_CAMARAS-M3 -> 462 | N2: =CANTIDAD_DE_CAMARAS-N3 -> 462 | O2: =CANTIDAD_DE_CAMARAS-O3 -> 462 | P2: =CANTIDAD_DE_CAMARAS-P3 -> 462 | Q2: =CANTIDAD_DE_CAMARAS-Q3 -> 437 | R2: =CANTIDAD_DE_CAMARAS-R3 -> 447 | S2: =CANTIDAD_DE_CAMARAS-S3 -> 462 | T2: =CANTIDAD_DE_CAMARAS-T3 -> 462 | ... AP2: =CANTIDAD_DE_CAMARAS-AP3 -> 462
D3: CAIDAS | L3: =COUNTIF(L4:L467, "apagado") -> 0 | M3: =COUNTIF(M4:M467, "apagado") -> 0 | N3: =COUNTIF(N4:N467, "apagado") -> 0 | O3: =COUNTIF(O4:O467, "apagado") -> 0 | P3: =COUNTIF(P4:P467, "apagado") -> 0 | Q3: =COUNTIF(Q4:Q467, "apagado") -> 25 | R3: =COUNTIF(R4:R467, "apagado") -> 15 | S3: =COUNTIF(S4:S467, "apagado") -> 0 | ... AP3: =COUNTIF(AP4:AP467, "apagado") -> 0
A4: Barrio | B4: [Denominacion] | C4: [Empresa Mantenimiento] | D4: [Ubicacion] | E4: [Tipo de Camara] | F4: [Tipo de Conexion] | G4: Destino | I4: DIAS FUNCIONANDO | J4: DIAS CAIDA | K4: EFECTIVIDAD | L4: 45108 | M4: 45109 | N4: 45110 | O4: 45111 | P4: 45112 | Q4: 45113 | R4: 45114 | S4: 45115 | T4: 45116 | U4: 45117 | V4: 45118 | W4: 45119 | X4: 45120 | Y4: 45121 | Z4: 45122 | AA4: 45123 | AB4: 45124 | AC4: 45125 | AD4: 45126 | AE4: 45127 | AF4: 45128 | AG4: 45129 | AH4: 45130 | AI4: 45131 | AJ4: 45132 | AK4: 45133 | AL4: 45134 | AM4: 45135 | AN4: 45136 | AO4: 45137 | AP4: 45138
A5: ALTAMIRA | B5: ALT01 | C5: BONOMO | D5: Calchaqui y Sgto. Cabral | E5: Domo | F5: Fibra Optica | H5: 172.20.10.6 | I5: =COUNTIF(L5:AM5,"") -> 26 | J5: =COUNTIF(L5:AM5,"APAGADO") -> 2 | K5: =(I5)/(J5+I5) -> 0.92857143 | Y5: APAGADO | AB5: APAGADO
A6: ALTAMIRA | B6: ALT02 | C6: BONOMO | D6: Calchaqui y Lope de Vega | E6: Domo | F6: PTO A FO | G6: CABRAL Y CALCHAQUI | H6: 172.20.12.218 | I6: =COUNTIF(L6:AM6,"") -> 25 | J6: =COUNTIF(L6:AM6,"APAGADO") -> 3 | K6: =(I6)/(J6+I6) -> 0.89285714 | Y6: APAGADO | AB6: APAGADO | AD6: APAGADO
A7: ALTAMIRA | B7: ALT 03 | C7: BONOMO | D7: Bombero Galarza y Necochea | E7: Domo | F7: Fibra Optica | H7: 172.20.12.54 | I7: =COUNTIF(L7:AM7,"") -> 26 | J7: =COUNTIF(L7:AM7,"APAGADO") -> 2 | K7: =(I7)/(J7+I7) -> 0.92857143 | Y7: APAGADO | AB7: APAGADO
A8: ALTAMIRA | B8: ALT 04 | C8: BONOMO | D8: Francia y Necochea | E8: Domo | F8: Fibra Optica | H8: 172.20.12.55 | I8: =COUNTIF(L8:AM8,"") -> 24 | J8: =COUNTIF(L8:AM8,"APAGADO") -> 4 | K8: =(I8)/(J8+I8) -> 0.85714286 | Y8: APAGADO | AB8: APAGADO | AF8: APAGADO | AG8: APAGADO
A9: ALTAMIRA | B9: ALT05 | C9: BONOMO | D9: Av. Calchaqui y Bombero Galarza | E9: Domo | F9: PTO A FO | G9: NECOCHEA Y GALARZA | H9: 172.20.12.216 | I9: =COUNTIF(L9:AM9,"") -> 25 | J9: =COUNTIF(L9:AM9,"APAGADO") -> 3 | K9: =(I9)/(J9+I9) -> 0.89285714 | Y9: APAGADO | AB9: APAGADO | AD9: APAGADO
A10: ALTAMIRA | B10: ALT 06 | C10: BONOMO | D10: LOPE DE VEGA Y NECOCHEA | E10: Domo | F10: PTO A FO | G10: NECOCHEA Y GALARZA | H10: 172.20.12.12 | I10: =COUNTIF(L10:AM10,"") -> 26 | J10: =COUNTIF(L10:AM10,"APAGADO") -> 2 | K10: =(I10)/(J10+I10) -> 0.92857143 | Y10: APAGADO | AB10: APAGADO
A11: ALTAMIRA | B11: ALT07 | C11: BONOMO | D11: AV. CALCHAQUI Y AV. DEL TRABAJO | E11: DOMO | F11: PTO A FO | G11: CABRAL Y CALCHAQUI | H11: 172.20.10.57 | I11: =COUNTIF(L11:AM11,"") -> 26 | J11: =COUNTIF(L11:AM11,"APAGADO") -> 2 | K11: =(I11)/(J11+I11) -> 0.92857143 | Y11: APAGADO | AB11: APAGADO
A12: ALTAMIRA | B12: ALT 08 | C12: BONOMO | D12: HUMAITA Y NECOCHEA | E12: DOMO | F12: Fibra Optica | H12: 172.20.11.215 | I12: =COUNTIF(L12:AM12,"") -> 26 | J12: =COUNTIF(L12:AM12,"APAGADO") -> 2 | K12: =(I12)/(J12+I12) -> 0.92857143 | Y12: APAGADO | AB12: APAGADO
A13: ALTAMIRA | B13: ALT 09 | C13: BONOMO | D13: NECOCHEA Y CURUPAITY | E13: DOMO | F13: Fibra Optica | H13: 172.20.11.216 | I13: =COUNTIF(L13:AM13,"") -> 22 | J13: =COUNTIF(L13:AM13,"APAGADO") -> 6 | K13: =(I13)/(J13+I13) -> 0.78571429 | Q13: APAGADO | R13: APAGADO | U13: APAGADO | V13: APAGADO | Y13: APAGADO | AB13: APAGADO
A14: ALTAMIRA | B14: ALT 10 | C14: BONOMO | D14: Calchaqui y Francia | E14: Domo | F14: Radio | H14: 172.20.12.156 | I14: =COUNTIF(L14:AM14,"") -> 25 | J14: =COUNTIF(L14:AM14,"APAGADO") -> 3 | K14: =(I14)/(J14+I14) -> 0.89285714 | Y14: APAGADO | AB14: APAGADO | AD14: APAGADO
A15: AGUSTIN RAMIREZ | B15: ARA 01 | C15: COSEIDI | D15: Malambo y Tranquera | E15: Domo | F15: Fibra Optica | H15: 172.20.12.110 | I15: =COUNTIF(L15:AM15,"") -> 16 | J15: =COUNTIF(L15:AM15,"APAGADO") -> 12 | K15: =(I15)/(J15+I15) -> 0.57142857 | V15: APAGADO | W15: APAGADO | X15: APAGADO | Y15: APAGADO | Z15: APAGADO | AA15: APAGADO | AB15: APAGADO | AC15: APAGADO | AD15: APAGADO | AE15: APAGADO | AF15: APAGADO | AG15: APAGADO
A16: BELGRANO | B16: BEL 01 | C16: BONOMO | D16: San Martin y Dardo Rocha | E16: DOMO | F16: Fibra Optica | H16: 172.20.12.64 | I16: =COUNTIF(L16:AM16,"") -> 28 | J16: =COUNTIF(L16:AM16,"APAGADO") -> 0 | K16: =(I16)/(J16+I16) -> 1
A17: BELGRANO | B17: BEL 02 | C17: BONOMO | D17: Guardia vieja y Fronteriz | E17: DOMO | F17: Fibra Optica | I17: =COUNTIF(L17:AM17,"") -> 28 | J17: =COUNTIF(L17:AM17,"APAGADO") -> 0 | K17: =(I17)/(J17+I17) -> 1
A18: BOSQUES CENTRO | B18: BOSQC 01 | C18: COSEIDI | D18: LUIS AGOTE E/DANUNCIO Y CAMPOAMOR | E18: Fija | F18: Radio | H18: 172.20.11.15 | I18: =COUNTIF(L18:AM18,"") -> 25 | J18: =COUNTIF(L18:AM18,"APAGADO") -> 3 | K18: =(I18)/(J18+I18) -> 0.89285714 | AB18: APAGADO | AC18: APAGADO | AD18: APAGADO
A19: BOSQUES CENTRO | B19: BOSQC 02 | C19: COSEIDI | D19: LUIS AGOTE E/DANUNCIO Y CAMPOAMOR | E19: Fija | F19: Radio | H19: 172.20.11.16 | I19: =COUNTIF(L19:AM19,"") -> 25 | J19: =COUNTIF(L19:AM19,"APAGADO") -> 3 | K19: =(I19)/(J19+I19) -> 0.89285714 | AB19: APAGADO | AC19: APAGADO | AD19: APAGADO
A20: BOSQUES CENTRO | B20: BOSQC 03 | C20: COSEIDI | D20: BENAVENTE Y LUIS AGOTE | E20: Fija | F20: Radio | H20: 172.20.11.13 | I20: =COUNTIF(L20:AM20,"") -> 24 | J20: =COUNTIF(L20:AM20,"APAGADO") -> 4 | K20: =(I20)/(J20+I20) -> 0.85714286 | U20: APAGADO | AB20: APAGADO | AC20: APAGADO | AD20: APAGADO
A21: BOSQUES CENTRO | B21: BOSQC 04 | C21: COSEIDI | D21: BENAVENTE Y LUIS AGOTE | E21: Fija | F21: Radio | H21: 172.20.11.113 | I21: =COUNTIF(L21:AM21,"") -> 24 | J21: =COUNTIF(L21:AM21,"APAGADO") -> 4 | K21: =(I21)/(J21+I21) -> 0.85714286 | U21: APAGADO | AB21: APAGADO | AC21: APAGADO | AD21: APAGADO
A22: BOSQUES CENTRO | B22: BOSQC 05 | C22: COSEIDI | D22: LUIS AGOTE Y RUTA 36 | E22: Fija | F22: Radio | H22: 172.20.11.17 | I22: =COUNTIF(L22:AM22,"") -> 25 | J22: =COUNTIF(L22:AM22,"APAGADO") -> 3 | K22: =(I22)/(J22+I22) -> 0.89285714 | AB22: APAGADO | AC22: APAGADO | AD22: APAGADO
A23: BOSQUES CENTRO | B23: BOSQC 06 | C23: COSEIDI | D23: LUIS AGOTE Y RUTA 36 | E23: Fija | F23: Radio | H23: 172.20.11.18 | I23: =COUNTIF(L23:AM23,"") -> 25 | J23: =COUNTIF(L23:AM23,"APAGADO") -> 3 | K23: =(I23)/(J23+I23) -> 0.89285714 | AB23: APAGADO | AC23: APAGADO | AD23: APAGADO
A24: CENTRO | B24: CEN01 | C24: BONOMO | D24: San Martin y 9 de Julio | E24: Fija | F24: Fibra Optica | H24: 172.20.11.10 | I24: =COUNTIF(L24:AM24,"") -> 28 | J24: =COUNTIF(L24:AM24,"APAGADO") -> 0 | K24: =(I24)/(J24+I24) -> 1
A25: CENTRO | B25: CEN02 | C25: BONOMO | D25: San Martin y Almafuerte | E25: Fija | F25: Fibra Optica | H25: 172.20.11.11 | I25: =COUNTIF(L25:AM25,"") -> 28 | J25: =COUNTIF(L25:AM25,"APAGADO") -> 0 | K25: =(I25)/(J25+I25) -> 1
A26: CENTRO | B26: CEN03 | C26: BONOMO | D26: San Martin y Sallares | E26: Domo | F26: Fibra Optica | H26: 172.20.12.30 | I26: =COUNTIF(L26:AM26,"") -> 28 | J26: =COUNTIF(L26:AM26,"APAGADO") -> 0 | K26: =(I26)/(J26+I26) -> 1
A27: CENTRO | B27: CEN04 | C27: BONOMO | D27: San Martin y Contreras | E27: Domo | F27: Fibra Optica | H27: 172.20.12.29 | I27: =COUNTIF(L27:AM27,"") -> 28 | J27: =COUNTIF(L27:AM27,"APAGADO") -> 0 | K27: =(I27)/(J27+I27) -> 1
A28: CENTRO | B28: CEN 05 | C28: BONOMO | D28: Bocuzzi e/España y San Martin | E28: DOMO | F28: Fibra Optica | H28: 172.20.10.200 | I28: =COUNTIF(L28:AM28,"") -> 28 | J28: =COUNTIF(L28:AM28,"APAGADO") -> 0 | K28: =(I28)/(J28+I28) -> 1
A29: CENTRO | B29: CEN06 | C29: BONOMO | D29: Monteagudo y A.del Valle | E29: Fija | F29: Fibra Optica | H29: 172.20.10.02 | I29: =COUNTIF(L29:AM29,"") -> 28 | J29: =COUNTIF(L29:AM29,"APAGADO") -> 0 | K29: =(I29)/(J29+I29) -> 1
A30: CENTRO | B30: CEN07 | C30: BONOMO | D30: San Martin y Guemes | E30: DOMO | F30: Fibra Optica | H30: 172.20.11.20 | I30: =COUNTIF(L30:AM30,"") -> 28 | J30: =COUNTIF(L30:AM30,"APAGADO") -> 0 | K30: =(I30)/(J30+I30) -> 1
A31: CENTRO | B31: CEN08 | C31: BONOMO | D31: San Martin y Pte.Peron | E31: Domo | F31: Fibra Optica | H31: 172.20.11.21 | I31: =COUNTIF(L31:AM31,"") -> 28 | J31: =COUNTIF(L31:AM31,"APAGADO") -> 0 | K31: =(I31)/(J31+I31) -> 1
A32: CENTRO | B32: CEN09 | C32: BONOMO | D32: Chacabuco y 25 de Mayo | E32: Domo | F32: Fibra Optica | H32: 172.20.11.22 | I32: =COUNTIF(L32:AM32,"") -> 28 | J32: =COUNTIF(L32:AM32,"APAGADO") -> 0 | K32: =(I32)/(J32+I32) -> 1
A33: CENTRO | B33: CEN10 | C33: BONOMO | D33: Monteagudo y Pte. Peron | E33: Domo | F33: Fibra Optica | H33: 172.20.11.23 | I33: =COUNTIF(L33:AM33,"") -> 28 | J33: =COUNTIF(L33:AM33,"APAGADO") -> 0 | K33: =(I33)/(J33+I33) -> 1
A34: CENTRO | B34: CEN11 | C34: BONOMO | D34: Monteagudo y Bocuzzi | E34: Domo | F34: Fibra Optica | H34: 172.20.10.24 | I34: =COUNTIF(L34:AM34,"") -> 28 | J34: =COUNTIF(L34:AM34,"APAGADO") -> 0 | K34: =(I34)/(J34+I34) -> 1
A35: CENTRO | B35: CEN 12 | C35: BONOMO | D35: Monteagudo y Mitre | E35: Domo | F35: Fibra Optica | H35: 172.20.10.23 | I35: =COUNTIF(L35:AM35,"") -> 28 | J35: =COUNTIF(L35:AM35,"APAGADO") -> 0 | K35: =(I35)/(J35+I35) -> 1
... A39: CENTRO | B39: CEN16 | C39: BONOMO | D39: San Martin y Pte. Peron | E39: Fija | F39: Fibra Optica | H39: 172.20.12.36 | I39: =COUNTIF(L39:AM39,"") -> 28 | J39: =COUNTIF(L39:AM39,"APAGADO") -> 0 | K39: =(I39)/(J39+I39) -> 1
A40: CENTRO | B40: CEN17 | C40: BONOMO | D40: San Martin y Mitre | E40: Domo | F40: PTO A FO | G40: SAN MARTIN Y SALLARES | H40: 172.20.12.200 | I40: =COUNTIF(L40:AM40,"") -> 27 | J40: =COUNTIF(L40:AM40,"APAGADO") -> 1 | K40: =(I40)/(J40+I40) -> 0.96428571 | Y40: APAGADO
A41: CENTRO | B41: CEN18 | C41: BONOMO | D41: Monteagudo e/Mitre y Sallares | E41: Fija | F41: Fibra Optica | H41: 172.20.10.26 | I41: =COUNTIF(L41:AM41,"") -> 28 | J41: =COUNTIF(L41:AM41,"APAGADO") -> 0 | K41: =(I41)/(J41+I41) -> 1
A42: CENTRO | B42: CEN19 | C42: BONOMO | D42: Chacabuco y 25 de Mayo | E42: Fija | F42: Fibra Optica | H42: 172.20.10.27 | I42: =COUNTIF(L42:AM42,"") -> 28 | J42: =COUNTIF(L42:AM42,"APAGADO") -> 0 | K42: =(I42)/(J42+I42) -> 1
A43: LOMAS DE MONTEVERDE | B43: CEN20 | C43: BONOMO | D43: Pte. Illia y Las Heras | E43: Domo | F43: Fibra Optica | H43: 172.20.10.33 | I43: =COUNTIF(L43:AM43,"") -> 28 | J43: =COUNTIF(L43:AM43,"APAGADO") -> 0 | K43: =(I43)/(J43+I43) -> 1
...

Sheet ESTADISTICA
A1: ='RESUMEN TOTAL'!A4 -> Barrio | B1: ='RESUMEN TOTAL'!B4 -> [Denominacion] | C1: ='RESUMEN TOTAL'!D4 -> [Ubicacion] | D1: ='RESUMEN TOTAL'!E4 -> [Tipo de Camara] | E1: ='RESUMEN TOTAL'!F4 -> [Tipo de Conexion] | F1: ='RESUMEN TOTAL'!L4 -> 45108 | G1: ='RESUMEN TOTAL'!M4 -> 45109 | H1: ='RESUMEN TOTAL'!N4 -> 45110 | I1: ='RESUMEN TOTAL'!O4 -> 45111 | J1: ='RESUMEN TOTAL'!P4 -> 45112 | K1: ='RESUMEN TOTAL'!Q4 -> 45113 | L1: ='RESUMEN TOTAL'!R4 -> 45114 | M1: ='RESUMEN TOTAL'!S4 -> 45115 | ... AI1: ='RESUMEN TOTAL'!AO4 -> 45137 | AJ1: ='RESUMEN TOTAL'!#REF! -> #REF!
A2: ='RESUMEN TOTAL'!A5 -> ALTAMIRA | B2: ='RESUMEN TOTAL'!B5 -> ALT01 | C2: ='RESUMEN TOTAL'!D5 -> Calchaqui y Sgto. Cabral | D2: ='RESUMEN TOTAL'!E5 -> Domo | E2: ='RESUMEN TOTAL'!F5 -> Fibra Optica | F2: ='RESUMEN TOTAL'!L5 -> 0 | G2: ='RESUMEN TOTAL'!M5 -> 0 | H2: ='RESUMEN TOTAL'!N5 -> 0 | I2: ='RESUMEN TOTAL'!O5 -> 0 | J2: ='RESUMEN TOTAL'!P5 -> 0 | K2: ='RESUMEN TOTAL'!Q5 -> 0 | L2: ='RESUMEN TOTAL'!R5 -> 0 | M2: ='RESUMEN TOTAL'!S5 -> 0 | ... AI2: ='RESUMEN TOTAL'!AO5 -> 0 | AJ2: ='RESUMEN TOTAL'!#REF! -> #REF!
A3: ='RESUMEN TOTAL'!A6 -> ALTAMIRA | B3: ='RESUMEN TOTAL'!B6 -> ALT02 | C3: ='RESUMEN TOTAL'!D6 -> Calchaqui y Lope de Vega | D3: ='RESUMEN TOTAL'!E6 -> Domo | E3: ='RESUMEN TOTAL'!F6 -> PTO A FO | F3: ='RESUMEN TOTAL'!L6 -> 0 | G3: ='RESUMEN TOTAL'!M6 -> 0 | H3: ='RESUMEN TOTAL'!N6 -> 0 | I3: ='RESUMEN TOTAL'!O6 -> 0 | J3: ='RESUMEN TOTAL'!P6 -> 0 | K3: ='RESUMEN TOTAL'!Q6 -> 0 | L3: ='RESUMEN TOTAL'!R6 -> 0 | M3: ='RESUMEN TOTAL'!S6 -> 0 | ... AI3: ='RESUMEN TOTAL'!AO6 -> 0 | AJ3: ='RESUMEN TOTAL'!#REF! -> #REF!
A4: ='RESUMEN TOTAL'!A7 -> ALTAMIRA | B4: ='RESUMEN TOTAL'!B7 -> ALT 03 | C4: ='RESUMEN TOTAL'!D7 -> Bombero Galarza y Necochea | D4: ='RESUMEN TOTAL'!E7 -> Domo | E4: ='RESUMEN TOTAL'!F7 -> Fibra Optica | F4: ='RESUMEN TOTAL'!L7 -> 0 | G4: ='RESUMEN TOTAL'!M7 -> 0 | H4: ='RESUMEN TOTAL'!N7 -> 0 | I4: ='RESUMEN TOTAL'!O7 -> 0 | J4: ='RESUMEN TOTAL'!P7 -> 0 | K4: ='RESUMEN TOTAL'!Q7 -> 0 | L4: ='RESUMEN TOTAL'!R7 -> 0 | M4: ='RESUMEN TOTAL'!S7 -> 0 | ... AI4: ='RESUMEN TOTAL'!AO7 -> 0 | AJ4: ='RESUMEN TOTAL'!#REF! -> #REF!
A5: ='RESUMEN TOTAL'!A8 -> ALTAMIRA | B5: ='RESUMEN TOTAL'!B8 -> ALT 04 | C5: ='RESUMEN TOTAL'!D8 -> Francia y Necochea | D5: ='RESUMEN TOTAL'!E8 -> Domo | E5: ='RESUMEN TOTAL'!F8 -> Fibra Optica | F5: ='RESUMEN TOTAL'!L8 -> 0 | G5: ='RESUMEN TOTAL'!M8 -> 0 | H5: ='RESUMEN TOTAL'!N8 -> 0 | I5: ='RESUMEN TOTAL'!O8 -> 0 | J5: ='RESUMEN TOTAL'!P8 -> 0 | K5: ='RESUMEN TOTAL'!Q8 -> 0 | L5: ='RESUMEN TOTAL'!R8 -> 0 | M5: ='RESUMEN TOTAL'!S8 -> 0 | ... AI5: ='RESUMEN TOTAL'!AO8 -> 0 | AJ5: ='RESUMEN TOTAL'!#REF! -> #REF!
A6: ='RESUMEN TOTAL'!A9 -> ALTAMIRA | B6: ='RESUMEN TOTAL'!B9 -> ALT05 | C6: ='RESUMEN TOTAL'!D9 -> Av. Calchaqui y Bombero Galarza | D6: ='RESUMEN TOTAL'!E9 -> Domo | E6: ='RESUMEN TOTAL'!F9 -> PTO A FO | F6: ='RESUMEN TOTAL'!L9 -> 0 | G6: ='RESUMEN TOTAL'!M9 -> 0 | H6: ='RESUMEN TOTAL'!N9 -> 0 | I6: ='RESUMEN TOTAL'!O9 -> 0 | J6: ='RESUMEN TOTAL'!P9 -> 0 | K6: ='RESUMEN TOTAL'!Q9 -> 0 | L6: ='RESUMEN TOTAL'!R9 -> 0 | M6: ='RESUMEN TOTAL'!S9 -> 0 | ... AI6: ='RESUMEN TOTAL'!AO9 -> 0 | AJ6: ='RESUMEN TOTAL'!#REF! -> #REF!
A7: ='RESUMEN TOTAL'!A10 -> ALTAMIRA | B7: ='RESUMEN TOTAL'!B10 -> ALT 06 | C7: ='RESUMEN TOTAL'!D10 -> LOPE DE VEGA Y NECOCHEA | D7: ='RESUMEN TOTAL'!E10 -> Domo | E7: ='RESUMEN TOTAL'!F10 -> PTO A FO | F7: ='RESUMEN TOTAL'!L10 -> 0 | G7: ='RESUMEN TOTAL'!M10 -> 0 | H7: ='RESUMEN TOTAL'!N10 -> 0 | I7: ='RESUMEN TOTAL'!O10 -> 0 | J7: ='RESUMEN TOTAL'!P10 -> 0 | K7: ='RESUMEN TOTAL'!Q10 -> 0 | L7: ='RESUMEN TOTAL'!R10 -> 0 | M7: ='RESUMEN TOTAL'!S10 -> 0 | ... AI7: ='RESUMEN TOTAL'!AO10 -> 0 | AJ7: ='RESUMEN TOTAL'!#REF! -> #REF!
A8: ='RESUMEN TOTAL'!A11 -> ALTAMIRA | B8: ='RESUMEN TOTAL'!B11 -> ALT07 | C8: ='RESUMEN TOTAL'!D11 -> AV. CALCHAQUI Y AV. DEL TRABAJO | D8: ='RESUMEN TOTAL'!E11 -> DOMO | E8: ='RESUMEN TOTAL'!F11 -> PTO A FO | F8: ='RESUMEN TOTAL'!L11 -> 0 | G8: ='RESUMEN TOTAL'!M11 -> 0 | H8: ='RESUMEN TOTAL'!N11 -> 0 | I8: ='RESUMEN TOTAL'!O11 -> 0 | J8: ='RESUMEN TOTAL'!P11 -> 0 | K8: ='RESUMEN TOTAL'!Q11 -> 0 | L8: ='RESUMEN TOTAL'!R11 -> 0 | M8: ='RESUMEN TOTAL'!S11 -> 0 | ... AI8: ='RESUMEN TOTAL'!AO11 -> 0 | AJ8: ='RESUMEN TOTAL'!#REF! -> #REF!
A9: ='RESUMEN TOTAL'!A12 -> ALTAMIRA | B9: ='RESUMEN TOTAL'!B12 -> ALT 08 | C9: ='RESUMEN TOTAL'!D12 -> HUMAITA Y NECOCHEA | D9: ='RESUMEN TOTAL'!E12 -> DOMO | E9: ='RESUMEN TOTAL'!F12 -> Fibra Optica | F9: ='RESUMEN TOTAL'!L12 -> 0 | G9: ='RESUMEN TOTAL'!M12 -> 0 | H9: ='RESUMEN TOTAL'!N12 -> 0 | I9: ='RESUMEN TOTAL'!O12 -> 0 | J9: ='RESUMEN TOTAL'!P12 -> 0 | K9: ='RESUMEN TOTAL'!Q12 -> 0 | L9: ='RESUMEN TOTAL'!R12 -> 0 | M9: ='RESUMEN TOTAL'!S12 -> 0 | ... AI9: ='RESUMEN TOTAL'!AO12 -> 0 | AJ9: ='RESUMEN TOTAL'!#REF! -> #REF!
A10: ='RESUMEN TOTAL'!A13 -> ALTAMIRA | B10: ='RESUMEN TOTAL'!B13 -> ALT 09 | C10: ='RESUMEN TOTAL'!D13 -> NECOCHEA Y CURUPAITY | D10: ='RESUMEN TOTAL'!E13 -> DOMO | E10: ='RESUMEN TOTAL'!F13 -> Fibra Optica | F10: ='RESUMEN TOTAL'!L13 -> 0 | G10: ='RESUMEN TOTAL'!M13 -> 0 | H10: ='RESUMEN TOTAL'!N13 -> 0 | I10: ='RESUMEN TOTAL'!O13 -> 0 | J10: ='RESUMEN TOTAL'!P13 -> 0 | K10: ='RESUMEN TOTAL'!Q13 -> APAGADO | L10: ='RESUMEN TOTAL'!R13 -> APAGADO | M10: ='RESUMEN TOTAL'!S13 -> 0 | ... AI10: ='RESUMEN TOTAL'!AO13 -> 0 | AJ10: ='RESUMEN TOTAL'!#REF! -> #REF!
A11: ='RESUMEN TOTAL'!A14 -> ALTAMIRA | B11: ='RESUMEN TOTAL'!B14 -> ALT 10 | C11: ='RESUMEN TOTAL'!D14 -> Calchaqui y Francia | D11: ='RESUMEN TOTAL'!E14 -> Domo | E11: ='RESUMEN TOTAL'!F14 -> Radio | F11: ='RESUMEN TOTAL'!L14 -> 0 | G11: ='RESUMEN TOTAL'!M14 -> 0 | H11: ='RESUMEN TOTAL'!N14 -> 0 | I11: ='RESUMEN TOTAL'!O14 -> 0 | J11: ='RESUMEN TOTAL'!P14 -> 0 | K11: ='RESUMEN TOTAL'!Q14 -> 0 | L11: ='RESUMEN TOTAL'!R14 -> 0 | M11: ='RESUMEN TOTAL'!S14 -> 0 | ... AI11: ='RESUMEN TOTAL'!AO14 -> 0 | AJ11: ='RESUMEN TOTAL'!#REF! -> #REF!
A12: ='RESUMEN TOTAL'!A15 -> AGUSTIN RAMIREZ | B12: ='RESUMEN TOTAL'!B15 -> ARA 01 | C12: ='RESUMEN TOTAL'!D15 -> Malambo y Tranquera | D12: ='RESUMEN TOTAL'!E15 -> Domo | E12: ='RESUMEN TOTAL'!F15 -> Fibra Optica | F12: ='RESUMEN TOTAL'!L15 -> 0 | G12: ='RESUMEN TOTAL'!M15 -> 0 | H12: ='RESUMEN TOTAL'!N15 -> 0 | I12: ='RESUMEN TOTAL'!O15 -> 0 | J12: ='RESUMEN TOTAL'!P15 -> 0 | K12: ='RESUMEN TOTAL'!Q15 -> 0 | L12: ='RESUMEN TOTAL'!R15 -> 0 | M12: ='RESUMEN TOTAL'!S15 -> 0 | ... AI12: ='RESUMEN TOTAL'!AO15 -> 0 | AJ12: ='RESUMEN TOTAL'!#REF! -> #REF!
... A638: ='RESUMEN TOTAL'!A641 -> 0 | B638: ='RESUMEN TOTAL'!B641 -> 0 | C638: ='RESUMEN TOTAL'!D641 -> 0 | D638: ='RESUMEN TOTAL'!E641 -> 0 | E638: ='RESUMEN TOTAL'!F641 -> 0 | F638: ='RESUMEN TOTAL'!L641 -> 0 | G638: ='RESUMEN TOTAL'!M641 -> 0 | H638: ='RESUMEN TOTAL'!N641 -> 0 | I638: ='RESUMEN TOTAL'!O641 -> 0 | J638: ='RESUMEN TOTAL'!P641 -> 0 | K638: ='RESUMEN TOTAL'!Q641 -> 0 | L638: ='RESUMEN TOTAL'!R641 -> 0 | M638: ='RESUMEN TOTAL'!S641 -> 0 | ... AI638: ='RESUMEN TOTAL'!AO641 -> 0 | AJ638: ='RESUMEN TOTAL'!#REF! -> #REF!

Sheet APAGADOS
E1: APAGADOS | F1: =COUNTIF(F3:F403, "APAGADO") -> 0 | G1: =COUNTIF(G3:G403, "APAGADO") -> 0 | H1: =COUNTIF(H3:H503, "APAGADO") -> 0 | I1: =COUNTIF(I3:I403, "APAGADO") -> 0 | J1: =COUNTIF(J3:J403, "APAGADO") -> 0 | K1: =COUNTIF(K3:K403, "APAGADO") -> 22 | L1: =COUNTIF(L3:L403, "APAGADO") -> 14 | M1: =COUNTIF(M3:M403, "APAGADO") -> 0 | N1: =COUNTIF(N3:N403, "APAGADO") -> 0 | O1: =COUNTIF(O3:O403, "APAGADO") -> 16 | P1: =COUNTIF(P3:P403, "APAGADO") -> 47 | ... AD1: =COUNTIF(AD3:AD403, "APAGADO") -> 0 | AE1: =COUNTIF(AE3:AE503, "APAGADO") -> 0 | AF1: =COUNTIF(AF3:AF403, "APAGADO") -> 0 | AG1: =COUNTIF(AG3:AG403, "APAGADO") -> 0 | AH1: =COUNTIF(AH3:AH403, "APAGADO") -> 0 | AI1: =COUNTIF(AI3:AI403, "APAGADO") -> 0 | AJ1: =COUNTIF(AJ3:AJ403, "APAGADO") -> 0
A2: =ESTADISTICA!A1 -> Barrio | B2: =ESTADISTICA!B1 -> [Denominacion] | C2: =ESTADISTICA!C1 -> [Ubicacion] | D2: =ESTADISTICA!D1 -> [Tipo de Camara] | E2: =ESTADISTICA!E1 -> [Tipo de Conexion] | F2: =ESTADISTICA!F1 -> 45108 | G2: =ESTADISTICA!G1 -> 45109 | H2: =ESTADISTICA!H1 -> 45110 | ... AJ2: =ESTADISTICA!AJ1 -> #REF!
A3: =ESTADISTICA!A2 -> ALTAMIRA | B3: =ESTADISTICA!B2 -> ALT01 | C3: =ESTADISTICA!C2 -> Calchaqui y Sgto. Cabral | D3: =ESTADISTICA!D2 -> Domo | E3: =ESTADISTICA!E2 -> Fibra Optica | F3: =ESTADISTICA!F2 -> 0 | G3: =ESTADISTICA!G2 -> 0 | H3: =ESTADISTICA!H2 -> 0 | ... AJ3: =ESTADISTICA!AJ2 -> #REF!
A4: =ESTADISTICA!A3 -> ALTAMIRA | B4: =ESTADISTICA!B3 -> ALT02 | C4: =ESTADISTICA!C3 -> Calchaqui y Lope de Vega | D4: =ESTADISTICA!D3 -> Domo | E4: =ESTADISTICA!E3 -> PTO A FO | F4: =ESTADISTICA!F3 -> 0 | G4: =ESTADISTICA!G3 -> 0 | H4: =ESTADISTICA!H3 -> 0 | ... AJ4: =ESTADISTICA!AJ3 -> #REF!
A5: =ESTADISTICA!A4 -> ALTAMIRA | B5: =ESTADISTICA!B4 -> ALT 03 | C5: =ESTADISTICA!C4 -> Bombero Galarza y Necochea | D5: =ESTADISTICA!D4 -> Domo | E5: =ESTADISTICA!E4 -> Fibra Optica | F5: =ESTADISTICA!F4 -> 0 | G5: =ESTADISTICA!G4 -> 0 | H5: =ESTADISTICA!H4 -> 0 | ... AJ5: =ESTADISTICA!AJ4 -> #REF!
A6: =ESTADISTICA!A5 -> ALTAMIRA | B6: =ESTADISTICA!B5 -> ALT 04 | C6: =ESTADISTICA!C5 -> Francia y Necochea | D6: =ESTADISTICA!D5 -> Domo | E6: =ESTADISTICA!E5 -> Fibra Optica | F6: =ESTADISTICA!F5 -> 0 | G6: =ESTADISTICA!G5 -> 0 | H6: =ESTADISTICA!H5 -> 0 | ... AJ6: =ESTADISTICA!AJ5 -> #REF!
A7: =ESTADISTICA!A6 -> ALTAMIRA | B7: =ESTADISTICA!B6 -> ALT05 | C7: =ESTADISTICA!C6 -> Av. Calchaqui y Bombero Galarza | D7: =ESTADISTICA!D6 -> Domo | E7: =ESTADISTICA!E6 -> PTO A FO | F7: =ESTADISTICA!F6 -> 0 | G7: =ESTADISTICA!G6 -> 0 | H7: =ESTADISTICA!H6 -> 0 | ... AJ7: =ESTADISTICA!AJ6 -> #REF!
A8: =ESTADISTICA!A7 -> ALTAMIRA | B8: =ESTADISTICA!B7 -> ALT 06 | C8: =ESTADISTICA!C7 -> LOPE DE VEGA Y NECOCHEA | D8: =ESTADISTICA!D7 -> Domo | E8: =ESTADISTICA!E7 -> PTO A FO | F8: =ESTADISTICA!F7 -> 0 | G8: =ESTADISTICA!G7 -> 0 | H8: =ESTADISTICA!H7 -> 0 | ... AJ8: =ESTADISTICA!AJ7 -> #REF!
A9: =ESTADISTICA!A8 -> ALTAMIRA | B9: =ESTADISTICA!B8 -> ALT07 | C9: =ESTADISTICA!C8 -> AV. CALCHAQUI Y AV. DEL TRABAJO | D9: =ESTADISTICA!D8 -> DOMO | E9: =ESTADISTICA!E8 -> PTO A FO | F9: =ESTADISTICA!F8 -> 0 | G9: =ESTADISTICA!G8 -> 0 | H9: =ESTADISTICA!H8 -> 0 | ... AJ9: =ESTADISTICA!AJ8 -> #REF!
A10: =ESTADISTICA!A9 -> ALTAMIRA | B10: =ESTADISTICA!B9 -> ALT 08 | C10: =ESTADISTICA!C9 -> HUMAITA Y NECOCHEA | D10: =ESTADISTICA!D9 -> DOMO | E10: =ESTADISTICA!E9 -> Fibra Optica | F10: =ESTADISTICA!F9 -> 0 | G10: =ESTADISTICA!G9 -> 0 | H10: =ESTADISTICA!H9 -> 0 | ... AJ10: =ESTADISTICA!AJ9 -> #REF!
A11: =ESTADISTICA!A10 -> ALTAMIRA | B11: =ESTADISTICA!B10 -> ALT 09 | C11: =ESTADISTICA!C10 -> NECOCHEA Y CURUPAITY | D11: =ESTADISTICA!D10 -> DOMO | E11: =ESTADISTICA!E10 -> Fibra Optica | F11: =ESTADISTICA!F10 -> 0 | G11: =ESTADISTICA!G10 -> 0 | H11: =ESTADISTICA!H10 -> 0 | ... AJ11: =ESTADISTICA!AJ10 -> #REF!
A12: =ESTADISTICA!A11 -> ALTAMIRA | B12: =ESTADISTICA!B11 -> ALT 10 | C12: =ESTADISTICA!C11 -> Calchaqui y Francia | D12: =ESTADISTICA!D11 -> Domo | E12: =ESTADISTICA!E11 -> Radio | F12: =ESTADISTICA!F11 -> 0 | G12: =ESTADISTICA!G11 -> 0 | H12: =ESTADISTICA!H11 -> 0 | ... AJ12: =ESTADISTICA!AJ11 -> #REF!
A13: =ESTADISTICA!A12 -> AGUSTIN RAMIREZ | B13: =ESTADISTICA!B12 -> ARA 01 | C13: =ESTADISTICA!C12 -> Malambo y Tranquera | D13: =ESTADISTICA!D12 -> Domo | E13: =ESTADISTICA!E12 -> Fibra Optica | F13: =ESTADISTICA!F12 -> 0 | G13: =ESTADISTICA!G12 -> 0 | H13: =ESTADISTICA!H12 -> 0 | ... AJ13: =ESTADISTICA!AJ12 -> #REF!
... A207: =ESTADISTICA!A206 -> SAN EMILIO | B207: =ESTADISTICA!B206 -> MFI06 | C207: =ESTADISTICA!C206 -> Con. Gral. Belgrano y Bombero Galarza | D207: =ESTADISTICA!D206 -> DOMO | E207: =ESTADISTICA!E206 -> Radio | F207: =ESTADISTICA!F206 -> 0 | G207: =ESTADISTICA!G206 -> 0 | H207: =ESTADISTICA!H206 -> 0 | ... AJ207: =ESTADISTICA!AJ206 -> #REF!
A208: =ESTADISTICA!A208 -> MARTIN FIERRO | B208: =ESTADISTICA!B208 -> MFI 08 | C208: =ESTADISTICA!C208 -> Braile y Batalla de Callao | D208: =ESTADISTICA!D208 -> Domo | E208: =ESTADISTICA!E208 -> PTO A FO | F208: =ESTADISTICA!F208 -> 0 | G208: =ESTADISTICA!G208 -> 0 | H208: =ESTADISTICA!H208 -> 0 | ... AJ208: =ESTADISTICA!AJ208 -> #REF!
A209: =ESTADISTICA!A209 -> GOBERNADOR MONTEVERDE | B209: =ESTADISTICA!B209 -> MON01 | C209: =ESTADISTICA!C209 -> San Martin y Patricias Argentinas | D209: =ESTADISTICA!D209 -> Fija | E209: =ESTADISTICA!E209 -> Fibra Optica | F209: =ESTADISTICA!F209 -> 0 | G209: =ESTADISTICA!G209 -> 0 | H209: =ESTADISTICA!H209 -> 0 | ... AJ209: =ESTADISTICA!AJ209 -> #REF!
A210: =ESTADISTICA!A210 -> GOBERNADOR MONTEVERDE | B210: =ESTADISTICA!B210 -> MON02 | C210: =ESTADISTICA!C210 -> Senzabello y Famatina | D210: =ESTADISTICA!D210 -> Domo | E210: =ESTADISTICA!E210 -> Radio | F210: =ESTADISTICA!F210 -> 0 | G210: =ESTADISTICA!G210 -> 0 | H210: =ESTADISTICA!H210 -> 0 | ... AJ210: =ESTADISTICA!AJ210 -> #REF!
A211: =ESTADISTICA!A211 -> GOBERNADOR MONTEVERDE | B211: =ESTADISTICA!B211 -> MON03 | C211: =ESTADISTICA!C211 -> Senzabello y Guemes | D211: =ESTADISTICA!D211 -> Domo | E211: =ESTADISTICA!E211 -> Radio | F211: =ESTADISTICA!F211 -> 0 | G211: =ESTADISTICA!G211 -> 0 | H211: =ESTADISTICA!H211 -> 0 | ... AJ211: =ESTADISTICA!AJ211 -> #REF!
A212: =ESTADISTICA!A212 -> GOBERNADOR MONTEVERDE | B212: =ESTADISTICA!B212 -> MON04 | C212: =ESTADISTICA!C212 -> Av. Yrigoyen y San Lorenzo | D212: =ESTADISTICA!D212 -> Domo | E212: =ESTADISTICA!E212 -> Radio | F212: =ESTADISTICA!F212 -> 0 | G212: =ESTADISTICA!G212 -> 0 | H212: =ESTADISTICA!H212 -> 0 | ... AJ212: =ESTADISTICA!AJ212 -> #REF!
A213: =ESTADISTICA!A213 -> 9 DE JULIO | B213: =ESTADISTICA!B213 -> NJU 01 | C213: =ESTADISTICA!C213 -> Sallares y Parrillo | D213: =ESTADISTICA!D213 -> Domo | E213: =ESTADISTICA!E213 -> Fibra Optica | F213: =ESTADISTICA!F213 -> 0 | G213: =ESTADISTICA!G213 -> 0 | H213: =ESTADISTICA!H213 -> 0 | ... AJ213: =ESTADISTICA!AJ213 -> #REF!
A214: =ESTADISTICA!A214 -> 9 DE JULIO | B214: =ESTADISTICA!B214 -> NJU02 | C214: =ESTADISTICA!C214 -> Ituzaingo y Boccuzzi | D214: =ESTADISTICA!D214 -> Domo | E214: =ESTADISTICA!E214 -> Radio | F214: =ESTADISTICA!F214 -> 0 | G214: =ESTADISTICA!G214 -> 0 | H214: =ESTADISTICA!H214 -> 0 | ... AJ214: =ESTADISTICA!AJ214 -> #REF!
A215: =ESTADISTICA!A215 -> 9 DE JULIO | B215: =ESTADISTICA!B215 -> NJU03 | C215: =ESTADISTICA!C215 -> San Juan y Parrillo | D215: =ESTADISTICA!D215 -> Domo | E215: =ESTADISTICA!E215 -> PTO A FO | F215: =ESTADISTICA!F215 -> 0 | G215: =ESTADISTICA!G215 -> 0 | H215: =ESTADISTICA!H215 -> 0 | ... AJ215: =ESTADISTICA!AJ215 -> #REF!
A216: =ESTADISTICA!A216 -> 9 DE JULIO | B216: =ESTADISTICA!B216 -> NJU04 | C216: =ESTADISTICA!C216 -> Ituzaingo y 214 A | D216: =ESTADISTICA!D216 -> Domo | E216: =ESTADISTICA!E216 -> Radio | F216: =ESTADISTICA!F216 -> 0 | G216: =ESTADISTICA!G216 -> 0 | H216: =ESTADISTICA!H216 -> 0 | ... AJ216: =ESTADISTICA!AJ216 -> #REF!
A217: =ESTADISTICA!A217 -> ZEBALLOS CENTRO | B217: =ESTADISTICA!B217 -> NJU05 | C217: =ESTADISTICA!C217 -> Ituzaingo y Alem | D217: =ESTADISTICA!D217 -> Domo | E217: =ESTADISTICA!E217 -> Radio | F217: =ESTADISTICA!F217 -> 0 | G217: =ESTADISTICA!G217 -> 0 | H217: =ESTADISTICA!H217 -> 0 | ... AJ217: =ESTADISTICA!AJ217 -> #REF!
A218: =ESTADISTICA!A218 -> CENTRO | B218: =ESTADISTICA!B218 -> NJU06 | C218: =ESTADISTICA!C218 -> Sallares y Rodo | D218: =ESTADISTICA!D218 -> Domo | E218: =ESTADISTICA!E218 -> Fibra Optica | F218: =ESTADISTICA!F218 -> 0 | G218: =ESTADISTICA!G218 -> 0 | H218: =ESTADISTICA!H218 -> 0 | ... AJ218: =ESTADISTICA!AJ218 -> #REF!
A219: =ESTADISTICA!A219 -> 9 DE JULIO | B219: =ESTADISTICA!B219 -> NJU07 | C219: =ESTADISTICA!C219 -> Gral. Juan Domingo Peron y Parrillo | D219: =ESTADISTICA!D219 -> Domo | E219: =ESTADISTICA!E219 -> Fibra Optica | F219: =ESTADISTICA!F219 -> 0 | G219: =ESTADISTICA!G219 -> 0 | H219: =ESTADISTICA!H219 -> 0 | ... AJ219: =ESTADISTICA!AJ219 -> #REF!
... A516: =ESTADISTICA!A516 -> 0 | B516: =ESTADISTICA!B516 -> 0 | C516: =ESTADISTICA!C516 -> 0 | D516: =ESTADISTICA!D516 -> 0 | E516: =ESTADISTICA!E516 -> 0 | F516: =ESTADISTICA!F516 -> 0 | G516: =ESTADISTICA!G516 -> 0 | H516: =ESTADISTICA!H516 -> 0 | ... AJ516: =ESTADISTICA!AJ516 -> #REF!

Sheet APAGADOS FIBRA
C1: TOTAL FIBRA | D1: =COUNTIFS(E4:E401,"=Fibra Optica") -> 271
E2: APAGADOS | F2: =COUNTIFS(F4:F501, "=APAGADO",E4:E501,"=Fibra Optica") -> 0 | G2: =COUNTIFS(G4:G501, "=APAGADO",E4:E501,"=Fibra Optica") -> 0 | H2: =COUNTIFS(H4:H501, "=APAGADO",E4:E501,"=Fibra Optica") -> 0 | I2: =COUNTIFS(I4:I501, "=APAGADO",E4:E501,"=Fibra Optica") -> 0 | J2: =COUNTIFS(J4:J501, "=APAGADO",E4:E501,"=Fibra Optica") -> 0 | K2: =COUNTIFS(K4:K501, "=APAGADO",E4:E501,"=Fibra Optica") -> 21 | L2: =COUNTIFS(L4:L501, "=APAGADO",E4:E501,"=Fibra Optica") -> 8 | M2: =COUNTIFS(M4:M501, "=APAGADO",E4:E501,"=Fibra Optica") -> 0 | N2: =COUNTIFS(N4:N501, "=APAGADO",E4:E501,"=Fibra Optica") -> 0 | O2: =COUNTIFS(O4:O501, "=APAGADO",E4:E501,"=Fibra Optica") -> 6 | P2: =COUNTIFS(P4:P501, "=APAGADO",E4:E501,"=Fibra Optica") -> 33 | Q2: =COUNTIFS(Q4:Q501, "=APAGADO",E4:E501,"=Fibra Optica") -> 32 | R2: =COUNTIFS(R4:R501, "=APAGADO",E4:E501,"=Fibra Optica") -> 55 | S2: =COUNTIFS(S4:S501, "=APAGADO",E4:E501,"=Fibra Optica") -> 98 | T2: =COUNTIFS(T4:T501, "=APAGADO",E4:E501,"=Fibra Optica") -> 29 | U2: =COUNTIFS(U4:U501, "=APAGADO",E4:E501,"=Fibra Optica") -> 44 | V2: =COUNTIFS(V4:V501, "=APAGADO",E4:E501,"=Fibra Optica") -> 75 | W2: =COUNTIFS(W4:W501, "=APAGADO",E4:E501,"=Fibra Optica") -> 69 | X2: =COUNTIFS(X4:X501, "=APAGADO",E4:E501,"=Fibra Optica") -> 79 | Y2: =COUNTIFS(Y4:Y501, "=APAGADO",E4:E501,"=Fibra Optica") -> 34 | Z2: =COUNTIFS(Z4:Z501, "=APAGADO",E4:E501,"=Fibra Optica") -> 31 | AA2: =COUNTIFS(AA4:AA501, "=APAGADO",E4:E501,"=Fibra Optica") -> 32 | AB2: =COUNTIFS(AB4:AB501, "=APAGADO",E4:E501,"=Fibra Optica") -> 0 | AC2: =COUNTIFS(AC4:AC501, "=APAGADO",E4:E501,"=Fibra Optica") -> 0 | AD2: =COUNTIFS(AD4:AD501, "=APAGADO",E4:E501,"=Fibra Optica") -> 0 | AE2: =COUNTIFS(AE4:AE501, "=APAGADO",E4:E501,"=Fibra Optica") -> 0 | AF2: =COUNTIFS(AF4:AF501, "=APAGADO",E4:E501,"=Fibra Optica") -> 0 | AG2: =COUNTIFS(AG4:AG501, "=APAGADO",E4:E501,"=Fibra Optica") -> 0 | AH2: =COUNTIFS(AH4:AH501, "=APAGADO",E4:E501,"=Fibra Optica") -> 0 | AI2: =COUNTIFS(AI4:AI401, "=APAGADO",E4:E401,"=Fibra Optica") -> 0 | AJ2: =COUNTIFS(AJ4:AJ401, "=APAGADO",F4:F401,"=Fibra Optica") -> 0
A3: =ESTADISTICA!A1 -> Barrio | B3: =ESTADISTICA!B1 -> [Denominacion] | C3: =ESTADISTICA!C1 -> [Ubicacion] | D3: =ESTADISTICA!D1 -> [Tipo de Camara] | E3: =ESTADISTICA!E1 -> [Tipo de Conexion] | F3: =ESTADISTICA!F1 -> 45108 | G3: =ESTADISTICA!G1 -> 45109 | H3: =ESTADISTICA!H1 -> 45110 | ... AJ3: =ESTADISTICA!AJ1 -> #REF!
A4: ='RESUMEN TOTAL'!A7 -> ALTAMIRA | B4: ='RESUMEN TOTAL'!B7 -> ALT 03 | C4: ='RESUMEN TOTAL'!D7 -> Bombero Galarza y Necochea | D4: ='RESUMEN TOTAL'!E7 -> Domo | E4: ='RESUMEN TOTAL'!F7 -> Fibra Optica | F4: ='RESUMEN TOTAL'!L7 -> 0 | G4: ='RESUMEN TOTAL'!M7 -> 0 | H4: ='RESUMEN TOTAL'!N7 -> 0 | I4: ='RESUMEN TOTAL'!O7 -> 0 | J4: ='RESUMEN TOTAL'!P7 -> 0 | K4: ='RESUMEN TOTAL'!Q7 -> 0 | L4: ='RESUMEN TOTAL'!R7 -> 0 | M4: ='RESUMEN TOTAL'!S7 -> 0 | ... AI4: ='RESUMEN TOTAL'!AO7 -> 0 | AJ4: ='RESUMEN TOTAL'!#REF! -> #REF!
A5: ='RESUMEN TOTAL'!A8 -> ALTAMIRA | B5: ='RESUMEN TOTAL'!B8 -> ALT 04 | C5: ='RESUMEN TOTAL'!D8 -> Francia y Necochea | D5: ='RESUMEN TOTAL'!E8 -> Domo | E5: ='RESUMEN TOTAL'!F8 -> Fibra Optica | F5: ='RESUMEN TOTAL'!L8 -> 0 | G5: ='RESUMEN TOTAL'!M8 -> 0 | H5: ='RESUMEN TOTAL'!N8 -> 0 | I5: ='RESUMEN TOTAL'!O8 -> 0 | J5: ='RESUMEN TOTAL'!P8 -> 0 | K5: ='RESUMEN TOTAL'!Q8 -> 0 | L5: ='RESUMEN TOTAL'!R8 -> 0 | M5: ='RESUMEN TOTAL'!S8 -> 0 | ... AI5: ='RESUMEN TOTAL'!AO8 -> 0 | AJ5: ='RESUMEN TOTAL'!#REF! -> #REF!
A6: ='RESUMEN TOTAL'!A9 -> ALTAMIRA | B6: ='RESUMEN TOTAL'!B9 -> ALT05 | C6: ='RESUMEN TOTAL'!D9 -> Av. Calchaqui y Bombero Galarza | D6: ='RESUMEN TOTAL'!E9 -> Domo | E6: ='RESUMEN TOTAL'!F9 -> PTO A FO | F6: ='RESUMEN TOTAL'!L9 -> 0 | G6: ='RESUMEN TOTAL'!M9 -> 0 | H6: ='RESUMEN TOTAL'!N9 -> 0 | I6: ='RESUMEN TOTAL'!O9 -> 0 | J6: ='RESUMEN TOTAL'!P9 -> 0 | K6: ='RESUMEN TOTAL'!Q9 -> 0 | L6: ='RESUMEN TOTAL'!R9 -> 0 | M6: ='RESUMEN TOTAL'!S9 -> 0 | ... AI6: ='RESUMEN TOTAL'!AO9 -> 0 | AJ6: ='RESUMEN TOTAL'!#REF! -> #REF!
A7: ='RESUMEN TOTAL'!A10 -> ALTAMIRA | B7: ='RESUMEN TOTAL'!B10 -> ALT 06 | C7: ='RESUMEN TOTAL'!D10 -> LOPE DE VEGA Y NECOCHEA | D7: ='RESUMEN TOTAL'!E10 -> Domo | E7: ='RESUMEN TOTAL'!F10 -> PTO A FO | F7: ='RESUMEN TOTAL'!L10 -> 0 | G7: ='RESUMEN TOTAL'!M10 -> 0 | H7: ='RESUMEN TOTAL'!N10 -> 0 | I7: ='RESUMEN TOTAL'!O10 -> 0 | J7: ='RESUMEN TOTAL'!P10 -> 0 | K7: ='RESUMEN TOTAL'!Q10 -> 0 | L7: ='RESUMEN TOTAL'!R10 -> 0 | M7: ='RESUMEN TOTAL'!S10 -> 0 | ... AI7: ='RESUMEN TOTAL'!AO10 -> 0 | AJ7: ='RESUMEN TOTAL'!#REF! -> #REF!
A8: ='RESUMEN TOTAL'!A11 -> ALTAMIRA | B8: ='RESUMEN TOTAL'!B11 -> ALT07 | C8: ='RESUMEN TOTAL'!D11 -> AV. CALCHAQUI Y AV. DEL TRABAJO | D8: ='RESUMEN TOTAL'!E11 -> DOMO | E8: ='RESUMEN TOTAL'!F11 -> PTO A FO | F8: ='RESUMEN TOTAL'!L11 -> 0 | G8: ='RESUMEN TOTAL'!M11 -> 0 | H8: ='RESUMEN TOTAL'!N11 -> 0 | I8: ='RESUMEN TOTAL'!O11 -> 0 | J8: ='RESUMEN TOTAL'!P11 -> 0 | K8: ='RESUMEN TOTAL'!Q11 -> 0 | L8: ='RESUMEN TOTAL'!R11 -> 0 | M8: ='RESUMEN TOTAL'!S11 -> 0 | ... AI8: ='RESUMEN TOTAL'!AO11 -> 0 | AJ8: ='RESUMEN TOTAL'!#REF! -> #REF!
A9: ='RESUMEN TOTAL'!A12 -> ALTAMIRA | B9: ='RESUMEN TOTAL'!B12 -> ALT 08 | C9: ='RESUMEN TOTAL'!D12 -> HUMAITA Y NECOCHEA | D9: ='RESUMEN TOTAL'!E12 -> DOMO | E9: ='RESUMEN TOTAL'!F12 -> Fibra Optica | F9: ='RESUMEN TOTAL'!L12 -> 0 | G9: ='RESUMEN TOTAL'!M12 -> 0 | H9: ='RESUMEN TOTAL'!N12 -> 0 | I9: ='RESUMEN TOTAL'!O12 -> 0 | J9: ='RESUMEN TOTAL'!P12 -> 0 | K9: ='RESUMEN TOTAL'!Q12 -> 0 | L9: ='RESUMEN TOTAL'!R12 -> 0 | M9: ='RESUMEN TOTAL'!S12 -> 0 | ... AI9: ='RESUMEN TOTAL'!AO12 -> 0 | AJ9: ='RESUMEN TOTAL'!#REF! -> #REF!
A10: ='RESUMEN TOTAL'!A13 -> ALTAMIRA | B10: ='RESUMEN TOTAL'!B13 -> ALT 09 | C10: ='RESUMEN TOTAL'!D13 -> NECOCHEA Y CURUPAITY | D10: ='RESUMEN TOTAL'!E13 -> DOMO | E10: ='RESUMEN TOTAL'!F13 -> Fibra Optica | F10: ='RESUMEN TOTAL'!L13 -> 0 | G10: ='RESUMEN TOTAL'!M13 -> 0 | H10: ='RESUMEN TOTAL'!N13 -> 0 | I10: ='RESUMEN TOTAL'!O13 -> 0 | J10: ='RESUMEN TOTAL'!P13 -> 0 | K10: ='RESUMEN TOTAL'!Q13 -> APAGADO | L10: ='RESUMEN TOTAL'!R13 -> APAGADO | M10: ='RESUMEN TOTAL'!S13 -> 0 | ... AI10: ='RESUMEN TOTAL'!AO13 -> 0 | AJ10: ='RESUMEN TOTAL'!#REF! -> #REF!
A11: ='RESUMEN TOTAL'!A14 -> ALTAMIRA | B11: ='RESUMEN TOTAL'!B14 -> ALT 10 | C11: ='RESUMEN TOTAL'!D14 -> Calchaqui y Francia | D11: ='RESUMEN TOTAL'!E14 -> Domo | E11: ='RESUMEN TOTAL'!F14 -> Radio | F11: ='RESUMEN TOTAL'!L14 -> 0 | G11: ='RESUMEN TOTAL'!M14 -> 0 | H11: ='RESUMEN TOTAL'!N14 -> 0 | I11: ='RESUMEN TOTAL'!O14 -> 0 | J11: ='RESUMEN TOTAL'!P14 -> 0 | K11: ='RESUMEN TOTAL'!Q14 -> 0 | L11: ='RESUMEN TOTAL'!R14 -> 0 | M11: ='RESUMEN TOTAL'!S14 -> 0 | ... AI11: ='RESUMEN TOTAL'!AO14 -> 0 | AJ11: ='RESUMEN TOTAL'!#REF! -> #REF!
A12: ='RESUMEN TOTAL'!A15 -> AGUSTIN RAMIREZ | B12: ='RESUMEN TOTAL'!B15 -> ARA 01 | C12: ='RESUMEN TOTAL'!D15 -> Malambo y Tranquera | D12: ='RESUMEN TOTAL'!E15 -> Domo | E12: ='RESUMEN TOTAL'!F15 -> Fibra Optica | F12: ='RESUMEN TOTAL'!L15 -> 0 | G12: ='RESUMEN TOTAL'!M15 -> 0 | H12: ='RESUMEN TOTAL'!N15 -> 0 | I12: ='RESUMEN TOTAL'!O15 -> 0 | J12: ='RESUMEN TOTAL'!P15 -> 0 | K12: ='RESUMEN TOTAL'!Q15 -> 0 | L12: ='RESUMEN TOTAL'!R15 -> 0 | M12: ='RESUMEN TOTAL'!S15 -> 0 | ... AI12: ='RESUMEN TOTAL'!AO15 -> 0 | AJ12: ='RESUMEN TOTAL'!#REF! -> #REF!
A13: ='RESUMEN TOTAL'!A16 -> BELGRANO | B13: ='RESUMEN TOTAL'!B16 -> BEL 01 | C13: ='RESUMEN TOTAL'!D16 -> San Martin y Dardo Rocha | D13: ='RESUMEN TOTAL'!E16 -> DOMO | E13: ='RESUMEN TOTAL'!F16 -> Fibra Optica | F13: ='RESUMEN TOTAL'!L16 -> 0 | G13: ='RESUMEN TOTAL'!M16 -> 0 | H13: ='RESUMEN TOTAL'!N16 -> 0 | I13: ='RESUMEN TOTAL'!O16 -> 0 | J13: ='RESUMEN TOTAL'!P16 -> 0 | K13: ='RESUMEN TOTAL'!Q16 -> 0 | L13: ='RESUMEN TOTAL'!R16 -> 0 | M13: ='RESUMEN TOTAL'!S16 -> 0 | ... AI13: ='RESUMEN TOTAL'!AO16 -> 0 | AJ13: ='RESUMEN TOTAL'!#REF! -> #REF!
A14: ='RESUMEN TOTAL'!A17 -> BELGRANO | B14: ='RESUMEN TOTAL'!B17 -> BEL 02 | C14: ='RESUMEN TOTAL'!D17 -> Guardia vieja y Fronteriz | D14: ='RESUMEN TOTAL'!E17 -> DOMO | E14: ='RESUMEN TOTAL'!F17 -> Fibra Optica | F14: ='RESUMEN TOTAL'!L17 -> 0 | G14: ='RESUMEN TOTAL'!M17 -> 0 | H14: ='RESUMEN TOTAL'!N17 -> 0 | I14: ='RESUMEN TOTAL'!O17 -> 0 | J14: ='RESUMEN TOTAL'!P17 -> 0 | K14: ='RESUMEN TOTAL'!Q17 -> 0 | L14: ='RESUMEN TOTAL'!R17 -> 0 | M14: ='RESUMEN TOTAL'!S17 -> 0 | ... AI14: ='RESUMEN TOTAL'!AO17 -> 0 | AJ14: ='RESUMEN TOTAL'!#REF! -> #REF!
A15: ='RESUMEN TOTAL'!A18 -> BOSQUES CENTRO | B15: ='RESUMEN TOTAL'!B18 -> BOSQC 01 | C15: ='RESUMEN TOTAL'!D18 -> LUIS AGOTE E/DANUNCIO Y CAMPOAMOR | D15: ='RESUMEN TOTAL'!E18 -> Fija | E15: ='RESUMEN TOTAL'!F18 -> Radio | F15: ='RESUMEN TOTAL'!L18 -> 0 | G15: ='RESUMEN TOTAL'!M18 -> 0 | H15: ='RESUMEN TOTAL'!N18 -> 0 | I15: ='RESUMEN TOTAL'!O18 -> 0 | J15: ='RESUMEN TOTAL'!P18 -> 0 | K15: ='RESUMEN TOTAL'!Q18 -> 0 | L15: ='RESUMEN TOTAL'!R18 -> 0 | M15: ='RESUMEN TOTAL'!S18 -> 0 | ... AI15: ='RESUMEN TOTAL'!AO18 -> 0 | AJ15: ='RESUMEN TOTAL'!#REF! -> #REF!
... A603: ='RESUMEN TOTAL'!A606 -> 0 | B603: ='RESUMEN TOTAL'!B606 -> 0 | C603: ='RESUMEN TOTAL'!D606 -> 0 | D603: ='RESUMEN TOTAL'!E606 -> 0 | E603: ='RESUMEN TOTAL'!F606 -> 0 | F603: ='RESUMEN TOTAL'!L606 -> 0 | G603: ='RESUMEN TOTAL'!M606 -> 0 | H603: ='RESUMEN TOTAL'!N606 -> 0 | I603: ='RESUMEN TOTAL'!O606 -> 0 | J603: ='RESUMEN TOTAL'!P606 -> 0 | K603: ='RESUMEN TOTAL'!Q606 -> 0 | L603: ='RESUMEN TOTAL'!R606 -> 0 | M603: ='RESUMEN TOTAL'!S606 -> 0 | ... AI603: ='RESUMEN TOTAL'!AO606 -> 0 | AJ603: ='RESUMEN TOTAL'!#REF! -> #REF!

Sheet APAGADOS ANTENA
C1: TOTAL PTO A FO
E2: APAGADOS | F2: =COUNTIFS(F5:F502, "=APAGADO",E5:E502,"=PTO A FO") -> 0 | G2: =COUNTIFS(G5:G502, "=APAGADO",E5:E502,"=PTO A FO") -> 0 | H2: =COUNTIFS(H5:H502, "=APAGADO",E5:E502,"=PTO A FO") -> 0 | I2: =COUNTIFS(I5:I502, "=APAGADO",E5:E502,"=PTO A FO") -> 0 | J2: =COUNTIFS(J5:J502, "=APAGADO",E5:E502,"=PTO A FO") -> 0 | K2: =COUNTIFS(K5:K502, "=APAGADO",E5:E502,"=PTO A FO") -> 0 | L2: =COUNTIFS(L5:L502, "=APAGADO",E5:E502,"=PTO A FO") -> 0 | M2: =COUNTIFS(M5:M502, "=APAGADO",E5:E502,"=PTO A FO") -> 0 | N2: =COUNTIFS(N5:N502, "=APAGADO",E5:E502,"=PTO A FO") -> 0 | O2: =COUNTIFS(O5:O502, "=APAGADO",E5:E502,"=PTO A FO") -> 0 | P2: =COUNTIFS(P5:P502, "=APAGADO",E5:E502,"=PTO A FO") -> 4 | Q2: =COUNTIFS(Q5:Q502, "=APAGADO",E5:E502,"=PTO A FO") -> 1 | R2: =COUNTIFS(R5:R502, "=APAGADO",E5:E502,"=PTO A FO") -> 1 | S2: =COUNTIFS(S5:S502, "=APAGADO",E5:E502,"=PTO A FO") -> 8 | T2: =COUNTIFS(T5:T502, "=APAGADO",E5:E502,"=PTO A FO") -> 4 | U2: =COUNTIFS(U5:U502, "=APAGADO",E5:E502,"=PTO A FO") -> 6 | V2: =COUNTIFS(V5:V502, "=APAGADO",E5:E502,"=PTO A FO") -> 10 | W2: =COUNTIFS(W5:W502, "=APAGADO",E5:E502,"=PTO A FO") -> 5 | X2: =COUNTIFS(X4:X502, "=APAGADO",E4:E502,"=PTO A FO") -> 6 | Y2: =COUNTIFS(Y5:Y502, "=APAGADO",E5:E502,"=PTO A FO") -> 0 | Z2: =COUNTIFS(Z5:Z502, "=APAGADO",E5:E502,"=PTO A FO") -> 0 | AA2: =COUNTIFS(AA5:AA502, "=APAGADO",E5:E502,"=PTO A FO") -> 4 | AB2: =COUNTIFS(AB5:AB502, "=APAGADO",E5:E502,"=PTO A FO") -> 0 | AC2: =COUNTIFS(AC5:AC502, "=APAGADO",E5:E502,"=PTO A FO") -> 0 | AD2: =COUNTIFS(AD5:AD502, "=APAGADO",E5:E502,"=PTO A FO") -> 0 | AE2: =COUNTIFS(AE5:AE502, "=APAGADO",E5:E502,"=PTO A FO") -> 0 | AF2: =COUNTIFS(AF5:AF502, "=APAGADO",E5:E502,"=PTO A FO") -> 0 | AG2: =COUNTIFS(AG5:AG502, "=APAGADO",E5:E502,"=PTO A FO") -> 0 | AH2: =COUNTIFS(AH5:AH502, "=APAGADO",E5:E502,"=PTO A FO") -> 0 | AI2: =COUNTIFS(AI5:AI502, "=APAGADO",E5:E502,"=PTO A FO") -> 0
A3: =ESTADISTICA!A1 -> Barrio | B3: =ESTADISTICA!B1 -> [Denominacion] | C3: =ESTADISTICA!C1 -> [Ubicacion] | D3: =ESTADISTICA!D1 -> [Tipo de Camara] | E3: =ESTADISTICA!E1 -> [Tipo de Conexion] | F3: =ESTADISTICA!F1 -> 45108 | G3: =ESTADISTICA!G1 -> 45109 | H3: =ESTADISTICA!H1 -> 45110 | ... AI3: =ESTADISTICA!AI1 -> 45137
A4: ='RESUMEN TOTAL'!A6 -> ALTAMIRA | B4: ='RESUMEN TOTAL'!B6 -> ALT02 | C4: ='RESUMEN TOTAL'!D6 -> Calchaqui y Lope de Vega | D4: ='RESUMEN TOTAL'!E6 -> Domo | E4: ='RESUMEN TOTAL'!F6 -> PTO A FO | F4: ='RESUMEN TOTAL'!L6 -> 0 | G4: ='RESUMEN TOTAL'!M6 -> 0 | H4: ='RESUMEN TOTAL'!N6 -> 0 | I4: ='RESUMEN TOTAL'!O6 -> 0 | J4: ='RESUMEN TOTAL'!P6 -> 0 | K4: ='RESUMEN TOTAL'!Q6 -> 0 | L4: ='RESUMEN TOTAL'!R6 -> 0 | M4: ='RESUMEN TOTAL'!S6 -> 0 | ... AI4: ='RESUMEN TOTAL'!AO6 -> 0 | AJ4: ='RESUMEN TOTAL'!#REF! -> #REF!
A5: ='RESUMEN TOTAL'!A7 -> ALTAMIRA | B5: ='RESUMEN TOTAL'!B7 -> ALT 03 | C5: ='RESUMEN TOTAL'!D7 -> Bombero Galarza y Necochea | D5: ='RESUMEN TOTAL'!E7 -> Domo | E5: ='RESUMEN TOTAL'!F7 -> Fibra Optica | F5: ='RESUMEN TOTAL'!L7 -> 0 | G5: ='RESUMEN TOTAL'!M7 -> 0 | H5: ='RESUMEN TOTAL'!N7 -> 0 | I5: ='RESUMEN TOTAL'!O7 -> 0 | J5: ='RESUMEN TOTAL'!P7 -> 0 | K5: ='RESUMEN TOTAL'!Q7 -> 0 | L5: ='RESUMEN TOTAL'!R7 -> 0 | M5: ='RESUMEN TOTAL'!S7 -> 0 | ... AI5: ='RESUMEN TOTAL'!AO7 -> 0 | AJ5: ='RESUMEN TOTAL'!#REF! -> #REF!
A6: ='RESUMEN TOTAL'!A8 -> ALTAMIRA | B6: ='RESUMEN TOTAL'!B8 -> ALT 04 | C6: ='RESUMEN TOTAL'!D8 -> Francia y Necochea | D6: ='RESUMEN TOTAL'!E8 -> Domo | E6: ='RESUMEN TOTAL'!F8 -> Fibra Optica | F6: ='RESUMEN TOTAL'!L8 -> 0 | G6: ='RESUMEN TOTAL'!M8 -> 0 | H6: ='RESUMEN TOTAL'!N8 -> 0 | I6: ='RESUMEN TOTAL'!O8 -> 0 | J6: ='RESUMEN TOTAL'!P8 -> 0 | K6: ='RESUMEN TOTAL'!Q8 -> 0 | L6: ='RESUMEN TOTAL'!R8 -> 0 | M6: ='RESUMEN TOTAL'!S8 -> 0 | ... AI6: ='RESUMEN TOTAL'!AO8 -> 0 | AJ6: ='RESUMEN TOTAL'!#REF! -> #REF!
A7: ='RESUMEN TOTAL'!A9 -> ALTAMIRA | B7: ='RESUMEN TOTAL'!B9 -> ALT05 | C7: ='RESUMEN TOTAL'!D9 -> Av. Calchaqui y Bombero Galarza | D7: ='RESUMEN TOTAL'!E9 -> Domo | E7: ='RESUMEN TOTAL'!F9 -> PTO A FO | F7: ='RESUMEN TOTAL'!L9 -> 0 | G7: ='RESUMEN TOTAL'!M9 -> 0 | H7: ='RESUMEN TOTAL'!N9 -> 0 | I7: ='RESUMEN TOTAL'!O9 -> 0 | J7: ='RESUMEN TOTAL'!P9 -> 0 | K7: ='RESUMEN TOTAL'!Q9 -> 0 | L7: ='RESUMEN TOTAL'!R9 -> 0 | M7: ='RESUMEN TOTAL'!S9 -> 0 | ... AI7: ='RESUMEN TOTAL'!AO9 -> 0 | AJ7: ='RESUMEN TOTAL'!#REF! -> #REF!
A8: ='RESUMEN TOTAL'!A10 -> ALTAMIRA | B8: ='RESUMEN TOTAL'!B10 -> ALT 06 | C8: ='RESUMEN TOTAL'!D10 -> LOPE DE VEGA Y NECOCHEA | D8: ='RESUMEN TOTAL'!E10 -> Domo | E8: ='RESUMEN TOTAL'!F10 -> PTO A FO | F8: ='RESUMEN TOTAL'!L10 -> 0 | G8: ='RESUMEN TOTAL'!M10 -> 0 | H8: ='RESUMEN TOTAL'!N10 -> 0 | I8: ='RESUMEN TOTAL'!O10 -> 0 | J8: ='RESUMEN TOTAL'!P10 -> 0 | K8: ='RESUMEN TOTAL'!Q10 -> 0 | L8: ='RESUMEN TOTAL'!R10 -> 0 | M8: ='RESUMEN TOTAL'!S10 -> 0 | ... AI8: ='RESUMEN TOTAL'!AO10 -> 0 | AJ8: ='RESUMEN TOTAL'!#REF! -> #REF!
A9: ='RESUMEN TOTAL'!A11 -> ALTAMIRA | B9: ='RESUMEN TOTAL'!B11 -> ALT07 | C9: ='RESUMEN TOTAL'!D11 -> AV. CALCHAQUI Y AV. DEL TRABAJO | D9: ='RESUMEN TOTAL'!E11 -> DOMO | E9: ='RESUMEN TOTAL'!F11 -> PTO A FO | F9: ='RESUMEN TOTAL'!L11 -> 0 | G9: ='RESUMEN TOTAL'!M11 -> 0 | H9: ='RESUMEN TOTAL'!N11 -> 0 | I9: ='RESUMEN TOTAL'!O11 -> 0 | J9: ='RESUMEN TOTAL'!P11 -> 0 | K9: ='RESUMEN TOTAL'!Q11 -> 0 | L9: ='RESUMEN TOTAL'!R11 -> 0 | M9: ='RESUMEN TOTAL'!S11 -> 0 | ... AI9: ='RESUMEN TOTAL'!AO11 -> 0 | AJ9: ='RESUMEN TOTAL'!#REF! -> #REF!
A10: ='RESUMEN TOTAL'!A12 -> ALTAMIRA | B10: ='RESUMEN TOTAL'!B12 -> ALT 08 | C10: ='RESUMEN TOTAL'!D12 -> HUMAITA Y NECOCHEA | D10: ='RESUMEN TOTAL'!E12 -> DOMO | E10: ='RESUMEN TOTAL'!F12 -> Fibra Optica | F10: ='RESUMEN TOTAL'!L12 -> 0 | G10: ='RESUMEN TOTAL'!M12 -> 0 | H10: ='RESUMEN TOTAL'!N12 -> 0 | I10: ='RESUMEN TOTAL'!O12 -> 0 | J10: ='RESUMEN TOTAL'!P12 -> 0 | K10: ='RESUMEN TOTAL'!Q12 -> 0 | L10: ='RESUMEN TOTAL'!R12 -> 0 | M10: ='RESUMEN TOTAL'!S12 -> 0 | ... AI10: ='RESUMEN TOTAL'!AO12 -> 0 | AJ10: ='RESUMEN TOTAL'!#REF! -> #REF!
A11: ='RESUMEN TOTAL'!A13 -> ALTAMIRA | B11: ='RESUMEN TOTAL'!B13 -> ALT 09 | C11: ='RESUMEN TOTAL'!D13 -> NECOCHEA Y CURUPAITY | D11: ='RESUMEN TOTAL'!E13 -> DOMO | E11: ='RESUMEN TOTAL'!F13 -> Fibra Optica | F11: ='RESUMEN TOTAL'!L13 -> 0 | G11: ='RESUMEN TOTAL'!M13 -> 0 | H11: ='RESUMEN TOTAL'!N13 -> 0 | I11: ='RESUMEN TOTAL'!O13 -> 0 | J11: ='RESUMEN TOTAL'!P13 -> 0 | K11: ='RESUMEN TOTAL'!Q13 -> APAGADO | L11: ='RESUMEN TOTAL'!R13 -> APAGADO | M11: ='RESUMEN TOTAL'!S13 -> 0 | ... AI11: ='RESUMEN TOTAL'!AO13 -> 0 | AJ11: ='RESUMEN TOTAL'!#REF! -> #REF!
A12: ='RESUMEN TOTAL'!A14 -> ALTAMIRA | B12: ='RESUMEN TOTAL'!B14 -> ALT 10 | C12: ='RESUMEN TOTAL'!D14 -> Calchaqui y Francia | D12: ='RESUMEN TOTAL'!E14 -> Domo | E12: ='RESUMEN TOTAL'!F14 -> Radio | F12: ='RESUMEN TOTAL'!L14 -> 0 | G12: ='RESUMEN TOTAL'!M14 -> 0 | H12: ='RESUMEN TOTAL'!N14 -> 0 | I12: ='RESUMEN TOTAL'!O14 -> 0 | J12: ='RESUMEN TOTAL'!P14 -> 0 | K12: ='RESUMEN TOTAL'!Q14 -> 0 | L12: ='RESUMEN TOTAL'!R14 -> 0 | M12: ='RESUMEN TOTAL'!S14 -> 0 | ... AI12: ='RESUMEN TOTAL'!AO14 -> 0 | AJ12: ='RESUMEN TOTAL'!#REF! -> #REF!
A13: ='RESUMEN TOTAL'!A15 -> AGUSTIN RAMIREZ | B13: ='RESUMEN TOTAL'!B15 -> ARA 01 | C13: ='RESUMEN TOTAL'!D15 -> Malambo y Tranquera | D13: ='RESUMEN TOTAL'!E15 -> Domo | E13: ='RESUMEN TOTAL'!F15 -> Fibra Optica | F13: ='RESUMEN TOTAL'!L15 -> 0 | G13: ='RESUMEN TOTAL'!M15 -> 0 | H13: ='RESUMEN TOTAL'!N15 -> 0 | I13: ='RESUMEN TOTAL'!O15 -> 0 | J13: ='RESUMEN TOTAL'!P15 -> 0 | K13: ='RESUMEN TOTAL'!Q15 -> 0 | L13: ='RESUMEN TOTAL'!R15 -> 0 | M13: ='RESUMEN TOTAL'!S15 -> 0 | ... AI13: ='RESUMEN TOTAL'!AO15 -> 0 | AJ13: ='RESUMEN TOTAL'!#REF! -> #REF!
A14: ='RESUMEN TOTAL'!A16 -> BELGRANO | B14: ='RESUMEN TOTAL'!B16 -> BEL 01 | C14: ='RESUMEN TOTAL'!D16 -> San Martin y Dardo Rocha | D14: ='RESUMEN TOTAL'!E16 -> DOMO | E14: ='RESUMEN TOTAL'!F16 -> Fibra Optica | F14: ='RESUMEN TOTAL'!L16 -> 0 | G14: ='RESUMEN TOTAL'!M16 -> 0 | H14: ='RESUMEN TOTAL'!N16 -> 0 | I14: ='RESUMEN TOTAL'!O16 -> 0 | J14: ='RESUMEN TOTAL'!P16 -> 0 | K14: ='RESUMEN TOTAL'!Q16 -> 0 | L14: ='RESUMEN TOTAL'!R16 -> 0 | M14: ='RESUMEN TOTAL'!S16 -> 0 | ... AI14: ='RESUMEN TOTAL'!AO16 -> 0 | AJ14: ='RESUMEN TOTAL'!#REF! -> #REF!
A15: ='RESUMEN TOTAL'!A17 -> BELGRANO | B15: ='RESUMEN TOTAL'!B17 -> BEL 02 | C15: ='RESUMEN TOTAL'!D17 -> Guardia vieja y Fronteriz | D15: ='RESUMEN TOTAL'!E17 -> DOMO | E15: ='RESUMEN TOTAL'!F17 -> Fibra Optica | F15: ='RESUMEN TOTAL'!L17 -> 0 | G15: ='RESUMEN TOTAL'!M17 -> 0 | H15: ='RESUMEN TOTAL'!N17 -> 0 | I15: ='RESUMEN TOTAL'!O17 -> 0 | J15: ='RESUMEN TOTAL'!P17 -> 0 | K15: ='RESUMEN TOTAL'!Q17 -> 0 | L15: ='RESUMEN TOTAL'!R17 -> 0 | M15: ='RESUMEN TOTAL'!S17 -> 0 | ... AI15: ='RESUMEN TOTAL'!AO17 -> 0 | AJ15: ='RESUMEN TOTAL'!#REF! -> #REF!
... A604: ='RESUMEN TOTAL'!A606 -> 0 | B604: ='RESUMEN TOTAL'!B606 -> 0 | C604: ='RESUMEN TOTAL'!D606 -> 0 | D604: ='RESUMEN TOTAL'!E606 -> 0 | E604: ='RESUMEN TOTAL'!F606 -> 0 | F604: ='RESUMEN TOTAL'!L606 -> 0 | G604: ='RESUMEN TOTAL'!M606 -> 0 | H604: ='RESUMEN TOTAL'!N606 -> 0 | I604: ='RESUMEN TOTAL'!O606 -> 0 | J604: ='RESUMEN TOTAL'!P606 -> 0 | K604: ='RESUMEN TOTAL'!Q606 -> 0 | L604: ='RESUMEN TOTAL'!R606 -> 0 | M604: ='RESUMEN TOTAL'!S606 -> 0 | ... AI604: ='RESUMEN TOTAL'!AO606 -> 0 | AJ604: ='RESUMEN TOTAL'!#REF! -> #REF!

Sheet APAGADOS RADIO
C1: TOTAL RADIO | D1: =COUNTIFS(E4:E400,"=radio") -> 89
E2: APAGADOS | F2: =COUNTIFS(F4:F500, "=APAGADO",E4:E500,"=radio") -> 0 | G2: =COUNTIFS(G4:G500, "=APAGADO",E4:E500,"=radio") -> 0 | H2: =COUNTIFS(H4:H500, "=APAGADO",E4:E500,"=radio") -> 0 | I2: =COUNTIFS(I4:I500, "=APAGADO",E4:E500,"=radio") -> 0 | J2: =COUNTIFS(J4:J500, "=APAGADO",E4:E500,"=radio") -> 0 | K2: =COUNTIFS(K4:K500, "=APAGADO",E4:E500,"=radio") -> 4 | L2: =COUNTIFS(L4:L500, "=APAGADO",E4:E500,"=radio") -> 7 | M2: =COUNTIFS(M4:M500, "=APAGADO",E4:E500,"=radio") -> 0 | N2: =COUNTIFS(N4:N500, "=APAGADO",E4:E500,"=radio") -> 0 | O2: =COUNTIFS(O4:O500, "=APAGADO",E4:E500,"=radio") -> 11 | P2: =COUNTIFS(P4:P500, "=APAGADO",E4:E500,"=radio") -> 11 | Q2: =COUNTIFS(Q4:Q367, "=APAGADO",E4:E367,"=radio") -> 9 | R2: =COUNTIFS(R4:R500, "=APAGADO",E4:E500,"=radio") -> 14 | S2: =COUNTIFS(S4:S500, "=APAGADO",E4:E500,"=radio") -> 18 | T2: =COUNTIFS(T4:T500, "=APAGADO",E4:E500,"=radio") -> 11 | U2: =COUNTIFS(U4:U500, "=APAGADO",E4:E500,"=radio") -> 8 | V2: =COUNTIFS(V4:V500, "=APAGADO",E4:E500,"=radio") -> 16 | W2: =COUNTIFS(W4:W500, "=APAGADO",E4:E500,"=radio") -> 11 | X2: =COUNTIFS(X4:X500, "=APAGADO",E4:E500,"=radio") -> 15 | Y2: =COUNTIFS(Y4:Y500, "=APAGADO",E4:E500,"=radio") -> 6 | Z2: =COUNTIFS(Z4:Z500, "=APAGADO",E4:E500,"=radio") -> 8 | AA2: =COUNTIFS(AA4:AA500, "=APAGADO",E4:E500,"=radio") -> 6 | AB2: =COUNTIFS(AB4:AB500, "=APAGADO",E4:E500,"=radio") -> 0 | AC2: =COUNTIFS(AC4:AC500, "=APAGADO",E4:E500,"=radio") -> 0 | AD2: =COUNTIFS(AD4:AD500, "=APAGADO",E4:E500,"=radio") -> 0 | AE2: =COUNTIFS(AE4:AE500, "=APAGADO",E4:E500,"=radio") -> 0 | AF2: =COUNTIFS(AF4:AF500, "=APAGADO",E4:E500,"=radio") -> 0 | AG2: =COUNTIFS(AG4:AG500, "=APAGADO",E4:E500,"=radio") -> 0 | AH2: =COUNTIFS(AH4:AH500, "=APAGADO",F4:F500,"=radio") -> 0 | AI2: =COUNTIFS(AI4:AI500, "=APAGADO",G4:G500,"=radio") -> 0 | AJ2: =COUNTIFS(AJ4:AJ500, "=APAGADO",H4:H500,"=radio") -> 0
A3: =ESTADISTICA!A1 -> Barrio | B3: =ESTADISTICA!B1 -> [Denominacion] | C3: =ESTADISTICA!C1 -> [Ubicacion] | D3: =ESTADISTICA!D1 -> [Tipo de Camara] | E3: =ESTADISTICA!E1 -> [Tipo de Conexion] | F3: =ESTADISTICA!F1 -> 45108 | G3: =ESTADISTICA!G1 -> 45109 | H3: =ESTADISTICA!H1 -> 45110 | ... AJ3: =ESTADISTICA!AJ1 -> #REF!
A4: ='RESUMEN TOTAL'!A7 -> ALTAMIRA | B4: ='RESUMEN TOTAL'!B7 -> ALT 03 | C4: ='RESUMEN TOTAL'!D7 -> Bombero Galarza y Necochea | D4: ='RESUMEN TOTAL'!E7 -> Domo | E4: ='RESUMEN TOTAL'!F7 -> Fibra Optica | F4: ='RESUMEN TOTAL'!L7 -> 0 | G4: ='RESUMEN TOTAL'!M7 -> 0 | H4: ='RESUMEN TOTAL'!N7 -> 0 | I4: ='RESUMEN TOTAL'!O7 -> 0 | J4: ='RESUMEN TOTAL'!P7 -> 0 | K4: ='RESUMEN TOTAL'!Q7 -> 0 | L4: ='RESUMEN TOTAL'!R7 -> 0 | M4: ='RESUMEN TOTAL'!S7 -> 0 | ... AI4: ='RESUMEN TOTAL'!AO7 -> 0 | AJ4: ='RESUMEN TOTAL'!#REF! -> #REF!
A5: ='RESUMEN TOTAL'!A8 -> ALTAMIRA | B5: ='RESUMEN TOTAL'!B8 -> ALT 04 | C5: ='RESUMEN TOTAL'!D8 -> Francia y Necochea | D5: ='RESUMEN TOTAL'!E8 -> Domo | E5: ='RESUMEN TOTAL'!F8 -> Fibra Optica | F5: ='RESUMEN TOTAL'!L8 -> 0 | G5: ='RESUMEN TOTAL'!M8 -> 0 | H5: ='RESUMEN TOTAL'!N8 -> 0 | I5: ='RESUMEN TOTAL'!O8 -> 0 | J5: ='RESUMEN TOTAL'!P8 -> 0 | K5: ='RESUMEN TOTAL'!Q8 -> 0 | L5: ='RESUMEN TOTAL'!R8 -> 0 | M5: ='RESUMEN TOTAL'!S8 -> 0 | ... AI5: ='RESUMEN TOTAL'!AO8 -> 0 | AJ5: ='RESUMEN TOTAL'!#REF! -> #REF!
A6: ='RESUMEN TOTAL'!A9 -> ALTAMIRA | B6: ='RESUMEN TOTAL'!B9 -> ALT05 | C6: ='RESUMEN TOTAL'!D9 -> Av. Calchaqui y Bombero Galarza | D6: ='RESUMEN TOTAL'!E9 -> Domo | E6: ='RESUMEN TOTAL'!F9 -> PTO A FO | F6: ='RESUMEN TOTAL'!L9 -> 0 | G6: ='RESUMEN TOTAL'!M9 -> 0 | H6: ='RESUMEN TOTAL'!N9 -> 0 | I6: ='RESUMEN TOTAL'!O9 -> 0 | J6: ='RESUMEN TOTAL'!P9 -> 0 | K6: ='RESUMEN TOTAL'!Q9 -> 0 | L6: ='RESUMEN TOTAL'!R9 -> 0 | M6: ='RESUMEN TOTAL'!S9 -> 0 | ... AI6: ='RESUMEN TOTAL'!AO9 -> 0 | AJ6: ='RESUMEN TOTAL'!#REF! -> #REF!
A7: ='RESUMEN TOTAL'!A10 -> ALTAMIRA | B7: ='RESUMEN TOTAL'!B10 -> ALT 06 | C7: ='RESUMEN TOTAL'!D10 -> LOPE DE VEGA Y NECOCHEA | D7: ='RESUMEN TOTAL'!E10 -> Domo | E7: ='RESUMEN TOTAL'!F10 -> PTO A FO | F7: ='RESUMEN TOTAL'!L10 -> 0 | G7: ='RESUMEN TOTAL'!M10 -> 0 | H7: ='RESUMEN TOTAL'!N10 -> 0 | I7: ='RESUMEN TOTAL'!O10 -> 0 | J7: ='RESUMEN TOTAL'!P10 -> 0 | K7: ='RESUMEN TOTAL'!Q10 -> 0 | L7: ='RESUMEN TOTAL'!R10 -> 0 | M7: ='RESUMEN TOTAL'!S10 -> 0 | ... AI7: ='RESUMEN TOTAL'!AO10 -> 0 | AJ7: ='RESUMEN TOTAL'!#REF! -> #REF!
A8: ='RESUMEN TOTAL'!A11 -> ALTAMIRA | B8: ='RESUMEN TOTAL'!B11 -> ALT07 | C8: ='RESUMEN TOTAL'!D11 -> AV. CALCHAQUI Y AV. DEL TRABAJO | D8: ='RESUMEN TOTAL'!E11 -> DOMO | E8: ='RESUMEN TOTAL'!F11 -> PTO A FO | F8: ='RESUMEN TOTAL'!L11 -> 0 | G8: ='RESUMEN TOTAL'!M11 -> 0 | H8: ='RESUMEN TOTAL'!N11 -> 0 | I8: ='RESUMEN TOTAL'!O11 -> 0 | J8: ='RESUMEN TOTAL'!P11 -> 0 | K8: ='RESUMEN TOTAL'!Q11 -> 0 | L8: ='RESUMEN TOTAL'!R11 -> 0 | M8: ='RESUMEN TOTAL'!S11 -> 0 | ... AI8: ='RESUMEN TOTAL'!AO11 -> 0 | AJ8: ='RESUMEN TOTAL'!#REF! -> #REF!
A9: ='RESUMEN TOTAL'!A12 -> ALTAMIRA | B9: ='RESUMEN TOTAL'!B12 -> ALT 08 | C9: ='RESUMEN TOTAL'!D12 -> HUMAITA Y NECOCHEA | D9: ='RESUMEN TOTAL'!E12 -> DOMO | E9: ='RESUMEN TOTAL'!F12 -> Fibra Optica | F9: ='RESUMEN TOTAL'!L12 -> 0 | G9: ='RESUMEN TOTAL'!M12 -> 0 | H9: ='RESUMEN TOTAL'!N12 -> 0 | I9: ='RESUMEN TOTAL'!O12 -> 0 | J9: ='RESUMEN TOTAL'!P12 -> 0 | K9: ='RESUMEN TOTAL'!Q12 -> 0 | L9: ='RESUMEN TOTAL'!R12 -> 0 | M9: ='RESUMEN TOTAL'!S12 -> 0 | ... AI9: ='RESUMEN TOTAL'!AO12 -> 0 | AJ9: ='RESUMEN TOTAL'!#REF! -> #REF!
A10: ='RESUMEN TOTAL'!A13 -> ALTAMIRA | B10: ='RESUMEN TOTAL'!B13 -> ALT 09 | C10: ='RESUMEN TOTAL'!D13 -> NECOCHEA Y CURUPAITY | D10: ='RESUMEN TOTAL'!E13 -> DOMO | E10: ='RESUMEN TOTAL'!F13 -> Fibra Optica | F10: ='RESUMEN TOTAL'!L13 -> 0 | G10: ='RESUMEN TOTAL'!M13 -> 0 | H10: ='RESUMEN TOTAL'!N13 -> 0 | I10: ='RESUMEN TOTAL'!O13 -> 0 | J10: ='RESUMEN TOTAL'!P13 -> 0 | K10: ='RESUMEN TOTAL'!Q13 -> APAGADO | L10: ='RESUMEN TOTAL'!R13 -> APAGADO | M10: ='RESUMEN TOTAL'!S13 -> 0 | ... AI10: ='RESUMEN TOTAL'!AO13 -> 0 | AJ10: ='RESUMEN TOTAL'!#REF! -> #REF!
A11: ='RESUMEN TOTAL'!A14 -> ALTAMIRA | B11: ='RESUMEN TOTAL'!B14 -> ALT 10 | C11: ='RESUMEN TOTAL'!D14 -> Calchaqui y Francia | D11: ='RESUMEN TOTAL'!E14 -> Domo | E11: ='RESUMEN TOTAL'!F14 -> Radio | F11: ='RESUMEN TOTAL'!L14 -> 0 | G11: ='RESUMEN TOTAL'!M14 -> 0 | H11: ='RESUMEN TOTAL'!N14 -> 0 | I11: ='RESUMEN TOTAL'!O14 -> 0 | J11: ='RESUMEN TOTAL'!P14 -> 0 | K11: ='RESUMEN TOTAL'!Q14 -> 0 | L11: ='RESUMEN TOTAL'!R14 -> 0 | M11: ='RESUMEN TOTAL'!S14 -> 0 | ... AI11: ='RESUMEN TOTAL'!AO14 -> 0 | AJ11: ='RESUMEN TOTAL'!#REF! -> #REF!
A12: ='RESUMEN TOTAL'!A15 -> AGUSTIN RAMIREZ | B12: ='RESUMEN TOTAL'!B15 -> ARA 01 | C12: ='RESUMEN TOTAL'!D15 -> Malambo y Tranquera | D12: ='RESUMEN TOTAL'!E15 -> Domo | E12: ='RESUMEN TOTAL'!F15 -> Fibra Optica | F12: ='RESUMEN TOTAL'!L15 -> 0 | G12: ='RESUMEN TOTAL'!M15 -> 0 | H12: ='RESUMEN TOTAL'!N15 -> 0 | I12: ='RESUMEN TOTAL'!O15 -> 0 | J12: ='RESUMEN TOTAL'!P15 -> 0 | K12: ='RESUMEN TOTAL'!Q15 -> 0 | L12: ='RESUMEN TOTAL'!R15 -> 0 | M12: ='RESUMEN TOTAL'!S15 -> 0 | ... AI12: ='RESUMEN TOTAL'!AO15 -> 0 | AJ12: ='RESUMEN TOTAL'!#REF! -> #REF!
A13: ='RESUMEN TOTAL'!A16 -> BELGRANO | B13: ='RESUMEN TOTAL'!B16 -> BEL 01 | C13: ='RESUMEN TOTAL'!D16 -> San Martin y Dardo Rocha | D13: ='RESUMEN TOTAL'!E16 -> DOMO | E13: ='RESUMEN TOTAL'!F16 -> Fibra Optica | F13: ='RESUMEN TOTAL'!L16 -> 0 | G13: ='RESUMEN TOTAL'!M16 -> 0 | H13: ='RESUMEN TOTAL'!N16 -> 0 | I13: ='RESUMEN TOTAL'!O16 -> 0 | J13: ='RESUMEN TOTAL'!P16 -> 0 | K13: ='RESUMEN TOTAL'!Q16 -> 0 | L13: ='RESUMEN TOTAL'!R16 -> 0 | M13: ='RESUMEN TOTAL'!S16 -> 0 | ... AI13: ='RESUMEN TOTAL'!AO16 -> 0 | AJ13: ='RESUMEN TOTAL'!#REF! -> #REF!
A14: ='RESUMEN TOTAL'!A17 -> BELGRANO | B14: ='RESUMEN TOTAL'!B17 -> BEL 02 | C14: ='RESUMEN TOTAL'!D17 -> Guardia vieja y Fronteriz | D14: ='RESUMEN TOTAL'!E17 -> DOMO | E14: ='RESUMEN TOTAL'!F17 -> Fibra Optica | F14: ='RESUMEN TOTAL'!L17 -> 0 | G14: ='RESUMEN TOTAL'!M17 -> 0 | H14: ='RESUMEN TOTAL'!N17 -> 0 | I14: ='RESUMEN TOTAL'!O17 -> 0 | J14: ='RESUMEN TOTAL'!P17 -> 0 | K14: ='RESUMEN TOTAL'!Q17 -> 0 | L14: ='RESUMEN TOTAL'!R17 -> 0 | M14: ='RESUMEN TOTAL'!S17 -> 0 | ... AI14: ='RESUMEN TOTAL'!AO17 -> 0 | AJ14: ='RESUMEN TOTAL'!#REF! -> #REF!
A15: ='RESUMEN TOTAL'!A18 -> BOSQUES CENTRO | B15: ='RESUMEN TOTAL'!B18 -> BOSQC 01 | C15: ='RESUMEN TOTAL'!D18 -> LUIS AGOTE E/DANUNCIO Y CAMPOAMOR | D15: ='RESUMEN TOTAL'!E18 -> Fija | E15: ='RESUMEN TOTAL'!F18 -> Radio | F15: ='RESUMEN TOTAL'!L18 -> 0 | G15: ='RESUMEN TOTAL'!M18 -> 0 | H15: ='RESUMEN TOTAL'!N18 -> 0 | I15: ='RESUMEN TOTAL'!O18 -> 0 | J15: ='RESUMEN TOTAL'!P18 -> 0 | K15: ='RESUMEN TOTAL'!Q18 -> 0 | L15: ='RESUMEN TOTAL'!R18 -> 0 | M15: ='RESUMEN TOTAL'!S18 -> 0 | ... AI15: ='RESUMEN TOTAL'!AO18 -> 0 | AJ15: ='RESUMEN TOTAL'!#REF! -> #REF!
... A602: ='RESUMEN TOTAL'!A605 -> 0 | B602: ='RESUMEN TOTAL'!B605 -> 0 | C602: ='RESUMEN TOTAL'!D605 -> 0 | D602: ='RESUMEN TOTAL'!E605 -> 0 | E602: ='RESUMEN TOTAL'!F605 -> 0 | F602: ='RESUMEN TOTAL'!L605 -> 0 | G602: ='RESUMEN TOTAL'!M605 -> 0 | H602: ='RESUMEN TOTAL'!N605 -> 0 | I602: ='RESUMEN TOTAL'!O605 -> 0 | J602: ='RESUMEN TOTAL'!P605 -> 0 | K602: ='RESUMEN TOTAL'!Q605 -> 0 | L602: ='RESUMEN TOTAL'!R605 -> 0 | M602: ='RESUMEN TOTAL'!S605 -> 0 | ... AI602: ='RESUMEN TOTAL'!AO605 -> 0 | AJ602: ='RESUMEN TOTAL'!#REF! -> #REF!
A603: ='RESUMEN TOTAL'!A606 -> 0 | B603: ='RESUMEN TOTAL'!B606 -> 0 | C603: ='RESUMEN TOTAL'!D606 -> 0 | D603: ='RESUMEN TOTAL'!E606 -> 0 | E603: ='RESUMEN TOTAL'!F606 -> 0 | F603: ='RESUMEN TOTAL'!L606 -> 0 | G603: ='RESUMEN TOTAL'!M606 -> 0 | H603: ='RESUMEN TOTAL'!N606 -> 0 | I603: ='RESUMEN TOTAL'!O606 -> 0 | J603: ='RESUMEN TOTAL'!P606 -> 0 | K603: ='RESUMEN TOTAL'!Q606 -> 0 | L603: ='RESUMEN TOTAL'!R606 -> 0 | M603: ='RESUMEN TOTAL'!S606 -> 0 | ... AI603: ='RESUMEN TOTAL'!AO606 -> 0
A604: ='RESUMEN TOTAL'!A607 -> 0 | B604: ='RESUMEN TOTAL'!B607 -> 0 | C604: ='RESUMEN TOTAL'!D607 -> 0 | D604: ='RESUMEN TOTAL'!E607 -> 0 | E604: ='RESUMEN TOTAL'!F607 -> 0 | F604: ='RESUMEN TOTAL'!L607 -> 0 | G604: ='RESUMEN TOTAL'!M607 -> 0 | H604: ='RESUMEN TOTAL'!N607 -> 0 | I604: ='RESUMEN TOTAL'!O607 -> 0 | J604: ='RESUMEN TOTAL'!P607 -> 0 | K604: ='RESUMEN TOTAL'!Q607 -> 0 | L604: ='RESUMEN TOTAL'!R607 -> 0 | M604: ='RESUMEN TOTAL'!S607 -> 0 | ... AI604: ='RESUMEN TOTAL'!AO607 -> 0
A605: ='RESUMEN TOTAL'!A608 -> 0 | B605: ='RESUMEN TOTAL'!B608 -> 0 | C605: ='RESUMEN TOTAL'!D608 -> 0 | D605: ='RESUMEN TOTAL'!E608 -> 0 | E605: ='RESUMEN TOTAL'!F608 -> 0 | F605: ='RESUMEN TOTAL'!L608 -> 0 | G605: ='RESUMEN TOTAL'!M608 -> 0 | H605: ='RESUMEN TOTAL'!N608 -> 0 | I605: ='RESUMEN TOTAL'!O608 -> 0 | J605: ='RESUMEN TOTAL'!P608 -> 0 | K605: ='RESUMEN TOTAL'!Q608 -> 0 | L605: ='RESUMEN TOTAL'!R608 -> 0 | M605: ='RESUMEN TOTAL'!S608 -> 0 | ... AI605: ='RESUMEN TOTAL'!AO608 -> 0
A606: ='RESUMEN TOTAL'!A609 -> 0 | B606: ='RESUMEN TOTAL'!B609 -> 0 | C606: ='RESUMEN TOTAL'!D609 -> 0 | D606: ='RESUMEN TOTAL'!E609 -> 0 | E606: ='RESUMEN TOTAL'!F609 -> 0 | F606: ='RESUMEN TOTAL'!L609 -> 0 | G606: ='RESUMEN TOTAL'!M609 -> 0 | H606: ='RESUMEN TOTAL'!N609 -> 0 | I606: ='RESUMEN TOTAL'!O609 -> 0 | J606: ='RESUMEN TOTAL'!P609 -> 0 | K606: ='RESUMEN TOTAL'!Q609 -> 0 | L606: ='RESUMEN TOTAL'!R609 -> 0 | M606: ='RESUMEN TOTAL'!S609 -> 0 | ... AI606: ='RESUMEN TOTAL'!AO609 -> 0
A607: ='RESUMEN TOTAL'!A610 -> 0 | B607: ='RESUMEN TOTAL'!B610 -> 0 | C607: ='RESUMEN TOTAL'!D610 -> 0 | D607: ='RESUMEN TOTAL'!E610 -> 0 | E607: ='RESUMEN TOTAL'!F610 -> 0 | F607: ='RESUMEN TOTAL'!L610 -> 0 | G607: ='RESUMEN TOTAL'!M610 -> 0 | H607: ='RESUMEN TOTAL'!N610 -> 0 | I607: ='RESUMEN TOTAL'!O610 -> 0 | J607: ='RESUMEN TOTAL'!P610 -> 0 | K607: ='RESUMEN TOTAL'!Q610 -> 0 | L607: ='RESUMEN TOTAL'!R610 -> 0 | M607: ='RESUMEN TOTAL'!S610 -> 0 | ... AI607: ='RESUMEN TOTAL'!AO610 -> 0
A608: ='RESUMEN TOTAL'!A611 -> 0 | B608: ='RESUMEN TOTAL'!B611 -> 0 | C608: ='RESUMEN TOTAL'!D611 -> 0 | D608: ='RESUMEN TOTAL'!E611 -> 0 | E608: ='RESUMEN TOTAL'!F611 -> 0 | F608: ='RESUMEN TOTAL'!L611 -> 0 | G608: ='RESUMEN TOTAL'!M611 -> 0 | H608: ='RESUMEN TOTAL'!N611 -> 0 | I608: ='RESUMEN TOTAL'!O611 -> 0 | J608: ='RESUMEN TOTAL'!P611 -> 0 | K608: ='RESUMEN TOTAL'!Q611 -> 0 | L608: ='RESUMEN TOTAL'!R611 -> 0 | M608: ='RESUMEN TOTAL'!S611 -> 0 | ... AI608: ='RESUMEN TOTAL'!AO611 -> 0
A609: ='RESUMEN TOTAL'!A612 -> 0 | B609: ='RESUMEN TOTAL'!B612 -> 0 | C609: ='RESUMEN TOTAL'!D612 -> 0 | D609: ='RESUMEN TOTAL'!E612 -> 0 | E609: ='RESUMEN TOTAL'!F612 -> 0 | F609: ='RESUMEN TOTAL'!L612 -> 0 | G609: ='RESUMEN TOTAL'!M612 -> 0 | H609: ='RESUMEN TOTAL'!N612 -> 0 | I609: ='RESUMEN TOTAL'!O612 -> 0 | J609: ='RESUMEN TOTAL'!P612 -> 0 | K609: ='RESUMEN TOTAL'!Q612 -> 0 | L609: ='RESUMEN TOTAL'!R612 -> 0 | M609: ='RESUMEN TOTAL'!S612 -> 0 | ... AI609: ='RESUMEN TOTAL'!AO612 -> 0
A610: ='RESUMEN TOTAL'!A613 -> 0 | B610: ='RESUMEN TOTAL'!B613 -> 0 | C610: ='RESUMEN TOTAL'!D613 -> 0 | D610: ='RESUMEN TOTAL'!E613 -> 0 | E610: ='RESUMEN TOTAL'!F613 -> 0 | F610: ='RESUMEN TOTAL'!L613 -> 0 | G610: ='RESUMEN TOTAL'!M613 -> 0 | H610: ='RESUMEN TOTAL'!N613 -> 0 | I610: ='RESUMEN TOTAL'!O613 -> 0 | J610: ='RESUMEN TOTAL'!P613 -> 0 | K610: ='RESUMEN TOTAL'!Q613 -> 0 | L610: ='RESUMEN TOTAL'!R613 -> 0 | M610: ='RESUMEN TOTAL'!S613 -> 0 | ... AI610: ='RESUMEN TOTAL'!AO613 -> 0
